Workbook

Sheet PJ_Casino
A1: Lieu : | B1: PERS-JUSSY_Giratoire de Casino | M1: Date : | N1: mardi 6 juin 2023
A2: Nom des personnes participant au comptage : | G2: Françoise SAGE
A3: Météo : | C3: Excellente (grand soleil)
A5: Remarques : | C5: 2 vélos venant de Pers-Jussy sont allés direction le chemin du Château de Magny Egalement compté 2 piétons | P5: Méthodologie : | R5: Pour chaque intervalle de temps, marquer une seule croix par personne comptée. Si c'est enfant, remplacer la croix par E, une trottinette T, un piéton P, etc.
C7: Depuis 'La Roche' | P7: Depuis 'Pers-Jussy'
C8: vers 'Reignier' | G8: vers 'Casino' | K8: vers 'Pers-Jussy' | P8: vers 'La Roche' | T8: vers 'Reignier' | X8: vers 'Casino'
C9: H | E9: F | G9: H | I9: F | K9: H | M9: F | P9: H | R9: F | T9: H | V9: F | X9: H | Z9: F
A10: Heure | B10: Minute | C10: VAE | D10: vélo | E10: VAE | F10: vélo | G10: VAE | H10: vélo | I10: VAE | J10: vélo | K10: VAE | L10: vélo | M10: VAE | N10: vélo | P10: VAE | Q10: vélo | R10: VAE | S10: vélo | T10: VAE | U10: vélo | V10: VAE | W10: vélo | X10: VAE | Y10: vélo | Z10: VAE | AA10: vélo
A11: 6 | B11: 30 – 44'59
B12: 45 – 59'59
A13: 7 | B13: 00 – 14'59 | D13: 2
B14: 15 – 29'59 | C14: 1 | D14: 1 | E14: 2 | T14: 1 | V14: 1
B15: 30 – 44'59 | C15: 1 | D15: 1 | V15: 1
B16: 45 – 59'59 | D16: 1 | E16: 1 | F16: 2 | W16: 1 | AA16: 1
A17: 8 | B17: 00 – 14'59 | D17: 1 | E17: 1
B18: 15 – 29'59 | U18: 1
B19: 30 – 44'59 | E19: 1 | W19: 1
B20: 45 – 59'59 | U20: 1
A21: 9 | B21: 00 – 14'59
B22: 15 – 29'59
A24: Remarques : | C24: 1 vélo allant à Casino est venu du chemin du Château de Magny Egalement compté 2 piétons
C26: Depuis 'Reignier' | P26: Depuis 'Casino'
C27: vers 'Casino' | G27: vers 'Pers-Jussy' | K27: vers 'La Roche' | P27: vers 'Pers-Jussy' | T27: vers 'La Roche' | X27: vers 'Reignier'
C28: H | E28: F | G28: H | I28: F | K28: H | M28: F | P28: H | R28: F | T28: H | V28: F | X28: H | Z28: F
A29: Heure | B29: Minute | C29: VAE | D29: vélo | E29: VAE | F29: vélo | G29: VAE | H29: vélo | I29: VAE | J29: vélo | K29: VAE | L29: vélo | M29: VAE | N29: vélo | P29: VAE | Q29: vélo | R29: VAE | S29: vélo | T29: VAE | U29: vélo | V29: VAE | W29: vélo | X29: VAE | Y29: vélo | Z29: VAE | AA29: vélo
A30: 6 | B30: 30 – 44'59
B31: 45 – 59'59
A32: 7 | B32: 00 – 14'59
B33: 15 – 29'59
B34: 30 – 44'59
B35: 45 – 59'59
A36: 8 | B36: 00 – 14'59
B37: 15 – 29'59 | G37: 1 | I37: 1
B38: 30 – 44'59
B39: 45 – 59'59 | D39: 1 | L39: 1
A40: 9 | B40: 00 – 14'59
B41: 15 – 29'59
C44: =C7 -> Depuis 'La Roche' | P44: =P7 -> Depuis 'Pers-Jussy' | AD44: TOTAL | AE44: Part des VAE dans le total | AF44: Part des femmes dans le total | AG44: Part des VAE chez les femmes | AH44: Part en direction de Reignier | AI44: Part en provenance de Reignier | AJ44: Part en provenance d'Esery | AK44: Remarques
C45: =C8 -> vers 'Reignier' | G45: =G8 -> vers 'Casino' | K45: =K8 -> vers 'Pers-Jussy' | P45: =P8 -> vers 'La Roche' | T45: =T8 -> vers 'Reignier' | X45: =X8 -> vers 'Casino'
C46: H | E46: F | G46: H | I46: F | K46: H | M46: F | P46: H | R46: F | T46: H | V46: F | X46: H | Z46: F
...

Sheet RE_Gare
A1: Lieu : | B1: REIGNIER_Carrefour Rue de la Gare / Rte de Bellecombe (vers Tour d'Ivoire) | N1: Date : | O1: mardi 6 juin 2023
A2: Nom des personnes participant au comptage : | G2: Jacques LACHEZE
A3: Météo : | C3: Excellente (grand soleil)
A5: Remarques : | C5: Carrefour non sécurisé // 5 trottinettes, dont 4 en dir. de la gare Sur 37 vélos+trott comptés, 17 vont vers la gare et 17 autres vont vers Reignier-Centre | P5: Méthodologie : | R5: Pour chaque intervalle de temps, marquer une seule croix par personne comptée. Si c'est enfant, remplacer la croix par E, une trottinette T, un piéton P, etc.
C7: Depuis 'Pers-Jussy' | L7: Depuis 'Reignier-centre' | U7: Depuis 'Gare'
C8: vers 'Reignier' | G8: vers 'Gare' | L8: vers 'Pers-Jussy' | P8: vers 'Gare' | U8: vers 'Reignier-centre' | Y8: vers 'Pers-Jussy'
C9: H | E9: F | G9: H | I9: F | L9: H | N9: F | P9: H | R9: F | U9: H | W9: F | Y9: H | AA9: F
A10: Heure | B10: Minute | C10: VAE | D10: vélo | E10: VAE | F10: vélo | G10: VAE | H10: vélo | I10: VAE | J10: vélo | L10: VAE | M10: vélo | N10: VAE | O10: vélo | P10: VAE | Q10: vélo | R10: VAE | S10: vélo | U10: VAE | V10: vélo | W10: VAE | X10: vélo | Y10: VAE | Z10: vélo | AA10: VAE | AB10: vélo
A11: 6 | B11: 30 – 44'59
B12: 45 – 59'59
A13: 7 | B13: 00 – 14'59 | C13: 4 | P13: 1 | R13: 1
B14: 15 – 29'59 | C14: 2 | E14: 1 | Q14: 2 | R14: 1
B15: 30 – 44'59 | C15: 1 | D15: 1 | G15: 1 | I15: 1 | R15: 1
B16: 45 – 59'59 | D16: 1 | G16: 1 | S16: 1
A17: 8 | B17: 00 – 14'59 | D17: 1 | E17: 1 | N17: 1 | Q17: 1 | X17: 1
B18: 15 – 29'59 | M18: 1 | R18: 1
B19: 30 – 44'59 | D19: 1 | F19: 1 | V19: 1
B20: 45 – 59'59
A21: 9 | B21: 00 – 14'59
B22: 15 – 29'59
C25: =C7 -> Depuis 'Pers-Jussy' | L25: =L7 -> Depuis 'Reignier-centre' | U25: =U7 -> Depuis 'Gare' | AE25: TOTAL | AF25: Part des VAE dans le total | AG25: Part des femmes dans le total | AH25: Part des VAE chez les femmes | AI25: Part en direction d'Annemasse-Genève | AJ25: Part en provenance de Reignier | AK25: Part en provenance d'Esery | AL25: Remarques
C26: =C8 -> vers 'Reignier' | G26: =G8 -> vers 'Gare' | L26: =L8 -> vers 'Pers-Jussy' | P26: =P8 -> vers 'Gare' | U26: =U8 -> vers 'Reignier-centre' | Y26: =Y8 -> vers 'Pers-Jussy'
C27: H | E27: F | G27: H | I27: F | L27: H | N27: F | P27: H | R27: F | U27: H | W27: F | Y27: H | AA27: F
A28: Période | C28: VAE | D28: vélo | E28: VAE | F28: vélo | G28: VAE | H28: vélo | I28: VAE | J28: vélo | L28: VAE | M28: vélo | N28: VAE | O28: vélo | P28: VAE | Q28: vélo | R28: VAE | S28: vélo | U28: VAE | V28: vélo | W28: VAE | X28: vélo | Y28: VAE | Z28: vélo | AA28: VAE | AB28: vélo | AC28: Période
A29: de 6:30 à 7:30 | C29: =SUM(C11:C14) -> 6 | D29: =SUM(D11:D14) -> 0 | E29: =SUM(E11:E14) -> 1 | F29: =SUM(F11:F14) -> 0 | G29: =SUM(G11:G14) -> 0 | H29: =SUM(H11:H14) -> 0 | I29: =SUM(I11:I14) -> 0 | J29: =SUM(J11:J14) -> 0 | L29: =SUM(L11:L14) -> 0 | M29: =SUM(M11:M14) -> 0 | N29: =SUM(N11:N14) -> 0 | O29: =SUM(O11:O14) -> 0 | P29: =SUM(P11:P14) -> 1 | Q29: =SUM(Q11:Q14) -> 2 | R29: =SUM(R11:R14) -> 2 | S29: =SUM(S11:S14) -> 0 | U29: =SUM(U11:U14) -> 0 | V29: =SUM(V11:V14) -> 0 | W29: =SUM(W11:W14) -> 0 | X29: =SUM(X11:X14) -> 0 | Y29: =SUM(Y11:Y14) -> 0 | Z29: =SUM(Z11:Z14) -> 0 | AA29: =SUM(AA11:AA14) -> 0 | AB29: =SUM(AB11:AB14) -> 0 | AC29: de 6:30 à 7:30 | AE29: =SUM(C29:AB29) -> 12 | AF29: =IF(AE29=0,0,AF41/AE29) -> 0.83333333 | AG29: =IF(AE29=0,0,AG41/AE29) -> 0.25 | AH29: =IF(AG41=0,0,AH41/AG41) -> 1 | AI29: =IF(AE29=0,0,AI41/AE29) -> 0.41666667 | AJ29: =IF(AE29=0,0,AJ41/AE29) -> 0.41666667 | AK29: =IF(AE29=0,0,AK41/AE29) -> 0.58333333
A30: de 7:00 à 8:00 | C30: =SUM(C13:C16) -> 7 | D30: =SUM(D13:D16) -> 2 | E30: =SUM(E13:E16) -> 1 | F30: =SUM(F13:F16) -> 0 | G30: =SUM(G13:G16) -> 2 | H30: =SUM(H13:H16) -> 0 | I30: =SUM(I13:I16) -> 1 | J30: =SUM(J13:J16) -> 0 | L30: =SUM(L13:L16) -> 0 | M30: =SUM(M13:M16) -> 0 | N30: =SUM(N13:N16) -> 0 | O30: =SUM(O13:O16) -> 0 | P30: =SUM(P13:P16) -> 1 | Q30: =SUM(Q13:Q16) -> 2 | R30: =SUM(R13:R16) -> 3 | S30: =SUM(S13:S16) -> 1 | U30: =SUM(U13:U16) -> 0 | V30: =SUM(V13:V16) -> 0 | W30: =SUM(W13:W16) -> 0 | X30: =SUM(X13:X16) -> 0 | Y30: =SUM(Y13:Y16) -> 0 | Z30: =SUM(Z13:Z16) -> 0 | AA30: =SUM(AA13:AA16) -> 0 | AB30: =SUM(AB13:AB16) -> 0 | AC30: de 7:00 à 8:00 | AE30: =SUM(C30:AB30) -> 20 | AF30: =IF(AE30=0,0,AF42/AE30) -> 0.75 | AG30: =IF(AE30=0,0,AG42/AE30) -> 0.3 | AH30: =IF(AG42=0,0,AH42/AG42) -> 0.83333333 | AI30: =IF(AE30=0,0,AI42/AE30) -> 0.5 | AJ30: =IF(AE30=0,0,AJ42/AE30) -> 0.35 | AK30: =IF(AE30=0,0,AK42/AE30) -> 0.65
A31: de 7:30 à 8:30 | C31: =SUM(C15:C18) -> 1 | D31: =SUM(D15:D18) -> 3 | E31: =SUM(E15:E18) -> 1 | F31: =SUM(F15:F18) -> 0 | G31: =SUM(G15:G18) -> 2 | H31: =SUM(H15:H18) -> 0 | I31: =SUM(I15:I18) -> 1 | J31: =SUM(J15:J18) -> 0 | L31: =SUM(L15:L18) -> 0 | M31: =SUM(M15:M18) -> 1 | N31: =SUM(N15:N18) -> 1 | O31: =SUM(O15:O18) -> 0 | P31: =SUM(P15:P18) -> 0 | Q31: =SUM(Q15:Q18) -> 1 | R31: =SUM(R15:R18) -> 2 | S31: =SUM(S15:S18) -> 1 | U31: =SUM(U15:U18) -> 0 | V31: =SUM(V15:V18) -> 0 | W31: =SUM(W15:W18) -> 0 | X31: =SUM(X15:X18) -> 1 | Y31: =SUM(Y15:Y18) -> 0 | Z31: =SUM(Z15:Z18) -> 0 | AA31: =SUM(AA15:AA18) -> 0 | AB31: =SUM(AB15:AB18) -> 0 | AC31: de 7:30 à 8:30 | AE31: =SUM(C31:AB31) -> 15 | AF31: =IF(AE31=0,0,AF43/AE31) -> 0.53333333 | AG31: =IF(AE31=0,0,AG43/AE31) -> 0.46666667 | AH31: =IF(AG43=0,0,AH43/AG43) -> 0.71428571 | AI31: =IF(AE31=0,0,AI43/AE31) -> 0.46666667 | AJ31: =IF(AE31=0,0,AJ43/AE31) -> 0.4 | AK31: =IF(AE31=0,0,AK43/AE31) -> 0.53333333
A32: de 8:00 à 9:00 | C32: =SUM(C17:C20) -> 0 | D32: =SUM(D17:D20) -> 2 | E32: =SUM(E17:E20) -> 1 | F32: =SUM(F17:F20) -> 1 | G32: =SUM(G17:G20) -> 0 | H32: =SUM(H17:H20) -> 0 | I32: =SUM(I17:I20) -> 0 | J32: =SUM(J17:J20) -> 0 | L32: =SUM(L17:L20) -> 0 | M32: =SUM(M17:M20) -> 1 | N32: =SUM(N17:N20) -> 1 | O32: =SUM(O17:O20) -> 0 | P32: =SUM(P17:P20) -> 0 | Q32: =SUM(Q17:Q20) -> 1 | R32: =SUM(R17:R20) -> 1 | S32: =SUM(S17:S20) -> 0 | U32: =SUM(U17:U20) -> 0 | V32: =SUM(V17:V20) -> 1 | W32: =SUM(W17:W20) -> 0 | X32: =SUM(X17:X20) -> 1 | Y32: =SUM(Y17:Y20) -> 0 | Z32: =SUM(Z17:Z20) -> 0 | AA32: =SUM(AA17:AA20) -> 0 | AB32: =SUM(AB17:AB20) -> 0 | AC32: de 8:00 à 9:00 | AE32: =SUM(C32:AB32) -> 10 | AF32: =IF(AE32=0,0,AF44/AE32) -> 0.3 | AG32: =IF(AE32=0,0,AG44/AE32) -> 0.5 | AH32: =IF(AG44=0,0,AH44/AG44) -> 0.6 | AI32: =IF(AE32=0,0,AI44/AE32) -> 0.2 | AJ32: =IF(AE32=0,0,AJ44/AE32) -> 0.4 | AK32: =IF(AE32=0,0,AK44/AE32) -> 0.4
A33: de 8:30 à 9:30 | C33: =SUM(C19:C22) -> 0 | D33: =SUM(D19:D22) -> 1 | E33: =SUM(E19:E22) -> 0 | F33: =SUM(F19:F22) -> 1 | G33: =SUM(G19:G22) -> 0 | H33: =SUM(H19:H22) -> 0 | I33: =SUM(I19:I22) -> 0 | J33: =SUM(J19:J22) -> 0 | L33: =SUM(L19:L22) -> 0 | M33: =SUM(M19:M22) -> 0 | N33: =SUM(N19:N22) -> 0 | O33: =SUM(O19:O22) -> 0 | P33: =SUM(P19:P22) -> 0 | Q33: =SUM(Q19:Q22) -> 0 | R33: =SUM(R19:R22) -> 0 | S33: =SUM(S19:S22) -> 0 | U33: =SUM(U19:U22) -> 0 | V33: =SUM(V19:V22) -> 1 | W33: =SUM(W19:W22) -> 0 | X33: =SUM(X19:X22) -> 0 | Y33: =SUM(Y19:Y22) -> 0 | Z33: =SUM(Z19:Z22) -> 0 | AA33: =SUM(AA19:AA22) -> 0 | AB33: =SUM(AB19:AB22) -> 0 | AC33: de 8:30 à 9:30 | AE33: =SUM(C33:AB33) -> 3 | AF33: =IF(AE33=0,0,AF45/AE33) -> 0 | AG33: =IF(AE33=0,0,AG45/AE33) -> 0.33333333 | AH33: =IF(AG45=0,0,AH45/AG45) -> 0 | AI33: =IF(AE33=0,0,AI45/AE33) -> 0 | AJ33: =IF(AE33=0,0,AJ45/AE33) -> 0 | AK33: =IF(AE33=0,0,AK45/AE33) -> 0.66666667
A34: TOTAL | C34: =SUM(C11:C22) -> 7 | D34: =SUM(D11:D22) -> 4 | E34: =SUM(E11:E22) -> 2 | F34: =SUM(F11:F22) -> 1 | G34: =SUM(G11:G22) -> 2 | H34: =SUM(H11:H22) -> 0 | I34: =SUM(I11:I22) -> 1 | J34: =SUM(J11:J22) -> 0 | L34: =SUM(L11:L22) -> 0 | M34: =SUM(M11:M22) -> 1 | N34: =SUM(N11:N22) -> 1 | O34: =SUM(O11:O22) -> 0 | P34: =SUM(P11:P22) -> 1 | Q34: =SUM(Q11:Q22) -> 3 | R34: =SUM(R11:R22) -> 4 | S34: =SUM(S11:S22) -> 1 | U34: =SUM(U11:U22) -> 0 | V34: =SUM(V11:V22) -> 1 | W34: =SUM(W11:W22) -> 0 | X34: =SUM(X11:X22) -> 1 | Y34: =SUM(Y11:Y22) -> 0 | Z34: =SUM(Z11:Z22) -> 0 | AA34: =SUM(AA11:AA22) -> 0 | AB34: =SUM(AB11:AB22) -> 0 | AC34: TOTAL | AE34: =SUM(C34:AB34) -> 30 | AF34: =IF(AE34=0,0,AF46/AE34) -> 0.6 | AG34: =IF(AE34=0,0,AG46/AE34) -> 0.36666667 | AH34: =IF(AG46=0,0,AH46/AG46) -> 0.72727273 | AI34: =IF(AE34=0,0,AI46/AE34) -> 0.4 | AJ34: =IF(AE34=0,0,AJ46/AE34) -> 0.36666667 | AK34: =IF(AE34=0,0,AK46/AE34) -> 0.56666667
A35: =IF($AE$29=MAX($AE$29:$AE$33),A29,IF($AE$30=MAX($AE$29:$AE$33),A30,IF($AE$31=MAX($AE$29:$AE$33),A31,IF($AE$32=MAX($AE$29:$AE$33),A32,A33)))) -> de 7:00 à 8:00 | C35: =IF($AE$29=MAX($AE$29:$AE$33),C29,IF($AE$30=MAX($AE$29:$AE$33),C30,IF($AE$31=MAX($AE$29:$AE$33),C31,IF($AE$32=MAX($AE$29:$AE$33),C32,C33)))) -> 7 | D35: =IF($AE$29=MAX($AE$29:$AE$33),D29,IF($AE$30=MAX($AE$29:$AE$33),D30,IF($AE$31=MAX($AE$29:$AE$33),D31,IF($AE$32=MAX($AE$29:$AE$33),D32,D33)))) -> 2 | E35: =IF($AE$29=MAX($AE$29:$AE$33),E29,IF($AE$30=MAX($AE$29:$AE$33),E30,IF($AE$31=MAX($AE$29:$AE$33),E31,IF($AE$32=MAX($AE$29:$AE$33),E32,E33)))) -> 1 | F35: =IF($AE$29=MAX($AE$29:$AE$33),F29,IF($AE$30=MAX($AE$29:$AE$33),F30,IF($AE$31=MAX($AE$29:$AE$33),F31,IF($AE$32=MAX($AE$29:$AE$33),F32,F33)))) -> 0 | G35: =IF($AE$29=MAX($AE$29:$AE$33),G29,IF($AE$30=MAX($AE$29:$AE$33),G30,IF($AE$31=MAX($AE$29:$AE$33),G31,IF($AE$32=MAX($AE$29:$AE$33),G32,G33)))) -> 2 | H35: =IF($AE$29=MAX($AE$29:$AE$33),H29,IF($AE$30=MAX($AE$29:$AE$33),H30,IF($AE$31=MAX($AE$29:$AE$33),H31,IF($AE$32=MAX($AE$29:$AE$33),H32,H33)))) -> 0 | I35: =IF($AE$29=MAX($AE$29:$AE$33),I29,IF($AE$30=MAX($AE$29:$AE$33),I30,IF($AE$31=MAX($AE$29:$AE$33),I31,IF($AE$32=MAX($AE$29:$AE$33),I32,I33)))) -> 1 | J35: =IF($AE$29=MAX($AE$29:$AE$33),J29,IF($AE$30=MAX($AE$29:$AE$33),J30,IF($AE$31=MAX($AE$29:$AE$33),J31,IF($AE$32=MAX($AE$29:$AE$33),J32,J33)))) -> 0 | L35: =IF($AE$29=MAX($AE$29:$AE$33),L29,IF($AE$30=MAX($AE$29:$AE$33),L30,IF($AE$31=MAX($AE$29:$AE$33),L31,IF($AE$32=MAX($AE$29:$AE$33),L32,L33)))) -> 0 | M35: =IF($AE$29=MAX($AE$29:$AE$33),M29,IF($AE$30=MAX($AE$29:$AE$33),M30,IF($AE$31=MAX($AE$29:$AE$33),M31,IF($AE$32=MAX($AE$29:$AE$33),M32,M33)))) -> 0 | N35: =IF($AE$29=MAX($AE$29:$AE$33),N29,IF($AE$30=MAX($AE$29:$AE$33),N30,IF($AE$31=MAX($AE$29:$AE$33),N31,IF($AE$32=MAX($AE$29:$AE$33),N32,N33)))) -> 0 | O35: =IF($AE$29=MAX($AE$29:$AE$33),O29,IF($AE$30=MAX($AE$29:$AE$33),O30,IF($AE$31=MAX($AE$29:$AE$33),O31,IF($AE$32=MAX($AE$29:$AE$33),O32,O33)))) -> 0 | P35: =IF($AE$29=MAX($AE$29:$AE$33),P29,IF($AE$30=MAX($AE$29:$AE$33),P30,IF($AE$31=MAX($AE$29:$AE$33),P31,IF($AE$32=MAX($AE$29:$AE$33),P32,P33)))) -> 1 | Q35: =IF($AE$29=MAX($AE$29:$AE$33),Q29,IF($AE$30=MAX($AE$29:$AE$33),Q30,IF($AE$31=MAX($AE$29:$AE$33),Q31,IF($AE$32=MAX($AE$29:$AE$33),Q32,Q33)))) -> 2 | R35: =IF($AE$29=MAX($AE$29:$AE$33),R29,IF($AE$30=MAX($AE$29:$AE$33),R30,IF($AE$31=MAX($AE$29:$AE$33),R31,IF($AE$32=MAX($AE$29:$AE$33),R32,R33)))) -> 3 | S35: =IF($AE$29=MAX($AE$29:$AE$33),S29,IF($AE$30=MAX($AE$29:$AE$33),S30,IF($AE$31=MAX($AE$29:$AE$33),S31,IF($AE$32=MAX($AE$29:$AE$33),S32,S33)))) -> 1 | U35: =IF($AE$29=MAX($AE$29:$AE$33),U29,IF($AE$30=MAX($AE$29:$AE$33),U30,IF($AE$31=MAX($AE$29:$AE$33),U31,IF($AE$32=MAX($AE$29:$AE$33),U32,U33)))) -> 0 | V35: =IF($AE$29=MAX($AE$29:$AE$33),V29,IF($AE$30=MAX($AE$29:$AE$33),V30,IF($AE$31=MAX($AE$29:$AE$33),V31,IF($AE$32=MAX($AE$29:$AE$33),V32,V33)))) -> 0 | W35: =IF($AE$29=MAX($AE$29:$AE$33),W29,IF($AE$30=MAX($AE$29:$AE$33),W30,IF($AE$31=MAX($AE$29:$AE$33),W31,IF($AE$32=MAX($AE$29:$AE$33),W32,W33)))) -> 0 | X35: =IF($AE$29=MAX($AE$29:$AE$33),X29,IF($AE$30=MAX($AE$29:$AE$33),X30,IF($AE$31=MAX($AE$29:$AE$33),X31,IF($AE$32=MAX($AE$29:$AE$33),X32,X33)))) -> 0 | Y35: =IF($AE$29=MAX($AE$29:$AE$33),Y29,IF($AE$30=MAX($AE$29:$AE$33),Y30,IF($AE$31=MAX($AE$29:$AE$33),Y31,IF($AE$32=MAX($AE$29:$AE$33),Y32,Y33)))) -> 0 | Z35: =IF($AE$29=MAX($AE$29:$AE$33),Z29,IF($AE$30=MAX($AE$29:$AE$33),Z30,IF($AE$31=MAX($AE$29:$AE$33),Z31,IF($AE$32=MAX($AE$29:$AE$33),Z32,Z33)))) -> 0 | AA35: =IF($AE$29=MAX($AE$29:$AE$33),AA29,IF($AE$30=MAX($AE$29:$AE$33),AA30,IF($AE$31=MAX($AE$29:$AE$33),AA31,IF($AE$32=MAX($AE$29:$AE$33),AA32,AA33)))) -> 0 | AB35: =IF($AE$29=MAX($AE$29:$AE$33),AB29,IF($AE$30=MAX($AE$29:$AE$33),AB30,IF($AE$31=MAX($AE$29:$AE$33),AB31,IF($AE$32=MAX($AE$29:$AE$33),AB32,AB33)))) -> 0 | AC35: =A35 -> de 7:00 à 8:00 | AE35: =SUM(C35:AB35) -> 20 | AF35: =IF(AE35=0,0,AF47/AE35) -> 0.75 | AG35: =IF(AE35=0,0,AG47/AE35) -> 0.3 | AH35: =IF(AG47=0,0,AH47/AG47) -> 0.83333333 | AI35: =IF(AE35=0,0,AI47/AE35) -> 0.5 | AJ35: =IF(AE35=0,0,AJ47/AE35) -> 0.35 | AK35: =IF(AE35=0,0,AK47/AE35) -> 0.65
AF37: Nombre de VAE dans le total | AG37: Nombre de femmes dans le total | AH37: Nombre de VAE chez les femmes | AI37: Cycles en direction d'Annemasse-Genève | AJ37: Cycles en provenance de Reignier | AK37: Cycles en provenance d'Esery
AF41: =(C29+E29+G29+I29+L29+N29+P29+R29+U29+W29+Y29+AA29) -> 10 | AG41: =(E29+F29+I29+J29+N29+O29+R29+S29+W29+X29+AA29+AB29) -> 3 | AH41: =(E29+I29+N29+R29+W29+AA29) -> 3 | AI41: =SUM(G29:J29,P29:S29) -> 5 | AJ41: =SUM(L29:S29) -> 5 | AK41: =SUM(C29:J29) -> 7
AF42: =(C30+E30+G30+I30+L30+N30+P30+R30+U30+W30+Y30+AA30) -> 15 | AG42: =(E30+F30+I30+J30+N30+O30+R30+S30+W30+X30+AA30+AB30) -> 6 | AH42: =(E30+I30+N30+R30+W30+AA30) -> 5 | AI42: =SUM(G30:J30,P30:S30) -> 10 | AJ42: =SUM(L30:S30) -> 7 | AK42: =SUM(C30:J30) -> 13
AF43: =(C31+E31+G31+I31+L31+N31+P31+R31+U31+W31+Y31+AA31) -> 8 | AG43: =(E31+F31+I31+J31+N31+O31+R31+S31+W31+X31+AA31+AB31) -> 7 | AH43: =(E31+I31+N31+R31+W31+AA31) -> 5 | AI43: =SUM(G31:J31,P31:S31) -> 7 | AJ43: =SUM(L31:S31) -> 6 | AK43: =SUM(C31:J31) -> 8
AF44: =(C32+E32+G32+I32+L32+N32+P32+R32+U32+W32+Y32+AA32) -> 3 | AG44: =(E32+F32+I32+J32+N32+O32+R32+S32+W32+X32+AA32+AB32) -> 5 | AH44: =(E32+I32+N32+R32+W32+AA32) -> 3 | AI44: =SUM(G32:J32,P32:S32) -> 2 | AJ44: =SUM(L32:S32) -> 4 | AK44: =SUM(C32:J32) -> 4
AF45: =(C33+E33+G33+I33+L33+N33+P33+R33+U33+W33+Y33+AA33) -> 0 | AG45: =(E33+F33+I33+J33+N33+O33+R33+S33+W33+X33+AA33+AB33) -> 1 | AH45: =(E33+I33+N33+R33+W33+AA33) -> 0 | AI45: =SUM(G33:J33,P33:S33) -> 0 | AJ45: =SUM(L33:S33) -> 0 | AK45: =SUM(C33:J33) -> 2
AF46: =(C34+E34+G34+I34+L34+N34+P34+R34+U34+W34+Y34+AA34) -> 18 | AG46: =(E34+F34+I34+J34+N34+O34+R34+S34+W34+X34+AA34+AB34) -> 11 | AH46: =(E34+I34+N34+R34+W34+AA34) -> 8 | AI46: =SUM(G34:J34,P34:S34) -> 12 | AJ46: =SUM(L34:S34) -> 11 | AK46: =SUM(C34:J34) -> 17
AF47: =(C35+E35+G35+I35+L35+N35+P35+R35+U35+W35+Y35+AA35) -> 15 | AG47: =(E35+F35+I35+J35+N35+O35+R35+S35+W35+X35+AA35+AB35) -> 6 | AH47: =(E35+I35+N35+R35+W35+AA35) -> 5 | AI47: =SUM(G35:J35,P35:S35) -> 10 | AJ47: =SUM(L35:S35) -> 7 | AK47: =SUM(C35:J35) -> 13

Sheet RE_ex-gendarmerie
A1: Lieu : | B1: REIGNIER_Giratoire de l'ancienne gendarmerie | M1: Date : | N1: mardi 6 juin 2023
A2: Nom des personnes participant au comptage : | G2: Philippe LEMOINE
A3: Météo : | C3: Excellente (grand soleil)
A5: Remarques : | C5: 3 cyclistes sur le trottoir >> symptomatiques du manque d’infrastructures 6 trottinettes, dont 5 en dir. de Pers-Jussy (sans doute vers la gare) | P5: Méthodologie : | R5: Pour chaque intervalle de temps, marquer une seule croix par personne comptée. Si c'est enfant, remplacer la croix par E, une trottinette T, un piéton P, etc.
C7: Depuis 'Annemasse - Genève' | P7: Depuis 'Carrefour - Bersat'
C8: vers 'Carrefour - Bersat' | G8: vers 'Pers-Jussy' | K8: vers 'Esery - Méran' | P8: vers 'Pers-Jussy' | T8: vers 'Esery - Méran' | X8: vers 'Annemasse - Genève'
C9: H | E9: F | G9: H | I9: F | K9: H | M9: F | P9: H | R9: F | T9: H | V9: F | X9: H | Z9: F
A10: Heure | B10: Minute | C10: VAE | D10: vélo | E10: VAE | F10: vélo | G10: VAE | H10: vélo | I10: VAE | J10: vélo | K10: VAE | L10: vélo | M10: VAE | N10: vélo | P10: VAE | Q10: vélo | R10: VAE | S10: vélo | T10: VAE | U10: vélo | V10: VAE | W10: vélo | X10: VAE | Y10: vélo | Z10: VAE | AA10: vélo
A11: 6 | B11: 30 – 44'59
B12: 45 – 59'59 | H12: 1 | I12: 2 | K12: 1 | M12: 1 | P12: 2 | R12: 1
A13: 7 | B13: 00 – 14'59 | I13: 1
B14: 15 – 29'59 | J14: 1 | U14: 1 | W14: 1 | Y14: 1
B15: 30 – 44'59 | I15: 1 | AA15: 1
B16: 45 – 59'59 | X16: 1
A17: 8 | B17: 00 – 14'59 | M17: 1 | Q17: 1 | U17: 1
B18: 15 – 29'59 | R18: 1 | U18: 1
B19: 30 – 44'59 | Z19: 1
B20: 45 – 59'59
A21: 9 | B21: 00 – 14'59
B22: 15 – 29'59
A24: Remarques : | C24: 3 cyclistes sur le trottoir >> symptomatiques du manque d’infrastructures 1 trottinette en dir. de Pers-Jussy (sans doute vers la gare)
C26: Depuis 'Pers-Jussy' | P26: Depuis 'Esery - Méran'
C27: vers 'Esery - Méran' | G27: vers 'Annemasse - Genève' | K27: vers 'Carrefour - Bersat' | P27: vers 'Annemasse - Genève' | T27: vers 'Carrefour - Bersat' | X27: vers 'Pers-Jussy'
C28: H | E28: F | G28: H | I28: F | K28: H | M28: F | P28: H | R28: F | T28: H | V28: F | X28: H | Z28: F
A29: Heure | B29: Minute | C29: VAE | D29: vélo | E29: VAE | F29: vélo | G29: VAE | H29: vélo | I29: VAE | J29: vélo | K29: VAE | L29: vélo | M29: VAE | N29: vélo | P29: VAE | Q29: vélo | R29: VAE | S29: vélo | T29: VAE | U29: vélo | V29: VAE | W29: vélo | X29: VAE | Y29: vélo | Z29: VAE | AA29: vélo
A30: 6 | B30: 30 – 44'59
B31: 45 – 59'59 | D31: 1
A32: 7 | B32: 00 – 14'59 | C32: 1 | D32: 1 | I32: 1 | U32: 1
B33: 15 – 29'59 | C33: 2 | E33: 1 | Y33: 3 | Z33: 1
B34: 30 – 44'59 | C34: 1 | F34: 1 | G34: 1
B35: 45 – 59'59 | D35: 1 | F35: 1 | H35: 1 | I35: 1 | R35: 1
A36: 8 | B36: 00 – 14'59 | G36: 1 | H36: 1 | Q36: 1 | U36: 2 | Y36: 1
B37: 15 – 29'59 | U37: 2 | X37: 1 | Z37: 1
B38: 30 – 44'59 | D38: 1 | I38: 1 | N38: 1
B39: 45 – 59'59 | G39: 1 | I39: 1 | U39: 1
A40: 9 | B40: 00 – 14'59
B41: 15 – 29'59
C44: =C7 -> Depuis 'Annemasse - Genève' | P44: =P7 -> Depuis 'Carrefour - Bersat' | AD44: TOTAL | AE44: Part des VAE dans le total | AF44: Part des femmes dans le total | AG44: Part des VAE chez les femmes | AH44: Part en direction d'Annemasse-Genève | AI44: Remarques
C45: =C8 -> vers 'Carrefour - Bersat' | G45: =G8 -> vers 'Pers-Jussy' | K45: =K8 -> vers 'Esery - Méran' | P45: =P8 -> vers 'Pers-Jussy' | T45: =T8 -> vers 'Esery - Méran' | X45: =X8 -> vers 'Annemasse - Genève'
C46: H | E46: F | G46: H | I46: F | K46: H | M46: F | P46: H | R46: F | T46: H | V46: F | X46: H | Z46: F
...

Sheet RE_Eglise
A1: Lieu : | B1: REIGNIER_Giratoire des Jonquilles (devant l'église) | M1: Date : | N1: jeudi 8 juin 2023
A2: Nom des personnes participant au comptage : | G2: Sylvain BEAUD
A3: Météo : | C3: Excellente (grand soleil)
A5: Remarques : | C5: Compté que de 7h00 à 8h00 >> extrapolé entre 8h00 et 9h00 sur la base des comptages 2022 4 trottinettes entre 8h et 9h | P5: Méthodologie : | R5: Pour chaque intervalle de temps, marquer une seule croix par personne comptée. Si c'est enfant, remplacer la croix par E, une trottinette T, un piéton P, etc.
C7: Depuis 'Annemasse - Genève' | P7: Depuis 'L'Eculaz'
C8: vers 'Reignier-centre' | G8: vers 'Rue des Ecoles' | K8: vers 'L'Eculaz' | P8: vers 'Reignier-centre' | T8: vers 'Rue des Ecoles' | X8: vers 'Annemasse - Genève'
C9: H | E9: F | G9: H | I9: F | K9: H | M9: F | P9: H | R9: F | T9: H | V9: F | X9: H | Z9: F
A10: Heure | B10: Minute | C10: VAE | D10: vélo | E10: VAE | F10: vélo | G10: VAE | H10: vélo | I10: VAE | J10: vélo | K10: VAE | L10: vélo | M10: VAE | N10: vélo | P10: VAE | Q10: vélo | R10: VAE | S10: vélo | T10: VAE | U10: vélo | V10: VAE | W10: vélo | X10: VAE | Y10: vélo | Z10: VAE | AA10: vélo
A11: 6 | B11: 30 – 44'59
B12: 45 – 59'59
A13: 7 | B13: 00 – 14'59 | AB13: =SUM(C13:AA13) -> 0 | AC13: =SUM(AB13:AB16) -> 8
B14: 15 – 29'59 | D14: 1 | AB14: =SUM(C14:AA14) -> 1
B15: 30 – 44'59 | X15: 1 | AB15: =SUM(C15:AA15) -> 1
B16: 45 – 59'59 | F16: 1 | Q16: 2 | R16: 1 | W16: 2 | AB16: =SUM(C16:AA16) -> 6
A17: 8 | B17: 00 – 14'59 | AB17: =SUM(C17:AA17) -> 0 | AC17: =SUM(AB17:AB20) -> 8
B18: 15 – 29'59 | Q18: 2 | U18: 2 | AB18: =SUM(C18:AA18) -> 4
B19: 30 – 44'59 | V19: 2 | W19: 2 | AB19: =SUM(C19:AA19) -> 4
B20: 45 – 59'59 | AB20: =SUM(C20:AA20) -> 0
A21: 9 | B21: 00 – 14'59
B22: 15 – 29'59
A24: Remarques : | C24: Compté que de 7h00 à 8h00 >> extrapolé entre 8h00 et 9h00 sur la base des comptages 2022 1 trottinette entre 8h et 9h
C26: Depuis 'Reignier-centre' | P26: Depuis 'Reignier - Rue des Ecoles'
C27: vers 'Annemasse - Genève' | G27: vers 'Rue des Ecoles' | K27: vers 'L'Eculaz' | P27: vers 'Reignier-centre' | T27: vers 'L'Eculaz' | X27: vers 'Annemasse - Genève'
C28: H | E28: F | G28: H | I28: F | K28: H | M28: F | P28: H | R28: F | T28: H | V28: F | X28: H | Z28: F
A29: Heure | B29: Minute | C29: VAE | D29: vélo | E29: VAE | F29: vélo | G29: VAE | H29: vélo | I29: VAE | J29: vélo | K29: VAE | L29: vélo | M29: VAE | N29: vélo | P29: VAE | Q29: vélo | R29: VAE | S29: vélo | T29: VAE | U29: vélo | V29: VAE | W29: vélo | X29: VAE | Y29: vélo | Z29: VAE | AA29: vélo
A30: 6 | B30: 30 – 44'59
B31: 45 – 59'59
A32: 7 | B32: 00 – 14'59 | D32: 2 | H32: 1 | AB32: =SUM(C32:AA32) -> 3 | AC32: =SUM(AB32:AB35) -> 15
B33: 15 – 29'59 | C33: 1 | L33: 1 | Y33: 1 | AB33: =SUM(C33:AA33) -> 3
B34: 30 – 44'59 | AB34: =SUM(C34:AA34) -> 0
B35: 45 – 59'59 | D35: 5 | E35: 1 | J35: 2 | M35: 1 | AB35: =SUM(C35:AA35) -> 9
A36: 8 | B36: 00 – 14'59 | H36: 2 | AB36: =SUM(C36:AA36) -> 2 | AC36: =SUM(AB36:AB39) -> 18
B37: 15 – 29'59 | E37: 2 | H37: 1 | L37: 2 | T37: 2 | U37: 2 | V37: 1 | AB37: =SUM(C37:AA37) -> 10
B38: 30 – 44'59 | K38: 2 | M38: 1 | AB38: =SUM(C38:AA38) -> 3
B39: 45 – 59'59 | C39: 1 | E39: 1 | U39: 1 | AB39: =SUM(C39:AA39) -> 3
A40: 9 | B40: 00 – 14'59
B41: 15 – 29'59
C44: =C7 -> Depuis 'Annemasse - Genève' | P44: =P7 -> Depuis 'L'Eculaz' | AD44: TOTAL | AE44: Part des VAE dans le total | AF44: Part des femmes dans le total | AG44: Part des VAE chez les femmes | AH44: Part en direction d'Annemasse-Genève | AI44: Remarques
C45: =C8 -> vers 'Reignier-centre' | G45: =G8 -> vers 'Rue des Ecoles' | K45: =K8 -> vers 'L'Eculaz' | P45: =P8 -> vers 'Reignier-centre' | T45: =T8 -> vers 'Rue des Ecoles' | X45: =X8 -> vers 'Annemasse - Genève'
C46: H | E46: F | G46: H | I46: F | K46: H | M46: F | P46: H | R46: F | T46: H | V46: F | X46: H | Z46: F
...

Sheet RE_Foron
A1: Lieu : | B1: REIGNIER BAS_Giratoire D2 / D202 (vers le Foron) | N1: Date : | O1: mardi 6 juin 2023
A2: Nom des personnes participant au comptage :
A3: Météo : | C3: Excellente (grand soleil)
A5: Remarques : | C5: Un groupe de 6 cyclistes vers 8h45, sinon RAS Sur 26 cyclistes comptés, 15 vont en dir. d'Annemasse, 3 en dir. de Reignier et 8 en dir. d'Arthaz | P5: Méthodologie : | R5: Pour chaque intervalle de temps, marquer une seule croix par personne comptée. Si c'est enfant, remplacer la croix par E, une trottinette T, un piéton P, etc.
C7: Depuis 'Arthaz' | L7: Depuis 'Annemasse' | U7: Depuis 'Reignier'
C8: vers 'Reignier' | G8: vers 'Annemasse' | L8: vers 'Reignier' | P8: vers 'Arthaz' | U8: vers 'Arthaz' | Y8: vers 'Annemasse'
C9: H | E9: F | G9: H | I9: F | L9: H | N9: F | P9: H | R9: F | U9: H | W9: F | Y9: H | AA9: F
A10: Heure | B10: Minute | C10: VAE | D10: vélo | E10: VAE | F10: vélo | G10: VAE | H10: vélo | I10: VAE | J10: vélo | L10: VAE | M10: vélo | N10: VAE | O10: vélo | P10: VAE | Q10: vélo | R10: VAE | S10: vélo | U10: VAE | V10: vélo | W10: VAE | X10: vélo | Y10: VAE | Z10: vélo | AA10: VAE | AB10: vélo
A11: 6 | B11: 30 – 44'59
B12: 45 – 59'59
A13: 7 | B13: 00 – 14'59 | N13: 1 | V13: 2
B14: 15 – 29'59 | C14: 1 | E14: 1 | W14: 1 | Y14: 1 | Z14: 3 | AA14: 1
B15: 30 – 44'59
B16: 45 – 59'59 | V16: 1 | Y16: 1
A17: 8 | B17: 00 – 14'59 | U17: 1 | V17: 1 | Y17: 1
B18: 15 – 29'59 | U18: 1 | Z18: 1
B19: 30 – 44'59
B20: 45 – 59'59 | G20: 6 | H20: 1 | V20: 1
A21: 9 | B21: 00 – 14'59
B22: 15 – 29'59
C25: =C7 -> Depuis 'Arthaz' | L25: =L7 -> Depuis 'Annemasse' | U25: =U7 -> Depuis 'Reignier' | AE25: TOTAL | AF25: Part des VAE dans le total | AG25: Part des femmes dans le total | AH25: Part des VAE chez les femmes | AI25: Part en direction d'Annemasse-Genève | AJ25: Cycles en provenance de Reignier | AK25: Cycles venant du giratoire des Jonquilles | AL25: Différence de cycles entre ces deux carrefour : >> descendus au chemin raide sous le cimetière, >> parti en vélo depuis le parking du cimetière ?
C26: =C8 -> vers 'Reignier' | G26: =G8 -> vers 'Annemasse' | L26: =L8 -> vers 'Reignier' | P26: =P8 -> vers 'Arthaz' | U26: =U8 -> vers 'Arthaz' | Y26: =Y8 -> vers 'Annemasse'
C27: H | E27: F | G27: H | I27: F | L27: H | N27: F | P27: H | R27: F | U27: H | W27: F | Y27: H | AA27: F
A28: Période | C28: VAE | D28: vélo | E28: VAE | F28: vélo | G28: VAE | H28: vélo | I28: VAE | J28: vélo | L28: VAE | M28: vélo | N28: VAE | O28: vélo | P28: VAE | Q28: vélo | R28: VAE | S28: vélo | U28: VAE | V28: vélo | W28: VAE | X28: vélo | Y28: VAE | Z28: vélo | AA28: VAE | AB28: vélo | AC28: Période
A29: de 6:30 à 7:30 | C29: =SUM(C11:C14) -> 1 | D29: =SUM(D11:D14) -> 0 | E29: =SUM(E11:E14) -> 1 | F29: =SUM(F11:F14) -> 0 | G29: =SUM(G11:G14) -> 0 | H29: =SUM(H11:H14) -> 0 | I29: =SUM(I11:I14) -> 0 | J29: =SUM(J11:J14) -> 0 | L29: =SUM(L11:L14) -> 0 | M29: =SUM(M11:M14) -> 0 | N29: =SUM(N11:N14) -> 1 | O29: =SUM(O11:O14) -> 0 | P29: =SUM(P11:P14) -> 0 | Q29: =SUM(Q11:Q14) -> 0 | R29: =SUM(R11:R14) -> 0 | S29: =SUM(S11:S14) -> 0 | U29: =SUM(U11:U14) -> 0 | V29: =SUM(V11:V14) -> 2 | W29: =SUM(W11:W14) -> 1 | X29: =SUM(X11:X14) -> 0 | Y29: =SUM(Y11:Y14) -> 1 | Z29: =SUM(Z11:Z14) -> 3 | AA29: =SUM(AA11:AA14) -> 1 | AB29: =SUM(AB11:AB14) -> 0 | AC29: de 6:30 à 7:30 | AE29: =SUM(C29:AB29) -> 11 | AF29: =IF(AE29=0,0,AF41/AE29) -> 0.54545455 | AG29: =IF(AE29=0,0,AG41/AE29) -> 0.36363636 | AH29: =IF(AG41=0,0,AH41/AG41) -> 1 | AI29: =IF(AE29=0,0,AI41/AE29) -> 0.45454545 | AJ29: =SUM(U29:AB29) -> 8 | AK29: =RE_Eglise!AH60 -> 4 | AL29: =AK29-AJ29 -> -4
A30: de 7:00 à 8:00 | C30: =SUM(C13:C16) -> 1 | D30: =SUM(D13:D16) -> 0 | E30: =SUM(E13:E16) -> 1 | F30: =SUM(F13:F16) -> 0 | G30: =SUM(G13:G16) -> 0 | H30: =SUM(H13:H16) -> 0 | I30: =SUM(I13:I16) -> 0 | J30: =SUM(J13:J16) -> 0 | L30: =SUM(L13:L16) -> 0 | M30: =SUM(M13:M16) -> 0 | N30: =SUM(N13:N16) -> 1 | O30: =SUM(O13:O16) -> 0 | P30: =SUM(P13:P16) -> 0 | Q30: =SUM(Q13:Q16) -> 0 | R30: =SUM(R13:R16) -> 0 | S30: =SUM(S13:S16) -> 0 | U30: =SUM(U13:U16) -> 0 | V30: =SUM(V13:V16) -> 3 | W30: =SUM(W13:W16) -> 1 | X30: =SUM(X13:X16) -> 0 | Y30: =SUM(Y13:Y16) -> 2 | Z30: =SUM(Z13:Z16) -> 3 | AA30: =SUM(AA13:AA16) -> 1 | AB30: =SUM(AB13:AB16) -> 0 | AC30: de 7:00 à 8:00 | AE30: =SUM(C30:AB30) -> 13 | AF30: =IF(AE30=0,0,AF42/AE30) -> 0.53846154 | AG30: =IF(AE30=0,0,AG42/AE30) -> 0.30769231 | AH30: =IF(AG42=0,0,AH42/AG42) -> 1 | AI30: =IF(AE30=0,0,AI42/AE30) -> 0.46153846 | AJ30: =SUM(U30:AB30) -> 10 | AK30: =RE_Eglise!AH61 -> 11 | AL30: =AK30-AJ30 -> 1
A31: de 7:30 à 8:30 | C31: =SUM(C15:C18) -> 0 | D31: =SUM(D15:D18) -> 0 | E31: =SUM(E15:E18) -> 0 | F31: =SUM(F15:F18) -> 0 | G31: =SUM(G15:G18) -> 0 | H31: =SUM(H15:H18) -> 0 | I31: =SUM(I15:I18) -> 0 | J31: =SUM(J15:J18) -> 0 | L31: =SUM(L15:L18) -> 0 | M31: =SUM(M15:M18) -> 0 | N31: =SUM(N15:N18) -> 0 | O31: =SUM(O15:O18) -> 0 | P31: =SUM(P15:P18) -> 0 | Q31: =SUM(Q15:Q18) -> 0 | R31: =SUM(R15:R18) -> 0 | S31: =SUM(S15:S18) -> 0 | U31: =SUM(U15:U18) -> 2 | V31: =SUM(V15:V18) -> 2 | W31: =SUM(W15:W18) -> 0 | X31: =SUM(X15:X18) -> 0 | Y31: =SUM(Y15:Y18) -> 2 | Z31: =SUM(Z15:Z18) -> 1 | AA31: =SUM(AA15:AA18) -> 0 | AB31: =SUM(AB15:AB18) -> 0 | AC31: de 7:30 à 8:30 | AE31: =SUM(C31:AB31) -> 7 | AF31: =IF(AE31=0,0,AF43/AE31) -> 0.57142857 | AG31: =IF(AE31=0,0,AG43/AE31) -> 0 | AH31: =IF(AG43=0,0,AH43/AG43) -> 0 | AI31: =IF(AE31=0,0,AI43/AE31) -> 0.42857143 | AJ31: =SUM(U31:AB31) -> 7 | AK31: =RE_Eglise!AH62 -> 9 | AL31: =AK31-AJ31 -> 2
A32: de 8:00 à 9:00 | C32: =SUM(C17:C20) -> 0 | D32: =SUM(D17:D20) -> 0 | E32: =SUM(E17:E20) -> 0 | F32: =SUM(F17:F20) -> 0 | G32: =SUM(G17:G20) -> 6 | H32: =SUM(H17:H20) -> 1 | I32: =SUM(I17:I20) -> 0 | J32: =SUM(J17:J20) -> 0 | L32: =SUM(L17:L20) -> 0 | M32: =SUM(M17:M20) -> 0 | N32: =SUM(N17:N20) -> 0 | O32: =SUM(O17:O20) -> 0 | P32: =SUM(P17:P20) -> 0 | Q32: =SUM(Q17:Q20) -> 0 | R32: =SUM(R17:R20) -> 0 | S32: =SUM(S17:S20) -> 0 | U32: =SUM(U17:U20) -> 2 | V32: =SUM(V17:V20) -> 2 | W32: =SUM(W17:W20) -> 0 | X32: =SUM(X17:X20) -> 0 | Y32: =SUM(Y17:Y20) -> 1 | Z32: =SUM(Z17:Z20) -> 1 | AA32: =SUM(AA17:AA20) -> 0 | AB32: =SUM(AB17:AB20) -> 0 | AC32: de 8:00 à 9:00 | AE32: =SUM(C32:AB32) -> 13 | AF32: =IF(AE32=0,0,AF44/AE32) -> 0.69230769 | AG32: =IF(AE32=0,0,AG44/AE32) -> 0 | AH32: =IF(AG44=0,0,AH44/AG44) -> 0 | AI32: =IF(AE32=0,0,AI44/AE32) -> 0.69230769 | AJ32: =SUM(U32:AB32) -> 6 | AK32: =RE_Eglise!AH63 -> 4 | AL32: =AK32-AJ32 -> -2
A33: de 8:30 à 9:30 | C33: =SUM(C19:C22) -> 0 | D33: =SUM(D19:D22) -> 0 | E33: =SUM(E19:E22) -> 0 | F33: =SUM(F19:F22) -> 0 | G33: =SUM(G19:G22) -> 6 | H33: =SUM(H19:H22) -> 1 | I33: =SUM(I19:I22) -> 0 | J33: =SUM(J19:J22) -> 0 | L33: =SUM(L19:L22) -> 0 | M33: =SUM(M19:M22) -> 0 | N33: =SUM(N19:N22) -> 0 | O33: =SUM(O19:O22) -> 0 | P33: =SUM(P19:P22) -> 0 | Q33: =SUM(Q19:Q22) -> 0 | R33: =SUM(R19:R22) -> 0 | S33: =SUM(S19:S22) -> 0 | U33: =SUM(U19:U22) -> 0 | V33: =SUM(V19:V22) -> 1 | W33: =SUM(W19:W22) -> 0 | X33: =SUM(X19:X22) -> 0 | Y33: =SUM(Y19:Y22) -> 0 | Z33: =SUM(Z19:Z22) -> 0 | AA33: =SUM(AA19:AA22) -> 0 | AB33: =SUM(AB19:AB22) -> 0 | AC33: de 8:30 à 9:30 | AE33: =SUM(C33:AB33) -> 8 | AF33: =IF(AE33=0,0,AF45/AE33) -> 0.75 | AG33: =IF(AE33=0,0,AG45/AE33) -> 0 | AH33: =IF(AG45=0,0,AH45/AG45) -> 0 | AI33: =IF(AE33=0,0,AI45/AE33) -> 0.875 | AJ33: =SUM(U33:AB33) -> 1 | AK33: =RE_Eglise!AH64 -> 2 | AL33: =AK33-AJ33 -> 1
A34: TOTAL | C34: =SUM(C11:C22) -> 1 | D34: =SUM(D11:D22) -> 0 | E34: =SUM(E11:E22) -> 1 | F34: =SUM(F11:F22) -> 0 | G34: =SUM(G11:G22) -> 6 | H34: =SUM(H11:H22) -> 1 | I34: =SUM(I11:I22) -> 0 | J34: =SUM(J11:J22) -> 0 | L34: =SUM(L11:L22) -> 0 | M34: =SUM(M11:M22) -> 0 | N34: =SUM(N11:N22) -> 1 | O34: =SUM(O11:O22) -> 0 | P34: =SUM(P11:P22) -> 0 | Q34: =SUM(Q11:Q22) -> 0 | R34: =SUM(R11:R22) -> 0 | S34: =SUM(S11:S22) -> 0 | U34: =SUM(U11:U22) -> 2 | V34: =SUM(V11:V22) -> 5 | W34: =SUM(W11:W22) -> 1 | X34: =SUM(X11:X22) -> 0 | Y34: =SUM(Y11:Y22) -> 3 | Z34: =SUM(Z11:Z22) -> 4 | AA34: =SUM(AA11:AA22) -> 1 | AB34: =SUM(AB11:AB22) -> 0 | AC34: TOTAL | AE34: =SUM(C34:AB34) -> 26 | AF34: =IF(AE34=0,0,AF46/AE34) -> 0.61538462 | AG34: =IF(AE34=0,0,AG46/AE34) -> 0.15384615 | AH34: =IF(AG46=0,0,AH46/AG46) -> 1 | AI34: =IF(AE34=0,0,AI46/AE34) -> 0.57692308 | AJ34: =SUM(U34:AB34) -> 16 | AK34: =RE_Eglise!AH65 -> 15 | AL34: =AK34-AJ34 -> -1
A35: =IF($AE$29=MAX($AE$29:$AE$33),A29,IF($AE$30=MAX($AE$29:$AE$33),A30,IF($AE$31=MAX($AE$29:$AE$33),A31,IF($AE$32=MAX($AE$29:$AE$33),A32,A33)))) -> de 7:00 à 8:00 | C35: =IF($AE$29=MAX($AE$29:$AE$33),C29,IF($AE$30=MAX($AE$29:$AE$33),C30,IF($AE$31=MAX($AE$29:$AE$33),C31,IF($AE$32=MAX($AE$29:$AE$33),C32,C33)))) -> 1 | D35: =IF($AE$29=MAX($AE$29:$AE$33),D29,IF($AE$30=MAX($AE$29:$AE$33),D30,IF($AE$31=MAX($AE$29:$AE$33),D31,IF($AE$32=MAX($AE$29:$AE$33),D32,D33)))) -> 0 | E35: =IF($AE$29=MAX($AE$29:$AE$33),E29,IF($AE$30=MAX($AE$29:$AE$33),E30,IF($AE$31=MAX($AE$29:$AE$33),E31,IF($AE$32=MAX($AE$29:$AE$33),E32,E33)))) -> 1 | F35: =IF($AE$29=MAX($AE$29:$AE$33),F29,IF($AE$30=MAX($AE$29:$AE$33),F30,IF($AE$31=MAX($AE$29:$AE$33),F31,IF($AE$32=MAX($AE$29:$AE$33),F32,F33)))) -> 0 | G35: =IF($AE$29=MAX($AE$29:$AE$33),G29,IF($AE$30=MAX($AE$29:$AE$33),G30,IF($AE$31=MAX($AE$29:$AE$33),G31,IF($AE$32=MAX($AE$29:$AE$33),G32,G33)))) -> 0 | H35: =IF($AE$29=MAX($AE$29:$AE$33),H29,IF($AE$30=MAX($AE$29:$AE$33),H30,IF($AE$31=MAX($AE$29:$AE$33),H31,IF($AE$32=MAX($AE$29:$AE$33),H32,H33)))) -> 0 | I35: =IF($AE$29=MAX($AE$29:$AE$33),I29,IF($AE$30=MAX($AE$29:$AE$33),I30,IF($AE$31=MAX($AE$29:$AE$33),I31,IF($AE$32=MAX($AE$29:$AE$33),I32,I33)))) -> 0 | J35: =IF($AE$29=MAX($AE$29:$AE$33),J29,IF($AE$30=MAX($AE$29:$AE$33),J30,IF($AE$31=MAX($AE$29:$AE$33),J31,IF($AE$32=MAX($AE$29:$AE$33),J32,J33)))) -> 0 | L35: =IF($AE$29=MAX($AE$29:$AE$33),L29,IF($AE$30=MAX($AE$29:$AE$33),L30,IF($AE$31=MAX($AE$29:$AE$33),L31,IF($AE$32=MAX($AE$29:$AE$33),L32,L33)))) -> 0 | M35: =IF($AE$29=MAX($AE$29:$AE$33),M29,IF($AE$30=MAX($AE$29:$AE$33),M30,IF($AE$31=MAX($AE$29:$AE$33),M31,IF($AE$32=MAX($AE$29:$AE$33),M32,M33)))) -> 0 | N35: =IF($AE$29=MAX($AE$29:$AE$33),N29,IF($AE$30=MAX($AE$29:$AE$33),N30,IF($AE$31=MAX($AE$29:$AE$33),N31,IF($AE$32=MAX($AE$29:$AE$33),N32,N33)))) -> 1 | O35: =IF($AE$29=MAX($AE$29:$AE$33),O29,IF($AE$30=MAX($AE$29:$AE$33),O30,IF($AE$31=MAX($AE$29:$AE$33),O31,IF($AE$32=MAX($AE$29:$AE$33),O32,O33)))) -> 0 | P35: =IF($AE$29=MAX($AE$29:$AE$33),P29,IF($AE$30=MAX($AE$29:$AE$33),P30,IF($AE$31=MAX($AE$29:$AE$33),P31,IF($AE$32=MAX($AE$29:$AE$33),P32,P33)))) -> 0 | Q35: =IF($AE$29=MAX($AE$29:$AE$33),Q29,IF($AE$30=MAX($AE$29:$AE$33),Q30,IF($AE$31=MAX($AE$29:$AE$33),Q31,IF($AE$32=MAX($AE$29:$AE$33),Q32,Q33)))) -> 0 | R35: =IF($AE$29=MAX($AE$29:$AE$33),R29,IF($AE$30=MAX($AE$29:$AE$33),R30,IF($AE$31=MAX($AE$29:$AE$33),R31,IF($AE$32=MAX($AE$29:$AE$33),R32,R33)))) -> 0 | S35: =IF($AE$29=MAX($AE$29:$AE$33),S29,IF($AE$30=MAX($AE$29:$AE$33),S30,IF($AE$31=MAX($AE$29:$AE$33),S31,IF($AE$32=MAX($AE$29:$AE$33),S32,S33)))) -> 0 | U35: =IF($AE$29=MAX($AE$29:$AE$33),U29,IF($AE$30=MAX($AE$29:$AE$33),U30,IF($AE$31=MAX($AE$29:$AE$33),U31,IF($AE$32=MAX($AE$29:$AE$33),U32,U33)))) -> 0 | V35: =IF($AE$29=MAX($AE$29:$AE$33),V29,IF($AE$30=MAX($AE$29:$AE$33),V30,IF($AE$31=MAX($AE$29:$AE$33),V31,IF($AE$32=MAX($AE$29:$AE$33),V32,V33)))) -> 3 | W35: =IF($AE$29=MAX($AE$29:$AE$33),W29,IF($AE$30=MAX($AE$29:$AE$33),W30,IF($AE$31=MAX($AE$29:$AE$33),W31,IF($AE$32=MAX($AE$29:$AE$33),W32,W33)))) -> 1 | X35: =IF($AE$29=MAX($AE$29:$AE$33),X29,IF($AE$30=MAX($AE$29:$AE$33),X30,IF($AE$31=MAX($AE$29:$AE$33),X31,IF($AE$32=MAX($AE$29:$AE$33),X32,X33)))) -> 0 | Y35: =IF($AE$29=MAX($AE$29:$AE$33),Y29,IF($AE$30=MAX($AE$29:$AE$33),Y30,IF($AE$31=MAX($AE$29:$AE$33),Y31,IF($AE$32=MAX($AE$29:$AE$33),Y32,Y33)))) -> 2 | Z35: =IF($AE$29=MAX($AE$29:$AE$33),Z29,IF($AE$30=MAX($AE$29:$AE$33),Z30,IF($AE$31=MAX($AE$29:$AE$33),Z31,IF($AE$32=MAX($AE$29:$AE$33),Z32,Z33)))) -> 3 | AA35: =IF($AE$29=MAX($AE$29:$AE$33),AA29,IF($AE$30=MAX($AE$29:$AE$33),AA30,IF($AE$31=MAX($AE$29:$AE$33),AA31,IF($AE$32=MAX($AE$29:$AE$33),AA32,AA33)))) -> 1 | AB35: =IF($AE$29=MAX($AE$29:$AE$33),AB29,IF($AE$30=MAX($AE$29:$AE$33),AB30,IF($AE$31=MAX($AE$29:$AE$33),AB31,IF($AE$32=MAX($AE$29:$AE$33),AB32,AB33)))) -> 0 | AC35: =A35 -> de 7:00 à 8:00 | AE35: =SUM(C35:AB35) -> 13 | AF35: =IF(AE35=0,0,AF47/AE35) -> 0.53846154 | AG35: =IF(AE35=0,0,AG47/AE35) -> 0.30769231 | AH35: =IF(AG47=0,0,AH47/AG47) -> 1 | AI35: =IF(AE35=0,0,AI47/AE35) -> 0.46153846 | AJ35: =SUM(U35:AB35) -> 10 | AK35: =RE_Eglise!AH66 -> 9 | AL35: =AK35-AJ35 -> -1
AF37: Nombre de VAE dans le total | AG37: Nombre de femmes dans le total | AH37: Nombre de VAE chez les femmes | AI37: Cycles en direction d'Annemasse-Genève
AF41: =(C29+E29+G29+I29+L29+N29+P29+R29+U29+W29+Y29+AA29) -> 6 | AG41: =(E29+F29+I29+J29+N29+O29+R29+S29+W29+X29+AA29+AB29) -> 4 | AH41: =(E29+I29+N29+R29+W29+AA29) -> 4 | AI41: =SUM(G29:J29,Y29:AB29) -> 5
AF42: =(C30+E30+G30+I30+L30+N30+P30+R30+U30+W30+Y30+AA30) -> 7 | AG42: =(E30+F30+I30+J30+N30+O30+R30+S30+W30+X30+AA30+AB30) -> 4 | AH42: =(E30+I30+N30+R30+W30+AA30) -> 4 | AI42: =SUM(G30:J30,Y30:AB30) -> 6
AF43: =(C31+E31+G31+I31+L31+N31+P31+R31+U31+W31+Y31+AA31) -> 4 | AG43: =(E31+F31+I31+J31+N31+O31+R31+S31+W31+X31+AA31+AB31) -> 0 | AH43: =(E31+I31+N31+R31+W31+AA31) -> 0 | AI43: =SUM(G31:J31,Y31:AB31) -> 3
AF44: =(C32+E32+G32+I32+L32+N32+P32+R32+U32+W32+Y32+AA32) -> 9 | AG44: =(E32+F32+I32+J32+N32+O32+R32+S32+W32+X32+AA32+AB32) -> 0 | AH44: =(E32+I32+N32+R32+W32+AA32) -> 0 | AI44: =SUM(G32:J32,Y32:AB32) -> 9
AF45: =(C33+E33+G33+I33+L33+N33+P33+R33+U33+W33+Y33+AA33) -> 6 | AG45: =(E33+F33+I33+J33+N33+O33+R33+S33+W33+X33+AA33+AB33) -> 0 | AH45: =(E33+I33+N33+R33+W33+AA33) -> 0 | AI45: =SUM(G33:J33,Y33:AB33) -> 7
AF46: =(C34+E34+G34+I34+L34+N34+P34+R34+U34+W34+Y34+AA34) -> 16 | AG46: =(E34+F34+I34+J34+N34+O34+R34+S34+W34+X34+AA34+AB34) -> 4 | AH46: =(E34+I34+N34+R34+W34+AA34) -> 4 | AI46: =SUM(G34:J34,Y34:AB34) -> 15
AF47: =(C35+E35+G35+I35+L35+N35+P35+R35+U35+W35+Y35+AA35) -> 7 | AG47: =(E35+F35+I35+J35+N35+O35+R35+S35+W35+X35+AA35+AB35) -> 4 | AH47: =(E35+I35+N35+R35+W35+AA35) -> 4 | AI47: =SUM(G35:J35,Y35:AB35) -> 6

Sheet RE_La Forge (gir.)
A1: Lieu : | B1: REIGNIER_Giratoire de la Forge (en-dessous du Fil des Saisons) | M1: Date : | N1: mardi 6 juin 2023
A2: Nom des personnes participant au comptage :
A3: Météo :
A4: Remarques :
A5: Méthodologie : | C5: Pour chaque intervalle de temps, marquer une seule croix par personne comptée
C6: Si c'est enfant, remplacer la croix par E, une trottinette T, un piéton P, etc.
C8: Depuis 'Esery' | K8: Depuis 'Reignier' | S8: Depuis 'Annemasse'
C9: vers 'Reignier' | G9: vers 'Annemasse' | K9: vers 'Esery' | O9: vers 'Annemasse' | S9: vers 'Reignier' | W9: vers 'Esery'
C10: H | E10: F | G10: H | I10: F | K10: H | M10: F | O10: H | Q10: F | S10: H | U10: F | W10: H | Y10: F
A11: Heure | B11: Minute | C11: VAE | D11: vélo | E11: VAE | F11: vélo | G11: VAE | H11: vélo | I11: VAE | J11: vélo | K11: VAE | L11: vélo | M11: VAE | N11: vélo | O11: VAE | P11: vélo | Q11: VAE | R11: vélo | S11: VAE | T11: vélo | U11: VAE | V11: vélo | W11: VAE | X11: vélo | Y11: VAE | Z11: vélo
A12: 6 | B12: 30 – 44'59
B13: 45 – 59'59
A14: 7 | B14: 00 – 14'59
B15: 15 – 29'59
B16: 30 – 44'59
B17: 45 – 59'59
A18: 8 | B18: 00 – 14'59
B19: 15 – 29'59
B20: 30 – 44'59
B21: 45 – 59'59
A22: 9 | B22: 00 – 14'59
B23: 15 – 29'59
A25: Lieu : | B25: =B1 -> REIGNIER_Giratoire de la Forge (en-dessous du Fil des Saisons) | M25: Date : | N25: =N1 -> mardi 6 juin 2023 | AA25: Lieu : | AB25: =B25 -> REIGNIER_Giratoire de la Forge (en-dessous du Fil des Saisons) | AH25: Date : | AI25: =N25 -> mardi 6 juin 2023
A26: Nom des personnes participant au comptage : | G26: =G2 -> 0 | AA26: Nom des personnes participant au comptage : | AE26: =G26 -> 0
A27: Météo : | C27: =C3 -> 0 | AA27: Météo : | AC27: =C27 -> 0
A28: Remarques : | C28: =C4 -> 0 | AA28: Remarques : | AC28: =C28 -> 0
C32: =C8 -> Depuis 'Esery' | K32: =K8 -> Depuis 'Reignier' | S32: =S8 -> Depuis 'Annemasse' | AC32: TOTAL | AD32: Part des VAE dans le total | AE32: Part des femmes dans le total | AF32: Part des VAE chez les femmes | AG32: Part en direction d'Annemasse-Genève | AH32: Part en provenance de Reignier | AI32: Part en provenance d'Esery | AJ32: Remarques
C33: =C9 -> vers 'Reignier' | G33: =G9 -> vers 'Annemasse' | K33: =K9 -> vers 'Esery' | O33: =O9 -> vers 'Annemasse' | S33: =S9 -> vers 'Reignier' | W33: =W9 -> vers 'Esery'
C34: H | E34: F | G34: H | I34: F | K34: H | M34: F | O34: H | Q34: F | S34: H | U34: F | W34: H | Y34: F
A35: Période | C35: VAE | D35: vélo | E35: VAE | F35: vélo | G35: VAE | H35: vélo | I35: VAE | J35: vélo | K35: VAE | L35: vélo | M35: VAE | N35: vélo | O35: VAE | P35: vélo | Q35: VAE | R35: vélo | S35: VAE | T35: vélo | U35: VAE | V35: vélo | W35: VAE | X35: vélo | Y35: VAE | Z35: vélo | AA35: Période
A36: de 6:30 à 7:30 | C36: =SUM(C12:C15) -> 0 | D36: =SUM(D12:D15) -> 0 | E36: =SUM(E12:E15) -> 0 | F36: =SUM(F12:F15) -> 0 | G36: =SUM(G12:G15) -> 0 | H36: =SUM(H12:H15) -> 0 | I36: =SUM(I12:I15) -> 0 | J36: =SUM(J12:J15) -> 0 | ... Z36: =SUM(Z12:Z15) -> 0 | AA36: de 6:30 à 7:30 | AC36: =SUM(C36:Z36) -> 0 | AD36: =IF(AC36=0,0,AD48/AC36) -> 0 | AE36: =IF(AC36=0,0,AE48/AC36) -> 0 | AF36: =IF(AE48=0,0,AF48/AE48) -> 0 | AG36: =IF(AC36=0,0,AG48/AC36) -> 0 | AH36: =IF(AC36=0,0,AH48/AC36) -> 0 | AI36: =IF(AC36=0,0,AI48/AC36) -> 0
A37: de 7:00 à 8:00 | C37: =SUM(C14:C17) -> 0 | D37: =SUM(D14:D17) -> 0 | E37: =SUM(E14:E17) -> 0 | F37: =SUM(F14:F17) -> 0 | G37: =SUM(G14:G17) -> 0 | H37: =SUM(H14:H17) -> 0 | I37: =SUM(I14:I17) -> 0 | J37: =SUM(J14:J17) -> 0 | ... Z37: =SUM(Z14:Z17) -> 0 | AA37: de 7:00 à 8:00 | AC37: =SUM(C37:Z37) -> 0 | AD37: =IF(AC37=0,0,AD49/AC37) -> 0 | AE37: =IF(AC37=0,0,AE49/AC37) -> 0 | AF37: =IF(AE49=0,0,AF49/AE49) -> 0 | AG37: =IF(AC37=0,0,AG49/AC37) -> 0 | AH37: =IF(AC37=0,0,AH49/AC37) -> 0 | AI37: =IF(AC37=0,0,AI49/AC37) -> 0
A38: de 7:30 à 8:30 | C38: =SUM(C16:C19) -> 0 | D38: =SUM(D16:D19) -> 0 | E38: =SUM(E16:E19) -> 0 | F38: =SUM(F16:F19) -> 0 | G38: =SUM(G16:G19) -> 0 | H38: =SUM(H16:H19) -> 0 | I38: =SUM(I16:I19) -> 0 | J38: =SUM(J16:J19) -> 0 | ... Z38: =SUM(Z16:Z19) -> 0 | AA38: de 7:30 à 8:30 | AC38: =SUM(C38:Z38) -> 0 | AD38: =IF(AC38=0,0,AD50/AC38) -> 0 | AE38: =IF(AC38=0,0,AE50/AC38) -> 0 | AF38: =IF(AE50=0,0,AF50/AE50) -> 0 | AG38: =IF(AC38=0,0,AG50/AC38) -> 0 | AH38: =IF(AC38=0,0,AH50/AC38) -> 0 | AI38: =IF(AC38=0,0,AI50/AC38) -> 0
A39: de 8:00 à 9:00 | C39: =SUM(C18:C21) -> 0 | D39: =SUM(D18:D21) -> 0 | E39: =SUM(E18:E21) -> 0 | F39: =SUM(F18:F21) -> 0 | G39: =SUM(G18:G21) -> 0 | H39: =SUM(H18:H21) -> 0 | I39: =SUM(I18:I21) -> 0 | J39: =SUM(J18:J21) -> 0 | ... Z39: =SUM(Z18:Z21) -> 0 | AA39: de 8:00 à 9:00 | AC39: =SUM(C39:Z39) -> 0 | AD39: =IF(AC39=0,0,AD51/AC39) -> 0 | AE39: =IF(AC39=0,0,AE51/AC39) -> 0 | AF39: =IF(AE51=0,0,AF51/AE51) -> 0 | AG39: =IF(AC39=0,0,AG51/AC39) -> 0 | AH39: =IF(AC39=0,0,AH51/AC39) -> 0 | AI39: =IF(AC39=0,0,AI51/AC39) -> 0
A40: de 8:30 à 9:30 | C40: =SUM(C20:C23) -> 0 | D40: =SUM(D20:D23) -> 0 | E40: =SUM(E20:E23) -> 0 | F40: =SUM(F20:F23) -> 0 | G40: =SUM(G20:G23) -> 0 | H40: =SUM(H20:H23) -> 0 | I40: =SUM(I20:I23) -> 0 | J40: =SUM(J20:J23) -> 0 | ... Z40: =SUM(Z20:Z23) -> 0 | AA40: de 8:30 à 9:30 | AC40: =SUM(C40:Z40) -> 0 | AD40: =IF(AC40=0,0,AD52/AC40) -> 0 | AE40: =IF(AC40=0,0,AE52/AC40) -> 0 | AF40: =IF(AE52=0,0,AF52/AE52) -> 0 | AG40: =IF(AC40=0,0,AG52/AC40) -> 0 | AH40: =IF(AC40=0,0,AH52/AC40) -> 0 | AI40: =IF(AC40=0,0,AI52/AC40) -> 0
A41: TOTAL | C41: =SUM(C12:C23) -> 0 | D41: =SUM(D12:D23) -> 0 | E41: =SUM(E12:E23) -> 0 | F41: =SUM(F12:F23) -> 0 | G41: =SUM(G12:G23) -> 0 | H41: =SUM(H12:H23) -> 0 | I41: =SUM(I12:I23) -> 0 | J41: =SUM(J12:J23) -> 0 | ... Z41: =SUM(Z12:Z23) -> 0 | AA41: TOTAL | AC41: =SUM(C41:Z41) -> 0 | AD41: =IF(AC41=0,0,AD53/AC41) -> 0 | AE41: =IF(AC41=0,0,AE53/AC41) -> 0 | AF41: =IF(AE53=0,0,AF53/AE53) -> 0 | AG41: =IF(AC41=0,0,AG53/AC41) -> 0 | AH41: =IF(AC41=0,0,AH53/AC41) -> 0 | AI41: =IF(AC41=0,0,AI53/AC41) -> 0
A42: =IF($AC$36=MAX($AC$36:$AC$40),A36,IF($AC$37=MAX($AC$36:$AC$40),A37,IF($AC$38=MAX($AC$36:$AC$40),A38,IF($AC$39=MAX($AC$36:$AC$40),A39,A40)))) -> de 6:30 à 7:30 | C42: =IF($AC$36=MAX($AC$36:$AC$40),C36,IF($AC$37=MAX($AC$36:$AC$40),C37,IF($AC$38=MAX($AC$36:$AC$40),C38,IF($AC$39=MAX($AC$36:$AC$40),C39,C40)))) -> 0 | D42: =IF($AC$36=MAX($AC$36:$AC$40),D36,IF($AC$37=MAX($AC$36:$AC$40),D37,IF($AC$38=MAX($AC$36:$AC$40),D38,IF($AC$39=MAX($AC$36:$AC$40),D39,D40)))) -> 0 | E42: =IF($AC$36=MAX($AC$36:$AC$40),E36,IF($AC$37=MAX($AC$36:$AC$40),E37,IF($AC$38=MAX($AC$36:$AC$40),E38,IF($AC$39=MAX($AC$36:$AC$40),E39,E40)))) -> 0 | F42: =IF($AC$36=MAX($AC$36:$AC$40),F36,IF($AC$37=MAX($AC$36:$AC$40),F37,IF($AC$38=MAX($AC$36:$AC$40),F38,IF($AC$39=MAX($AC$36:$AC$40),F39,F40)))) -> 0 | G42: =IF($AC$36=MAX($AC$36:$AC$40),G36,IF($AC$37=MAX($AC$36:$AC$40),G37,IF($AC$38=MAX($AC$36:$AC$40),G38,IF($AC$39=MAX($AC$36:$AC$40),G39,G40)))) -> 0 | H42: =IF($AC$36=MAX($AC$36:$AC$40),H36,IF($AC$37=MAX($AC$36:$AC$40),H37,IF($AC$38=MAX($AC$36:$AC$40),H38,IF($AC$39=MAX($AC$36:$AC$40),H39,H40)))) -> 0 | I42: =IF($AC$36=MAX($AC$36:$AC$40),I36,IF($AC$37=MAX($AC$36:$AC$40),I37,IF($AC$38=MAX($AC$36:$AC$40),I38,IF($AC$39=MAX($AC$36:$AC$40),I39,I40)))) -> 0 | J42: =IF($AC$36=MAX($AC$36:$AC$40),J36,IF($AC$37=MAX($AC$36:$AC$40),J37,IF($AC$38=MAX($AC$36:$AC$40),J38,IF($AC$39=MAX($AC$36:$AC$40),J39,J40)))) -> 0 | ... Z42: =IF($AC$36=MAX($AC$36:$AC$40),Z36,IF($AC$37=MAX($AC$36:$AC$40),Z37,IF($AC$38=MAX($AC$36:$AC$40),Z38,IF($AC$39=MAX($AC$36:$AC$40),Z39,Z40)))) -> 0 | AA42: =A42 -> de 6:30 à 7:30 | AC42: =SUM(C42:Z42) -> 0 | AD42: =IF(AC42=0,0,AD54/AC42) -> 0 | AE42: =IF(AC42=0,0,AE54/AC42) -> 0 | AF42: =IF(AE54=0,0,AF54/AE54) -> 0 | AG42: =IF(AC42=0,0,AG54/AC42) -> 0 | AH42: =IF(AC42=0,0,AH54/AC42) -> 0 | AI42: =IF(AC42=0,0,AI54/AC42) -> 0
AD44: Nombre de VAE dans le total | AE44: Nombre de femmes dans le total | AF44: Nombre de VAE chez les femmes | AG44: Cycles en direction d'Annemasse-Genève | AH44: Cycles en provenance de Reignier | AI44: Cycles en provenance d'Esery
AD48: =(C36+E36+G36+I36+K36+M36+O36+Q36+S36+U36+W36+Y36) -> 0 | AE48: =(E36+F36+I36+J36+M36+N36+Q36+R36+U36+V36+Y36+Z36) -> 0 | AF48: =(E36+I36+M36+Q36+U36+Y36) -> 0 | AG48: =SUM(G36:J36,O36:R36) -> 0 | AH48: =SUM(K36:R36) -> 0 | AI48: =SUM(C36:J36) -> 0
AD49: =(C37+E37+G37+I37+K37+M37+O37+Q37+S37+U37+W37+Y37) -> 0 | AE49: =(E37+F37+I37+J37+M37+N37+Q37+R37+U37+V37+Y37+Z37) -> 0 | AF49: =(E37+I37+M37+Q37+U37+Y37) -> 0 | AG49: =SUM(G37:J37,O37:R37) -> 0 | AH49: =SUM(K37:R37) -> 0 | AI49: =SUM(C37:J37) -> 0
...

Sheet RE_Fil Saisons
A1: Lieu : | B1: REIGNIER_Carrefour Marsinge / Viaison (au-dessus du Fil des Saisons) | N1: Date : | O1: mardi 6 juin 2023
A2: Nom des personnes participant au comptage : | G2: Jean-Claude BRUN
A3: Météo : | C3: Excellente (grand soleil)
A5: Remarques : | C5: RAS | P5: Méthodologie : | R5: Pour chaque intervalle de temps, marquer une seule croix par personne comptée. Si c'est enfant, remplacer la croix par E, une trottinette T, un piéton P, etc.
C7: Depuis 'Esery' | L7: Depuis 'Reignier' | U7: Depuis 'Annemasse'
C8: vers 'Reignier' | G8: vers 'Annemasse' | L8: vers 'Esery' | P8: vers 'Annemasse' | U8: vers 'Reignier' | Y8: vers 'Esery'
C9: H | E9: F | G9: H | I9: F | L9: H | N9: F | P9: H | R9: F | U9: H | W9: F | Y9: H | AA9: F
A10: Heure | B10: Minute | C10: VAE | D10: vélo | E10: VAE | F10: vélo | G10: VAE | H10: vélo | I10: VAE | J10: vélo | L10: VAE | M10: vélo | N10: VAE | O10: vélo | P10: VAE | Q10: vélo | R10: VAE | S10: vélo | U10: VAE | V10: vélo | W10: VAE | X10: vélo | Y10: VAE | Z10: vélo | AA10: VAE | AB10: vélo
A11: 6 | B11: 30 – 44'59
B12: 45 – 59'59
A13: 7 | B13: 00 – 14'59 | G13: 1 | H13: 1 | Q13: 4 | R13: 1
B14: 15 – 29'59 | I14: 1 | P14: 2 | R14: 1
B15: 30 – 44'59 | G15: 1 | P15: 2 | R15: 1
B16: 45 – 59'59 | G16: 1 | P16: 1 | Q16: 1 | R16: 1 | V16: 1
A17: 8 | B17: 00 – 14'59 | Q17: 1 | R17: 1 | V17: 1
B18: 15 – 29'59 | Q18: 2
B19: 30 – 44'59 | H19: 1
B20: 45 – 59'59 | G20: 1 | H20: 1
A21: 9 | B21: 00 – 14'59
B22: 15 – 29'59
C25: =C7 -> Depuis 'Esery' | L25: =L7 -> Depuis 'Reignier' | U25: =U7 -> Depuis 'Annemasse' | AE25: TOTAL | AF25: Part des VAE dans le total | AG25: Part des femmes dans le total | AH25: Part des VAE chez les femmes | AI25: Part en direction d'Annemasse-Genève | AJ25: Part en provenance de Reignier | AK25: Part en provenance d'Esery | AL25: Remarques
C26: =C8 -> vers 'Reignier' | G26: =G8 -> vers 'Annemasse' | L26: =L8 -> vers 'Esery' | P26: =P8 -> vers 'Annemasse' | U26: =U8 -> vers 'Reignier' | Y26: =Y8 -> vers 'Esery'
C27: H | E27: F | G27: H | I27: F | L27: H | N27: F | P27: H | R27: F | U27: H | W27: F | Y27: H | AA27: F
A28: Période | C28: VAE | D28: vélo | E28: VAE | F28: vélo | G28: VAE | H28: vélo | I28: VAE | J28: vélo | L28: VAE | M28: vélo | N28: VAE | O28: vélo | P28: VAE | Q28: vélo | R28: VAE | S28: vélo | U28: VAE | V28: vélo | W28: VAE | X28: vélo | Y28: VAE | Z28: vélo | AA28: VAE | AB28: vélo | AC28: Période
A29: de 6:30 à 7:30 | C29: =SUM(C11:C14) -> 0 | D29: =SUM(D11:D14) -> 0 | E29: =SUM(E11:E14) -> 0 | F29: =SUM(F11:F14) -> 0 | G29: =SUM(G11:G14) -> 1 | H29: =SUM(H11:H14) -> 1 | I29: =SUM(I11:I14) -> 1 | J29: =SUM(J11:J14) -> 0 | L29: =SUM(L11:L14) -> 0 | M29: =SUM(M11:M14) -> 0 | N29: =SUM(N11:N14) -> 0 | O29: =SUM(O11:O14) -> 0 | P29: =SUM(P11:P14) -> 2 | Q29: =SUM(Q11:Q14) -> 4 | R29: =SUM(R11:R14) -> 2 | S29: =SUM(S11:S14) -> 0 | U29: =SUM(U11:U14) -> 0 | V29: =SUM(V11:V14) -> 0 | W29: =SUM(W11:W14) -> 0 | X29: =SUM(X11:X14) -> 0 | Y29: =SUM(Y11:Y14) -> 0 | Z29: =SUM(Z11:Z14) -> 0 | AA29: =SUM(AA11:AA14) -> 0 | AB29: =SUM(AB11:AB14) -> 0 | AC29: de 6:30 à 7:30 | AE29: =SUM(C29:AB29) -> 11 | AF29: =IF(AE29=0,0,AF41/AE29) -> 0.54545455 | AG29: =IF(AE29=0,0,AG41/AE29) -> 0.27272727 | AH29: =IF(AG41=0,0,AH41/AG41) -> 1 | AI29: =IF(AE29=0,0,AI41/AE29) -> 1 | AJ29: =IF(AE29=0,0,AJ41/AE29) -> 0.72727273 | AK29: =IF(AE29=0,0,AK41/AE29) -> 0.27272727
A30: de 7:00 à 8:00 | C30: =SUM(C13:C16) -> 0 | D30: =SUM(D13:D16) -> 0 | E30: =SUM(E13:E16) -> 0 | F30: =SUM(F13:F16) -> 0 | G30: =SUM(G13:G16) -> 3 | H30: =SUM(H13:H16) -> 1 | I30: =SUM(I13:I16) -> 1 | J30: =SUM(J13:J16) -> 0 | L30: =SUM(L13:L16) -> 0 | M30: =SUM(M13:M16) -> 0 | N30: =SUM(N13:N16) -> 0 | O30: =SUM(O13:O16) -> 0 | P30: =SUM(P13:P16) -> 5 | Q30: =SUM(Q13:Q16) -> 5 | R30: =SUM(R13:R16) -> 4 | S30: =SUM(S13:S16) -> 0 | U30: =SUM(U13:U16) -> 0 | V30: =SUM(V13:V16) -> 1 | W30: =SUM(W13:W16) -> 0 | X30: =SUM(X13:X16) -> 0 | Y30: =SUM(Y13:Y16) -> 0 | Z30: =SUM(Z13:Z16) -> 0 | AA30: =SUM(AA13:AA16) -> 0 | AB30: =SUM(AB13:AB16) -> 0 | AC30: de 7:00 à 8:00 | AE30: =SUM(C30:AB30) -> 20 | AF30: =IF(AE30=0,0,AF42/AE30) -> 0.65 | AG30: =IF(AE30=0,0,AG42/AE30) -> 0.25 | AH30: =IF(AG42=0,0,AH42/AG42) -> 1 | AI30: =IF(AE30=0,0,AI42/AE30) -> 0.95 | AJ30: =IF(AE30=0,0,AJ42/AE30) -> 0.7 | AK30: =IF(AE30=0,0,AK42/AE30) -> 0.25
A31: de 7:30 à 8:30 | C31: =SUM(C15:C18) -> 0 | D31: =SUM(D15:D18) -> 0 | E31: =SUM(E15:E18) -> 0 | F31: =SUM(F15:F18) -> 0 | G31: =SUM(G15:G18) -> 2 | H31: =SUM(H15:H18) -> 0 | I31: =SUM(I15:I18) -> 0 | J31: =SUM(J15:J18) -> 0 | L31: =SUM(L15:L18) -> 0 | M31: =SUM(M15:M18) -> 0 | N31: =SUM(N15:N18) -> 0 | O31: =SUM(O15:O18) -> 0 | P31: =SUM(P15:P18) -> 3 | Q31: =SUM(Q15:Q18) -> 4 | R31: =SUM(R15:R18) -> 3 | S31: =SUM(S15:S18) -> 0 | U31: =SUM(U15:U18) -> 0 | V31: =SUM(V15:V18) -> 2 | W31: =SUM(W15:W18) -> 0 | X31: =SUM(X15:X18) -> 0 | Y31: =SUM(Y15:Y18) -> 0 | Z31: =SUM(Z15:Z18) -> 0 | AA31: =SUM(AA15:AA18) -> 0 | AB31: =SUM(AB15:AB18) -> 0 | AC31: de 7:30 à 8:30 | AE31: =SUM(C31:AB31) -> 14 | AF31: =IF(AE31=0,0,AF43/AE31) -> 0.57142857 | AG31: =IF(AE31=0,0,AG43/AE31) -> 0.21428571 | AH31: =IF(AG43=0,0,AH43/AG43) -> 1 | AI31: =IF(AE31=0,0,AI43/AE31) -> 0.85714286 | AJ31: =IF(AE31=0,0,AJ43/AE31) -> 0.71428571 | AK31: =IF(AE31=0,0,AK43/AE31) -> 0.14285714
A32: de 8:00 à 9:00 | C32: =SUM(C17:C20) -> 0 | D32: =SUM(D17:D20) -> 0 | E32: =SUM(E17:E20) -> 0 | F32: =SUM(F17:F20) -> 0 | G32: =SUM(G17:G20) -> 1 | H32: =SUM(H17:H20) -> 2 | I32: =SUM(I17:I20) -> 0 | J32: =SUM(J17:J20) -> 0 | L32: =SUM(L17:L20) -> 0 | M32: =SUM(M17:M20) -> 0 | N32: =SUM(N17:N20) -> 0 | O32: =SUM(O17:O20) -> 0 | P32: =SUM(P17:P20) -> 0 | Q32: =SUM(Q17:Q20) -> 3 | R32: =SUM(R17:R20) -> 1 | S32: =SUM(S17:S20) -> 0 | U32: =SUM(U17:U20) -> 0 | V32: =SUM(V17:V20) -> 1 | W32: =SUM(W17:W20) -> 0 | X32: =SUM(X17:X20) -> 0 | Y32: =SUM(Y17:Y20) -> 0 | Z32: =SUM(Z17:Z20) -> 0 | AA32: =SUM(AA17:AA20) -> 0 | AB32: =SUM(AB17:AB20) -> 0 | AC32: de 8:00 à 9:00 | AE32: =SUM(C32:AB32) -> 8 | AF32: =IF(AE32=0,0,AF44/AE32) -> 0.25 | AG32: =IF(AE32=0,0,AG44/AE32) -> 0.125 | AH32: =IF(AG44=0,0,AH44/AG44) -> 1 | AI32: =IF(AE32=0,0,AI44/AE32) -> 0.875 | AJ32: =IF(AE32=0,0,AJ44/AE32) -> 0.5 | AK32: =IF(AE32=0,0,AK44/AE32) -> 0.375
A33: de 8:30 à 9:30 | C33: =SUM(C19:C22) -> 0 | D33: =SUM(D19:D22) -> 0 | E33: =SUM(E19:E22) -> 0 | F33: =SUM(F19:F22) -> 0 | G33: =SUM(G19:G22) -> 1 | H33: =SUM(H19:H22) -> 2 | I33: =SUM(I19:I22) -> 0 | J33: =SUM(J19:J22) -> 0 | L33: =SUM(L19:L22) -> 0 | M33: =SUM(M19:M22) -> 0 | N33: =SUM(N19:N22) -> 0 | O33: =SUM(O19:O22) -> 0 | P33: =SUM(P19:P22) -> 0 | Q33: =SUM(Q19:Q22) -> 0 | R33: =SUM(R19:R22) -> 0 | S33: =SUM(S19:S22) -> 0 | U33: =SUM(U19:U22) -> 0 | V33: =SUM(V19:V22) -> 0 | W33: =SUM(W19:W22) -> 0 | X33: =SUM(X19:X22) -> 0 | Y33: =SUM(Y19:Y22) -> 0 | Z33: =SUM(Z19:Z22) -> 0 | AA33: =SUM(AA19:AA22) -> 0 | AB33: =SUM(AB19:AB22) -> 0 | AC33: de 8:30 à 9:30 | AE33: =SUM(C33:AB33) -> 3 | AF33: =IF(AE33=0,0,AF45/AE33) -> 0.33333333 | AG33: =IF(AE33=0,0,AG45/AE33) -> 0 | AH33: =IF(AG45=0,0,AH45/AG45) -> 0 | AI33: =IF(AE33=0,0,AI45/AE33) -> 1 | AJ33: =IF(AE33=0,0,AJ45/AE33) -> 0 | AK33: =IF(AE33=0,0,AK45/AE33) -> 1
A34: TOTAL | C34: =SUM(C11:C22) -> 0 | D34: =SUM(D11:D22) -> 0 | E34: =SUM(E11:E22) -> 0 | F34: =SUM(F11:F22) -> 0 | G34: =SUM(G11:G22) -> 4 | H34: =SUM(H11:H22) -> 3 | I34: =SUM(I11:I22) -> 1 | J34: =SUM(J11:J22) -> 0 | L34: =SUM(L11:L22) -> 0 | M34: =SUM(M11:M22) -> 0 | N34: =SUM(N11:N22) -> 0 | O34: =SUM(O11:O22) -> 0 | P34: =SUM(P11:P22) -> 5 | Q34: =SUM(Q11:Q22) -> 8 | R34: =SUM(R11:R22) -> 5 | S34: =SUM(S11:S22) -> 0 | U34: =SUM(U11:U22) -> 0 | V34: =SUM(V11:V22) -> 2 | W34: =SUM(W11:W22) -> 0 | X34: =SUM(X11:X22) -> 0 | Y34: =SUM(Y11:Y22) -> 0 | Z34: =SUM(Z11:Z22) -> 0 | AA34: =SUM(AA11:AA22) -> 0 | AB34: =SUM(AB11:AB22) -> 0 | AC34: TOTAL | AE34: =SUM(C34:AB34) -> 28 | AF34: =IF(AE34=0,0,AF46/AE34) -> 0.53571429 | AG34: =IF(AE34=0,0,AG46/AE34) -> 0.21428571 | AH34: =IF(AG46=0,0,AH46/AG46) -> 1 | AI34: =IF(AE34=0,0,AI46/AE34) -> 0.92857143 | AJ34: =IF(AE34=0,0,AJ46/AE34) -> 0.64285714 | AK34: =IF(AE34=0,0,AK46/AE34) -> 0.28571429
A35: =IF($AE$29=MAX($AE$29:$AE$33),A29,IF($AE$30=MAX($AE$29:$AE$33),A30,IF($AE$31=MAX($AE$29:$AE$33),A31,IF($AE$32=MAX($AE$29:$AE$33),A32,A33)))) -> de 7:00 à 8:00 | C35: =IF($AE$29=MAX($AE$29:$AE$33),C29,IF($AE$30=MAX($AE$29:$AE$33),C30,IF($AE$31=MAX($AE$29:$AE$33),C31,IF($AE$32=MAX($AE$29:$AE$33),C32,C33)))) -> 0 | D35: =IF($AE$29=MAX($AE$29:$AE$33),D29,IF($AE$30=MAX($AE$29:$AE$33),D30,IF($AE$31=MAX($AE$29:$AE$33),D31,IF($AE$32=MAX($AE$29:$AE$33),D32,D33)))) -> 0 | E35: =IF($AE$29=MAX($AE$29:$AE$33),E29,IF($AE$30=MAX($AE$29:$AE$33),E30,IF($AE$31=MAX($AE$29:$AE$33),E31,IF($AE$32=MAX($AE$29:$AE$33),E32,E33)))) -> 0 | F35: =IF($AE$29=MAX($AE$29:$AE$33),F29,IF($AE$30=MAX($AE$29:$AE$33),F30,IF($AE$31=MAX($AE$29:$AE$33),F31,IF($AE$32=MAX($AE$29:$AE$33),F32,F33)))) -> 0 | G35: =IF($AE$29=MAX($AE$29:$AE$33),G29,IF($AE$30=MAX($AE$29:$AE$33),G30,IF($AE$31=MAX($AE$29:$AE$33),G31,IF($AE$32=MAX($AE$29:$AE$33),G32,G33)))) -> 3 | H35: =IF($AE$29=MAX($AE$29:$AE$33),H29,IF($AE$30=MAX($AE$29:$AE$33),H30,IF($AE$31=MAX($AE$29:$AE$33),H31,IF($AE$32=MAX($AE$29:$AE$33),H32,H33)))) -> 1 | I35: =IF($AE$29=MAX($AE$29:$AE$33),I29,IF($AE$30=MAX($AE$29:$AE$33),I30,IF($AE$31=MAX($AE$29:$AE$33),I31,IF($AE$32=MAX($AE$29:$AE$33),I32,I33)))) -> 1 | J35: =IF($AE$29=MAX($AE$29:$AE$33),J29,IF($AE$30=MAX($AE$29:$AE$33),J30,IF($AE$31=MAX($AE$29:$AE$33),J31,IF($AE$32=MAX($AE$29:$AE$33),J32,J33)))) -> 0 | L35: =IF($AE$29=MAX($AE$29:$AE$33),L29,IF($AE$30=MAX($AE$29:$AE$33),L30,IF($AE$31=MAX($AE$29:$AE$33),L31,IF($AE$32=MAX($AE$29:$AE$33),L32,L33)))) -> 0 | M35: =IF($AE$29=MAX($AE$29:$AE$33),M29,IF($AE$30=MAX($AE$29:$AE$33),M30,IF($AE$31=MAX($AE$29:$AE$33),M31,IF($AE$32=MAX($AE$29:$AE$33),M32,M33)))) -> 0 | N35: =IF($AE$29=MAX($AE$29:$AE$33),N29,IF($AE$30=MAX($AE$29:$AE$33),N30,IF($AE$31=MAX($AE$29:$AE$33),N31,IF($AE$32=MAX($AE$29:$AE$33),N32,N33)))) -> 0 | O35: =IF($AE$29=MAX($AE$29:$AE$33),O29,IF($AE$30=MAX($AE$29:$AE$33),O30,IF($AE$31=MAX($AE$29:$AE$33),O31,IF($AE$32=MAX($AE$29:$AE$33),O32,O33)))) -> 0 | P35: =IF($AE$29=MAX($AE$29:$AE$33),P29,IF($AE$30=MAX($AE$29:$AE$33),P30,IF($AE$31=MAX($AE$29:$AE$33),P31,IF($AE$32=MAX($AE$29:$AE$33),P32,P33)))) -> 5 | Q35: =IF($AE$29=MAX($AE$29:$AE$33),Q29,IF($AE$30=MAX($AE$29:$AE$33),Q30,IF($AE$31=MAX($AE$29:$AE$33),Q31,IF($AE$32=MAX($AE$29:$AE$33),Q32,Q33)))) -> 5 | R35: =IF($AE$29=MAX($AE$29:$AE$33),R29,IF($AE$30=MAX($AE$29:$AE$33),R30,IF($AE$31=MAX($AE$29:$AE$33),R31,IF($AE$32=MAX($AE$29:$AE$33),R32,R33)))) -> 4 | S35: =IF($AE$29=MAX($AE$29:$AE$33),S29,IF($AE$30=MAX($AE$29:$AE$33),S30,IF($AE$31=MAX($AE$29:$AE$33),S31,IF($AE$32=MAX($AE$29:$AE$33),S32,S33)))) -> 0 | U35: =IF($AE$29=MAX($AE$29:$AE$33),U29,IF($AE$30=MAX($AE$29:$AE$33),U30,IF($AE$31=MAX($AE$29:$AE$33),U31,IF($AE$32=MAX($AE$29:$AE$33),U32,U33)))) -> 0 | V35: =IF($AE$29=MAX($AE$29:$AE$33),V29,IF($AE$30=MAX($AE$29:$AE$33),V30,IF($AE$31=MAX($AE$29:$AE$33),V31,IF($AE$32=MAX($AE$29:$AE$33),V32,V33)))) -> 1 | W35: =IF($AE$29=MAX($AE$29:$AE$33),W29,IF($AE$30=MAX($AE$29:$AE$33),W30,IF($AE$31=MAX($AE$29:$AE$33),W31,IF($AE$32=MAX($AE$29:$AE$33),W32,W33)))) -> 0 | X35: =IF($AE$29=MAX($AE$29:$AE$33),X29,IF($AE$30=MAX($AE$29:$AE$33),X30,IF($AE$31=MAX($AE$29:$AE$33),X31,IF($AE$32=MAX($AE$29:$AE$33),X32,X33)))) -> 0 | Y35: =IF($AE$29=MAX($AE$29:$AE$33),Y29,IF($AE$30=MAX($AE$29:$AE$33),Y30,IF($AE$31=MAX($AE$29:$AE$33),Y31,IF($AE$32=MAX($AE$29:$AE$33),Y32,Y33)))) -> 0 | Z35: =IF($AE$29=MAX($AE$29:$AE$33),Z29,IF($AE$30=MAX($AE$29:$AE$33),Z30,IF($AE$31=MAX($AE$29:$AE$33),Z31,IF($AE$32=MAX($AE$29:$AE$33),Z32,Z33)))) -> 0 | AA35: =IF($AE$29=MAX($AE$29:$AE$33),AA29,IF($AE$30=MAX($AE$29:$AE$33),AA30,IF($AE$31=MAX($AE$29:$AE$33),AA31,IF($AE$32=MAX($AE$29:$AE$33),AA32,AA33)))) -> 0 | AB35: =IF($AE$29=MAX($AE$29:$AE$33),AB29,IF($AE$30=MAX($AE$29:$AE$33),AB30,IF($AE$31=MAX($AE$29:$AE$33),AB31,IF($AE$32=MAX($AE$29:$AE$33),AB32,AB33)))) -> 0 | AC35: =A35 -> de 7:00 à 8:00 | AE35: =SUM(C35:AB35) -> 20 | AF35: =IF(AE35=0,0,AF47/AE35) -> 0.65 | AG35: =IF(AE35=0,0,AG47/AE35) -> 0.25 | AH35: =IF(AG47=0,0,AH47/AG47) -> 1 | AI35: =IF(AE35=0,0,AI47/AE35) -> 0.95 | AJ35: =IF(AE35=0,0,AJ47/AE35) -> 0.7 | AK35: =IF(AE35=0,0,AK47/AE35) -> 0.25
