Workbook

Sheet PJ_Casino
A1: Lieu : | B1: PERS-JUSSY_Giratoire de Casino | M1: Date : | N1: mardi 31 mai 2022
A2: Nom des personnes participant au comptage : | G2: Florence PELTIER
A3: Météo :
A4: Remarques :
A5: Méthodologie : | C5: Pour chaque intervalle de temps, marquer une seule croix par personne comptée
C6: Si c'est enfant, remplacer la croix par E, une trottinette T, un piéton P, etc.
C8: Depuis 'La Roche' | O8: Depuis 'Pers-Jussy'
C9: vers 'Reignier' | G9: vers 'Casino' | K9: vers 'Pers-Jussy' | O9: vers 'La Roche' | S9: vers 'Reignier' | W9: vers 'Casino'
C10: H | E10: F | G10: H | I10: F | K10: H | M10: F | O10: H | Q10: F | S10: H | U10: F | W10: H | Y10: F
A11: Heure | B11: Minute | C11: VAE | D11: vélo | E11: VAE | F11: vélo | G11: VAE | H11: vélo | I11: VAE | J11: vélo | K11: VAE | L11: vélo | M11: VAE | N11: vélo | O11: VAE | P11: vélo | Q11: VAE | R11: vélo | S11: VAE | T11: vélo | U11: VAE | V11: vélo | W11: VAE | X11: vélo | Y11: VAE | Z11: vélo
A12: 6 | B12: 30 – 44'59
A13: 6 | B13: 45 – 59'59
A14: 7 | B14: 00 – 14'59 | D14: 2 | T14: 1
B15: 15 – 29'59 | D15: 3 | S15: 1 | V15: 1
B16: 30 – 44'59
B17: 45 – 59'59 | S17: 1
A18: 8 | B18: 00 – 14'59
B19: 15 – 29'59 | D19: 2 | U19: 2
B20: 30 – 44'59
B21: 45 – 59'59
A22: 9 | B22: 00 – 14'59
B23: 15 – 29'59
A25: Lieu : | B25: =B1 -> PERS-JUSSY_Giratoire de Casino | M25: Date : | N25: =N1 -> mardi 31 mai 2022
A26: Nom des personnes participant au comptage : | G26: =G2 -> Florence PELTIER
A27: Météo : | C27: =C3 -> 0
A28: Remarques : | C28: =C4 -> 0
A29: =A5 -> Méthodologie : | C29: =C5 -> Pour chaque intervalle de temps, marquer une seule croix par personne comptée
C30: =C6 -> Si c'est enfant, remplacer la croix par E, une trottinette T, un piéton P, etc.
C32: Depuis 'Reignier' | O32: Depuis 'Casino'
C33: vers 'Casino' | G33: vers 'Pers-Jussy' | K33: vers 'La Roche' | O33: vers 'Pers-Jussy' | S33: vers 'La Roche' | W33: vers 'Reignier'
C34: H | E34: F | G34: H | I34: F | K34: H | M34: F | O34: H | Q34: F | S34: H | U34: F | W34: H | Y34: F
A35: Heure | B35: Minute | C35: VAE | D35: vélo | E35: VAE | F35: vélo | G35: VAE | H35: vélo | I35: VAE | J35: vélo | K35: VAE | L35: vélo | M35: VAE | N35: vélo | O35: VAE | P35: vélo | Q35: VAE | R35: vélo | S35: VAE | T35: vélo | U35: VAE | V35: vélo | W35: VAE | X35: vélo | Y35: VAE | Z35: vélo
A36: 6 | B36: 30 – 44'59
A37: 6 | B37: 45 – 59'59
A38: 7 | B38: 00 – 14'59 | L38: 1
B39: 15 – 29'59
B40: 30 – 44'59
B41: 45 – 59'59
A42: 8 | B42: 00 – 14'59
B43: 15 – 29'59
...

Sheet RE_Gare
A1: Lieu : | B1: REIGNIER_Carrefour Rue de la Gare / Rte de Bellecombe (vers Tour d'Ivoire) | M1: Date : | N1: mardi 31 mai 2022
A2: Nom des personnes participant au comptage :
A3: Météo :
A4: Remarques :
A5: Méthodologie : | C5: Pour chaque intervalle de temps, marquer une seule croix par personne comptée
C6: Si c'est enfant, remplacer la croix par E, une trottinette T, un piéton P, etc.
C8: Depuis 'Pers-Jussy' | K8: Depuis 'Reignier-centre' | S8: Depuis 'Gare'
C9: vers 'Reignier' | G9: vers 'Gare' | K9: vers 'Pers-Jussy' | O9: vers 'Gare' | S9: vers 'Reignier-centre' | W9: vers 'Pers-Jussy'
C10: H | E10: F | G10: H | I10: F | K10: H | M10: F | O10: H | Q10: F | S10: H | U10: F | W10: H | Y10: F
A11: Heure | B11: Minute | C11: VAE | D11: vélo | E11: VAE | F11: vélo | G11: VAE | H11: vélo | I11: VAE | J11: vélo | K11: VAE | L11: vélo | M11: VAE | N11: vélo | O11: VAE | P11: vélo | Q11: VAE | R11: vélo | S11: VAE | T11: vélo | U11: VAE | V11: vélo | W11: VAE | X11: vélo | Y11: VAE | Z11: vélo
A12: 6 | B12: 30 – 44'59
B13: 45 – 59'59
A14: 7 | B14: 00 – 14'59
B15: 15 – 29'59
B16: 30 – 44'59
B17: 45 – 59'59
A18: 8 | B18: 00 – 14'59
B19: 15 – 29'59
B20: 30 – 44'59
B21: 45 – 59'59
A22: 9 | B22: 00 – 14'59
B23: 15 – 29'59
A25: Lieu : | B25: =B1 -> REIGNIER_Carrefour Rue de la Gare / Rte de Bellecombe (vers Tour d'Ivoire) | M25: Date : | N25: =N1 -> mardi 31 mai 2022 | AA25: Lieu : | AB25: =B25 -> REIGNIER_Carrefour Rue de la Gare / Rte de Bellecombe (vers Tour d'Ivoire) | AG25: Date : | AH25: =N25 -> mardi 31 mai 2022
A26: Nom des personnes participant au comptage : | G26: =G2 -> 0 | AA26: Nom des personnes participant au comptage : | AE26: =G26 -> 0
A27: Météo : | C27: =C3 -> 0 | AA27: Météo : | AC27: =C27 -> 0
A28: Remarques : | C28: =C4 -> 0 | AA28: Remarques : | AC28: =C28 -> 0
C32: =C8 -> Depuis 'Pers-Jussy' | K32: =K8 -> Depuis 'Reignier-centre' | S32: =S8 -> Depuis 'Gare' | AC32: TOTAL | AD32: Part des VAE dans le total | AE32: Part des femmes dans le total | AF32: Part des VAE chez les femmes | AG32: Part en direction d'Annemasse-Genève | AH32: Part en provenance de Reignier | AI32: Part en provenance d'Esery | AJ32: Remarques
C33: =C9 -> vers 'Reignier' | G33: =G9 -> vers 'Gare' | K33: =K9 -> vers 'Pers-Jussy' | O33: =O9 -> vers 'Gare' | S33: =S9 -> vers 'Reignier-centre' | W33: =W9 -> vers 'Pers-Jussy'
C34: H | E34: F | G34: H | I34: F | K34: H | M34: F | O34: H | Q34: F | S34: H | U34: F | W34: H | Y34: F
A35: Période | C35: VAE | D35: vélo | E35: VAE | F35: vélo | G35: VAE | H35: vélo | I35: VAE | J35: vélo | K35: VAE | L35: vélo | M35: VAE | N35: vélo | O35: VAE | P35: vélo | Q35: VAE | R35: vélo | S35: VAE | T35: vélo | U35: VAE | V35: vélo | W35: VAE | X35: vélo | Y35: VAE | Z35: vélo | AA35: Période
A36: de 6:30 à 7:30 | C36: =SUM(C12:C15) -> 0 | D36: =SUM(D12:D15) -> 0 | E36: =SUM(E12:E15) -> 0 | F36: =SUM(F12:F15) -> 0 | G36: =SUM(G12:G15) -> 0 | H36: =SUM(H12:H15) -> 0 | I36: =SUM(I12:I15) -> 0 | J36: =SUM(J12:J15) -> 0 | ... Z36: =SUM(Z12:Z15) -> 0 | AA36: de 6:30 à 7:30 | AC36: =SUM(C36:Z36) -> 0 | AD36: =IF(AC36=0,0,AD48/AC36) -> 0 | AE36: =IF(AC36=0,0,AE48/AC36) -> 0 | AF36: =IF(AE48=0,0,AF48/AE48) -> 0 | AG36: =IF(AC36=0,0,AG48/AC36) -> 0 | AH36: =IF(AC36=0,0,AH48/AC36) -> 0 | AI36: =IF(AC36=0,0,AI48/AC36) -> 0
A37: de 7:00 à 8:00 | C37: =SUM(C14:C17) -> 0 | D37: =SUM(D14:D17) -> 0 | E37: =SUM(E14:E17) -> 0 | F37: =SUM(F14:F17) -> 0 | G37: =SUM(G14:G17) -> 0 | H37: =SUM(H14:H17) -> 0 | I37: =SUM(I14:I17) -> 0 | J37: =SUM(J14:J17) -> 0 | ... Z37: =SUM(Z14:Z17) -> 0 | AA37: de 7:00 à 8:00 | AC37: =SUM(C37:Z37) -> 0 | AD37: =IF(AC37=0,0,AD49/AC37) -> 0 | AE37: =IF(AC37=0,0,AE49/AC37) -> 0 | AF37: =IF(AE49=0,0,AF49/AE49) -> 0 | AG37: =IF(AC37=0,0,AG49/AC37) -> 0 | AH37: =IF(AC37=0,0,AH49/AC37) -> 0 | AI37: =IF(AC37=0,0,AI49/AC37) -> 0
A38: de 7:30 à 8:30 | C38: =SUM(C16:C19) -> 0 | D38: =SUM(D16:D19) -> 0 | E38: =SUM(E16:E19) -> 0 | F38: =SUM(F16:F19) -> 0 | G38: =SUM(G16:G19) -> 0 | H38: =SUM(H16:H19) -> 0 | I38: =SUM(I16:I19) -> 0 | J38: =SUM(J16:J19) -> 0 | ... Z38: =SUM(Z16:Z19) -> 0 | AA38: de 7:30 à 8:30 | AC38: =SUM(C38:Z38) -> 0 | AD38: =IF(AC38=0,0,AD50/AC38) -> 0 | AE38: =IF(AC38=0,0,AE50/AC38) -> 0 | AF38: =IF(AE50=0,0,AF50/AE50) -> 0 | AG38: =IF(AC38=0,0,AG50/AC38) -> 0 | AH38: =IF(AC38=0,0,AH50/AC38) -> 0 | AI38: =IF(AC38=0,0,AI50/AC38) -> 0
A39: de 8:00 à 9:00 | C39: =SUM(C18:C21) -> 0 | D39: =SUM(D18:D21) -> 0 | E39: =SUM(E18:E21) -> 0 | F39: =SUM(F18:F21) -> 0 | G39: =SUM(G18:G21) -> 0 | H39: =SUM(H18:H21) -> 0 | I39: =SUM(I18:I21) -> 0 | J39: =SUM(J18:J21) -> 0 | ... Z39: =SUM(Z18:Z21) -> 0 | AA39: de 8:00 à 9:00 | AC39: =SUM(C39:Z39) -> 0 | AD39: =IF(AC39=0,0,AD51/AC39) -> 0 | AE39: =IF(AC39=0,0,AE51/AC39) -> 0 | AF39: =IF(AE51=0,0,AF51/AE51) -> 0 | AG39: =IF(AC39=0,0,AG51/AC39) -> 0 | AH39: =IF(AC39=0,0,AH51/AC39) -> 0 | AI39: =IF(AC39=0,0,AI51/AC39) -> 0
A40: de 8:30 à 9:30 | C40: =SUM(C20:C23) -> 0 | D40: =SUM(D20:D23) -> 0 | E40: =SUM(E20:E23) -> 0 | F40: =SUM(F20:F23) -> 0 | G40: =SUM(G20:G23) -> 0 | H40: =SUM(H20:H23) -> 0 | I40: =SUM(I20:I23) -> 0 | J40: =SUM(J20:J23) -> 0 | ... Z40: =SUM(Z20:Z23) -> 0 | AA40: de 8:30 à 9:30 | AC40: =SUM(C40:Z40) -> 0 | AD40: =IF(AC40=0,0,AD52/AC40) -> 0 | AE40: =IF(AC40=0,0,AE52/AC40) -> 0 | AF40: =IF(AE52=0,0,AF52/AE52) -> 0 | AG40: =IF(AC40=0,0,AG52/AC40) -> 0 | AH40: =IF(AC40=0,0,AH52/AC40) -> 0 | AI40: =IF(AC40=0,0,AI52/AC40) -> 0
A41: TOTAL | C41: =SUM(C12:C23) -> 0 | D41: =SUM(D12:D23) -> 0 | E41: =SUM(E12:E23) -> 0 | F41: =SUM(F12:F23) -> 0 | G41: =SUM(G12:G23) -> 0 | H41: =SUM(H12:H23) -> 0 | I41: =SUM(I12:I23) -> 0 | J41: =SUM(J12:J23) -> 0 | ... Z41: =SUM(Z12:Z23) -> 0 | AA41: TOTAL | AC41: =SUM(C41:Z41) -> 0 | AD41: =IF(AC41=0,0,AD53/AC41) -> 0 | AE41: =IF(AC41=0,0,AE53/AC41) -> 0 | AF41: =IF(AE53=0,0,AF53/AE53) -> 0 | AG41: =IF(AC41=0,0,AG53/AC41) -> 0 | AH41: =IF(AC41=0,0,AH53/AC41) -> 0 | AI41: =IF(AC41=0,0,AI53/AC41) -> 0
A42: =IF($AC$36=MAX($AC$36:$AC$40),A36,IF($AC$37=MAX($AC$36:$AC$40),A37,IF($AC$38=MAX($AC$36:$AC$40),A38,IF($AC$39=MAX($AC$36:$AC$40),A39,A40)))) -> de 6:30 à 7:30 | C42: =IF($AC$36=MAX($AC$36:$AC$40),C36,IF($AC$37=MAX($AC$36:$AC$40),C37,IF($AC$38=MAX($AC$36:$AC$40),C38,IF($AC$39=MAX($AC$36:$AC$40),C39,C40)))) -> 0 | D42: =IF($AC$36=MAX($AC$36:$AC$40),D36,IF($AC$37=MAX($AC$36:$AC$40),D37,IF($AC$38=MAX($AC$36:$AC$40),D38,IF($AC$39=MAX($AC$36:$AC$40),D39,D40)))) -> 0 | E42: =IF($AC$36=MAX($AC$36:$AC$40),E36,IF($AC$37=MAX($AC$36:$AC$40),E37,IF($AC$38=MAX($AC$36:$AC$40),E38,IF($AC$39=MAX($AC$36:$AC$40),E39,E40)))) -> 0 | F42: =IF($AC$36=MAX($AC$36:$AC$40),F36,IF($AC$37=MAX($AC$36:$AC$40),F37,IF($AC$38=MAX($AC$36:$AC$40),F38,IF($AC$39=MAX($AC$36:$AC$40),F39,F40)))) -> 0 | G42: =IF($AC$36=MAX($AC$36:$AC$40),G36,IF($AC$37=MAX($AC$36:$AC$40),G37,IF($AC$38=MAX($AC$36:$AC$40),G38,IF($AC$39=MAX($AC$36:$AC$40),G39,G40)))) -> 0 | H42: =IF($AC$36=MAX($AC$36:$AC$40),H36,IF($AC$37=MAX($AC$36:$AC$40),H37,IF($AC$38=MAX($AC$36:$AC$40),H38,IF($AC$39=MAX($AC$36:$AC$40),H39,H40)))) -> 0 | I42: =IF($AC$36=MAX($AC$36:$AC$40),I36,IF($AC$37=MAX($AC$36:$AC$40),I37,IF($AC$38=MAX($AC$36:$AC$40),I38,IF($AC$39=MAX($AC$36:$AC$40),I39,I40)))) -> 0 | J42: =IF($AC$36=MAX($AC$36:$AC$40),J36,IF($AC$37=MAX($AC$36:$AC$40),J37,IF($AC$38=MAX($AC$36:$AC$40),J38,IF($AC$39=MAX($AC$36:$AC$40),J39,J40)))) -> 0 | ... Z42: =IF($AC$36=MAX($AC$36:$AC$40),Z36,IF($AC$37=MAX($AC$36:$AC$40),Z37,IF($AC$38=MAX($AC$36:$AC$40),Z38,IF($AC$39=MAX($AC$36:$AC$40),Z39,Z40)))) -> 0 | AA42: =A42 -> de 6:30 à 7:30 | AC42: =SUM(C42:Z42) -> 0 | AD42: =IF(AC42=0,0,AD54/AC42) -> 0 | AE42: =IF(AC42=0,0,AE54/AC42) -> 0 | AF42: =IF(AE54=0,0,AF54/AE54) -> 0 | AG42: =IF(AC42=0,0,AG54/AC42) -> 0 | AH42: =IF(AC42=0,0,AH54/AC42) -> 0 | AI42: =IF(AC42=0,0,AI54/AC42) -> 0
AD44: Nombre de VAE dans le total | AE44: Nombre de femmes dans le total | AF44: Nombre de VAE chez les femmes | AG44: Cycles en direction d'Annemasse-Genève | AH44: Cycles en provenance de Reignier | AI44: Cycles en provenance d'Esery
AD48: =(C36+E36+G36+I36+K36+M36+O36+Q36+S36+U36+W36+Y36) -> 0 | AE48: =(E36+F36+I36+J36+M36+N36+Q36+R36+U36+V36+Y36+Z36) -> 0 | AF48: =(E36+I36+M36+Q36+U36+Y36) -> 0 | AG48: =SUM(G36:J36,O36:R36) -> 0 | AH48: =SUM(K36:R36) -> 0 | AI48: =SUM(C36:J36) -> 0
AD49: =(C37+E37+G37+I37+K37+M37+O37+Q37+S37+U37+W37+Y37) -> 0 | AE49: =(E37+F37+I37+J37+M37+N37+Q37+R37+U37+V37+Y37+Z37) -> 0 | AF49: =(E37+I37+M37+Q37+U37+Y37) -> 0 | AG49: =SUM(G37:J37,O37:R37) -> 0 | AH49: =SUM(K37:R37) -> 0 | AI49: =SUM(C37:J37) -> 0
...

Sheet RE_ex-gendarmerie
A1: Lieu : | B1: REIGNIER_Giratoire de l'ancienne gendarmerie | M1: Date : | N1: mardi 31 mai 2022
A2: Nom des personnes participant au comptage :
A3: Météo :
A4: Remarques :
A5: Méthodologie : | C5: Pour chaque intervalle de temps, marquer une seule croix par personne comptée
C6: Si c'est enfant, remplacer la croix par E, une trottinette T, un piéton P, etc.
C8: Depuis 'Annemasse - Genève' | O8: Depuis 'Carrefour - Bersat'
C9: vers 'Carrefour - Bersat' | G9: vers 'Pers-Jussy' | K9: vers 'Esery - Méran' | O9: vers 'Pers-Jussy' | S9: vers 'Esery - Méran' | W9: vers 'Annemasse - Genève'
C10: H | E10: F | G10: H | I10: F | K10: H | M10: F | O10: H | Q10: F | S10: H | U10: F | W10: H | Y10: F
A11: Heure | B11: Minute | C11: VAE | D11: vélo | E11: VAE | F11: vélo | G11: VAE | H11: vélo | I11: VAE | J11: vélo | K11: VAE | L11: vélo | M11: VAE | N11: vélo | O11: VAE | P11: vélo | Q11: VAE | R11: vélo | S11: VAE | T11: vélo | U11: VAE | V11: vélo | W11: VAE | X11: vélo | Y11: VAE | Z11: vélo
A12: 6 | B12: 30 – 44'59
B13: 45 – 59'59
A14: 7 | B14: 00 – 14'59
B15: 15 – 29'59
B16: 30 – 44'59
B17: 45 – 59'59
A18: 8 | B18: 00 – 14'59
B19: 15 – 29'59
B20: 30 – 44'59
B21: 45 – 59'59
A22: 9 | B22: 00 – 14'59
B23: 15 – 29'59
A25: Lieu : | B25: =B1 -> REIGNIER_Giratoire de l'ancienne gendarmerie | M25: Date : | N25: =N1 -> mardi 31 mai 2022
A26: Nom des personnes participant au comptage : | G26: =G2 -> 0
A27: Météo : | C27: =C3 -> 0
A28: Remarques : | C28: =C4 -> 0
A29: =A5 -> Méthodologie : | C29: =C5 -> Pour chaque intervalle de temps, marquer une seule croix par personne comptée
C30: =C6 -> Si c'est enfant, remplacer la croix par E, une trottinette T, un piéton P, etc.
C32: Depuis 'Pers-Jussy' | O32: Depuis 'Esery - Méran'
C33: vers 'Esery - Méran' | G33: vers 'Annemasse - Genève' | K33: vers 'Carrefour - Bersat' | O33: vers 'Annemasse - Genève' | S33: vers 'Carrefour - Bersat' | W33: vers 'Pers-Jussy'
C34: H | E34: F | G34: H | I34: F | K34: H | M34: F | O34: H | Q34: F | S34: H | U34: F | W34: H | Y34: F
A35: Heure | B35: Minute | C35: VAE | D35: vélo | E35: VAE | F35: vélo | G35: VAE | H35: vélo | I35: VAE | J35: vélo | K35: VAE | L35: vélo | M35: VAE | N35: vélo | O35: VAE | P35: vélo | Q35: VAE | R35: vélo | S35: VAE | T35: vélo | U35: VAE | V35: vélo | W35: VAE | X35: vélo | Y35: VAE | Z35: vélo
A36: 6 | B36: 30 – 44'59
B37: 45 – 59'59
A38: 7 | B38: 00 – 14'59
B39: 15 – 29'59
B40: 30 – 44'59
B41: 45 – 59'59
A42: 8 | B42: 00 – 14'59
B43: 15 – 29'59
...

Sheet RE_Eglise
A1: Lieu : | B1: REIGNIER_Giratoire des Jonquilles (devant l'église) | M1: Date : | N1: mardi 31 mai 2022
A2: Nom des personnes participant au comptage : | G2: Sylvain BEAUD
A3: Météo :
A4: Remarques :
A5: Méthodologie : | C5: Pour chaque intervalle de temps, marquer une seule croix par personne comptée
C6: Si c'est enfant, remplacer la croix par E, une trottinette T, un piéton P, etc.
C8: Depuis 'Annemasse - Genève' | O8: Depuis 'L'Eculaz'
C9: vers 'Reignier-centre' | G9: vers 'Rue des Ecoles' | K9: vers 'L'Eculaz' | O9: vers 'Reignier-centre' | S9: vers 'Rue des Ecoles' | W9: vers 'Annemasse - Genève'
C10: H | E10: F | G10: H | I10: F | K10: H | M10: F | O10: H | Q10: F | S10: H | U10: F | W10: H | Y10: F
A11: Heure | B11: Minute | C11: VAE | D11: vélo | E11: VAE | F11: vélo | G11: VAE | H11: vélo | I11: VAE | J11: vélo | K11: VAE | L11: vélo | M11: VAE | N11: vélo | O11: VAE | P11: vélo | Q11: VAE | R11: vélo | S11: VAE | T11: vélo | U11: VAE | V11: vélo | W11: VAE | X11: vélo | Y11: VAE | Z11: vélo
A12: 6 | B12: 30 – 44'59
A13: 6 | B13: 45 – 59'59 | R13: 1
A14: 7 | B14: 00 – 14'59
B15: 15 – 29'59 | W15: 1
B16: 30 – 44'59
B17: 45 – 59'59 | V17: 1 | X17: 1
A18: 8 | B18: 00 – 14'59
B19: 15 – 29'59 | P19: 1 | T19: 1
B20: 30 – 44'59 | U20: 1 | V20: 1
B21: 45 – 59'59
A22: 9 | B22: 00 – 14'59
B23: 15 – 29'59
A25: Lieu : | B25: =B1 -> REIGNIER_Giratoire des Jonquilles (devant l'église) | M25: Date : | N25: =N1 -> mardi 31 mai 2022
A26: Nom des personnes participant au comptage : | G26: =G2 -> Sylvain BEAUD
A27: Météo : | C27: =C3 -> 0
A28: Remarques : | C28: =C4 -> 0
A29: =A5 -> Méthodologie : | C29: =C5 -> Pour chaque intervalle de temps, marquer une seule croix par personne comptée
C30: =C6 -> Si c'est enfant, remplacer la croix par E, une trottinette T, un piéton P, etc.
C32: Depuis 'Reignier-centre' | O32: Depuis 'Reignier - Rue des Ecoles'
C33: vers 'Annemasse - Genève' | G33: vers 'Rue des Ecoles' | K33: vers 'L'Eculaz' | O33: vers 'Reignier-centre' | S33: vers 'L'Eculaz' | W33: vers 'Annemasse - Genève'
C34: H | E34: F | G34: H | I34: F | K34: H | M34: F | O34: H | Q34: F | S34: H | U34: F | W34: H | Y34: F
A35: Heure | B35: Minute | C35: VAE | D35: vélo | E35: VAE | F35: vélo | G35: VAE | H35: vélo | I35: VAE | J35: vélo | K35: VAE | L35: vélo | M35: VAE | N35: vélo | O35: VAE | P35: vélo | Q35: VAE | R35: vélo | S35: VAE | T35: vélo | U35: VAE | V35: vélo | W35: VAE | X35: vélo | Y35: VAE | Z35: vélo
A36: 6 | B36: 30 – 44'59
A37: 6 | B37: 45 – 59'59 | J37: 1
A38: 7 | B38: 00 – 14'59 | C38: 1 | D38: 1
B39: 15 – 29'59 | C39: 1 | D39: 1 | H39: 1
B40: 30 – 44'59 | D40: 1 | X40: 1
B41: 45 – 59'59 | H41: 2
A42: 8 | B42: 00 – 14'59 | E42: 1 | H42: 1 | L42: 1 | S42: 1 | T42: 1 | U42: 1
B43: 15 – 29'59 | K43: 1 | M43: 1
...

Sheet RE_Foron
A1: Lieu : | B1: REIGNIER BAS_Giratoire D2 / D202 (vers le Foron) | M1: Date : | N1: mardi 31 mai 2022
A2: Nom des personnes participant au comptage : | G2: Joël MIGNON
A3: Météo :
A4: Remarques :
A5: Méthodologie : | C5: Pour chaque intervalle de temps, marquer une seule croix par personne comptée
C6: Si c'est enfant, remplacer la croix par E, une trottinette T, un piéton P, etc.
C8: Depuis 'Arthaz' | K8: Depuis 'Annemasse' | S8: Depuis 'Reignier'
C9: vers 'Reignier' | G9: vers 'Annemasse' | K9: vers 'Reignier' | O9: vers 'Arthaz' | S9: vers 'Arthaz' | W9: vers 'Annemasse'
C10: H | E10: F | G10: H | I10: F | K10: H | M10: F | O10: H | Q10: F | S10: H | U10: F | W10: H | Y10: F
A11: Heure | B11: Minute | C11: VAE | D11: vélo | E11: VAE | F11: vélo | G11: VAE | H11: vélo | I11: VAE | J11: vélo | K11: VAE | L11: vélo | M11: VAE | N11: vélo | O11: VAE | P11: vélo | Q11: VAE | R11: vélo | S11: VAE | T11: vélo | U11: VAE | V11: vélo | W11: VAE | X11: vélo | Y11: VAE | Z11: vélo
A12: 6 | B12: 30 – 44'59 | D12: 1 | X12: 2
B13: 45 – 59'59 | X13: 1
A14: 7 | B14: 00 – 14'59 | T14: 1 | W14: 1
B15: 15 – 29'59 | T15: 1 | X15: 2
B16: 30 – 44'59 | X16: 2
B17: 45 – 59'59 | Y17: 1
A18: 8 | B18: 00 – 14'59 | T18: 1
B19: 15 – 29'59 | P19: 1 | W19: 2 | Y19: 1
B20: 30 – 44'59 | Y20: 1
B21: 45 – 59'59
A22: 9 | B22: 00 – 14'59
B23: 15 – 29'59
A25: Lieu : | B25: =B1 -> REIGNIER BAS_Giratoire D2 / D202 (vers le Foron) | M25: Date : | N25: =N1 -> mardi 31 mai 2022 | AA25: Lieu : | AB25: =B25 -> REIGNIER BAS_Giratoire D2 / D202 (vers le Foron) | AG25: Date : | AH25: =N25 -> mardi 31 mai 2022
A26: Nom des personnes participant au comptage : | G26: =G2 -> Joël MIGNON | AA26: Nom des personnes participant au comptage : | AE26: =G26 -> Joël MIGNON
A27: Météo : | C27: =C3 -> 0 | AA27: Météo : | AC27: =C27 -> 0
A28: Remarques : | C28: =C4 -> 0 | AA28: Remarques : | AC28: =C28 -> 0
C32: =C8 -> Depuis 'Arthaz' | K32: =K8 -> Depuis 'Annemasse' | S32: =S8 -> Depuis 'Reignier' | AC32: TOTAL | AD32: Part des VAE dans le total | AE32: Part des femmes dans le total | AF32: Part des VAE chez les femmes | AG32: Part en direction d'Annemasse-Genève | AH32: Cycles en provenance de Reignier | AI32: Cycles venant du giratoire des Jonquilles | AJ32: Différence de cycles entre ces deux carrefour : >> descendus au chemin raide sous le cimetière, >> parti en vélo depuis le parking du cimetière ?
C33: =C9 -> vers 'Reignier' | G33: =G9 -> vers 'Annemasse' | K33: =K9 -> vers 'Reignier' | O33: =O9 -> vers 'Arthaz' | S33: =S9 -> vers 'Arthaz' | W33: =W9 -> vers 'Annemasse'
C34: H | E34: F | G34: H | I34: F | K34: H | M34: F | O34: H | Q34: F | S34: H | U34: F | W34: H | Y34: F
A35: Période | C35: VAE | D35: vélo | E35: VAE | F35: vélo | G35: VAE | H35: vélo | I35: VAE | J35: vélo | K35: VAE | L35: vélo | M35: VAE | N35: vélo | O35: VAE | P35: vélo | Q35: VAE | R35: vélo | S35: VAE | T35: vélo | U35: VAE | V35: vélo | W35: VAE | X35: vélo | Y35: VAE | Z35: vélo | AA35: Période
A36: de 6:30 à 7:30 | C36: =SUM(C12:C15) -> 0 | D36: =SUM(D12:D15) -> 1 | E36: =SUM(E12:E15) -> 0 | F36: =SUM(F12:F15) -> 0 | G36: =SUM(G12:G15) -> 0 | H36: =SUM(H12:H15) -> 0 | I36: =SUM(I12:I15) -> 0 | J36: =SUM(J12:J15) -> 0 | ... Z36: =SUM(Z12:Z15) -> 0 | AA36: de 6:30 à 7:30 | AC36: =SUM(C36:Z36) -> 9 | AD36: =IF(AC36=0,0,AD48/AC36) -> 0.11111111 | AE36: =IF(AC36=0,0,AE48/AC36) -> 0 | AF36: =IF(AE48=0,0,AF48/AE48) -> 0 | AG36: =IF(AC36=0,0,AG48/AC36) -> 0.66666667 | AH36: =SUM(S36:Z36) -> 8 | AI36: =RE_Eglise!AG72 -> 5 | AJ36: =AI36-AH36 -> -3
A37: de 7:00 à 8:00 | C37: =SUM(C14:C17) -> 0 | D37: =SUM(D14:D17) -> 0 | E37: =SUM(E14:E17) -> 0 | F37: =SUM(F14:F17) -> 0 | G37: =SUM(G14:G17) -> 0 | H37: =SUM(H14:H17) -> 0 | I37: =SUM(I14:I17) -> 0 | J37: =SUM(J14:J17) -> 0 | ... Z37: =SUM(Z14:Z17) -> 0 | AA37: de 7:00 à 8:00 | AC37: =SUM(C37:Z37) -> 8 | AD37: =IF(AC37=0,0,AD49/AC37) -> 0.25 | AE37: =IF(AC37=0,0,AE49/AC37) -> 0.125 | AF37: =IF(AE49=0,0,AF49/AE49) -> 1 | AG37: =IF(AC37=0,0,AG49/AC37) -> 0.75 | AH37: =SUM(S37:Z37) -> 8 | AI37: =RE_Eglise!AG73 -> 8 | AJ37: =AI37-AH37 -> 0
A38: de 7:30 à 8:30 | C38: =SUM(C16:C19) -> 0 | D38: =SUM(D16:D19) -> 0 | E38: =SUM(E16:E19) -> 0 | F38: =SUM(F16:F19) -> 0 | G38: =SUM(G16:G19) -> 0 | H38: =SUM(H16:H19) -> 0 | I38: =SUM(I16:I19) -> 0 | J38: =SUM(J16:J19) -> 0 | ... Z38: =SUM(Z16:Z19) -> 0 | AA38: de 7:30 à 8:30 | AC38: =SUM(C38:Z38) -> 8 | AD38: =IF(AC38=0,0,AD50/AC38) -> 0.5 | AE38: =IF(AC38=0,0,AE50/AC38) -> 0.25 | AF38: =IF(AE50=0,0,AF50/AE50) -> 1 | AG38: =IF(AC38=0,0,AG50/AC38) -> 0.75 | AH38: =SUM(S38:Z38) -> 7 | AI38: =RE_Eglise!AG74 -> 4 | AJ38: =AI38-AH38 -> -3
A39: de 8:00 à 9:00 | C39: =SUM(C18:C21) -> 0 | D39: =SUM(D18:D21) -> 0 | E39: =SUM(E18:E21) -> 0 | F39: =SUM(F18:F21) -> 0 | G39: =SUM(G18:G21) -> 0 | H39: =SUM(H18:H21) -> 0 | I39: =SUM(I18:I21) -> 0 | J39: =SUM(J18:J21) -> 0 | ... Z39: =SUM(Z18:Z21) -> 0 | AA39: de 8:00 à 9:00 | AC39: =SUM(C39:Z39) -> 6 | AD39: =IF(AC39=0,0,AD51/AC39) -> 0.66666667 | AE39: =IF(AC39=0,0,AE51/AC39) -> 0.33333333 | AF39: =IF(AE51=0,0,AF51/AE51) -> 1 | AG39: =IF(AC39=0,0,AG51/AC39) -> 0.66666667 | AH39: =SUM(S39:Z39) -> 5 | AI39: =RE_Eglise!AG75 -> 3 | AJ39: =AI39-AH39 -> -2
A40: de 8:30 à 9:30 | C40: =SUM(C20:C23) -> 0 | D40: =SUM(D20:D23) -> 0 | E40: =SUM(E20:E23) -> 0 | F40: =SUM(F20:F23) -> 0 | G40: =SUM(G20:G23) -> 0 | H40: =SUM(H20:H23) -> 0 | I40: =SUM(I20:I23) -> 0 | J40: =SUM(J20:J23) -> 0 | ... Z40: =SUM(Z20:Z23) -> 0 | AA40: de 8:30 à 9:30 | AC40: =SUM(C40:Z40) -> 1 | AD40: =IF(AC40=0,0,AD52/AC40) -> 1 | AE40: =IF(AC40=0,0,AE52/AC40) -> 1 | AF40: =IF(AE52=0,0,AF52/AE52) -> 1 | AG40: =IF(AC40=0,0,AG52/AC40) -> 1 | AH40: =SUM(S40:Z40) -> 1 | AI40: =RE_Eglise!AG76 -> 2 | AJ40: =AI40-AH40 -> 1
A41: TOTAL | C41: =SUM(C12:C23) -> 0 | D41: =SUM(D12:D23) -> 1 | E41: =SUM(E12:E23) -> 0 | F41: =SUM(F12:F23) -> 0 | G41: =SUM(G12:G23) -> 0 | H41: =SUM(H12:H23) -> 0 | I41: =SUM(I12:I23) -> 0 | J41: =SUM(J12:J23) -> 0 | ... Z41: =SUM(Z12:Z23) -> 0 | AA41: TOTAL | AC41: =SUM(C41:Z41) -> 18 | AD41: =IF(AC41=0,0,AD53/AC41) -> 0.33333333 | AE41: =IF(AC41=0,0,AE53/AC41) -> 0.16666667 | AF41: =IF(AE53=0,0,AF53/AE53) -> 1 | AG41: =IF(AC41=0,0,AG53/AC41) -> 0.72222222 | AH41: =SUM(S41:Z41) -> 16 | AI41: =RE_Eglise!AG77 -> 11 | AJ41: =AI41-AH41 -> -5
A42: =IF($AC$36=MAX($AC$36:$AC$40),A36,IF($AC$37=MAX($AC$36:$AC$40),A37,IF($AC$38=MAX($AC$36:$AC$40),A38,IF($AC$39=MAX($AC$36:$AC$40),A39,A40)))) -> de 6:30 à 7:30 | C42: =IF($AC$36=MAX($AC$36:$AC$40),C36,IF($AC$37=MAX($AC$36:$AC$40),C37,IF($AC$38=MAX($AC$36:$AC$40),C38,IF($AC$39=MAX($AC$36:$AC$40),C39,C40)))) -> 0 | D42: =IF($AC$36=MAX($AC$36:$AC$40),D36,IF($AC$37=MAX($AC$36:$AC$40),D37,IF($AC$38=MAX($AC$36:$AC$40),D38,IF($AC$39=MAX($AC$36:$AC$40),D39,D40)))) -> 1 | E42: =IF($AC$36=MAX($AC$36:$AC$40),E36,IF($AC$37=MAX($AC$36:$AC$40),E37,IF($AC$38=MAX($AC$36:$AC$40),E38,IF($AC$39=MAX($AC$36:$AC$40),E39,E40)))) -> 0 | F42: =IF($AC$36=MAX($AC$36:$AC$40),F36,IF($AC$37=MAX($AC$36:$AC$40),F37,IF($AC$38=MAX($AC$36:$AC$40),F38,IF($AC$39=MAX($AC$36:$AC$40),F39,F40)))) -> 0 | G42: =IF($AC$36=MAX($AC$36:$AC$40),G36,IF($AC$37=MAX($AC$36:$AC$40),G37,IF($AC$38=MAX($AC$36:$AC$40),G38,IF($AC$39=MAX($AC$36:$AC$40),G39,G40)))) -> 0 | H42: =IF($AC$36=MAX($AC$36:$AC$40),H36,IF($AC$37=MAX($AC$36:$AC$40),H37,IF($AC$38=MAX($AC$36:$AC$40),H38,IF($AC$39=MAX($AC$36:$AC$40),H39,H40)))) -> 0 | I42: =IF($AC$36=MAX($AC$36:$AC$40),I36,IF($AC$37=MAX($AC$36:$AC$40),I37,IF($AC$38=MAX($AC$36:$AC$40),I38,IF($AC$39=MAX($AC$36:$AC$40),I39,I40)))) -> 0 | J42: =IF($AC$36=MAX($AC$36:$AC$40),J36,IF($AC$37=MAX($AC$36:$AC$40),J37,IF($AC$38=MAX($AC$36:$AC$40),J38,IF($AC$39=MAX($AC$36:$AC$40),J39,J40)))) -> 0 | ... Z42: =IF($AC$36=MAX($AC$36:$AC$40),Z36,IF($AC$37=MAX($AC$36:$AC$40),Z37,IF($AC$38=MAX($AC$36:$AC$40),Z38,IF($AC$39=MAX($AC$36:$AC$40),Z39,Z40)))) -> 0 | AA42: =A42 -> de 6:30 à 7:30 | AC42: =SUM(C42:Z42) -> 9 | AD42: =IF(AC42=0,0,AD54/AC42) -> 0.11111111 | AE42: =IF(AC42=0,0,AE54/AC42) -> 0 | AF42: =IF(AE54=0,0,AF54/AE54) -> 0 | AG42: =IF(AC42=0,0,AG54/AC42) -> 0.66666667 | AH42: =SUM(S42:Z42) -> 8 | AI42: =RE_Eglise!AG78 -> 4 | AJ42: =AI42-AH42 -> -4
AD44: Nombre de VAE dans le total | AE44: Nombre de femmes dans le total | AF44: Nombre de VAE chez les femmes | AG44: Cycles en direction d'Annemasse-Genève
AD48: =(C36+E36+G36+I36+K36+M36+O36+Q36+S36+U36+W36+Y36) -> 1 | AE48: =(E36+F36+I36+J36+M36+N36+Q36+R36+U36+V36+Y36+Z36) -> 0 | AF48: =(E36+I36+M36+Q36+U36+Y36) -> 0 | AG48: =SUM(G36:J36,W36:Z36) -> 6
AD49: =(C37+E37+G37+I37+K37+M37+O37+Q37+S37+U37+W37+Y37) -> 2 | AE49: =(E37+F37+I37+J37+M37+N37+Q37+R37+U37+V37+Y37+Z37) -> 1 | AF49: =(E37+I37+M37+Q37+U37+Y37) -> 1 | AG49: =SUM(G37:J37,W37:Z37) -> 6
...

Sheet RE_La Forge (gir.)
A1: Lieu : | B1: REIGNIER_Giratoire de la Forge (en-dessous du Fil des Saisons) | M1: Date : | N1: mardi 31 mai 2022
A2: Nom des personnes participant au comptage :
A3: Météo :
A4: Remarques :
A5: Méthodologie : | C5: Pour chaque intervalle de temps, marquer une seule croix par personne comptée
C6: Si c'est enfant, remplacer la croix par E, une trottinette T, un piéton P, etc.
C8: Depuis 'Esery' | K8: Depuis 'Reignier' | S8: Depuis 'Annemasse'
C9: vers 'Reignier' | G9: vers 'Annemasse' | K9: vers 'Esery' | O9: vers 'Annemasse' | S9: vers 'Reignier' | W9: vers 'Esery'
C10: H | E10: F | G10: H | I10: F | K10: H | M10: F | O10: H | Q10: F | S10: H | U10: F | W10: H | Y10: F
A11: Heure | B11: Minute | C11: VAE | D11: vélo | E11: VAE | F11: vélo | G11: VAE | H11: vélo | I11: VAE | J11: vélo | K11: VAE | L11: vélo | M11: VAE | N11: vélo | O11: VAE | P11: vélo | Q11: VAE | R11: vélo | S11: VAE | T11: vélo | U11: VAE | V11: vélo | W11: VAE | X11: vélo | Y11: VAE | Z11: vélo
A12: 6 | B12: 30 – 44'59
B13: 45 – 59'59
A14: 7 | B14: 00 – 14'59
B15: 15 – 29'59
B16: 30 – 44'59
B17: 45 – 59'59
A18: 8 | B18: 00 – 14'59
B19: 15 – 29'59
B20: 30 – 44'59
B21: 45 – 59'59
A22: 9 | B22: 00 – 14'59
B23: 15 – 29'59
A25: Lieu : | B25: =B1 -> REIGNIER_Giratoire de la Forge (en-dessous du Fil des Saisons) | M25: Date : | N25: =N1 -> mardi 31 mai 2022 | AA25: Lieu : | AB25: =B25 -> REIGNIER_Giratoire de la Forge (en-dessous du Fil des Saisons) | AH25: Date : | AI25: =N25 -> mardi 31 mai 2022
A26: Nom des personnes participant au comptage : | G26: =G2 -> 0 | AA26: Nom des personnes participant au comptage : | AE26: =G26 -> 0
A27: Météo : | C27: =C3 -> 0 | AA27: Météo : | AC27: =C27 -> 0
A28: Remarques : | C28: =C4 -> 0 | AA28: Remarques : | AC28: =C28 -> 0
C32: =C8 -> Depuis 'Esery' | K32: =K8 -> Depuis 'Reignier' | S32: =S8 -> Depuis 'Annemasse' | AC32: TOTAL | AD32: Part des VAE dans le total | AE32: Part des femmes dans le total | AF32: Part des VAE chez les femmes | AG32: Part en direction d'Annemasse-Genève | AH32: Part en provenance de Reignier | AI32: Part en provenance d'Esery | AJ32: Remarques
C33: =C9 -> vers 'Reignier' | G33: =G9 -> vers 'Annemasse' | K33: =K9 -> vers 'Esery' | O33: =O9 -> vers 'Annemasse' | S33: =S9 -> vers 'Reignier' | W33: =W9 -> vers 'Esery'
C34: H | E34: F | G34: H | I34: F | K34: H | M34: F | O34: H | Q34: F | S34: H | U34: F | W34: H | Y34: F
A35: Période | C35: VAE | D35: vélo | E35: VAE | F35: vélo | G35: VAE | H35: vélo | I35: VAE | J35: vélo | K35: VAE | L35: vélo | M35: VAE | N35: vélo | O35: VAE | P35: vélo | Q35: VAE | R35: vélo | S35: VAE | T35: vélo | U35: VAE | V35: vélo | W35: VAE | X35: vélo | Y35: VAE | Z35: vélo | AA35: Période
A36: de 6:30 à 7:30 | C36: =SUM(C12:C15) -> 0 | D36: =SUM(D12:D15) -> 0 | E36: =SUM(E12:E15) -> 0 | F36: =SUM(F12:F15) -> 0 | G36: =SUM(G12:G15) -> 0 | H36: =SUM(H12:H15) -> 0 | I36: =SUM(I12:I15) -> 0 | J36: =SUM(J12:J15) -> 0 | ... Z36: =SUM(Z12:Z15) -> 0 | AA36: de 6:30 à 7:30 | AC36: =SUM(C36:Z36) -> 0 | AD36: =IF(AC36=0,0,AD48/AC36) -> 0 | AE36: =IF(AC36=0,0,AE48/AC36) -> 0 | AF36: =IF(AE48=0,0,AF48/AE48) -> 0 | AG36: =IF(AC36=0,0,AG48/AC36) -> 0 | AH36: =IF(AC36=0,0,AH48/AC36) -> 0 | AI36: =IF(AC36=0,0,AI48/AC36) -> 0
A37: de 7:00 à 8:00 | C37: =SUM(C14:C17) -> 0 | D37: =SUM(D14:D17) -> 0 | E37: =SUM(E14:E17) -> 0 | F37: =SUM(F14:F17) -> 0 | G37: =SUM(G14:G17) -> 0 | H37: =SUM(H14:H17) -> 0 | I37: =SUM(I14:I17) -> 0 | J37: =SUM(J14:J17) -> 0 | ... Z37: =SUM(Z14:Z17) -> 0 | AA37: de 7:00 à 8:00 | AC37: =SUM(C37:Z37) -> 0 | AD37: =IF(AC37=0,0,AD49/AC37) -> 0 | AE37: =IF(AC37=0,0,AE49/AC37) -> 0 | AF37: =IF(AE49=0,0,AF49/AE49) -> 0 | AG37: =IF(AC37=0,0,AG49/AC37) -> 0 | AH37: =IF(AC37=0,0,AH49/AC37) -> 0 | AI37: =IF(AC37=0,0,AI49/AC37) -> 0
A38: de 7:30 à 8:30 | C38: =SUM(C16:C19) -> 0 | D38: =SUM(D16:D19) -> 0 | E38: =SUM(E16:E19) -> 0 | F38: =SUM(F16:F19) -> 0 | G38: =SUM(G16:G19) -> 0 | H38: =SUM(H16:H19) -> 0 | I38: =SUM(I16:I19) -> 0 | J38: =SUM(J16:J19) -> 0 | ... Z38: =SUM(Z16:Z19) -> 0 | AA38: de 7:30 à 8:30 | AC38: =SUM(C38:Z38) -> 0 | AD38: =IF(AC38=0,0,AD50/AC38) -> 0 | AE38: =IF(AC38=0,0,AE50/AC38) -> 0 | AF38: =IF(AE50=0,0,AF50/AE50) -> 0 | AG38: =IF(AC38=0,0,AG50/AC38) -> 0 | AH38: =IF(AC38=0,0,AH50/AC38) -> 0 | AI38: =IF(AC38=0,0,AI50/AC38) -> 0
A39: de 8:00 à 9:00 | C39: =SUM(C18:C21) -> 0 | D39: =SUM(D18:D21) -> 0 | E39: =SUM(E18:E21) -> 0 | F39: =SUM(F18:F21) -> 0 | G39: =SUM(G18:G21) -> 0 | H39: =SUM(H18:H21) -> 0 | I39: =SUM(I18:I21) -> 0 | J39: =SUM(J18:J21) -> 0 | ... Z39: =SUM(Z18:Z21) -> 0 | AA39: de 8:00 à 9:00 | AC39: =SUM(C39:Z39) -> 0 | AD39: =IF(AC39=0,0,AD51/AC39) -> 0 | AE39: =IF(AC39=0,0,AE51/AC39) -> 0 | AF39: =IF(AE51=0,0,AF51/AE51) -> 0 | AG39: =IF(AC39=0,0,AG51/AC39) -> 0 | AH39: =IF(AC39=0,0,AH51/AC39) -> 0 | AI39: =IF(AC39=0,0,AI51/AC39) -> 0
A40: de 8:30 à 9:30 | C40: =SUM(C20:C23) -> 0 | D40: =SUM(D20:D23) -> 0 | E40: =SUM(E20:E23) -> 0 | F40: =SUM(F20:F23) -> 0 | G40: =SUM(G20:G23) -> 0 | H40: =SUM(H20:H23) -> 0 | I40: =SUM(I20:I23) -> 0 | J40: =SUM(J20:J23) -> 0 | ... Z40: =SUM(Z20:Z23) -> 0 | AA40: de 8:30 à 9:30 | AC40: =SUM(C40:Z40) -> 0 | AD40: =IF(AC40=0,0,AD52/AC40) -> 0 | AE40: =IF(AC40=0,0,AE52/AC40) -> 0 | AF40: =IF(AE52=0,0,AF52/AE52) -> 0 | AG40: =IF(AC40=0,0,AG52/AC40) -> 0 | AH40: =IF(AC40=0,0,AH52/AC40) -> 0 | AI40: =IF(AC40=0,0,AI52/AC40) -> 0
A41: TOTAL | C41: =SUM(C12:C23) -> 0 | D41: =SUM(D12:D23) -> 0 | E41: =SUM(E12:E23) -> 0 | F41: =SUM(F12:F23) -> 0 | G41: =SUM(G12:G23) -> 0 | H41: =SUM(H12:H23) -> 0 | I41: =SUM(I12:I23) -> 0 | J41: =SUM(J12:J23) -> 0 | ... Z41: =SUM(Z12:Z23) -> 0 | AA41: TOTAL | AC41: =SUM(C41:Z41) -> 0 | AD41: =IF(AC41=0,0,AD53/AC41) -> 0 | AE41: =IF(AC41=0,0,AE53/AC41) -> 0 | AF41: =IF(AE53=0,0,AF53/AE53) -> 0 | AG41: =IF(AC41=0,0,AG53/AC41) -> 0 | AH41: =IF(AC41=0,0,AH53/AC41) -> 0 | AI41: =IF(AC41=0,0,AI53/AC41) -> 0
A42: =IF($AC$36=MAX($AC$36:$AC$40),A36,IF($AC$37=MAX($AC$36:$AC$40),A37,IF($AC$38=MAX($AC$36:$AC$40),A38,IF($AC$39=MAX($AC$36:$AC$40),A39,A40)))) -> de 6:30 à 7:30 | C42: =IF($AC$36=MAX($AC$36:$AC$40),C36,IF($AC$37=MAX($AC$36:$AC$40),C37,IF($AC$38=MAX($AC$36:$AC$40),C38,IF($AC$39=MAX($AC$36:$AC$40),C39,C40)))) -> 0 | D42: =IF($AC$36=MAX($AC$36:$AC$40),D36,IF($AC$37=MAX($AC$36:$AC$40),D37,IF($AC$38=MAX($AC$36:$AC$40),D38,IF($AC$39=MAX($AC$36:$AC$40),D39,D40)))) -> 0 | E42: =IF($AC$36=MAX($AC$36:$AC$40),E36,IF($AC$37=MAX($AC$36:$AC$40),E37,IF($AC$38=MAX($AC$36:$AC$40),E38,IF($AC$39=MAX($AC$36:$AC$40),E39,E40)))) -> 0 | F42: =IF($AC$36=MAX($AC$36:$AC$40),F36,IF($AC$37=MAX($AC$36:$AC$40),F37,IF($AC$38=MAX($AC$36:$AC$40),F38,IF($AC$39=MAX($AC$36:$AC$40),F39,F40)))) -> 0 | G42: =IF($AC$36=MAX($AC$36:$AC$40),G36,IF($AC$37=MAX($AC$36:$AC$40),G37,IF($AC$38=MAX($AC$36:$AC$40),G38,IF($AC$39=MAX($AC$36:$AC$40),G39,G40)))) -> 0 | H42: =IF($AC$36=MAX($AC$36:$AC$40),H36,IF($AC$37=MAX($AC$36:$AC$40),H37,IF($AC$38=MAX($AC$36:$AC$40),H38,IF($AC$39=MAX($AC$36:$AC$40),H39,H40)))) -> 0 | I42: =IF($AC$36=MAX($AC$36:$AC$40),I36,IF($AC$37=MAX($AC$36:$AC$40),I37,IF($AC$38=MAX($AC$36:$AC$40),I38,IF($AC$39=MAX($AC$36:$AC$40),I39,I40)))) -> 0 | J42: =IF($AC$36=MAX($AC$36:$AC$40),J36,IF($AC$37=MAX($AC$36:$AC$40),J37,IF($AC$38=MAX($AC$36:$AC$40),J38,IF($AC$39=MAX($AC$36:$AC$40),J39,J40)))) -> 0 | ... Z42: =IF($AC$36=MAX($AC$36:$AC$40),Z36,IF($AC$37=MAX($AC$36:$AC$40),Z37,IF($AC$38=MAX($AC$36:$AC$40),Z38,IF($AC$39=MAX($AC$36:$AC$40),Z39,Z40)))) -> 0 | AA42: =A42 -> de 6:30 à 7:30 | AC42: =SUM(C42:Z42) -> 0 | AD42: =IF(AC42=0,0,AD54/AC42) -> 0 | AE42: =IF(AC42=0,0,AE54/AC42) -> 0 | AF42: =IF(AE54=0,0,AF54/AE54) -> 0 | AG42: =IF(AC42=0,0,AG54/AC42) -> 0 | AH42: =IF(AC42=0,0,AH54/AC42) -> 0 | AI42: =IF(AC42=0,0,AI54/AC42) -> 0
AD44: Nombre de VAE dans le total | AE44: Nombre de femmes dans le total | AF44: Nombre de VAE chez les femmes | AG44: Cycles en direction d'Annemasse-Genève | AH44: Cycles en provenance de Reignier | AI44: Cycles en provenance d'Esery
AD48: =(C36+E36+G36+I36+K36+M36+O36+Q36+S36+U36+W36+Y36) -> 0 | AE48: =(E36+F36+I36+J36+M36+N36+Q36+R36+U36+V36+Y36+Z36) -> 0 | AF48: =(E36+I36+M36+Q36+U36+Y36) -> 0 | AG48: =SUM(G36:J36,O36:R36) -> 0 | AH48: =SUM(K36:R36) -> 0 | AI48: =SUM(C36:J36) -> 0
AD49: =(C37+E37+G37+I37+K37+M37+O37+Q37+S37+U37+W37+Y37) -> 0 | AE49: =(E37+F37+I37+J37+M37+N37+Q37+R37+U37+V37+Y37+Z37) -> 0 | AF49: =(E37+I37+M37+Q37+U37+Y37) -> 0 | AG49: =SUM(G37:J37,O37:R37) -> 0 | AH49: =SUM(K37:R37) -> 0 | AI49: =SUM(C37:J37) -> 0
...

Sheet RE_Fil Saisons
A1: Lieu : | B1: REIGNIER_Carrefour Marsinge / Viaison (au-dessus du Fil des Saisons) | M1: Date : | N1: mardi 31 mai 2022
A2: Nom des personnes participant au comptage : | G2: Francis AMACHER
A3: Météo :
A4: Remarques :
A5: Méthodologie : | C5: Pour chaque intervalle de temps, marquer une seule croix par personne comptée
C6: Si c'est enfant, remplacer la croix par E, une trottinette T, un piéton P, etc.
C8: Depuis 'Esery' | K8: Depuis 'Reignier' | S8: Depuis 'Annemasse'
C9: vers 'Reignier' | G9: vers 'Annemasse' | K9: vers 'Esery' | O9: vers 'Annemasse' | S9: vers 'Reignier' | W9: vers 'Esery'
C10: H | E10: F | G10: H | I10: F | K10: H | M10: F | O10: H | Q10: F | S10: H | U10: F | W10: H | Y10: F
A11: Heure | B11: Minute | C11: VAE | D11: vélo | E11: VAE | F11: vélo | G11: VAE | H11: vélo | I11: VAE | J11: vélo | K11: VAE | L11: vélo | M11: VAE | N11: vélo | O11: VAE | P11: vélo | Q11: VAE | R11: vélo | S11: VAE | T11: vélo | U11: VAE | V11: vélo | W11: VAE | X11: vélo | Y11: VAE | Z11: vélo
A12: 6 | B12: 30 – 44'59
B13: 45 – 59'59 | O13: 2 | P13: 1
A14: 7 | B14: 00 – 14'59 | O14: 1
B15: 15 – 29'59 | O15: 2 | P15: 1
B16: 30 – 44'59
B17: 45 – 59'59 | G17: 1 | P17: 1 | Q17: 1
A18: 8 | B18: 00 – 14'59 | P18: 1
B19: 15 – 29'59
B20: 30 – 44'59
B21: 45 – 59'59
A22: 9 | B22: 00 – 14'59
B23: 15 – 29'59
A25: Lieu : | B25: =B1 -> REIGNIER_Carrefour Marsinge / Viaison (au-dessus du Fil des Saisons) | M25: Date : | N25: =N1 -> mardi 31 mai 2022 | AA25: Lieu : | AB25: =B25 -> REIGNIER_Carrefour Marsinge / Viaison (au-dessus du Fil des Saisons) | AG25: Date : | AH25: =N25 -> mardi 31 mai 2022
A26: Nom des personnes participant au comptage : | G26: =G2 -> Francis AMACHER | AA26: Nom des personnes participant au comptage : | AE26: =G26 -> Francis AMACHER
A27: Météo : | C27: =C3 -> 0 | AA27: Météo : | AC27: =C27 -> 0
A28: Remarques : | C28: =C4 -> 0 | AA28: Remarques : | AC28: =C28 -> 0
C32: =C8 -> Depuis 'Esery' | K32: =K8 -> Depuis 'Reignier' | S32: =S8 -> Depuis 'Annemasse' | AC32: TOTAL | AD32: Part des VAE dans le total | AE32: Part des femmes dans le total | AF32: Part des VAE chez les femmes | AG32: Part en direction d'Annemasse-Genève | AH32: Part en provenance de Reignier | AI32: Part en provenance d'Esery | AJ32: Remarques
C33: =C9 -> vers 'Reignier' | G33: =G9 -> vers 'Annemasse' | K33: =K9 -> vers 'Esery' | O33: =O9 -> vers 'Annemasse' | S33: =S9 -> vers 'Reignier' | W33: =W9 -> vers 'Esery'
C34: H | E34: F | G34: H | I34: F | K34: H | M34: F | O34: H | Q34: F | S34: H | U34: F | W34: H | Y34: F
A35: Période | C35: VAE | D35: vélo | E35: VAE | F35: vélo | G35: VAE | H35: vélo | I35: VAE | J35: vélo | K35: VAE | L35: vélo | M35: VAE | N35: vélo | O35: VAE | P35: vélo | Q35: VAE | R35: vélo | S35: VAE | T35: vélo | U35: VAE | V35: vélo | W35: VAE | X35: vélo | Y35: VAE | Z35: vélo | AA35: Période
A36: de 6:30 à 7:30 | C36: =SUM(C12:C15) -> 0 | D36: =SUM(D12:D15) -> 0 | E36: =SUM(E12:E15) -> 0 | F36: =SUM(F12:F15) -> 0 | G36: =SUM(G12:G15) -> 0 | H36: =SUM(H12:H15) -> 0 | I36: =SUM(I12:I15) -> 0 | J36: =SUM(J12:J15) -> 0 | ... Z36: =SUM(Z12:Z15) -> 0 | AA36: de 6:30 à 7:30 | AC36: =SUM(C36:Z36) -> 7 | AD36: =IF(AC36=0,0,AD48/AC36) -> 0.71428571 | AE36: =IF(AC36=0,0,AE48/AC36) -> 0 | AF36: =IF(AE48=0,0,AF48/AE48) -> 0 | AG36: =IF(AC36=0,0,AG48/AC36) -> 1 | AH36: =IF(AC36=0,0,AH48/AC36) -> 1 | AI36: =IF(AC36=0,0,AI48/AC36) -> 0
A37: de 7:00 à 8:00 | C37: =SUM(C14:C17) -> 0 | D37: =SUM(D14:D17) -> 0 | E37: =SUM(E14:E17) -> 0 | F37: =SUM(F14:F17) -> 0 | G37: =SUM(G14:G17) -> 1 | H37: =SUM(H14:H17) -> 0 | I37: =SUM(I14:I17) -> 0 | J37: =SUM(J14:J17) -> 0 | ... Z37: =SUM(Z14:Z17) -> 0 | AA37: de 7:00 à 8:00 | AC37: =SUM(C37:Z37) -> 7 | AD37: =IF(AC37=0,0,AD49/AC37) -> 0.71428571 | AE37: =IF(AC37=0,0,AE49/AC37) -> 0.14285714 | AF37: =IF(AE49=0,0,AF49/AE49) -> 1 | AG37: =IF(AC37=0,0,AG49/AC37) -> 1 | AH37: =IF(AC37=0,0,AH49/AC37) -> 0.85714286 | AI37: =IF(AC37=0,0,AI49/AC37) -> 0.14285714
A38: de 7:30 à 8:30 | C38: =SUM(C16:C19) -> 0 | D38: =SUM(D16:D19) -> 0 | E38: =SUM(E16:E19) -> 0 | F38: =SUM(F16:F19) -> 0 | G38: =SUM(G16:G19) -> 1 | H38: =SUM(H16:H19) -> 0 | I38: =SUM(I16:I19) -> 0 | J38: =SUM(J16:J19) -> 0 | ... Z38: =SUM(Z16:Z19) -> 0 | AA38: de 7:30 à 8:30 | AC38: =SUM(C38:Z38) -> 4 | AD38: =IF(AC38=0,0,AD50/AC38) -> 0.5 | AE38: =IF(AC38=0,0,AE50/AC38) -> 0.25 | AF38: =IF(AE50=0,0,AF50/AE50) -> 1 | AG38: =IF(AC38=0,0,AG50/AC38) -> 1 | AH38: =IF(AC38=0,0,AH50/AC38) -> 0.75 | AI38: =IF(AC38=0,0,AI50/AC38) -> 0.25
A39: de 8:00 à 9:00 | C39: =SUM(C18:C21) -> 0 | D39: =SUM(D18:D21) -> 0 | E39: =SUM(E18:E21) -> 0 | F39: =SUM(F18:F21) -> 0 | G39: =SUM(G18:G21) -> 0 | H39: =SUM(H18:H21) -> 0 | I39: =SUM(I18:I21) -> 0 | J39: =SUM(J18:J21) -> 0 | ... Z39: =SUM(Z18:Z21) -> 0 | AA39: de 8:00 à 9:00 | AC39: =SUM(C39:Z39) -> 1 | AD39: =IF(AC39=0,0,AD51/AC39) -> 0 | AE39: =IF(AC39=0,0,AE51/AC39) -> 0 | AF39: =IF(AE51=0,0,AF51/AE51) -> 0 | AG39: =IF(AC39=0,0,AG51/AC39) -> 1 | AH39: =IF(AC39=0,0,AH51/AC39) -> 1 | AI39: =IF(AC39=0,0,AI51/AC39) -> 0
A40: de 8:30 à 9:30 | C40: =SUM(C20:C23) -> 0 | D40: =SUM(D20:D23) -> 0 | E40: =SUM(E20:E23) -> 0 | F40: =SUM(F20:F23) -> 0 | G40: =SUM(G20:G23) -> 0 | H40: =SUM(H20:H23) -> 0 | I40: =SUM(I20:I23) -> 0 | J40: =SUM(J20:J23) -> 0 | ... Z40: =SUM(Z20:Z23) -> 0 | AA40: de 8:30 à 9:30 | AC40: =SUM(C40:Z40) -> 0 | AD40: =IF(AC40=0,0,AD52/AC40) -> 0 | AE40: =IF(AC40=0,0,AE52/AC40) -> 0 | AF40: =IF(AE52=0,0,AF52/AE52) -> 0 | AG40: =IF(AC40=0,0,AG52/AC40) -> 0 | AH40: =IF(AC40=0,0,AH52/AC40) -> 0 | AI40: =IF(AC40=0,0,AI52/AC40) -> 0
A41: TOTAL | C41: =SUM(C12:C23) -> 0 | D41: =SUM(D12:D23) -> 0 | E41: =SUM(E12:E23) -> 0 | F41: =SUM(F12:F23) -> 0 | G41: =SUM(G12:G23) -> 1 | H41: =SUM(H12:H23) -> 0 | I41: =SUM(I12:I23) -> 0 | J41: =SUM(J12:J23) -> 0 | ... Z41: =SUM(Z12:Z23) -> 0 | AA41: TOTAL | AC41: =SUM(C41:Z41) -> 11 | AD41: =IF(AC41=0,0,AD53/AC41) -> 0.63636364 | AE41: =IF(AC41=0,0,AE53/AC41) -> 0.090909091 | AF41: =IF(AE53=0,0,AF53/AE53) -> 1 | AG41: =IF(AC41=0,0,AG53/AC41) -> 1 | AH41: =IF(AC41=0,0,AH53/AC41) -> 0.90909091 | AI41: =IF(AC41=0,0,AI53/AC41) -> 0.090909091
A42: =IF($AC$36=MAX($AC$36:$AC$40),A36,IF($AC$37=MAX($AC$36:$AC$40),A37,IF($AC$38=MAX($AC$36:$AC$40),A38,IF($AC$39=MAX($AC$36:$AC$40),A39,A40)))) -> de 6:30 à 7:30 | C42: =IF($AC$36=MAX($AC$36:$AC$40),C36,IF($AC$37=MAX($AC$36:$AC$40),C37,IF($AC$38=MAX($AC$36:$AC$40),C38,IF($AC$39=MAX($AC$36:$AC$40),C39,C40)))) -> 0 | D42: =IF($AC$36=MAX($AC$36:$AC$40),D36,IF($AC$37=MAX($AC$36:$AC$40),D37,IF($AC$38=MAX($AC$36:$AC$40),D38,IF($AC$39=MAX($AC$36:$AC$40),D39,D40)))) -> 0 | E42: =IF($AC$36=MAX($AC$36:$AC$40),E36,IF($AC$37=MAX($AC$36:$AC$40),E37,IF($AC$38=MAX($AC$36:$AC$40),E38,IF($AC$39=MAX($AC$36:$AC$40),E39,E40)))) -> 0 | F42: =IF($AC$36=MAX($AC$36:$AC$40),F36,IF($AC$37=MAX($AC$36:$AC$40),F37,IF($AC$38=MAX($AC$36:$AC$40),F38,IF($AC$39=MAX($AC$36:$AC$40),F39,F40)))) -> 0 | G42: =IF($AC$36=MAX($AC$36:$AC$40),G36,IF($AC$37=MAX($AC$36:$AC$40),G37,IF($AC$38=MAX($AC$36:$AC$40),G38,IF($AC$39=MAX($AC$36:$AC$40),G39,G40)))) -> 0 | H42: =IF($AC$36=MAX($AC$36:$AC$40),H36,IF($AC$37=MAX($AC$36:$AC$40),H37,IF($AC$38=MAX($AC$36:$AC$40),H38,IF($AC$39=MAX($AC$36:$AC$40),H39,H40)))) -> 0 | I42: =IF($AC$36=MAX($AC$36:$AC$40),I36,IF($AC$37=MAX($AC$36:$AC$40),I37,IF($AC$38=MAX($AC$36:$AC$40),I38,IF($AC$39=MAX($AC$36:$AC$40),I39,I40)))) -> 0 | J42: =IF($AC$36=MAX($AC$36:$AC$40),J36,IF($AC$37=MAX($AC$36:$AC$40),J37,IF($AC$38=MAX($AC$36:$AC$40),J38,IF($AC$39=MAX($AC$36:$AC$40),J39,J40)))) -> 0 | ... Z42: =IF($AC$36=MAX($AC$36:$AC$40),Z36,IF($AC$37=MAX($AC$36:$AC$40),Z37,IF($AC$38=MAX($AC$36:$AC$40),Z38,IF($AC$39=MAX($AC$36:$AC$40),Z39,Z40)))) -> 0 | AA42: =A42 -> de 6:30 à 7:30 | AC42: =SUM(C42:Z42) -> 7 | AD42: =IF(AC42=0,0,AD54/AC42) -> 0.71428571 | AE42: =IF(AC42=0,0,AE54/AC42) -> 0 | AF42: =IF(AE54=0,0,AF54/AE54) -> 0 | AG42: =IF(AC42=0,0,AG54/AC42) -> 1 | AH42: =IF(AC42=0,0,AH54/AC42) -> 1 | AI42: =IF(AC42=0,0,AI54/AC42) -> 0
AD44: Nombre de VAE dans le total | AE44: Nombre de femmes dans le total | AF44: Nombre de VAE chez les femmes | AG44: Cycles en direction d'Annemasse-Genève | AH44: Cycles en provenance de Reignier | AI44: Cycles en provenance d'Esery
AD48: =(C36+E36+G36+I36+K36+M36+O36+Q36+S36+U36+W36+Y36) -> 5 | AE48: =(E36+F36+I36+J36+M36+N36+Q36+R36+U36+V36+Y36+Z36) -> 0 | AF48: =(E36+I36+M36+Q36+U36+Y36) -> 0 | AG48: =SUM(G36:J36,O36:R36) -> 7 | AH48: =SUM(K36:R36) -> 7 | AI48: =SUM(C36:J36) -> 0
AD49: =(C37+E37+G37+I37+K37+M37+O37+Q37+S37+U37+W37+Y37) -> 5 | AE49: =(E37+F37+I37+J37+M37+N37+Q37+R37+U37+V37+Y37+Z37) -> 1 | AF49: =(E37+I37+M37+Q37+U37+Y37) -> 1 | AG49: =SUM(G37:J37,O37:R37) -> 7 | AH49: =SUM(K37:R37) -> 6 | AI49: =SUM(C37:J37) -> 1
...

Sheet ART_Lavage auto
A1: Lieu : | B1: ARTHAZ_Route de Reignier D202 / Route Nationale D1205 | M1: Date : | N1: mardi 31 mai 2022
A2: Nom des personnes participant au comptage :
A3: Météo :
A4: Remarques :
A5: Méthodologie : | C5: Pour chaque intervalle de temps, marquer une seule croix par personne comptée
C6: Si c'est enfant, remplacer la croix par E, une trottinette T, un piéton P, etc.
C8: Depuis 'Annemasse' | O8: Depuis 'Nangy'
C9: vers 'Reignier' | G9: vers 'Nangy' | K9: vers 'Rossat' | O9: vers 'Reignier' | S9: vers 'Annemasse' | W9: vers 'Rossat'
C10: H | E10: F | G10: H | I10: F | K10: H | M10: F | O10: H | Q10: F | S10: H | U10: F | W10: H | Y10: F
A11: Heure | B11: Minute | C11: VAE | D11: vélo | E11: VAE | F11: vélo | G11: VAE | H11: vélo | I11: VAE | J11: vélo | K11: VAE | L11: vélo | M11: VAE | N11: vélo | O11: VAE | P11: vélo | Q11: VAE | R11: vélo | S11: VAE | T11: vélo | U11: VAE | V11: vélo | W11: VAE | X11: vélo | Y11: VAE | Z11: vélo
A12: 6 | B12: 30 – 44'59
A13: 6 | B13: 45 – 59'59
A14: 7 | B14: 00 – 14'59
B15: 15 – 29'59
B16: 30 – 44'59
B17: 45 – 59'59
A18: 8 | B18: 00 – 14'59
B19: 15 – 29'59
B20: 30 – 44'59
B21: 45 – 59'59
A22: 9 | B22: 00 – 14'59
B23: 15 – 29'59
A25: Lieu : | B25: =B1 -> ARTHAZ_Route de Reignier D202 / Route Nationale D1205 | M25: Date : | N25: =N1 -> mardi 31 mai 2022
A26: Nom des personnes participant au comptage : | G26: =G2 -> 0
A27: Météo : | C27: =C3 -> 0
A28: Remarques : | C28: =C4 -> 0
A29: =A5 -> Méthodologie : | C29: =C5 -> Pour chaque intervalle de temps, marquer une seule croix par personne comptée
C30: =C6 -> Si c'est enfant, remplacer la croix par E, une trottinette T, un piéton P, etc.
C32: Depuis 'Reignier' | O32: Depuis 'Rossat'
C33: vers 'Nangy' | G33: vers 'Rossat' | K33: vers 'Annemasse' | O33: vers 'Reignier' | S33: vers 'Nangy' | W33: vers 'Annemasse'
C34: H | E34: F | G34: H | I34: F | K34: H | M34: F | O34: H | Q34: F | S34: H | U34: F | W34: H | Y34: F
A35: Heure | B35: Minute | C35: VAE | D35: vélo | E35: VAE | F35: vélo | G35: VAE | H35: vélo | I35: VAE | J35: vélo | K35: VAE | L35: vélo | M35: VAE | N35: vélo | O35: VAE | P35: vélo | Q35: VAE | R35: vélo | S35: VAE | T35: vélo | U35: VAE | V35: vélo | W35: VAE | X35: vélo | Y35: VAE | Z35: vélo
A36: 6 | B36: 30 – 44'59
A37: 6 | B37: 45 – 59'59
A38: 7 | B38: 00 – 14'59
B39: 15 – 29'59
B40: 30 – 44'59
B41: 45 – 59'59
A42: 8 | B42: 00 – 14'59
B43: 15 – 29'59
...

Sheet ETR_D2 (ex-PN93)
A1: Lieu : | B1: ETREMBIERES_D2 route de la Libération / D906a (ex-PN93) | M1: Date : | N1: mardi 31 mai 2022
A2: Nom des personnes participant au comptage : | F2: Yannick ROGUET
A3: Météo :
A4: Remarques :
A5: Méthodologie : | C5: Pour chaque intervalle de temps, marquer une seule croix par personne comptée
C6: Si c'est enfant, remplacer la croix par E, une trottinette T, un piéton P, etc.
C8: Depuis 'Château d'Etrembières' | K8: Depuis 'Etrembières - Autoroute'
C9: vers 'Reignier' | G9: vers 'Monnetier - La Muraz' | K9: vers 'Reignier' | O9: vers 'Monnetier - La Muraz'
C10: H | E10: F | G10: H | I10: F | K10: H | M10: F | O10: H | Q10: F
A11: Heure | B11: Minute | C11: VAE | D11: vélo | E11: VAE | F11: vélo | G11: VAE | H11: vélo | I11: VAE | J11: vélo | K11: VAE | L11: vélo | M11: VAE | N11: vélo | O11: VAE | P11: vélo | Q11: VAE | R11: vélo
A12: 6 | B12: 30 – 44'59
B13: 45 – 59'59
A14: 7 | B14: 00 – 14'59
B15: 15 – 29'59 | P15: 1
B16: 30 – 44'59 | H16: 1 | K16: 1 | O16: 1
B17: 45 – 59'59
A18: 8 | B18: 00 – 14'59 | L18: 1
B19: 15 – 29'59 | G19: 1 | H19: 1
B20: 30 – 44'59
B21: 45 – 59'59
A22: 9 | B22: 00 – 14'59
B23: 15 – 29'59
A25: Lieu : | B25: =B1 -> ETREMBIERES_D2 route de la Libération / D906a (ex-PN93) | M25: Date : | N25: =N1 -> mardi 31 mai 2022
A26: Nom des personnes participant au comptage : | F26: =F2 -> Yannick ROGUET
A27: Météo : | C27: =C3 -> 0
A28: Remarques : | C28: =C4 -> 0
A29: =A5 -> Méthodologie : | C29: =C5 -> Pour chaque intervalle de temps, marquer une seule croix par personne comptée
C30: =C6 -> Si c'est enfant, remplacer la croix par E, une trottinette T, un piéton P, etc.
C32: Depuis 'Reignier' | K32: Depuis 'Monnetier - La Muraz'
C33: vers 'Château d'Etrembières' | G33: vers 'Etrembières - Autoroute' | K33: vers 'Château d'Etrembières' | O33: vers 'Etrembières - Autoroute'
C34: H | E34: F | G34: H | I34: F | K34: H | M34: F | O34: H | Q34: F
A35: Heure | B35: Minute | C35: VAE | D35: vélo | E35: VAE | F35: vélo | G35: VAE | H35: vélo | I35: VAE | J35: vélo | K35: VAE | L35: vélo | M35: VAE | N35: vélo | O35: VAE | P35: vélo | Q35: VAE | R35: vélo
A36: 6 | B36: 30 – 44'59
B37: 45 – 59'59
A38: 7 | B38: 00 – 14'59 | C38: 2 | D38: 2 | H38: 1 | K38: 1
B39: 15 – 29'59 | C39: 1 | D39: 1 | H39: 1 | K39: 1 | M39: 1 | O39: 2 | P39: 2
B40: 30 – 44'59 | C40: 1 | D40: 1 | G40: 1 | H40: 1 | O40: 4 | Q40: 2
B41: 45 – 59'59 | G41: 2 | I41: 1 | K41: 1 | M41: 1 | O41: 3
A42: 8 | B42: 00 – 14'59 | C42: 1 | G42: 1 | M42: 2 | R42: 1
B43: 15 – 29'59 | C43: 1 | D43: 1 | I43: 1 | Q43: 1 | R43: 1
...

Sheet ETR_Château
A1: Lieu : | B1: ETREMBIERES_Rte de St-Julien / Rte du Salève (sous château) | M1: Date : | N1: mardi 31 mai 2022
A2: Nom des personnes participant au comptage : | G2: Philippe LEMOINE
A3: Météo :
A4: Remarques : | C4: Aucun vélo n'est allé en direction du nouveau chemin du pied du Salève (qui rejoint Le Pas-de-L'Echelle)
A5: Méthodologie : | C5: Pour chaque intervalle de temps, marquer une seule croix par personne comptée
C6: Si c'est enfant, remplacer la croix par E, une trottinette T, un piéton P, etc.
C8: Depuis 'Pas-de-l'Echelle' | K8: Depuis 'Annemasse' | S8: Depuis 'Reignier'
C9: vers 'Reignier' | G9: vers 'Annemasse' | K9: vers 'Reignier' | O9: vers 'Pas-de-l'Echelle' | S9: vers 'Pas-de-l'Echelle' | W9: vers 'Annemasse'
C10: H | E10: F | G10: H | I10: F | K10: H | M10: F | O10: H | Q10: F | S10: H | U10: F | W10: H | Y10: F
A11: Heure | B11: Minute | C11: VAE | D11: vélo | E11: VAE | F11: vélo | G11: VAE | H11: vélo | I11: VAE | J11: vélo | K11: VAE | L11: vélo | M11: VAE | N11: vélo | O11: VAE | P11: vélo | Q11: VAE | R11: vélo | S11: VAE | T11: vélo | U11: VAE | V11: vélo | W11: VAE | X11: vélo | Y11: VAE | Z11: vélo
A12: 6 | B12: 30 – 44'59
B13: 45 – 59'59
A14: 7 | B14: 00 – 14'59 | P14: 1 | S14: 1 | T14: 2
B15: 15 – 29'59 | O15: 1 | P15: 1 | S15: 1 | T15: 2 | U15: 1
B16: 30 – 44'59 | D16: 1 | S16: 1
B17: 45 – 59'59 | T17: 3 | U17: 2
A18: 8 | B18: 00 – 14'59 | T18: 1 | U18: 1
B19: 15 – 29'59 | C19: 1 | P19: 1 | R19: 1 | S19: 2 | T19: 1 | V19: 1
B20: 30 – 44'59
B21: 45 – 59'59
A22: 9 | B22: 00 – 14'59
B23: 15 – 29'59
A25: Lieu : | B25: =B1 -> ETREMBIERES_Rte de St-Julien / Rte du Salève (sous château) | M25: Date : | N25: =N1 -> mardi 31 mai 2022 | AA25: Lieu : | AB25: =B25 -> ETREMBIERES_Rte de St-Julien / Rte du Salève (sous château) | AG25: Date : | AH25: =N25 -> mardi 31 mai 2022
A26: Nom des personnes participant au comptage : | G26: =G2 -> Philippe LEMOINE | AA26: Nom des personnes participant au comptage : | AE26: =G26 -> Philippe LEMOINE
A27: Météo : | C27: =C3 -> 0 | AA27: Météo : | AC27: =C27 -> 0
A28: Remarques : | C28: =C4 -> Aucun vélo n'est allé en direction du nouveau chemin du pied du Salève (qui rejoint Le Pas-de-L'Echelle) | AA28: Remarques : | AC28: =C28 -> Aucun vélo n'est allé en direction du nouveau chemin du pied du Salève (qui rejoint Le Pas-de-L'Echelle)
C32: =C8 -> Depuis 'Pas-de-l'Echelle' | K32: =K8 -> Depuis 'Annemasse' | S32: =S8 -> Depuis 'Reignier' | AC32: TOTAL | AD32: Part des VAE dans le total | AE32: Part des femmes dans le total | AF32: Part des VAE chez les femmes | AG32: Part en direction d'Annemasse-Genève | AH32: Cycles en provenance de Reignier | AI32: Cycles comptés au carrefour amont (PN93) | AJ32: Différence de cycles entre ces deux carrefour : >> descendus au chemin raide sous le cimetière, >> parti en vélo depuis le parking du cimetière ?
C33: =C9 -> vers 'Reignier' | G33: =G9 -> vers 'Annemasse' | K33: =K9 -> vers 'Reignier' | O33: =O9 -> vers 'Pas-de-l'Echelle' | S33: =S9 -> vers 'Pas-de-l'Echelle' | W33: =W9 -> vers 'Annemasse'
C34: H | E34: F | G34: H | I34: F | K34: H | M34: F | O34: H | Q34: F | S34: H | U34: F | W34: H | Y34: F
A35: Période | C35: VAE | D35: vélo | E35: VAE | F35: vélo | G35: VAE | H35: vélo | I35: VAE | J35: vélo | K35: VAE | L35: vélo | M35: VAE | N35: vélo | O35: VAE | P35: vélo | Q35: VAE | R35: vélo | S35: VAE | T35: vélo | U35: VAE | V35: vélo | W35: VAE | X35: vélo | Y35: VAE | Z35: vélo | AA35: Période
A36: de 6:30 à 7:30 | C36: =SUM(C12:C15) -> 0 | D36: =SUM(D12:D15) -> 0 | E36: =SUM(E12:E15) -> 0 | F36: =SUM(F12:F15) -> 0 | G36: =SUM(G12:G15) -> 0 | H36: =SUM(H12:H15) -> 0 | I36: =SUM(I12:I15) -> 0 | J36: =SUM(J12:J15) -> 0 | ... Z36: =SUM(Z12:Z15) -> 0 | AA36: de 6:30 à 7:30 | AC36: =SUM(C36:Z36) -> 10 | AD36: =IF(AC36=0,0,AD48/AC36) -> 0.4 | AE36: =IF(AC36=0,0,AE48/AC36) -> 0.1 | AF36: =IF(AE48=0,0,AF48/AE48) -> 1 | AG36: =IF(AC36=0,0,AG48/AC36) -> 1 | AH36: =SUM(S36:Z36) -> 7 | AI36: ='ETR_D2 (ex-PN93)'!Y72 -> 15 | AJ36: =AI36-AH36 -> 8
A37: de 7:00 à 8:00 | C37: =SUM(C14:C17) -> 0 | D37: =SUM(D14:D17) -> 1 | E37: =SUM(E14:E17) -> 0 | F37: =SUM(F14:F17) -> 0 | G37: =SUM(G14:G17) -> 0 | H37: =SUM(H14:H17) -> 0 | I37: =SUM(I14:I17) -> 0 | J37: =SUM(J14:J17) -> 0 | ... Z37: =SUM(Z14:Z17) -> 0 | AA37: de 7:00 à 8:00 | AC37: =SUM(C37:Z37) -> 17 | AD37: =IF(AC37=0,0,AD49/AC37) -> 0.41176471 | AE37: =IF(AC37=0,0,AE49/AC37) -> 0.17647059 | AF37: =IF(AE49=0,0,AF49/AE49) -> 1 | AG37: =IF(AC37=0,0,AG49/AC37) -> 0.94117647 | AH37: =SUM(S37:Z37) -> 13 | AI37: ='ETR_D2 (ex-PN93)'!Y73 -> 33 | AJ37: =AI37-AH37 -> 20
A38: de 7:30 à 8:30 | C38: =SUM(C16:C19) -> 1 | D38: =SUM(D16:D19) -> 1 | E38: =SUM(E16:E19) -> 0 | F38: =SUM(F16:F19) -> 0 | G38: =SUM(G16:G19) -> 0 | H38: =SUM(H16:H19) -> 0 | I38: =SUM(I16:I19) -> 0 | J38: =SUM(J16:J19) -> 0 | ... Z38: =SUM(Z16:Z19) -> 0 | AA38: de 7:30 à 8:30 | AC38: =SUM(C38:Z38) -> 16 | AD38: =IF(AC38=0,0,AD50/AC38) -> 0.4375 | AE38: =IF(AC38=0,0,AE50/AC38) -> 0.3125 | AF38: =IF(AE50=0,0,AF50/AE50) -> 0.6 | AG38: =IF(AC38=0,0,AG50/AC38) -> 0.875 | AH38: =SUM(S38:Z38) -> 12 | AI38: ='ETR_D2 (ex-PN93)'!Y74 -> 28 | AJ38: =AI38-AH38 -> 16
A39: de 8:00 à 9:00 | C39: =SUM(C18:C21) -> 1 | D39: =SUM(D18:D21) -> 0 | E39: =SUM(E18:E21) -> 0 | F39: =SUM(F18:F21) -> 0 | G39: =SUM(G18:G21) -> 0 | H39: =SUM(H18:H21) -> 0 | I39: =SUM(I18:I21) -> 0 | J39: =SUM(J18:J21) -> 0 | ... Z39: =SUM(Z18:Z21) -> 0 | AA39: de 8:00 à 9:00 | AC39: =SUM(C39:Z39) -> 9 | AD39: =IF(AC39=0,0,AD51/AC39) -> 0.44444444 | AE39: =IF(AC39=0,0,AE51/AC39) -> 0.33333333 | AF39: =IF(AE51=0,0,AF51/AE51) -> 0.33333333 | AG39: =IF(AC39=0,0,AG51/AC39) -> 0.88888889 | AH39: =SUM(S39:Z39) -> 6 | AI39: ='ETR_D2 (ex-PN93)'!Y77 -> 43 | AJ39: =AI39-AH39 -> 37
A40: de 8:30 à 9:30 | C40: =SUM(C20:C23) -> 0 | D40: =SUM(D20:D23) -> 0 | E40: =SUM(E20:E23) -> 0 | F40: =SUM(F20:F23) -> 0 | G40: =SUM(G20:G23) -> 0 | H40: =SUM(H20:H23) -> 0 | I40: =SUM(I20:I23) -> 0 | J40: =SUM(J20:J23) -> 0 | ... Z40: =SUM(Z20:Z23) -> 0 | AA40: de 8:30 à 9:30 | AC40: =SUM(C40:Z40) -> 0 | AD40: =IF(AC40=0,0,AD52/AC40) -> 0 | AE40: =IF(AC40=0,0,AE52/AC40) -> 0 | AF40: =IF(AE52=0,0,AF52/AE52) -> 0 | AG40: =IF(AC40=0,0,AG52/AC40) -> 0 | AH40: =SUM(S40:Z40) -> 0 | AI40: ='ETR_D2 (ex-PN93)'!Y78 -> 33 | AJ40: =AI40-AH40 -> 33
A41: TOTAL | C41: =SUM(C12:C23) -> 1 | D41: =SUM(D12:D23) -> 1 | E41: =SUM(E12:E23) -> 0 | F41: =SUM(F12:F23) -> 0 | G41: =SUM(G12:G23) -> 0 | H41: =SUM(H12:H23) -> 0 | I41: =SUM(I12:I23) -> 0 | J41: =SUM(J12:J23) -> 0 | ... Z41: =SUM(Z12:Z23) -> 0 | AA41: TOTAL | AC41: =SUM(C41:Z41) -> 26 | AD41: =IF(AC41=0,0,AD53/AC41) -> 0.42307692 | AE41: =IF(AC41=0,0,AE53/AC41) -> 0.23076923 | AF41: =IF(AE53=0,0,AF53/AE53) -> 0.66666667 | AG41: =IF(AC41=0,0,AG53/AC41) -> 0.92307692 | AH41: =SUM(S41:Z41) -> 19 | AI41: ='ETR_D2 (ex-PN93)'!Y77 -> 43 | AJ41: =AI41-AH41 -> 24
A42: =IF($AC$36=MAX($AC$36:$AC$40),A36,IF($AC$37=MAX($AC$36:$AC$40),A37,IF($AC$38=MAX($AC$36:$AC$40),A38,IF($AC$39=MAX($AC$36:$AC$40),A39,A40)))) -> de 7:00 à 8:00 | C42: =IF($AC$36=MAX($AC$36:$AC$40),C36,IF($AC$37=MAX($AC$36:$AC$40),C37,IF($AC$38=MAX($AC$36:$AC$40),C38,IF($AC$39=MAX($AC$36:$AC$40),C39,C40)))) -> 0 | D42: =IF($AC$36=MAX($AC$36:$AC$40),D36,IF($AC$37=MAX($AC$36:$AC$40),D37,IF($AC$38=MAX($AC$36:$AC$40),D38,IF($AC$39=MAX($AC$36:$AC$40),D39,D40)))) -> 1 | E42: =IF($AC$36=MAX($AC$36:$AC$40),E36,IF($AC$37=MAX($AC$36:$AC$40),E37,IF($AC$38=MAX($AC$36:$AC$40),E38,IF($AC$39=MAX($AC$36:$AC$40),E39,E40)))) -> 0 | F42: =IF($AC$36=MAX($AC$36:$AC$40),F36,IF($AC$37=MAX($AC$36:$AC$40),F37,IF($AC$38=MAX($AC$36:$AC$40),F38,IF($AC$39=MAX($AC$36:$AC$40),F39,F40)))) -> 0 | G42: =IF($AC$36=MAX($AC$36:$AC$40),G36,IF($AC$37=MAX($AC$36:$AC$40),G37,IF($AC$38=MAX($AC$36:$AC$40),G38,IF($AC$39=MAX($AC$36:$AC$40),G39,G40)))) -> 0 | H42: =IF($AC$36=MAX($AC$36:$AC$40),H36,IF($AC$37=MAX($AC$36:$AC$40),H37,IF($AC$38=MAX($AC$36:$AC$40),H38,IF($AC$39=MAX($AC$36:$AC$40),H39,H40)))) -> 0 | I42: =IF($AC$36=MAX($AC$36:$AC$40),I36,IF($AC$37=MAX($AC$36:$AC$40),I37,IF($AC$38=MAX($AC$36:$AC$40),I38,IF($AC$39=MAX($AC$36:$AC$40),I39,I40)))) -> 0 | J42: =IF($AC$36=MAX($AC$36:$AC$40),J36,IF($AC$37=MAX($AC$36:$AC$40),J37,IF($AC$38=MAX($AC$36:$AC$40),J38,IF($AC$39=MAX($AC$36:$AC$40),J39,J40)))) -> 0 | ... Z42: =IF($AC$36=MAX($AC$36:$AC$40),Z36,IF($AC$37=MAX($AC$36:$AC$40),Z37,IF($AC$38=MAX($AC$36:$AC$40),Z38,IF($AC$39=MAX($AC$36:$AC$40),Z39,Z40)))) -> 0 | AA42: =A42 -> de 7:00 à 8:00 | AC42: =SUM(C42:Z42) -> 17 | AD42: =IF(AC42=0,0,AD54/AC42) -> 0.41176471 | AE42: =IF(AC42=0,0,AE54/AC42) -> 0.17647059 | AF42: =IF(AE54=0,0,AF54/AE54) -> 1 | AG42: =IF(AC42=0,0,AG54/AC42) -> 0.94117647 | AH42: =SUM(S42:Z42) -> 13 | AI42: ='ETR_D2 (ex-PN93)'!Y78 -> 33 | AJ42: =AI42-AH42 -> 20
AD44: Nombre de VAE dans le total | AE44: Nombre de femmes dans le total | AF44: Nombre de VAE chez les femmes | AG44: Cycles en direction d'Annemasse-Genève
AD48: =(C36+E36+G36+I36+K36+M36+O36+Q36+S36+U36+W36+Y36) -> 4 | AE48: =(E36+F36+I36+J36+M36+N36+Q36+R36+U36+V36+Y36+Z36) -> 1 | AF48: =(E36+I36+M36+Q36+U36+Y36) -> 1 | AG48: =SUM(G36:J36,O36:Z36) -> 10
AD49: =(C37+E37+G37+I37+K37+M37+O37+Q37+S37+U37+W37+Y37) -> 7 | AE49: =(E37+F37+I37+J37+M37+N37+Q37+R37+U37+V37+Y37+Z37) -> 3 | AF49: =(E37+I37+M37+Q37+U37+Y37) -> 3 | AG49: =SUM(G37:J37,O37:Z37) -> 16
...

Sheet SCI_Bellecombe
A1: Lieu : | B1: SCIENTRIER_Carrefour vers la Tour de Bellecombe | M1: Date : | N1: mardi 31 mai 2022
A2: Nom des personnes participant au comptage :
A3: Météo :
A4: Remarques :
A5: Méthodologie : | C5: Pour chaque intervalle de temps, marquer une seule croix par personne comptée
C6: Si c'est enfant, remplacer la croix par E, une trottinette T, un piéton P, etc.
C8: Depuis 'La Roche' | K8: Depuis 'Reignier' | S8: Depuis 'Findrol'
C9: vers 'Reignier' | G9: vers 'Findrol' | K9: vers 'Findrol' | O9: vers 'La Roche' | S9: vers 'Reignier' | W9: vers 'La Roche'
C10: H | E10: F | G10: H | I10: F | K10: H | M10: F | O10: H | Q10: F | S10: H | U10: F | W10: H | Y10: F
A11: Heure | B11: Minute | C11: VAE | D11: vélo | E11: VAE | F11: vélo | G11: VAE | H11: vélo | I11: VAE | J11: vélo | K11: VAE | L11: vélo | M11: VAE | N11: vélo | O11: VAE | P11: vélo | Q11: VAE | R11: vélo | S11: VAE | T11: vélo | U11: VAE | V11: vélo | W11: VAE | X11: vélo | Y11: VAE | Z11: vélo
A12: 6 | B12: 30 – 44'59
B13: 45 – 59'59
A14: 7 | B14: 00 – 14'59
B15: 15 – 29'59
B16: 30 – 44'59
B17: 45 – 59'59
A18: 8 | B18: 00 – 14'59
B19: 15 – 29'59
B20: 30 – 44'59
B21: 45 – 59'59
A22: 9 | B22: 00 – 14'59
B23: 15 – 29'59
A25: Lieu : | B25: =B1 -> SCIENTRIER_Carrefour vers la Tour de Bellecombe | M25: Date : | N25: =N1 -> mardi 31 mai 2022 | AA25: Lieu : | AB25: =B25 -> SCIENTRIER_Carrefour vers la Tour de Bellecombe | AG25: Date : | AH25: =N25 -> mardi 31 mai 2022
A26: Nom des personnes participant au comptage : | G26: =G2 -> 0 | AA26: Nom des personnes participant au comptage : | AE26: =G26 -> 0
A27: Météo : | C27: =C3 -> 0 | AA27: Météo : | AC27: =C27 -> 0
A28: Remarques : | C28: =C4 -> 0 | AA28: Remarques : | AC28: =C28 -> 0
C32: =C8 -> Depuis 'La Roche' | K32: =K8 -> Depuis 'Reignier' | S32: =S8 -> Depuis 'Findrol' | AC32: TOTAL | AD32: Part des VAE dans le total | AE32: Part des femmes dans le total | AF32: Part des VAE chez les femmes | AG32: Part en direction de Findrol | AH32: Part en provenance de La Roche | AI32: Part en provenance de Reignier | AJ32: Remarques
C33: =C9 -> vers 'Reignier' | G33: =G9 -> vers 'Findrol' | K33: =K9 -> vers 'Findrol' | O33: =O9 -> vers 'La Roche' | S33: =S9 -> vers 'Reignier' | W33: =W9 -> vers 'La Roche'
C34: H | E34: F | G34: H | I34: F | K34: H | M34: F | O34: H | Q34: F | S34: H | U34: F | W34: H | Y34: F
A35: Période | C35: VAE | D35: vélo | E35: VAE | F35: vélo | G35: VAE | H35: vélo | I35: VAE | J35: vélo | K35: VAE | L35: vélo | M35: VAE | N35: vélo | O35: VAE | P35: vélo | Q35: VAE | R35: vélo | S35: VAE | T35: vélo | U35: VAE | V35: vélo | W35: VAE | X35: vélo | Y35: VAE | Z35: vélo | AA35: Période
A36: de 6:30 à 7:30 | C36: =SUM(C12:C15) -> 0 | D36: =SUM(D12:D15) -> 0 | E36: =SUM(E12:E15) -> 0 | F36: =SUM(F12:F15) -> 0 | G36: =SUM(G12:G15) -> 0 | H36: =SUM(H12:H15) -> 0 | I36: =SUM(I12:I15) -> 0 | J36: =SUM(J12:J15) -> 0 | ... Z36: =SUM(Z12:Z15) -> 0 | AA36: de 6:30 à 7:30 | AC36: =SUM(C36:Z36) -> 0 | AD36: =IF(AC36=0,0,AD48/AC36) -> 0 | AE36: =IF(AC36=0,0,AE48/AC36) -> 0 | AF36: =IF(AE48=0,0,AF48/AE48) -> 0 | AG36: =IF(AC36=0,0,AG48/AC36) -> 0 | AH36: =IF(AC36=0,0,AH48/AC36) -> 0 | AI36: =IF(AC36=0,0,AI48/AC36) -> 0
