Workbook

Sheet PJ_Casino
A1: Lieu : | B1: PERS-JUSSY_Giratoire de Casino | M1: Date : | N1: mardi 28 mai 2024
A2: Nom des personnes participant au comptage : | G2: Florence PELTIER
A3: Météo : | C3: Ensoleillé, mais lendemain d'une journée très pluvieuse
A5: Remarques : | C5: Compté de 7h30 à 8h25 >> chiffres redressés sur la base des années précédentes | P5: Méthodologie : | R5: Pour chaque intervalle de temps, marquer une seule croix par personne comptée. Si c'est enfant, remplacer la croix par E, une trottinette T, un piéton P, etc.
C7: Depuis 'La Roche' | P7: Depuis 'Pers-Jussy'
C8: vers 'Reignier' | G8: vers 'Casino' | K8: vers 'Pers-Jussy' | P8: vers 'La Roche' | T8: vers 'Reignier' | X8: vers 'Casino'
C9: H | E9: F | G9: H | I9: F | K9: H | M9: F | P9: H | R9: F | T9: H | V9: F | X9: H | Z9: F
A10: Heure | B10: Minute | C10: VAE | D10: vélo | E10: VAE | F10: vélo | G10: VAE | H10: vélo | I10: VAE | J10: vélo | K10: VAE | L10: vélo | M10: VAE | N10: vélo | P10: VAE | Q10: vélo | R10: VAE | S10: vélo | T10: VAE | U10: vélo | V10: VAE | W10: vélo | X10: VAE | Y10: vélo | Z10: VAE | AA10: vélo
A11: 6 | B11: 30 – 44'59
B12: 45 – 59'59
A13: 7 | B13: 00 – 14 | D13: 2
B14: 15 – 29 | C14: 1 | E14: 1 | T14: 1 | V14: 1
B15: 30 – 44 | V15: 1
B16: 45 – 59 | C16: 1 | T16: 1 | U16: 1
A17: 8 | B17: 00 – 14 | D17: 1
B18: 15 – 29 | T18: 1 | V18: 1 | Y18: 1
B19: 30 – 44 | E19: 1 | W19: 1
B20: 45 – 59 | U20: 1
A21: 9 | B21: 00 – 14'59
B22: 15 – 29'59
A24: Remarques :
C26: Depuis 'Reignier' | P26: Depuis 'Casino'
C27: vers 'Casino' | G27: vers 'Pers-Jussy' | K27: vers 'La Roche' | P27: vers 'Pers-Jussy' | T27: vers 'La Roche' | X27: vers 'Reignier'
C28: H | E28: F | G28: H | I28: F | K28: H | M28: F | P28: H | R28: F | T28: H | V28: F | X28: H | Z28: F
A29: Heure | B29: Minute | C29: VAE | D29: vélo | E29: VAE | F29: vélo | G29: VAE | H29: vélo | I29: VAE | J29: vélo | K29: VAE | L29: vélo | M29: VAE | N29: vélo | P29: VAE | Q29: vélo | R29: VAE | S29: vélo | T29: VAE | U29: vélo | V29: VAE | W29: vélo | X29: VAE | Y29: vélo | Z29: VAE | AA29: vélo
A30: 6 | B30: 30 – 44'59
B31: 45 – 59'59
A32: 7 | B32: 00 – 14
B33: 15 – 29
B34: 30 – 44
B35: 45 – 59
A36: 8 | B36: 00 – 14
B37: 15 – 29 | I37: 1 | P37: 1
B38: 30 – 44
B39: 45 – 59 | D39: 1 | L39: 1
A40: 9 | B40: 00 – 14'59
B41: 15 – 29'59
C44: =C7 -> Depuis 'La Roche' | P44: =P7 -> Depuis 'Pers-Jussy' | AD44: TOTAL | AE44: Part des VAE dans le total | AF44: Part des femmes dans le total | AG44: Part des VAE chez les femmes | AH44: Part en direction de Reignier | AI44: Part en provenance de Reignier | AJ44: Part en provenance d'Esery | AK44: Remarques
C45: =C8 -> vers 'Reignier' | G45: =G8 -> vers 'Casino' | K45: =K8 -> vers 'Pers-Jussy' | P45: =P8 -> vers 'La Roche' | T45: =T8 -> vers 'Reignier' | X45: =X8 -> vers 'Casino'
C46: H | E46: F | G46: H | I46: F | K46: H | M46: F | P46: H | R46: F | T46: H | V46: F | X46: H | Z46: F
...

Sheet RE_Gare
A1: Lieu : | B1: REIGNIER_Carrefour Rue de la Gare / Rte de Bellecombe (vers Tour d'Ivoire) | M1: Date : | N1: mardi 28 mai 2024
A2: Nom des personnes participant au comptage : | G2: Marie-Christine VAGNOUX
A3: Météo : | C3: Ensoleillé, mais lendemain d'une journée très pluvieuse
A5: Remarques : | P5: Méthodologie : | R5: Pour chaque intervalle de temps, marquer une seule croix par personne comptée. Si c'est enfant, remplacer la croix par E, une trottinette T, un piéton P, etc.
C7: Depuis 'Pers-Jussy' | L7: Depuis 'Reignier-centre' | U7: Depuis 'Gare'
C8: vers 'Reignier' | G8: vers 'Gare' | L8: vers 'Pers-Jussy' | P8: vers 'Gare' | U8: vers 'Reignier-centre' | Y8: vers 'Pers-Jussy'
C9: H | E9: F | G9: H | I9: F | L9: H | N9: F | P9: H | R9: F | U9: H | W9: F | Y9: H | AA9: F
A10: Heure | B10: Minute | C10: VAE | D10: vélo | E10: VAE | F10: vélo | G10: VAE | H10: vélo | I10: VAE | J10: vélo | L10: VAE | M10: vélo | N10: VAE | O10: vélo | P10: VAE | Q10: vélo | R10: VAE | S10: vélo | U10: VAE | V10: vélo | W10: VAE | X10: vélo | Y10: VAE | Z10: vélo | AA10: VAE | AB10: vélo
A11: 6 | B11: 30 – 44'59
B12: 45 – 59'59
A13: 7 | B13: 00 – 14 | D13: 2 | I13: 1 | Q13: 1 | R13: 1
B14: 15 – 29 | C14: 2 | Q14: 2 | R14: 1
B15: 30 – 44 | D15: 1 | I15: 1 | P15: 2 | S15: 1 | V15: 1 | X15: 1
B16: 45 – 59 | D16: 1 | E16: 1 | F16: 1
A17: 8 | B17: 00 – 14 | D17: 1
B18: 15 – 29 | D18: 1 | N18: 1 | R18: 1
B19: 30 – 44 | H19: 1 | V19: 1
B20: 45 – 59
A21: 9 | B21: 00 – 14'59
B22: 15 – 29'59
C25: =C7 -> Depuis 'Pers-Jussy' | L25: =L7 -> Depuis 'Reignier-centre' | U25: =U7 -> Depuis 'Gare' | AE25: TOTAL | AF25: Part des VAE dans le total | AG25: Part des femmes dans le total | AH25: Part des VAE chez les femmes | AI25: Part en direction d'Annemasse-Genève | AJ25: Part en provenance de Reignier | AK25: Part en provenance d'Esery | AL25: Remarques
C26: =C8 -> vers 'Reignier' | G26: =G8 -> vers 'Gare' | L26: =L8 -> vers 'Pers-Jussy' | P26: =P8 -> vers 'Gare' | U26: =U8 -> vers 'Reignier-centre' | Y26: =Y8 -> vers 'Pers-Jussy'
C27: H | E27: F | G27: H | I27: F | L27: H | N27: F | P27: H | R27: F | U27: H | W27: F | Y27: H | AA27: F
A28: Période | C28: VAE | D28: vélo | E28: VAE | F28: vélo | G28: VAE | H28: vélo | I28: VAE | J28: vélo | L28: VAE | M28: vélo | N28: VAE | O28: vélo | P28: VAE | Q28: vélo | R28: VAE | S28: vélo | U28: VAE | V28: vélo | W28: VAE | X28: vélo | Y28: VAE | Z28: vélo | AA28: VAE | AB28: vélo | AC28: Période
A29: de 6:30 à 7:30 | C29: =SUM(C11:C14) -> 2 | D29: =SUM(D11:D14) -> 2 | E29: =SUM(E11:E14) -> 0 | F29: =SUM(F11:F14) -> 0 | G29: =SUM(G11:G14) -> 0 | H29: =SUM(H11:H14) -> 0 | I29: =SUM(I11:I14) -> 1 | J29: =SUM(J11:J14) -> 0 | L29: =SUM(L11:L14) -> 0 | M29: =SUM(M11:M14) -> 0 | N29: =SUM(N11:N14) -> 0 | O29: =SUM(O11:O14) -> 0 | P29: =SUM(P11:P14) -> 0 | Q29: =SUM(Q11:Q14) -> 3 | R29: =SUM(R11:R14) -> 2 | S29: =SUM(S11:S14) -> 0 | U29: =SUM(U11:U14) -> 0 | V29: =SUM(V11:V14) -> 0 | W29: =SUM(W11:W14) -> 0 | X29: =SUM(X11:X14) -> 0 | Y29: =SUM(Y11:Y14) -> 0 | Z29: =SUM(Z11:Z14) -> 0 | AA29: =SUM(AA11:AA14) -> 0 | AB29: =SUM(AB11:AB14) -> 0 | AC29: de 6:30 à 7:30 | AE29: =SUM(C29:AB29) -> 10 | AF29: =IF(AE29=0,0,AF41/AE29) -> 0.5 | AG29: =IF(AE29=0,0,AG41/AE29) -> 0.3 | AH29: =IF(AG41=0,0,AH41/AG41) -> 1 | AI29: =IF(AE29=0,0,AI41/AE29) -> 0.6 | AJ29: =IF(AE29=0,0,AJ41/AE29) -> 0.5 | AK29: =IF(AE29=0,0,AK41/AE29) -> 0.5
A30: de 7:00 à 8:00 | C30: =SUM(C13:C16) -> 2 | D30: =SUM(D13:D16) -> 4 | E30: =SUM(E13:E16) -> 1 | F30: =SUM(F13:F16) -> 1 | G30: =SUM(G13:G16) -> 0 | H30: =SUM(H13:H16) -> 0 | I30: =SUM(I13:I16) -> 2 | J30: =SUM(J13:J16) -> 0 | L30: =SUM(L13:L16) -> 0 | M30: =SUM(M13:M16) -> 0 | N30: =SUM(N13:N16) -> 0 | O30: =SUM(O13:O16) -> 0 | P30: =SUM(P13:P16) -> 2 | Q30: =SUM(Q13:Q16) -> 3 | R30: =SUM(R13:R16) -> 2 | S30: =SUM(S13:S16) -> 1 | U30: =SUM(U13:U16) -> 0 | V30: =SUM(V13:V16) -> 1 | W30: =SUM(W13:W16) -> 0 | X30: =SUM(X13:X16) -> 1 | Y30: =SUM(Y13:Y16) -> 0 | Z30: =SUM(Z13:Z16) -> 0 | AA30: =SUM(AA13:AA16) -> 0 | AB30: =SUM(AB13:AB16) -> 0 | AC30: de 7:00 à 8:00 | AE30: =SUM(C30:AB30) -> 20 | AF30: =IF(AE30=0,0,AF42/AE30) -> 0.45 | AG30: =IF(AE30=0,0,AG42/AE30) -> 0.4 | AH30: =IF(AG42=0,0,AH42/AG42) -> 0.625 | AI30: =IF(AE30=0,0,AI42/AE30) -> 0.5 | AJ30: =IF(AE30=0,0,AJ42/AE30) -> 0.4 | AK30: =IF(AE30=0,0,AK42/AE30) -> 0.5
A31: de 7:30 à 8:30 | C31: =SUM(C15:C18) -> 0 | D31: =SUM(D15:D18) -> 4 | E31: =SUM(E15:E18) -> 1 | F31: =SUM(F15:F18) -> 1 | G31: =SUM(G15:G18) -> 0 | H31: =SUM(H15:H18) -> 0 | I31: =SUM(I15:I18) -> 1 | J31: =SUM(J15:J18) -> 0 | L31: =SUM(L15:L18) -> 0 | M31: =SUM(M15:M18) -> 0 | N31: =SUM(N15:N18) -> 1 | O31: =SUM(O15:O18) -> 0 | P31: =SUM(P15:P18) -> 2 | Q31: =SUM(Q15:Q18) -> 0 | R31: =SUM(R15:R18) -> 1 | S31: =SUM(S15:S18) -> 1 | U31: =SUM(U15:U18) -> 0 | V31: =SUM(V15:V18) -> 1 | W31: =SUM(W15:W18) -> 0 | X31: =SUM(X15:X18) -> 1 | Y31: =SUM(Y15:Y18) -> 0 | Z31: =SUM(Z15:Z18) -> 0 | AA31: =SUM(AA15:AA18) -> 0 | AB31: =SUM(AB15:AB18) -> 0 | AC31: de 7:30 à 8:30 | AE31: =SUM(C31:AB31) -> 14 | AF31: =IF(AE31=0,0,AF43/AE31) -> 0.42857143 | AG31: =IF(AE31=0,0,AG43/AE31) -> 0.5 | AH31: =IF(AG43=0,0,AH43/AG43) -> 0.57142857 | AI31: =IF(AE31=0,0,AI43/AE31) -> 0.35714286 | AJ31: =IF(AE31=0,0,AJ43/AE31) -> 0.35714286 | AK31: =IF(AE31=0,0,AK43/AE31) -> 0.5
A32: de 8:00 à 9:00 | C32: =SUM(C17:C20) -> 0 | D32: =SUM(D17:D20) -> 2 | E32: =SUM(E17:E20) -> 0 | F32: =SUM(F17:F20) -> 0 | G32: =SUM(G17:G20) -> 0 | H32: =SUM(H17:H20) -> 1 | I32: =SUM(I17:I20) -> 0 | J32: =SUM(J17:J20) -> 0 | L32: =SUM(L17:L20) -> 0 | M32: =SUM(M17:M20) -> 0 | N32: =SUM(N17:N20) -> 1 | O32: =SUM(O17:O20) -> 0 | P32: =SUM(P17:P20) -> 0 | Q32: =SUM(Q17:Q20) -> 0 | R32: =SUM(R17:R20) -> 1 | S32: =SUM(S17:S20) -> 0 | U32: =SUM(U17:U20) -> 0 | V32: =SUM(V17:V20) -> 1 | W32: =SUM(W17:W20) -> 0 | X32: =SUM(X17:X20) -> 0 | Y32: =SUM(Y17:Y20) -> 0 | Z32: =SUM(Z17:Z20) -> 0 | AA32: =SUM(AA17:AA20) -> 0 | AB32: =SUM(AB17:AB20) -> 0 | AC32: de 8:00 à 9:00 | AE32: =SUM(C32:AB32) -> 6 | AF32: =IF(AE32=0,0,AF44/AE32) -> 0.33333333 | AG32: =IF(AE32=0,0,AG44/AE32) -> 0.33333333 | AH32: =IF(AG44=0,0,AH44/AG44) -> 1 | AI32: =IF(AE32=0,0,AI44/AE32) -> 0.33333333 | AJ32: =IF(AE32=0,0,AJ44/AE32) -> 0.33333333 | AK32: =IF(AE32=0,0,AK44/AE32) -> 0.5
A33: de 8:30 à 9:30 | C33: =SUM(C19:C22) -> 0 | D33: =SUM(D19:D22) -> 0 | E33: =SUM(E19:E22) -> 0 | F33: =SUM(F19:F22) -> 0 | G33: =SUM(G19:G22) -> 0 | H33: =SUM(H19:H22) -> 1 | I33: =SUM(I19:I22) -> 0 | J33: =SUM(J19:J22) -> 0 | L33: =SUM(L19:L22) -> 0 | M33: =SUM(M19:M22) -> 0 | N33: =SUM(N19:N22) -> 0 | O33: =SUM(O19:O22) -> 0 | P33: =SUM(P19:P22) -> 0 | Q33: =SUM(Q19:Q22) -> 0 | R33: =SUM(R19:R22) -> 0 | S33: =SUM(S19:S22) -> 0 | U33: =SUM(U19:U22) -> 0 | V33: =SUM(V19:V22) -> 1 | W33: =SUM(W19:W22) -> 0 | X33: =SUM(X19:X22) -> 0 | Y33: =SUM(Y19:Y22) -> 0 | Z33: =SUM(Z19:Z22) -> 0 | AA33: =SUM(AA19:AA22) -> 0 | AB33: =SUM(AB19:AB22) -> 0 | AC33: de 8:30 à 9:30 | AE33: =SUM(C33:AB33) -> 2 | AF33: =IF(AE33=0,0,AF45/AE33) -> 0 | AG33: =IF(AE33=0,0,AG45/AE33) -> 0 | AH33: =IF(AG45=0,0,AH45/AG45) -> 0 | AI33: =IF(AE33=0,0,AI45/AE33) -> 0.5 | AJ33: =IF(AE33=0,0,AJ45/AE33) -> 0 | AK33: =IF(AE33=0,0,AK45/AE33) -> 0.5
A34: TOTAL | C34: =SUM(C11:C22) -> 2 | D34: =SUM(D11:D22) -> 6 | E34: =SUM(E11:E22) -> 1 | F34: =SUM(F11:F22) -> 1 | G34: =SUM(G11:G22) -> 0 | H34: =SUM(H11:H22) -> 1 | I34: =SUM(I11:I22) -> 2 | J34: =SUM(J11:J22) -> 0 | L34: =SUM(L11:L22) -> 0 | M34: =SUM(M11:M22) -> 0 | N34: =SUM(N11:N22) -> 1 | O34: =SUM(O11:O22) -> 0 | P34: =SUM(P11:P22) -> 2 | Q34: =SUM(Q11:Q22) -> 3 | R34: =SUM(R11:R22) -> 3 | S34: =SUM(S11:S22) -> 1 | U34: =SUM(U11:U22) -> 0 | V34: =SUM(V11:V22) -> 2 | W34: =SUM(W11:W22) -> 0 | X34: =SUM(X11:X22) -> 1 | Y34: =SUM(Y11:Y22) -> 0 | Z34: =SUM(Z11:Z22) -> 0 | AA34: =SUM(AA11:AA22) -> 0 | AB34: =SUM(AB11:AB22) -> 0 | AC34: TOTAL | AE34: =SUM(C34:AB34) -> 26 | AF34: =IF(AE34=0,0,AF46/AE34) -> 0.42307692 | AG34: =IF(AE34=0,0,AG46/AE34) -> 0.38461538 | AH34: =IF(AG46=0,0,AH46/AG46) -> 0.7 | AI34: =IF(AE34=0,0,AI46/AE34) -> 0.46153846 | AJ34: =IF(AE34=0,0,AJ46/AE34) -> 0.38461538 | AK34: =IF(AE34=0,0,AK46/AE34) -> 0.5
A35: =IF($AE$29=MAX($AE$29:$AE$33),A29,IF($AE$30=MAX($AE$29:$AE$33),A30,IF($AE$31=MAX($AE$29:$AE$33),A31,IF($AE$32=MAX($AE$29:$AE$33),A32,A33)))) -> de 7:00 à 8:00 | C35: =IF($AE$29=MAX($AE$29:$AE$33),C29,IF($AE$30=MAX($AE$29:$AE$33),C30,IF($AE$31=MAX($AE$29:$AE$33),C31,IF($AE$32=MAX($AE$29:$AE$33),C32,C33)))) -> 2 | D35: =IF($AE$29=MAX($AE$29:$AE$33),D29,IF($AE$30=MAX($AE$29:$AE$33),D30,IF($AE$31=MAX($AE$29:$AE$33),D31,IF($AE$32=MAX($AE$29:$AE$33),D32,D33)))) -> 4 | E35: =IF($AE$29=MAX($AE$29:$AE$33),E29,IF($AE$30=MAX($AE$29:$AE$33),E30,IF($AE$31=MAX($AE$29:$AE$33),E31,IF($AE$32=MAX($AE$29:$AE$33),E32,E33)))) -> 1 | F35: =IF($AE$29=MAX($AE$29:$AE$33),F29,IF($AE$30=MAX($AE$29:$AE$33),F30,IF($AE$31=MAX($AE$29:$AE$33),F31,IF($AE$32=MAX($AE$29:$AE$33),F32,F33)))) -> 1 | G35: =IF($AE$29=MAX($AE$29:$AE$33),G29,IF($AE$30=MAX($AE$29:$AE$33),G30,IF($AE$31=MAX($AE$29:$AE$33),G31,IF($AE$32=MAX($AE$29:$AE$33),G32,G33)))) -> 0 | H35: =IF($AE$29=MAX($AE$29:$AE$33),H29,IF($AE$30=MAX($AE$29:$AE$33),H30,IF($AE$31=MAX($AE$29:$AE$33),H31,IF($AE$32=MAX($AE$29:$AE$33),H32,H33)))) -> 0 | I35: =IF($AE$29=MAX($AE$29:$AE$33),I29,IF($AE$30=MAX($AE$29:$AE$33),I30,IF($AE$31=MAX($AE$29:$AE$33),I31,IF($AE$32=MAX($AE$29:$AE$33),I32,I33)))) -> 2 | J35: =IF($AE$29=MAX($AE$29:$AE$33),J29,IF($AE$30=MAX($AE$29:$AE$33),J30,IF($AE$31=MAX($AE$29:$AE$33),J31,IF($AE$32=MAX($AE$29:$AE$33),J32,J33)))) -> 0 | L35: =IF($AE$29=MAX($AE$29:$AE$33),L29,IF($AE$30=MAX($AE$29:$AE$33),L30,IF($AE$31=MAX($AE$29:$AE$33),L31,IF($AE$32=MAX($AE$29:$AE$33),L32,L33)))) -> 0 | M35: =IF($AE$29=MAX($AE$29:$AE$33),M29,IF($AE$30=MAX($AE$29:$AE$33),M30,IF($AE$31=MAX($AE$29:$AE$33),M31,IF($AE$32=MAX($AE$29:$AE$33),M32,M33)))) -> 0 | N35: =IF($AE$29=MAX($AE$29:$AE$33),N29,IF($AE$30=MAX($AE$29:$AE$33),N30,IF($AE$31=MAX($AE$29:$AE$33),N31,IF($AE$32=MAX($AE$29:$AE$33),N32,N33)))) -> 0 | O35: =IF($AE$29=MAX($AE$29:$AE$33),O29,IF($AE$30=MAX($AE$29:$AE$33),O30,IF($AE$31=MAX($AE$29:$AE$33),O31,IF($AE$32=MAX($AE$29:$AE$33),O32,O33)))) -> 0 | P35: =IF($AE$29=MAX($AE$29:$AE$33),P29,IF($AE$30=MAX($AE$29:$AE$33),P30,IF($AE$31=MAX($AE$29:$AE$33),P31,IF($AE$32=MAX($AE$29:$AE$33),P32,P33)))) -> 2 | Q35: =IF($AE$29=MAX($AE$29:$AE$33),Q29,IF($AE$30=MAX($AE$29:$AE$33),Q30,IF($AE$31=MAX($AE$29:$AE$33),Q31,IF($AE$32=MAX($AE$29:$AE$33),Q32,Q33)))) -> 3 | R35: =IF($AE$29=MAX($AE$29:$AE$33),R29,IF($AE$30=MAX($AE$29:$AE$33),R30,IF($AE$31=MAX($AE$29:$AE$33),R31,IF($AE$32=MAX($AE$29:$AE$33),R32,R33)))) -> 2 | S35: =IF($AE$29=MAX($AE$29:$AE$33),S29,IF($AE$30=MAX($AE$29:$AE$33),S30,IF($AE$31=MAX($AE$29:$AE$33),S31,IF($AE$32=MAX($AE$29:$AE$33),S32,S33)))) -> 1 | U35: =IF($AE$29=MAX($AE$29:$AE$33),U29,IF($AE$30=MAX($AE$29:$AE$33),U30,IF($AE$31=MAX($AE$29:$AE$33),U31,IF($AE$32=MAX($AE$29:$AE$33),U32,U33)))) -> 0 | V35: =IF($AE$29=MAX($AE$29:$AE$33),V29,IF($AE$30=MAX($AE$29:$AE$33),V30,IF($AE$31=MAX($AE$29:$AE$33),V31,IF($AE$32=MAX($AE$29:$AE$33),V32,V33)))) -> 1 | W35: =IF($AE$29=MAX($AE$29:$AE$33),W29,IF($AE$30=MAX($AE$29:$AE$33),W30,IF($AE$31=MAX($AE$29:$AE$33),W31,IF($AE$32=MAX($AE$29:$AE$33),W32,W33)))) -> 0 | X35: =IF($AE$29=MAX($AE$29:$AE$33),X29,IF($AE$30=MAX($AE$29:$AE$33),X30,IF($AE$31=MAX($AE$29:$AE$33),X31,IF($AE$32=MAX($AE$29:$AE$33),X32,X33)))) -> 1 | Y35: =IF($AE$29=MAX($AE$29:$AE$33),Y29,IF($AE$30=MAX($AE$29:$AE$33),Y30,IF($AE$31=MAX($AE$29:$AE$33),Y31,IF($AE$32=MAX($AE$29:$AE$33),Y32,Y33)))) -> 0 | Z35: =IF($AE$29=MAX($AE$29:$AE$33),Z29,IF($AE$30=MAX($AE$29:$AE$33),Z30,IF($AE$31=MAX($AE$29:$AE$33),Z31,IF($AE$32=MAX($AE$29:$AE$33),Z32,Z33)))) -> 0 | AA35: =IF($AE$29=MAX($AE$29:$AE$33),AA29,IF($AE$30=MAX($AE$29:$AE$33),AA30,IF($AE$31=MAX($AE$29:$AE$33),AA31,IF($AE$32=MAX($AE$29:$AE$33),AA32,AA33)))) -> 0 | AB35: =IF($AE$29=MAX($AE$29:$AE$33),AB29,IF($AE$30=MAX($AE$29:$AE$33),AB30,IF($AE$31=MAX($AE$29:$AE$33),AB31,IF($AE$32=MAX($AE$29:$AE$33),AB32,AB33)))) -> 0 | AC35: =A35 -> de 7:00 à 8:00 | AE35: =SUM(C35:AB35) -> 20 | AF35: =IF(AE35=0,0,AF47/AE35) -> 0.45 | AG35: =IF(AE35=0,0,AG47/AE35) -> 0.4 | AH35: =IF(AG47=0,0,AH47/AG47) -> 0.625 | AI35: =IF(AE35=0,0,AI47/AE35) -> 0.5 | AJ35: =IF(AE35=0,0,AJ47/AE35) -> 0.4 | AK35: =IF(AE35=0,0,AK47/AE35) -> 0.5
AF37: Nombre de VAE dans le total | AG37: Nombre de femmes dans le total | AH37: Nombre de VAE chez les femmes | AI37: Cycles en direction d'Annemasse-Genève | AJ37: Cycles en provenance de Reignier | AK37: Cycles en provenance d'Esery
AF41: =(C29+E29+G29+I29+L29+N29+P29+R29+U29+W29+Y29+AA29) -> 5 | AG41: =(E29+F29+I29+J29+N29+O29+R29+S29+W29+X29+AA29+AB29) -> 3 | AH41: =(E29+I29+N29+R29+W29+AA29) -> 3 | AI41: =SUM(G29:J29,P29:S29) -> 6 | AJ41: =SUM(L29:S29) -> 5 | AK41: =SUM(C29:J29) -> 5
AF42: =(C30+E30+G30+I30+L30+N30+P30+R30+U30+W30+Y30+AA30) -> 9 | AG42: =(E30+F30+I30+J30+N30+O30+R30+S30+W30+X30+AA30+AB30) -> 8 | AH42: =(E30+I30+N30+R30+W30+AA30) -> 5 | AI42: =SUM(G30:J30,P30:S30) -> 10 | AJ42: =SUM(L30:S30) -> 8 | AK42: =SUM(C30:J30) -> 10
AF43: =(C31+E31+G31+I31+L31+N31+P31+R31+U31+W31+Y31+AA31) -> 6 | AG43: =(E31+F31+I31+J31+N31+O31+R31+S31+W31+X31+AA31+AB31) -> 7 | AH43: =(E31+I31+N31+R31+W31+AA31) -> 4 | AI43: =SUM(G31:J31,P31:S31) -> 5 | AJ43: =SUM(L31:S31) -> 5 | AK43: =SUM(C31:J31) -> 7
AF44: =(C32+E32+G32+I32+L32+N32+P32+R32+U32+W32+Y32+AA32) -> 2 | AG44: =(E32+F32+I32+J32+N32+O32+R32+S32+W32+X32+AA32+AB32) -> 2 | AH44: =(E32+I32+N32+R32+W32+AA32) -> 2 | AI44: =SUM(G32:J32,P32:S32) -> 2 | AJ44: =SUM(L32:S32) -> 2 | AK44: =SUM(C32:J32) -> 3
AF45: =(C33+E33+G33+I33+L33+N33+P33+R33+U33+W33+Y33+AA33) -> 0 | AG45: =(E33+F33+I33+J33+N33+O33+R33+S33+W33+X33+AA33+AB33) -> 0 | AH45: =(E33+I33+N33+R33+W33+AA33) -> 0 | AI45: =SUM(G33:J33,P33:S33) -> 1 | AJ45: =SUM(L33:S33) -> 0 | AK45: =SUM(C33:J33) -> 1
AF46: =(C34+E34+G34+I34+L34+N34+P34+R34+U34+W34+Y34+AA34) -> 11 | AG46: =(E34+F34+I34+J34+N34+O34+R34+S34+W34+X34+AA34+AB34) -> 10 | AH46: =(E34+I34+N34+R34+W34+AA34) -> 7 | AI46: =SUM(G34:J34,P34:S34) -> 12 | AJ46: =SUM(L34:S34) -> 10 | AK46: =SUM(C34:J34) -> 13
AF47: =(C35+E35+G35+I35+L35+N35+P35+R35+U35+W35+Y35+AA35) -> 9 | AG47: =(E35+F35+I35+J35+N35+O35+R35+S35+W35+X35+AA35+AB35) -> 8 | AH47: =(E35+I35+N35+R35+W35+AA35) -> 5 | AI47: =SUM(G35:J35,P35:S35) -> 10 | AJ47: =SUM(L35:S35) -> 8 | AK47: =SUM(C35:J35) -> 10

Sheet RE_Eglise
A1: Lieu : | B1: REIGNIER_Giratoire des Jonquilles (devant l'église) | M1: Date : | N1: mardi 28 mai 2024
A2: Nom des personnes participant au comptage : | G2: Sylvain BEAUD
A3: Météo : | C3: Ensoleillé, mais lendemain d'une journée très pluvieuse
A5: Remarques : | P5: Méthodologie : | R5: Pour chaque intervalle de temps, marquer une seule croix par personne comptée. Si c'est enfant, remplacer la croix par E, une trottinette T, un piéton P, etc.
C7: Depuis 'Annemasse - Genève' | P7: Depuis 'L'Eculaz'
C8: vers 'Reignier-centre' | G8: vers 'Rue des Ecoles' | K8: vers 'L'Eculaz' | P8: vers 'Reignier-centre' | T8: vers 'Rue des Ecoles' | X8: vers 'Annemasse - Genève'
C9: H | E9: F | G9: H | I9: F | K9: H | M9: F | P9: H | R9: F | T9: H | V9: F | X9: H | Z9: F
A10: Heure | B10: Minute | C10: VAE | D10: vélo | E10: VAE | F10: vélo | G10: VAE | H10: vélo | I10: VAE | J10: vélo | K10: VAE | L10: vélo | M10: VAE | N10: vélo | P10: VAE | Q10: vélo | R10: VAE | S10: vélo | T10: VAE | U10: vélo | V10: VAE | W10: vélo | X10: VAE | Y10: vélo | Z10: VAE | AA10: vélo
A11: 6 | B11: 30 – 44'59
B12: 45 – 59'59
A13: 7 | B13: 00 – 14 | AB13: =SUM(C13:AA13) -> 0 | AC13: =SUM(AB13:AB16) -> 15
B14: 15 – 29 | V14: 1 | AB14: =SUM(C14:AA14) -> 1
B15: 30 – 44 | Q15: 1 | X15: 1 | AB15: =SUM(C15:AA15) -> 2
B16: 45 – 59 | S16: 2 | U16: 6 | W16: 3 | Y16: 1 | AB16: =SUM(C16:AA16) -> 12
A17: 8 | B17: 00 – 14 | W17: 2 | AB17: =SUM(C17:AA17) -> 2 | AC17: =SUM(AB17:AB20) -> 6
B18: 15 – 29 | X18: 1 | AB18: =SUM(C18:AA18) -> 1
B19: 30 – 44 | L19: 1 | P19: 1 | AB19: =SUM(C19:AA19) -> 2
B20: 45 – 59 | X20: 1 | AB20: =SUM(C20:AA20) -> 1
A21: 9 | B21: 00 – 14'59
B22: 15 – 29'59
A24: Remarques :
C26: Depuis 'Reignier-centre' | P26: Depuis 'Reignier - Rue des Ecoles'
C27: vers 'Annemasse - Genève' | G27: vers 'Rue des Ecoles' | K27: vers 'L'Eculaz' | P27: vers 'Reignier-centre' | T27: vers 'L'Eculaz' | X27: vers 'Annemasse - Genève'
C28: H | E28: F | G28: H | I28: F | K28: H | M28: F | P28: H | R28: F | T28: H | V28: F | X28: H | Z28: F
A29: Heure | B29: Minute | C29: VAE | D29: vélo | E29: VAE | F29: vélo | G29: VAE | H29: vélo | I29: VAE | J29: vélo | K29: VAE | L29: vélo | M29: VAE | N29: vélo | P29: VAE | Q29: vélo | R29: VAE | S29: vélo | T29: VAE | U29: vélo | V29: VAE | W29: vélo | X29: VAE | Y29: vélo | Z29: VAE | AA29: vélo
A30: 6 | B30: 30 – 44'59
B31: 45 – 59'59
A32: 7 | B32: 00 – 14 | C32: 2 | D32: 3 | N32: 1 | AB32: =SUM(C32:AA32) -> 6 | AC32: =SUM(AB32:AB35) -> 15
B33: 15 – 29 | E33: 1 | F33: 1 | AB33: =SUM(C33:AA33) -> 2
B34: 30 – 44 | D34: 1 | E34: 1 | H34: 1 | L34: 2 | AB34: =SUM(C34:AA34) -> 5
B35: 45 – 59 | D35: 1 | L35: 1 | AB35: =SUM(C35:AA35) -> 2
A36: 8 | B36: 00 – 14 | H36: 2 | J36: 2 | L36: 1 | M36: 2 | P36: 1 | R36: 1 | U36: 1 | AB36: =SUM(C36:AA36) -> 10 | AC36: =SUM(AB36:AB39) -> 15
B37: 15 – 29 | G37: 1 | AB37: =SUM(C37:AA37) -> 1
B38: 30 – 44 | D38: 1 | G38: 1 | M38: 1 | N38: 1 | AB38: =SUM(C38:AA38) -> 4
B39: 45 – 59 | AB39: =SUM(C39:AA39) -> 0
A40: 9 | B40: 00 – 14'59
B41: 15 – 29'59
C44: =C7 -> Depuis 'Annemasse - Genève' | P44: =P7 -> Depuis 'L'Eculaz' | AD44: TOTAL | AE44: Part des VAE dans le total | AF44: Part des femmes dans le total | AG44: Part des VAE chez les femmes | AH44: Part en direction d'Annemasse-Genève | AI44: Remarques
C45: =C8 -> vers 'Reignier-centre' | G45: =G8 -> vers 'Rue des Ecoles' | K45: =K8 -> vers 'L'Eculaz' | P45: =P8 -> vers 'Reignier-centre' | T45: =T8 -> vers 'Rue des Ecoles' | X45: =X8 -> vers 'Annemasse - Genève'
C46: H | E46: F | G46: H | I46: F | K46: H | M46: F | P46: H | R46: F | T46: H | V46: F | X46: H | Z46: F
...

Sheet RE_Foron
A1: Lieu : | B1: REIGNIER BAS_Giratoire D2 / D202 (vers le Foron) | M1: Date : | N1: mardi 28 mai 2024
A2: Nom des personnes participant au comptage : | G2: Anne ASHOURI
A3: Météo : | C3: Ensoleillé, mais lendemain d'une journée très pluvieuse
A5: Remarques : | P5: Méthodologie : | R5: Pour chaque intervalle de temps, marquer une seule croix par personne comptée. Si c'est enfant, remplacer la croix par E, une trottinette T, un piéton P, etc.
C7: Depuis 'Arthaz' | L7: Depuis 'Annemasse' | U7: Depuis 'Reignier'
C8: vers 'Reignier' | G8: vers 'Annemasse' | L8: vers 'Reignier' | P8: vers 'Arthaz' | U8: vers 'Arthaz' | Y8: vers 'Annemasse'
C9: H | E9: F | G9: H | I9: F | L9: H | N9: F | P9: H | R9: F | U9: H | W9: F | Y9: H | AA9: F
A10: Heure | B10: Minute | C10: VAE | D10: vélo | E10: VAE | F10: vélo | G10: VAE | H10: vélo | I10: VAE | J10: vélo | L10: VAE | M10: vélo | N10: VAE | O10: vélo | P10: VAE | Q10: vélo | R10: VAE | S10: vélo | U10: VAE | V10: vélo | W10: VAE | X10: vélo | Y10: VAE | Z10: vélo | AA10: VAE | AB10: vélo
A11: 6 | B11: 30 – 44'59
B12: 45 – 59'59
A13: 7 | B13: 00 – 14 | Z13: 2
B14: 15 – 29 | E14: 1 | H14: 1 | W14: 1 | Z14: 1 | AA14: 2
B15: 30 – 44 | V15: 2
B16: 45 – 59 | R16: 1 | V16: 1 | W16: 1 | Z16: 2
A17: 8 | B17: 00 – 14 | E17: 1 | L17: 1 | M17: 1 | Y17: 1
B18: 15 – 29 | W18: 1 | AA18: 1
B19: 30 – 44 | L19: 1 | U19: 1 | V19: 1
B20: 45 – 59 | M20: 1 | V20: 1 | Z20: 2
A21: 9 | B21: 00 – 14'59
B22: 15 – 29'59
C25: =C7 -> Depuis 'Arthaz' | L25: =L7 -> Depuis 'Annemasse' | U25: =U7 -> Depuis 'Reignier' | AE25: TOTAL | AF25: Part des VAE dans le total | AG25: Part des femmes dans le total | AH25: Part des VAE chez les femmes | AI25: Part en direction d'Annemasse-Genève | AJ25: Cycles en provenance de Reignier | AK25: Cycles venant du giratoire des Jonquilles | AL25: Différence de cycles entre ces deux carrefour : >> descendus au chemin raide sous le cimetière, >> parti en vélo depuis le parking du cimetière ?
C26: =C8 -> vers 'Reignier' | G26: =G8 -> vers 'Annemasse' | L26: =L8 -> vers 'Reignier' | P26: =P8 -> vers 'Arthaz' | U26: =U8 -> vers 'Arthaz' | Y26: =Y8 -> vers 'Annemasse'
C27: H | E27: F | G27: H | I27: F | L27: H | N27: F | P27: H | R27: F | U27: H | W27: F | Y27: H | AA27: F
A28: Période | C28: VAE | D28: vélo | E28: VAE | F28: vélo | G28: VAE | H28: vélo | I28: VAE | J28: vélo | L28: VAE | M28: vélo | N28: VAE | O28: vélo | P28: VAE | Q28: vélo | R28: VAE | S28: vélo | U28: VAE | V28: vélo | W28: VAE | X28: vélo | Y28: VAE | Z28: vélo | AA28: VAE | AB28: vélo | AC28: Période
A29: de 6:30 à 7:30 | C29: =SUM(C11:C14) -> 0 | D29: =SUM(D11:D14) -> 0 | E29: =SUM(E11:E14) -> 1 | F29: =SUM(F11:F14) -> 0 | G29: =SUM(G11:G14) -> 0 | H29: =SUM(H11:H14) -> 1 | I29: =SUM(I11:I14) -> 0 | J29: =SUM(J11:J14) -> 0 | L29: =SUM(L11:L14) -> 0 | M29: =SUM(M11:M14) -> 0 | N29: =SUM(N11:N14) -> 0 | O29: =SUM(O11:O14) -> 0 | P29: =SUM(P11:P14) -> 0 | Q29: =SUM(Q11:Q14) -> 0 | R29: =SUM(R11:R14) -> 0 | S29: =SUM(S11:S14) -> 0 | U29: =SUM(U11:U14) -> 0 | V29: =SUM(V11:V14) -> 0 | W29: =SUM(W11:W14) -> 1 | X29: =SUM(X11:X14) -> 0 | Y29: =SUM(Y11:Y14) -> 0 | Z29: =SUM(Z11:Z14) -> 3 | AA29: =SUM(AA11:AA14) -> 2 | AB29: =SUM(AB11:AB14) -> 0 | AC29: de 6:30 à 7:30 | AE29: =SUM(C29:AB29) -> 8 | AF29: =IF(AE29=0,0,AF41/AE29) -> 0.5 | AG29: =IF(AE29=0,0,AG41/AE29) -> 0.5 | AH29: =IF(AG41=0,0,AH41/AG41) -> 1 | AI29: =IF(AE29=0,0,AI41/AE29) -> 0.75 | AJ29: =SUM(U29:AB29) -> 6 | AK29: =RE_Eglise!AH60 -> 7 | AL29: =AK29-AJ29 -> 1
A30: de 7:00 à 8:00 | C30: =SUM(C13:C16) -> 0 | D30: =SUM(D13:D16) -> 0 | E30: =SUM(E13:E16) -> 1 | F30: =SUM(F13:F16) -> 0 | G30: =SUM(G13:G16) -> 0 | H30: =SUM(H13:H16) -> 1 | I30: =SUM(I13:I16) -> 0 | J30: =SUM(J13:J16) -> 0 | L30: =SUM(L13:L16) -> 0 | M30: =SUM(M13:M16) -> 0 | N30: =SUM(N13:N16) -> 0 | O30: =SUM(O13:O16) -> 0 | P30: =SUM(P13:P16) -> 0 | Q30: =SUM(Q13:Q16) -> 0 | R30: =SUM(R13:R16) -> 1 | S30: =SUM(S13:S16) -> 0 | U30: =SUM(U13:U16) -> 0 | V30: =SUM(V13:V16) -> 3 | W30: =SUM(W13:W16) -> 2 | X30: =SUM(X13:X16) -> 0 | Y30: =SUM(Y13:Y16) -> 0 | Z30: =SUM(Z13:Z16) -> 5 | AA30: =SUM(AA13:AA16) -> 2 | AB30: =SUM(AB13:AB16) -> 0 | AC30: de 7:00 à 8:00 | AE30: =SUM(C30:AB30) -> 15 | AF30: =IF(AE30=0,0,AF42/AE30) -> 0.4 | AG30: =IF(AE30=0,0,AG42/AE30) -> 0.4 | AH30: =IF(AG42=0,0,AH42/AG42) -> 1 | AI30: =IF(AE30=0,0,AI42/AE30) -> 0.53333333 | AJ30: =SUM(U30:AB30) -> 12 | AK30: =RE_Eglise!AH61 -> 12 | AL30: =AK30-AJ30 -> 0
A31: de 7:30 à 8:30 | C31: =SUM(C15:C18) -> 0 | D31: =SUM(D15:D18) -> 0 | E31: =SUM(E15:E18) -> 1 | F31: =SUM(F15:F18) -> 0 | G31: =SUM(G15:G18) -> 0 | H31: =SUM(H15:H18) -> 0 | I31: =SUM(I15:I18) -> 0 | J31: =SUM(J15:J18) -> 0 | L31: =SUM(L15:L18) -> 1 | M31: =SUM(M15:M18) -> 1 | N31: =SUM(N15:N18) -> 0 | O31: =SUM(O15:O18) -> 0 | P31: =SUM(P15:P18) -> 0 | Q31: =SUM(Q15:Q18) -> 0 | R31: =SUM(R15:R18) -> 1 | S31: =SUM(S15:S18) -> 0 | U31: =SUM(U15:U18) -> 0 | V31: =SUM(V15:V18) -> 3 | W31: =SUM(W15:W18) -> 2 | X31: =SUM(X15:X18) -> 0 | Y31: =SUM(Y15:Y18) -> 1 | Z31: =SUM(Z15:Z18) -> 2 | AA31: =SUM(AA15:AA18) -> 1 | AB31: =SUM(AB15:AB18) -> 0 | AC31: de 7:30 à 8:30 | AE31: =SUM(C31:AB31) -> 13 | AF31: =IF(AE31=0,0,AF43/AE31) -> 0.53846154 | AG31: =IF(AE31=0,0,AG43/AE31) -> 0.38461538 | AH31: =IF(AG43=0,0,AH43/AG43) -> 1 | AI31: =IF(AE31=0,0,AI43/AE31) -> 0.30769231 | AJ31: =SUM(U31:AB31) -> 9 | AK31: =RE_Eglise!AH62 -> 6 | AL31: =AK31-AJ31 -> -3
A32: de 8:00 à 9:00 | C32: =SUM(C17:C20) -> 0 | D32: =SUM(D17:D20) -> 0 | E32: =SUM(E17:E20) -> 1 | F32: =SUM(F17:F20) -> 0 | G32: =SUM(G17:G20) -> 0 | H32: =SUM(H17:H20) -> 0 | I32: =SUM(I17:I20) -> 0 | J32: =SUM(J17:J20) -> 0 | L32: =SUM(L17:L20) -> 2 | M32: =SUM(M17:M20) -> 2 | N32: =SUM(N17:N20) -> 0 | O32: =SUM(O17:O20) -> 0 | P32: =SUM(P17:P20) -> 0 | Q32: =SUM(Q17:Q20) -> 0 | R32: =SUM(R17:R20) -> 0 | S32: =SUM(S17:S20) -> 0 | U32: =SUM(U17:U20) -> 1 | V32: =SUM(V17:V20) -> 2 | W32: =SUM(W17:W20) -> 1 | X32: =SUM(X17:X20) -> 0 | Y32: =SUM(Y17:Y20) -> 1 | Z32: =SUM(Z17:Z20) -> 2 | AA32: =SUM(AA17:AA20) -> 1 | AB32: =SUM(AB17:AB20) -> 0 | AC32: de 8:00 à 9:00 | AE32: =SUM(C32:AB32) -> 13 | AF32: =IF(AE32=0,0,AF44/AE32) -> 0.53846154 | AG32: =IF(AE32=0,0,AG44/AE32) -> 0.23076923 | AH32: =IF(AG44=0,0,AH44/AG44) -> 1 | AI32: =IF(AE32=0,0,AI44/AE32) -> 0.30769231 | AJ32: =SUM(U32:AB32) -> 8 | AK32: =RE_Eglise!AH63 -> 3 | AL32: =AK32-AJ32 -> -5
A33: de 8:30 à 9:30 | C33: =SUM(C19:C22) -> 0 | D33: =SUM(D19:D22) -> 0 | E33: =SUM(E19:E22) -> 0 | F33: =SUM(F19:F22) -> 0 | G33: =SUM(G19:G22) -> 0 | H33: =SUM(H19:H22) -> 0 | I33: =SUM(I19:I22) -> 0 | J33: =SUM(J19:J22) -> 0 | L33: =SUM(L19:L22) -> 1 | M33: =SUM(M19:M22) -> 1 | N33: =SUM(N19:N22) -> 0 | O33: =SUM(O19:O22) -> 0 | P33: =SUM(P19:P22) -> 0 | Q33: =SUM(Q19:Q22) -> 0 | R33: =SUM(R19:R22) -> 0 | S33: =SUM(S19:S22) -> 0 | U33: =SUM(U19:U22) -> 1 | V33: =SUM(V19:V22) -> 2 | W33: =SUM(W19:W22) -> 0 | X33: =SUM(X19:X22) -> 0 | Y33: =SUM(Y19:Y22) -> 0 | Z33: =SUM(Z19:Z22) -> 2 | AA33: =SUM(AA19:AA22) -> 0 | AB33: =SUM(AB19:AB22) -> 0 | AC33: de 8:30 à 9:30 | AE33: =SUM(C33:AB33) -> 7 | AF33: =IF(AE33=0,0,AF45/AE33) -> 0.28571429 | AG33: =IF(AE33=0,0,AG45/AE33) -> 0 | AH33: =IF(AG45=0,0,AH45/AG45) -> 0 | AI33: =IF(AE33=0,0,AI45/AE33) -> 0.28571429 | AJ33: =SUM(U33:AB33) -> 5 | AK33: =RE_Eglise!AH64 -> 2 | AL33: =AK33-AJ33 -> -3
A34: TOTAL | C34: =SUM(C11:C22) -> 0 | D34: =SUM(D11:D22) -> 0 | E34: =SUM(E11:E22) -> 2 | F34: =SUM(F11:F22) -> 0 | G34: =SUM(G11:G22) -> 0 | H34: =SUM(H11:H22) -> 1 | I34: =SUM(I11:I22) -> 0 | J34: =SUM(J11:J22) -> 0 | L34: =SUM(L11:L22) -> 2 | M34: =SUM(M11:M22) -> 2 | N34: =SUM(N11:N22) -> 0 | O34: =SUM(O11:O22) -> 0 | P34: =SUM(P11:P22) -> 0 | Q34: =SUM(Q11:Q22) -> 0 | R34: =SUM(R11:R22) -> 1 | S34: =SUM(S11:S22) -> 0 | U34: =SUM(U11:U22) -> 1 | V34: =SUM(V11:V22) -> 5 | W34: =SUM(W11:W22) -> 3 | X34: =SUM(X11:X22) -> 0 | Y34: =SUM(Y11:Y22) -> 1 | Z34: =SUM(Z11:Z22) -> 7 | AA34: =SUM(AA11:AA22) -> 3 | AB34: =SUM(AB11:AB22) -> 0 | AC34: TOTAL | AE34: =SUM(C34:AB34) -> 28 | AF34: =IF(AE34=0,0,AF46/AE34) -> 0.46428571 | AG34: =IF(AE34=0,0,AG46/AE34) -> 0.32142857 | AH34: =IF(AG46=0,0,AH46/AG46) -> 1 | AI34: =IF(AE34=0,0,AI46/AE34) -> 0.42857143 | AJ34: =SUM(U34:AB34) -> 20 | AK34: =RE_Eglise!AH65 -> 15 | AL34: =AK34-AJ34 -> -5
A35: =IF($AE$29=MAX($AE$29:$AE$33),A29,IF($AE$30=MAX($AE$29:$AE$33),A30,IF($AE$31=MAX($AE$29:$AE$33),A31,IF($AE$32=MAX($AE$29:$AE$33),A32,A33)))) -> de 7:00 à 8:00 | C35: =IF($AE$29=MAX($AE$29:$AE$33),C29,IF($AE$30=MAX($AE$29:$AE$33),C30,IF($AE$31=MAX($AE$29:$AE$33),C31,IF($AE$32=MAX($AE$29:$AE$33),C32,C33)))) -> 0 | D35: =IF($AE$29=MAX($AE$29:$AE$33),D29,IF($AE$30=MAX($AE$29:$AE$33),D30,IF($AE$31=MAX($AE$29:$AE$33),D31,IF($AE$32=MAX($AE$29:$AE$33),D32,D33)))) -> 0 | E35: =IF($AE$29=MAX($AE$29:$AE$33),E29,IF($AE$30=MAX($AE$29:$AE$33),E30,IF($AE$31=MAX($AE$29:$AE$33),E31,IF($AE$32=MAX($AE$29:$AE$33),E32,E33)))) -> 1 | F35: =IF($AE$29=MAX($AE$29:$AE$33),F29,IF($AE$30=MAX($AE$29:$AE$33),F30,IF($AE$31=MAX($AE$29:$AE$33),F31,IF($AE$32=MAX($AE$29:$AE$33),F32,F33)))) -> 0 | G35: =IF($AE$29=MAX($AE$29:$AE$33),G29,IF($AE$30=MAX($AE$29:$AE$33),G30,IF($AE$31=MAX($AE$29:$AE$33),G31,IF($AE$32=MAX($AE$29:$AE$33),G32,G33)))) -> 0 | H35: =IF($AE$29=MAX($AE$29:$AE$33),H29,IF($AE$30=MAX($AE$29:$AE$33),H30,IF($AE$31=MAX($AE$29:$AE$33),H31,IF($AE$32=MAX($AE$29:$AE$33),H32,H33)))) -> 1 | I35: =IF($AE$29=MAX($AE$29:$AE$33),I29,IF($AE$30=MAX($AE$29:$AE$33),I30,IF($AE$31=MAX($AE$29:$AE$33),I31,IF($AE$32=MAX($AE$29:$AE$33),I32,I33)))) -> 0 | J35: =IF($AE$29=MAX($AE$29:$AE$33),J29,IF($AE$30=MAX($AE$29:$AE$33),J30,IF($AE$31=MAX($AE$29:$AE$33),J31,IF($AE$32=MAX($AE$29:$AE$33),J32,J33)))) -> 0 | L35: =IF($AE$29=MAX($AE$29:$AE$33),L29,IF($AE$30=MAX($AE$29:$AE$33),L30,IF($AE$31=MAX($AE$29:$AE$33),L31,IF($AE$32=MAX($AE$29:$AE$33),L32,L33)))) -> 0 | M35: =IF($AE$29=MAX($AE$29:$AE$33),M29,IF($AE$30=MAX($AE$29:$AE$33),M30,IF($AE$31=MAX($AE$29:$AE$33),M31,IF($AE$32=MAX($AE$29:$AE$33),M32,M33)))) -> 0 | N35: =IF($AE$29=MAX($AE$29:$AE$33),N29,IF($AE$30=MAX($AE$29:$AE$33),N30,IF($AE$31=MAX($AE$29:$AE$33),N31,IF($AE$32=MAX($AE$29:$AE$33),N32,N33)))) -> 0 | O35: =IF($AE$29=MAX($AE$29:$AE$33),O29,IF($AE$30=MAX($AE$29:$AE$33),O30,IF($AE$31=MAX($AE$29:$AE$33),O31,IF($AE$32=MAX($AE$29:$AE$33),O32,O33)))) -> 0 | P35: =IF($AE$29=MAX($AE$29:$AE$33),P29,IF($AE$30=MAX($AE$29:$AE$33),P30,IF($AE$31=MAX($AE$29:$AE$33),P31,IF($AE$32=MAX($AE$29:$AE$33),P32,P33)))) -> 0 | Q35: =IF($AE$29=MAX($AE$29:$AE$33),Q29,IF($AE$30=MAX($AE$29:$AE$33),Q30,IF($AE$31=MAX($AE$29:$AE$33),Q31,IF($AE$32=MAX($AE$29:$AE$33),Q32,Q33)))) -> 0 | R35: =IF($AE$29=MAX($AE$29:$AE$33),R29,IF($AE$30=MAX($AE$29:$AE$33),R30,IF($AE$31=MAX($AE$29:$AE$33),R31,IF($AE$32=MAX($AE$29:$AE$33),R32,R33)))) -> 1 | S35: =IF($AE$29=MAX($AE$29:$AE$33),S29,IF($AE$30=MAX($AE$29:$AE$33),S30,IF($AE$31=MAX($AE$29:$AE$33),S31,IF($AE$32=MAX($AE$29:$AE$33),S32,S33)))) -> 0 | U35: =IF($AE$29=MAX($AE$29:$AE$33),U29,IF($AE$30=MAX($AE$29:$AE$33),U30,IF($AE$31=MAX($AE$29:$AE$33),U31,IF($AE$32=MAX($AE$29:$AE$33),U32,U33)))) -> 0 | V35: =IF($AE$29=MAX($AE$29:$AE$33),V29,IF($AE$30=MAX($AE$29:$AE$33),V30,IF($AE$31=MAX($AE$29:$AE$33),V31,IF($AE$32=MAX($AE$29:$AE$33),V32,V33)))) -> 3 | W35: =IF($AE$29=MAX($AE$29:$AE$33),W29,IF($AE$30=MAX($AE$29:$AE$33),W30,IF($AE$31=MAX($AE$29:$AE$33),W31,IF($AE$32=MAX($AE$29:$AE$33),W32,W33)))) -> 2 | X35: =IF($AE$29=MAX($AE$29:$AE$33),X29,IF($AE$30=MAX($AE$29:$AE$33),X30,IF($AE$31=MAX($AE$29:$AE$33),X31,IF($AE$32=MAX($AE$29:$AE$33),X32,X33)))) -> 0 | Y35: =IF($AE$29=MAX($AE$29:$AE$33),Y29,IF($AE$30=MAX($AE$29:$AE$33),Y30,IF($AE$31=MAX($AE$29:$AE$33),Y31,IF($AE$32=MAX($AE$29:$AE$33),Y32,Y33)))) -> 0 | Z35: =IF($AE$29=MAX($AE$29:$AE$33),Z29,IF($AE$30=MAX($AE$29:$AE$33),Z30,IF($AE$31=MAX($AE$29:$AE$33),Z31,IF($AE$32=MAX($AE$29:$AE$33),Z32,Z33)))) -> 5 | AA35: =IF($AE$29=MAX($AE$29:$AE$33),AA29,IF($AE$30=MAX($AE$29:$AE$33),AA30,IF($AE$31=MAX($AE$29:$AE$33),AA31,IF($AE$32=MAX($AE$29:$AE$33),AA32,AA33)))) -> 2 | AB35: =IF($AE$29=MAX($AE$29:$AE$33),AB29,IF($AE$30=MAX($AE$29:$AE$33),AB30,IF($AE$31=MAX($AE$29:$AE$33),AB31,IF($AE$32=MAX($AE$29:$AE$33),AB32,AB33)))) -> 0 | AC35: =A35 -> de 7:00 à 8:00 | AE35: =SUM(C35:AB35) -> 15 | AF35: =IF(AE35=0,0,AF47/AE35) -> 0.4 | AG35: =IF(AE35=0,0,AG47/AE35) -> 0.4 | AH35: =IF(AG47=0,0,AH47/AG47) -> 1 | AI35: =IF(AE35=0,0,AI47/AE35) -> 0.53333333 | AJ35: =SUM(U35:AB35) -> 12 | AK35: =RE_Eglise!AH66 -> 6 | AL35: =AK35-AJ35 -> -6
AF37: Nombre de VAE dans le total | AG37: Nombre de femmes dans le total | AH37: Nombre de VAE chez les femmes | AI37: Cycles en direction d'Annemasse-Genève
AF41: =(C29+E29+G29+I29+L29+N29+P29+R29+U29+W29+Y29+AA29) -> 4 | AG41: =(E29+F29+I29+J29+N29+O29+R29+S29+W29+X29+AA29+AB29) -> 4 | AH41: =(E29+I29+N29+R29+W29+AA29) -> 4 | AI41: =SUM(G29:J29,Y29:AB29) -> 6
AF42: =(C30+E30+G30+I30+L30+N30+P30+R30+U30+W30+Y30+AA30) -> 6 | AG42: =(E30+F30+I30+J30+N30+O30+R30+S30+W30+X30+AA30+AB30) -> 6 | AH42: =(E30+I30+N30+R30+W30+AA30) -> 6 | AI42: =SUM(G30:J30,Y30:AB30) -> 8
AF43: =(C31+E31+G31+I31+L31+N31+P31+R31+U31+W31+Y31+AA31) -> 7 | AG43: =(E31+F31+I31+J31+N31+O31+R31+S31+W31+X31+AA31+AB31) -> 5 | AH43: =(E31+I31+N31+R31+W31+AA31) -> 5 | AI43: =SUM(G31:J31,Y31:AB31) -> 4
AF44: =(C32+E32+G32+I32+L32+N32+P32+R32+U32+W32+Y32+AA32) -> 7 | AG44: =(E32+F32+I32+J32+N32+O32+R32+S32+W32+X32+AA32+AB32) -> 3 | AH44: =(E32+I32+N32+R32+W32+AA32) -> 3 | AI44: =SUM(G32:J32,Y32:AB32) -> 4
AF45: =(C33+E33+G33+I33+L33+N33+P33+R33+U33+W33+Y33+AA33) -> 2 | AG45: =(E33+F33+I33+J33+N33+O33+R33+S33+W33+X33+AA33+AB33) -> 0 | AH45: =(E33+I33+N33+R33+W33+AA33) -> 0 | AI45: =SUM(G33:J33,Y33:AB33) -> 2
AF46: =(C34+E34+G34+I34+L34+N34+P34+R34+U34+W34+Y34+AA34) -> 13 | AG46: =(E34+F34+I34+J34+N34+O34+R34+S34+W34+X34+AA34+AB34) -> 9 | AH46: =(E34+I34+N34+R34+W34+AA34) -> 9 | AI46: =SUM(G34:J34,Y34:AB34) -> 12
AF47: =(C35+E35+G35+I35+L35+N35+P35+R35+U35+W35+Y35+AA35) -> 6 | AG47: =(E35+F35+I35+J35+N35+O35+R35+S35+W35+X35+AA35+AB35) -> 6 | AH47: =(E35+I35+N35+R35+W35+AA35) -> 6 | AI47: =SUM(G35:J35,Y35:AB35) -> 8

Sheet RE_La Forge (gir.)
A1: Lieu : | B1: REIGNIER_Giratoire de la Forge (en-dessous du Fil des Saisons) | M1: Date : | N1: mardi 28 mai 2024
A2: Nom des personnes participant au comptage : | G2: Francis AMACHER
A3: Météo : | C3: Ensoleillé, mais lendemain d'une journée très pluvieuse
A5: Remarques : | P5: Méthodologie : | R5: Pour chaque intervalle de temps, marquer une seule croix par personne comptée. Si c'est enfant, remplacer la croix par E, une trottinette T, un piéton P, etc.
C7: Depuis 'Esery' | L7: Depuis 'Reignier' | U7: Depuis 'Annemasse'
C8: vers 'Reignier' | G8: vers 'Annemasse' | L8: vers 'Esery' | P8: vers 'Annemasse' | U8: vers 'Reignier' | Y8: vers 'Esery'
C9: H | E9: F | G9: H | I9: F | L9: H | N9: F | P9: H | R9: F | U9: H | W9: F | Y9: H | AA9: F
A10: Heure | B10: Minute | C10: VAE | D10: vélo | E10: VAE | F10: vélo | G10: VAE | H10: vélo | I10: VAE | J10: vélo | L10: VAE | M10: vélo | N10: VAE | O10: vélo | P10: VAE | Q10: vélo | R10: VAE | S10: vélo | U10: VAE | V10: vélo | W10: VAE | X10: vélo | Y10: VAE | Z10: vélo | AA10: VAE | AB10: vélo
A11: 6 | B11: 30 – 44'59
B12: 45 – 59'59
A13: 7 | B13: 00 – 14 | G13: 1 | H13: 2 | I13: 2 | M13: 1 | Q13: 4
B14: 15 – 29 | G14: 2 | H14: 3 | I14: 3 | Q14: 2 | R14: 2 | S14: 1
B15: 30 – 44 | G15: 1 | I15: 1 | R15: 1 | Z15: 2
B16: 45 – 59 | D16: 1 | Q16: 1 | R16: 1 | U16: 1 | W16: 1
A17: 8 | B17: 00 – 14 | G17: 3 | H17: 2 | I17: 1 | P17: 2 | Q17: 1
B18: 15 – 29 | G18: 1 | H18: 1 | J18: 1 | R18: 1 | V18: 1
B19: 30 – 44 | D19: 1 | H19: 3
B20: 45 – 59 | G20: 1 | I20: 1 | P20: 1 | Q20: 1 | V20: 1 | Y20: 1
A21: 9 | B21: 00 – 14'59
B22: 15 – 29'59
C25: =C7 -> Depuis 'Esery' | L25: =L7 -> Depuis 'Reignier' | U25: =U7 -> Depuis 'Annemasse' | AE25: TOTAL | AF25: Part des VAE dans le total | AG25: Part des femmes dans le total | AH25: Part des VAE chez les femmes | AI25: Part en direction d'Annemasse-Genève | AJ25: Cycles en provenance de Reignier | AK25: Cycles venant du giratoire des Jonquilles | AL25: Différence de cycles entre ces deux carrefour : >> descendus au chemin raide sous le cimetière, >> parti en vélo depuis le parking du cimetière ?
C26: =C8 -> vers 'Reignier' | G26: =G8 -> vers 'Annemasse' | L26: =L8 -> vers 'Esery' | P26: =P8 -> vers 'Annemasse' | U26: =U8 -> vers 'Reignier' | Y26: =Y8 -> vers 'Esery'
C27: H | E27: F | G27: H | I27: F | L27: H | N27: F | P27: H | R27: F | U27: H | W27: F | Y27: H | AA27: F
A28: Période | C28: VAE | D28: vélo | E28: VAE | F28: vélo | G28: VAE | H28: vélo | I28: VAE | J28: vélo | L28: VAE | M28: vélo | N28: VAE | O28: vélo | P28: VAE | Q28: vélo | R28: VAE | S28: vélo | U28: VAE | V28: vélo | W28: VAE | X28: vélo | Y28: VAE | Z28: vélo | AA28: VAE | AB28: vélo | AC28: Période
A29: de 6:30 à 7:30 | C29: =SUM(C11:C14) -> 0 | D29: =SUM(D11:D14) -> 0 | E29: =SUM(E11:E14) -> 0 | F29: =SUM(F11:F14) -> 0 | G29: =SUM(G11:G14) -> 3 | H29: =SUM(H11:H14) -> 5 | I29: =SUM(I11:I14) -> 5 | J29: =SUM(J11:J14) -> 0 | L29: =SUM(L11:L14) -> 0 | M29: =SUM(M11:M14) -> 1 | N29: =SUM(N11:N14) -> 0 | O29: =SUM(O11:O14) -> 0 | P29: =SUM(P11:P14) -> 0 | Q29: =SUM(Q11:Q14) -> 6 | R29: =SUM(R11:R14) -> 2 | S29: =SUM(S11:S14) -> 1 | U29: =SUM(U11:U14) -> 0 | V29: =SUM(V11:V14) -> 0 | W29: =SUM(W11:W14) -> 0 | X29: =SUM(X11:X14) -> 0 | Y29: =SUM(Y11:Y14) -> 0 | Z29: =SUM(Z11:Z14) -> 0 | AA29: =SUM(AA11:AA14) -> 0 | AB29: =SUM(AB11:AB14) -> 0 | AC29: de 6:30 à 7:30 | AE29: =SUM(C29:AB29) -> 23 | AF29: =IF(AE29=0,0,AF41/AE29) -> 0.43478261 | AG29: =IF(AE29=0,0,AG41/AE29) -> 0.34782609 | AH29: =IF(AG41=0,0,AH41/AG41) -> 0.875 | AI29: =IF(AE29=0,0,AI41/AE29) -> 0.56521739 | AJ29: =SUM(U29:AB29) -> 0 | AK29: =RE_Eglise!AH60 -> 7 | AL29: =AK29-AJ29 -> 7
A30: de 7:00 à 8:00 | C30: =SUM(C13:C16) -> 0 | D30: =SUM(D13:D16) -> 1 | E30: =SUM(E13:E16) -> 0 | F30: =SUM(F13:F16) -> 0 | G30: =SUM(G13:G16) -> 4 | H30: =SUM(H13:H16) -> 5 | I30: =SUM(I13:I16) -> 6 | J30: =SUM(J13:J16) -> 0 | L30: =SUM(L13:L16) -> 0 | M30: =SUM(M13:M16) -> 1 | N30: =SUM(N13:N16) -> 0 | O30: =SUM(O13:O16) -> 0 | P30: =SUM(P13:P16) -> 0 | Q30: =SUM(Q13:Q16) -> 7 | R30: =SUM(R13:R16) -> 4 | S30: =SUM(S13:S16) -> 1 | U30: =SUM(U13:U16) -> 1 | V30: =SUM(V13:V16) -> 0 | W30: =SUM(W13:W16) -> 1 | X30: =SUM(X13:X16) -> 0 | Y30: =SUM(Y13:Y16) -> 0 | Z30: =SUM(Z13:Z16) -> 2 | AA30: =SUM(AA13:AA16) -> 0 | AB30: =SUM(AB13:AB16) -> 0 | AC30: de 7:00 à 8:00 | AE30: =SUM(C30:AB30) -> 33 | AF30: =IF(AE30=0,0,AF42/AE30) -> 0.48484848 | AG30: =IF(AE30=0,0,AG42/AE30) -> 0.36363636 | AH30: =IF(AG42=0,0,AH42/AG42) -> 0.91666667 | AI30: =IF(AE30=0,0,AI42/AE30) -> 0.51515152 | AJ30: =SUM(U30:AB30) -> 4 | AK30: =RE_Eglise!AH61 -> 12 | AL30: =AK30-AJ30 -> 8
A31: de 7:30 à 8:30 | C31: =SUM(C15:C18) -> 0 | D31: =SUM(D15:D18) -> 1 | E31: =SUM(E15:E18) -> 0 | F31: =SUM(F15:F18) -> 0 | G31: =SUM(G15:G18) -> 5 | H31: =SUM(H15:H18) -> 3 | I31: =SUM(I15:I18) -> 2 | J31: =SUM(J15:J18) -> 1 | L31: =SUM(L15:L18) -> 0 | M31: =SUM(M15:M18) -> 0 | N31: =SUM(N15:N18) -> 0 | O31: =SUM(O15:O18) -> 0 | P31: =SUM(P15:P18) -> 2 | Q31: =SUM(Q15:Q18) -> 2 | R31: =SUM(R15:R18) -> 3 | S31: =SUM(S15:S18) -> 0 | U31: =SUM(U15:U18) -> 1 | V31: =SUM(V15:V18) -> 1 | W31: =SUM(W15:W18) -> 1 | X31: =SUM(X15:X18) -> 0 | Y31: =SUM(Y15:Y18) -> 0 | Z31: =SUM(Z15:Z18) -> 2 | AA31: =SUM(AA15:AA18) -> 0 | AB31: =SUM(AB15:AB18) -> 0 | AC31: de 7:30 à 8:30 | AE31: =SUM(C31:AB31) -> 24 | AF31: =IF(AE31=0,0,AF43/AE31) -> 0.58333333 | AG31: =IF(AE31=0,0,AG43/AE31) -> 0.29166667 | AH31: =IF(AG43=0,0,AH43/AG43) -> 0.85714286 | AI31: =IF(AE31=0,0,AI43/AE31) -> 0.54166667 | AJ31: =SUM(U31:AB31) -> 5 | AK31: =RE_Eglise!AH62 -> 6 | AL31: =AK31-AJ31 -> 1
A32: de 8:00 à 9:00 | C32: =SUM(C17:C20) -> 0 | D32: =SUM(D17:D20) -> 1 | E32: =SUM(E17:E20) -> 0 | F32: =SUM(F17:F20) -> 0 | G32: =SUM(G17:G20) -> 5 | H32: =SUM(H17:H20) -> 6 | I32: =SUM(I17:I20) -> 2 | J32: =SUM(J17:J20) -> 1 | L32: =SUM(L17:L20) -> 0 | M32: =SUM(M17:M20) -> 0 | N32: =SUM(N17:N20) -> 0 | O32: =SUM(O17:O20) -> 0 | P32: =SUM(P17:P20) -> 3 | Q32: =SUM(Q17:Q20) -> 2 | R32: =SUM(R17:R20) -> 1 | S32: =SUM(S17:S20) -> 0 | U32: =SUM(U17:U20) -> 0 | V32: =SUM(V17:V20) -> 2 | W32: =SUM(W17:W20) -> 0 | X32: =SUM(X17:X20) -> 0 | Y32: =SUM(Y17:Y20) -> 1 | Z32: =SUM(Z17:Z20) -> 0 | AA32: =SUM(AA17:AA20) -> 0 | AB32: =SUM(AB17:AB20) -> 0 | AC32: de 8:00 à 9:00 | AE32: =SUM(C32:AB32) -> 24 | AF32: =IF(AE32=0,0,AF44/AE32) -> 0.5 | AG32: =IF(AE32=0,0,AG44/AE32) -> 0.16666667 | AH32: =IF(AG44=0,0,AH44/AG44) -> 0.75 | AI32: =IF(AE32=0,0,AI44/AE32) -> 0.625 | AJ32: =SUM(U32:AB32) -> 3 | AK32: =RE_Eglise!AH63 -> 3 | AL32: =AK32-AJ32 -> 0
A33: de 8:30 à 9:30 | C33: =SUM(C19:C22) -> 0 | D33: =SUM(D19:D22) -> 1 | E33: =SUM(E19:E22) -> 0 | F33: =SUM(F19:F22) -> 0 | G33: =SUM(G19:G22) -> 1 | H33: =SUM(H19:H22) -> 3 | I33: =SUM(I19:I22) -> 1 | J33: =SUM(J19:J22) -> 0 | L33: =SUM(L19:L22) -> 0 | M33: =SUM(M19:M22) -> 0 | N33: =SUM(N19:N22) -> 0 | O33: =SUM(O19:O22) -> 0 | P33: =SUM(P19:P22) -> 1 | Q33: =SUM(Q19:Q22) -> 1 | R33: =SUM(R19:R22) -> 0 | S33: =SUM(S19:S22) -> 0 | U33: =SUM(U19:U22) -> 0 | V33: =SUM(V19:V22) -> 1 | W33: =SUM(W19:W22) -> 0 | X33: =SUM(X19:X22) -> 0 | Y33: =SUM(Y19:Y22) -> 1 | Z33: =SUM(Z19:Z22) -> 0 | AA33: =SUM(AA19:AA22) -> 0 | AB33: =SUM(AB19:AB22) -> 0 | AC33: de 8:30 à 9:30 | AE33: =SUM(C33:AB33) -> 10 | AF33: =IF(AE33=0,0,AF45/AE33) -> 0.4 | AG33: =IF(AE33=0,0,AG45/AE33) -> 0.1 | AH33: =IF(AG45=0,0,AH45/AG45) -> 1 | AI33: =IF(AE33=0,0,AI45/AE33) -> 0.6 | AJ33: =SUM(U33:AB33) -> 2 | AK33: =RE_Eglise!AH64 -> 2 | AL33: =AK33-AJ33 -> 0
A34: TOTAL | C34: =SUM(C11:C22) -> 0 | D34: =SUM(D11:D22) -> 2 | E34: =SUM(E11:E22) -> 0 | F34: =SUM(F11:F22) -> 0 | G34: =SUM(G11:G22) -> 9 | H34: =SUM(H11:H22) -> 11 | I34: =SUM(I11:I22) -> 8 | J34: =SUM(J11:J22) -> 1 | L34: =SUM(L11:L22) -> 0 | M34: =SUM(M11:M22) -> 1 | N34: =SUM(N11:N22) -> 0 | O34: =SUM(O11:O22) -> 0 | P34: =SUM(P11:P22) -> 3 | Q34: =SUM(Q11:Q22) -> 9 | R34: =SUM(R11:R22) -> 5 | S34: =SUM(S11:S22) -> 1 | U34: =SUM(U11:U22) -> 1 | V34: =SUM(V11:V22) -> 2 | W34: =SUM(W11:W22) -> 1 | X34: =SUM(X11:X22) -> 0 | Y34: =SUM(Y11:Y22) -> 1 | Z34: =SUM(Z11:Z22) -> 2 | AA34: =SUM(AA11:AA22) -> 0 | AB34: =SUM(AB11:AB22) -> 0 | AC34: TOTAL | AE34: =SUM(C34:AB34) -> 57 | AF34: =IF(AE34=0,0,AF46/AE34) -> 0.49122807 | AG34: =IF(AE34=0,0,AG46/AE34) -> 0.28070175 | AH34: =IF(AG46=0,0,AH46/AG46) -> 0.875 | AI34: =IF(AE34=0,0,AI46/AE34) -> 0.56140351 | AJ34: =SUM(U34:AB34) -> 7 | AK34: =RE_Eglise!AH65 -> 15 | AL34: =AK34-AJ34 -> 8
A35: =IF($AE$29=MAX($AE$29:$AE$33),A29,IF($AE$30=MAX($AE$29:$AE$33),A30,IF($AE$31=MAX($AE$29:$AE$33),A31,IF($AE$32=MAX($AE$29:$AE$33),A32,A33)))) -> de 7:00 à 8:00 | C35: =IF($AE$29=MAX($AE$29:$AE$33),C29,IF($AE$30=MAX($AE$29:$AE$33),C30,IF($AE$31=MAX($AE$29:$AE$33),C31,IF($AE$32=MAX($AE$29:$AE$33),C32,C33)))) -> 0 | D35: =IF($AE$29=MAX($AE$29:$AE$33),D29,IF($AE$30=MAX($AE$29:$AE$33),D30,IF($AE$31=MAX($AE$29:$AE$33),D31,IF($AE$32=MAX($AE$29:$AE$33),D32,D33)))) -> 1 | E35: =IF($AE$29=MAX($AE$29:$AE$33),E29,IF($AE$30=MAX($AE$29:$AE$33),E30,IF($AE$31=MAX($AE$29:$AE$33),E31,IF($AE$32=MAX($AE$29:$AE$33),E32,E33)))) -> 0 | F35: =IF($AE$29=MAX($AE$29:$AE$33),F29,IF($AE$30=MAX($AE$29:$AE$33),F30,IF($AE$31=MAX($AE$29:$AE$33),F31,IF($AE$32=MAX($AE$29:$AE$33),F32,F33)))) -> 0 | G35: =IF($AE$29=MAX($AE$29:$AE$33),G29,IF($AE$30=MAX($AE$29:$AE$33),G30,IF($AE$31=MAX($AE$29:$AE$33),G31,IF($AE$32=MAX($AE$29:$AE$33),G32,G33)))) -> 4 | H35: =IF($AE$29=MAX($AE$29:$AE$33),H29,IF($AE$30=MAX($AE$29:$AE$33),H30,IF($AE$31=MAX($AE$29:$AE$33),H31,IF($AE$32=MAX($AE$29:$AE$33),H32,H33)))) -> 5 | I35: =IF($AE$29=MAX($AE$29:$AE$33),I29,IF($AE$30=MAX($AE$29:$AE$33),I30,IF($AE$31=MAX($AE$29:$AE$33),I31,IF($AE$32=MAX($AE$29:$AE$33),I32,I33)))) -> 6 | J35: =IF($AE$29=MAX($AE$29:$AE$33),J29,IF($AE$30=MAX($AE$29:$AE$33),J30,IF($AE$31=MAX($AE$29:$AE$33),J31,IF($AE$32=MAX($AE$29:$AE$33),J32,J33)))) -> 0 | L35: =IF($AE$29=MAX($AE$29:$AE$33),L29,IF($AE$30=MAX($AE$29:$AE$33),L30,IF($AE$31=MAX($AE$29:$AE$33),L31,IF($AE$32=MAX($AE$29:$AE$33),L32,L33)))) -> 0 | M35: =IF($AE$29=MAX($AE$29:$AE$33),M29,IF($AE$30=MAX($AE$29:$AE$33),M30,IF($AE$31=MAX($AE$29:$AE$33),M31,IF($AE$32=MAX($AE$29:$AE$33),M32,M33)))) -> 1 | N35: =IF($AE$29=MAX($AE$29:$AE$33),N29,IF($AE$30=MAX($AE$29:$AE$33),N30,IF($AE$31=MAX($AE$29:$AE$33),N31,IF($AE$32=MAX($AE$29:$AE$33),N32,N33)))) -> 0 | O35: =IF($AE$29=MAX($AE$29:$AE$33),O29,IF($AE$30=MAX($AE$29:$AE$33),O30,IF($AE$31=MAX($AE$29:$AE$33),O31,IF($AE$32=MAX($AE$29:$AE$33),O32,O33)))) -> 0 | P35: =IF($AE$29=MAX($AE$29:$AE$33),P29,IF($AE$30=MAX($AE$29:$AE$33),P30,IF($AE$31=MAX($AE$29:$AE$33),P31,IF($AE$32=MAX($AE$29:$AE$33),P32,P33)))) -> 0 | Q35: =IF($AE$29=MAX($AE$29:$AE$33),Q29,IF($AE$30=MAX($AE$29:$AE$33),Q30,IF($AE$31=MAX($AE$29:$AE$33),Q31,IF($AE$32=MAX($AE$29:$AE$33),Q32,Q33)))) -> 7 | R35: =IF($AE$29=MAX($AE$29:$AE$33),R29,IF($AE$30=MAX($AE$29:$AE$33),R30,IF($AE$31=MAX($AE$29:$AE$33),R31,IF($AE$32=MAX($AE$29:$AE$33),R32,R33)))) -> 4 | S35: =IF($AE$29=MAX($AE$29:$AE$33),S29,IF($AE$30=MAX($AE$29:$AE$33),S30,IF($AE$31=MAX($AE$29:$AE$33),S31,IF($AE$32=MAX($AE$29:$AE$33),S32,S33)))) -> 1 | U35: =IF($AE$29=MAX($AE$29:$AE$33),U29,IF($AE$30=MAX($AE$29:$AE$33),U30,IF($AE$31=MAX($AE$29:$AE$33),U31,IF($AE$32=MAX($AE$29:$AE$33),U32,U33)))) -> 1 | V35: =IF($AE$29=MAX($AE$29:$AE$33),V29,IF($AE$30=MAX($AE$29:$AE$33),V30,IF($AE$31=MAX($AE$29:$AE$33),V31,IF($AE$32=MAX($AE$29:$AE$33),V32,V33)))) -> 0 | W35: =IF($AE$29=MAX($AE$29:$AE$33),W29,IF($AE$30=MAX($AE$29:$AE$33),W30,IF($AE$31=MAX($AE$29:$AE$33),W31,IF($AE$32=MAX($AE$29:$AE$33),W32,W33)))) -> 1 | X35: =IF($AE$29=MAX($AE$29:$AE$33),X29,IF($AE$30=MAX($AE$29:$AE$33),X30,IF($AE$31=MAX($AE$29:$AE$33),X31,IF($AE$32=MAX($AE$29:$AE$33),X32,X33)))) -> 0 | Y35: =IF($AE$29=MAX($AE$29:$AE$33),Y29,IF($AE$30=MAX($AE$29:$AE$33),Y30,IF($AE$31=MAX($AE$29:$AE$33),Y31,IF($AE$32=MAX($AE$29:$AE$33),Y32,Y33)))) -> 0 | Z35: =IF($AE$29=MAX($AE$29:$AE$33),Z29,IF($AE$30=MAX($AE$29:$AE$33),Z30,IF($AE$31=MAX($AE$29:$AE$33),Z31,IF($AE$32=MAX($AE$29:$AE$33),Z32,Z33)))) -> 2 | AA35: =IF($AE$29=MAX($AE$29:$AE$33),AA29,IF($AE$30=MAX($AE$29:$AE$33),AA30,IF($AE$31=MAX($AE$29:$AE$33),AA31,IF($AE$32=MAX($AE$29:$AE$33),AA32,AA33)))) -> 0 | AB35: =IF($AE$29=MAX($AE$29:$AE$33),AB29,IF($AE$30=MAX($AE$29:$AE$33),AB30,IF($AE$31=MAX($AE$29:$AE$33),AB31,IF($AE$32=MAX($AE$29:$AE$33),AB32,AB33)))) -> 0 | AC35: =A35 -> de 7:00 à 8:00 | AE35: =SUM(C35:AB35) -> 33 | AF35: =IF(AE35=0,0,AF47/AE35) -> 0.48484848 | AG35: =IF(AE35=0,0,AG47/AE35) -> 0.36363636 | AH35: =IF(AG47=0,0,AH47/AG47) -> 0.91666667 | AI35: =IF(AE35=0,0,AI47/AE35) -> 0.51515152 | AJ35: =SUM(U35:AB35) -> 4 | AK35: =RE_Eglise!AH66 -> 6 | AL35: =AK35-AJ35 -> 2
AF37: Nombre de VAE dans le total | AG37: Nombre de femmes dans le total | AH37: Nombre de VAE chez les femmes | AI37: Cycles en direction d'Annemasse-Genève
AF41: =(C29+E29+G29+I29+L29+N29+P29+R29+U29+W29+Y29+AA29) -> 10 | AG41: =(E29+F29+I29+J29+N29+O29+R29+S29+W29+X29+AA29+AB29) -> 8 | AH41: =(E29+I29+N29+R29+W29+AA29) -> 7 | AI41: =SUM(G29:J29,Y29:AB29) -> 13
AF42: =(C30+E30+G30+I30+L30+N30+P30+R30+U30+W30+Y30+AA30) -> 16 | AG42: =(E30+F30+I30+J30+N30+O30+R30+S30+W30+X30+AA30+AB30) -> 12 | AH42: =(E30+I30+N30+R30+W30+AA30) -> 11 | AI42: =SUM(G30:J30,Y30:AB30) -> 17
AF43: =(C31+E31+G31+I31+L31+N31+P31+R31+U31+W31+Y31+AA31) -> 14 | AG43: =(E31+F31+I31+J31+N31+O31+R31+S31+W31+X31+AA31+AB31) -> 7 | AH43: =(E31+I31+N31+R31+W31+AA31) -> 6 | AI43: =SUM(G31:J31,Y31:AB31) -> 13
AF44: =(C32+E32+G32+I32+L32+N32+P32+R32+U32+W32+Y32+AA32) -> 12 | AG44: =(E32+F32+I32+J32+N32+O32+R32+S32+W32+X32+AA32+AB32) -> 4 | AH44: =(E32+I32+N32+R32+W32+AA32) -> 3 | AI44: =SUM(G32:J32,Y32:AB32) -> 15
AF45: =(C33+E33+G33+I33+L33+N33+P33+R33+U33+W33+Y33+AA33) -> 4 | AG45: =(E33+F33+I33+J33+N33+O33+R33+S33+W33+X33+AA33+AB33) -> 1 | AH45: =(E33+I33+N33+R33+W33+AA33) -> 1 | AI45: =SUM(G33:J33,Y33:AB33) -> 6
AF46: =(C34+E34+G34+I34+L34+N34+P34+R34+U34+W34+Y34+AA34) -> 28 | AG46: =(E34+F34+I34+J34+N34+O34+R34+S34+W34+X34+AA34+AB34) -> 16 | AH46: =(E34+I34+N34+R34+W34+AA34) -> 14 | AI46: =SUM(G34:J34,Y34:AB34) -> 32
AF47: =(C35+E35+G35+I35+L35+N35+P35+R35+U35+W35+Y35+AA35) -> 16 | AG47: =(E35+F35+I35+J35+N35+O35+R35+S35+W35+X35+AA35+AB35) -> 12 | AH47: =(E35+I35+N35+R35+W35+AA35) -> 11 | AI47: =SUM(G35:J35,Y35:AB35) -> 17

Sheet ETR_D2 (ex-PN93)
A1: Lieu : | B1: ETREMBIERES_D2 route de la Libération / D906a (ex-PN93) | M1: Date : | N1: mardi 28 mai 2024
A2: Nom des personnes participant au comptage : | F2: Yannick ROGUET
A3: Météo : | C3: Ensoleillé, mais lendemain d'une journée très pluvieuse
A5: Remarques : | C5: 3 vélos-cargos ou triporteurs + 1 vélo type vélomoteur (mais comme un vélo) >> il ne pédalait pas ! 4 piétons, tous entre 'Etrembères - Autoroute' et 'Monnetier - La Muraz' Le trafic s'est calmé vers 8h30 ; sinon, remontées de file presque continues depuis la fin des pavés roses (depuis Reignier) | P5: Méthodologie : | R5: Pour chaque intervalle de temps, marquer une seule croix par personne comptée. Si c'est enfant, remplacer la croix par E, une trottinette T, un piéton P, etc.
C7: Depuis 'Château d'Etrembières' | P7: Depuis 'Etrembières - Autoroute'
C8: vers 'Reignier' | G8: vers 'Monnetier - La Muraz' | K8: vers 'Etrembères - Autoroute' | P8: vers 'Reignier' | T8: vers 'Monnetier - La Muraz' | X8: vers 'Château d'Etrembières'
C9: H | E9: F | G9: H | I9: F | K9: H | M9: F | P9: H | R9: F | T9: H | V9: F | X9: H | Z9: F
A10: Heure | B10: Minute | C10: VAE | D10: vélo | E10: VAE | F10: vélo | G10: VAE | H10: vélo | I10: VAE | J10: vélo | K10: VAE | L10: vélo | M10: VAE | N10: vélo | P10: VAE | Q10: vélo | R10: VAE | S10: vélo | T10: VAE | U10: vélo | V10: VAE | W10: vélo | X10: VAE | Y10: vélo | Z10: VAE | AA10: vélo
A11: 6 | B11: 30 – 44'59
B12: 45 – 59'59
A13: 7 | B13: 00 – 14
B14: 15 – 29 | U14: 2
B15: 30 – 44 | K15: 1
B16: 45 – 59 | D16: 1 | Q16: 1
A17: 8 | B17: 00 – 14
B18: 15 – 29 | Q18: 1 | T18: 1
B19: 30 – 44 | U19: 1
B20: 45 – 59 | Q20: 1 | U20: 2
A21: 9 | B21: 00 – 14'59
B22: 15 – 29'59
A24: Remarques : | C24: De Reignier vers Etrembières/autoroute, 1 vélo sur 2 reste sur le trottoir et ne s'insère pas dans le trafic. 12 à 15 voitures avec vélo sur le hayon du coffre. Trottinnettes électriques >> surtout des jeunes et presque jamais de casques
C26: Depuis 'Reignier' | P26: Depuis 'Monnetier - La Muraz'
C27: vers 'Château d'Etrembières' | G27: vers 'Etrembières - Autoroute' | K27: vers 'Monnetier - La Muraz' | P27: vers 'Château d'Etrembières' | T27: vers 'Etrembières - Autoroute' | X27: vers 'Reignier'
C28: H | E28: F | G28: H | I28: F | K28: H | M28: F | P28: H | R28: F | T28: H | V28: F | X28: H | Z28: F
A29: Heure | B29: Minute | C29: VAE | D29: vélo | E29: VAE | F29: vélo | G29: VAE | H29: vélo | I29: VAE | J29: vélo | K29: VAE | L29: vélo | M29: VAE | N29: vélo | P29: VAE | Q29: vélo | R29: VAE | S29: vélo | T29: VAE | U29: vélo | V29: VAE | W29: vélo | X29: VAE | Y29: vélo | Z29: VAE | AA29: vélo
A30: 6 | B30: 30 – 44'59
B31: 45 – 59'59
A32: 7 | B32: 00 – 14 | C32: 1 | H32: 1 | I32: 1 | R32: 2 | T32: 1 | V32: 1 | W32: 2
B33: 15 – 29 | D33: 2 | I33: 2 | T33: 5 | U33: 2 | V33: 2
B34: 30 – 44 | C34: 1 | D34: 1 | E34: 1 | G34: 2 | P34: 1 | Q34: 1 | R34: 1 | S34: 1 | T34: 4 | U34: 2 | V34: 1
B35: 45 – 59 | R35: 1 | T35: 2 | U35: 2 | V35: 2 | W35: 1
A36: 8 | B36: 00 – 14 | C36: 2 | D36: 1 | E36: 1 | G36: 1 | H36: 1 | I36: 1 | P36: 1 | R36: 3 | T36: 2 | U36: 1 | V36: 1
B37: 15 – 29 | C37: 2 | D37: 1 | G37: 1 | H37: 2 | R37: 1 | T37: 2 | V37: 1
B38: 30 – 44 | D38: 1 | E38: 1 | H38: 3 | I38: 1 | Q38: 1 | R38: 3 | T38: 5 | V38: 2
B39: 45 – 59 | G39: 1 | Q39: 1 | T39: 1 | U39: 1 | V39: 2
A40: 9 | B40: 00 – 14'59
B41: 15 – 29'59
C44: =C7 -> Depuis 'Château d'Etrembières' | P44: =P7 -> Depuis 'Etrembières - Autoroute' | AD44: TOTAL | AE44: Part des VAE dans le total | AF44: Part des femmes dans le total | AG44: Part des VAE chez les femmes | AH44: Part en direction d'Annemasse-Genève | AI44: Remarques
C45: =C8 -> vers 'Reignier' | G45: =G8 -> vers 'Monnetier - La Muraz' | K45: =K8 -> vers 'Etrembères - Autoroute' | P45: =P8 -> vers 'Reignier' | T45: =T8 -> vers 'Monnetier - La Muraz' | X45: =X8 -> vers 'Château d'Etrembières'
C46: H | E46: F | G46: H | I46: F | K46: H | M46: F | P46: H | R46: F | T46: H | V46: F | X46: H | Z46: F
...

Sheet ETR_Château
A1: Lieu : | B1: ETREMBIERES_Rte de St-Julien / Rte du Salève (sous château) | M1: Date : | N1: mardi 28 mai 2024
A2: Nom des personnes participant au comptage : | G2: Philippe LEMOINE
A3: Météo : | C3: Ensoleillé, mais lendemain d'une journée très pluvieuse
A5: Remarques : | C5: 11 piétons 14 vélos de/vers le chemin du pied du Salève (tous de/vers Reignier) >> tableau à adapter pour l'an prochain | P5: Méthodologie : | R5: Pour chaque intervalle de temps, marquer une seule croix par personne comptée. Si c'est enfant, remplacer la croix par E, une trottinette T, un piéton P, etc.
C7: Depuis 'Pas-de-l'Echelle' | L7: Depuis 'Annemasse' | U7: Depuis 'Reignier'
C8: vers 'Reignier' | G8: vers 'Annemasse' | L8: vers 'Reignier' | P8: vers 'Pas-de-l'Echelle' | U8: vers 'Pas-de-l'Echelle' | Y8: vers 'Annemasse'
C9: H | E9: F | G9: H | I9: F | L9: H | N9: F | P9: H | R9: F | U9: H | W9: F | Y9: H | AA9: F
A10: Heure | B10: Minute | C10: VAE | D10: vélo | E10: VAE | F10: vélo | G10: VAE | H10: vélo | I10: VAE | J10: vélo | L10: VAE | M10: vélo | N10: VAE | O10: vélo | P10: VAE | Q10: vélo | R10: VAE | S10: vélo | U10: VAE | V10: vélo | W10: VAE | X10: vélo | Y10: VAE | Z10: vélo | AA10: VAE | AB10: vélo
A11: 6 | B11: 30 – 44'59
B12: 45 – 59'59
A13: 7 | B13: 00 – 14 | U13: 1 | W13: 2
B14: 15 – 29 | R14: 1 | U14: 1 | V14: 2 | W14: 2
B15: 30 – 44 | P15: 1 | U15: 3 | V15: 3 | W15: 3 | X15: 1
B16: 45 – 59 | C16: 1 | D16: 1 | V16: 1 | W16: 1
A17: 8 | B17: 00 – 14 | E17: 1 | P17: 1 | U17: 4 | V17: 2 | W17: 3
B18: 15 – 29 | P18: 1 | U18: 1 | V18: 1 | W18: 2
B19: 30 – 44 | D19: 1 | P19: 2 | R19: 1 | U19: 2 | V19: 1 | W19: 2
B20: 45 – 59 | V20: 2
A21: 9 | B21: 00 – 14'59
B22: 15 – 29'59
C25: =C7 -> Depuis 'Pas-de-l'Echelle' | L25: =L7 -> Depuis 'Annemasse' | U25: =U7 -> Depuis 'Reignier' | AE25: TOTAL | AF25: Part des VAE dans le total | AG25: Part des femmes dans le total | AH25: Part des VAE chez les femmes | AI25: Part en direction d'Annemasse-Genève | AJ25: Cycles en provenance de Reignier | AK25: Cycles comptés au carrefour amont (PN93) | AL25: Différence de cycles entre ces deux carrefour : >> descendus au chemin raide sous le cimetière, >> parti en vélo depuis le parking du cimetière ?
C26: =C8 -> vers 'Reignier' | G26: =G8 -> vers 'Annemasse' | L26: =L8 -> vers 'Reignier' | P26: =P8 -> vers 'Pas-de-l'Echelle' | U26: =U8 -> vers 'Pas-de-l'Echelle' | Y26: =Y8 -> vers 'Annemasse'
C27: H | E27: F | G27: H | I27: F | L27: H | N27: F | P27: H | R27: F | U27: H | W27: F | Y27: H | AA27: F
A28: Période | C28: VAE | D28: vélo | E28: VAE | F28: vélo | G28: VAE | H28: vélo | I28: VAE | J28: vélo | L28: VAE | M28: vélo | N28: VAE | O28: vélo | P28: VAE | Q28: vélo | R28: VAE | S28: vélo | U28: VAE | V28: vélo | W28: VAE | X28: vélo | Y28: VAE | Z28: vélo | AA28: VAE | AB28: vélo | AC28: Période
A29: de 6:30 à 7:30 | C29: =SUM(C11:C14) -> 0 | D29: =SUM(D11:D14) -> 0 | E29: =SUM(E11:E14) -> 0 | F29: =SUM(F11:F14) -> 0 | G29: =SUM(G11:G14) -> 0 | H29: =SUM(H11:H14) -> 0 | I29: =SUM(I11:I14) -> 0 | J29: =SUM(J11:J14) -> 0 | L29: =SUM(L11:L14) -> 0 | M29: =SUM(M11:M14) -> 0 | N29: =SUM(N11:N14) -> 0 | O29: =SUM(O11:O14) -> 0 | P29: =SUM(P11:P14) -> 0 | Q29: =SUM(Q11:Q14) -> 0 | R29: =SUM(R11:R14) -> 1 | S29: =SUM(S11:S14) -> 0 | U29: =SUM(U11:U14) -> 2 | V29: =SUM(V11:V14) -> 2 | W29: =SUM(W11:W14) -> 4 | X29: =SUM(X11:X14) -> 0 | Y29: =SUM(Y11:Y14) -> 0 | Z29: =SUM(Z11:Z14) -> 0 | AA29: =SUM(AA11:AA14) -> 0 | AB29: =SUM(AB11:AB14) -> 0 | AC29: de 6:30 à 7:30 | AE29: =SUM(C29:AB29) -> 9 | AF29: =IF(AE29=0,0,AF41/AE29) -> 0.77777778 | AG29: =IF(AE29=0,0,AG41/AE29) -> 0.55555556 | AH29: =IF(AG41=0,0,AH41/AG41) -> 1 | AI29: =IF(AE29=0,0,AI41/AE29) -> 1 | AJ29: =SUM(U29:AB29) -> 8 | AK29: =#REF! -> #REF! | AL29: =AK29-AJ29 -> #REF!
A30: de 7:00 à 8:00 | C30: =SUM(C13:C16) -> 1 | D30: =SUM(D13:D16) -> 1 | E30: =SUM(E13:E16) -> 0 | F30: =SUM(F13:F16) -> 0 | G30: =SUM(G13:G16) -> 0 | H30: =SUM(H13:H16) -> 0 | I30: =SUM(I13:I16) -> 0 | J30: =SUM(J13:J16) -> 0 | L30: =SUM(L13:L16) -> 0 | M30: =SUM(M13:M16) -> 0 | N30: =SUM(N13:N16) -> 0 | O30: =SUM(O13:O16) -> 0 | P30: =SUM(P13:P16) -> 1 | Q30: =SUM(Q13:Q16) -> 0 | R30: =SUM(R13:R16) -> 1 | S30: =SUM(S13:S16) -> 0 | U30: =SUM(U13:U16) -> 5 | V30: =SUM(V13:V16) -> 6 | W30: =SUM(W13:W16) -> 8 | X30: =SUM(X13:X16) -> 1 | Y30: =SUM(Y13:Y16) -> 0 | Z30: =SUM(Z13:Z16) -> 0 | AA30: =SUM(AA13:AA16) -> 0 | AB30: =SUM(AB13:AB16) -> 0 | AC30: de 7:00 à 8:00 | AE30: =SUM(C30:AB30) -> 24 | AF30: =IF(AE30=0,0,AF42/AE30) -> 0.66666667 | AG30: =IF(AE30=0,0,AG42/AE30) -> 0.41666667 | AH30: =IF(AG42=0,0,AH42/AG42) -> 0.9 | AI30: =IF(AE30=0,0,AI42/AE30) -> 0.91666667 | AJ30: =SUM(U30:AB30) -> 20 | AK30: =#REF! -> #REF! | AL30: =AK30-AJ30 -> #REF!
A31: de 7:30 à 8:30 | C31: =SUM(C15:C18) -> 1 | D31: =SUM(D15:D18) -> 1 | E31: =SUM(E15:E18) -> 1 | F31: =SUM(F15:F18) -> 0 | G31: =SUM(G15:G18) -> 0 | H31: =SUM(H15:H18) -> 0 | I31: =SUM(I15:I18) -> 0 | J31: =SUM(J15:J18) -> 0 | L31: =SUM(L15:L18) -> 0 | M31: =SUM(M15:M18) -> 0 | N31: =SUM(N15:N18) -> 0 | O31: =SUM(O15:O18) -> 0 | P31: =SUM(P15:P18) -> 3 | Q31: =SUM(Q15:Q18) -> 0 | R31: =SUM(R15:R18) -> 0 | S31: =SUM(S15:S18) -> 0 | U31: =SUM(U15:U18) -> 8 | V31: =SUM(V15:V18) -> 7 | W31: =SUM(W15:W18) -> 9 | X31: =SUM(X15:X18) -> 1 | Y31: =SUM(Y15:Y18) -> 0 | Z31: =SUM(Z15:Z18) -> 0 | AA31: =SUM(AA15:AA18) -> 0 | AB31: =SUM(AB15:AB18) -> 0 | AC31: de 7:30 à 8:30 | AE31: =SUM(C31:AB31) -> 31 | AF31: =IF(AE31=0,0,AF43/AE31) -> 0.70967742 | AG31: =IF(AE31=0,0,AG43/AE31) -> 0.35483871 | AH31: =IF(AG43=0,0,AH43/AG43) -> 0.90909091 | AI31: =IF(AE31=0,0,AI43/AE31) -> 0.90322581 | AJ31: =SUM(U31:AB31) -> 25 | AK31: =#REF! -> #REF! | AL31: =AK31-AJ31 -> #REF!
A32: de 8:00 à 9:00 | C32: =SUM(C17:C20) -> 0 | D32: =SUM(D17:D20) -> 1 | E32: =SUM(E17:E20) -> 1 | F32: =SUM(F17:F20) -> 0 | G32: =SUM(G17:G20) -> 0 | H32: =SUM(H17:H20) -> 0 | I32: =SUM(I17:I20) -> 0 | J32: =SUM(J17:J20) -> 0 | L32: =SUM(L17:L20) -> 0 | M32: =SUM(M17:M20) -> 0 | N32: =SUM(N17:N20) -> 0 | O32: =SUM(O17:O20) -> 0 | P32: =SUM(P17:P20) -> 4 | Q32: =SUM(Q17:Q20) -> 0 | R32: =SUM(R17:R20) -> 1 | S32: =SUM(S17:S20) -> 0 | U32: =SUM(U17:U20) -> 7 | V32: =SUM(V17:V20) -> 6 | W32: =SUM(W17:W20) -> 7 | X32: =SUM(X17:X20) -> 0 | Y32: =SUM(Y17:Y20) -> 0 | Z32: =SUM(Z17:Z20) -> 0 | AA32: =SUM(AA17:AA20) -> 0 | AB32: =SUM(AB17:AB20) -> 0 | AC32: de 8:00 à 9:00 | AE32: =SUM(C32:AB32) -> 27 | AF32: =IF(AE32=0,0,AF44/AE32) -> 0.74074074 | AG32: =IF(AE32=0,0,AG44/AE32) -> 0.33333333 | AH32: =IF(AG44=0,0,AH44/AG44) -> 1 | AI32: =IF(AE32=0,0,AI44/AE32) -> 0.92592593 | AJ32: =SUM(U32:AB32) -> 20 | AK32: =#REF! -> #REF! | AL32: =AK32-AJ32 -> #REF!
