Workbook

Sheet Resume
B1: Hommes | C1: Femmes | D1: %Femmes | E1: VT | F1: VAE | G1: Nouveau | H1: 2r | I1: %VAE | J1: %Nouveau | K1: Piétons | L1: >CH | M1: >FR | N1: TOT
A2: Ferney | B2: =Ferney!S14 -> 140 | C2: =Ferney!T14 -> 71 | D2: =Ferney!U14 -> 0.33649289 | E2: =Ferney!V14 -> 102 | F2: =Ferney!W14 -> 85 | G2: =Ferney!X14 -> 20 | H2: =Ferney!Y14 -> 207 | I2: =Ferney!Z14 -> 0.41062802 | ... N2: =Ferney!AE14 -> 211
A4: StGenis-> Meyrin | B4: ='StGenis->Meyrin'!S14 -> 145 | C4: ='StGenis->Meyrin'!T14 -> 61 | D4: ='StGenis->Meyrin'!U14 -> 0.2961165 | E4: ='StGenis->Meyrin'!V14 -> 98 | F4: ='StGenis->Meyrin'!W14 -> 87 | G4: ='StGenis->Meyrin'!X14 -> 8 | H4: ='StGenis->Meyrin'!Y14 -> 193 | I4: ='StGenis->Meyrin'!Z14 -> 0.4507772 | ... N4: ='StGenis->Meyrin'!AE14 -> 206
A5: StGenis->Bourdigny | B5: ='StGenis->Bourdigny'!S14 -> 24 | C5: ='StGenis->Bourdigny'!T14 -> 4 | D5: ='StGenis->Bourdigny'!U14 -> 0.14285714 | E5: ='StGenis->Bourdigny'!V14 -> 19 | F5: ='StGenis->Bourdigny'!W14 -> 9 | G5: ='StGenis->Bourdigny'!X14 -> 0 | H5: ='StGenis->Bourdigny'!Y14 -> 28 | I5: ='StGenis->Bourdigny'!Z14 -> 0.32142857 | ... N5: ='StGenis->Bourdigny'!AE14 -> 28
A6: StGenis->CERN | B6: ='StGenis->CERN'!S14 -> 125 | C6: ='StGenis->CERN'!T14 -> 25 | D6: ='StGenis->CERN'!U14 -> 0.16666667 | E6: ='StGenis->CERN'!V14 -> 100 | F6: ='StGenis->CERN'!W14 -> 10 | G6: ='StGenis->CERN'!X14 -> 3 | H6: ='StGenis->CERN'!Y14 -> 113 | I6: ='StGenis->CERN'!Z14 -> 0.088495575 | ... N6: ='StGenis->CERN'!AE14 -> 150
A7: RteEurope->Meyrin | B7: ='RteEurope->Meyrin'!S14 -> 12 | C7: ='RteEurope->Meyrin'!T14 -> 0 | D7: ='RteEurope->Meyrin'!U14 -> 0 | E7: ='RteEurope->Meyrin'!V14 -> 9 | F7: ='RteEurope->Meyrin'!W14 -> 3 | G7: ='RteEurope->Meyrin'!X14 -> 0 | H7: ='RteEurope->Meyrin'!Y14 -> 12 | I7: ='RteEurope->Meyrin'!Z14 -> 0.25 | ... N7: ='RteEurope->Meyrin'!AE14 -> 12
A8: Total StGenis | B8: =SUM(B4:B7) -> 306 | C8: =SUM(C4:C6) -> 90 | D8: =C8/(C8+B8) -> 0.22727273 | E8: =SUM(E4:E7) -> 226 | F8: =SUM(F4:F7) -> 109 | G8: =SUM(G4:G7) -> 11 | H8: =SUM(H4:H7) -> 346 | I8: =F8/H8 -> 0.3150289 | J8: =G8/H8 -> 0.031791908 | K8: =SUM(K4:K7) -> 50 | L8: =SUM(L4:L7) -> 374 | M8: =SUM(M4:M7) -> 22 | N8: =SUM(N4:N7) -> 396
A10: MategninAnneaux | B10: =MategninAnneaux!S14 -> 111 | C10: =MategninAnneaux!T14 -> 66 | D10: =MategninAnneaux!U14 -> 0.37288136 | E10: =MategninAnneaux!V14 -> 85 | F10: =MategninAnneaux!W14 -> 61 | G10: =MategninAnneaux!X14 -> 11 | H10: =MategninAnneaux!Y14 -> 157 | I10: =MategninAnneaux!Z14 -> 0.38853503 | ... N10: =MategninAnneaux!AE14 -> 177
A11: MategninDouane | B11: =MategninDouane!S14 -> 70 | C11: =MategninDouane!T14 -> 28 | D11: =MategninDouane!U14 -> 0.28571429 | E11: =MategninDouane!V14 -> 56 | F11: =MategninDouane!W14 -> 24 | G11: =MategninDouane!X14 -> 2 | H11: =MategninDouane!Y14 -> 82 | I11: =MategninDouane!Z14 -> 0.29268293 | ... N11: =MategninDouane!AE14 -> 98
A12: Total Mategnin | B12: =SUM(B10:B11) -> 181 | C12: =SUM(C10:C11) -> 94 | D12: =C12/(C12+B12) -> 0.34181818 | E12: =SUM(E10:E11) -> 141 | F12: =SUM(F10:F11) -> 85 | G12: =SUM(G10:G11) -> 13 | H12: =SUM(H10:H11) -> 239 | I12: =F12/H12 -> 0.35564854 | J12: =G12/H12 -> 0.054393305 | K12: =SUM(K10:K11) -> 36 | L12: =SUM(L10:L11) -> 228 | M12: =SUM(M10:M11) -> 47 | N12: =SUM(N10:N11) -> 275
A14: Versonnex | B14: =Versonnex!S14 -> 27 | C14: =Versonnex!T14 -> 13 | D14: =Versonnex!U14 -> 0.325 | E14: =Versonnex!V14 -> 25 | F14: =Versonnex!W14 -> 15 | G14: =Versonnex!X14 -> 0 | H14: =Versonnex!Y14 -> 40 | I14: =Versonnex!Z14 -> 0.375 | ... N14: =Versonnex!AE14 -> 40
A15: Sauverny | B15: =Sauverny!S14 -> 22 | C15: =Sauverny!T14 -> 12 | D15: =Sauverny!U14 -> 0.35294118 | E15: =Sauverny!V14 -> 12 | F15: =Sauverny!W14 -> 11 | G15: =Sauverny!X14 -> 1 | H15: =Sauverny!Y14 -> 24 | I15: =Sauverny!Z14 -> 0.45833333 | ... N15: =Sauverny!AE14 -> 34
A16: Divonne (Chavanne) | B16: ='Divonne->Chavanne'!S14 -> 0
A17: Crassy | B17: =Crassy!S14 -> 0
A18: Total Pays de Gex Nord | B18: =SUM(B14:B17) -> 49 | C18: =SUM(C14:C16) -> 25 | D18: =C18/(C18+B18) -> 0.33783784 | E18: =SUM(E14:E16) -> 37 | F18: =SUM(F14:F16) -> 26 | G18: =SUM(G14:G16) -> 1 | H18: =SUM(H14:H16) -> 64 | I18: =F18/H18 -> 0.40625 | J18: =G18/H18 -> 0.015625 | K18: =SUM(K14:K16) -> 10 | L18: =SUM(L14:L16) -> 60 | M18: =SUM(M14:M16) -> 14 | N18: =SUM(N14:N16) -> 74
A19: TOTAL | B19: =B18+B12+B8+B2 -> 676 | C19: =C18+C12+C8+C2 -> 280 | D19: =C19/(C19+B19) -> 0.29288703 | E19: =E18+E12+E8+E2 -> 506 | F19: =F18+F12+F8+F2 -> 305 | G19: =G18+G12+G8+G2 -> 45 | H19: =H18+H12+H8+H2 -> 856 | I19: =F19/H19 -> 0.35630841 | J19: =G19/H19 -> 0.052570093 | K19: =K18+K12+K8+K2 -> 100 | L19: =L18+L12+L8+L2 -> 865 | M19: =M18+M12+M8+M2 -> 91 | N19: =N18+N12+N8+N2 -> 956

Sheet Resume (HP)
B1: Hommes | C1: Femmes | D1: %Femmes | E1: VT | F1: VAE | G1: Nouveau | H1: 2r | I1: %VAE | J1: %Nouveau | K1: Piétons | L1: >CH | M1: >FR | N1: TOT
A2: Ferney | B2: =Ferney!S15 -> 66 | C2: =Ferney!T15 -> 36 | D2: =Ferney!U15 -> 0.35294118 | E2: =Ferney!V15 -> 44 | F2: =Ferney!W15 -> 46 | G2: =Ferney!X15 -> 9 | H2: =Ferney!Y15 -> 99 | I2: =Ferney!Z15 -> 0.46464646 | ... N2: =Ferney!AE15 -> 102
A4: StGenis-> Meyrin | B4: ='StGenis->Meyrin'!S15 -> 78 | C4: ='StGenis->Meyrin'!T15 -> 33 | D4: ='StGenis->Meyrin'!U15 -> 0.2972973 | E4: ='StGenis->Meyrin'!V15 -> 43 | F4: ='StGenis->Meyrin'!W15 -> 53 | G4: ='StGenis->Meyrin'!X15 -> 6 | H4: ='StGenis->Meyrin'!Y15 -> 102 | I4: ='StGenis->Meyrin'!Z15 -> 0.51960784 | ... N4: ='StGenis->Meyrin'!AE15 -> 111
A5: StGenis->Bourdigny | B5: ='StGenis->Bourdigny'!S15 -> 12 | C5: ='StGenis->Bourdigny'!T15 -> 2 | D5: ='StGenis->Bourdigny'!U15 -> 0.14285714 | E5: ='StGenis->Bourdigny'!V15 -> 12 | F5: ='StGenis->Bourdigny'!W15 -> 2 | G5: ='StGenis->Bourdigny'!X15 -> 0 | H5: ='StGenis->Bourdigny'!Y15 -> 14 | I5: ='StGenis->Bourdigny'!Z15 -> 0.14285714 | ... N5: ='StGenis->Bourdigny'!AE15 -> 14
A6: StGenis->CERN | B6: ='StGenis->CERN'!S15 -> 67 | C6: ='StGenis->CERN'!T15 -> 11 | D6: ='StGenis->CERN'!U15 -> 0.14102564 | E6: ='StGenis->CERN'!V15 -> 48 | F6: ='StGenis->CERN'!W15 -> 2 | G6: ='StGenis->CERN'!X15 -> 1 | H6: ='StGenis->CERN'!Y15 -> 51 | I6: ='StGenis->CERN'!Z15 -> 0.039215686 | ... N6: ='StGenis->CERN'!AE15 -> 78
A7: RteEurope->Meyrin | B7: ='RteEurope->Meyrin'!S15 -> 7 | C7: ='RteEurope->Meyrin'!T15 -> 0 | D7: ='RteEurope->Meyrin'!U15 -> 0 | E7: ='RteEurope->Meyrin'!V15 -> 6 | F7: ='RteEurope->Meyrin'!W15 -> 1 | G7: ='RteEurope->Meyrin'!X15 -> 0 | H7: ='RteEurope->Meyrin'!Y15 -> 7 | I7: ='RteEurope->Meyrin'!Z15 -> 0.14285714 | ... N7: ='RteEurope->Meyrin'!AE15 -> 7
A8: Total StGenis | B8: =SUM(B4:B7) -> 164 | C8: =SUM(C4:C6) -> 46 | D8: =C8/(C8+B8) -> 0.21904762 | E8: =SUM(E4:E7) -> 109 | F8: =SUM(F4:F7) -> 58 | G8: =SUM(G4:G7) -> 7 | H8: =SUM(H4:H7) -> 174 | I8: =F8/H8 -> 0.33333333 | J8: =G8/H8 -> 0.040229885 | K8: =SUM(K4:K7) -> 36 | L8: =SUM(L4:L7) -> 195 | M8: =SUM(M4:M7) -> 15 | N8: =SUM(N4:N7) -> 210
A10: MategninAnneaux | B10: =MategninAnneaux!S15 -> 58 | C10: =MategninAnneaux!T15 -> 28 | D10: =MategninAnneaux!U15 -> 0.3255814 | E10: =MategninAnneaux!V15 -> 39 | F10: =MategninAnneaux!W15 -> 34 | G10: =MategninAnneaux!X15 -> 5 | H10: =MategninAnneaux!Y15 -> 78 | I10: =MategninAnneaux!Z15 -> 0.43589744 | ... N10: =MategninAnneaux!AE15 -> 86
A11: MategninDouane | B11: =MategninDouane!S15 -> 30 | C11: =MategninDouane!T15 -> 15 | D11: =MategninDouane!U15 -> 0.33333333 | E11: =MategninDouane!V15 -> 25 | F11: =MategninDouane!W15 -> 11 | G11: =MategninDouane!X15 -> 0 | H11: =MategninDouane!Y15 -> 36 | I11: =MategninDouane!Z15 -> 0.30555556 | ... N11: =MategninDouane!AE15 -> 45
A12: Total Mategnin | B12: =SUM(B10:B11) -> 88 | C12: =SUM(C10:C11) -> 43 | D12: =C12/(C12+B12) -> 0.32824427 | E12: =SUM(E10:E11) -> 64 | F12: =SUM(F10:F11) -> 45 | G12: =SUM(G10:G11) -> 5 | H12: =SUM(H10:H11) -> 114 | I12: =F12/H12 -> 0.39473684 | J12: =G12/H12 -> 0.043859649 | K12: =SUM(K10:K11) -> 17 | L12: =SUM(L10:L11) -> 105 | M12: =SUM(M10:M11) -> 26 | N12: =SUM(N10:N11) -> 131
A14: Versonnex | B14: =Versonnex!S15 -> 11 | C14: =Versonnex!T15 -> 9 | D14: =Versonnex!U15 -> 0.45 | E14: =Versonnex!V15 -> 10 | F14: =Versonnex!W15 -> 10 | G14: =Versonnex!X15 -> 0 | H14: =Versonnex!Y15 -> 20 | I14: =Versonnex!Z15 -> 0.5 | ... N14: =Versonnex!AE15 -> 20
A15: Sauverny | B15: =Sauverny!S15 -> 19 | C15: =Sauverny!T15 -> 8 | D15: =Sauverny!U15 -> 0.2962963 | E15: =Sauverny!V15 -> 9 | F15: =Sauverny!W15 -> 8 | G15: =Sauverny!X15 -> 1 | H15: =Sauverny!Y15 -> 18 | I15: =Sauverny!Z15 -> 0.44444444 | ... N15: =Sauverny!AE15 -> 27
A16: Divonne (Chavanne) | B16: ='Divonne->Chavanne'!S15 -> 0
A17: Crassy | B17: =Crassy!S15 -> 0
A18: Total Pays de Gex Nord | B18: =SUM(B14:B17) -> 30 | C18: =SUM(C14:C16) -> 17 | D18: =C18/(C18+B18) -> 0.36170213 | E18: =SUM(E14:E16) -> 19 | F18: =SUM(F14:F16) -> 18 | G18: =SUM(G14:G16) -> 1 | H18: =SUM(H14:H16) -> 38 | I18: =F18/H18 -> 0.47368421 | J18: =G18/H18 -> 0.026315789 | K18: =SUM(K14:K16) -> 9 | L18: =SUM(L14:L16) -> 40 | M18: =SUM(M14:M16) -> 7 | N18: =SUM(N14:N16) -> 47
A19: TOTAL | B19: =B18+B12+B8+B2 -> 348 | C19: =C18+C12+C8+C2 -> 142 | D19: =C19/(C19+B19) -> 0.28979592 | E19: =E18+E12+E8+E2 -> 236 | F19: =F18+F12+F8+F2 -> 167 | G19: =G18+G12+G8+G2 -> 22 | H19: =H18+H12+H8+H2 -> 425 | I19: =F19/H19 -> 0.39294118 | J19: =G19/H19 -> 0.051764706 | K19: =K18+K12+K8+K2 -> 65 | L19: =L18+L12+L8+L2 -> 437 | M19: =M18+M12+M8+M2 -> 53 | N19: =N18+N12+N8+N2 -> 490

Sheet APiCy total
B1: Lieu: | C1: APiCy Frontière Total
B2: France -> Suisse | J2: Suisse -> France | S2: ="Totaux 2021 " & $C1 -> Totaux 2021 APiCy Frontière Total | AG2: ="Totaux 2020 " & $C1 -> Totaux 2020 APiCy Frontière Total | AU2: ="Changement depuis 2020 " & $C1 -> Changement depuis 2020 APiCy Frontière Total
B3: Vélo traditionel | D3: VAE | F3: Mode Nouveau Electrique | H3: Piéton/ne | J3: Vélo traditionel | L3: VAE | N3: Mode Nouveau Electrique (trotinette, scateboard , …) | P3: Piéton/ne | S3: Hommes | T3: Femmes | U3: %Femmes | V3: VT | W3: VAE | X3: Nouveau | Y3: 2r | Z3: %VAE | AA3: %Nouveau | AB3: Piétons | AC3: >CH | AD3: >FR | AE3: TOT | AG3: Hommes | AH3: Femmes | AI3: %Femmes | AJ3: VT | AK3: VAE | AL3: Nouveau | AM3: 2r | AN3: %VAE | AO3: %Nouveau | AP3: Piétons | AQ3: >CH | AR3: >FR | AS3: TOT | AU3: Hommes | AV3: Femmes | AW3: %Femmes | AX3: VT | AY3: VAE | AZ3: Nouveau | BA3: 2r | BB3: %VAE | BC3: %Nouveau | BD3: Piétons | BE3: >CH | BF3: >FR | BG3: TOT
A4: Heure | B4: H | C4: F | D4: H | E4: F | F4: H | G4: F | H4: H | I4: F | J4: H | K4: F | L4: H | M4: F | N4: H | O4: F | P4: H | Q4: F
A5: 0.29166667 | B5: =Ferney!B5+'StGenis total'!B5+'PdG Nord'!B5+'Mategnin Total'!B5 -> 33 | C5: =Ferney!C5+'StGenis total'!C5+'PdG Nord'!C5+'Mategnin Total'!C5 -> 10 | D5: =Ferney!D5+'StGenis total'!D5+'PdG Nord'!D5+'Mategnin Total'!D5 -> 17 | E5: =Ferney!E5+'StGenis total'!E5+'PdG Nord'!E5+'Mategnin Total'!E5 -> 11 | F5: =Ferney!F5+'StGenis total'!F5+'PdG Nord'!F5+'Mategnin Total'!F5 -> 6 | G5: =Ferney!G5+'StGenis total'!G5+'PdG Nord'!G5+'Mategnin Total'!G5 -> 0 | H5: =Ferney!H5+'StGenis total'!H5+'PdG Nord'!H5+'Mategnin Total'!H5 -> 2 | I5: =Ferney!I5+'StGenis total'!I5+'PdG Nord'!I5+'Mategnin Total'!I5 -> 0 | ... Q5: =Ferney!Q5+'StGenis total'!Q5+'PdG Nord'!Q5+'Mategnin Total'!Q5 -> 0 | S5: =B5+D5+F5+H5+J5+L5+N5+P5 -> 61 | T5: =C5+E5+G5+I5+K5+M5+O5+Q5 -> 23 | U5: =T5/(T5+S5) -> 0.27380952 | V5: =B5+C5+J5+K5 -> 46 | W5: =D5+E5+L5+M5 -> 30 | X5: =F5+G5+N5+O5 -> 6 | Y5: =SUM(V5:X5) -> 82 | Z5: =W5/Y5 -> 0.36585366 | AA5: =X5/Y5 -> 0.073170732 | AB5: =H5+I5+P5+Q5 -> 2 | AC5: =SUM(B5:I5) -> 79 | AD5: =SUM(J5:Q5) -> 5 | AE5: =SUM(B5:Q5) -> 84 | AG5: 43 | AH5: 26 | AI5: 0.37681159 | AJ5: 35 | AK5: 25 | AL5: 3 | AM5: 63 | AN5: 0.3968254 | AO5: 0.047619048 | AP5: 6 | AQ5: 63 | AR5: 6 | AS5: 69 | AU5: =(S5/AG5) - 1 -> 0.41860465 | AV5: =(T5/AH5) - 1 -> -0.11538462 | AW5: =(U5/AI5) - 1 -> -0.27335165 | AX5: =(V5/AJ5) - 1 -> 0.31428571 | AY5: =(W5/AK5) - 1 -> 0.2 | AZ5: =(X5/AL5) - 1 -> 1 | BA5: =(Y5/AM5) - 1 -> 0.3015873 | BB5: =(Z5/AN5) - 1 -> -0.07804878 | ... BG5: =(AE5/AS5) - 1 -> 0.2173913
A6: 0.30208333 | B6: =Ferney!B6+'StGenis total'!B6+'PdG Nord'!B6+'Mategnin Total'!B6 -> 43 | C6: =Ferney!C6+'StGenis total'!C6+'PdG Nord'!C6+'Mategnin Total'!C6 -> 11 | D6: =Ferney!D6+'StGenis total'!D6+'PdG Nord'!D6+'Mategnin Total'!D6 -> 23 | E6: =Ferney!E6+'StGenis total'!E6+'PdG Nord'!E6+'Mategnin Total'!E6 -> 15 | F6: =Ferney!F6+'StGenis total'!F6+'PdG Nord'!F6+'Mategnin Total'!F6 -> 2 | G6: =Ferney!G6+'StGenis total'!G6+'PdG Nord'!G6+'Mategnin Total'!G6 -> 3 | H6: =Ferney!H6+'StGenis total'!H6+'PdG Nord'!H6+'Mategnin Total'!H6 -> 2 | I6: =Ferney!I6+'StGenis total'!I6+'PdG Nord'!I6+'Mategnin Total'!I6 -> 1 | ... Q6: =Ferney!Q6+'StGenis total'!Q6+'PdG Nord'!Q6+'Mategnin Total'!Q6 -> 0 | S6: =B6+D6+F6+H6+J6+L6+N6+P6 -> 77 | T6: =C6+E6+G6+I6+K6+M6+O6+Q6 -> 30 | U6: =T6/(T6+S6) -> 0.28037383 | V6: =B6+C6+J6+K6 -> 58 | W6: =D6+E6+L6+M6 -> 40 | X6: =F6+G6+N6+O6 -> 5 | Y6: =SUM(V6:X6) -> 103 | Z6: =W6/Y6 -> 0.38834951 | AA6: =X6/Y6 -> 0.048543689 | AB6: =H6+I6+P6+Q6 -> 4 | AC6: =SUM(B6:I6) -> 100 | AD6: =SUM(J6:Q6) -> 7 | AE6: =SUM(B6:Q6) -> 107 | AG6: 67 | AH6: 30 | AI6: 0.30927835 | AJ6: 54 | AK6: 28 | AL6: 5 | AM6: 87 | AN6: 0.32183908 | AO6: 0.057471264 | AP6: 10 | AQ6: 87 | AR6: 10 | AS6: 97 | AU6: =(S6/AG6) - 1 -> 0.14925373 | AV6: =(T6/AH6) - 1 -> 0 | AW6: =(U6/AI6) - 1 -> -0.093457944 | AX6: =(V6/AJ6) - 1 -> 0.074074074 | AY6: =(W6/AK6) - 1 -> 0.42857143 | AZ6: =(X6/AL6) - 1 -> 0 | BA6: =(Y6/AM6) - 1 -> 0.18390805 | BB6: =(Z6/AN6) - 1 -> 0.20665742 | ... BG6: =(AE6/AS6) - 1 -> 0.10309278
A7: 0.3125 | B7: =Ferney!B7+'StGenis total'!B7+'PdG Nord'!B7+'Mategnin Total'!B7 -> 32 | C7: =Ferney!C7+'StGenis total'!C7+'PdG Nord'!C7+'Mategnin Total'!C7 -> 11 | D7: =Ferney!D7+'StGenis total'!D7+'PdG Nord'!D7+'Mategnin Total'!D7 -> 22 | E7: =Ferney!E7+'StGenis total'!E7+'PdG Nord'!E7+'Mategnin Total'!E7 -> 17 | F7: =Ferney!F7+'StGenis total'!F7+'PdG Nord'!F7+'Mategnin Total'!F7 -> 4 | G7: =Ferney!G7+'StGenis total'!G7+'PdG Nord'!G7+'Mategnin Total'!G7 -> 0 | H7: =Ferney!H7+'StGenis total'!H7+'PdG Nord'!H7+'Mategnin Total'!H7 -> 10 | I7: =Ferney!I7+'StGenis total'!I7+'PdG Nord'!I7+'Mategnin Total'!I7 -> 1 | ... Q7: =Ferney!Q7+'StGenis total'!Q7+'PdG Nord'!Q7+'Mategnin Total'!Q7 -> 0 | S7: =B7+D7+F7+H7+J7+L7+N7+P7 -> 80 | T7: =C7+E7+G7+I7+K7+M7+O7+Q7 -> 30 | U7: =T7/(T7+S7) -> 0.27272727 | V7: =B7+C7+J7+K7 -> 52 | W7: =D7+E7+L7+M7 -> 42 | X7: =F7+G7+N7+O7 -> 4 | Y7: =SUM(V7:X7) -> 98 | Z7: =W7/Y7 -> 0.42857143 | AA7: =X7/Y7 -> 0.040816327 | AB7: =H7+I7+P7+Q7 -> 12 | AC7: =SUM(B7:I7) -> 97 | AD7: =SUM(J7:Q7) -> 13 | AE7: =SUM(B7:Q7) -> 110 | AG7: 55 | AH7: 23 | AI7: 0.29487179 | AJ7: 52 | AK7: 20 | AL7: 2 | AM7: 74 | AN7: 0.27027027 | AO7: 0.027027027 | AP7: 4 | AQ7: 70 | AR7: 8 | AS7: 78 | AU7: =(S7/AG7) - 1 -> 0.45454545 | AV7: =(T7/AH7) - 1 -> 0.30434783 | AW7: =(U7/AI7) - 1 -> -0.075098814 | AX7: =(V7/AJ7) - 1 -> 0 | AY7: =(W7/AK7) - 1 -> 1.1 | AZ7: =(X7/AL7) - 1 -> 1 | BA7: =(Y7/AM7) - 1 -> 0.32432432 | BB7: =(Z7/AN7) - 1 -> 0.58571429 | ... BG7: =(AE7/AS7) - 1 -> 0.41025641
A8: 0.32291667 | B8: =Ferney!B8+'StGenis total'!B8+'PdG Nord'!B8+'Mategnin Total'!B8 -> 40 | C8: =Ferney!C8+'StGenis total'!C8+'PdG Nord'!C8+'Mategnin Total'!C8 -> 13 | D8: =Ferney!D8+'StGenis total'!D8+'PdG Nord'!D8+'Mategnin Total'!D8 -> 25 | E8: =Ferney!E8+'StGenis total'!E8+'PdG Nord'!E8+'Mategnin Total'!E8 -> 23 | F8: =Ferney!F8+'StGenis total'!F8+'PdG Nord'!F8+'Mategnin Total'!F8 -> 6 | G8: =Ferney!G8+'StGenis total'!G8+'PdG Nord'!G8+'Mategnin Total'!G8 -> 1 | H8: =Ferney!H8+'StGenis total'!H8+'PdG Nord'!H8+'Mategnin Total'!H8 -> 6 | I8: =Ferney!I8+'StGenis total'!I8+'PdG Nord'!I8+'Mategnin Total'!I8 -> 6 | ... Q8: =Ferney!Q8+'StGenis total'!Q8+'PdG Nord'!Q8+'Mategnin Total'!Q8 -> 1 | S8: =B8+D8+F8+H8+J8+L8+N8+P8 -> 85 | T8: =C8+E8+G8+I8+K8+M8+O8+Q8 -> 46 | U8: =T8/(T8+S8) -> 0.35114504 | V8: =B8+C8+J8+K8 -> 59 | W8: =D8+E8+L8+M8 -> 51 | X8: =F8+G8+N8+O8 -> 7 | Y8: =SUM(V8:X8) -> 117 | Z8: =W8/Y8 -> 0.43589744 | AA8: =X8/Y8 -> 0.05982906 | AB8: =H8+I8+P8+Q8 -> 14 | AC8: =SUM(B8:I8) -> 120 | AD8: =SUM(J8:Q8) -> 11 | AE8: =SUM(B8:Q8) -> 131 | AG8: 45 | AH8: 30 | AI8: 0.4 | AJ8: 38 | AK8: 24 | AL8: 6 | AM8: 68 | AN8: 0.35294118 | AO8: 0.088235294 | AP8: 7 | AQ8: 68 | AR8: 7 | AS8: 75 | AU8: =(S8/AG8) - 1 -> 0.88888889 | AV8: =(T8/AH8) - 1 -> 0.53333333 | AW8: =(U8/AI8) - 1 -> -0.1221374 | AX8: =(V8/AJ8) - 1 -> 0.55263158 | AY8: =(W8/AK8) - 1 -> 1.125 | AZ8: =(X8/AL8) - 1 -> 0.16666667 | BA8: =(Y8/AM8) - 1 -> 0.72058824 | BB8: =(Z8/AN8) - 1 -> 0.23504274 | ... BG8: =(AE8/AS8) - 1 -> 0.74666667
A9: 0.33333333 | B9: =Ferney!B9+'StGenis total'!B9+'PdG Nord'!B9+'Mategnin Total'!B9 -> 47 | C9: =Ferney!C9+'StGenis total'!C9+'PdG Nord'!C9+'Mategnin Total'!C9 -> 15 | D9: =Ferney!D9+'StGenis total'!D9+'PdG Nord'!D9+'Mategnin Total'!D9 -> 19 | E9: =Ferney!E9+'StGenis total'!E9+'PdG Nord'!E9+'Mategnin Total'!E9 -> 9 | F9: =Ferney!F9+'StGenis total'!F9+'PdG Nord'!F9+'Mategnin Total'!F9 -> 2 | G9: =Ferney!G9+'StGenis total'!G9+'PdG Nord'!G9+'Mategnin Total'!G9 -> 3 | H9: =Ferney!H9+'StGenis total'!H9+'PdG Nord'!H9+'Mategnin Total'!H9 -> 11 | I9: =Ferney!I9+'StGenis total'!I9+'PdG Nord'!I9+'Mategnin Total'!I9 -> 2 | ... Q9: =Ferney!Q9+'StGenis total'!Q9+'PdG Nord'!Q9+'Mategnin Total'!Q9 -> 1 | S9: =B9+D9+F9+H9+J9+L9+N9+P9 -> 86 | T9: =C9+E9+G9+I9+K9+M9+O9+Q9 -> 32 | U9: =T9/(T9+S9) -> 0.27118644 | V9: =B9+C9+J9+K9 -> 65 | W9: =D9+E9+L9+M9 -> 34 | X9: =F9+G9+N9+O9 -> 5 | Y9: =SUM(V9:X9) -> 104 | Z9: =W9/Y9 -> 0.32692308 | AA9: =X9/Y9 -> 0.048076923 | AB9: =H9+I9+P9+Q9 -> 14 | AC9: =SUM(B9:I9) -> 108 | AD9: =SUM(J9:Q9) -> 10 | AE9: =SUM(B9:Q9) -> 118 | AG9: 47 | AH9: 24 | AI9: 0.33802817 | AJ9: 40 | AK9: 20 | AL9: 2 | AM9: 62 | AN9: 0.32258065 | AO9: 0.032258065 | AP9: 9 | AQ9: 63 | AR9: 8 | AS9: 71 | AU9: =(S9/AG9) - 1 -> 0.82978723 | AV9: =(T9/AH9) - 1 -> 0.33333333 | AW9: =(U9/AI9) - 1 -> -0.19774011 | AX9: =(V9/AJ9) - 1 -> 0.625 | AY9: =(W9/AK9) - 1 -> 0.7 | AZ9: =(X9/AL9) - 1 -> 1.5 | BA9: =(Y9/AM9) - 1 -> 0.67741935 | BB9: =(Z9/AN9) - 1 -> 0.013461538 | ... BG9: =(AE9/AS9) - 1 -> 0.66197183
A10: 0.34375 | B10: =Ferney!B10+'StGenis total'!B10+'PdG Nord'!B10+'Mategnin Total'!B10 -> 39 | C10: =Ferney!C10+'StGenis total'!C10+'PdG Nord'!C10+'Mategnin Total'!C10 -> 12 | D10: =Ferney!D10+'StGenis total'!D10+'PdG Nord'!D10+'Mategnin Total'!D10 -> 22 | E10: =Ferney!E10+'StGenis total'!E10+'PdG Nord'!E10+'Mategnin Total'!E10 -> 12 | F10: =Ferney!F10+'StGenis total'!F10+'PdG Nord'!F10+'Mategnin Total'!F10 -> 6 | G10: =Ferney!G10+'StGenis total'!G10+'PdG Nord'!G10+'Mategnin Total'!G10 -> 0 | H10: =Ferney!H10+'StGenis total'!H10+'PdG Nord'!H10+'Mategnin Total'!H10 -> 19 | I10: =Ferney!I10+'StGenis total'!I10+'PdG Nord'!I10+'Mategnin Total'!I10 -> 2 | ... Q10: =Ferney!Q10+'StGenis total'!Q10+'PdG Nord'!Q10+'Mategnin Total'!Q10 -> 2 | S10: =B10+D10+F10+H10+J10+L10+N10+P10 -> 97 | T10: =C10+E10+G10+I10+K10+M10+O10+Q10 -> 34 | U10: =T10/(T10+S10) -> 0.25954198 | V10: =B10+C10+J10+K10 -> 60 | W10: =D10+E10+L10+M10 -> 40 | X10: =F10+G10+N10+O10 -> 6 | Y10: =SUM(V10:X10) -> 106 | Z10: =W10/Y10 -> 0.37735849 | AA10: =X10/Y10 -> 0.056603774 | AB10: =H10+I10+P10+Q10 -> 25 | AC10: =SUM(B10:I10) -> 112 | AD10: =SUM(J10:Q10) -> 19 | AE10: =SUM(B10:Q10) -> 131 | AG10: 48 | AH10: 39 | AI10: 0.44827586 | AJ10: 40 | AK10: 27 | AL10: 6 | AM10: 73 | AN10: 0.36986301 | AO10: 0.082191781 | AP10: 14 | AQ10: 74 | AR10: 13 | AS10: 87 | AU10: =(S10/AG10) - 1 -> 1.0208333 | AV10: =(T10/AH10) - 1 -> -0.12820513 | AW10: =(U10/AI10) - 1 -> -0.42102173 | AX10: =(V10/AJ10) - 1 -> 0.5 | AY10: =(W10/AK10) - 1 -> 0.48148148 | AZ10: =(X10/AL10) - 1 -> 0 | BA10: =(Y10/AM10) - 1 -> 0.45205479 | BB10: =(Z10/AN10) - 1 -> 0.020265549 | ... BG10: =(AE10/AS10) - 1 -> 0.50574713
A11: 0.35416667 | B11: =Ferney!B11+'StGenis total'!B11+'PdG Nord'!B11+'Mategnin Total'!B11 -> 57 | C11: =Ferney!C11+'StGenis total'!C11+'PdG Nord'!C11+'Mategnin Total'!C11 -> 10 | D11: =Ferney!D11+'StGenis total'!D11+'PdG Nord'!D11+'Mategnin Total'!D11 -> 23 | E11: =Ferney!E11+'StGenis total'!E11+'PdG Nord'!E11+'Mategnin Total'!E11 -> 9 | F11: =Ferney!F11+'StGenis total'!F11+'PdG Nord'!F11+'Mategnin Total'!F11 -> 4 | G11: =Ferney!G11+'StGenis total'!G11+'PdG Nord'!G11+'Mategnin Total'!G11 -> 3 | H11: =Ferney!H11+'StGenis total'!H11+'PdG Nord'!H11+'Mategnin Total'!H11 -> 6 | I11: =Ferney!I11+'StGenis total'!I11+'PdG Nord'!I11+'Mategnin Total'!I11 -> 7 | ... Q11: =Ferney!Q11+'StGenis total'!Q11+'PdG Nord'!Q11+'Mategnin Total'!Q11 -> 0 | S11: =B11+D11+F11+H11+J11+L11+N11+P11 -> 98 | T11: =C11+E11+G11+I11+K11+M11+O11+Q11 -> 31 | U11: =T11/(T11+S11) -> 0.24031008 | V11: =B11+C11+J11+K11 -> 74 | W11: =D11+E11+L11+M11 -> 33 | X11: =F11+G11+N11+O11 -> 7 | Y11: =SUM(V11:X11) -> 114 | Z11: =W11/Y11 -> 0.28947368 | AA11: =X11/Y11 -> 0.061403509 | AB11: =H11+I11+P11+Q11 -> 15 | AC11: =SUM(B11:I11) -> 119 | AD11: =SUM(J11:Q11) -> 10 | AE11: =SUM(B11:Q11) -> 129 | AG11: 66 | AH11: 24 | AI11: 0.26666667 | AJ11: 50 | AK11: 19 | AL11: 11 | AM11: 80 | AN11: 0.2375 | AO11: 0.1375 | AP11: 10 | AQ11: 79 | AR11: 11 | AS11: 90 | AU11: =(S11/AG11) - 1 -> 0.48484848 | AV11: =(T11/AH11) - 1 -> 0.29166667 | AW11: =(U11/AI11) - 1 -> -0.098837209 | AX11: =(V11/AJ11) - 1 -> 0.48 | AY11: =(W11/AK11) - 1 -> 0.73684211 | AZ11: =(X11/AL11) - 1 -> -0.36363636 | BA11: =(Y11/AM11) - 1 -> 0.425 | BB11: =(Z11/AN11) - 1 -> 0.21883657 | ... BG11: =(AE11/AS11) - 1 -> 0.43333333
A12: 0.36458333 | B12: =Ferney!B12+'StGenis total'!B12+'PdG Nord'!B12+'Mategnin Total'!B12 -> 47 | C12: =Ferney!C12+'StGenis total'!C12+'PdG Nord'!C12+'Mategnin Total'!C12 -> 24 | D12: =Ferney!D12+'StGenis total'!D12+'PdG Nord'!D12+'Mategnin Total'!D12 -> 18 | E12: =Ferney!E12+'StGenis total'!E12+'PdG Nord'!E12+'Mategnin Total'!E12 -> 12 | F12: =Ferney!F12+'StGenis total'!F12+'PdG Nord'!F12+'Mategnin Total'!F12 -> 3 | G12: =Ferney!G12+'StGenis total'!G12+'PdG Nord'!G12+'Mategnin Total'!G12 -> 1 | H12: =Ferney!H12+'StGenis total'!H12+'PdG Nord'!H12+'Mategnin Total'!H12 -> 4 | I12: =Ferney!I12+'StGenis total'!I12+'PdG Nord'!I12+'Mategnin Total'!I12 -> 6 | ... Q12: =Ferney!Q12+'StGenis total'!Q12+'PdG Nord'!Q12+'Mategnin Total'!Q12 -> 1 | S12: =B12+D12+F12+H12+J12+L12+N12+P12 -> 80 | T12: =C12+E12+G12+I12+K12+M12+O12+Q12 -> 45 | U12: =T12/(T12+S12) -> 0.36 | V12: =B12+C12+J12+K12 -> 78 | W12: =D12+E12+L12+M12 -> 32 | X12: =F12+G12+N12+O12 -> 4 | Y12: =SUM(V12:X12) -> 114 | Z12: =W12/Y12 -> 0.28070175 | AA12: =X12/Y12 -> 0.035087719 | AB12: =H12+I12+P12+Q12 -> 11 | AC12: =SUM(B12:I12) -> 115 | AD12: =SUM(J12:Q12) -> 10 | AE12: =SUM(B12:Q12) -> 125 | AG12: 43 | AH12: 28 | AI12: 0.3943662 | AJ12: 35 | AK12: 12 | AL12: 7 | AM12: 54 | AN12: 0.22222222 | AO12: 0.12962963 | AP12: 17 | AQ12: 55 | AR12: 16 | AS12: 71 | AU12: =(S12/AG12) - 1 -> 0.86046512 | AV12: =(T12/AH12) - 1 -> 0.60714286 | AW12: =(U12/AI12) - 1 -> -0.087142857 | AX12: =(V12/AJ12) - 1 -> 1.2285714 | AY12: =(W12/AK12) - 1 -> 1.6666667 | AZ12: =(X12/AL12) - 1 -> -0.42857143 | BA12: =(Y12/AM12) - 1 -> 1.1111111 | BB12: =(Z12/AN12) - 1 -> 0.26315789 | ... BG12: =(AE12/AS12) - 1 -> 0.76056338
A13: 0.375 | B13: =Ferney!B13+'StGenis total'!B13+'PdG Nord'!B13+'Mategnin Total'!B13 -> 4 | C13: =Ferney!C13+'StGenis total'!C13+'PdG Nord'!C13+'Mategnin Total'!C13 -> 6 | D13: =Ferney!D13+'StGenis total'!D13+'PdG Nord'!D13+'Mategnin Total'!D13 -> 1 | E13: =Ferney!E13+'StGenis total'!E13+'PdG Nord'!E13+'Mategnin Total'!E13 -> 2 | F13: =Ferney!F13+'StGenis total'!F13+'PdG Nord'!F13+'Mategnin Total'!F13 -> 1 | G13: =Ferney!G13+'StGenis total'!G13+'PdG Nord'!G13+'Mategnin Total'!G13 -> 0 | H13: =Ferney!H13+'StGenis total'!H13+'PdG Nord'!H13+'Mategnin Total'!H13 -> 1 | I13: =Ferney!I13+'StGenis total'!I13+'PdG Nord'!I13+'Mategnin Total'!I13 -> 0 | ... Q13: =Ferney!Q13+'StGenis total'!Q13+'PdG Nord'!Q13+'Mategnin Total'!Q13 -> 1
A14: Total | B14: =SUM(B5:B13) -> 342 | C14: =SUM(C5:C13) -> 112 | D14: =SUM(D5:D13) -> 170 | E14: =SUM(E5:E13) -> 110 | F14: =SUM(F5:F13) -> 34 | G14: =SUM(G5:G13) -> 11 | H14: =SUM(H5:H13) -> 61 | I14: =SUM(I5:I13) -> 25 | ... Q14: =SUM(Q5:Q13) -> 6 | S14: =B14+D14+F14+H14+J14+L14+N14+P14 -> 676 | T14: =C14+E14+G14+I14+K14+M14+O14+Q14 -> 280 | U14: =T14/(T14+S14) -> 0.29288703 | V14: =B14+C14+J14+K14 -> 506 | W14: =D14+E14+L14+M14 -> 305 | X14: =F14+G14+N14+O14 -> 45 | Y14: =SUM(V14:X14) -> 856 | Z14: =W14/Y14 -> 0.35630841 | AA14: =X14/Y14 -> 0.052570093 | AB14: =H14+I14+P14+Q14 -> 100 | AC14: =SUM(B14:I14) -> 865 | AD14: =SUM(J14:Q14) -> 91 | AE14: =SUM(B14:Q14) -> 956 | AG14: 414 | AH14: 224 | AI14: 0.35109718 | AJ14: 344 | AK14: 175 | AL14: 42 | AM14: 561 | AN14: 0.31194296 | AO14: 0.07486631 | AP14: 77 | AQ14: 559 | AR14: 79 | AS14: 638 | AU14: =(S14/AG14) - 1 -> 0.63285024 | AV14: =(T14/AH14) - 1 -> 0.25 | AW14: =(U14/AI14) - 1 -> -0.16579498 | AX14: =(V14/AJ14) - 1 -> 0.47093023 | AY14: =(W14/AK14) - 1 -> 0.74285714 | AZ14: =(X14/AL14) - 1 -> 0.071428571 | BA14: =(Y14/AM14) - 1 -> 0.5258467 | BB14: =(Z14/AN14) - 1 -> 0.14222296 | ... BG14: =(AE14/AS14) - 1 -> 0.4984326
A15: Total HP | B15: =SUM(B7:B10) -> 158 | C15: =SUM(C7:C10) -> 51 | D15: =SUM(D7:D10) -> 88 | E15: =SUM(E7:E10) -> 61 | F15: =SUM(F7:F10) -> 18 | G15: =SUM(G7:G10) -> 4 | H15: =SUM(H7:H10) -> 46 | I15: =SUM(I7:I10) -> 11 | ... Q15: =SUM(Q7:Q10) -> 4 | S15: =B15+D15+F15+H15+J15+L15+N15+P15 -> 348 | T15: =C15+E15+G15+I15+K15+M15+O15+Q15 -> 142 | U15: =T15/(T15+S15) -> 0.28979592 | V15: =B15+C15+J15+K15 -> 236 | W15: =D15+E15+L15+M15 -> 167 | X15: =F15+G15+N15+O15 -> 22 | Y15: =SUM(V15:X15) -> 425 | Z15: =W15/Y15 -> 0.39294118 | AA15: =X15/Y15 -> 0.051764706 | AB15: =H15+I15+P15+Q15 -> 65 | AC15: =SUM(B15:I15) -> 437 | AD15: =SUM(J15:Q15) -> 53 | AE15: =SUM(B15:Q15) -> 490 | AG15: 195 | AH15: 116 | AI15: 0.37299035 | AJ15: 170 | AK15: 91 | AL15: 16 | AM15: 277 | AN15: 0.32851986 | AO15: 0.057761733 | AP15: 34 | AQ15: 275 | AR15: 36 | AS15: 311 | AU15: =(S15/AG15) - 1 -> 0.78461538 | AV15: =(T15/AH15) - 1 -> 0.22413793 | AW15: =(U15/AI15) - 1 -> -0.22304715 | AX15: =(V15/AJ15) - 1 -> 0.38823529 | AY15: =(W15/AK15) - 1 -> 0.83516484 | AZ15: =(X15/AL15) - 1 -> 0.375 | BA15: =(Y15/AM15) - 1 -> 0.53429603 | BB15: =(Z15/AN15) - 1 -> 0.19609567 | ... BG15: =(AE15/AS15) - 1 -> 0.5755627
A17: Tot 7 | B17: =SUM(B5:B8) -> 148 | C17: =SUM(C5:C8) -> 45 | D17: =SUM(D5:D8) -> 87 | E17: =SUM(E5:E8) -> 66 | F17: =SUM(F5:F8) -> 18 | G17: =SUM(G5:G8) -> 4 | H17: =SUM(H5:H8) -> 20 | I17: =SUM(I5:I8) -> 8 | ... Q17: =SUM(Q5:Q8) -> 1
A18: Tot 8 | B18: =SUM(B9:B12) -> 190 | C18: =SUM(C9:C12) -> 61 | D18: =SUM(D9:D12) -> 82 | E18: =SUM(E9:E12) -> 42 | F18: =SUM(F9:F12) -> 15 | G18: =SUM(G9:G12) -> 7 | H18: =SUM(H9:H12) -> 40 | I18: =SUM(I9:I12) -> 17 | ... Q18: =SUM(Q9:Q12) -> 4 | AE18: =AE14/#REF! -> #REF!
S21: =S14/#REF! -> #REF! | T21: =T14/#REF! -> #REF!

Sheet Ferney
B1: Lieu: | C1: Ferney-Tunnel
B2: France -> Suisse | J2: Suisse -> France | S2: ="Totaux 2021 " & $C1 -> Totaux 2021 Ferney-Tunnel | AG2: ="Totaux 2020 " & $C1 -> Totaux 2020 Ferney-Tunnel | AU2: ="Changement depuis 2020 " & $C1 -> Changement depuis 2020 Ferney-Tunnel
B3: Vélo traditionel | D3: VAE | F3: Mode Nouveau Electrique | H3: Piéton/ne | J3: Vélo traditionel | L3: VAE | N3: Mode Nouveau Electrique (trotinette, scateboard , …) | P3: Piéton/ne | S3: Hommes | T3: Femmes | U3: %Femmes | V3: VT | W3: VAE | X3: Nouveau | Y3: 2r | Z3: %VAE | AA3: %Nouveau | AB3: Piétons | AC3: >CH | AD3: >FR | AE3: TOT | AG3: Hommes | AH3: Femmes | AI3: %Femmes | AJ3: VT | AK3: VAE | AL3: Nouveau | AM3: 2r | AN3: %VAE | AO3: %Nouveau | AP3: Piétons | AQ3: >CH | AR3: >FR | AS3: TOT | AU3: Hommes | AV3: Femmes | AW3: %Femmes | AX3: VT | AY3: VAE | AZ3: Nouveau | BA3: 2r | BB3: %VAE | BC3: %Nouveau | BD3: Piétons | BE3: >CH | BF3: >FR | BG3: TOT
A4: Heure | B4: H | C4: F | D4: H | E4: F | F4: H | G4: F | H4: H | I4: F | J4: H | K4: F | L4: H | M4: F | N4: H | O4: F | P4: H | Q4: F
A5: 0.29166667 | B5: 8 | C5: 2 | D5: 2 | E5: 1 | F5: 2 | G5: 0 | S5: =B5+D5+F5+H5+J5+L5+N5+P5 -> 12 | T5: =C5+E5+G5+I5+K5+M5+O5+Q5 -> 3 | U5: =T5/(T5+S5) -> 0.2 | V5: =B5+C5+J5+K5 -> 10 | W5: =D5+E5+L5+M5 -> 3 | X5: =F5+G5+N5+O5 -> 2 | Y5: =SUM(V5:X5) -> 15 | Z5: =W5/Y5 -> 0.2 | AA5: =X5/Y5 -> 0.13333333 | AB5: =H5+I5+P5+Q5 -> 0 | AC5: =SUM(B5:I5) -> 15 | AD5: =SUM(J5:Q5) -> 0 | AE5: =SUM(B5:Q5) -> 15 | AG5: 4 | AH5: 8 | AI5: 0.66666667 | AJ5: 7 | AK5: 5 | AL5: 0 | AM5: 12 | AN5: 0.41666667 | AO5: 0 | AP5: 0 | AQ5: 11 | AR5: 1 | AS5: 12 | AU5: =(S5/AG5) - 1 -> 2 | AV5: =(T5/AH5) - 1 -> -0.625 | AW5: =(U5/AI5) - 1 -> -0.7 | AX5: =(V5/AJ5) - 1 -> 0.42857143 | AY5: =(W5/AK5) - 1 -> -0.4 | AZ5: =(X5/AL5) - 1 -> #DIV/0! | BA5: =(Y5/AM5) - 1 -> 0.25 | BB5: =(Z5/AN5) - 1 -> -0.52 | ... BG5: =(AE5/AS5) - 1 -> 0.25
A6: 0.30208333 | B6: 9 | C6: 6 | D6: 8 | E6: 4 | F6: 1 | G6: 2 | J6: 1 | L6: 1 | S6: =B6+D6+F6+H6+J6+L6+N6+P6 -> 20 | T6: =C6+E6+G6+I6+K6+M6+O6+Q6 -> 12 | U6: =T6/(T6+S6) -> 0.375 | V6: =B6+C6+J6+K6 -> 16 | W6: =D6+E6+L6+M6 -> 13 | X6: =F6+G6+N6+O6 -> 3 | Y6: =SUM(V6:X6) -> 32 | Z6: =W6/Y6 -> 0.40625 | AA6: =X6/Y6 -> 0.09375 | AB6: =H6+I6+P6+Q6 -> 0 | AC6: =SUM(B6:I6) -> 30 | AD6: =SUM(J6:Q6) -> 2 | AE6: =SUM(B6:Q6) -> 32 | AG6: 9 | AH6: 4 | AI6: 0.30769231 | AJ6: 6 | AK6: 6 | AL6: 0 | AM6: 12 | AN6: 0.5 | AO6: 0 | AP6: 1 | AQ6: 13 | AR6: 0 | AS6: 13 | AU6: =(S6/AG6) - 1 -> 1.2222222 | AV6: =(T6/AH6) - 1 -> 2 | AW6: =(U6/AI6) - 1 -> 0.21875 | AX6: =(V6/AJ6) - 1 -> 1.6666667 | AY6: =(W6/AK6) - 1 -> 1.1666667 | AZ6: =(X6/AL6) - 1 -> #DIV/0! | BA6: =(Y6/AM6) - 1 -> 1.6666667 | BB6: =(Z6/AN6) - 1 -> -0.1875 | ... BG6: =(AE6/AS6) - 1 -> 1.4615385
A7: 0.3125 | B7: 6 | C7: 4 | D7: 6 | E7: 2 | F7: 1 | G7: 0 | S7: =B7+D7+F7+H7+J7+L7+N7+P7 -> 13 | T7: =C7+E7+G7+I7+K7+M7+O7+Q7 -> 6 | U7: =T7/(T7+S7) -> 0.31578947 | V7: =B7+C7+J7+K7 -> 10 | W7: =D7+E7+L7+M7 -> 8 | X7: =F7+G7+N7+O7 -> 1 | Y7: =SUM(V7:X7) -> 19 | Z7: =W7/Y7 -> 0.42105263 | AA7: =X7/Y7 -> 0.052631579 | AB7: =H7+I7+P7+Q7 -> 0 | AC7: =SUM(B7:I7) -> 19 | AD7: =SUM(J7:Q7) -> 0 | AE7: =SUM(B7:Q7) -> 19 | AG7: 14 | AH7: 5 | AI7: 0.26315789 | AJ7: 13 | AK7: 6 | AL7: 0 | AM7: 19 | AN7: 0.31578947 | AO7: 0 | AP7: 0 | AQ7: 18 | AR7: 1 | AS7: 19 | AU7: =(S7/AG7) - 1 -> -0.071428571 | AV7: =(T7/AH7) - 1 -> 0.2 | AW7: =(U7/AI7) - 1 -> 0.2 | AX7: =(V7/AJ7) - 1 -> -0.23076923 | AY7: =(W7/AK7) - 1 -> 0.33333333 | AZ7: =(X7/AL7) - 1 -> #DIV/0! | BA7: =(Y7/AM7) - 1 -> 0 | BB7: =(Z7/AN7) - 1 -> 0.33333333 | ... BG7: =(AE7/AS7) - 1 -> 0
A8: 0.32291667 | B8: 12 | C8: 5 | D8: 7 | E8: 9 | F8: 3 | G8: 0 | H8: 1 | I8: 1 | P8: 1 | S8: =B8+D8+F8+H8+J8+L8+N8+P8 -> 24 | T8: =C8+E8+G8+I8+K8+M8+O8+Q8 -> 15 | U8: =T8/(T8+S8) -> 0.38461538 | V8: =B8+C8+J8+K8 -> 17 | W8: =D8+E8+L8+M8 -> 16 | X8: =F8+G8+N8+O8 -> 3 | Y8: =SUM(V8:X8) -> 36 | Z8: =W8/Y8 -> 0.44444444 | AA8: =X8/Y8 -> 0.083333333 | AB8: =H8+I8+P8+Q8 -> 3 | AC8: =SUM(B8:I8) -> 38 | AD8: =SUM(J8:Q8) -> 1 | AE8: =SUM(B8:Q8) -> 39 | AG8: 11 | AH8: 6 | AI8: 0.35294118 | AJ8: 11 | AK8: 6 | AL8: 0 | AM8: 17 | AN8: 0.35294118 | AO8: 0 | AP8: 0 | AQ8: 17 | AR8: 0 | AS8: 17 | AU8: =(S8/AG8) - 1 -> 1.1818182 | AV8: =(T8/AH8) - 1 -> 1.5 | AW8: =(U8/AI8) - 1 -> 0.08974359 | AX8: =(V8/AJ8) - 1 -> 0.54545455 | AY8: =(W8/AK8) - 1 -> 1.6666667 | AZ8: =(X8/AL8) - 1 -> #DIV/0! | BA8: =(Y8/AM8) - 1 -> 1.1176471 | BB8: =(Z8/AN8) - 1 -> 0.25925926 | ... BG8: =(AE8/AS8) - 1 -> 1.2941176
A9: 0.33333333 | B9: 6 | C9: 3 | D9: 4 | E9: 3 | F9: 1 | G9: 1 | L9: 1 | S9: =B9+D9+F9+H9+J9+L9+N9+P9 -> 12 | T9: =C9+E9+G9+I9+K9+M9+O9+Q9 -> 7 | U9: =T9/(T9+S9) -> 0.36842105 | V9: =B9+C9+J9+K9 -> 9 | W9: =D9+E9+L9+M9 -> 8 | X9: =F9+G9+N9+O9 -> 2 | Y9: =SUM(V9:X9) -> 19 | Z9: =W9/Y9 -> 0.42105263 | AA9: =X9/Y9 -> 0.10526316 | AB9: =H9+I9+P9+Q9 -> 0 | AC9: =SUM(B9:I9) -> 18 | AD9: =SUM(J9:Q9) -> 1 | AE9: =SUM(B9:Q9) -> 19 | AG9: 13 | AH9: 12 | AI9: 0.48 | AJ9: 13 | AK9: 10 | AL9: 2 | AM9: 25 | AN9: 0.4 | AO9: 0.08 | AP9: 0 | AQ9: 23 | AR9: 2 | AS9: 25 | AU9: =(S9/AG9) - 1 -> -0.076923077 | AV9: =(T9/AH9) - 1 -> -0.41666667 | AW9: =(U9/AI9) - 1 -> -0.23245614 | AX9: =(V9/AJ9) - 1 -> -0.30769231 | AY9: =(W9/AK9) - 1 -> -0.2 | AZ9: =(X9/AL9) - 1 -> 0 | BA9: =(Y9/AM9) - 1 -> -0.24 | BB9: =(Z9/AN9) - 1 -> 0.052631579 | ... BG9: =(AE9/AS9) - 1 -> -0.24
A10: 0.34375 | B10: 5 | C10: 3 | D10: 7 | E10: 4 | F10: 3 | G10: 0 | L10: 2 | M10: 1 | S10: =B10+D10+F10+H10+J10+L10+N10+P10 -> 17 | T10: =C10+E10+G10+I10+K10+M10+O10+Q10 -> 8 | U10: =T10/(T10+S10) -> 0.32 | V10: =B10+C10+J10+K10 -> 8 | W10: =D10+E10+L10+M10 -> 14 | X10: =F10+G10+N10+O10 -> 3 | Y10: =SUM(V10:X10) -> 25 | Z10: =W10/Y10 -> 0.56 | AA10: =X10/Y10 -> 0.12 | AB10: =H10+I10+P10+Q10 -> 0 | AC10: =SUM(B10:I10) -> 22 | AD10: =SUM(J10:Q10) -> 3 | AE10: =SUM(B10:Q10) -> 25 | AG10: 13 | AH10: 14 | AI10: 0.51851852 | AJ10: 9 | AK10: 14 | AL10: 3 | AM10: 26 | AN10: 0.53846154 | AO10: 0.11538462 | AP10: 1 | AQ10: 23 | AR10: 4 | AS10: 27 | AU10: =(S10/AG10) - 1 -> 0.30769231 | AV10: =(T10/AH10) - 1 -> -0.42857143 | AW10: =(U10/AI10) - 1 -> -0.38285714 | AX10: =(V10/AJ10) - 1 -> -0.11111111 | AY10: =(W10/AK10) - 1 -> 0 | AZ10: =(X10/AL10) - 1 -> 0 | BA10: =(Y10/AM10) - 1 -> -0.038461538 | BB10: =(Z10/AN10) - 1 -> 0.04 | ... BG10: =(AE10/AS10) - 1 -> -0.074074074
A11: 0.35416667 | B11: 12 | C11: 1 | D11: 6 | E11: 2 | F11: 2 | G11: 2 | L11: 1 | S11: =B11+D11+F11+H11+J11+L11+N11+P11 -> 21 | T11: =C11+E11+G11+I11+K11+M11+O11+Q11 -> 5 | U11: =T11/(T11+S11) -> 0.19230769 | V11: =B11+C11+J11+K11 -> 13 | W11: =D11+E11+L11+M11 -> 9 | X11: =F11+G11+N11+O11 -> 4 | Y11: =SUM(V11:X11) -> 26 | Z11: =W11/Y11 -> 0.34615385 | AA11: =X11/Y11 -> 0.15384615 | AB11: =H11+I11+P11+Q11 -> 0 | AC11: =SUM(B11:I11) -> 25 | AD11: =SUM(J11:Q11) -> 1 | AE11: =SUM(B11:Q11) -> 26 | AG11: 21 | AH11: 9 | AI11: 0.3 | AJ11: 16 | AK11: 12 | AL11: 1 | AM11: 29 | AN11: 0.4137931 | AO11: 0.034482759 | AP11: 1 | AQ11: 27 | AR11: 3 | AS11: 30 | AU11: =(S11/AG11) - 1 -> 0 | AV11: =(T11/AH11) - 1 -> -0.44444444 | AW11: =(U11/AI11) - 1 -> -0.35897436 | AX11: =(V11/AJ11) - 1 -> -0.1875 | AY11: =(W11/AK11) - 1 -> -0.25 | AZ11: =(X11/AL11) - 1 -> 3 | BA11: =(Y11/AM11) - 1 -> -0.10344828 | BB11: =(Z11/AN11) - 1 -> -0.16346154 | ... BG11: =(AE11/AS11) - 1 -> -0.13333333
A12: 0.36458333 | B12: 11 | C12: 8 | D12: 8 | E12: 6 | F12: 2 | G12: 0 | I12: 1 | L12: 0 | S12: =B12+D12+F12+H12+J12+L12+N12+P12 -> 21 | T12: =C12+E12+G12+I12+K12+M12+O12+Q12 -> 15 | U12: =T12/(T12+S12) -> 0.41666667 | V12: =B12+C12+J12+K12 -> 19 | W12: =D12+E12+L12+M12 -> 14 | X12: =F12+G12+N12+O12 -> 2 | Y12: =SUM(V12:X12) -> 35 | Z12: =W12/Y12 -> 0.4 | AA12: =X12/Y12 -> 0.057142857 | AB12: =H12+I12+P12+Q12 -> 1 | AC12: =SUM(B12:I12) -> 36 | AD12: =SUM(J12:Q12) -> 0 | AE12: =SUM(B12:Q12) -> 36 | AG12: 13 | AH12: 4 | AI12: 0.23529412 | AJ12: 11 | AK12: 4 | AL12: 1 | AM12: 16 | AN12: 0.25 | AO12: 0.0625 | AP12: 1 | AQ12: 14 | AR12: 3 | AS12: 17 | AU12: =(S12/AG12) - 1 -> 0.61538462 | AV12: =(T12/AH12) - 1 -> 2.75 | AW12: =(U12/AI12) - 1 -> 0.77083333 | AX12: =(V12/AJ12) - 1 -> 0.72727273 | AY12: =(W12/AK12) - 1 -> 2.5 | AZ12: =(X12/AL12) - 1 -> 1 | BA12: =(Y12/AM12) - 1 -> 1.1875 | BB12: =(Z12/AN12) - 1 -> 0.6 | ... BG12: =(AE12/AS12) - 1 -> 1.1176471
A14: Total | B14: =SUM(B5:B12) -> 69 | C14: =SUM(C5:C12) -> 32 | D14: =SUM(D5:D12) -> 48 | E14: =SUM(E5:E12) -> 31 | F14: =SUM(F5:F12) -> 15 | G14: =SUM(G5:G12) -> 5 | H14: =SUM(H5:H12) -> 1 | I14: =SUM(I5:I12) -> 2 | ... Q14: =SUM(Q5:Q12) -> 0 | S14: =B14+D14+F14+H14+J14+L14+N14+P14 -> 140 | T14: =C14+E14+G14+I14+K14+M14+O14+Q14 -> 71 | U14: =T14/(T14+S14) -> 0.33649289 | V14: =B14+C14+J14+K14 -> 102 | W14: =D14+E14+L14+M14 -> 85 | X14: =F14+G14+N14+O14 -> 20 | Y14: =SUM(V14:X14) -> 207 | Z14: =W14/Y14 -> 0.41062802 | AA14: =X14/Y14 -> 0.096618357 | AB14: =H14+I14+P14+Q14 -> 4 | AC14: =SUM(B14:I14) -> 203 | AD14: =SUM(J14:Q14) -> 8 | AE14: =SUM(B14:Q14) -> 211 | AG14: 98 | AH14: 62 | AI14: 0.3875 | AJ14: 86 | AK14: 63 | AL14: 7 | AM14: 156 | AN14: 0.40384615 | AO14: 0.044871795 | AP14: 4 | AQ14: 146 | AR14: 14 | AS14: 160 | AU14: =(S14/AG14) - 1 -> 0.42857143 | AV14: =(T14/AH14) - 1 -> 0.14516129 | AW14: =(U14/AI14) - 1 -> -0.13163125 | AX14: =(V14/AJ14) - 1 -> 0.18604651 | AY14: =(W14/AK14) - 1 -> 0.34920635 | AZ14: =(X14/AL14) - 1 -> 1.8571429 | BA14: =(Y14/AM14) - 1 -> 0.32692308 | BB14: =(Z14/AN14) - 1 -> 0.016793191 | ... BG14: =(AE14/AS14) - 1 -> 0.31875
A15: Total HP | B15: =SUM(B7:B10) -> 29 | C15: =SUM(C7:C10) -> 15 | D15: =SUM(D7:D10) -> 24 | E15: =SUM(E7:E10) -> 18 | F15: =SUM(F7:F10) -> 8 | G15: =SUM(G7:G10) -> 1 | H15: =SUM(H7:H10) -> 1 | I15: =SUM(I7:I10) -> 1 | ... Q15: =SUM(Q7:Q10) -> 0 | S15: =B15+D15+F15+H15+J15+L15+N15+P15 -> 66 | T15: =C15+E15+G15+I15+K15+M15+O15+Q15 -> 36 | U15: =T15/(T15+S15) -> 0.35294118 | V15: =B15+C15+J15+K15 -> 44 | W15: =D15+E15+L15+M15 -> 46 | X15: =F15+G15+N15+O15 -> 9 | Y15: =SUM(V15:X15) -> 99 | Z15: =W15/Y15 -> 0.46464646 | AA15: =X15/Y15 -> 0.090909091 | AB15: =H15+I15+P15+Q15 -> 3 | AC15: =SUM(B15:I15) -> 97 | AD15: =SUM(J15:Q15) -> 5 | AE15: =SUM(B15:Q15) -> 102 | AG15: 51 | AH15: 37 | AI15: 0.42045455 | AJ15: 46 | AK15: 36 | AL15: 5 | AM15: 87 | AN15: 0.4137931 | AO15: 0.057471264 | AP15: 1 | AQ15: 81 | AR15: 7 | AS15: 88 | AU15: =(S15/AG15) - 1 -> 0.29411765 | AV15: =(T15/AH15) - 1 -> -0.027027027 | AW15: =(U15/AI15) - 1 -> -0.16057234 | AX15: =(V15/AJ15) - 1 -> -0.043478261 | AY15: =(W15/AK15) - 1 -> 0.27777778 | AZ15: =(X15/AL15) - 1 -> 0.8 | BA15: =(Y15/AM15) - 1 -> 0.13793103 | BB15: =(Z15/AN15) - 1 -> 0.12289562 | ... BG15: =(AE15/AS15) - 1 -> 0.15909091
A17: Tot 7 | B17: =SUM(B5:B8) -> 35 | C17: =SUM(C5:C8) -> 17 | D17: =SUM(D5:D8) -> 23 | E17: =SUM(E5:E8) -> 16 | F17: =SUM(F5:F8) -> 7 | G17: =SUM(G5:G8) -> 2 | H17: =SUM(H5:H8) -> 1 | I17: =SUM(I5:I8) -> 1 | ... Q17: =SUM(Q5:Q8) -> 0
A18: Tot 8 | B18: =SUM(B9:B12) -> 34 | C18: =SUM(C9:C12) -> 15 | D18: =SUM(D9:D12) -> 25 | E18: =SUM(E9:E12) -> 15 | F18: =SUM(F9:F12) -> 8 | G18: =SUM(G9:G12) -> 3 | H18: =SUM(H9:H12) -> 0 | I18: =SUM(I9:I12) -> 1 | ... Q18: =SUM(Q9:Q12) -> 0
S20: =S14/#REF! -> #REF! | T20: =T14/#REF! -> #REF! | AE20: =AE14/#REF! -> #REF! | AG20: 0.48039216 | AH20: 0.42465753 | AS20: 0.45714286

Sheet Ferney-BoisBrulé
B1: Lieu: | C1: Ferney-BoisBrûlé
B2: France -> Suisse | J2: Suisse -> France | S2: ="Totaux 2021 " & $C1 -> Totaux 2021 Ferney-BoisBrûlé | AG2: ="Totaux 2020 " & $C1 -> Totaux 2020 Ferney-BoisBrûlé
B3: Vélo traditionel | D3: VAE | F3: Mode Nouveau Electrique | H3: Piéton/ne | J3: Vélo traditionel | L3: VAE | N3: Mode Nouveau Electrique (trotinette, scateboard , …) | P3: Piéton/ne | S3: Hommes | T3: Femmes | U3: %Femmes | V3: VT | W3: VAE | X3: Nouveau | Y3: 2r | Z3: %VAE | AA3: %Nouveau | AB3: Piétons | AC3: >CH | AD3: >FR | AE3: TOT
A4: Heure | B4: H | C4: F | D4: H | E4: F | F4: H | G4: F | H4: H | I4: F | J4: H | K4: F | L4: H | M4: F | N4: H | O4: F | P4: H | Q4: F
A5: 0.29166667 | B5: 1 | C5: 1 | D5: 0 | E5: 1 | S5: =B5+D5+F5+H5+J5+L5+N5+P5 -> 1 | T5: =C5+E5+G5+I5+K5+M5+O5+Q5 -> 2 | U5: =T5/(T5+S5) -> 0.66666667 | V5: =B5+C5+J5+K5 -> 2 | W5: =D5+E5+L5+M5 -> 1 | X5: =F5+G5+N5+O5 -> 0 | Y5: =SUM(V5:X5) -> 3 | Z5: =W5/Y5 -> 0.33333333 | AA5: =X5/Y5 -> 0 | AB5: =H5+I5+P5+Q5 -> 0 | AC5: =SUM(B5:I5) -> 3 | AD5: =SUM(J5:Q5) -> 0 | AE5: =SUM(B5:Q5) -> 3
A6: 0.30208333 | B6: 0 | C6: 0 | D6: 0 | E6: 1 | S6: =B6+D6+F6+H6+J6+L6+N6+P6 -> 0 | T6: =C6+E6+G6+I6+K6+M6+O6+Q6 -> 1 | U6: =T6/(T6+S6) -> 1 | V6: =B6+C6+J6+K6 -> 0 | W6: =D6+E6+L6+M6 -> 1 | X6: =F6+G6+N6+O6 -> 0 | Y6: =SUM(V6:X6) -> 1 | Z6: =W6/Y6 -> 1 | AA6: =X6/Y6 -> 0 | AB6: =H6+I6+P6+Q6 -> 0 | AC6: =SUM(B6:I6) -> 1 | AD6: =SUM(J6:Q6) -> 0 | AE6: =SUM(B6:Q6) -> 1
A7: 0.3125 | B7: 4 | C7: 1 | D7: 3 | E7: 0 | S7: =B7+D7+F7+H7+J7+L7+N7+P7 -> 7 | T7: =C7+E7+G7+I7+K7+M7+O7+Q7 -> 1 | U7: =T7/(T7+S7) -> 0.125 | V7: =B7+C7+J7+K7 -> 5 | W7: =D7+E7+L7+M7 -> 3 | X7: =F7+G7+N7+O7 -> 0 | Y7: =SUM(V7:X7) -> 8 | Z7: =W7/Y7 -> 0.375 | AA7: =X7/Y7 -> 0 | AB7: =H7+I7+P7+Q7 -> 0 | AC7: =SUM(B7:I7) -> 8 | AD7: =SUM(J7:Q7) -> 0 | AE7: =SUM(B7:Q7) -> 8
A8: 0.32291667 | B8: 0 | C8: 0 | K8: 1 | S8: =B8+D8+F8+H8+J8+L8+N8+P8 -> 0 | T8: =C8+E8+G8+I8+K8+M8+O8+Q8 -> 1 | U8: =T8/(T8+S8) -> 1 | V8: =B8+C8+J8+K8 -> 1 | W8: =D8+E8+L8+M8 -> 0 | X8: =F8+G8+N8+O8 -> 0 | Y8: =SUM(V8:X8) -> 1 | Z8: =W8/Y8 -> 0 | AA8: =X8/Y8 -> 0 | AB8: =H8+I8+P8+Q8 -> 0 | AC8: =SUM(B8:I8) -> 0 | AD8: =SUM(J8:Q8) -> 1 | AE8: =SUM(B8:Q8) -> 1
A9: 0.33333333 | B9: 0 | J9: 1 | K9: 0 | L9: 1 | M9: 1 | S9: =B9+D9+F9+H9+J9+L9+N9+P9 -> 2 | T9: =C9+E9+G9+I9+K9+M9+O9+Q9 -> 1 | U9: =T9/(T9+S9) -> 0.33333333 | V9: =B9+C9+J9+K9 -> 1 | W9: =D9+E9+L9+M9 -> 2 | X9: =F9+G9+N9+O9 -> 0 | Y9: =SUM(V9:X9) -> 3 | Z9: =W9/Y9 -> 0.66666667 | AA9: =X9/Y9 -> 0 | AB9: =H9+I9+P9+Q9 -> 0 | AC9: =SUM(B9:I9) -> 0 | AD9: =SUM(J9:Q9) -> 3 | AE9: =SUM(B9:Q9) -> 3
A10: 0.34375 | B10: 1 | J10: 1 | K10: 0 | S10: =B10+D10+F10+H10+J10+L10+N10+P10 -> 2 | T10: =C10+E10+G10+I10+K10+M10+O10+Q10 -> 0 | U10: =T10/(T10+S10) -> 0 | V10: =B10+C10+J10+K10 -> 2 | W10: =D10+E10+L10+M10 -> 0 | X10: =F10+G10+N10+O10 -> 0 | Y10: =SUM(V10:X10) -> 2 | Z10: =W10/Y10 -> 0 | AA10: =X10/Y10 -> 0 | AB10: =H10+I10+P10+Q10 -> 0 | AC10: =SUM(B10:I10) -> 1 | AD10: =SUM(J10:Q10) -> 1 | AE10: =SUM(B10:Q10) -> 2
A11: 0.35416667 | J11: 2 | K11: 2 | S11: =B11+D11+F11+H11+J11+L11+N11+P11 -> 2 | T11: =C11+E11+G11+I11+K11+M11+O11+Q11 -> 2 | U11: =T11/(T11+S11) -> 0.5 | V11: =B11+C11+J11+K11 -> 4 | W11: =D11+E11+L11+M11 -> 0 | X11: =F11+G11+N11+O11 -> 0 | Y11: =SUM(V11:X11) -> 4 | Z11: =W11/Y11 -> 0 | AA11: =X11/Y11 -> 0 | AB11: =H11+I11+P11+Q11 -> 0 | AC11: =SUM(B11:I11) -> 0 | AD11: =SUM(J11:Q11) -> 4 | AE11: =SUM(B11:Q11) -> 4
A12: 0.36458333 | J12: 1 | S12: =B12+D12+F12+H12+J12+L12+N12+P12 -> 1 | T12: =C12+E12+G12+I12+K12+M12+O12+Q12 -> 0 | U12: =T12/(T12+S12) -> 0 | V12: =B12+C12+J12+K12 -> 1 | W12: =D12+E12+L12+M12 -> 0 | X12: =F12+G12+N12+O12 -> 0 | Y12: =SUM(V12:X12) -> 1 | Z12: =W12/Y12 -> 0 | AA12: =X12/Y12 -> 0 | AB12: =H12+I12+P12+Q12 -> 0 | AC12: =SUM(B12:I12) -> 0 | AD12: =SUM(J12:Q12) -> 1 | AE12: =SUM(B12:Q12) -> 1
A14: Total | B14: =SUM(B5:B12) -> 6 | C14: =SUM(C5:C12) -> 2 | D14: =SUM(D5:D12) -> 3 | E14: =SUM(E5:E12) -> 2 | F14: =SUM(F5:F12) -> 0 | G14: =SUM(G5:G12) -> 0 | H14: =SUM(H5:H12) -> 0 | I14: =SUM(I5:I12) -> 0 | ... Q14: =SUM(Q5:Q12) -> 0 | S14: =B14+D14+F14+H14+J14+L14+N14+P14 -> 15 | T14: =C14+E14+G14+I14+K14+M14+O14+Q14 -> 8 | U14: =T14/(T14+S14) -> 0.34782609 | V14: =B14+C14+J14+K14 -> 16 | W14: =D14+E14+L14+M14 -> 7 | X14: =F14+G14+N14+O14 -> 0 | Y14: =SUM(V14:X14) -> 23 | Z14: =W14/Y14 -> 0.30434783 | AA14: =X14/Y14 -> 0 | AB14: =H14+I14+P14+Q14 -> 0 | AC14: =SUM(B14:I14) -> 13 | AD14: =SUM(J14:Q14) -> 10 | AE14: =SUM(B14:Q14) -> 23
A15: Total HP | B15: =SUM(B7:B10) -> 5 | C15: =SUM(C7:C10) -> 1 | D15: =SUM(D7:D10) -> 3 | E15: =SUM(E7:E10) -> 0 | F15: =SUM(F7:F10) -> 0 | G15: =SUM(G7:G10) -> 0 | H15: =SUM(H7:H10) -> 0 | I15: =SUM(I7:I10) -> 0 | ... Q15: =SUM(Q7:Q10) -> 0 | S15: =B15+D15+F15+H15+J15+L15+N15+P15 -> 11 | T15: =C15+E15+G15+I15+K15+M15+O15+Q15 -> 3 | U15: =T15/(T15+S15) -> 0.21428571 | V15: =B15+C15+J15+K15 -> 9 | W15: =D15+E15+L15+M15 -> 5 | X15: =F15+G15+N15+O15 -> 0 | Y15: =SUM(V15:X15) -> 14 | Z15: =W15/Y15 -> 0.35714286 | AA15: =X15/Y15 -> 0 | AB15: =H15+I15+P15+Q15 -> 0 | AC15: =SUM(B15:I15) -> 9 | AD15: =SUM(J15:Q15) -> 5 | AE15: =SUM(B15:Q15) -> 14
A17: Tot 7 | B17: =SUM(B5:B8) -> 5 | C17: =SUM(C5:C8) -> 2 | D17: =SUM(D5:D8) -> 3 | E17: =SUM(E5:E8) -> 2 | F17: =SUM(F5:F8) -> 0 | G17: =SUM(G5:G8) -> 0 | H17: =SUM(H5:H8) -> 0 | I17: =SUM(I5:I8) -> 0 | ... Q17: =SUM(Q5:Q8) -> 0
A18: Tot 8 | B18: =SUM(B9:B12) -> 1 | C18: =SUM(C9:C12) -> 0 | D18: =SUM(D9:D12) -> 0 | E18: =SUM(E9:E12) -> 0 | F18: =SUM(F9:F12) -> 0 | G18: =SUM(G9:G12) -> 0 | H18: =SUM(H9:H12) -> 0 | I18: =SUM(I9:I12) -> 0 | ... Q18: =SUM(Q9:Q12) -> 0

Sheet StGenis total
B1: Lieu: | C1: StGenis Total
B2: France -> Suisse | J2: Suisse -> France | S2: ="Totaux 2021 " & $C1 -> Totaux 2021 StGenis Total | AG2: ="Totaux 2020 " & $C1 -> Totaux 2020 StGenis Total | AU2: ="Changement depuis 2020 " & $C1 -> Changement depuis 2020 StGenis Total
B3: Vélo traditionel | D3: VAE | F3: Mode Nouveau Electrique | H3: Piéton/ne | J3: Vélo traditionel | L3: VAE | N3: Mode Nouveau Electrique (trotinette, scateboard , …) | P3: Piéton/ne | S3: Hommes | T3: Femmes | U3: %Femmes | V3: VT | W3: VAE | X3: Nouveau | Y3: 2r | Z3: %VAE | AA3: %Nouveau | AB3: Piétons | AC3: >CH | AD3: >FR | AE3: TOT | AG3: Hommes | AH3: Femmes | AI3: %Femmes | AJ3: VT | AK3: VAE | AL3: Nouveau | AM3: 2r | AN3: %VAE | AO3: %Nouveau | AP3: Piétons | AQ3: >CH | AR3: >FR | AS3: TOT | AU3: Hommes | AV3: Femmes | AW3: %Femmes | AX3: VT | AY3: VAE | AZ3: Nouveau | BA3: 2r | BB3: %VAE | BC3: %Nouveau | BD3: Piétons | BE3: >CH | BF3: >FR | BG3: TOT
A4: Heure | B4: H | C4: F | D4: H | E4: F | F4: H | G4: F | H4: H | I4: F | J4: H | K4: F | L4: H | M4: F | N4: H | O4: F | P4: H | Q4: F
A5: 0.29166667 | B5: ='StGenis->Meyrin'!B5+'StGenis->Bourdigny'!B5+'RteEurope->Meyrin'!B5+'StGenis->CERN'!B5 -> 18 | C5: ='StGenis->Meyrin'!C5+'StGenis->Bourdigny'!C5+'RteEurope->Meyrin'!C5+'StGenis->CERN'!C5 -> 4 | D5: ='StGenis->Meyrin'!D5+'StGenis->Bourdigny'!D5+'RteEurope->Meyrin'!D5+'StGenis->CERN'!D5 -> 9 | E5: ='StGenis->Meyrin'!E5+'StGenis->Bourdigny'!E5+'RteEurope->Meyrin'!E5+'StGenis->CERN'!E5 -> 4 | F5: ='StGenis->Meyrin'!F5+'StGenis->Bourdigny'!F5+'RteEurope->Meyrin'!F5+'StGenis->CERN'!F5 -> 1 | G5: ='StGenis->Meyrin'!G5+'StGenis->Bourdigny'!G5+'RteEurope->Meyrin'!G5+'StGenis->CERN'!G5 -> 0 | H5: ='StGenis->Meyrin'!H5+'StGenis->Bourdigny'!H5+'RteEurope->Meyrin'!H5+'StGenis->CERN'!H5 -> 0 | I5: ='StGenis->Meyrin'!I5+'StGenis->Bourdigny'!I5+'RteEurope->Meyrin'!I5+'StGenis->CERN'!I5 -> 0 | ... Q5: ='StGenis->Meyrin'!Q5+'StGenis->Bourdigny'!Q5+'RteEurope->Meyrin'!Q5+'StGenis->CERN'!Q5 -> 0 | S5: =B5+D5+F5+H5+J5+L5+N5+P5 -> 29 | T5: =C5+E5+G5+I5+K5+M5+O5+Q5 -> 9 | U5: =T5/(T5+S5) -> 0.23684211 | V5: =B5+C5+J5+K5 -> 22 | W5: =D5+E5+L5+M5 -> 15 | X5: =F5+G5+N5+O5 -> 1 | Y5: =SUM(V5:X5) -> 38 | Z5: =W5/Y5 -> 0.39473684 | AA5: =X5/Y5 -> 0.026315789 | AB5: =H5+I5+P5+Q5 -> 0 | AC5: =SUM(B5:I5) -> 36 | AD5: =SUM(J5:Q5) -> 2 | AE5: =SUM(B5:Q5) -> 38 | AG5: 21 | AH5: 11 | AI5: 0.34375 | AJ5: 17 | AK5: 12 | AL5: 2 | AM5: 31 | AN5: 0.38709677 | AO5: 0.064516129 | AP5: 1 | AQ5: 31 | AR5: 1 | AS5: 32 | AU5: =(S5/AG5) - 1 -> 0.38095238 | AV5: =(T5/AH5) - 1 -> -0.18181818 | AW5: =(U5/AI5) - 1 -> -0.31100478 | AX5: =(V5/AJ5) - 1 -> 0.29411765 | AY5: =(W5/AK5) - 1 -> 0.25 | AZ5: =(X5/AL5) - 1 -> -0.5 | BA5: =(Y5/AM5) - 1 -> 0.22580645 | BB5: =(Z5/AN5) - 1 -> 0.019736842 | ... BG5: =(AE5/AS5) - 1 -> 0.1875
A6: 0.30208333 | B6: ='StGenis->Meyrin'!B6+'StGenis->Bourdigny'!B6+'RteEurope->Meyrin'!B6+'StGenis->CERN'!B6 -> 20 | C6: ='StGenis->Meyrin'!C6+'StGenis->Bourdigny'!C6+'RteEurope->Meyrin'!C6+'StGenis->CERN'!C6 -> 2 | D6: ='StGenis->Meyrin'!D6+'StGenis->Bourdigny'!D6+'RteEurope->Meyrin'!D6+'StGenis->CERN'!D6 -> 8 | E6: ='StGenis->Meyrin'!E6+'StGenis->Bourdigny'!E6+'RteEurope->Meyrin'!E6+'StGenis->CERN'!E6 -> 7 | F6: ='StGenis->Meyrin'!F6+'StGenis->Bourdigny'!F6+'RteEurope->Meyrin'!F6+'StGenis->CERN'!F6 -> 0 | G6: ='StGenis->Meyrin'!G6+'StGenis->Bourdigny'!G6+'RteEurope->Meyrin'!G6+'StGenis->CERN'!G6 -> 1 | H6: ='StGenis->Meyrin'!H6+'StGenis->Bourdigny'!H6+'RteEurope->Meyrin'!H6+'StGenis->CERN'!H6 -> 0 | I6: ='StGenis->Meyrin'!I6+'StGenis->Bourdigny'!I6+'RteEurope->Meyrin'!I6+'StGenis->CERN'!I6 -> 0 | ... Q6: ='StGenis->Meyrin'!Q6+'StGenis->Bourdigny'!Q6+'RteEurope->Meyrin'!Q6+'StGenis->CERN'!Q6 -> 0 | S6: =B6+D6+F6+H6+J6+L6+N6+P6 -> 29 | T6: =C6+E6+G6+I6+K6+M6+O6+Q6 -> 10 | U6: =T6/(T6+S6) -> 0.25641026 | V6: =B6+C6+J6+K6 -> 22 | W6: =D6+E6+L6+M6 -> 16 | X6: =F6+G6+N6+O6 -> 1 | Y6: =SUM(V6:X6) -> 39 | Z6: =W6/Y6 -> 0.41025641 | AA6: =X6/Y6 -> 0.025641026 | AB6: =H6+I6+P6+Q6 -> 0 | AC6: =SUM(B6:I6) -> 38 | AD6: =SUM(J6:Q6) -> 1 | AE6: =SUM(B6:Q6) -> 39 | AG6: 34 | AH6: 9 | AI6: 0.20930233 | AJ6: 19 | AK6: 18 | AL6: 2 | AM6: 39 | AN6: 0.46153846 | AO6: 0.051282051 | AP6: 4 | AQ6: 40 | AR6: 3 | AS6: 43 | AU6: =(S6/AG6) - 1 -> -0.14705882 | AV6: =(T6/AH6) - 1 -> 0.11111111 | AW6: =(U6/AI6) - 1 -> 0.22507123 | AX6: =(V6/AJ6) - 1 -> 0.15789474 | AY6: =(W6/AK6) - 1 -> -0.11111111 | AZ6: =(X6/AL6) - 1 -> -0.5 | BA6: =(Y6/AM6) - 1 -> 0 | BB6: =(Z6/AN6) - 1 -> -0.11111111 | ... BG6: =(AE6/AS6) - 1 -> -0.093023256
A7: 0.3125 | B7: ='StGenis->Meyrin'!B7+'StGenis->Bourdigny'!B7+'RteEurope->Meyrin'!B7+'StGenis->CERN'!B7 -> 18 | C7: ='StGenis->Meyrin'!C7+'StGenis->Bourdigny'!C7+'RteEurope->Meyrin'!C7+'StGenis->CERN'!C7 -> 2 | D7: ='StGenis->Meyrin'!D7+'StGenis->Bourdigny'!D7+'RteEurope->Meyrin'!D7+'StGenis->CERN'!D7 -> 6 | E7: ='StGenis->Meyrin'!E7+'StGenis->Bourdigny'!E7+'RteEurope->Meyrin'!E7+'StGenis->CERN'!E7 -> 9 | F7: ='StGenis->Meyrin'!F7+'StGenis->Bourdigny'!F7+'RteEurope->Meyrin'!F7+'StGenis->CERN'!F7 -> 3 | G7: ='StGenis->Meyrin'!G7+'StGenis->Bourdigny'!G7+'RteEurope->Meyrin'!G7+'StGenis->CERN'!G7 -> 0 | H7: ='StGenis->Meyrin'!H7+'StGenis->Bourdigny'!H7+'RteEurope->Meyrin'!H7+'StGenis->CERN'!H7 -> 4 | I7: ='StGenis->Meyrin'!I7+'StGenis->Bourdigny'!I7+'RteEurope->Meyrin'!I7+'StGenis->CERN'!I7 -> 0 | ... Q7: ='StGenis->Meyrin'!Q7+'StGenis->Bourdigny'!Q7+'RteEurope->Meyrin'!Q7+'StGenis->CERN'!Q7 -> 0 | S7: =B7+D7+F7+H7+J7+L7+N7+P7 -> 38 | T7: =C7+E7+G7+I7+K7+M7+O7+Q7 -> 12 | U7: =T7/(T7+S7) -> 0.24 | V7: =B7+C7+J7+K7 -> 26 | W7: =D7+E7+L7+M7 -> 17 | X7: =F7+G7+N7+O7 -> 3 | Y7: =SUM(V7:X7) -> 46 | Z7: =W7/Y7 -> 0.36956522 | AA7: =X7/Y7 -> 0.065217391 | AB7: =H7+I7+P7+Q7 -> 4 | AC7: =SUM(B7:I7) -> 42 | AD7: =SUM(J7:Q7) -> 8 | AE7: =SUM(B7:Q7) -> 50 | AG7: 20 | AH7: 9 | AI7: 0.31034483 | AJ7: 17 | AK7: 8 | AL7: 2 | AM7: 27 | AN7: 0.2962963 | AO7: 0.074074074 | AP7: 2 | AQ7: 29 | AR7: 0 | AS7: 29 | AU7: =(S7/AG7) - 1 -> 0.9 | AV7: =(T7/AH7) - 1 -> 0.33333333 | AW7: =(U7/AI7) - 1 -> -0.22666667 | AX7: =(V7/AJ7) - 1 -> 0.52941176 | AY7: =(W7/AK7) - 1 -> 1.125 | AZ7: =(X7/AL7) - 1 -> 0.5 | BA7: =(Y7/AM7) - 1 -> 0.7037037 | BB7: =(Z7/AN7) - 1 -> 0.24728261 | ... BG7: =(AE7/AS7) - 1 -> 0.72413793
A8: 0.32291667 | B8: ='StGenis->Meyrin'!B8+'StGenis->Bourdigny'!B8+'RteEurope->Meyrin'!B8+'StGenis->CERN'!B8 -> 18 | C8: ='StGenis->Meyrin'!C8+'StGenis->Bourdigny'!C8+'RteEurope->Meyrin'!C8+'StGenis->CERN'!C8 -> 4 | D8: ='StGenis->Meyrin'!D8+'StGenis->Bourdigny'!D8+'RteEurope->Meyrin'!D8+'StGenis->CERN'!D8 -> 9 | E8: ='StGenis->Meyrin'!E8+'StGenis->Bourdigny'!E8+'RteEurope->Meyrin'!E8+'StGenis->CERN'!E8 -> 5 | F8: ='StGenis->Meyrin'!F8+'StGenis->Bourdigny'!F8+'RteEurope->Meyrin'!F8+'StGenis->CERN'!F8 -> 0 | G8: ='StGenis->Meyrin'!G8+'StGenis->Bourdigny'!G8+'RteEurope->Meyrin'!G8+'StGenis->CERN'!G8 -> 0 | H8: ='StGenis->Meyrin'!H8+'StGenis->Bourdigny'!H8+'RteEurope->Meyrin'!H8+'StGenis->CERN'!H8 -> 5 | I8: ='StGenis->Meyrin'!I8+'StGenis->Bourdigny'!I8+'RteEurope->Meyrin'!I8+'StGenis->CERN'!I8 -> 1 | ... Q8: ='StGenis->Meyrin'!Q8+'StGenis->Bourdigny'!Q8+'RteEurope->Meyrin'!Q8+'StGenis->CERN'!Q8 -> 0 | S8: =B8+D8+F8+H8+J8+L8+N8+P8 -> 34 | T8: =C8+E8+G8+I8+K8+M8+O8+Q8 -> 11 | U8: =T8/(T8+S8) -> 0.24444444 | V8: =B8+C8+J8+K8 -> 24 | W8: =D8+E8+L8+M8 -> 15 | X8: =F8+G8+N8+O8 -> 0 | Y8: =SUM(V8:X8) -> 39 | Z8: =W8/Y8 -> 0.38461538 | AA8: =X8/Y8 -> 0 | AB8: =H8+I8+P8+Q8 -> 6 | AC8: =SUM(B8:I8) -> 42 | AD8: =SUM(J8:Q8) -> 3 | AE8: =SUM(B8:Q8) -> 45 | AG8: 12 | AH8: 13 | AI8: 0.52 | AJ8: 11 | AK8: 11 | AL8: 3 | AM8: 25 | AN8: 0.44 | AO8: 0.12 | AP8: 0 | AQ8: 25 | AR8: 0 | AS8: 25 | AU8: =(S8/AG8) - 1 -> 1.8333333 | AV8: =(T8/AH8) - 1 -> -0.15384615 | AW8: =(U8/AI8) - 1 -> -0.52991453 | AX8: =(V8/AJ8) - 1 -> 1.1818182 | AY8: =(W8/AK8) - 1 -> 0.36363636 | AZ8: =(X8/AL8) - 1 -> -1 | BA8: =(Y8/AM8) - 1 -> 0.56 | BB8: =(Z8/AN8) - 1 -> -0.12587413 | ... BG8: =(AE8/AS8) - 1 -> 0.8
A9: 0.33333333 | B9: ='StGenis->Meyrin'!B9+'StGenis->Bourdigny'!B9+'RteEurope->Meyrin'!B9+'StGenis->CERN'!B9 -> 21 | C9: ='StGenis->Meyrin'!C9+'StGenis->Bourdigny'!C9+'RteEurope->Meyrin'!C9+'StGenis->CERN'!C9 -> 4 | D9: ='StGenis->Meyrin'!D9+'StGenis->Bourdigny'!D9+'RteEurope->Meyrin'!D9+'StGenis->CERN'!D9 -> 6 | E9: ='StGenis->Meyrin'!E9+'StGenis->Bourdigny'!E9+'RteEurope->Meyrin'!E9+'StGenis->CERN'!E9 -> 3 | F9: ='StGenis->Meyrin'!F9+'StGenis->Bourdigny'!F9+'RteEurope->Meyrin'!F9+'StGenis->CERN'!F9 -> 1 | G9: ='StGenis->Meyrin'!G9+'StGenis->Bourdigny'!G9+'RteEurope->Meyrin'!G9+'StGenis->CERN'!G9 -> 1 | H9: ='StGenis->Meyrin'!H9+'StGenis->Bourdigny'!H9+'RteEurope->Meyrin'!H9+'StGenis->CERN'!H9 -> 6 | I9: ='StGenis->Meyrin'!I9+'StGenis->Bourdigny'!I9+'RteEurope->Meyrin'!I9+'StGenis->CERN'!I9 -> 1 | ... Q9: ='StGenis->Meyrin'!Q9+'StGenis->Bourdigny'!Q9+'RteEurope->Meyrin'!Q9+'StGenis->CERN'!Q9 -> 0 | S9: =B9+D9+F9+H9+J9+L9+N9+P9 -> 35 | T9: =C9+E9+G9+I9+K9+M9+O9+Q9 -> 9 | U9: =T9/(T9+S9) -> 0.20454545 | V9: =B9+C9+J9+K9 -> 25 | W9: =D9+E9+L9+M9 -> 10 | X9: =F9+G9+N9+O9 -> 2 | Y9: =SUM(V9:X9) -> 37 | Z9: =W9/Y9 -> 0.27027027 | AA9: =X9/Y9 -> 0.054054054 | AB9: =H9+I9+P9+Q9 -> 7 | AC9: =SUM(B9:I9) -> 43 | AD9: =SUM(J9:Q9) -> 1 | AE9: =SUM(B9:Q9) -> 44 | AG9: 21 | AH9: 9 | AI9: 0.3 | AJ9: 19 | AK9: 3 | AL9: 0 | AM9: 22 | AN9: 0.13636364 | AO9: 0 | AP9: 8 | AQ9: 28 | AR9: 2 | AS9: 30 | AU9: =(S9/AG9) - 1 -> 0.66666667 | AV9: =(T9/AH9) - 1 -> 0 | AW9: =(U9/AI9) - 1 -> -0.31818182 | AX9: =(V9/AJ9) - 1 -> 0.31578947 | AY9: =(W9/AK9) - 1 -> 2.3333333 | AZ9: =(X9/AL9) - 1 -> #DIV/0! | BA9: =(Y9/AM9) - 1 -> 0.68181818 | BB9: =(Z9/AN9) - 1 -> 0.98198198 | ... BG9: =(AE9/AS9) - 1 -> 0.46666667
A10: 0.34375 | B10: ='StGenis->Meyrin'!B10+'StGenis->Bourdigny'!B10+'RteEurope->Meyrin'!B10+'StGenis->CERN'!B10 -> 24 | C10: ='StGenis->Meyrin'!C10+'StGenis->Bourdigny'!C10+'RteEurope->Meyrin'!C10+'StGenis->CERN'!C10 -> 7 | D10: ='StGenis->Meyrin'!D10+'StGenis->Bourdigny'!D10+'RteEurope->Meyrin'!D10+'StGenis->CERN'!D10 -> 10 | E10: ='StGenis->Meyrin'!E10+'StGenis->Bourdigny'!E10+'RteEurope->Meyrin'!E10+'StGenis->CERN'!E10 -> 6 | F10: ='StGenis->Meyrin'!F10+'StGenis->Bourdigny'!F10+'RteEurope->Meyrin'!F10+'StGenis->CERN'!F10 -> 2 | G10: ='StGenis->Meyrin'!G10+'StGenis->Bourdigny'!G10+'RteEurope->Meyrin'!G10+'StGenis->CERN'!G10 -> 0 | H10: ='StGenis->Meyrin'!H10+'StGenis->Bourdigny'!H10+'RteEurope->Meyrin'!H10+'StGenis->CERN'!H10 -> 18 | I10: ='StGenis->Meyrin'!I10+'StGenis->Bourdigny'!I10+'RteEurope->Meyrin'!I10+'StGenis->CERN'!I10 -> 1 | ... Q10: ='StGenis->Meyrin'!Q10+'StGenis->Bourdigny'!Q10+'RteEurope->Meyrin'!Q10+'StGenis->CERN'!Q10 -> 0 | S10: =B10+D10+F10+H10+J10+L10+N10+P10 -> 57 | T10: =C10+E10+G10+I10+K10+M10+O10+Q10 -> 14 | U10: =T10/(T10+S10) -> 0.1971831 | V10: =B10+C10+J10+K10 -> 34 | W10: =D10+E10+L10+M10 -> 16 | X10: =F10+G10+N10+O10 -> 2 | Y10: =SUM(V10:X10) -> 52 | Z10: =W10/Y10 -> 0.30769231 | AA10: =X10/Y10 -> 0.038461538 | AB10: =H10+I10+P10+Q10 -> 19 | AC10: =SUM(B10:I10) -> 68 | AD10: =SUM(J10:Q10) -> 3 | AE10: =SUM(B10:Q10) -> 71 | AG10: 22 | AH10: 10 | AI10: 0.3125 | AJ10: 16 | AK10: 9 | AL10: 3 | AM10: 28 | AN10: 0.32142857 | AO10: 0.10714286 | AP10: 4 | AQ10: 30 | AR10: 2 | AS10: 32 | AU10: =(S10/AG10) - 1 -> 1.5909091 | AV10: =(T10/AH10) - 1 -> 0.4 | AW10: =(U10/AI10) - 1 -> -0.36901408 | AX10: =(V10/AJ10) - 1 -> 1.125 | AY10: =(W10/AK10) - 1 -> 0.77777778 | AZ10: =(X10/AL10) - 1 -> -0.33333333 | BA10: =(Y10/AM10) - 1 -> 0.85714286 | BB10: =(Z10/AN10) - 1 -> -0.042735043 | ... BG10: =(AE10/AS10) - 1 -> 1.21875
A11: 0.35416667 | B11: ='StGenis->Meyrin'!B11+'StGenis->Bourdigny'!B11+'RteEurope->Meyrin'!B11+'StGenis->CERN'!B11 -> 29 | C11: ='StGenis->Meyrin'!C11+'StGenis->Bourdigny'!C11+'RteEurope->Meyrin'!C11+'StGenis->CERN'!C11 -> 6 | D11: ='StGenis->Meyrin'!D11+'StGenis->Bourdigny'!D11+'RteEurope->Meyrin'!D11+'StGenis->CERN'!D11 -> 8 | E11: ='StGenis->Meyrin'!E11+'StGenis->Bourdigny'!E11+'RteEurope->Meyrin'!E11+'StGenis->CERN'!E11 -> 4 | F11: ='StGenis->Meyrin'!F11+'StGenis->Bourdigny'!F11+'RteEurope->Meyrin'!F11+'StGenis->CERN'!F11 -> 1 | G11: ='StGenis->Meyrin'!G11+'StGenis->Bourdigny'!G11+'RteEurope->Meyrin'!G11+'StGenis->CERN'!G11 -> 1 | H11: ='StGenis->Meyrin'!H11+'StGenis->Bourdigny'!H11+'RteEurope->Meyrin'!H11+'StGenis->CERN'!H11 -> 5 | I11: ='StGenis->Meyrin'!I11+'StGenis->Bourdigny'!I11+'RteEurope->Meyrin'!I11+'StGenis->CERN'!I11 -> 2 | ... Q11: ='StGenis->Meyrin'!Q11+'StGenis->Bourdigny'!Q11+'RteEurope->Meyrin'!Q11+'StGenis->CERN'!Q11 -> 0 | S11: =B11+D11+F11+H11+J11+L11+N11+P11 -> 45 | T11: =C11+E11+G11+I11+K11+M11+O11+Q11 -> 13 | U11: =T11/(T11+S11) -> 0.22413793 | V11: =B11+C11+J11+K11 -> 37 | W11: =D11+E11+L11+M11 -> 12 | X11: =F11+G11+N11+O11 -> 2 | Y11: =SUM(V11:X11) -> 51 | Z11: =W11/Y11 -> 0.23529412 | AA11: =X11/Y11 -> 0.039215686 | AB11: =H11+I11+P11+Q11 -> 7 | AC11: =SUM(B11:I11) -> 56 | AD11: =SUM(J11:Q11) -> 2 | AE11: =SUM(B11:Q11) -> 58 | AG11: 25 | AH11: 9 | AI11: 0.26470588 | AJ11: 17 | AK11: 1 | AL11: 10 | AM11: 28 | AN11: 0.035714286 | AO11: 0.35714286 | AP11: 6 | AQ11: 33 | AR11: 1 | AS11: 34 | AU11: =(S11/AG11) - 1 -> 0.8 | AV11: =(T11/AH11) - 1 -> 0.44444444 | AW11: =(U11/AI11) - 1 -> -0.1532567 | AX11: =(V11/AJ11) - 1 -> 1.1764706 | AY11: =(W11/AK11) - 1 -> 11 | AZ11: =(X11/AL11) - 1 -> -0.8 | BA11: =(Y11/AM11) - 1 -> 0.82142857 | BB11: =(Z11/AN11) - 1 -> 5.5882353 | ... BG11: =(AE11/AS11) - 1 -> 0.70588235
A12: 0.36458333 | B12: ='StGenis->Meyrin'!B12+'StGenis->Bourdigny'!B12+'RteEurope->Meyrin'!B12+'StGenis->CERN'!B12 -> 27 | C12: ='StGenis->Meyrin'!C12+'StGenis->Bourdigny'!C12+'RteEurope->Meyrin'!C12+'StGenis->CERN'!C12 -> 7 | D12: ='StGenis->Meyrin'!D12+'StGenis->Bourdigny'!D12+'RteEurope->Meyrin'!D12+'StGenis->CERN'!D12 -> 6 | E12: ='StGenis->Meyrin'!E12+'StGenis->Bourdigny'!E12+'RteEurope->Meyrin'!E12+'StGenis->CERN'!E12 -> 2 | F12: ='StGenis->Meyrin'!F12+'StGenis->Bourdigny'!F12+'RteEurope->Meyrin'!F12+'StGenis->CERN'!F12 -> 0 | G12: ='StGenis->Meyrin'!G12+'StGenis->Bourdigny'!G12+'RteEurope->Meyrin'!G12+'StGenis->CERN'!G12 -> 0 | H12: ='StGenis->Meyrin'!H12+'StGenis->Bourdigny'!H12+'RteEurope->Meyrin'!H12+'StGenis->CERN'!H12 -> 4 | I12: ='StGenis->Meyrin'!I12+'StGenis->Bourdigny'!I12+'RteEurope->Meyrin'!I12+'StGenis->CERN'!I12 -> 3 | ... Q12: ='StGenis->Meyrin'!Q12+'StGenis->Bourdigny'!Q12+'RteEurope->Meyrin'!Q12+'StGenis->CERN'!Q12 -> 0 | S12: =B12+D12+F12+H12+J12+L12+N12+P12 -> 39 | T12: =C12+E12+G12+I12+K12+M12+O12+Q12 -> 12 | U12: =T12/(T12+S12) -> 0.23529412 | V12: =B12+C12+J12+K12 -> 36 | W12: =D12+E12+L12+M12 -> 8 | X12: =F12+G12+N12+O12 -> 0 | Y12: =SUM(V12:X12) -> 44 | Z12: =W12/Y12 -> 0.18181818 | AA12: =X12/Y12 -> 0 | AB12: =H12+I12+P12+Q12 -> 7 | AC12: =SUM(B12:I12) -> 49 | AD12: =SUM(J12:Q12) -> 2 | AE12: =SUM(B12:Q12) -> 51 | AG12: 16 | AH12: 9 | AI12: 0.36 | AJ12: 12 | AK12: 0 | AL12: 5 | AM12: 17 | AN12: 0 | AO12: 0.29411765 | AP12: 8 | AQ12: 25 | AR12: 0 | AS12: 25 | AU12: =(S12/AG12) - 1 -> 1.4375 | AV12: =(T12/AH12) - 1 -> 0.33333333 | AW12: =(U12/AI12) - 1 -> -0.34640523 | AX12: =(V12/AJ12) - 1 -> 2 | AY12: =(W12/AK12) - 1 -> #DIV/0! | AZ12: =(X12/AL12) - 1 -> -1 | BA12: =(Y12/AM12) - 1 -> 1.5882353 | BB12: =(Z12/AN12) - 1 -> #DIV/0! | ... BG12: =(AE12/AS12) - 1 -> 1.04
B13: ='StGenis->Meyrin'!B13+'StGenis->Bourdigny'!B13+'RteEurope->Meyrin'!B13+'StGenis->CERN'!B13 -> 0 | C13: ='StGenis->Meyrin'!C13+'StGenis->Bourdigny'!C13+'RteEurope->Meyrin'!C13+'StGenis->CERN'!C13 -> 0 | D13: ='StGenis->Meyrin'!D13+'StGenis->Bourdigny'!D13+'RteEurope->Meyrin'!D13+'StGenis->CERN'!D13 -> 0 | E13: ='StGenis->Meyrin'!E13+'StGenis->Bourdigny'!E13+'RteEurope->Meyrin'!E13+'StGenis->CERN'!E13 -> 0 | F13: ='StGenis->Meyrin'!F13+'StGenis->Bourdigny'!F13+'RteEurope->Meyrin'!F13+'StGenis->CERN'!F13 -> 0 | G13: ='StGenis->Meyrin'!G13+'StGenis->Bourdigny'!G13+'RteEurope->Meyrin'!G13+'StGenis->CERN'!G13 -> 0 | H13: ='StGenis->Meyrin'!H13+'StGenis->Bourdigny'!H13+'RteEurope->Meyrin'!H13+'StGenis->CERN'!H13 -> 0 | I13: ='StGenis->Meyrin'!I13+'StGenis->Bourdigny'!I13+'RteEurope->Meyrin'!I13+'StGenis->CERN'!I13 -> 0 | ... Q13: ='StGenis->Meyrin'!Q13+'StGenis->Bourdigny'!Q13+'RteEurope->Meyrin'!Q13+'StGenis->CERN'!Q13 -> 0
