Workbook

Sheet Evolution 2
A3: Evolution Mobilité douce (piétons+cyclistes)
C6: 2014 | D6: 2015 | E6: 2016 | F6: 2017 | G6: 2018 | H6: 2019 | I6: 2020 | J6: 2021 | K6: 2022 | L6: 2023 | M6: 2024 | N6: 2025
B7: Mategnin | C7: 94 | D7: 247 | E7: 237 | F7: 370 | G7: 313 | H7: 387 | I7: 200 | J7: 275 | K7: 357 | L7: 526 | M7: ='Mategnin Total'!CE14 -> 508 | N7: ='Mategnin Total'!AJ14 -> 667
B8: Ferney | C8: 231 | D8: 211 | E8: 237 | F8: 311 | G8: 302 | H8: 350 | I8: 160 | J8: 234 | K8: 291 | L8: 398 | M8: ='Ferney->Genève'!CE14 -> 414 | N8: ='Ferney->Genève'!AJ14 -> 436
B9: StGenis | C9: 354 | D9: 536 | E9: 492 | F9: 710 | G9: 635 | H9: 472 | I9: 250 | J9: 396 | K9: 542 | L9: 669 | M9: ='StGenis total'!CE14 -> 719 | N9: ='StGenis total'!AJ14 -> 716 | AB9: Traffic voiture | AC9: Moy. Journalière annuelle
B10: TOTAL | C10: 679 | D10: 994 | E10: 966 | F10: 1391 | G10: 1250 | H10: 1209 | I10: 638 | J10: 1030 | K10: 1190 | L10: =SUM(L7:L9) -> 1593 | M10: =SUM(M7:M9) -> 1641 | N10: =SUM(N7:N9) -> 1819 | AB10: Crassier | AC10: 7165
D11: =(D10/C10)-1 -> 0.46391753 | E11: =(E10/D10)-1 -> -0.028169014 | F11: =(F10/E10)-1 -> 0.43995859 | G11: =(G10/F10)-1 -> -0.10136592 | H11: =(H10/G10)-1 -> -0.0328 | I11: =(I10/H10)-1 -> -0.47229115 | J11: =(J10/I10)-1 -> 0.61442006 | K11: =(K10/J10)-1 -> 0.15533981 | ... N11: =(N10/M10)-1 -> 0.10847044 | AB11: Divonne | AC11: 13740
AB12: Sauverny | AC12: 4339
B13: Depuis 2014 | N13: =(N10/C10)-1 -> 1.6789396 | AB13: Versonnex | AC13: 4626
AB14: Vireloup | AC14: 8131
AB15: Ferney | AC15: 13786
AB16: Meyrin | AC16: 24947
AB17: St Jean | AC17: 1659
A18: Evolution Piétons/Cyclistes | AB18: Challex | AC18: 1601
AB19: Collonge | AC19: 1724
AB20: Total | AC20: =SUM(AC10:AC19) -> 81718
AC21: =AC20/2 -> 40859
C22: 2014 | D22: 2015 | E22: 2016 | F22: 2017 | G22: 2018 | H22: 2019 | I22: 2020 | J22: 2021 | K22: 2022 | L22: 2023 | M22: 2024 | N22: 2025 | AB22: Jours ouvrés one way | AC22: =AC20*0.8/2 -> 32687.2
B23: Cyclistes | C23: 654 | D23: 769 | E23: 781 | F23: 1119 | G23: 1048 | H23: 1049 | I23: 561 | J23: 929 | K23: 1318 | L23: 1884 | M23: ='APiCy total'!BS24 -> 1886 | N23: ='APiCy total'!AD14 -> 2005
B24: Piétons | C24: 143 | D24: 225 | E24: 185 | F24: 272 | G24: 202 | H24: 160 | I24: 77 | J24: 101 | K24: 173 | L24: 186 | M24: ='APiCy total'!CC24 -> 223 | N24: ='APiCy total'!AG14 -> 308
B25: TOTAL | C25: 797 | D25: 994 | E25: 966 | F25: 1391 | G25: 1250 | H25: 1209 | I25: 638 | J25: 1030 | K25: 1491 | L25: 2070 | M25: =SUM(M23:M24) -> 2109 | N25: ='APiCy total'!AJ14 -> 2313
A36: EvolutionHommes/Femmes
D38: Année | E38: 2016 | F38: 2017 | G38: 2018 | H38: 2019 | I38: 2020 | J38: 2021 | K38: 2022 | L38: 2023 | M38: 2024 | N38: 2025
D39: %femme | E39: 0.27150259 | F39: 0.27606039 | G39: 0.2456 | H39: 0.30024814 | I39: 0.35109718 | J39: 0.2936803 | K39: 0.32327297 | L39: 0.33285024 | M39: ='APiCy total'!BW24 -> 0.33775186 | N39: ='APiCy total'!Y14 -> 0.36093609
D40: Hommes | E40: 703 | F40: 1007 | G40: 943 | H40: 846 | I40: 414 | J40: 760 | K40: 1009 | L40: 1381 | M40: ='APiCy total'!BS14 -> 1384 | N40: ='APiCy total'!W14 -> 1420
D41: Femmes | E41: 262 | F41: 384 | G41: 307 | H41: 363 | I41: 224 | J41: 316 | K41: 482 | L41: 689 | M41: ='APiCy total'!BT14 -> 725 | N41: ='APiCy total'!X14 -> 802
D42: Total | E42: 965 | F42: 1391 | G42: 1250 | H42: 1209 | I42: 638 | J42: 1076 | K42: 1491 | L42: 2070 | M42: =SUM(M40:M41) -> 2109 | N42: ='APiCy total'!AJ14 -> 2313
C52: 0.29166667 | D52: 0.30208333 | E52: 0.3125 | F52: 0.32291667 | G52: 0.33333333 | H52: 0.34375 | I52: 0.35416667 | J52: 0.36458333
B53: Pdg Centre | C53: ='PdG Centre Total'!AJ$5 -> 119 | D53: ='PdG Centre Total'!AJ$6 -> 179 | E53: ='PdG Centre Total'!AJ$7 -> 179 | F53: ='PdG Centre Total'!AJ$8 -> 259 | G53: ='PdG Centre Total'!AJ$9 -> 266 | H53: ='PdG Centre Total'!AJ$10 -> 290 | I53: ='PdG Centre Total'!AJ$11 -> 277 | J53: ='PdG Centre Total'!AJ$12 -> 250
B54: PdG Nord | C54: ='PdG Nord Total'!AJ$5 -> 52 | D54: ='PdG Nord Total'!AJ$6 -> 49 | E54: ='PdG Nord Total'!AJ$7 -> 77 | F54: ='PdG Nord Total'!AJ$8 -> 73 | G54: ='PdG Nord Total'!AJ$9 -> 73 | H54: ='PdG Nord Total'!AJ$10 -> 55 | I54: ='PdG Nord Total'!AJ$11 -> 44 | J54: ='PdG Nord Total'!AJ$12 -> 33
B55: Total
C58: =C52 -> 0.29166667 | D58: =D52 -> 0.30208333 | E58: =E52 -> 0.3125 | F58: =F52 -> 0.32291667 | G58: =G52 -> 0.33333333 | H58: =H52 -> 0.34375 | I58: =I52 -> 0.35416667 | J58: =J52 -> 0.36458333
B59: PdG Nord | C59: =C53/SUM($C53:$J53) -> 0.065420561 | D59: =D53/SUM($C53:$J53) -> 0.098405717 | E59: =E53/SUM($C53:$J53) -> 0.098405717 | F59: =F53/SUM($C53:$J53) -> 0.14238593 | G59: =G53/SUM($C53:$J53) -> 0.14623419 | H59: =H53/SUM($C53:$J53) -> 0.15942826 | I59: =I53/SUM($C53:$J53) -> 0.15228147 | J59: =J53/SUM($C53:$J53) -> 0.13743815
B60: Pdg Centre | C60: =C54/SUM($C54:$J54) -> 0.11403509 | D60: =D54/SUM($C54:$J54) -> 0.10745614 | E60: =E54/SUM($C54:$J54) -> 0.16885965 | F60: =F54/SUM($C54:$J54) -> 0.16008772 | G60: =G54/SUM($C54:$J54) -> 0.16008772 | H60: =H54/SUM($C54:$J54) -> 0.12061404 | I60: =I54/SUM($C54:$J54) -> 0.096491228 | J60: =J54/SUM($C54:$J54) -> 0.072368421
A65: Evolution par mode
I68: 2020 | J68: 2021 | K68: 2022 | L68: 2023 | M68: 2024 | N68: 2025
H69: Vélo traditionels | I69: ='APiCy total'!HU14 -> 344 | J69: ='APiCy total'!HG14 -> 582 | K69: ='APiCy total'!FL14 -> 752 | L69: ='APiCy total'!DQ14 -> 1017 | M69: ='APiCy total'!BV14 -> 945 | N69: ='APiCy total'!Z14 -> 891
H70: VAE | I70: ='APiCy total'!HV14 -> 175 | J70: ='APiCy total'!HH14 -> 337 | K70: ='APiCy total'!FM14 -> 498 | L70: ='APiCy total'!DR14 -> 752 | M70: ='APiCy total'!BW14 -> 809 | N70: ='APiCy total'!AA14 -> 986
H71: EDPM (trotinette) | I71: ='APiCy total'!HW14 -> 42 | J71: ='APiCy total'!HI14 -> 46 | K71: ='APiCy total'!FN14 -> 68 | L71: ='APiCy total'!DS14 -> 115 | M71: ='APiCy total'!BX14 -> 132 | N71: ='APiCy total'!AC14 -> 128
H72: TOTAL 2roues | I72: =SUM(I69:I71) -> 561 | J72: =SUM(J69:J71) -> 965 | K72: =SUM(K69:K71) -> 1318 | L72: =SUM(L69:L71) -> 1884 | M72: =SUM(M69:M71) -> 1886 | N72: ='APiCy total'!AJ14 -> 2313
...

Sheet Resume
B1: DONNEES 2024 | P1: CHANGEMENT
B2: Hommes | C2: Femmes | D2: %Femmes | E2: VT | F2: VAE | G2: Nouveau | H2: 2r | I2: %VAE | J2: %Nouveau | K2: Piétons | L2: >FR | M2: >CH | N2: TOT | P2: Hommes | Q2: Femmes | R2: %Femmes | S2: VT | T2: VAE | U2: Nouveau | V2: 2r | W2: %VAE | X2: %Nouveau | Y2: Piétons | Z2: >CH | AA2: >FR | AB2: TOT
A3: Ferney->Genève | B3: {=INDIRECT( "'" & $A3 & "'"& "!" & B$33)} -> 254 | C3: {=INDIRECT( "'" & $A3 & "'"& "!" & C$33)} -> 165 | D3: {=INDIRECT( "'" & $A3 & "'"& "!" & D$33)} -> 0.39379475 | E3: {=INDIRECT( "'" & $A3 & "'"& "!" & E$33)} -> 153 | F3: {=INDIRECT( "'" & $A3 & "'"& "!" & F$33)} -> 254 | G3: {=INDIRECT( "'" & $A3 & "'"& "!" & G$33)} -> 23 | H3: {=INDIRECT( "'" & $A3 & "'"& "!" & H$33)} -> 430 | I3: {=INDIRECT( "'" & $A3 & "'"& "!" & I$33)} -> 0.62407862 | ... N3: {=INDIRECT( "'" & $A3 & "'"& "!" & N$33)} -> 436 | P3: {=INDIRECT( "'" & $A3 & "'"& "!" & P$33)} -> 0.04526749 | Q3: {=INDIRECT( "'" & $A3 & "'"& "!" & Q$33)} -> -0.035087719 | R3: {=INDIRECT( "'" & $A3 & "'"& "!" & R$33)} -> -0.046602186 | S3: {=INDIRECT( "'" & $A3 & "'"& "!" & S$33)} -> -0.083832335 | T3: {=INDIRECT( "'" & $A3 & "'"& "!" & T$33)} -> 0.25123153 | U3: {=INDIRECT( "'" & $A3 & "'"& "!" & U$33)} -> -0.20689655 | V3: {=INDIRECT( "'" & $A3 & "'"& "!" & V$33)} -> 0.077694236 | W3: {=INDIRECT( "'" & $A3 & "'"& "!" & W$33)} -> 0.13748321 | ... AB3: {=INDIRECT( "'" & $A3 & "'"& "!" & AB$33)} -> 0.053140097
A5: StGenis->Meyrin | B5: {=INDIRECT( "'" & $A5 & "'"& "!" & B$33)} -> 256 | C5: {=INDIRECT( "'" & $A5 & "'"& "!" & C$33)} -> 116 | D5: {=INDIRECT( "'" & $A5 & "'"& "!" & D$33)} -> 0.31182796 | E5: {=INDIRECT( "'" & $A5 & "'"& "!" & E$33)} -> 159 | F5: {=INDIRECT( "'" & $A5 & "'"& "!" & F$33)} -> 171 | G5: {=INDIRECT( "'" & $A5 & "'"& "!" & G$33)} -> 31 | H5: {=INDIRECT( "'" & $A5 & "'"& "!" & H$33)} -> 361 | I5: {=INDIRECT( "'" & $A5 & "'"& "!" & I$33)} -> 0.51818182 | ... N5: {=INDIRECT( "'" & $A5 & "'"& "!" & N$33)} -> 388 | P5: {=INDIRECT( "'" & $A5 & "'"& "!" & P$33)} -> -0.14381271 | Q5: {=INDIRECT( "'" & $A5 & "'"& "!" & Q$33)} -> -0.21088435 | R5: {=INDIRECT( "'" & $A5 & "'"& "!" & R$33)} -> -0.053909736 | S5: {=INDIRECT( "'" & $A5 & "'"& "!" & S$33)} -> -0.171875 | T5: {=INDIRECT( "'" & $A5 & "'"& "!" & T$33)} -> -0.070652174 | U5: {=INDIRECT( "'" & $A5 & "'"& "!" & U$33)} -> -0.24390244 | V5: {=INDIRECT( "'" & $A5 & "'"& "!" & V$33)} -> -0.13429257 | W5: {=INDIRECT( "'" & $A5 & "'"& "!" & W$33)} -> 0.058893281 | ... AB5: {=INDIRECT( "'" & $A5 & "'"& "!" & AB$33)} -> -0.13004484
A6: StGenis->Bourdigny | B6: {=INDIRECT( "'" & $A6 & "'"& "!" & B$33)} -> 15 | C6: {=INDIRECT( "'" & $A6 & "'"& "!" & C$33)} -> 9 | D6: {=INDIRECT( "'" & $A6 & "'"& "!" & D$33)} -> 0.375 | E6: {=INDIRECT( "'" & $A6 & "'"& "!" & E$33)} -> 13 | F6: {=INDIRECT( "'" & $A6 & "'"& "!" & F$33)} -> 13 | G6: {=INDIRECT( "'" & $A6 & "'"& "!" & G$33)} -> 0 | H6: {=INDIRECT( "'" & $A6 & "'"& "!" & H$33)} -> 26 | I6: {=INDIRECT( "'" & $A6 & "'"& "!" & I$33)} -> 0.5 | ... N6: {=INDIRECT( "'" & $A6 & "'"& "!" & N$33)} -> 26 | P6: {=INDIRECT( "'" & $A6 & "'"& "!" & P$33)} -> -0.69387755 | Q6: {=INDIRECT( "'" & $A6 & "'"& "!" & Q$33)} -> #DIV/0! | R6: {=INDIRECT( "'" & $A6 & "'"& "!" & R$33)} -> #DIV/0! | S6: {=INDIRECT( "'" & $A6 & "'"& "!" & S$33)} -> -0.72340426 | T6: {=INDIRECT( "'" & $A6 & "'"& "!" & T$33)} -> #DIV/0! | U6: {=INDIRECT( "'" & $A6 & "'"& "!" & U$33)} -> -1 | V6: {=INDIRECT( "'" & $A6 & "'"& "!" & V$33)} -> -0.45833333 | W6: {=INDIRECT( "'" & $A6 & "'"& "!" & W$33)} -> #DIV/0! | ... AB6: {=INDIRECT( "'" & $A6 & "'"& "!" & AB$33)} -> -0.46938776
A7: StGenis->CERN | B7: {=INDIRECT( "'" & $A7 & "'"& "!" & B$33)} -> 215 | C7: {=INDIRECT( "'" & $A7 & "'"& "!" & C$33)} -> 77 | D7: {=INDIRECT( "'" & $A7 & "'"& "!" & D$33)} -> 0.26369863 | E7: {=INDIRECT( "'" & $A7 & "'"& "!" & E$33)} -> 139 | F7: {=INDIRECT( "'" & $A7 & "'"& "!" & F$33)} -> 91 | G7: {=INDIRECT( "'" & $A7 & "'"& "!" & G$33)} -> 9 | H7: {=INDIRECT( "'" & $A7 & "'"& "!" & H$33)} -> 239 | I7: {=INDIRECT( "'" & $A7 & "'"& "!" & I$33)} -> 0.39565217 | ... N7: {=INDIRECT( "'" & $A7 & "'"& "!" & N$33)} -> 302 | P7: {=INDIRECT( "'" & $A7 & "'"& "!" & P$33)} -> 0.3190184 | Q7: {=INDIRECT( "'" & $A7 & "'"& "!" & Q$33)} -> 0.26229508 | R7: {=INDIRECT( "'" & $A7 & "'"& "!" & R$33)} -> -0.031664047 | S7: {=INDIRECT( "'" & $A7 & "'"& "!" & S$33)} -> 0.069230769 | T7: {=INDIRECT( "'" & $A7 & "'"& "!" & T$33)} -> 2.25 | U7: {=INDIRECT( "'" & $A7 & "'"& "!" & U$33)} -> 0.28571429 | V7: {=INDIRECT( "'" & $A7 & "'"& "!" & V$33)} -> 0.44848485 | W7: {=INDIRECT( "'" & $A7 & "'"& "!" & W$33)} -> 1.2326087 | ... AB7: {=INDIRECT( "'" & $A7 & "'"& "!" & AB$33)} -> 0.34821429
A8: RteEurope->Meyrin
A9: StGenis Total | B9: =SUM(B5:B8) -> 486 | C9: =SUM(C5:C8) -> 202 | D9: =C9/(B9+C9) -> 0.29360465 | E9: =SUM(E5:E8) -> 311 | F9: =SUM(F5:F8) -> 275 | G9: =SUM(G5:G8) -> 40 | H9: =SUM(H5:H8) -> 626 | I9: =F9/H9 -> 0.43929712 | J9: =G9/H9 -> 0.063897764 | K9: =SUM(K5:K8) -> 90 | L9: =SUM(L5:L8) -> 18 | M9: =SUM(M5:M8) -> 698 | N9: =SUM(N5:N8) -> 716 | P9: {=INDIRECT( "'" & $A9 & "'"& "!" & P$33)} -> -0.048923679 | Q9: {=INDIRECT( "'" & $A9 & "'"& "!" & Q$33)} -> -0.028846154 | R9: {=INDIRECT( "'" & $A9 & "'"& "!" & R$33)} -> 0.014912232 | S9: {=INDIRECT( "'" & $A9 & "'"& "!" & S$33)} -> -0.15718157 | T9: {=INDIRECT( "'" & $A9 & "'"& "!" & T$33)} -> 0.29716981 | U9: {=INDIRECT( "'" & $A9 & "'"& "!" & U$33)} -> -0.18367347 | V9: {=INDIRECT( "'" & $A9 & "'"& "!" & V$33)} -> -0.0063492063 | W9: {=INDIRECT( "'" & $A9 & "'"& "!" & W$33)} -> 0.28610181 | ... AB9: {=INDIRECT( "'" & $A9 & "'"& "!" & AB$33)} -> -0.0041724618
A11: MategninAnneaux | B11: {=INDIRECT( "'" & $A11 & "'"& "!" & B$33)} -> 222 | C11: {=INDIRECT( "'" & $A11 & "'"& "!" & C$33)} -> 118 | D11: {=INDIRECT( "'" & $A11 & "'"& "!" & D$33)} -> 0.34705882 | E11: {=INDIRECT( "'" & $A11 & "'"& "!" & E$33)} -> 151 | F11: {=INDIRECT( "'" & $A11 & "'"& "!" & F$33)} -> 153 | G11: {=INDIRECT( "'" & $A11 & "'"& "!" & G$33)} -> 34 | H11: {=INDIRECT( "'" & $A11 & "'"& "!" & H$33)} -> 338 | I11: {=INDIRECT( "'" & $A11 & "'"& "!" & I$33)} -> 0.50328947 | ... N11: {=INDIRECT( "'" & $A11 & "'"& "!" & N$33)} -> 354 | P11: {=INDIRECT( "'" & $A11 & "'"& "!" & P$33)} -> 0.0090909091 | Q11: {=INDIRECT( "'" & $A11 & "'"& "!" & Q$33)} -> 0.14563107 | R11: {=INDIRECT( "'" & $A11 & "'"& "!" & R$33)} -> 0.088349515 | S11: {=INDIRECT( "'" & $A11 & "'"& "!" & S$33)} -> 0.078571429 | T11: {=INDIRECT( "'" & $A11 & "'"& "!" & T$33)} -> 0.125 | U11: {=INDIRECT( "'" & $A11 & "'"& "!" & U$33)} -> 0.47826087 | V11: {=INDIRECT( "'" & $A11 & "'"& "!" & V$33)} -> 0.13043478 | W11: {=INDIRECT( "'" & $A11 & "'"& "!" & W$33)} -> 0.021381579 | ... AB11: {=INDIRECT( "'" & $A11 & "'"& "!" & AB$33)} -> 0.095975232
A12: MategninDouane | B12: {=INDIRECT( "'" & $A12 & "'"& "!" & B$33)} -> 193 | C12: {=INDIRECT( "'" & $A12 & "'"& "!" & C$33)} -> 108 | D12: {=INDIRECT( "'" & $A12 & "'"& "!" & D$33)} -> 0.35880399 | E12: {=INDIRECT( "'" & $A12 & "'"& "!" & E$33)} -> 102 | F12: {=INDIRECT( "'" & $A12 & "'"& "!" & F$33)} -> 123 | G12: {=INDIRECT( "'" & $A12 & "'"& "!" & G$33)} -> 18 | H12: {=INDIRECT( "'" & $A12 & "'"& "!" & H$33)} -> 243 | I12: {=INDIRECT( "'" & $A12 & "'"& "!" & I$33)} -> 0.54666667 | ... N12: {=INDIRECT( "'" & $A12 & "'"& "!" & N$33)} -> 313 | P12: {=INDIRECT( "'" & $A12 & "'"& "!" & P$33)} -> 0.62184874 | Q12: {=INDIRECT( "'" & $A12 & "'"& "!" & Q$33)} -> 0.63636364 | R12: {=INDIRECT( "'" & $A12 & "'"& "!" & R$33)} -> 0.0057384476 | S12: {=INDIRECT( "'" & $A12 & "'"& "!" & S$33)} -> 0.32467532 | T12: {=INDIRECT( "'" & $A12 & "'"& "!" & T$33)} -> 0.5375 | U12: {=INDIRECT( "'" & $A12 & "'"& "!" & U$33)} -> 0.28571429 | V12: {=INDIRECT( "'" & $A12 & "'"& "!" & V$33)} -> 0.42105263 | W12: {=INDIRECT( "'" & $A12 & "'"& "!" & W$33)} -> 0.072833333 | ... AB12: {=INDIRECT( "'" & $A12 & "'"& "!" & AB$33)} -> 0.69189189
A13: Mategnin Total | B13: =SUM(B11:B12) -> 415 | C13: =SUM(C11:C12) -> 226 | D13: =C13/(B13+C13) -> 0.3525741 | E13: =SUM(E11:E12) -> 253 | F13: =SUM(F11:F12) -> 276 | G13: =SUM(G11:G12) -> 52 | H13: =SUM(H11:H12) -> 581 | I13: =F13/H13 -> 0.47504303 | J13: =G13/H13 -> 0.089500861 | K13: =SUM(K11:K12) -> 86 | L13: =SUM(L11:L12) -> 98 | M13: =SUM(M11:M12) -> 569 | N13: =SUM(N11:N12) -> 667 | P13: {=INDIRECT( "'" & $A13 & "'"& "!" & P$33)} -> 0.22418879 | Q13: {=INDIRECT( "'" & $A13 & "'"& "!" & Q$33)} -> 0.33727811 | R13: {=INDIRECT( "'" & $A13 & "'"& "!" & R$33)} -> 0.059808546 | S13: {=INDIRECT( "'" & $A13 & "'"& "!" & S$33)} -> 0.16589862 | T13: {=INDIRECT( "'" & $A13 & "'"& "!" & T$33)} -> 0.27777778 | U13: {=INDIRECT( "'" & $A13 & "'"& "!" & U$33)} -> 0.40540541 | V13: {=INDIRECT( "'" & $A13 & "'"& "!" & V$33)} -> 0.23617021 | W13: {=INDIRECT( "'" & $A13 & "'"& "!" & W$33)} -> 0.04589372 | ... AB13: {=INDIRECT( "'" & $A13 & "'"& "!" & AB$33)} -> 0.31299213
A15: PdG Centre Total | B15: =B13+B9+B3 -> 1155 | C15: =C13+C9+C3 -> 593 | D15: =C15/(B15+C15) -> 0.33924485 | E15: =E13+E9+E3 -> 717 | F15: =F13+F9+F3 -> 805 | G15: =G13+G9+G3 -> 115 | H15: =H13+H9+H3 -> 1637 | I15: =F15/H15 -> 0.49175321 | J15: =G15/H15 -> 0.070250458 | K15: =K13+K9+K3 -> 182 | L15: =L13+L9+L3 -> 121 | M15: =M13+M9+M3 -> 1698 | N15: =N13+N9+N3 -> 1819 | P15: {=INDIRECT( "'" & $A15 & "'"& "!" & P$33)} -> 0.056724611 | Q15: {=INDIRECT( "'" & $A15 & "'"& "!" & Q$33)} -> 0.082116788 | R15: {=INDIRECT( "'" & $A15 & "'"& "!" & R$33)} -> 0.015877374 | S15: {=INDIRECT( "'" & $A15 & "'"& "!" & S$33)} -> -0.047808765 | T15: {=INDIRECT( "'" & $A15 & "'"& "!" & T$33)} -> 0.27575277 | U15: {=INDIRECT( "'" & $A15 & "'"& "!" & U$33)} -> 0 | V15: {=INDIRECT( "'" & $A15 & "'"& "!" & V$33)} -> 0.092061374 | W15: {=INDIRECT( "'" & $A15 & "'"& "!" & W$33)} -> 0.16008005 | ... AB15: {=INDIRECT( "'" & $A15 & "'"& "!" & AB$33)} -> 0.10847044
A17: Vireloup Douane | B17: {=INDIRECT( "'" & $A17 & "'"& "!" & B$33)} -> 65 | C17: {=INDIRECT( "'" & $A17 & "'"& "!" & C$33)} -> 36 | D17: {=INDIRECT( "'" & $A17 & "'"& "!" & D$33)} -> 0.35643564 | E17: {=INDIRECT( "'" & $A17 & "'"& "!" & E$33)} -> 51 | F17: {=INDIRECT( "'" & $A17 & "'"& "!" & F$33)} -> 30 | G17: {=INDIRECT( "'" & $A17 & "'"& "!" & G$33)} -> 7 | H17: {=INDIRECT( "'" & $A17 & "'"& "!" & H$33)} -> 88 | I17: {=INDIRECT( "'" & $A17 & "'"& "!" & I$33)} -> 0.37037037 | ... N17: {=INDIRECT( "'" & $A17 & "'"& "!" & N$33)} -> 105 | P17: {=INDIRECT( "'" & $A17 & "'"& "!" & P$33)} -> -0.30107527 | Q17: {=INDIRECT( "'" & $A17 & "'"& "!" & Q$33)} -> -0.4375 | R17: {=INDIRECT( "'" & $A17 & "'"& "!" & R$33)} -> -0.12561881 | S17: {=INDIRECT( "'" & $A17 & "'"& "!" & S$33)} -> -0.10526316 | T17: {=INDIRECT( "'" & $A17 & "'"& "!" & T$33)} -> -0.53125 | U17: {=INDIRECT( "'" & $A17 & "'"& "!" & U$33)} -> -0.3 | V17: {=INDIRECT( "'" & $A17 & "'"& "!" & V$33)} -> -0.32824427 | W17: {=INDIRECT( "'" & $A17 & "'"& "!" & W$33)} -> -0.29976852 | ... AB17: {=INDIRECT( "'" & $A17 & "'"& "!" & AB$33)} -> -0.33121019
A18: Versonnex | B18: {=INDIRECT( "'" & $A18 & "'"& "!" & B$33)} -> 49 | C18: {=INDIRECT( "'" & $A18 & "'"& "!" & C$33)} -> 27 | D18: {=INDIRECT( "'" & $A18 & "'"& "!" & D$33)} -> 0.35526316 | E18: {=INDIRECT( "'" & $A18 & "'"& "!" & E$33)} -> 28 | F18: {=INDIRECT( "'" & $A18 & "'"& "!" & F$33)} -> 48 | G18: {=INDIRECT( "'" & $A18 & "'"& "!" & G$33)} -> 0 | H18: {=INDIRECT( "'" & $A18 & "'"& "!" & H$33)} -> 76 | I18: {=INDIRECT( "'" & $A18 & "'"& "!" & I$33)} -> 0.63157895 | ... N18: {=INDIRECT( "'" & $A18 & "'"& "!" & N$33)} -> 76 | P18: {=INDIRECT( "'" & $A18 & "'"& "!" & P$33)} -> 0.11363636 | Q18: {=INDIRECT( "'" & $A18 & "'"& "!" & Q$33)} -> 0.28571429 | R18: {=INDIRECT( "'" & $A18 & "'"& "!" & R$33)} -> 0.09962406 | S18: {=INDIRECT( "'" & $A18 & "'"& "!" & S$33)} -> 0.2173913 | T18: {=INDIRECT( "'" & $A18 & "'"& "!" & T$33)} -> 0.17073171 | U18: {=INDIRECT( "'" & $A18 & "'"& "!" & U$33)} -> #DIV/0! | V18: {=INDIRECT( "'" & $A18 & "'"& "!" & V$33)} -> 0.1875 | W18: {=INDIRECT( "'" & $A18 & "'"& "!" & W$33)} -> -0.014120668 | ... AB18: {=INDIRECT( "'" & $A18 & "'"& "!" & AB$33)} -> 0.16923077
A19: Sauverny | B19: {=INDIRECT( "'" & $A19 & "'"& "!" & B$33)} -> 41 | C19: {=INDIRECT( "'" & $A19 & "'"& "!" & C$33)} -> 45 | D19: {=INDIRECT( "'" & $A19 & "'"& "!" & D$33)} -> 0.52325581 | E19: {=INDIRECT( "'" & $A19 & "'"& "!" & E$33)} -> 25 | F19: {=INDIRECT( "'" & $A19 & "'"& "!" & F$33)} -> 16 | G19: {=INDIRECT( "'" & $A19 & "'"& "!" & G$33)} -> 1 | H19: {=INDIRECT( "'" & $A19 & "'"& "!" & H$33)} -> 42 | I19: {=INDIRECT( "'" & $A19 & "'"& "!" & I$33)} -> 0.3902439 | ... N19: {=INDIRECT( "'" & $A19 & "'"& "!" & N$33)} -> 86
A20: Divonne->Chavanne | B20: {=INDIRECT( "'" & $A20 & "'"& "!" & B$33)} -> 53 | C20: {=INDIRECT( "'" & $A20 & "'"& "!" & C$33)} -> 48 | D20: {=INDIRECT( "'" & $A20 & "'"& "!" & D$33)} -> 0.47524752 | E20: {=INDIRECT( "'" & $A20 & "'"& "!" & E$33)} -> 26 | F20: {=INDIRECT( "'" & $A20 & "'"& "!" & F$33)} -> 48 | G20: {=INDIRECT( "'" & $A20 & "'"& "!" & G$33)} -> 5 | H20: {=INDIRECT( "'" & $A20 & "'"& "!" & H$33)} -> 79 | I20: {=INDIRECT( "'" & $A20 & "'"& "!" & I$33)} -> 0.64864865 | ... N20: {=INDIRECT( "'" & $A20 & "'"& "!" & N$33)} -> 114 | P20: {=INDIRECT( "'" & $A20 & "'"& "!" & P$33)} -> -0.053571429 | Q20: {=INDIRECT( "'" & $A20 & "'"& "!" & Q$33)} -> 0.14285714 | R20: {=INDIRECT( "'" & $A20 & "'"& "!" & R$33)} -> 0.10891089 | S20: {=INDIRECT( "'" & $A20 & "'"& "!" & S$33)} -> -0.58064516 | T20: {=INDIRECT( "'" & $A20 & "'"& "!" & T$33)} -> 0.77777778 | U20: {=INDIRECT( "'" & $A20 & "'"& "!" & U$33)} -> 1.5 | V20: {=INDIRECT( "'" & $A20 & "'"& "!" & V$33)} -> -0.13186813 | W20: {=INDIRECT( "'" & $A20 & "'"& "!" & W$33)} -> 1.1381381 | ... AB20: {=INDIRECT( "'" & $A20 & "'"& "!" & AB$33)} -> 0.16326531
A21: Crassier Voie Verte | B21: {=INDIRECT( "'" & $A21 & "'"& "!" & B$33)} -> 42 | C21: {=INDIRECT( "'" & $A21 & "'"& "!" & C$33)} -> 32 | D21: {=INDIRECT( "'" & $A21 & "'"& "!" & D$33)} -> 0.43243243 | E21: {=INDIRECT( "'" & $A21 & "'"& "!" & E$33)} -> 30 | F21: {=INDIRECT( "'" & $A21 & "'"& "!" & F$33)} -> 33 | G21: {=INDIRECT( "'" & $A21 & "'"& "!" & G$33)} -> 0 | H21: {=INDIRECT( "'" & $A21 & "'"& "!" & H$33)} -> 63 | I21: {=INDIRECT( "'" & $A21 & "'"& "!" & I$33)} -> 0.52380952 | ... N21: {=INDIRECT( "'" & $A21 & "'"& "!" & N$33)} -> 75 | P21: {=INDIRECT( "'" & $A21 & "'"& "!" & P$33)} -> 0.5 | Q21: {=INDIRECT( "'" & $A21 & "'"& "!" & Q$33)} -> 1.9090909 | R21: {=INDIRECT( "'" & $A21 & "'"& "!" & R$33)} -> 0.53316953 | S21: {=INDIRECT( "'" & $A21 & "'"& "!" & S$33)} -> 3.2857143 | T21: {=INDIRECT( "'" & $A21 & "'"& "!" & T$33)} -> 1.0625 | U21: {=INDIRECT( "'" & $A21 & "'"& "!" & U$33)} -> #DIV/0! | V21: {=INDIRECT( "'" & $A21 & "'"& "!" & V$33)} -> 1.7391304 | W21: {=INDIRECT( "'" & $A21 & "'"& "!" & W$33)} -> -0.24702381 | ... AB21: {=INDIRECT( "'" & $A21 & "'"& "!" & AB$33)} -> 0.92307692
A22: Crassier Douane
A23: PdG Nord Total | B23: =SUM(B17:B22) -> 250 | C23: =SUM(C17:C22) -> 188 | D23: =C23/(B23+C23) -> 0.42922374 | E23: =SUM(E17:E22) -> 160 | F23: =SUM(F17:F22) -> 175 | G23: =SUM(G17:G22) -> 13 | H23: =SUM(H17:H22) -> 348 | I23: =F23/H23 -> 0.50287356 | J23: =G23/H23 -> 0.037356322 | K23: =SUM(K17:K22) -> 108 | L23: =SUM(L17:L22) -> 72 | M23: =SUM(M17:M22) -> 384 | N23: =SUM(N17:N22) -> 456 | P23: {=INDIRECT( "'" & $A23 & "'"& "!" & P$33)} -> -0.11347518 | Q23: {=INDIRECT( "'" & $A23 & "'"& "!" & Q$33)} -> 0.10588235 | R23: {=INDIRECT( "'" & $A23 & "'"& "!" & R$33)} -> 0.14123019 | S23: {=INDIRECT( "'" & $A23 & "'"& "!" & S$33)} -> -0.13513514 | T23: {=INDIRECT( "'" & $A23 & "'"& "!" & T$33)} -> 0.011560694 | U23: {=INDIRECT( "'" & $A23 & "'"& "!" & U$33)} -> -0.071428571 | V23: {=INDIRECT( "'" & $A23 & "'"& "!" & V$33)} -> -0.064516129 | W23: {=INDIRECT( "'" & $A23 & "'"& "!" & W$33)} -> 0.081011129 | ... AB23: {=INDIRECT( "'" & $A23 & "'"& "!" & AB$33)} -> 0.0088495575
A25: StJeanDeG | B25: {=INDIRECT( "'" & $A25 & "'"& "!" & B$33)} -> 1 | C25: {=INDIRECT( "'" & $A25 & "'"& "!" & C$33)} -> 1 | D25: {=INDIRECT( "'" & $A25 & "'"& "!" & D$33)} -> 0.5 | E25: {=INDIRECT( "'" & $A25 & "'"& "!" & E$33)} -> 1 | F25: {=INDIRECT( "'" & $A25 & "'"& "!" & F$33)} -> 1 | G25: {=INDIRECT( "'" & $A25 & "'"& "!" & G$33)} -> 0 | H25: {=INDIRECT( "'" & $A25 & "'"& "!" & H$33)} -> 2 | I25: {=INDIRECT( "'" & $A25 & "'"& "!" & I$33)} -> 0.5 | ... N25: {=INDIRECT( "'" & $A25 & "'"& "!" & N$33)} -> 2
A26: Challex->Dardagny
A27: Challex->LaPlaine
A28: Pougny | B28: {=INDIRECT( "'" & $A28 & "'"& "!" & B$33)} -> 14 | C28: {=INDIRECT( "'" & $A28 & "'"& "!" & C$33)} -> 20 | D28: {=INDIRECT( "'" & $A28 & "'"& "!" & D$33)} -> 0.58823529 | E28: {=INDIRECT( "'" & $A28 & "'"& "!" & E$33)} -> 13 | F28: {=INDIRECT( "'" & $A28 & "'"& "!" & F$33)} -> 5 | G28: {=INDIRECT( "'" & $A28 & "'"& "!" & G$33)} -> 0 | H28: {=INDIRECT( "'" & $A28 & "'"& "!" & H$33)} -> 18 | I28: {=INDIRECT( "'" & $A28 & "'"& "!" & I$33)} -> 0.27777778 | ... N28: {=INDIRECT( "'" & $A28 & "'"& "!" & N$33)} -> 36
A29: PdG Sud Total | B29: =SUM(B25:B28) -> 15 | C29: =SUM(C25:C28) -> 21 | D29: =C29/(B29+C29) -> 0.58333333 | E29: =SUM(E25:E28) -> 14 | F29: =SUM(F25:F28) -> 6 | G29: =SUM(G25:G28) -> 0 | H29: =SUM(H25:H28) -> 20 | I29: =F29/H29 -> 0.3 | J29: =G29/H29 -> 0 | K29: =SUM(K25:K28) -> 18 | L29: =SUM(L25:L28) -> 3 | M29: =SUM(M25:M28) -> 35 | N29: =SUM(N25:N28) -> 38
A31: APiCy total | B31: =B23+B15+B29 -> 1420 | C31: =C23+C15+C29 -> 802 | D31: =C31/(C31+B31) -> 0.36093609 | E31: =E23+E15+E29 -> 891 | F31: =F23+F15+F29 -> 986 | G31: =G23+G15+G29 -> 128 | H31: =H23+H15+H29 -> 2005 | I31: =F31/H31 -> 0.49177057 | J31: =G31/H31 -> 0.063840399 | K31: =K23+K15+K29 -> 308 | L31: =L23+L15+L29 -> 196 | M31: =M23+M15+M29 -> 2117 | N31: =N23+N15+N29 -> 2313 | P31: {=INDIRECT( "'" & $A31 & "'"& "!" & P$33)} -> 0.026011561 | Q31: {=INDIRECT( "'" & $A31 & "'"& "!" & Q$33)} -> 0.1062069 | R31: {=INDIRECT( "'" & $A31 & "'"& "!" & R$33)} -> 0.04995065 | S31: {=INDIRECT( "'" & $A31 & "'"& "!" & S$33)} -> -0.057142857 | T31: {=INDIRECT( "'" & $A31 & "'"& "!" & T$33)} -> 0.21878863 | U31: {=INDIRECT( "'" & $A31 & "'"& "!" & U$33)} -> -0.03030303 | V31: {=INDIRECT( "'" & $A31 & "'"& "!" & V$33)} -> 0.063096501 | W31: {=INDIRECT( "'" & $A31 & "'"& "!" & W$33)} -> 0.13892129 | ... AB31: {=INDIRECT( "'" & $A31 & "'"& "!" & AB$33)} -> 0.096728307
B33: W14 | C33: X14 | D33: Y14 | E33: Z14 | F33: AA14 | G33: AC14 | H33: AD14 | I33: AE14 | J33: AF14 | K33: AG14 | L33: AI14 | M33: AH14 | N33: AJ14 | P33: AM14 | Q33: An14 | R33: AO14 | S33: AP14 | T33: AQ14 | U33: AR14 | V33: AS14 | W33: AT14 | X33: AU14 | Y33: AV14 | Z33: AW14 | AA33: AX14 | AB33: AY14
P36: AH14 | Q36: AI14 | R36: AJ14 | S36: AK14 | T36: AL14 | U36: AM14 | V36: AN14 | W36: AO14 | X36: AP14 | Y36: AQ14 | Z36: AR14 | AA36: AS14 | AB36: AT14
P39: AM14 | Q39: An14 | R39: AO14 | S39: AP14 | T39: AQ14 | U39: AR14 | V39: AS14 | W39: AT14 | X39: AU14 | Y39: AV14 | Z39: AW14 | AA39: AX14 | AB39: AY14

Sheet APiCy total
A1: 2025 | B1: Lieu: | C1: {=MID(CELL("filename",A1),FIND("]",CELL("filename",A1))+1,255)} -> APiCy total | BA1: 2024 | BB1: Lieu: | BC1: {=MID(CELL("filename",BA1),FIND("]",CELL("filename",BA1))+1,255)} -> APiCy total | CV1: 2023 | CW1: Lieu: | CX1: {=MID(CELL("filename",CV1),FIND("]",CELL("filename",CV1))+1,255)} -> APiCy total | EQ1: 2022 | ER1: Lieu: | ES1: {=MID(CELL("filename",EQ1),FIND("]",CELL("filename",EQ1))+1,255)} -> APiCy total | GL1: 2021 | GM1: Lieu: | GN1: APiCy Frontière Total
B2: France -> Suisse | L2: Suisse -> France | W2: ="Totaux "& A1 & " " & $C1 -> Totaux 2025 APiCy total | AM2: ="Changement depuis " & (A1 - 1) & " " & $C1 -> Changement depuis 2024 APiCy total | BB2: France -> Suisse | BJ2: Suisse -> France | BS2: ="Totaux 2024 " & $CX1 -> Totaux 2024 APiCy total | CH2: ="Changement depuis 2023 " & $CX1 -> Changement depuis 2023 APiCy total | CW2: France -> Suisse | DE2: Suisse -> France | DN2: ="Totaux 2023 " & $CX1 -> Totaux 2023 APiCy total | EC2: ="Changement depuis 2022 " & $CX1 -> Changement depuis 2022 APiCy total | ER2: France -> Suisse | EZ2: Suisse -> France | FI2: ="Totaux 2022 " & $ES1 -> Totaux 2022 APiCy total | FX2: ="Changement depuis 2021 " & $ES1 -> Changement depuis 2021 APiCy total | GM2: France -> Suisse | GU2: Suisse -> France | HD2: ="Totaux 2021 " & $GN1 -> Totaux 2021 APiCy Frontière Total | HR2: ="Totaux 2020 " & $GN1 -> Totaux 2020 APiCy Frontière Total | IF2: ="Changement depuis 2020 " & $GN1 -> Changement depuis 2020 APiCy Frontière Total
B3: Vélo traditionel | D3: VAE | F3: Vélos Speciaux | H3: Mode Nouveau Electrique | J3: Piéton/ne | L3: Vélo traditionel | N3: VAE | P3: Vélos Speciaux | R3: Mode Nouveau Electrique | T3: Piéton/ne | W3: Hommes | X3: Femmes | Y3: %Femmes | Z3: VT | AA3: VAE (incl speciaux) | AB3: Vélos Speciaux | AC3: EDPM | AD3: Tot 2roues (vélo+ EDPM) | AE3: %VAE (incl speciaux) | AF3: %Nouveau | AG3: Piétons | AH3: >CH | AI3: >FR | AJ3: TOT | AM3: Hommes | AN3: Femmes | AO3: %Femmes | AP3: VT | AQ3: VAE | AR3: Nouveau | AS3: 2r | AT3: %VAE | AU3: %Nouveau | AV3: Piétons | AW3: >CH | AX3: >FR | AY3: TOT | BB3: Vélo traditionel | BD3: VAE | BF3: Mode Nouveau Electrique | BH3: Piéton/ne | BJ3: Vélo traditionel | BL3: VAE | BN3: Mode Nouveau Electrique | BP3: Piéton/ne | BS3: Hommes | BT3: Femmes | BU3: %Femmes | BV3: VT | BW3: VAE | BX3: Nouveau | BY3: 2r | BZ3: %VAE | CA3: %Nouveau | CB3: Piétons | CC3: >CH | CD3: >FR | CE3: TOT | CH3: Hommes | CI3: Femmes | CJ3: %Femmes | CK3: VT | CL3: VAE | CM3: Nouveau | CN3: 2r | CO3: %VAE | CP3: %Nouveau | CQ3: Piétons | CR3: >CH | CS3: >FR | CT3: TOT | CW3: Vélo traditionel | CY3: VAE | DA3: Mode Nouveau Electrique | DC3: Piéton/ne | DE3: Vélo traditionel | DG3: VAE | DI3: Mode Nouveau Electrique | DK3: Piéton/ne | DN3: Hommes | DO3: Femmes | DP3: %Femmes | DQ3: VT | DR3: VAE | DS3: Nouveau | DT3: 2r | DU3: %VAE | DV3: %Nouveau | DW3: Piétons | DX3: >CH | DY3: >FR | DZ3: TOT | EC3: Hommes | ED3: Femmes | EE3: %Femmes | EF3: VT | EG3: VAE | EH3: Nouveau | EI3: 2r | EJ3: %VAE | EK3: %Nouveau | EL3: Piétons | EM3: >CH | EN3: >FR | EO3: TOT | ER3: Vélo traditionel | ET3: VAE | EV3: Mode Nouveau Electrique | EX3: Piéton/ne | EZ3: Vélo traditionel | FB3: VAE | FD3: Mode Nouveau Electrique | FF3: Piéton/ne | FI3: Hommes | FJ3: Femmes | FK3: %Femmes | FL3: VT | FM3: VAE | FN3: Nouveau | FO3: 2r | FP3: %VAE | FQ3: %Nouveau | FR3: Piétons | FS3: >CH | FT3: >FR | FU3: TOT | FX3: Hommes | FY3: Femmes | FZ3: %Femmes | GA3: VT | GB3: VAE | GC3: Nouveau | GD3: 2r | GE3: %VAE | GF3: %Nouveau | GG3: Piétons | GH3: >CH | GI3: >FR | GJ3: TOT | GM3: Vélo traditionel | GO3: VAE | GQ3: Mode Nouveau Electrique | GS3: Piéton/ne | GU3: Vélo traditionel | GW3: VAE | GY3: Mode Nouveau Electrique (trotinette, scateboard , …) | HA3: Piéton/ne | HD3: Hommes | HE3: Femmes | HF3: %Femmes | HG3: VT | HH3: VAE | HI3: Nouveau | HJ3: 2r | HK3: %VAE | HL3: %Nouveau | HM3: Piétons | HN3: >CH | HO3: >FR | HP3: TOT | HR3: Hommes | HS3: Femmes | HT3: %Femmes | HU3: VT | HV3: VAE | HW3: Nouveau | HX3: 2r | HY3: %VAE | HZ3: %Nouveau | IA3: Piétons | IB3: >CH | IC3: >FR | ID3: TOT | IF3: Hommes | IG3: Femmes | IH3: %Femmes | II3: VT | IJ3: VAE | IK3: Nouveau | IL3: 2r | IM3: %VAE | IN3: %Nouveau | IO3: Piétons | IP3: >CH | IQ3: >FR | IR3: TOT
A4: Heure | B4: H | C4: F | D4: H | E4: F | F4: H | G4: F | H4: H | I4: F | J4: H | K4: F | L4: H | M4: F | N4: H | O4: F | P4: H | Q4: F | R4: H | S4: F | T4: H | U4: F | BA4: Heure | BB4: H | BC4: F | BD4: H | BE4: F | BF4: H | BG4: F | BH4: H | BI4: F | BJ4: H | BK4: F | BL4: H | BM4: F | BN4: H | BO4: F | BP4: H | BQ4: F | CV4: Heure | CW4: H | CX4: F | CY4: H | CZ4: F | DA4: H | DB4: F | DC4: H | DD4: F | DE4: H | DF4: F | DG4: H | DH4: F | DI4: H | DJ4: F | DK4: H | DL4: F | EQ4: Heure | ER4: H | ES4: F | ET4: H | EU4: F | EV4: H | EW4: F | EX4: H | EY4: F | EZ4: H | FA4: F | FB4: H | FC4: F | FD4: H | FE4: F | FF4: H | FG4: F | GL4: Heure | GM4: H | GN4: F | GO4: H | GP4: F | GQ4: H | GR4: F | GS4: H | GT4: F | GU4: H | GV4: F | GW4: H | GX4: F | GY4: H | GZ4: F | HA4: H | HB4: F
A5: 0.29166667 | B5: ='PdG Nord Total'!B5+'PdG Sud Total'!B5+'PdG Centre Total'!B5 -> 58 | C5: ='PdG Nord Total'!C5+'PdG Sud Total'!C5+'PdG Centre Total'!C5 -> 13 | D5: ='PdG Nord Total'!D5+'PdG Sud Total'!D5+'PdG Centre Total'!D5 -> 27 | E5: ='PdG Nord Total'!E5+'PdG Sud Total'!E5+'PdG Centre Total'!E5 -> 32 | F5: ='PdG Nord Total'!F5+'PdG Sud Total'!F5+'PdG Centre Total'!F5 -> 2 | G5: ='PdG Nord Total'!G5+'PdG Sud Total'!G5+'PdG Centre Total'!G5 -> 2 | H5: ='PdG Nord Total'!H5+'PdG Sud Total'!H5+'PdG Centre Total'!H5 -> 9 | I5: ='PdG Nord Total'!I5+'PdG Sud Total'!I5+'PdG Centre Total'!I5 -> 4 | ... U5: ='PdG Nord Total'!U5+'PdG Sud Total'!U5+'PdG Centre Total'!U5 -> 0 | W5: =B5+D5+F5+H5+J5+L5+N5+P5+R5+T5 -> 112 | X5: =C5+E5+G5+I5+K5+M5+O5+Q5+S5+U5 -> 66 | Y5: =X5/(X5+W5) -> 0.37078652 | Z5: =B5+C5+L5+M5 -> 78 | AA5: =D5+E5+N5+O5+F5+G5+P5+Q5 -> 63 | AB5: =F5+G5+P5+Q5 -> 4 | AC5: =H5+I5+R5+S5 -> 14 | AD5: =Z5+AA5+AC5 -> 155 | AE5: =AA5/(Z5+AA5) -> 0.44680851 | AF5: =AC5/AD5 -> 0.090322581 | AG5: =J5+K5+T5+U5 -> 23 | AH5: =SUM(B5:K5) -> 170 | AI5: =SUM(L5:U5) -> 8 | AJ5: =SUM(B5:U5) -> 178 | AM5: =(W5/BS5) - 1 -> -0.042735043 | AN5: =(X5/BT5) - 1 -> -0.043478261 | AO5: =(Y5/BU5) - 1 -> -0.00048851979 | AP5: =(Z5/BV5) - 1 -> 0.026315789 | AQ5: =(AA5/BW5) - 1 -> -0.086956522 | AR5: =(AC5/BX5) - 1 -> -0.22222222 | AS5: =(AD5/BY5) - 1 -> -0.049079755 | AT5: =(AE5/BZ5) - 1 -> -0.061054579 | AU5: =(AF5/CA5) - 1 -> -0.18207885 | AV5: =(AG5/CB5) - 1 -> 0 | AW5: =(AH5/CC5) - 1 -> -0.01734104 | AX5: =(AI5/CD5) - 1 -> -0.38461538 | AY5: =(AJ5/CE5) - 1 -> -0.043010753 | BA5: 0.29166667 | BB5: ='Ferney->Genève'!BB5+'StGenis total'!BB5+'Mategnin Total'!BB5+'PdG Nord Total'!BB5+'PdG Sud Total'!BB5 -> 52 | BC5: ='Ferney->Genève'!BC5+'StGenis total'!BC5+'Mategnin Total'!BC5+'PdG Nord Total'!BC5+'PdG Sud Total'!BC5 -> 18 | BD5: ='Ferney->Genève'!BD5+'StGenis total'!BD5+'Mategnin Total'!BD5+'PdG Nord Total'!BD5+'PdG Sud Total'!BD5 -> 35 | BE5: ='Ferney->Genève'!BE5+'StGenis total'!BE5+'Mategnin Total'!BE5+'PdG Nord Total'!BE5+'PdG Sud Total'!BE5 -> 32 | BF5: ='Ferney->Genève'!BF5+'StGenis total'!BF5+'Mategnin Total'!BF5+'PdG Nord Total'!BF5+'PdG Sud Total'!BF5 -> 13 | BG5: ='Ferney->Genève'!BG5+'StGenis total'!BG5+'Mategnin Total'!BG5+'PdG Nord Total'!BG5+'PdG Sud Total'!BG5 -> 5 | BH5: ='Ferney->Genève'!BH5+'StGenis total'!BH5+'Mategnin Total'!BH5+'PdG Nord Total'!BH5+'PdG Sud Total'!BH5 -> 7 | BI5: ='Ferney->Genève'!BI5+'StGenis total'!BI5+'Mategnin Total'!BI5+'PdG Nord Total'!BI5+'PdG Sud Total'!BI5 -> 11 | ... BQ5: ='Ferney->Genève'!BQ5+'StGenis total'!BQ5+'Mategnin Total'!BQ5+'PdG Nord Total'!BQ5+'PdG Sud Total'!BQ5 -> 2 | BS5: =BB5+BD5+BF5+BH5+BJ5+BL5+BN5+BP5 -> 117 | BT5: =BC5+BE5+BG5+BI5+BK5+BM5+BO5+BQ5 -> 69 | BU5: =BT5/(BT5+BS5) -> 0.37096774 | BV5: =BB5+BC5+BJ5+BK5 -> 76 | BW5: =BD5+BE5+BL5+BM5 -> 69 | BX5: =BF5+BG5+BN5+BO5 -> 18 | BY5: =SUM(BV5:BX5) -> 163 | BZ5: =BW5/(BW5+BV5) -> 0.47586207 | CA5: =BX5/BY5 -> 0.11042945 | CB5: =BH5+BI5+BP5+BQ5 -> 23 | CC5: =SUM(BB5:BI5) -> 173 | CD5: =SUM(BJ5:BQ5) -> 13 | CE5: =SUM(BB5:BQ5) -> 186 | CH5: =(BS5/DN5) - 1 -> -0.13333333 | CI5: =(BT5/DO5) - 1 -> 0.23214286 | CJ5: =(BU5/DP5) - 1 -> 0.26526498 | CK5: =(BV5/DQ5) - 1 -> -0.084337349 | CL5: =(BW5/DR5) - 1 -> -0.092105263 | CM5: =(BX5/DS5) - 1 -> 0.28571429 | CN5: =(BY5/DT5) - 1 -> -0.057803468 | CO5: =(BZ5/DU5) - 1 -> 0.083212341 | ... CT5: =(CE5/DZ5) - 1 -> -0.02617801 | CV5: 0.29166667 | CW5: ='Ferney->Genève'!CW5+'StGenis total'!CW5+'Mategnin Total'!CW5+'PdG Nord Total'!CW5+'PdG Sud Total'!CW5 -> 62 | CX5: ='Ferney->Genève'!CX5+'StGenis total'!CX5+'Mategnin Total'!CX5+'PdG Nord Total'!CX5+'PdG Sud Total'!CX5 -> 13 | CY5: ='Ferney->Genève'!CY5+'StGenis total'!CY5+'Mategnin Total'!CY5+'PdG Nord Total'!CY5+'PdG Sud Total'!CY5 -> 38 | CZ5: ='Ferney->Genève'!CZ5+'StGenis total'!CZ5+'Mategnin Total'!CZ5+'PdG Nord Total'!CZ5+'PdG Sud Total'!CZ5 -> 33 | DA5: ='Ferney->Genève'!DA5+'StGenis total'!DA5+'Mategnin Total'!DA5+'PdG Nord Total'!DA5+'PdG Sud Total'!DA5 -> 9 | DB5: ='Ferney->Genève'!DB5+'StGenis total'!DB5+'Mategnin Total'!DB5+'PdG Nord Total'!DB5+'PdG Sud Total'!DB5 -> 1 | DC5: ='Ferney->Genève'!DC5+'StGenis total'!DC5+'Mategnin Total'!DC5+'PdG Nord Total'!DC5+'PdG Sud Total'!DC5 -> 12 | DD5: ='Ferney->Genève'!DD5+'StGenis total'!DD5+'Mategnin Total'!DD5+'PdG Nord Total'!DD5+'PdG Sud Total'!DD5 -> 4 | ... DL5: ='Ferney->Genève'!DL5+'StGenis total'!DL5+'Mategnin Total'!DL5+'PdG Nord Total'!DL5+'PdG Sud Total'!DL5 -> 1 | DN5: =CW5+CY5+DA5+DC5+DE5+DG5+DI5+DK5 -> 135 | DO5: =CX5+CZ5+DB5+DD5+DF5+DH5+DJ5+DL5 -> 56 | DP5: =DO5/(DO5+DN5) -> 0.29319372 | DQ5: =CW5+CX5+DE5+DF5 -> 83 | DR5: =CY5+CZ5+DG5+DH5 -> 76 | DS5: =DA5+DB5+DI5+DJ5 -> 14 | DT5: =SUM(DQ5:DS5) -> 173 | DU5: =DR5/DT5 -> 0.43930636 | DV5: =DS5/DT5 -> 0.080924855 | DW5: =DC5+DD5+DK5+DL5 -> 18 | DX5: =SUM(CW5:DD5) -> 172 | DY5: =SUM(DE5:DL5) -> 19 | DZ5: =SUM(CW5:DL5) -> 191 | EC5: =(DN5/FI5) - 1 -> 0.51685393 | ED5: =(DO5/FJ5) - 1 -> 0.19148936 | EE5: =(DP5/FK5) - 1 -> -0.15160967 | EF5: =(DQ5/FL5) - 1 -> 0.22058824 | EG5: =(DR5/FM5) - 1 -> 0.85365854 | EH5: =(DS5/FN5) - 1 -> 1 | EI5: =(DT5/FO5) - 1 -> 0.49137931 | EJ5: =(DU5/FP5) - 1 -> 0.24291555 | ... EO5: =(DZ5/FU5) - 1 -> 0.40441176 | EQ5: 0.29166667 | ER5: ='Ferney->Genève'!ER5+'StGenis total'!ER5+'Mategnin Total'!ER5+'PdG Nord Total'!ER5+'PdG Sud Total'!ER5 -> 44 | ES5: ='Ferney->Genève'!ES5+'StGenis total'!ES5+'Mategnin Total'!ES5+'PdG Nord Total'!ES5+'PdG Sud Total'!ES5 -> 21 | ET5: ='Ferney->Genève'!ET5+'StGenis total'!ET5+'Mategnin Total'!ET5+'PdG Nord Total'!ET5+'PdG Sud Total'!ET5 -> 20 | EU5: ='Ferney->Genève'!EU5+'StGenis total'!EU5+'Mategnin Total'!EU5+'PdG Nord Total'!EU5+'PdG Sud Total'!EU5 -> 18 | EV5: ='Ferney->Genève'!EV5+'StGenis total'!EV5+'Mategnin Total'!EV5+'PdG Nord Total'!EV5+'PdG Sud Total'!EV5 -> 5 | EW5: ='Ferney->Genève'!EW5+'StGenis total'!EW5+'Mategnin Total'!EW5+'PdG Nord Total'!EW5+'PdG Sud Total'!EW5 -> 0 | EX5: ='Ferney->Genève'!EX5+'StGenis total'!EX5+'Mategnin Total'!EX5+'PdG Nord Total'!EX5+'PdG Sud Total'!EX5 -> 12 | EY5: ='Ferney->Genève'!EY5+'StGenis total'!EY5+'Mategnin Total'!EY5+'PdG Nord Total'!EY5+'PdG Sud Total'!EY5 -> 7 | ... FG5: ='Ferney->Genève'!FG5+'StGenis total'!FG5+'Mategnin Total'!FG5+'PdG Nord Total'!FG5+'PdG Sud Total'!FG5 -> 0 | FI5: =ER5+ET5+EV5+EX5+EZ5+FB5+FD5+FF5 -> 89 | FJ5: =ES5+EU5+EW5+EY5+FA5+FC5+FE5+FG5 -> 47 | FK5: =FJ5/(FJ5+FI5) -> 0.34558824 | FL5: =ER5+ES5+EZ5+FA5 -> 68 | FM5: =ET5+EU5+FB5+FC5 -> 41 | FN5: =EV5+EW5+FD5+FE5 -> 7 | FO5: =SUM(FL5:FN5) -> 116 | FP5: =FM5/FO5 -> 0.35344828 | FQ5: =FN5/FO5 -> 0.060344828 | FR5: =EX5+EY5+FF5+FG5 -> 20 | FS5: =SUM(ER5:EY5) -> 127 | FT5: =SUM(EZ5:FG5) -> 9 | FU5: =SUM(ER5:FG5) -> 136 | FX5: =(FI5/HD5) - 1 -> 0.28985507 | FY5: =(FJ5/HE5) - 1 -> 0.74074074 | FZ5: =(FK5/HF5) - 1 -> 0.22875817 | GA5: =(FL5/HG5) - 1 -> 0.25925926 | GB5: =(FM5/HH5) - 1 -> 0.24242424 | GC5: =(FN5/HI5) - 1 -> 0 | GD5: =(FO5/HJ5) - 1 -> 0.23404255 | GE5: =(FP5/HK5) - 1 -> 0.0067920585 | ... GJ5: =(FU5/HP5) - 1 -> 0.41666667 | GL5: 0.29166667 | GM5: =#REF!+'StGenis total'!GM5+'Mategnin Total'!GM5+'PdG Nord Total'!GM5 -> #REF! | GN5: =#REF!+'StGenis total'!GN5+'Mategnin Total'!GN5+'PdG Nord Total'!GN5 -> #REF! | GO5: =#REF!+'StGenis total'!GO5+'Mategnin Total'!GO5+'PdG Nord Total'!GO5 -> #REF! | GP5: =#REF!+'StGenis total'!GP5+'Mategnin Total'!GP5+'PdG Nord Total'!GP5 -> #REF! | GQ5: =#REF!+'StGenis total'!GQ5+'Mategnin Total'!GQ5+'PdG Nord Total'!GQ5 -> #REF! | GR5: =#REF!+'StGenis total'!GR5+'Mategnin Total'!GR5+'PdG Nord Total'!GR5 -> #REF! | GS5: =#REF!+'StGenis total'!GS5+'Mategnin Total'!GS5+'PdG Nord Total'!GS5 -> #REF! | GT5: =#REF!+'StGenis total'!GT5+'Mategnin Total'!GT5+'PdG Nord Total'!GT5 -> #REF! | ... HB5: =#REF!+'StGenis total'!HB5+'Mategnin Total'!HB5+'PdG Nord Total'!HB5 -> #REF! | HD5: 69 | HE5: 27 | HF5: 0.28125 | HG5: 54 | HH5: 33 | HI5: 7 | HJ5: 94 | HK5: 0.35106383 | HL5: 0.074468085 | HM5: 2 | HN5: 89 | HO5: 7 | HP5: 96 | HR5: 43 | HS5: 26 | HT5: 0.37681159 | HU5: 35 | HV5: 25 | HW5: 3 | HX5: 63 | HY5: 0.3968254 | HZ5: 0.047619048 | IA5: 6 | IB5: 63 | IC5: 6 | ID5: 69 | IF5: =(HD5/HR5) - 1 -> 0.60465116 | IG5: =(HE5/HS5) - 1 -> 0.038461538 | IH5: =(HF5/HT5) - 1 -> -0.25360577 | II5: =(HG5/HU5) - 1 -> 0.54285714 | IJ5: =(HH5/HV5) - 1 -> 0.32 | IK5: =(HI5/HW5) - 1 -> 1.3333333 | IL5: =(HJ5/HX5) - 1 -> 0.49206349 | IM5: =(HK5/HY5) - 1 -> -0.11531915 | ... IR5: =(HP5/ID5) - 1 -> 0.39130435
A6: 0.30208333 | B6: ='PdG Nord Total'!B6+'PdG Sud Total'!B6+'PdG Centre Total'!B6 -> 57 | C6: ='PdG Nord Total'!C6+'PdG Sud Total'!C6+'PdG Centre Total'!C6 -> 25 | D6: ='PdG Nord Total'!D6+'PdG Sud Total'!D6+'PdG Centre Total'!D6 -> 43 | E6: ='PdG Nord Total'!E6+'PdG Sud Total'!E6+'PdG Centre Total'!E6 -> 36 | F6: ='PdG Nord Total'!F6+'PdG Sud Total'!F6+'PdG Centre Total'!F6 -> 4 | G6: ='PdG Nord Total'!G6+'PdG Sud Total'!G6+'PdG Centre Total'!G6 -> 3 | H6: ='PdG Nord Total'!H6+'PdG Sud Total'!H6+'PdG Centre Total'!H6 -> 19 | I6: ='PdG Nord Total'!I6+'PdG Sud Total'!I6+'PdG Centre Total'!I6 -> 7 | ... U6: ='PdG Nord Total'!U6+'PdG Sud Total'!U6+'PdG Centre Total'!U6 -> 2 | W6: =B6+D6+F6+H6+J6+L6+N6+P6+R6+T6 -> 146 | X6: =C6+E6+G6+I6+K6+M6+O6+Q6+S6+U6 -> 86 | Y6: =X6/(X6+W6) -> 0.37068966 | Z6: =B6+C6+L6+M6 -> 95 | AA6: =D6+E6+N6+O6+F6+G6+P6+Q6 -> 91 | AB6: =F6+G6+P6+Q6 -> 8 | AC6: =H6+I6+R6+S6 -> 28 | AD6: =Z6+AA6+AC6 -> 214 | AE6: =AA6/(Z6+AA6) -> 0.48924731 | AF6: =AC6/AD6 -> 0.13084112 | AG6: =J6+K6+T6+U6 -> 18 | AH6: =SUM(B6:K6) -> 208 | AI6: =SUM(L6:U6) -> 24 | AJ6: =SUM(B6:U6) -> 232 | AM6: =(W6/BS6) - 1 -> 0.057971014 | AN6: =(X6/BT6) - 1 -> 0.28358209 | AO6: =(Y6/BU6) - 1 -> 0.13419969 | AP6: =(Z6/BV6) - 1 -> 0.10465116 | AQ6: =(AA6/BW6) - 1 -> 0.15189873 | AR6: =(AC6/BX6) - 1 -> 0.75 | AS6: =(AD6/BY6) - 1 -> 0.18232044 | AT6: =(AE6/BZ6) - 1 -> 0.021845651 | AU6: =(AF6/CA6) - 1 -> 0.48014019 | AV6: =(AG6/CB6) - 1 -> -0.25 | AW6: =(AH6/CC6) - 1 -> 0.077720207 | AX6: =(AI6/CD6) - 1 -> 1 | AY6: =(AJ6/CE6) - 1 -> 0.13170732 | BA6: 0.30208333 | BB6: ='Ferney->Genève'!BB6+'StGenis total'!BB6+'Mategnin Total'!BB6+'PdG Nord Total'!BB6+'PdG Sud Total'!BB6 -> 56 | BC6: ='Ferney->Genève'!BC6+'StGenis total'!BC6+'Mategnin Total'!BC6+'PdG Nord Total'!BC6+'PdG Sud Total'!BC6 -> 23 | BD6: ='Ferney->Genève'!BD6+'StGenis total'!BD6+'Mategnin Total'!BD6+'PdG Nord Total'!BD6+'PdG Sud Total'!BD6 -> 43 | BE6: ='Ferney->Genève'!BE6+'StGenis total'!BE6+'Mategnin Total'!BE6+'PdG Nord Total'!BE6+'PdG Sud Total'!BE6 -> 34 | BF6: ='Ferney->Genève'!BF6+'StGenis total'!BF6+'Mategnin Total'!BF6+'PdG Nord Total'!BF6+'PdG Sud Total'!BF6 -> 14 | BG6: ='Ferney->Genève'!BG6+'StGenis total'!BG6+'Mategnin Total'!BG6+'PdG Nord Total'!BG6+'PdG Sud Total'!BG6 -> 2 | BH6: ='Ferney->Genève'!BH6+'StGenis total'!BH6+'Mategnin Total'!BH6+'PdG Nord Total'!BH6+'PdG Sud Total'!BH6 -> 14 | BI6: ='Ferney->Genève'!BI6+'StGenis total'!BI6+'Mategnin Total'!BI6+'PdG Nord Total'!BI6+'PdG Sud Total'!BI6 -> 7 | ... BQ6: ='Ferney->Genève'!BQ6+'StGenis total'!BQ6+'Mategnin Total'!BQ6+'PdG Nord Total'!BQ6+'PdG Sud Total'!BQ6 -> 1 | BS6: =BB6+BD6+BF6+BH6+BJ6+BL6+BN6+BP6 -> 138 | BT6: =BC6+BE6+BG6+BI6+BK6+BM6+BO6+BQ6 -> 67 | BU6: =BT6/(BT6+BS6) -> 0.32682927 | BV6: =BB6+BC6+BJ6+BK6 -> 86 | BW6: =BD6+BE6+BL6+BM6 -> 79 | BX6: =BF6+BG6+BN6+BO6 -> 16 | BY6: =SUM(BV6:BX6) -> 181 | BZ6: =BW6/(BW6+BV6) -> 0.47878788 | CA6: =BX6/BY6 -> 0.08839779 | CB6: =BH6+BI6+BP6+BQ6 -> 24 | CC6: =SUM(BB6:BI6) -> 193 | CD6: =SUM(BJ6:BQ6) -> 12 | CE6: =SUM(BB6:BQ6) -> 205 | CH6: =(BS6/DN6) - 1 -> 0.069767442 | CI6: =(BT6/DO6) - 1 -> 0.19642857 | CJ6: =(BU6/DP6) - 1 -> 0.079703833 | CK6: =(BV6/DQ6) - 1 -> -0.094736842 | CL6: =(BW6/DR6) - 1 -> 0.067567568 | CM6: =(BX6/DS6) - 1 -> 0.77777778 | CN6: =(BY6/DT6) - 1 -> 0.016853933 | CO6: =(BZ6/DU6) - 1 -> 0.15167895 | ... CT6: =(CE6/DZ6) - 1 -> 0.10810811 | CV6: 0.30208333 | CW6: ='Ferney->Genève'!CW6+'StGenis total'!CW6+'Mategnin Total'!CW6+'PdG Nord Total'!CW6+'PdG Sud Total'!CW6 -> 66 | CX6: ='Ferney->Genève'!CX6+'StGenis total'!CX6+'Mategnin Total'!CX6+'PdG Nord Total'!CX6+'PdG Sud Total'!CX6 -> 18 | CY6: ='Ferney->Genève'!CY6+'StGenis total'!CY6+'Mategnin Total'!CY6+'PdG Nord Total'!CY6+'PdG Sud Total'!CY6 -> 38 | CZ6: ='Ferney->Genève'!CZ6+'StGenis total'!CZ6+'Mategnin Total'!CZ6+'PdG Nord Total'!CZ6+'PdG Sud Total'!CZ6 -> 32 | DA6: ='Ferney->Genève'!DA6+'StGenis total'!DA6+'Mategnin Total'!DA6+'PdG Nord Total'!DA6+'PdG Sud Total'!DA6 -> 8 | DB6: ='Ferney->Genève'!DB6+'StGenis total'!DB6+'Mategnin Total'!DB6+'PdG Nord Total'!DB6+'PdG Sud Total'!DB6 -> 1 | DC6: ='Ferney->Genève'!DC6+'StGenis total'!DC6+'Mategnin Total'!DC6+'PdG Nord Total'!DC6+'PdG Sud Total'!DC6 -> 2 | DD6: ='Ferney->Genève'!DD6+'StGenis total'!DD6+'Mategnin Total'!DD6+'PdG Nord Total'!DD6+'PdG Sud Total'!DD6 -> 2 | ... DL6: ='Ferney->Genève'!DL6+'StGenis total'!DL6+'Mategnin Total'!DL6+'PdG Nord Total'!DL6+'PdG Sud Total'!DL6 -> 0 | DN6: =CW6+CY6+DA6+DC6+DE6+DG6+DI6+DK6 -> 129 | DO6: =CX6+CZ6+DB6+DD6+DF6+DH6+DJ6+DL6 -> 56 | DP6: =DO6/(DO6+DN6) -> 0.3027027 | DQ6: =CW6+CX6+DE6+DF6 -> 95 | DR6: =CY6+CZ6+DG6+DH6 -> 74 | DS6: =DA6+DB6+DI6+DJ6 -> 9 | DT6: =SUM(DQ6:DS6) -> 178 | DU6: =DR6/DT6 -> 0.41573034 | DV6: =DS6/DT6 -> 0.050561798 | DW6: =DC6+DD6+DK6+DL6 -> 7 | DX6: =SUM(CW6:DD6) -> 167 | DY6: =SUM(DE6:DL6) -> 18 | DZ6: =SUM(CW6:DL6) -> 185 | EC6: =(DN6/FI6) - 1 -> 0.21698113 | ED6: =(DO6/FJ6) - 1 -> 0.056603774 | EE6: =(DP6/FK6) - 1 -> -0.091891892 | EF6: =(DQ6/FL6) - 1 -> 0.11764706 | EG6: =(DR6/FM6) - 1 -> 0.34545455 | EH6: =(DS6/FN6) - 1 -> 0.125 | EI6: =(DT6/FO6) - 1 -> 0.2027027 | EJ6: =(DU6/FP6) - 1 -> 0.11869254 | ... EO6: =(DZ6/FU6) - 1 -> 0.16352201 | EQ6: 0.30208333 | ER6: ='Ferney->Genève'!ER6+'StGenis total'!ER6+'Mategnin Total'!ER6+'PdG Nord Total'!ER6+'PdG Sud Total'!ER6 -> 47 | ES6: ='Ferney->Genève'!ES6+'StGenis total'!ES6+'Mategnin Total'!ES6+'PdG Nord Total'!ES6+'PdG Sud Total'!ES6 -> 26 | ET6: ='Ferney->Genève'!ET6+'StGenis total'!ET6+'Mategnin Total'!ET6+'PdG Nord Total'!ET6+'PdG Sud Total'!ET6 -> 30 | EU6: ='Ferney->Genève'!EU6+'StGenis total'!EU6+'Mategnin Total'!EU6+'PdG Nord Total'!EU6+'PdG Sud Total'!EU6 -> 23 | EV6: ='Ferney->Genève'!EV6+'StGenis total'!EV6+'Mategnin Total'!EV6+'PdG Nord Total'!EV6+'PdG Sud Total'!EV6 -> 6 | EW6: ='Ferney->Genève'!EW6+'StGenis total'!EW6+'Mategnin Total'!EW6+'PdG Nord Total'!EW6+'PdG Sud Total'!EW6 -> 1 | EX6: ='Ferney->Genève'!EX6+'StGenis total'!EX6+'Mategnin Total'!EX6+'PdG Nord Total'!EX6+'PdG Sud Total'!EX6 -> 6 | EY6: ='Ferney->Genève'!EY6+'StGenis total'!EY6+'Mategnin Total'!EY6+'PdG Nord Total'!EY6+'PdG Sud Total'!EY6 -> 2 | ... FG6: ='Ferney->Genève'!FG6+'StGenis total'!FG6+'Mategnin Total'!FG6+'PdG Nord Total'!FG6+'PdG Sud Total'!FG6 -> 0 | FI6: =ER6+ET6+EV6+EX6+EZ6+FB6+FD6+FF6 -> 106 | FJ6: =ES6+EU6+EW6+EY6+FA6+FC6+FE6+FG6 -> 53 | FK6: =FJ6/(FJ6+FI6) -> 0.33333333 | FL6: =ER6+ES6+EZ6+FA6 -> 85 | FM6: =ET6+EU6+FB6+FC6 -> 55 | FN6: =EV6+EW6+FD6+FE6 -> 8 | FO6: =SUM(FL6:FN6) -> 148 | FP6: =FM6/FO6 -> 0.37162162 | FQ6: =FN6/FO6 -> 0.054054054 | FR6: =EX6+EY6+FF6+FG6 -> 11 | FS6: =SUM(ER6:EY6) -> 141 | FT6: =SUM(EZ6:FG6) -> 18 | FU6: =SUM(ER6:FG6) -> 159 | FX6: =(FI6/HD6) - 1 -> 0.24705882 | FY6: =(FJ6/HE6) - 1 -> 0.65625 | FZ6: =(FK6/HF6) - 1 -> 0.21875 | GA6: =(FL6/HG6) - 1 -> 0.328125 | GB6: =(FM6/HH6) - 1 -> 0.25 | GC6: =(FN6/HI6) - 1 -> 0.6 | GD6: =(FO6/HJ6) - 1 -> 0.30973451 | GE6: =(FP6/HK6) - 1 -> -0.045608108 | ... GJ6: =(FU6/HP6) - 1 -> 0.35897436 | GL6: 0.30208333 | GM6: =#REF!+'StGenis total'!GM6+'Mategnin Total'!GM6+'PdG Nord Total'!GM6 -> #REF! | GN6: =#REF!+'StGenis total'!GN6+'Mategnin Total'!GN6+'PdG Nord Total'!GN6 -> #REF! | GO6: =#REF!+'StGenis total'!GO6+'Mategnin Total'!GO6+'PdG Nord Total'!GO6 -> #REF! | GP6: =#REF!+'StGenis total'!GP6+'Mategnin Total'!GP6+'PdG Nord Total'!GP6 -> #REF! | GQ6: =#REF!+'StGenis total'!GQ6+'Mategnin Total'!GQ6+'PdG Nord Total'!GQ6 -> #REF! | GR6: =#REF!+'StGenis total'!GR6+'Mategnin Total'!GR6+'PdG Nord Total'!GR6 -> #REF! | GS6: =#REF!+'StGenis total'!GS6+'Mategnin Total'!GS6+'PdG Nord Total'!GS6 -> #REF! | GT6: =#REF!+'StGenis total'!GT6+'Mategnin Total'!GT6+'PdG Nord Total'!GT6 -> #REF! | ... HB6: =#REF!+'StGenis total'!HB6+'Mategnin Total'!HB6+'PdG Nord Total'!HB6 -> #REF! | HD6: 85 | HE6: 32 | HF6: 0.27350427 | HG6: 64 | HH6: 44 | HI6: 5 | HJ6: 113 | HK6: 0.38938053 | HL6: 0.044247788 | HM6: 4 | HN6: 108 | HO6: 9 | HP6: 117 | HR6: 67 | HS6: 30 | HT6: 0.30927835 | HU6: 54 | HV6: 28 | HW6: 5 | HX6: 87 | HY6: 0.32183908 | HZ6: 0.057471264 | IA6: 10 | IB6: 87 | IC6: 10 | ID6: 97 | IF6: =(HD6/HR6) - 1 -> 0.26865672 | IG6: =(HE6/HS6) - 1 -> 0.066666667 | IH6: =(HF6/HT6) - 1 -> -0.11566952 | II6: =(HG6/HU6) - 1 -> 0.18518519 | IJ6: =(HH6/HV6) - 1 -> 0.57142857 | IK6: =(HI6/HW6) - 1 -> 0 | IL6: =(HJ6/HX6) - 1 -> 0.29885057 | IM6: =(HK6/HY6) - 1 -> 0.20986094 | ... IR6: =(HP6/ID6) - 1 -> 0.20618557
A7: 0.3125 | B7: ='PdG Nord Total'!B7+'PdG Sud Total'!B7+'PdG Centre Total'!B7 -> 57 | C7: ='PdG Nord Total'!C7+'PdG Sud Total'!C7+'PdG Centre Total'!C7 -> 25 | D7: ='PdG Nord Total'!D7+'PdG Sud Total'!D7+'PdG Centre Total'!D7 -> 46 | E7: ='PdG Nord Total'!E7+'PdG Sud Total'!E7+'PdG Centre Total'!E7 -> 46 | F7: ='PdG Nord Total'!F7+'PdG Sud Total'!F7+'PdG Centre Total'!F7 -> 5 | G7: ='PdG Nord Total'!G7+'PdG Sud Total'!G7+'PdG Centre Total'!G7 -> 1 | H7: ='PdG Nord Total'!H7+'PdG Sud Total'!H7+'PdG Centre Total'!H7 -> 12 | I7: ='PdG Nord Total'!I7+'PdG Sud Total'!I7+'PdG Centre Total'!I7 -> 7 | ... U7: ='PdG Nord Total'!U7+'PdG Sud Total'!U7+'PdG Centre Total'!U7 -> 7 | W7: =B7+D7+F7+H7+J7+L7+N7+P7+R7+T7 -> 152 | X7: =C7+E7+G7+I7+K7+M7+O7+Q7+S7+U7 -> 111 | Y7: =X7/(X7+W7) -> 0.42205323 | Z7: =B7+C7+L7+M7 -> 88 | AA7: =D7+E7+N7+O7+F7+G7+P7+Q7 -> 102 | AB7: =F7+G7+P7+Q7 -> 6 | AC7: =H7+I7+R7+S7 -> 20 | AD7: =Z7+AA7+AC7 -> 210 | AE7: =AA7/(Z7+AA7) -> 0.53684211 | AF7: =AC7/AD7 -> 0.095238095 | AG7: =J7+K7+T7+U7 -> 53 | AH7: =SUM(B7:K7) -> 244 | AI7: =SUM(L7:U7) -> 19 | AJ7: =SUM(B7:U7) -> 263 | AM7: =(W7/BS7) - 1 -> -0.15555556 | AN7: =(X7/BT7) - 1 -> 0.15625 | AO7: =(Y7/BU7) - 1 -> 0.21340304 | AP7: =(Z7/BV7) - 1 -> -0.28455285 | AQ7: =(AA7/BW7) - 1 -> -0.0097087379 | AR7: =(AC7/BX7) - 1 -> 0.17647059 | AS7: =(AD7/BY7) - 1 -> -0.13580247 | AT7: =(AE7/BZ7) - 1 -> 0.1779254 | AU7: =(AF7/CA7) - 1 -> 0.36134454 | AV7: =(AG7/CB7) - 1 -> 0.60606061 | AW7: =(AH7/CC7) - 1 -> -0.0081300813 | AX7: =(AI7/CD7) - 1 -> -0.36666667 | AY7: =(AJ7/CE7) - 1 -> -0.047101449 | BA7: 0.3125 | BB7: ='Ferney->Genève'!BB7+'StGenis total'!BB7+'Mategnin Total'!BB7+'PdG Nord Total'!BB7+'PdG Sud Total'!BB7 -> 79 | BC7: ='Ferney->Genève'!BC7+'StGenis total'!BC7+'Mategnin Total'!BC7+'PdG Nord Total'!BC7+'PdG Sud Total'!BC7 -> 28 | BD7: ='Ferney->Genève'!BD7+'StGenis total'!BD7+'Mategnin Total'!BD7+'PdG Nord Total'!BD7+'PdG Sud Total'!BD7 -> 57 | BE7: ='Ferney->Genève'!BE7+'StGenis total'!BE7+'Mategnin Total'!BE7+'PdG Nord Total'!BE7+'PdG Sud Total'!BE7 -> 40 | BF7: ='Ferney->Genève'!BF7+'StGenis total'!BF7+'Mategnin Total'!BF7+'PdG Nord Total'!BF7+'PdG Sud Total'!BF7 -> 14 | BG7: ='Ferney->Genève'!BG7+'StGenis total'!BG7+'Mategnin Total'!BG7+'PdG Nord Total'!BG7+'PdG Sud Total'!BG7 -> 2 | BH7: ='Ferney->Genève'!BH7+'StGenis total'!BH7+'Mategnin Total'!BH7+'PdG Nord Total'!BH7+'PdG Sud Total'!BH7 -> 12 | BI7: ='Ferney->Genève'!BI7+'StGenis total'!BI7+'Mategnin Total'!BI7+'PdG Nord Total'!BI7+'PdG Sud Total'!BI7 -> 14 | ... BQ7: ='Ferney->Genève'!BQ7+'StGenis total'!BQ7+'Mategnin Total'!BQ7+'PdG Nord Total'!BQ7+'PdG Sud Total'!BQ7 -> 3 | BS7: =BB7+BD7+BF7+BH7+BJ7+BL7+BN7+BP7 -> 180 | BT7: =BC7+BE7+BG7+BI7+BK7+BM7+BO7+BQ7 -> 96 | BU7: =BT7/(BT7+BS7) -> 0.34782609 | BV7: =BB7+BC7+BJ7+BK7 -> 123 | BW7: =BD7+BE7+BL7+BM7 -> 103 | BX7: =BF7+BG7+BN7+BO7 -> 17 | BY7: =SUM(BV7:BX7) -> 243 | BZ7: =BW7/(BW7+BV7) -> 0.45575221 | CA7: =BX7/BY7 -> 0.069958848 | CB7: =BH7+BI7+BP7+BQ7 -> 33 | CC7: =SUM(BB7:BI7) -> 246 | CD7: =SUM(BJ7:BQ7) -> 30 | CE7: =SUM(BB7:BQ7) -> 276 | CH7: =(BS7/DN7) - 1 -> 0.17647059 | CI7: =(BT7/DO7) - 1 -> 0.010526316 | CJ7: =(BU7/DP7) - 1 -> -0.091990847 | CK7: =(BV7/DQ7) - 1 -> 0.069565217 | CL7: =(BW7/DR7) - 1 -> 0.03 | CM7: =(BX7/DS7) - 1 -> 0.21428571 | CN7: =(BY7/DT7) - 1 -> 0.061135371 | CO7: =(BZ7/DU7) - 1 -> 0.043672566 | ... CT7: =(CE7/DZ7) - 1 -> 0.11290323 | CV7: 0.3125 | CW7: ='Ferney->Genève'!CW7+'StGenis total'!CW7+'Mategnin Total'!CW7+'PdG Nord Total'!CW7+'PdG Sud Total'!CW7 -> 72 | CX7: ='Ferney->Genève'!CX7+'StGenis total'!CX7+'Mategnin Total'!CX7+'PdG Nord Total'!CX7+'PdG Sud Total'!CX7 -> 26 | CY7: ='Ferney->Genève'!CY7+'StGenis total'!CY7+'Mategnin Total'!CY7+'PdG Nord Total'!CY7+'PdG Sud Total'!CY7 -> 39 | CZ7: ='Ferney->Genève'!CZ7+'StGenis total'!CZ7+'Mategnin Total'!CZ7+'PdG Nord Total'!CZ7+'PdG Sud Total'!CZ7 -> 54 | DA7: ='Ferney->Genève'!DA7+'StGenis total'!DA7+'Mategnin Total'!DA7+'PdG Nord Total'!DA7+'PdG Sud Total'!DA7 -> 11 | DB7: ='Ferney->Genève'!DB7+'StGenis total'!DB7+'Mategnin Total'!DB7+'PdG Nord Total'!DB7+'PdG Sud Total'!DB7 -> 2 | DC7: ='Ferney->Genève'!DC7+'StGenis total'!DC7+'Mategnin Total'!DC7+'PdG Nord Total'!DC7+'PdG Sud Total'!DC7 -> 8 | DD7: ='Ferney->Genève'!DD7+'StGenis total'!DD7+'Mategnin Total'!DD7+'PdG Nord Total'!DD7+'PdG Sud Total'!DD7 -> 7 | ... DL7: ='Ferney->Genève'!DL7+'StGenis total'!DL7+'Mategnin Total'!DL7+'PdG Nord Total'!DL7+'PdG Sud Total'!DL7 -> 1 | DN7: =CW7+CY7+DA7+DC7+DE7+DG7+DI7+DK7 -> 153 | DO7: =CX7+CZ7+DB7+DD7+DF7+DH7+DJ7+DL7 -> 95 | DP7: =DO7/(DO7+DN7) -> 0.38306452 | DQ7: =CW7+CX7+DE7+DF7 -> 115 | DR7: =CY7+CZ7+DG7+DH7 -> 100 | DS7: =DA7+DB7+DI7+DJ7 -> 14 | DT7: =SUM(DQ7:DS7) -> 229 | DU7: =DR7/DT7 -> 0.43668122 | DV7: =DS7/DT7 -> 0.061135371 | DW7: =DC7+DD7+DK7+DL7 -> 19 | DX7: =SUM(CW7:DD7) -> 219 | DY7: =SUM(DE7:DL7) -> 29 | DZ7: =SUM(CW7:DL7) -> 248 | EC7: =(DN7/FI7) - 1 -> 0.40366972 | ED7: =(DO7/FJ7) - 1 -> 0.61016949 | EE7: =(DP7/FK7) - 1 -> 0.090759978 | EF7: =(DQ7/FL7) - 1 -> 0.4556962 | EG7: =(DR7/FM7) - 1 -> 0.58730159 | EH7: =(DS7/FN7) - 1 -> 0.16666667 | EI7: =(DT7/FO7) - 1 -> 0.48701299 | EJ7: =(DU7/FP7) - 1 -> 0.067442989 | ... EO7: =(DZ7/FU7) - 1 -> 0.47619048 | EQ7: 0.3125 | ER7: ='Ferney->Genève'!ER7+'StGenis total'!ER7+'Mategnin Total'!ER7+'PdG Nord Total'!ER7+'PdG Sud Total'!ER7 -> 54 | ES7: ='Ferney->Genève'!ES7+'StGenis total'!ES7+'Mategnin Total'!ES7+'PdG Nord Total'!ES7+'PdG Sud Total'!ES7 -> 21 | ET7: ='Ferney->Genève'!ET7+'StGenis total'!ET7+'Mategnin Total'!ET7+'PdG Nord Total'!ET7+'PdG Sud Total'!ET7 -> 35 | EU7: ='Ferney->Genève'!EU7+'StGenis total'!EU7+'Mategnin Total'!EU7+'PdG Nord Total'!EU7+'PdG Sud Total'!EU7 -> 22 | EV7: ='Ferney->Genève'!EV7+'StGenis total'!EV7+'Mategnin Total'!EV7+'PdG Nord Total'!EV7+'PdG Sud Total'!EV7 -> 6 | EW7: ='Ferney->Genève'!EW7+'StGenis total'!EW7+'Mategnin Total'!EW7+'PdG Nord Total'!EW7+'PdG Sud Total'!EW7 -> 4 | EX7: ='Ferney->Genève'!EX7+'StGenis total'!EX7+'Mategnin Total'!EX7+'PdG Nord Total'!EX7+'PdG Sud Total'!EX7 -> 6 | EY7: ='Ferney->Genève'!EY7+'StGenis total'!EY7+'Mategnin Total'!EY7+'PdG Nord Total'!EY7+'PdG Sud Total'!EY7 -> 6 | ... FG7: ='Ferney->Genève'!FG7+'StGenis total'!FG7+'Mategnin Total'!FG7+'PdG Nord Total'!FG7+'PdG Sud Total'!FG7 -> 0 | FI7: =ER7+ET7+EV7+EX7+EZ7+FB7+FD7+FF7 -> 109 | FJ7: =ES7+EU7+EW7+EY7+FA7+FC7+FE7+FG7 -> 59 | FK7: =FJ7/(FJ7+FI7) -> 0.35119048 | FL7: =ER7+ES7+EZ7+FA7 -> 79 | FM7: =ET7+EU7+FB7+FC7 -> 63 | FN7: =EV7+EW7+FD7+FE7 -> 12 | FO7: =SUM(FL7:FN7) -> 154 | FP7: =FM7/FO7 -> 0.40909091 | FQ7: =FN7/FO7 -> 0.077922078 | FR7: =EX7+EY7+FF7+FG7 -> 14 | FS7: =SUM(ER7:EY7) -> 154 | FT7: =SUM(EZ7:FG7) -> 14 | FU7: =SUM(ER7:FG7) -> 168 | FX7: =(FI7/HD7) - 1 -> 0.1122449 | FY7: =(FJ7/HE7) - 1 -> 0.475 | FZ7: =(FK7/HF7) - 1 -> 0.21160714 | GA7: =(FL7/HG7) - 1 -> 0.25396825 | GB7: =(FM7/HH7) - 1 -> 0.16666667 | GC7: =(FN7/HI7) - 1 -> 2 | GD7: =(FO7/HJ7) - 1 -> 0.27272727 | GE7: =(FP7/HK7) - 1 -> -0.083333333 | ... GJ7: =(FU7/HP7) - 1 -> 0.2173913 | GL7: 0.3125 | GM7: =#REF!+'StGenis total'!GM7+'Mategnin Total'!GM7+'PdG Nord Total'!GM7 -> #REF! | GN7: =#REF!+'StGenis total'!GN7+'Mategnin Total'!GN7+'PdG Nord Total'!GN7 -> #REF! | GO7: =#REF!+'StGenis total'!GO7+'Mategnin Total'!GO7+'PdG Nord Total'!GO7 -> #REF! | GP7: =#REF!+'StGenis total'!GP7+'Mategnin Total'!GP7+'PdG Nord Total'!GP7 -> #REF! | GQ7: =#REF!+'StGenis total'!GQ7+'Mategnin Total'!GQ7+'PdG Nord Total'!GQ7 -> #REF! | GR7: =#REF!+'StGenis total'!GR7+'Mategnin Total'!GR7+'PdG Nord Total'!GR7 -> #REF! | GS7: =#REF!+'StGenis total'!GS7+'Mategnin Total'!GS7+'PdG Nord Total'!GS7 -> #REF! | GT7: =#REF!+'StGenis total'!GT7+'Mategnin Total'!GT7+'PdG Nord Total'!GT7 -> #REF! | ... HB7: =#REF!+'StGenis total'!HB7+'Mategnin Total'!HB7+'PdG Nord Total'!HB7 -> #REF! | HD7: 98 | HE7: 40 | HF7: 0.28985507 | HG7: 63 | HH7: 54 | HI7: 4 | HJ7: 121 | HK7: 0.44628099 | HL7: 0.033057851 | HM7: 17 | HN7: 123 | HO7: 15 | HP7: 138 | HR7: 55 | HS7: 23 | HT7: 0.29487179 | HU7: 52 | HV7: 20 | HW7: 2 | HX7: 74 | HY7: 0.27027027 | HZ7: 0.027027027 | IA7: 4 | IB7: 70 | IC7: 8 | ID7: 78 | IF7: =(HD7/HR7) - 1 -> 0.78181818 | IG7: =(HE7/HS7) - 1 -> 0.73913043 | IH7: =(HF7/HT7) - 1 -> -0.017013233 | II7: =(HG7/HU7) - 1 -> 0.21153846 | IJ7: =(HH7/HV7) - 1 -> 1.7 | IK7: =(HI7/HW7) - 1 -> 1 | IL7: =(HJ7/HX7) - 1 -> 0.63513514 | IM7: =(HK7/HY7) - 1 -> 0.65123967 | ... IR7: =(HP7/ID7) - 1 -> 0.76923077
