Workbook

Sheet Evolution 2
A3: Evolution Mobilité douce (piétons+cyclistes)
C6: 2014 | D6: 2015 | E6: 2016 | F6: 2017 | G6: 2018 | H6: 2019 | I6: 2020 | J6: 2021 | K6: 2022 | L6: 2023 | M6: 2024
B7: Mategnin | C7: 94 | D7: 247 | E7: 237 | F7: 370 | G7: 313 | H7: 387 | I7: 200 | J7: 275 | K7: 357 | L7: 526 | M7: ='Mategnin Total'!AE14 -> 508
B8: Ferney | C8: 231 | D8: 211 | E8: 237 | F8: 311 | G8: 302 | H8: 350 | I8: 160 | J8: 234 | K8: 291 | L8: 398 | M8: ='Ferney->Genève'!AE14 -> 414
B9: StGenis | C9: 354 | D9: 536 | E9: 492 | F9: 710 | G9: 635 | H9: 472 | I9: 250 | J9: 396 | K9: 542 | L9: 669 | M9: ='StGenis total'!AE14 -> 719 | AB9: Traffic voiture | AC9: Moy. Journalière annuelle
B10: TOTAL | C10: 679 | D10: 994 | E10: 966 | F10: 1391 | G10: 1250 | H10: 1209 | I10: 638 | J10: 1030 | K10: 1190 | L10: =SUM(L7:L9) -> 1593 | M10: =SUM(M7:M9) -> 1641 | AB10: Crassier | AC10: 7165
D11: =(D10/C10)-1 -> 0.46391753 | E11: =(E10/D10)-1 -> -0.028169014 | F11: =(F10/E10)-1 -> 0.43995859 | G11: =(G10/F10)-1 -> -0.10136592 | H11: =(H10/G10)-1 -> -0.0328 | I11: =(I10/H10)-1 -> -0.47229115 | J11: =(J10/I10)-1 -> 0.61442006 | K11: =(K10/J10)-1 -> 0.15533981 | ... M11: =(M10/L10)-1 -> 0.030131827 | AB11: Divonne | AC11: 13740
AB12: Sauverny | AC12: 4339
AB13: Versonnex | AC13: 4626
AB14: Vireloup | AC14: 8131
AB15: Ferney | AC15: 13786
AB16: Meyrin | AC16: 24947
AB17: St Jean | AC17: 1659
A18: Evolution Piétons/Cyclistes | AB18: Challex | AC18: 1601
AB19: Collonge | AC19: 1724
AB20: Total | AC20: =SUM(AC10:AC19) -> 81718
AC21: =AC20/2 -> 40859
C22: 2014 | D22: 2015 | E22: 2016 | F22: 2017 | G22: 2018 | H22: 2019 | I22: 2020 | J22: 2021 | K22: 2022 | L22: 2023 | M22: 2024 | AB22: Jours ouvrés one way | AC22: =AC20*0.8/2 -> 32687.2
B23: Cyclistes | C23: 654 | D23: 769 | E23: 781 | F23: 1119 | G23: 1048 | H23: 1049 | I23: 561 | J23: 929 | K23: 1318 | L23: 1884 | M23: ='APiCy total'!S24 -> 1886
B24: Piétons | C24: 143 | D24: 225 | E24: 185 | F24: 272 | G24: 202 | H24: 160 | I24: 77 | J24: 101 | K24: 173 | L24: 186 | M24: ='APiCy total'!AC24 -> 223
B25: TOTAL | C25: 797 | D25: 994 | E25: 966 | F25: 1391 | G25: 1250 | H25: 1209 | I25: 638 | J25: 1030 | K25: 1491 | L25: 2070 | M25: =SUM(M23:M24) -> 2109
A36: EvolutionHommes/Femmes
B38: Année | C38: 2016 | D38: 2017 | E38: 2018 | F38: 2019 | G38: 2020 | H38: 2021 | I38: 2022 | J38: 2023 | K38: 2024
B39: %femme | C39: 0.27150259 | D39: 0.27606039 | E39: 0.2456 | F39: 0.30024814 | G39: 0.35109718 | H39: 0.2936803 | I39: 0.32327297 | J39: 0.33285024 | K39: ='APiCy total'!W24 -> 0.33775186
B40: Hommes | C40: 703 | D40: 1007 | E40: 943 | F40: 846 | G40: 414 | H40: 760 | I40: 1009 | J40: 1381 | K40: ='APiCy total'!S14 -> 1384
B41: Femmes | C41: 262 | D41: 384 | E41: 307 | F41: 363 | G41: 224 | H41: 316 | I41: 482 | J41: 689 | K41: ='APiCy total'!T14 -> 725
B42: Total | C42: 965 | D42: 1391 | E42: 1250 | F42: 1209 | G42: 638 | H42: 1076 | I42: 1491 | J42: 2070 | K42: =SUM(K40:K41) -> 2109
C52: 0.29166667 | D52: 0.30208333 | E52: 0.3125 | F52: 0.32291667 | G52: 0.33333333 | H52: 0.34375 | I52: 0.35416667 | J52: 0.36458333
B53: Pdg Centre | C53: =SUM('PdG Centre Total'!B5:Q5) -> 134 | D53: =SUM('PdG Centre Total'!$B6:$Q6) -> 155 | E53: =SUM('PdG Centre Total'!$B7:$Q7) -> 192 | F53: =SUM('PdG Centre Total'!$B8:$Q8) -> 187 | G53: =SUM('PdG Centre Total'!$B9:$Q9) -> 244 | H53: =SUM('PdG Centre Total'!$B10:$Q10) -> 234 | I53: =SUM('PdG Centre Total'!$B11:$Q11) -> 267 | J53: =SUM('PdG Centre Total'!$B12:$Q12) -> 228
B54: PdG Nord | C54: =SUM('PdG Nord Total'!$B5:$Q5) -> 51 | D54: =SUM('PdG Nord Total'!$B6:$Q6) -> 44 | E54: =SUM('PdG Nord Total'!$B7:$Q7) -> 79 | F54: =SUM('PdG Nord Total'!$B8:$Q8) -> 55 | G54: =SUM('PdG Nord Total'!$B9:$Q9) -> 73 | H54: =SUM('PdG Nord Total'!$B10:$Q10) -> 51 | I54: =SUM('PdG Nord Total'!$B11:$Q11) -> 59 | J54: =SUM('PdG Nord Total'!$B12:$Q12) -> 40
B55: Total | C55: =SUM(C53:C54) -> 185 | D55: =SUM(D53:D54) -> 199 | E55: =SUM(E53:E54) -> 271 | F55: =SUM(F53:F54) -> 242 | G55: =SUM(G53:G54) -> 317 | H55: =SUM(H53:H54) -> 285 | I55: =SUM(I53:I54) -> 326 | J55: =SUM(J53:J54) -> 268
C58: =C52 -> 0.29166667 | D58: =D52 -> 0.30208333 | E58: =E52 -> 0.3125 | F58: =F52 -> 0.32291667 | G58: =G52 -> 0.33333333 | H58: =H52 -> 0.34375 | I58: =I52 -> 0.35416667 | J58: =J52 -> 0.36458333
B59: PdG Nord | C59: =C53/SUM($C53:$J53) -> 0.081657526 | D59: =D53/SUM($C53:$J53) -> 0.094454601 | E59: =E53/SUM($C53:$J53) -> 0.11700183 | F59: =F53/SUM($C53:$J53) -> 0.11395491 | G59: =G53/SUM($C53:$J53) -> 0.14868982 | H59: =H53/SUM($C53:$J53) -> 0.14259598 | I59: =I53/SUM($C53:$J53) -> 0.16270567 | J59: =J53/SUM($C53:$J53) -> 0.13893967
B60: Pdg Centre | C60: =C54/SUM($C54:$J54) -> 0.11283186 | D60: =D54/SUM($C54:$J54) -> 0.097345133 | E60: =E54/SUM($C54:$J54) -> 0.17477876 | F60: =F54/SUM($C54:$J54) -> 0.12168142 | G60: =G54/SUM($C54:$J54) -> 0.16150442 | H60: =H54/SUM($C54:$J54) -> 0.11283186 | I60: =I54/SUM($C54:$J54) -> 0.13053097 | J60: =J54/SUM($C54:$J54) -> 0.088495575
A65: Evolution par mode
C68: 2020 | D68: 2021 | E68: 2022 | F68: 2023 | G68: 2024
B69: Vélo | C69: ='APiCy total'!FU14 -> 344 | D69: ='APiCy total'!FG14 -> 582 | E69: ='APiCy total'!DL14 -> 752 | F69: ='APiCy total'!BQ14 -> 1017 | G69: ='APiCy total'!V14 -> 945
B70: VAE | C70: ='APiCy total'!FV14 -> 175 | D70: ='APiCy total'!FH14 -> 337 | E70: ='APiCy total'!DM14 -> 498 | F70: ='APiCy total'!BR14 -> 752 | G70: ='APiCy total'!W14 -> 809
B71: Nouveau | C71: ='APiCy total'!FW14 -> 42 | D71: ='APiCy total'!FI14 -> 46 | E71: ='APiCy total'!DN14 -> 68 | F71: ='APiCy total'!BS14 -> 115 | G71: ='APiCy total'!X14 -> 132
B72: TOTAL | C72: =SUM(C69:C71) -> 561 | D72: =SUM(D69:D71) -> 965 | E72: =SUM(E69:E71) -> 1318 | F72: =SUM(F69:F71) -> 1884 | G72: =SUM(G69:G71) -> 1886
...

Sheet Resume
B1: DONNEES 2024 | P1: CHANGEMENT
B2: Hommes | C2: Femmes | D2: %Femmes | E2: VT | F2: VAE | G2: Nouveau | H2: 2r | I2: %VAE | J2: %Nouveau | K2: Piétons | L2: >FR | M2: >CH | N2: TOT | P2: Hommes | Q2: Femmes | R2: %Femmes | S2: VT | T2: VAE | U2: Nouveau | V2: 2r | W2: %VAE | X2: %Nouveau | Y2: Piétons | Z2: >CH | AA2: >FR | AB2: TOT
A3: Ferney->Genève | B3: {=INDIRECT( "'" & $A3 & "'"& "!" & B$33)} -> 243 | C3: {=INDIRECT( "'" & $A3 & "'"& "!" & C$33)} -> 171 | D3: {=INDIRECT( "'" & $A3 & "'"& "!" & D$33)} -> 0.41304348 | E3: {=INDIRECT( "'" & $A3 & "'"& "!" & E$33)} -> 167 | F3: {=INDIRECT( "'" & $A3 & "'"& "!" & F$33)} -> 203 | G3: {=INDIRECT( "'" & $A3 & "'"& "!" & G$33)} -> 29 | H3: {=INDIRECT( "'" & $A3 & "'"& "!" & H$33)} -> 399 | I3: {=INDIRECT( "'" & $A3 & "'"& "!" & I$33)} -> 0.50877193 | ... N3: {=INDIRECT( "'" & $A3 & "'"& "!" & N$33)} -> 414 | P3: {=INDIRECT( "'" & $A3 & "'"& "!" & P$33)} -> 0.038461538 | Q3: {=INDIRECT( "'" & $A3 & "'"& "!" & Q$33)} -> 0.042682927 | R3: {=INDIRECT( "'" & $A3 & "'"& "!" & R$33)} -> 0.0023860021 | S3: {=INDIRECT( "'" & $A3 & "'"& "!" & S$33)} -> 0.04375 | T3: {=INDIRECT( "'" & $A3 & "'"& "!" & T$33)} -> -0.024038462 | U3: {=INDIRECT( "'" & $A3 & "'"& "!" & U$33)} -> 0.31818182 | V3: {=INDIRECT( "'" & $A3 & "'"& "!" & V$33)} -> 0.023076923 | W3: {=INDIRECT( "'" & $A3 & "'"& "!" & W$33)} -> -0.046052632 | ... AB3: {=INDIRECT( "'" & $A3 & "'"& "!" & AB$33)} -> 0.040201005
A5: StGenis->Meyrin | B5: {=INDIRECT( "'" & $A5 & "'"& "!" & B$33)} -> 299 | C5: {=INDIRECT( "'" & $A5 & "'"& "!" & C$33)} -> 147 | D5: {=INDIRECT( "'" & $A5 & "'"& "!" & D$33)} -> 0.32959641 | E5: {=INDIRECT( "'" & $A5 & "'"& "!" & E$33)} -> 192 | F5: {=INDIRECT( "'" & $A5 & "'"& "!" & F$33)} -> 184 | G5: {=INDIRECT( "'" & $A5 & "'"& "!" & G$33)} -> 41 | H5: {=INDIRECT( "'" & $A5 & "'"& "!" & H$33)} -> 417 | I5: {=INDIRECT( "'" & $A5 & "'"& "!" & I$33)} -> 0.441247 | ... N5: {=INDIRECT( "'" & $A5 & "'"& "!" & N$33)} -> 446 | P5: {=INDIRECT( "'" & $A5 & "'"& "!" & P$33)} -> 0.091240876 | Q5: {=INDIRECT( "'" & $A5 & "'"& "!" & Q$33)} -> 0.1221374 | R5: {=INDIRECT( "'" & $A5 & "'"& "!" & R$33)} -> 0.018981275 | S5: {=INDIRECT( "'" & $A5 & "'"& "!" & S$33)} -> -0.04950495 | T5: {=INDIRECT( "'" & $A5 & "'"& "!" & T$33)} -> 0.27777778 | U5: {=INDIRECT( "'" & $A5 & "'"& "!" & U$33)} -> 0.20588235 | V5: {=INDIRECT( "'" & $A5 & "'"& "!" & V$33)} -> 0.097368421 | W5: {=INDIRECT( "'" & $A5 & "'"& "!" & W$33)} -> 0.16440181 | ... AB5: {=INDIRECT( "'" & $A5 & "'"& "!" & AB$33)} -> 0.10123457
A6: StGenis->Bourdigny | B6: {=INDIRECT( "'" & $A6 & "'"& "!" & B$33)} -> 49 | C6: {=INDIRECT( "'" & $A6 & "'"& "!" & C$33)} -> 0 | D6: {=INDIRECT( "'" & $A6 & "'"& "!" & D$33)} -> 0 | E6: {=INDIRECT( "'" & $A6 & "'"& "!" & E$33)} -> 47 | F6: {=INDIRECT( "'" & $A6 & "'"& "!" & F$33)} -> 0 | G6: {=INDIRECT( "'" & $A6 & "'"& "!" & G$33)} -> 1 | H6: {=INDIRECT( "'" & $A6 & "'"& "!" & H$33)} -> 48 | I6: {=INDIRECT( "'" & $A6 & "'"& "!" & I$33)} -> 0 | ... N6: {=INDIRECT( "'" & $A6 & "'"& "!" & N$33)} -> 49 | P6: {=INDIRECT( "'" & $A6 & "'"& "!" & P$33)} -> -0.16949153 | Q6: {=INDIRECT( "'" & $A6 & "'"& "!" & Q$33)} -> #DIV/0! | R6: {=INDIRECT( "'" & $A6 & "'"& "!" & R$33)} -> #DIV/0! | S6: {=INDIRECT( "'" & $A6 & "'"& "!" & S$33)} -> -0.16071429 | T6: {=INDIRECT( "'" & $A6 & "'"& "!" & T$33)} -> #DIV/0! | U6: {=INDIRECT( "'" & $A6 & "'"& "!" & U$33)} -> -0.5 | V6: {=INDIRECT( "'" & $A6 & "'"& "!" & V$33)} -> -0.17241379 | W6: {=INDIRECT( "'" & $A6 & "'"& "!" & W$33)} -> #DIV/0! | ... AB6: {=INDIRECT( "'" & $A6 & "'"& "!" & AB$33)} -> -0.16949153
A7: StGenis->CERN | B7: {=INDIRECT( "'" & $A7 & "'"& "!" & B$33)} -> 163 | C7: {=INDIRECT( "'" & $A7 & "'"& "!" & C$33)} -> 61 | D7: {=INDIRECT( "'" & $A7 & "'"& "!" & D$33)} -> 0.27232143 | E7: {=INDIRECT( "'" & $A7 & "'"& "!" & E$33)} -> 130 | F7: {=INDIRECT( "'" & $A7 & "'"& "!" & F$33)} -> 28 | G7: {=INDIRECT( "'" & $A7 & "'"& "!" & G$33)} -> 7 | H7: {=INDIRECT( "'" & $A7 & "'"& "!" & H$33)} -> 165 | I7: {=INDIRECT( "'" & $A7 & "'"& "!" & I$33)} -> 0.16969697 | ... N7: {=INDIRECT( "'" & $A7 & "'"& "!" & N$33)} -> 224 | P7: {=INDIRECT( "'" & $A7 & "'"& "!" & P$33)} -> -0.029761905 | Q7: {=INDIRECT( "'" & $A7 & "'"& "!" & Q$33)} -> 0.64864865 | R7: {=INDIRECT( "'" & $A7 & "'"& "!" & R$33)} -> 0.50880792 | S7: {=INDIRECT( "'" & $A7 & "'"& "!" & S$33)} -> -0.057971014 | T7: {=INDIRECT( "'" & $A7 & "'"& "!" & T$33)} -> #DIV/0! | U7: {=INDIRECT( "'" & $A7 & "'"& "!" & U$33)} -> -0.22222222 | V7: {=INDIRECT( "'" & $A7 & "'"& "!" & V$33)} -> 0.12244898 | W7: {=INDIRECT( "'" & $A7 & "'"& "!" & W$33)} -> #DIV/0! | ... AB7: {=INDIRECT( "'" & $A7 & "'"& "!" & AB$33)} -> 0.092682927
A8: RteEurope->Meyrin
A9: StGenis Total | B9: =SUM(B5:B8) -> 511 | C9: =SUM(C5:C8) -> 208 | D9: =C9/(B9+C9) -> 0.28929068 | E9: =SUM(E5:E8) -> 369 | F9: =SUM(F5:F8) -> 212 | G9: =SUM(G5:G8) -> 49 | H9: =SUM(H5:H8) -> 630 | I9: =F9/H9 -> 0.33650794 | J9: =G9/H9 -> 0.077777778 | K9: =SUM(K5:K8) -> 89 | L9: =SUM(L5:L8) -> 690 | M9: =SUM(M5:M8) -> 29 | N9: =SUM(N5:N8) -> 719 | P9: {=INDIRECT( "'" & $A9 & "'"& "!" & P$33)} -> 0.01996008 | Q9: {=INDIRECT( "'" & $A9 & "'"& "!" & Q$33)} -> 0.23809524 | R9: {=INDIRECT( "'" & $A9 & "'"& "!" & R$33)} -> 0.15199682 | S9: {=INDIRECT( "'" & $A9 & "'"& "!" & S$33)} -> -0.068181818 | T9: {=INDIRECT( "'" & $A9 & "'"& "!" & T$33)} -> 0.47222222 | U9: {=INDIRECT( "'" & $A9 & "'"& "!" & U$33)} -> 0.088888889 | V9: {=INDIRECT( "'" & $A9 & "'"& "!" & V$33)} -> 0.076923077 | W9: {=INDIRECT( "'" & $A9 & "'"& "!" & W$33)} -> 0.36706349 | ... AB9: {=INDIRECT( "'" & $A9 & "'"& "!" & AB$33)} -> 0.074738416
A11: MategninAnneaux | B11: {=INDIRECT( "'" & $A11 & "'"& "!" & B$33)} -> 220 | C11: {=INDIRECT( "'" & $A11 & "'"& "!" & C$33)} -> 103 | D11: {=INDIRECT( "'" & $A11 & "'"& "!" & D$33)} -> 0.31888545 | E11: {=INDIRECT( "'" & $A11 & "'"& "!" & E$33)} -> 140 | F11: {=INDIRECT( "'" & $A11 & "'"& "!" & F$33)} -> 136 | G11: {=INDIRECT( "'" & $A11 & "'"& "!" & G$33)} -> 23 | H11: {=INDIRECT( "'" & $A11 & "'"& "!" & H$33)} -> 299 | I11: {=INDIRECT( "'" & $A11 & "'"& "!" & I$33)} -> 0.4548495 | ... N11: {=INDIRECT( "'" & $A11 & "'"& "!" & N$33)} -> 323 | P11: {=INDIRECT( "'" & $A11 & "'"& "!" & P$33)} -> -0.030837004 | Q11: {=INDIRECT( "'" & $A11 & "'"& "!" & Q$33)} -> -0.055045872 | R11: {=INDIRECT( "'" & $A11 & "'"& "!" & R$33)} -> -0.017013662 | S11: {=INDIRECT( "'" & $A11 & "'"& "!" & S$33)} -> -0.078947368 | T11: {=INDIRECT( "'" & $A11 & "'"& "!" & T$33)} -> -0.074829932 | U11: {=INDIRECT( "'" & $A11 & "'"& "!" & U$33)} -> 0.35294118 | V11: {=INDIRECT( "'" & $A11 & "'"& "!" & V$33)} -> -0.053797468 | W11: {=INDIRECT( "'" & $A11 & "'"& "!" & W$33)} -> -0.022228289 | ... AB11: {=INDIRECT( "'" & $A11 & "'"& "!" & AB$33)} -> -0.038690476
A12: MategninDouane | B12: {=INDIRECT( "'" & $A12 & "'"& "!" & B$33)} -> 119 | C12: {=INDIRECT( "'" & $A12 & "'"& "!" & C$33)} -> 66 | D12: {=INDIRECT( "'" & $A12 & "'"& "!" & D$33)} -> 0.35675676 | E12: {=INDIRECT( "'" & $A12 & "'"& "!" & E$33)} -> 77 | F12: {=INDIRECT( "'" & $A12 & "'"& "!" & F$33)} -> 80 | G12: {=INDIRECT( "'" & $A12 & "'"& "!" & G$33)} -> 14 | H12: {=INDIRECT( "'" & $A12 & "'"& "!" & H$33)} -> 171 | I12: {=INDIRECT( "'" & $A12 & "'"& "!" & I$33)} -> 0.46783626 | ... N12: {=INDIRECT( "'" & $A12 & "'"& "!" & N$33)} -> 185 | P12: {=INDIRECT( "'" & $A12 & "'"& "!" & P$33)} -> -0.016528926 | Q12: {=INDIRECT( "'" & $A12 & "'"& "!" & Q$33)} -> -0.043478261 | R12: {=INDIRECT( "'" & $A12 & "'"& "!" & R$33)} -> -0.017626322 | S12: {=INDIRECT( "'" & $A12 & "'"& "!" & S$33)} -> -0.0375 | T12: {=INDIRECT( "'" & $A12 & "'"& "!" & T$33)} -> 0.095890411 | U12: {=INDIRECT( "'" & $A12 & "'"& "!" & U$33)} -> 0.75 | V12: {=INDIRECT( "'" & $A12 & "'"& "!" & V$33)} -> 0.062111801 | W12: {=INDIRECT( "'" & $A12 & "'"& "!" & W$33)} -> 0.031803252 | ... AB12: {=INDIRECT( "'" & $A12 & "'"& "!" & AB$33)} -> -0.026315789
A13: Mategnin Total | B13: =SUM(B11:B12) -> 339 | C13: =SUM(C11:C12) -> 169 | D13: =C13/(B13+C13) -> 0.33267717 | E13: =SUM(E11:E12) -> 217 | F13: =SUM(F11:F12) -> 216 | G13: =SUM(G11:G12) -> 37 | H13: =SUM(H11:H12) -> 470 | I13: =F13/H13 -> 0.45957447 | J13: =G13/H13 -> 0.078723404 | K13: =SUM(K11:K12) -> 38 | L13: =SUM(L11:L12) -> 453 | M13: =SUM(M11:M12) -> 55 | N13: =SUM(N11:N12) -> 508 | P13: {=INDIRECT( "'" & $A13 & "'"& "!" & P$33)} -> -0.025862069 | Q13: {=INDIRECT( "'" & $A13 & "'"& "!" & Q$33)} -> -0.050561798 | R13: {=INDIRECT( "'" & $A13 & "'"& "!" & R$33)} -> -0.016920287 | S13: {=INDIRECT( "'" & $A13 & "'"& "!" & S$33)} -> -0.064655172 | T13: {=INDIRECT( "'" & $A13 & "'"& "!" & T$33)} -> -0.018181818 | U13: {=INDIRECT( "'" & $A13 & "'"& "!" & U$33)} -> 0.48 | V13: {=INDIRECT( "'" & $A13 & "'"& "!" & V$33)} -> -0.014675052 | W13: {=INDIRECT( "'" & $A13 & "'"& "!" & W$33)} -> -0.0035589942 | ... AB13: {=INDIRECT( "'" & $A13 & "'"& "!" & AB$33)} -> -0.034220532
A15: PdG Centre Total | B15: =B13+B9+B3 -> 1093 | C15: =C13+C9+C3 -> 548 | D15: =C15/(B15+C15) -> 0.33394272 | E15: =E13+E9+E3 -> 753 | F15: =F13+F9+F3 -> 631 | G15: =G13+G9+G3 -> 115 | H15: =H13+H9+H3 -> 1499 | I15: =F15/H15 -> 0.4209473 | J15: =G15/H15 -> 0.076717812 | K15: =K13+K9+K3 -> 142 | L15: =L13+L9+L3 -> 1546 | M15: =M13+M9+M3 -> 95 | N15: =N13+N9+N3 -> 1641 | P15: {=INDIRECT( "'" & $A15 & "'"& "!" & P$33)} -> 0.0092336103 | Q15: {=INDIRECT( "'" & $A15 & "'"& "!" & Q$33)} -> 0.074509804 | R15: {=INDIRECT( "'" & $A15 & "'"& "!" & R$33)} -> 0.043079901 | S15: {=INDIRECT( "'" & $A15 & "'"& "!" & S$33)} -> -0.044416244 | T15: {=INDIRECT( "'" & $A15 & "'"& "!" & T$33)} -> 0.10314685 | U15: {=INDIRECT( "'" & $A15 & "'"& "!" & U$33)} -> 0.25 | V15: {=INDIRECT( "'" & $A15 & "'"& "!" & V$33)} -> 0.032369146 | W15: {=INDIRECT( "'" & $A15 & "'"& "!" & W$33)} -> 0.068558526 | ... AB15: {=INDIRECT( "'" & $A15 & "'"& "!" & AB$33)} -> 0.030131827
A17: Vireloup Douane | B17: {=INDIRECT( "'" & $A17 & "'"& "!" & B$33)} -> 93 | C17: {=INDIRECT( "'" & $A17 & "'"& "!" & C$33)} -> 64 | D17: {=INDIRECT( "'" & $A17 & "'"& "!" & D$33)} -> 0.40764331 | E17: {=INDIRECT( "'" & $A17 & "'"& "!" & E$33)} -> 57 | F17: {=INDIRECT( "'" & $A17 & "'"& "!" & F$33)} -> 64 | G17: {=INDIRECT( "'" & $A17 & "'"& "!" & G$33)} -> 10 | H17: {=INDIRECT( "'" & $A17 & "'"& "!" & H$33)} -> 131 | I17: {=INDIRECT( "'" & $A17 & "'"& "!" & I$33)} -> 0.48854962 | ... N17: {=INDIRECT( "'" & $A17 & "'"& "!" & N$33)} -> 157 | P17: {=INDIRECT( "'" & $A17 & "'"& "!" & P$33)} -> -0.14678899 | Q17: {=INDIRECT( "'" & $A17 & "'"& "!" & Q$33)} -> -0.17948718 | R17: {=INDIRECT( "'" & $A17 & "'"& "!" & R$33)} -> -0.02270129 | S17: {=INDIRECT( "'" & $A17 & "'"& "!" & S$33)} -> -0.44660194 | T17: {=INDIRECT( "'" & $A17 & "'"& "!" & T$33)} -> -0.044776119 | U17: {=INDIRECT( "'" & $A17 & "'"& "!" & U$33)} -> -0.23076923 | V17: {=INDIRECT( "'" & $A17 & "'"& "!" & V$33)} -> -0.28415301 | W17: {=INDIRECT( "'" & $A17 & "'"& "!" & W$33)} -> 0.33439672 | ... AB17: {=INDIRECT( "'" & $A17 & "'"& "!" & AB$33)} -> -0.16042781
A18: Versonnex | B18: {=INDIRECT( "'" & $A18 & "'"& "!" & B$33)} -> 44 | C18: {=INDIRECT( "'" & $A18 & "'"& "!" & C$33)} -> 21 | D18: {=INDIRECT( "'" & $A18 & "'"& "!" & D$33)} -> 0.32307692 | E18: {=INDIRECT( "'" & $A18 & "'"& "!" & E$33)} -> 23 | F18: {=INDIRECT( "'" & $A18 & "'"& "!" & F$33)} -> 41 | G18: {=INDIRECT( "'" & $A18 & "'"& "!" & G$33)} -> 0 | H18: {=INDIRECT( "'" & $A18 & "'"& "!" & H$33)} -> 64 | I18: {=INDIRECT( "'" & $A18 & "'"& "!" & I$33)} -> 0.640625 | ... N18: {=INDIRECT( "'" & $A18 & "'"& "!" & N$33)} -> 65 | P18: {=INDIRECT( "'" & $A18 & "'"& "!" & P$33)} -> -0.29032258 | Q18: {=INDIRECT( "'" & $A18 & "'"& "!" & Q$33)} -> -0.25 | R18: {=INDIRECT( "'" & $A18 & "'"& "!" & R$33)} -> 0.038461538 | S18: {=INDIRECT( "'" & $A18 & "'"& "!" & S$33)} -> -0.46511628 | T18: {=INDIRECT( "'" & $A18 & "'"& "!" & T$33)} -> -0.10869565 | U18: {=INDIRECT( "'" & $A18 & "'"& "!" & U$33)} -> -1 | V18: {=INDIRECT( "'" & $A18 & "'"& "!" & V$33)} -> -0.28888889 | W18: {=INDIRECT( "'" & $A18 & "'"& "!" & W$33)} -> 0.25339674 | ... AB18: {=INDIRECT( "'" & $A18 & "'"& "!" & AB$33)} -> -0.27777778
A19: Sauverny | B19: {=INDIRECT( "'" & $A19 & "'"& "!" & B$33)} -> 43 | C19: {=INDIRECT( "'" & $A19 & "'"& "!" & C$33)} -> 26 | D19: {=INDIRECT( "'" & $A19 & "'"& "!" & D$33)} -> 0.37681159 | E19: {=INDIRECT( "'" & $A19 & "'"& "!" & E$33)} -> 24 | F19: {=INDIRECT( "'" & $A19 & "'"& "!" & F$33)} -> 18 | G19: {=INDIRECT( "'" & $A19 & "'"& "!" & G$33)} -> 1 | H19: {=INDIRECT( "'" & $A19 & "'"& "!" & H$33)} -> 43 | I19: {=INDIRECT( "'" & $A19 & "'"& "!" & I$33)} -> 0.41860465 | ... N19: {=INDIRECT( "'" & $A19 & "'"& "!" & N$33)} -> 69
A20: Divonne->Chavanne | B20: {=INDIRECT( "'" & $A20 & "'"& "!" & B$33)} -> 56 | C20: {=INDIRECT( "'" & $A20 & "'"& "!" & C$33)} -> 42 | D20: {=INDIRECT( "'" & $A20 & "'"& "!" & D$33)} -> 0.42857143 | E20: {=INDIRECT( "'" & $A20 & "'"& "!" & E$33)} -> 62 | F20: {=INDIRECT( "'" & $A20 & "'"& "!" & F$33)} -> 27 | G20: {=INDIRECT( "'" & $A20 & "'"& "!" & G$33)} -> 2 | H20: {=INDIRECT( "'" & $A20 & "'"& "!" & H$33)} -> 91 | I20: {=INDIRECT( "'" & $A20 & "'"& "!" & I$33)} -> 0.2967033 | ... N20: {=INDIRECT( "'" & $A20 & "'"& "!" & N$33)} -> 98 | P20: {=INDIRECT( "'" & $A20 & "'"& "!" & P$33)} -> 0.018181818 | Q20: {=INDIRECT( "'" & $A20 & "'"& "!" & Q$33)} -> 0.5 | R20: {=INDIRECT( "'" & $A20 & "'"& "!" & R$33)} -> 0.27040816 | S20: {=INDIRECT( "'" & $A20 & "'"& "!" & S$33)} -> 0.34782609 | T20: {=INDIRECT( "'" & $A20 & "'"& "!" & T$33)} -> 0.42105263 | U20: {=INDIRECT( "'" & $A20 & "'"& "!" & U$33)} -> -0.6 | V20: {=INDIRECT( "'" & $A20 & "'"& "!" & V$33)} -> 0.3 | W20: {=INDIRECT( "'" & $A20 & "'"& "!" & W$33)} -> 0.093117409 | ... AB20: {=INDIRECT( "'" & $A20 & "'"& "!" & AB$33)} -> 0.18072289
A21: Crassier Voie Verte | B21: {=INDIRECT( "'" & $A21 & "'"& "!" & B$33)} -> 28 | C21: {=INDIRECT( "'" & $A21 & "'"& "!" & C$33)} -> 11 | D21: {=INDIRECT( "'" & $A21 & "'"& "!" & D$33)} -> 0.28205128 | E21: {=INDIRECT( "'" & $A21 & "'"& "!" & E$33)} -> 7 | F21: {=INDIRECT( "'" & $A21 & "'"& "!" & F$33)} -> 16 | G21: {=INDIRECT( "'" & $A21 & "'"& "!" & G$33)} -> 0 | H21: {=INDIRECT( "'" & $A21 & "'"& "!" & H$33)} -> 23 | I21: {=INDIRECT( "'" & $A21 & "'"& "!" & I$33)} -> 0.69565217 | ... N21: {=INDIRECT( "'" & $A21 & "'"& "!" & N$33)} -> 39 | P21: {=INDIRECT( "'" & $A21 & "'"& "!" & P$33)} -> -0.17647059 | Q21: {=INDIRECT( "'" & $A21 & "'"& "!" & Q$33)} -> -0.38888889 | R21: {=INDIRECT( "'" & $A21 & "'"& "!" & R$33)} -> -0.18518519 | S21: {=INDIRECT( "'" & $A21 & "'"& "!" & S$33)} -> -0.58823529 | T21: {=INDIRECT( "'" & $A21 & "'"& "!" & T$33)} -> -0.36 | U21: {=INDIRECT( "'" & $A21 & "'"& "!" & U$33)} -> -1 | V21: {=INDIRECT( "'" & $A21 & "'"& "!" & V$33)} -> -0.47727273 | W21: {=INDIRECT( "'" & $A21 & "'"& "!" & W$33)} -> 0.22434783 | ... AB21: {=INDIRECT( "'" & $A21 & "'"& "!" & AB$33)} -> -0.25
A22: Crassier Douane | B22: {=INDIRECT( "'" & $A22 & "'"& "!" & B$33)} -> 18 | C22: {=INDIRECT( "'" & $A22 & "'"& "!" & C$33)} -> 6 | D22: {=INDIRECT( "'" & $A22 & "'"& "!" & D$33)} -> 0.25 | E22: {=INDIRECT( "'" & $A22 & "'"& "!" & E$33)} -> 12 | F22: {=INDIRECT( "'" & $A22 & "'"& "!" & F$33)} -> 7 | G22: {=INDIRECT( "'" & $A22 & "'"& "!" & G$33)} -> 1 | H22: {=INDIRECT( "'" & $A22 & "'"& "!" & H$33)} -> 20 | I22: {=INDIRECT( "'" & $A22 & "'"& "!" & I$33)} -> 0.35 | ... N22: {=INDIRECT( "'" & $A22 & "'"& "!" & N$33)} -> 24 | P22: {=INDIRECT( "'" & $A22 & "'"& "!" & P$33)} -> 3.5 | Q22: {=INDIRECT( "'" & $A22 & "'"& "!" & Q$33)} -> 1 | R22: {=INDIRECT( "'" & $A22 & "'"& "!" & R$33)} -> -0.41666667 | S22: {=INDIRECT( "'" & $A22 & "'"& "!" & S$33)} -> 5 | T22: {=INDIRECT( "'" & $A22 & "'"& "!" & T$33)} -> 0.4 | U22: {=INDIRECT( "'" & $A22 & "'"& "!" & U$33)} -> #DIV/0! | V22: {=INDIRECT( "'" & $A22 & "'"& "!" & V$33)} -> 1.8571429 | W22: {=INDIRECT( "'" & $A22 & "'"& "!" & W$33)} -> -0.51 | ... AB22: {=INDIRECT( "'" & $A22 & "'"& "!" & AB$33)} -> 2.4285714
A23: PdG Nord Total | B23: =SUM(B17:B22) -> 282 | C23: =SUM(C17:C22) -> 170 | D23: =C23/(B23+C23) -> 0.37610619 | E23: =SUM(E17:E22) -> 185 | F23: =SUM(F17:F22) -> 173 | G23: =SUM(G17:G22) -> 14 | H23: =SUM(H17:H22) -> 372 | I23: =F23/H23 -> 0.46505376 | J23: =G23/H23 -> 0.037634409 | K23: =SUM(K17:K22) -> 80 | L23: =SUM(L17:L22) -> 328 | M23: =SUM(M17:M22) -> 124 | N23: =SUM(N17:N22) -> 452 | P23: {=INDIRECT( "'" & $A23 & "'"& "!" & P$33)} -> -0.053691275 | Q23: {=INDIRECT( "'" & $A23 & "'"& "!" & Q$33)} -> -0.05027933 | R23: {=INDIRECT( "'" & $A23 & "'"& "!" & R$33)} -> 0.0022494685 | S23: {=INDIRECT( "'" & $A23 & "'"& "!" & S$33)} -> -0.19213974 | T23: {=INDIRECT( "'" & $A23 & "'"& "!" & T$33)} -> -0.038888889 | U23: {=INDIRECT( "'" & $A23 & "'"& "!" & U$33)} -> -0.39130435 | V23: {=INDIRECT( "'" & $A23 & "'"& "!" & V$33)} -> -0.13888889 | W23: {=INDIRECT( "'" & $A23 & "'"& "!" & W$33)} -> 0.11612903 | ... AB23: {=INDIRECT( "'" & $A23 & "'"& "!" & AB$33)} -> -0.052410901
A25: StJeanDeG
A26: Challex->Dardagny
A27: Challex->LaPlaine
A28: Pougny
A29: PdG Sud Total
A31: APiCy total | B31: =B23+B15+B29 -> 1375 | C31: =C23+C15+C29 -> 718 | D31: =C31/(C31+B31) -> 0.34304826 | E31: =E23+E15+E29 -> 938 | F31: =F23+F15+F29 -> 804 | G31: =G23+G15+G29 -> 129 | H31: =H23+H15+H29 -> 1871 | I31: =F31/H31 -> 0.42971673 | J31: =G31/H31 -> 0.068947087 | K31: =K23+K15+K29 -> 222 | L31: =L23+L15+L29 -> 1874 | M31: =M23+M15+M29 -> 219 | N31: =N23+N15+N29 -> 2093 | P31: {=INDIRECT( "'" & $A31 & "'"& "!" & P$33)} -> 0.0021723389 | Q31: {=INDIRECT( "'" & $A31 & "'"& "!" & Q$33)} -> 0.052249637 | R31: {=INDIRECT( "'" & $A31 & "'"& "!" & R$33)} -> 0.032791251 | S31: {=INDIRECT( "'" & $A31 & "'"& "!" & S$33)} -> -0.07079646 | T31: {=INDIRECT( "'" & $A31 & "'"& "!" & T$33)} -> 0.075797872 | U31: {=INDIRECT( "'" & $A31 & "'"& "!" & U$33)} -> 0.14782609 | V31: {=INDIRECT( "'" & $A31 & "'"& "!" & V$33)} -> 0.0010615711 | W31: {=INDIRECT( "'" & $A31 & "'"& "!" & W$33)} -> 0.074657047 | ... AB31: {=INDIRECT( "'" & $A31 & "'"& "!" & AB$33)} -> 0.01884058
B33: S14 | C33: T14 | D33: U14 | E33: V14 | F33: W14 | G33: X14 | H33: Y14 | I33: Z14 | J33: AA14 | K33: AB14 | L33: AC14 | M33: AD14 | N33: AE14 | P33: AH14 | Q33: AI14 | R33: AJ14 | S33: AK14 | T33: AL14 | U33: AM14 | V33: AN14 | W33: AO14 | X33: AP14 | Y33: AQ14 | Z33: AR14 | AA33: AS14 | AB33: AT14

Sheet Sheet1
B1: Association(s) | C1: Arrière-pays | D1: Nombre de bénévoles | E1: Postes de comptage | F1: France / Suisse / Frontière | G1: Nombre de vélos | I1: % VAE dans le total | J1: NB VAE dans le total | K1: % femmes dans le total | L1: NB de femmes dans le total | M1: % de VAE chez les femmes | N1: NB de VAE chez les femmes | O1: Autres modes | Q1: Piétons | S1: > Suisse | U1: > France
G3: total | H3: HP | O3: total | P3: HP | Q3: total | R3: HP | S3: total | T3: HP | U3: total | V3: HP
B4: APiCy (Association des Piétons et Cyclistes du Pays de Gex) + ProVélo La Côte et ATE Vaud | C4: NON | D4: 23 | E4: STJEAN_Douane de Dardagny | F4: Frontière
E5: CHALLEX_Douane de La Plaine | F5: Frontière
E6: POUGNY_Douane de Chancy | F6: Frontière
E7: ST-GENIS_Giratoire Porte de France | F7: Frontière | I7: =J7/G7 -> #DIV/0! | K7: =L7/G7 -> #DIV/0! | M7: =IF(N7="-","-",N7/L7) -> #DIV/0!
E8: FERNEY_Douane du GdSaconnex | F8: Frontière | I8: =J8/G8 -> #DIV/0! | K8: =L8/G8 -> #DIV/0! | M8: =IF(N8="-","-",N8/L8) -> #DIV/0!
E9: FERNEY_Douane de Mategnin | F9: Frontière | I9: =J9/G9 -> #DIV/0! | K9: =L9/G9 -> #DIV/0! | M9: =IF(N9="-","-",N9/L9) -> #DIV/0!
E10: FERNEY_Douane de Vireloup | F10: Frontière | I10: =J10/G10 -> #DIV/0! | K10: =L10/G10 -> #DIV/0! | M10: =IF(N10="-","-",N10/L10) -> #DIV/0!
E11: VERSONNEX_Douane de Collex-Bossy | F11: Frontière | I11: =J11/G11 -> #DIV/0! | K11: =L11/G11 -> #DIV/0! | M11: =IF(N11="-","-",N11/L11) -> #DIV/0!
E12: SAUVERNY_Douane de Sauverny | F12: Frontière | I12: =J12/G12 -> #DIV/0! | K12: =L12/G12 -> #DIV/0! | M12: =IF(N12="-","-",N12/L12) -> #DIV/0!
I13: =J13/G13 -> #DIV/0! | K13: =L13/G13 -> #DIV/0! | M13: =IF(N13="-","-",N13/L13) -> #DIV/0!
I14: =J14/G14 -> #DIV/0! | K14: =L14/G14 -> #DIV/0! | M14: =IF(N14="-","-",N14/L14) -> #DIV/0!
E15: GRILLY_Douane du Pont | F15: Frontière | I15: =J15/G15 -> #DIV/0! | K15: =L15/G15 -> #DIV/0! | M15: =IF(N15="-","-",N15/L15) -> #DIV/0!
D16: Sous-total | G16: =SUM(G7:G15) -> 0 | H16: =SUM(H7:H15) -> 0 | I16: =J16/G16 -> #DIV/0! | J16: =SUM(J7:J15) -> 0 | K16: =L16/G16 -> #DIV/0! | L16: =SUM(L7:L15) -> 0 | M16: =N16/L16 -> #DIV/0! | N16: =SUM(N7:N15) -> 0 | O16: =SUM(O7:O15) -> 0 | P16: =SUM(P7:P15) -> 0 | Q16: =SUM(Q7:Q15) -> 0 | R16: =SUM(R7:R15) -> 0 | S16: =SUM(S7:S15) -> 0 | T16: =SUM(T7:T15) -> 0 | U16: =SUM(U7:U15) -> 0 | V16: =SUM(V7:V15) -> 0
B17: ATE Vaud / ProVélo La Côte | C17: NON | D17: 3 | E17: DIVONNE_Douane de Chavanne | F17: Frontière | I17: =J17/G17 -> #DIV/0! | K17: =L17/G17 -> #DIV/0! | M17: =IF(N17="-","-",N17/L17) -> #DIV/0!
E18: DIVONNE-CRASSIER_Voie verte | F18: Frontière | I18: =J18/G18 -> #DIV/0! | K18: =L18/G18 -> #DIV/0! | M18: =IF(N18="-","-",N18/L18) -> #DIV/0!
I19: =J19/G19 -> #DIV/0! | K19: =L19/G19 -> #DIV/0! | M19: =IF(N19="-","-",N19/L19) -> #DIV/0!
I20: =J20/G20 -> #DIV/0! | K20: =L20/G20 -> #DIV/0! | M20: =IF(N20="-","-",N20/L20) -> #DIV/0!
E21: DIVONNE_Douane de Crassy / Crassier | F21: Frontière | I21: =J21/G21 -> #DIV/0! | K21: =L21/G21 -> #DIV/0! | M21: =IF(N21="-","-",N21/L21) -> #DIV/0!
D22: Sous-total | G22: =SUM(G17:G21) -> 0 | H22: =SUM(H17:H21) -> 0 | I22: =J22/G22 -> #DIV/0! | J22: =SUM(J17:J21) -> 0 | K22: =L22/G22 -> #DIV/0! | L22: =SUM(L17:L21) -> 0 | M22: =N22/L22 -> #DIV/0! | N22: =SUM(N17:N21) -> 0 | O22: =SUM(O17:O21) -> 0 | P22: =SUM(P17:P21) -> 0 | Q22: =SUM(Q17:Q21) -> 0 | R22: =SUM(R17:R21) -> 0 | S22: =SUM(S17:S21) -> 0 | T22: =SUM(T17:T21) -> 0 | U22: =SUM(U17:U21) -> 0 | V22: =SUM(V17:V21) -> 0

Sheet CICLABLE2
C1: > CH Vélo traditionel H Total | D1: > CH Vélo traditionel F Total | E1: > CH VAE H Total | F1: > CH VAE F Total | G1: > CH Mode Nouveau H Total | H1: > CH Mode Nouveau F Total | I1: > CH Piéton/ne H Total | J1: > CH Piéton/ne F Total | K1: >FR Vélo traditionel H Total | L1: >FR Vélo traditionel F Total | M1: >FR VAE H Total | N1: >FR VAE F Total | O1: >FR Mode Nouveau H Total | P1: >FR Mode Nouveau F Total | Q1: >FR Piéton/ne H Total | R1: >FR Piéton/ne F Total | S1: > CH Vélo traditionel H HP | T1: > CH Vélo traditionel F HP | U1: > CH VAE H HP | V1: > CH VAE F HP | W1: > CH Mode Nouveau H HP | X1: > CH Mode Nouveau F HP | Y1: > CH Piéton/ne H HP | Z1: > CH Piéton/ne F HP | AA1: >FR Vélo traditionel H HP | AB1: >FR Vélo traditionel F HP | AC1: >FR VAE H HP | AD1: >FR VAE F HP | AE1: >FR Mode Nouveau H HP | AF1: >FR Mode Nouveau F HP | AG1: >FR Piéton/ne H HP | AH1: >FR Piéton/ne F HP | AJ1: Velos total | AK1: Vélos HP | AL1: % VAE dans le total | AM1: NB VAE dans le total | AN1: % femmes dans le total | AO1: NB de femmes dans le total | AP1: % de VAE chez les femmes | AQ1: NB de VAE chez les femmes | AR1: Autres modes total | AS1: Autres Modes HP | AT1: Pietons total | AU1: Pietons HP | AV1: >CH total | AW1: >CH HP | AX1: >FR total | AY1: >FR HP
C2: B | D2: C | E2: D | F2: E | G2: F | H2: G | I2: H | J2: I | K2: J | L2: K | M2: L | N2: M | O2: N | P2: O | Q2: P | R2: Q | S2: B | T2: C | U2: D | V2: E | W2: F | X2: G | Y2: H | Z2: I | AA2: J | AB2: K | AC2: L | AD2: M | AE2: N | AF2: O | AG2: P | AH2: Q
C3: 14 | D3: 14 | E3: 14 | F3: 14 | G3: 14 | H3: 14 | I3: 14 | J3: 14 | K3: 14 | L3: 14 | M3: 14 | N3: 14 | O3: 14 | P3: 14 | Q3: 14 | R3: 14 | S3: 15 | T3: 15 | U3: 15 | V3: 15 | W3: 15 | X3: 15 | Y3: 15 | Z3: 15 | AA3: 15 | AB3: 15 | AC3: 15 | AD3: 15 | AE3: 15 | AF3: 15 | AG3: 15 | AH3: 15
A4: StJeanDeG | B4: STJEAN_Douane de Dardagny
A5: Challex->LaPlaine | B5: CHALLEX_Douane de La Plaine
A6: Pougny | B6: POUGNY_Douane de Chancy
A7: StGenis total | B7: ST-GENIS_Giratoire Porte de France | C7: {=INDIRECT( "'" & $A7 & "'"& "!" &C$2 & C$3)} -> 287 | D7: {=INDIRECT( "'" & $A7 & "'"& "!" &D$2 & D$3)} -> 66 | E7: {=INDIRECT( "'" & $A7 & "'"& "!" &E$2 & E$3)} -> 103 | F7: {=INDIRECT( "'" & $A7 & "'"& "!" &F$2 & F$3)} -> 104 | G7: {=INDIRECT( "'" & $A7 & "'"& "!" &G$2 & G$3)} -> 38 | H7: {=INDIRECT( "'" & $A7 & "'"& "!" &H$2 & H$3)} -> 10 | I7: {=INDIRECT( "'" & $A7 & "'"& "!" &I$2 & I$3)} -> 57 | J7: {=INDIRECT( "'" & $A7 & "'"& "!" &J$2 & J$3)} -> 25 | ... AH7: {=INDIRECT( "'" & $A7 & "'"& "!" &AH$2 & AH$3)} -> 1 | AJ7: =C7+D7+E7+F7+K7+L7+M7+N7+G7+H7+O7+P7 -> 630 | AK7: =S7+T7+U7+V7+AA7+AB7+AC7+AD7+W7+X7+AE7+AF7 -> 337 | AL7: =AM7/AJ7 -> 0.33650794 | AM7: =E7+F7+M7+N7 -> 212 | AN7: =AO7/AJ7 -> 0.28888889 | AO7: =D7+F7+L7+N7+H7+P7 -> 182 | AP7: =AQ7/AO7 -> 0.58241758 | AQ7: =F7+N7 -> 106 | AR7: =G7+H7+O7+P7 -> 49 | AS7: =W7+X7+AE7+AF7 -> 30 | AT7: =I7+J7+Q7+R7 -> 89 | AU7: =Y7+Z7+AG7+AH7 -> 34 | AV7: =SUM(C7:J7) -> 690 | AW7: =SUM(S7:Z7) -> 356 | AX7: =SUM(K7:R7) -> 29 | AY7: =SUM(AA7:AH7) -> 15
A8: Ferney->Genève | B8: FERNEY_Douane du GdSaconnex | C8: {=INDIRECT( "'" & $A8 & "'"& "!" &C$2 & C$3)} -> 109 | D8: {=INDIRECT( "'" & $A8 & "'"& "!" &D$2 & D$3)} -> 55 | E8: {=INDIRECT( "'" & $A8 & "'"& "!" &E$2 & E$3)} -> 95 | F8: {=INDIRECT( "'" & $A8 & "'"& "!" &F$2 & F$3)} -> 105 | G8: {=INDIRECT( "'" & $A8 & "'"& "!" &G$2 & G$3)} -> 21 | H8: {=INDIRECT( "'" & $A8 & "'"& "!" &H$2 & H$3)} -> 4 | I8: {=INDIRECT( "'" & $A8 & "'"& "!" &I$2 & I$3)} -> 8 | J8: {=INDIRECT( "'" & $A8 & "'"& "!" &J$2 & J$3)} -> 6 | ... AH8: {=INDIRECT( "'" & $A8 & "'"& "!" &AH$2 & AH$3)} -> 0 | AJ8: =C8+D8+E8+F8+K8+L8+M8+N8+G8+H8+O8+P8 -> 399 | AK8: =S8+T8+U8+V8+AA8+AB8+AC8+AD8+W8+X8+AE8+AF8 -> 206 | AL8: =AM8/AJ8 -> 0.50877193 | AM8: =E8+F8+M8+N8 -> 203 | AN8: =AO8/AJ8 -> 0.41102757 | AO8: =D8+F8+L8+N8+H8+P8 -> 164 | AP8: =AQ8/AO8 -> 0.6402439 | AQ8: =F8+N8 -> 105 | AR8: =G8+H8+O8+P8 -> 29 | AS8: =W8+X8+AE8+AF8 -> 17 | AT8: =I8+J8+Q8+R8 -> 15 | AU8: =Y8+Z8+AG8+AH8 -> 7 | AV8: =SUM(C8:J8) -> 403 | AW8: =SUM(S8:Z8) -> 210 | AX8: =SUM(K8:R8) -> 11 | AY8: =SUM(AA8:AH8) -> 3
A9: Mategnin Total | B9: FERNEY_Douane de Mategnin | C9: {=INDIRECT( "'" & $A9 & "'"& "!" &C$2 & C$3)} -> 146 | D9: {=INDIRECT( "'" & $A9 & "'"& "!" &D$2 & D$3)} -> 49 | E9: {=INDIRECT( "'" & $A9 & "'"& "!" &E$2 & E$3)} -> 114 | F9: {=INDIRECT( "'" & $A9 & "'"& "!" &F$2 & F$3)} -> 81 | G9: {=INDIRECT( "'" & $A9 & "'"& "!" &G$2 & G$3)} -> 28 | H9: {=INDIRECT( "'" & $A9 & "'"& "!" &H$2 & H$3)} -> 7 | I9: {=INDIRECT( "'" & $A9 & "'"& "!" &I$2 & I$3)} -> 14 | J9: {=INDIRECT( "'" & $A9 & "'"& "!" &J$2 & J$3)} -> 14 | ... AH9: {=INDIRECT( "'" & $A9 & "'"& "!" &AH$2 & AH$3)} -> 5 | AJ9: =C9+D9+E9+F9+K9+L9+M9+N9+G9+H9+O9+P9 -> 470 | AK9: =S9+T9+U9+V9+AA9+AB9+AC9+AD9+W9+X9+AE9+AF9 -> 252 | AL9: =AM9/AJ9 -> 0.45957447 | AM9: =E9+F9+M9+N9 -> 216 | AN9: =AO9/AJ9 -> 0.31702128 | AO9: =D9+F9+L9+N9+H9+P9 -> 149 | AP9: =AQ9/AO9 -> 0.59731544 | AQ9: =F9+N9 -> 89 | AR9: =G9+H9+O9+P9 -> 37 | AS9: =W9+X9+AE9+AF9 -> 16 | AT9: =I9+J9+Q9+R9 -> 38 | AU9: =Y9+Z9+AG9+AH9 -> 21 | AV9: =SUM(C9:J9) -> 453 | AW9: =SUM(S9:Z9) -> 241 | AX9: =SUM(K9:R9) -> 55 | AY9: =SUM(AA9:AH9) -> 32
A10: Vireloup Douane | B10: FERNEY_Douane de Vireloup | C10: {=INDIRECT( "'" & $A10 & "'"& "!" &C$2 & C$3)} -> 18 | D10: {=INDIRECT( "'" & $A10 & "'"& "!" &D$2 & D$3)} -> 14 | E10: {=INDIRECT( "'" & $A10 & "'"& "!" &E$2 & E$3)} -> 22 | F10: {=INDIRECT( "'" & $A10 & "'"& "!" &F$2 & F$3)} -> 19 | G10: {=INDIRECT( "'" & $A10 & "'"& "!" &G$2 & G$3)} -> 4 | H10: {=INDIRECT( "'" & $A10 & "'"& "!" &H$2 & H$3)} -> 4 | I10: {=INDIRECT( "'" & $A10 & "'"& "!" &I$2 & I$3)} -> 2 | J10: {=INDIRECT( "'" & $A10 & "'"& "!" &J$2 & J$3)} -> 3 | ... AH10: {=INDIRECT( "'" & $A10 & "'"& "!" &AH$2 & AH$3)} -> 7 | AJ10: =C10+D10+E10+F10+K10+L10+M10+N10+G10+H10+O10+P10 -> 131 | AK10: =S10+T10+U10+V10+AA10+AB10+AC10+AD10+W10+X10+AE10+AF10 -> 70 | AL10: =AM10/AJ10 -> 0.48854962 | AM10: =E10+F10+M10+N10 -> 64 | AN10: =AO10/AJ10 -> 0.38931298 | AO10: =D10+F10+L10+N10+H10+P10 -> 51 | AP10: =AQ10/AO10 -> 0.54901961 | AQ10: =F10+N10 -> 28 | AR10: =G10+H10+O10+P10 -> 10 | AS10: =W10+X10+AE10+AF10 -> 4 | AT10: =I10+J10+Q10+R10 -> 26 | AU10: =Y10+Z10+AG10+AH10 -> 18 | AV10: =SUM(C10:J10) -> 86 | AW10: =SUM(S10:Z10) -> 39 | AX10: =SUM(K10:R10) -> 71 | AY10: =SUM(AA10:AH10) -> 49
A11: Versonnex | B11: VERSONNEX_Douane de Collex-Bossy | C11: {=INDIRECT( "'" & $A11 & "'"& "!" &C$2 & C$3)} -> 17 | D11: {=INDIRECT( "'" & $A11 & "'"& "!" &D$2 & D$3)} -> 3 | E11: {=INDIRECT( "'" & $A11 & "'"& "!" &E$2 & E$3)} -> 21 | F11: {=INDIRECT( "'" & $A11 & "'"& "!" &F$2 & F$3)} -> 18 | G11: {=INDIRECT( "'" & $A11 & "'"& "!" &G$2 & G$3)} -> 0 | H11: {=INDIRECT( "'" & $A11 & "'"& "!" &H$2 & H$3)} -> 0 | I11: {=INDIRECT( "'" & $A11 & "'"& "!" &I$2 & I$3)} -> 1 | J11: {=INDIRECT( "'" & $A11 & "'"& "!" &J$2 & J$3)} -> 0 | ... AH11: {=INDIRECT( "'" & $A11 & "'"& "!" &AH$2 & AH$3)} -> 0 | AJ11: =C11+D11+E11+F11+K11+L11+M11+N11+G11+H11+O11+P11 -> 64 | AK11: =S11+T11+U11+V11+AA11+AB11+AC11+AD11+W11+X11+AE11+AF11 -> 31 | AL11: =AM11/AJ11 -> 0.640625 | AM11: =E11+F11+M11+N11 -> 41 | AN11: =AO11/AJ11 -> 0.328125 | AO11: =D11+F11+L11+N11+H11+P11 -> 21 | AP11: =AQ11/AO11 -> 0.85714286 | AQ11: =F11+N11 -> 18 | AR11: =G11+H11+O11+P11 -> 0 | AS11: =W11+X11+AE11+AF11 -> 0 | AT11: =I11+J11+Q11+R11 -> 1 | AU11: =Y11+Z11+AG11+AH11 -> 0 | AV11: =SUM(C11:J11) -> 60 | AW11: =SUM(S11:Z11) -> 26 | AX11: =SUM(K11:R11) -> 5 | AY11: =SUM(AA11:AH11) -> 5
A12: Sauverny | B12: SAUVERNY_Douane de Sauverny | C12: {=INDIRECT( "'" & $A12 & "'"& "!" &C$2 & C$3)} -> 15 | D12: {=INDIRECT( "'" & $A12 & "'"& "!" &D$2 & D$3)} -> 3 | E12: {=INDIRECT( "'" & $A12 & "'"& "!" &E$2 & E$3)} -> 9 | F12: {=INDIRECT( "'" & $A12 & "'"& "!" &F$2 & F$3)} -> 9 | G12: {=INDIRECT( "'" & $A12 & "'"& "!" &G$2 & G$3)} -> 0 | H12: {=INDIRECT( "'" & $A12 & "'"& "!" &H$2 & H$3)} -> 1 | I12: {=INDIRECT( "'" & $A12 & "'"& "!" &I$2 & I$3)} -> 12 | J12: {=INDIRECT( "'" & $A12 & "'"& "!" &J$2 & J$3)} -> 12 | ... AH12: {=INDIRECT( "'" & $A12 & "'"& "!" &AH$2 & AH$3)} -> 0 | AJ12: =C12+D12+E12+F12+K12+L12+M12+N12+G12+H12+O12+P12 -> 43 | AK12: =S12+T12+U12+V12+AA12+AB12+AC12+AD12+W12+X12+AE12+AF12 -> 20 | AL12: =AM12/AJ12 -> 0.41860465 | AM12: =E12+F12+M12+N12 -> 18 | AN12: =AO12/AJ12 -> 0.3255814 | AO12: =D12+F12+L12+N12+H12+P12 -> 14 | AP12: =AQ12/AO12 -> 0.64285714 | AQ12: =F12+N12 -> 9 | AR12: =G12+H12+O12+P12 -> 1 | AS12: =W12+X12+AE12+AF12 -> 1 | AT12: =I12+J12+Q12+R12 -> 26 | AU12: =Y12+Z12+AG12+AH12 -> 16 | AV12: =SUM(C12:J12) -> 61 | AW12: =SUM(S12:Z12) -> 32 | AX12: =SUM(K12:R12) -> 8 | AY12: =SUM(AA12:AH12) -> 4
B13: COMMUNE_Carrefour
B14: COMMUNE_Carrefour
A15: Grilly | B15: GRILLY_Douane du Pont
B16: COMMUNE_Carrefour
B17: COMMUNE_Carrefour
B18: COMMUNE_Carrefour
C19: =SUM(C4:C18) -> 592 | D19: =SUM(D4:D18) -> 190 | E19: =SUM(E4:E18) -> 364 | F19: =SUM(F4:F18) -> 336 | G19: =SUM(G4:G18) -> 91 | H19: =SUM(H4:H18) -> 26 | I19: =SUM(I4:I18) -> 94 | J19: =SUM(J4:J18) -> 60 | ... AH19: =SUM(AH4:AH18) -> 13 | AJ19: =C19+D19+E19+F19+K19+L19+M19+N19+G19+H19+O19+P19 -> 1737 | AK19: =S19+T19+U19+V19+AA19+AB19+AC19+AD19+W19+X19+AE19+AF19 -> 916 | AL19: =AM19/AJ19 -> 0.43408175 | AM19: =E19+F19+M19+N19 -> 754 | AN19: =AO19/AJ19 -> 0.33448474 | AO19: =D19+F19+L19+N19+H19+P19 -> 581 | AP19: =AQ19/AO19 -> 0.61101549 | AQ19: =F19+N19 -> 355 | AR19: =G19+H19+O19+P19 -> 126 | AS19: =W19+X19+AE19+AF19 -> 68 | AT19: =I19+J19+Q19+R19 -> 195 | AU19: =Y19+Z19+AG19+AH19 -> 96 | AV19: =SUM(C19:J19) -> 1753 | AW19: =SUM(S19:Z19) -> 904 | AX19: =SUM(K19:R19) -> 179 | AY19: =SUM(AA19:AH19) -> 108
A20: Divonne->Chavanne | B20: DIVONNE_Douane de Chavanne | C20: {=INDIRECT( "'" & $A20 & "'"& "!" &C$2 & C$3)} -> 23 | D20: {=INDIRECT( "'" & $A20 & "'"& "!" &D$2 & D$3)} -> 12 | E20: {=INDIRECT( "'" & $A20 & "'"& "!" &E$2 & E$3)} -> 16 | F20: {=INDIRECT( "'" & $A20 & "'"& "!" &F$2 & F$3)} -> 9 | G20: {=INDIRECT( "'" & $A20 & "'"& "!" &G$2 & G$3)} -> 2 | H20: {=INDIRECT( "'" & $A20 & "'"& "!" &H$2 & H$3)} -> 0 | I20: {=INDIRECT( "'" & $A20 & "'"& "!" &I$2 & I$3)} -> 2 | J20: {=INDIRECT( "'" & $A20 & "'"& "!" &J$2 & J$3)} -> 3 | ... AH20: {=INDIRECT( "'" & $A20 & "'"& "!" &AH$2 & AH$3)} -> 0 | AJ20: =C20+D20+E20+F20+K20+L20+M20+N20+G20+H20+O20+P20 -> 91 | AK20: =S20+T20+U20+V20+AA20+AB20+AC20+AD20+W20+X20+AE20+AF20 -> 54 | AL20: =AM20/AJ20 -> 0.2967033 | AM20: =E20+F20+M20+N20 -> 27 | AN20: =AO20/AJ20 -> 0.40659341 | AO20: =D20+F20+L20+N20+H20+P20 -> 37 | AP20: =AQ20/AO20 -> 0.27027027 | AQ20: =F20+N20 -> 10 | AR20: =G20+H20+O20+P20 -> 2 | AS20: =W20+X20+AE20+AF20 -> 1 | AT20: =I20+J20+Q20+R20 -> 7 | AU20: =Y20+Z20+AG20+AH20 -> 2 | AV20: =SUM(C20:J20) -> 67 | AW20: =SUM(S20:Z20) -> 38 | AX20: =SUM(K20:R20) -> 31 | AY20: =SUM(AA20:AH20) -> 18
A21: Crassier Voie Verte | B21: DIVONNE-CRASSIER_Voie verte | C21: {=INDIRECT( "'" & $A21 & "'"& "!" &C$2 & C$3)} -> 6 | D21: {=INDIRECT( "'" & $A21 & "'"& "!" &D$2 & D$3)} -> 1 | E21: {=INDIRECT( "'" & $A21 & "'"& "!" &E$2 & E$3)} -> 9 | F21: {=INDIRECT( "'" & $A21 & "'"& "!" &F$2 & F$3)} -> 7 | G21: {=INDIRECT( "'" & $A21 & "'"& "!" &G$2 & G$3)} -> 0 | H21: {=INDIRECT( "'" & $A21 & "'"& "!" &H$2 & H$3)} -> 0 | I21: {=INDIRECT( "'" & $A21 & "'"& "!" &I$2 & I$3)} -> 8 | J21: {=INDIRECT( "'" & $A21 & "'"& "!" &J$2 & J$3)} -> 3 | ... AH21: {=INDIRECT( "'" & $A21 & "'"& "!" &AH$2 & AH$3)} -> 0 | AJ21: =C21+D21+E21+F21+K21+L21+M21+N21+G21+H21+O21+P21 -> 23 | AK21: =S21+T21+U21+V21+AA21+AB21+AC21+AD21+W21+X21+AE21+AF21 -> 13 | AL21: =AM21/AJ21 -> 0.69565217 | AM21: =E21+F21+M21+N21 -> 16 | AN21: =AO21/AJ21 -> 0.34782609 | AO21: =D21+F21+L21+N21+H21+P21 -> 8 | AP21: =AQ21/AO21 -> 0.875 | AQ21: =F21+N21 -> 7 | AR21: =G21+H21+O21+P21 -> 0 | AS21: =W21+X21+AE21+AF21 -> 0 | AT21: =I21+J21+Q21+R21 -> 16 | AU21: =Y21+Z21+AG21+AH21 -> 10 | AV21: =SUM(C21:J21) -> 34 | AW21: =SUM(S21:Z21) -> 19 | AX21: =SUM(K21:R21) -> 5 | AY21: =SUM(AA21:AH21) -> 4
B22: COMMUNE_Carrefour
B23: COMMUNE_Carrefour
A24: Crassier Douane | B24: DIVONNE_Douane de Crassy / Crassier | C24: {=INDIRECT( "'" & $A24 & "'"& "!" &C$2 & C$3)} -> 8 | D24: {=INDIRECT( "'" & $A24 & "'"& "!" &D$2 & D$3)} -> 2 | E24: {=INDIRECT( "'" & $A24 & "'"& "!" &E$2 & E$3)} -> 4 | F24: {=INDIRECT( "'" & $A24 & "'"& "!" &F$2 & F$3)} -> 2 | G24: {=INDIRECT( "'" & $A24 & "'"& "!" &G$2 & G$3)} -> 1 | H24: {=INDIRECT( "'" & $A24 & "'"& "!" &H$2 & H$3)} -> 0 | I24: {=INDIRECT( "'" & $A24 & "'"& "!" &I$2 & I$3)} -> 2 | J24: {=INDIRECT( "'" & $A24 & "'"& "!" &J$2 & J$3)} -> 1 | ... AH24: {=INDIRECT( "'" & $A24 & "'"& "!" &AH$2 & AH$3)} -> 1 | AJ24: =C24+D24+E24+F24+K24+L24+M24+N24+G24+H24+O24+P24 -> 20 | AK24: =S24+T24+U24+V24+AA24+AB24+AC24+AD24+W24+X24+AE24+AF24 -> 14 | AL24: =AM24/AJ24 -> 0.35 | AM24: =E24+F24+M24+N24 -> 7 | AN24: =AO24/AJ24 -> 0.2 | AO24: =D24+F24+L24+N24+H24+P24 -> 4 | AP24: =AQ24/AO24 -> 0.5 | AQ24: =F24+N24 -> 2 | AR24: =G24+H24+O24+P24 -> 1 | AS24: =W24+X24+AE24+AF24 -> 0 | AT24: =I24+J24+Q24+R24 -> 4 | AU24: =Y24+Z24+AG24+AH24 -> 2 | AV24: =SUM(C24:J24) -> 20 | AW24: =SUM(S24:Z24) -> 12 | AX24: =SUM(K24:R24) -> 4 | AY24: =SUM(AA24:AH24) -> 4
B25: COMMUNE_Carrefour
B26: COMMUNE_Carrefour
B27: COMMUNE_Carrefour
C28: =SUM(C20:C27) -> 37 | D28: =SUM(D20:D27) -> 15 | E28: =SUM(E20:E27) -> 29 | F28: =SUM(F20:F27) -> 18 | G28: =SUM(G20:G27) -> 3 | H28: =SUM(H20:H27) -> 0 | I28: =SUM(I20:I27) -> 12 | J28: =SUM(J20:J27) -> 7 | ... AH28: =SUM(AH20:AH27) -> 1 | AJ28: =C28+D28+E28+F28+K28+L28+M28+N28+G28+H28+O28+P28 -> 134 | AK28: =S28+T28+U28+V28+AA28+AB28+AC28+AD28+W28+X28+AE28+AF28 -> 81 | AL28: =AM28/AJ28 -> 0.37313433 | AM28: =E28+F28+M28+N28 -> 50 | AN28: =AO28/AJ28 -> 0.36567164 | AO28: =D28+F28+L28+N28+H28+P28 -> 49 | AP28: =AQ28/AO28 -> 0.3877551 | AQ28: =F28+N28 -> 19 | AR28: =G28+H28+O28+P28 -> 3 | AS28: =W28+X28+AE28+AF28 -> 1 | AT28: =I28+J28+Q28+R28 -> 27 | AU28: =Y28+Z28+AG28+AH28 -> 14 | AV28: =SUM(C28:J28) -> 121 | AW28: =SUM(S28:Z28) -> 69 | AX28: =SUM(K28:R28) -> 40 | AY28: =SUM(AA28:AH28) -> 26
B35: TOTAL | C35: =C28+C19 -> 629 | D35: =D28+D19 -> 205 | E35: =E28+E19 -> 393 | F35: =F28+F19 -> 354 | G35: =G28+G19 -> 94 | H35: =H28+H19 -> 26 | I35: =I28+I19 -> 106 | J35: =J28+J19 -> 67 | ... AH35: =AH28+AH19 -> 14

Sheet Sheet2
B1: Rang | C1: Lieu | D1: > CH Vélo traditionel H Total | E1: > CH Vélo traditionel F Total | F1: > CH VAE H Total | G1: > CH VAE F Total | H1: > CH Mode Nouveau H Total | I1: > CH Mode Nouveau F Total | J1: > CH Piéton/ne H Total | K1: > CH Piéton/ne F Total | L1: >FR Vélo traditionel H Total | M1: >FR Vélo traditionel F Total | N1: >FR VAE H Total | O1: >FR VAE F Total | P1: >FR Mode Nouveau H Total | Q1: >FR Mode Nouveau F Total | R1: >FR Piéton/ne H Total | S1: >FR Piéton/ne F Total | T1: > CH Vélo traditionel H HP | U1: > CH Vélo traditionel F HP | V1: > CH VAE H HP | W1: > CH VAE F HP | X1: > CH Mode Nouveau H HP | Y1: > CH Mode Nouveau F HP | Z1: > CH Piéton/ne H HP | AA1: > CH Piéton/ne F HP | AB1: >FR Vélo traditionel H HP | AC1: >FR Vélo traditionel F HP | AD1: >FR VAE H HP | AE1: >FR VAE F HP | AF1: >FR Mode Nouveau H HP | AG1: >FR Mode Nouveau F HP | AH1: >FR Piéton/ne H HP | AI1: >FR Piéton/ne F HP
D2: =INDIRECT( "'" & $A4 & "'"& "!" &D$2 & D$3) -> #VALUE! | E2: =INDIRECT( "'" & $A4 & "'"& "!" &E$2 & E$3) -> #VALUE! | F2: =INDIRECT( "'" & $A4 & "'"& "!" &F$2 & F$3) -> #VALUE! | G2: =INDIRECT( "'" & $A4 & "'"& "!" &G$2 & G$3) -> #VALUE! | H2: =INDIRECT( "'" & $A4 & "'"& "!" &H$2 & H$3) -> #VALUE! | I2: =INDIRECT( "'" & $A4 & "'"& "!" &I$2 & I$3) -> #VALUE! | J2: =INDIRECT( "'" & $A4 & "'"& "!" &J$2 & J$3) -> #VALUE! | K2: =INDIRECT( "'" & $A4 & "'"& "!" &K$2 & K$3) -> #VALUE! | ... AI2: =INDIRECT( "'" & $A4 & "'"& "!" &AI$2 & AI$3) -> #VALUE!
D3: =INDIRECT( "'" & $A5 & "'"& "!" &D$2 & D$3) -> #VALUE! | E3: =INDIRECT( "'" & $A5 & "'"& "!" &E$2 & E$3) -> #VALUE! | F3: =INDIRECT( "'" & $A5 & "'"& "!" &F$2 & F$3) -> #VALUE! | G3: =INDIRECT( "'" & $A5 & "'"& "!" &G$2 & G$3) -> #VALUE! | H3: =INDIRECT( "'" & $A5 & "'"& "!" &H$2 & H$3) -> #VALUE! | I3: =INDIRECT( "'" & $A5 & "'"& "!" &I$2 & I$3) -> #VALUE! | J3: =INDIRECT( "'" & $A5 & "'"& "!" &J$2 & J$3) -> #VALUE! | K3: =INDIRECT( "'" & $A5 & "'"& "!" &K$2 & K$3) -> #VALUE! | ... AI3: =INDIRECT( "'" & $A5 & "'"& "!" &AI$2 & AI$3) -> #VALUE!
A4: StJeanDeG | B4: 1 | C4: STJEAN_Douane de Dardagny | D4: =INDIRECT( "'" & $A4 & "'"& "!" &D$2 & D$3) -> #VALUE! | E4: =INDIRECT( "'" & $A4 & "'"& "!" &E$2 & E$3) -> #VALUE! | F4: =INDIRECT( "'" & $A6 & "'"& "!" &F$2 & F$3) -> #VALUE! | G4: =INDIRECT( "'" & $A6 & "'"& "!" &G$2 & G$3) -> #VALUE! | H4: =INDIRECT( "'" & $A6 & "'"& "!" &H$2 & H$3) -> #VALUE! | I4: =INDIRECT( "'" & $A6 & "'"& "!" &I$2 & I$3) -> #VALUE! | J4: =INDIRECT( "'" & $A6 & "'"& "!" &J$2 & J$3) -> #VALUE! | K4: =INDIRECT( "'" & $A6 & "'"& "!" &K$2 & K$3) -> #VALUE! | L4: =INDIRECT( "'" & $A6 & "'"& "!" &L$2 & L$3) -> #VALUE! | M4: =INDIRECT( "'" & $A6 & "'"& "!" &M$2 & M$3) -> #VALUE! | ... AI4: =INDIRECT( "'" & $A6 & "'"& "!" &AI$2 & AI$3) -> #VALUE!
A5: Challex->LaPlaine | B5: 2 | C5: CHALLEX_Douane de La Plaine | D5: =INDIRECT( "'" & $A7 & "'"& "!" &D$2 & D$3) -> #VALUE! | E5: =INDIRECT( "'" & $A7 & "'"& "!" &E$2 & E$3) -> #VALUE! | F5: =INDIRECT( "'" & $A7 & "'"& "!" &F$2 & F$3) -> #VALUE! | G5: =INDIRECT( "'" & $A7 & "'"& "!" &G$2 & G$3) -> #VALUE! | H5: =INDIRECT( "'" & $A7 & "'"& "!" &H$2 & H$3) -> #VALUE! | I5: =INDIRECT( "'" & $A7 & "'"& "!" &I$2 & I$3) -> #VALUE! | J5: =INDIRECT( "'" & $A7 & "'"& "!" &J$2 & J$3) -> #VALUE! | K5: =INDIRECT( "'" & $A7 & "'"& "!" &K$2 & K$3) -> #VALUE! | ... AI5: =INDIRECT( "'" & $A7 & "'"& "!" &AI$2 & AI$3) -> #VALUE!
A6: Pougny | B6: 3 | C6: POUGNY_Douane de Chancy | D6: =INDIRECT( "'" & $A8 & "'"& "!" &D$2 & D$3) -> #VALUE! | E6: =INDIRECT( "'" & $A8 & "'"& "!" &E$2 & E$3) -> #VALUE! | F6: =INDIRECT( "'" & $A8 & "'"& "!" &F$2 & F$3) -> #VALUE! | G6: =INDIRECT( "'" & $A8 & "'"& "!" &G$2 & G$3) -> #VALUE! | H6: =INDIRECT( "'" & $A8 & "'"& "!" &H$2 & H$3) -> #VALUE! | I6: =INDIRECT( "'" & $A8 & "'"& "!" &I$2 & I$3) -> #VALUE! | J6: =INDIRECT( "'" & $A8 & "'"& "!" &J$2 & J$3) -> #VALUE! | K6: =INDIRECT( "'" & $A8 & "'"& "!" &K$2 & K$3) -> #VALUE! | ... AI6: =INDIRECT( "'" & $A8 & "'"& "!" &AI$2 & AI$3) -> #VALUE!
A7: StGenis total | B7: 4 | C7: ST-GENIS_Giratoire Porte de France | D7: =INDIRECT( "'" & $A9 & "'"& "!" &D$2 & D$3) -> #VALUE! | E7: =INDIRECT( "'" & $A9 & "'"& "!" &E$2 & E$3) -> #VALUE! | F7: =INDIRECT( "'" & $A9 & "'"& "!" &F$2 & F$3) -> #VALUE! | G7: =INDIRECT( "'" & $A9 & "'"& "!" &G$2 & G$3) -> #VALUE! | H7: =INDIRECT( "'" & $A9 & "'"& "!" &H$2 & H$3) -> #VALUE! | I7: =INDIRECT( "'" & $A9 & "'"& "!" &I$2 & I$3) -> #VALUE! | J7: =INDIRECT( "'" & $A9 & "'"& "!" &J$2 & J$3) -> #VALUE! | K7: =INDIRECT( "'" & $A9 & "'"& "!" &K$2 & K$3) -> #VALUE! | ... AI7: =INDIRECT( "'" & $A9 & "'"& "!" &AI$2 & AI$3) -> #VALUE!
A8: Ferney->Genève | B8: 5 | C8: FERNEY_Douane du GdSaconnex | D8: =INDIRECT( "'" & $A10 & "'"& "!" &D$2 & D$3) -> #VALUE! | E8: =INDIRECT( "'" & $A10 & "'"& "!" &E$2 & E$3) -> #VALUE! | F8: =INDIRECT( "'" & $A10 & "'"& "!" &F$2 & F$3) -> #VALUE! | G8: =INDIRECT( "'" & $A10 & "'"& "!" &G$2 & G$3) -> #VALUE! | H8: =INDIRECT( "'" & $A10 & "'"& "!" &H$2 & H$3) -> #VALUE! | I8: =INDIRECT( "'" & $A10 & "'"& "!" &I$2 & I$3) -> #VALUE! | J8: =INDIRECT( "'" & $A10 & "'"& "!" &J$2 & J$3) -> #VALUE! | K8: =INDIRECT( "'" & $A10 & "'"& "!" &K$2 & K$3) -> #VALUE! | ... AI8: =INDIRECT( "'" & $A10 & "'"& "!" &AI$2 & AI$3) -> #VALUE!
A9: Mategnin Total | B9: 6 | C9: FERNEY_Douane de Mategnin | D9: =INDIRECT( "'" & $A11 & "'"& "!" &D$2 & D$3) -> #VALUE! | E9: =INDIRECT( "'" & $A11 & "'"& "!" &E$2 & E$3) -> #VALUE! | F9: =INDIRECT( "'" & $A11 & "'"& "!" &F$2 & F$3) -> #VALUE! | G9: =INDIRECT( "'" & $A11 & "'"& "!" &G$2 & G$3) -> #VALUE! | H9: =INDIRECT( "'" & $A11 & "'"& "!" &H$2 & H$3) -> #VALUE! | I9: =INDIRECT( "'" & $A11 & "'"& "!" &I$2 & I$3) -> #VALUE! | J9: =INDIRECT( "'" & $A11 & "'"& "!" &J$2 & J$3) -> #VALUE! | K9: =INDIRECT( "'" & $A11 & "'"& "!" &K$2 & K$3) -> #VALUE! | ... AI9: =INDIRECT( "'" & $A11 & "'"& "!" &AI$2 & AI$3) -> #VALUE!
A10: Vireloup Douane | B10: 7 | C10: FERNEY_Douane de Vireloup | D10: =INDIRECT( "'" & $A12 & "'"& "!" &D$2 & D$3) -> #VALUE! | E10: =INDIRECT( "'" & $A12 & "'"& "!" &E$2 & E$3) -> #VALUE! | F10: =INDIRECT( "'" & $A12 & "'"& "!" &F$2 & F$3) -> #VALUE! | G10: =INDIRECT( "'" & $A12 & "'"& "!" &G$2 & G$3) -> #VALUE! | H10: =INDIRECT( "'" & $A12 & "'"& "!" &H$2 & H$3) -> #VALUE! | I10: =INDIRECT( "'" & $A12 & "'"& "!" &I$2 & I$3) -> #VALUE! | J10: =INDIRECT( "'" & $A12 & "'"& "!" &J$2 & J$3) -> #VALUE! | K10: =INDIRECT( "'" & $A12 & "'"& "!" &K$2 & K$3) -> #VALUE! | ... AI10: =INDIRECT( "'" & $A12 & "'"& "!" &AI$2 & AI$3) -> #VALUE!
A11: Versonnex | B11: 8 | C11: VERSONNEX_Douane de Collex-Bossy
A12: Sauverny | B12: 9 | C12: SAUVERNY_Douane de Sauverny
B13: 10 | D13: =INDIRECT( "'" & $A15 & "'"& "!" &D$2 & D$3) -> #VALUE! | E13: =INDIRECT( "'" & $A15 & "'"& "!" &E$2 & E$3) -> #VALUE! | F13: =INDIRECT( "'" & $A15 & "'"& "!" &F$2 & F$3) -> #VALUE! | G13: =INDIRECT( "'" & $A15 & "'"& "!" &G$2 & G$3) -> #VALUE! | H13: =INDIRECT( "'" & $A15 & "'"& "!" &H$2 & H$3) -> #VALUE! | I13: =INDIRECT( "'" & $A15 & "'"& "!" &I$2 & I$3) -> #VALUE! | J13: =INDIRECT( "'" & $A15 & "'"& "!" &J$2 & J$3) -> #VALUE! | K13: =INDIRECT( "'" & $A15 & "'"& "!" &K$2 & K$3) -> #VALUE! | ... AI13: =INDIRECT( "'" & $A15 & "'"& "!" &AI$2 & AI$3) -> #VALUE!
B14: 11 | D14: =SUM(D2:D13) -> #VALUE!
A15: Grilly | B15: 12 | C15: GRILLY_Douane du Pont | D15: =INDIRECT( "'" & $A17 & "'"& "!" &D$2 & D$3) -> #VALUE! | E15: =INDIRECT( "'" & $A17 & "'"& "!" &E$2 & E$3) -> #VALUE! | F15: =INDIRECT( "'" & $A17 & "'"& "!" &F$2 & F$3) -> #VALUE! | G15: =INDIRECT( "'" & $A17 & "'"& "!" &G$2 & G$3) -> #VALUE! | H15: =INDIRECT( "'" & $A17 & "'"& "!" &H$2 & H$3) -> #VALUE! | I15: =INDIRECT( "'" & $A17 & "'"& "!" &I$2 & I$3) -> #VALUE! | J15: =INDIRECT( "'" & $A17 & "'"& "!" &J$2 & J$3) -> #VALUE! | K15: =INDIRECT( "'" & $A17 & "'"& "!" &K$2 & K$3) -> #VALUE! | ... AI15: =INDIRECT( "'" & $A17 & "'"& "!" &AI$2 & AI$3) -> #VALUE!
B16: 13 | C16: APiCy | D16: =INDIRECT( "'" & $A18 & "'"& "!" &D$2 & D$3) -> #VALUE! | E16: =INDIRECT( "'" & $A18 & "'"& "!" &E$2 & E$3) -> #VALUE! | F16: =INDIRECT( "'" & $A18 & "'"& "!" &F$2 & F$3) -> #VALUE! | G16: =INDIRECT( "'" & $A18 & "'"& "!" &G$2 & G$3) -> #VALUE! | H16: =INDIRECT( "'" & $A18 & "'"& "!" &H$2 & H$3) -> #VALUE! | I16: =INDIRECT( "'" & $A18 & "'"& "!" &I$2 & I$3) -> #VALUE! | J16: =INDIRECT( "'" & $A18 & "'"& "!" &J$2 & J$3) -> #VALUE! | K16: =INDIRECT( "'" & $A18 & "'"& "!" &K$2 & K$3) -> #VALUE! | ... AI16: =INDIRECT( "'" & $A18 & "'"& "!" &AI$2 & AI$3) -> #VALUE!
A17: Divonne->Chavanne | B17: 14 | C17: DIVONNE_Douane de Chavanne
A18: Crassier Voie Verte | B18: 15 | C18: DIVONNE-CRASSIER_Voie verte
B19: 16 | D19: =INDIRECT( "'" & $A21 & "'"& "!" &D$2 & D$3) -> #VALUE! | E19: =INDIRECT( "'" & $A21 & "'"& "!" &E$2 & E$3) -> #VALUE! | F19: =INDIRECT( "'" & $A21 & "'"& "!" &F$2 & F$3) -> #VALUE! | G19: =INDIRECT( "'" & $A21 & "'"& "!" &G$2 & G$3) -> #VALUE! | H19: =INDIRECT( "'" & $A21 & "'"& "!" &H$2 & H$3) -> #VALUE! | I19: =INDIRECT( "'" & $A21 & "'"& "!" &I$2 & I$3) -> #VALUE! | J19: =INDIRECT( "'" & $A21 & "'"& "!" &J$2 & J$3) -> #VALUE! | K19: =INDIRECT( "'" & $A21 & "'"& "!" &K$2 & K$3) -> #VALUE! | ... AI19: =INDIRECT( "'" & $A21 & "'"& "!" &AI$2 & AI$3) -> #VALUE!
B20: 17
A21: Crassier Douane | B21: 18 | C21: DIVONNE_Douane de Crassy / Crassier | D21: B | E21: C | F21: D | G21: E | H21: F | I21: G | J21: H | K21: I | L21: J | M21: K | N21: L | O21: M | P21: N | Q21: O | R21: P | S21: Q | T21: B | U21: C | V21: D | W21: E | X21: F | Y21: G | Z21: H | AA21: I | AB21: J | AC21: K | AD21: L | AE21: M | AF21: N | AG21: O | AH21: P | AI21: Q
B22: 19 | C22: ATE-VD | D22: 14 | E22: 14 | F22: 14 | G22: 14 | H22: 14 | I22: 14 | J22: 14 | K22: 14 | L22: 14 | M22: 14 | N22: 14 | O22: 14 | P22: 14 | Q22: 14 | R22: 14 | S22: 14 | T22: 15 | U22: 15 | V22: 15 | W22: 15 | X22: 15 | Y22: 15 | Z22: 15 | AA22: 15 | AB22: 15 | AC22: 15 | AD22: 15 | AE22: 15 | AF22: 15 | AG22: 15 | AH22: 15 | AI22: 15
D25: =INDIRECT( "'" & $A27 & "'"& "!" &D$2 & D$3) -> #VALUE! | E25: =INDIRECT( "'" & $A27 & "'"& "!" &E$2 & E$3) -> #VALUE! | F25: =INDIRECT( "'" & $A27 & "'"& "!" &F$2 & F$3) -> #VALUE! | G25: =INDIRECT( "'" & $A27 & "'"& "!" &G$2 & G$3) -> #VALUE! | H25: =INDIRECT( "'" & $A27 & "'"& "!" &H$2 & H$3) -> #VALUE! | I25: =INDIRECT( "'" & $A27 & "'"& "!" &I$2 & I$3) -> #VALUE! | J25: =INDIRECT( "'" & $A27 & "'"& "!" &J$2 & J$3) -> #VALUE! | K25: =INDIRECT( "'" & $A27 & "'"& "!" &K$2 & K$3) -> #VALUE! | ... AI25: =INDIRECT( "'" & $A27 & "'"& "!" &AI$2 & AI$3) -> #VALUE!
D26: =INDIRECT( "'" & $A28 & "'"& "!" &D$2 & D$3) -> #VALUE! | E26: =INDIRECT( "'" & $A28 & "'"& "!" &E$2 & E$3) -> #VALUE! | F26: =INDIRECT( "'" & $A28 & "'"& "!" &F$2 & F$3) -> #VALUE! | G26: =INDIRECT( "'" & $A28 & "'"& "!" &G$2 & G$3) -> #VALUE! | H26: =INDIRECT( "'" & $A28 & "'"& "!" &H$2 & H$3) -> #VALUE! | I26: =INDIRECT( "'" & $A28 & "'"& "!" &I$2 & I$3) -> #VALUE! | J26: =INDIRECT( "'" & $A28 & "'"& "!" &J$2 & J$3) -> #VALUE! | K26: =INDIRECT( "'" & $A28 & "'"& "!" &K$2 & K$3) -> #VALUE! | ... AI26: =INDIRECT( "'" & $A28 & "'"& "!" &AI$2 & AI$3) -> #VALUE!
A27: StGenis->Meyrin | D27: =INDIRECT( "'" & $A29 & "'"& "!" &D$2 & D$3) -> #VALUE! | E27: =INDIRECT( "'" & $A29 & "'"& "!" &E$2 & E$3) -> #VALUE! | F27: =INDIRECT( "'" & $A29 & "'"& "!" &F$2 & F$3) -> #VALUE! | G27: =INDIRECT( "'" & $A29 & "'"& "!" &G$2 & G$3) -> #VALUE! | H27: =INDIRECT( "'" & $A29 & "'"& "!" &H$2 & H$3) -> #VALUE! | I27: =INDIRECT( "'" & $A29 & "'"& "!" &I$2 & I$3) -> #VALUE! | J27: =INDIRECT( "'" & $A29 & "'"& "!" &J$2 & J$3) -> #VALUE! | K27: =INDIRECT( "'" & $A29 & "'"& "!" &K$2 & K$3) -> #VALUE! | ... AI27: =INDIRECT( "'" & $A29 & "'"& "!" &AI$2 & AI$3) -> #VALUE!
A28: StGenis->Bourdigny | D28: =INDIRECT( "'" & $A30 & "'"& "!" &D$2 & D$3) -> #VALUE! | E28: =INDIRECT( "'" & $A30 & "'"& "!" &E$2 & E$3) -> #VALUE! | F28: =INDIRECT( "'" & $A30 & "'"& "!" &F$2 & F$3) -> #VALUE! | G28: =INDIRECT( "'" & $A30 & "'"& "!" &G$2 & G$3) -> #VALUE! | H28: =INDIRECT( "'" & $A30 & "'"& "!" &H$2 & H$3) -> #VALUE! | I28: =INDIRECT( "'" & $A30 & "'"& "!" &I$2 & I$3) -> #VALUE! | J28: =INDIRECT( "'" & $A30 & "'"& "!" &J$2 & J$3) -> #VALUE! | K28: =INDIRECT( "'" & $A30 & "'"& "!" &K$2 & K$3) -> #VALUE! | ... AI28: =INDIRECT( "'" & $A30 & "'"& "!" &AI$2 & AI$3) -> #VALUE!
A29: StGenis->CERN | D29: =INDIRECT( "'" & $A31 & "'"& "!" &D$2 & D$3) -> #VALUE! | E29: =INDIRECT( "'" & $A31 & "'"& "!" &E$2 & E$3) -> #VALUE! | F29: =INDIRECT( "'" & $A31 & "'"& "!" &F$2 & F$3) -> #VALUE! | G29: =INDIRECT( "'" & $A31 & "'"& "!" &G$2 & G$3) -> #VALUE! | H29: =INDIRECT( "'" & $A31 & "'"& "!" &H$2 & H$3) -> #VALUE! | I29: =INDIRECT( "'" & $A31 & "'"& "!" &I$2 & I$3) -> #VALUE! | J29: =INDIRECT( "'" & $A31 & "'"& "!" &J$2 & J$3) -> #VALUE! | K29: =INDIRECT( "'" & $A31 & "'"& "!" &K$2 & K$3) -> #VALUE! | ... AI29: =INDIRECT( "'" & $A31 & "'"& "!" &AI$2 & AI$3) -> #VALUE!
A30: RteEurope->Meyrin | D30: =INDIRECT( "'" & $A32 & "'"& "!" &D$2 & D$3) -> #VALUE! | E30: =INDIRECT( "'" & $A32 & "'"& "!" &E$2 & E$3) -> #VALUE! | F30: =INDIRECT( "'" & $A32 & "'"& "!" &F$2 & F$3) -> #VALUE! | G30: =INDIRECT( "'" & $A32 & "'"& "!" &G$2 & G$3) -> #VALUE! | H30: =INDIRECT( "'" & $A32 & "'"& "!" &H$2 & H$3) -> #VALUE! | I30: =INDIRECT( "'" & $A32 & "'"& "!" &I$2 & I$3) -> #VALUE! | J30: =INDIRECT( "'" & $A32 & "'"& "!" &J$2 & J$3) -> #VALUE! | K30: =INDIRECT( "'" & $A32 & "'"& "!" &K$2 & K$3) -> #VALUE! | ... AI30: =INDIRECT( "'" & $A32 & "'"& "!" &AI$2 & AI$3) -> #VALUE!
A31: MategninAnneaux | D31: =INDIRECT( "'" & $A33 & "'"& "!" &D$2 & D$3) -> #VALUE! | E31: =INDIRECT( "'" & $A33 & "'"& "!" &E$2 & E$3) -> #VALUE! | F31: =INDIRECT( "'" & $A33 & "'"& "!" &F$2 & F$3) -> #VALUE! | G31: =INDIRECT( "'" & $A33 & "'"& "!" &G$2 & G$3) -> #VALUE! | H31: =INDIRECT( "'" & $A33 & "'"& "!" &H$2 & H$3) -> #VALUE! | I31: =INDIRECT( "'" & $A33 & "'"& "!" &I$2 & I$3) -> #VALUE! | J31: =INDIRECT( "'" & $A33 & "'"& "!" &J$2 & J$3) -> #VALUE! | K31: =INDIRECT( "'" & $A33 & "'"& "!" &K$2 & K$3) -> #VALUE! | ... AI31: =INDIRECT( "'" & $A33 & "'"& "!" &AI$2 & AI$3) -> #VALUE!
A32: MategninDouane | D32: =INDIRECT( "'" & $A34 & "'"& "!" &D$2 & D$3) -> #VALUE! | E32: =INDIRECT( "'" & $A34 & "'"& "!" &E$2 & E$3) -> #VALUE! | F32: =INDIRECT( "'" & $A34 & "'"& "!" &F$2 & F$3) -> #VALUE! | G32: =INDIRECT( "'" & $A34 & "'"& "!" &G$2 & G$3) -> #VALUE! | H32: =INDIRECT( "'" & $A34 & "'"& "!" &H$2 & H$3) -> #VALUE! | I32: =INDIRECT( "'" & $A34 & "'"& "!" &I$2 & I$3) -> #VALUE! | J32: =INDIRECT( "'" & $A34 & "'"& "!" &J$2 & J$3) -> #VALUE! | K32: =INDIRECT( "'" & $A34 & "'"& "!" &K$2 & K$3) -> #VALUE! | ... AI32: =INDIRECT( "'" & $A34 & "'"& "!" &AI$2 & AI$3) -> #VALUE!
A33: PdG Nord Total | D33: =INDIRECT( "'" & $A35 & "'"& "!" &D$2 & D$3) -> #VALUE! | E33: =INDIRECT( "'" & $A35 & "'"& "!" &E$2 & E$3) -> #VALUE! | F33: =INDIRECT( "'" & $A35 & "'"& "!" &F$2 & F$3) -> #VALUE! | G33: =INDIRECT( "'" & $A35 & "'"& "!" &G$2 & G$3) -> #VALUE! | H33: =INDIRECT( "'" & $A35 & "'"& "!" &H$2 & H$3) -> #VALUE! | I33: =INDIRECT( "'" & $A35 & "'"& "!" &I$2 & I$3) -> #VALUE! | J33: =INDIRECT( "'" & $A35 & "'"& "!" &J$2 & J$3) -> #VALUE! | K33: =INDIRECT( "'" & $A35 & "'"& "!" &K$2 & K$3) -> #VALUE! | ... AI33: =INDIRECT( "'" & $A35 & "'"& "!" &AI$2 & AI$3) -> #VALUE!
A34: Challex->Dardagny | D34: =INDIRECT( "'" & $A36 & "'"& "!" &D$2 & D$3) -> #VALUE! | E34: =INDIRECT( "'" & $A36 & "'"& "!" &E$2 & E$3) -> #VALUE! | F34: =INDIRECT( "'" & $A36 & "'"& "!" &F$2 & F$3) -> #VALUE! | G34: =INDIRECT( "'" & $A36 & "'"& "!" &G$2 & G$3) -> #VALUE! | H34: =INDIRECT( "'" & $A36 & "'"& "!" &H$2 & H$3) -> #VALUE! | I34: =INDIRECT( "'" & $A36 & "'"& "!" &I$2 & I$3) -> #VALUE! | J34: =INDIRECT( "'" & $A36 & "'"& "!" &J$2 & J$3) -> #VALUE! | K34: =INDIRECT( "'" & $A36 & "'"& "!" &K$2 & K$3) -> #VALUE! | ... AI34: =INDIRECT( "'" & $A36 & "'"& "!" &AI$2 & AI$3) -> #VALUE!
A35: PdG Sud Total
A36: APiCy total

Sheet Resumé CICLABLE
B1: > CH Vélo traditionel H Total | C1: > CH Vélo traditionel F Total | D1: > CH VAE H Total | E1: > CH VAE F Total | F1: > CH Mode Nouveau H Total | G1: > CH Mode Nouveau F Total | H1: > CH Piéton/ne H Total | I1: > CH Piéton/ne F Total | J1: >FR Vélo traditionel H Total | K1: >FR Vélo traditionel F Total | L1: >FR VAE H Total | M1: >FR VAE F Total | N1: >FR Mode Nouveau H Total | O1: >FR Mode Nouveau F Total | P1: >FR Piéton/ne H Total | Q1: >FR Piéton/ne F Total | R1: > CH Vélo traditionel H HP | S1: > CH Vélo traditionel F HP | T1: > CH VAE H HP | U1: > CH VAE F HP | V1: > CH Mode Nouveau H HP | W1: > CH Mode Nouveau F HP | X1: > CH Piéton/ne H HP | Y1: > CH Piéton/ne F HP | Z1: >FR Vélo traditionel H HP | AA1: >FR Vélo traditionel F HP | AB1: >FR VAE H HP | AC1: >FR VAE F HP | AD1: >FR Mode Nouveau H HP | AE1: >FR Mode Nouveau F HP | AF1: >FR Piéton/ne H HP | AG1: >FR Piéton/ne F HP | AI1: Velos total | AJ1: Vélos HP | AK1: % VAE dans le total | AL1: NB VAE dans le total | AM1: % femmes dans le total | AN1: NB de femmes dans le total | AO1: % de VAE chez les femmes | AP1: NB de VAE chez les femmes | AQ1: Autres modes total | AR1: Autres Modes HP | AS1: Pietons total | AT1: Pietons HP | AU1: >CH total | AV1: >CH HP | AW1: >FR total | AX1: >FR HP
B2: B | C2: C | D2: D | E2: E | F2: F | G2: G | H2: H | I2: I | J2: J | K2: K | L2: L | M2: M | N2: N | O2: O | P2: P | Q2: Q | R2: B | S2: C | T2: D | U2: E | V2: F | W2: G | X2: H | Y2: I | Z2: J | AA2: K | AB2: L | AC2: M | AD2: N | AE2: O | AF2: P | AG2: Q
B3: 14 | C3: 14 | D3: 14 | E3: 14 | F3: 14 | G3: 14 | H3: 14 | I3: 14 | J3: 14 | K3: 14 | L3: 14 | M3: 14 | N3: 14 | O3: 14 | P3: 14 | Q3: 14 | R3: 15 | S3: 15 | T3: 15 | U3: 15 | V3: 15 | W3: 15 | X3: 15 | Y3: 15 | Z3: 15 | AA3: 15 | AB3: 15 | AC3: 15 | AD3: 15 | AE3: 15 | AF3: 15 | AG3: 15
