Workbook

Sheet APiCy total
B1: Lieu:
B2: France -> Suisse | J2: Suisse -> France | S2: Totaux | AG2: 2019 | AP2: Chanagement 2019 -> 2020
B3: Vélo traditionel | D3: VAE | F3: Mode Nouveau Electrique | H3: Piéton/ne | J3: Vélo traditionel | L3: VAE | N3: Mode Nouveau Electrique (trotinette, scateboard , …) | P3: Piéton/ne | S3: Hommes | T3: Femmes | U3: %Femmes | V3: VT | W3: VAE | X3: Nouveau | Y3: 2r | Z3: %VAE | AA3: %Nouveau | AB3: Piétons | AC3: >CH | AD3: >FR | AE3: TOT | AG3: Cyclistes | AH3: Pietons | AI3: Hommes | AJ3: Femmes | AK3: -> CH | AL3: -> FR | AM3: % femmes | AN3: TOTAL | AP3: Cyclistes | AQ3: Pietons | AR3: Hommes | AS3: Femmes | AT3: -> CH | AU3: -> FR | AV3: % femmes | AW3: TOTAL
A4: Heure | B4: H | C4: F | D4: H | E4: F | F4: H | G4: F | H4: H | I4: F | J4: H | K4: F | L4: H | M4: F | N4: H | O4: F | P4: H | Q4: F
A5: 0.29166667 | B5: =Ferney!B5+'StGenis total'!B5+Crassy!B5+'Mategnin Total'!B5 -> 24 | C5: =Ferney!C5+'StGenis total'!C5+Crassy!C5+'Mategnin Total'!C5 -> 7 | D5: =Ferney!D5+'StGenis total'!D5+Crassy!D5+'Mategnin Total'!D5 -> 8 | E5: =Ferney!E5+'StGenis total'!E5+Crassy!E5+'Mategnin Total'!E5 -> 15 | F5: =Ferney!F5+'StGenis total'!F5+Crassy!F5+'Mategnin Total'!F5 -> 2 | G5: =Ferney!G5+'StGenis total'!G5+Crassy!G5+'Mategnin Total'!G5 -> 1 | H5: =Ferney!H5+'StGenis total'!H5+Crassy!H5+'Mategnin Total'!H5 -> 5 | I5: =Ferney!I5+'StGenis total'!I5+Crassy!I5+'Mategnin Total'!I5 -> 1 | ... Q5: =Ferney!Q5+'StGenis total'!Q5+Crassy!Q5+'Mategnin Total'!Q5 -> 0 | S5: =B5+D5+F5+H5+J5+L5+N5+P5 -> 43 | T5: =C5+E5+G5+I5+K5+M5+O5+Q5 -> 26 | U5: =T5/(T5+S5) -> 0.37681159 | V5: =B5+C5+J5+K5 -> 35 | W5: =D5+E5+L5+M5 -> 25 | X5: =F5+G5+N5+O5 -> 3 | Y5: =SUM(V5:X5) -> 63 | Z5: =W5/Y5 -> 0.3968254 | AA5: =X5/Y5 -> 0.047619048 | AB5: =H5+I5+P5+Q5 -> 6 | AC5: =SUM(B5:I5) -> 63 | AD5: =SUM(J5:Q5) -> 6 | AE5: =SUM(B5:Q5) -> 69
A6: 0.30208333 | B6: =Ferney!B6+'StGenis total'!B6+Crassy!B6+'Mategnin Total'!B6 -> 36 | C6: =Ferney!C6+'StGenis total'!C6+Crassy!C6+'Mategnin Total'!C6 -> 11 | D6: =Ferney!D6+'StGenis total'!D6+Crassy!D6+'Mategnin Total'!D6 -> 14 | E6: =Ferney!E6+'StGenis total'!E6+Crassy!E6+'Mategnin Total'!E6 -> 12 | F6: =Ferney!F6+'StGenis total'!F6+Crassy!F6+'Mategnin Total'!F6 -> 3 | G6: =Ferney!G6+'StGenis total'!G6+Crassy!G6+'Mategnin Total'!G6 -> 1 | H6: =Ferney!H6+'StGenis total'!H6+Crassy!H6+'Mategnin Total'!H6 -> 7 | I6: =Ferney!I6+'StGenis total'!I6+Crassy!I6+'Mategnin Total'!I6 -> 3 | ... Q6: =Ferney!Q6+'StGenis total'!Q6+Crassy!Q6+'Mategnin Total'!Q6 -> 0 | S6: =B6+D6+F6+H6+J6+L6+N6+P6 -> 67 | T6: =C6+E6+G6+I6+K6+M6+O6+Q6 -> 30 | U6: =T6/(T6+S6) -> 0.30927835 | V6: =B6+C6+J6+K6 -> 54 | W6: =D6+E6+L6+M6 -> 28 | X6: =F6+G6+N6+O6 -> 5 | Y6: =SUM(V6:X6) -> 87 | Z6: =W6/Y6 -> 0.32183908 | AA6: =X6/Y6 -> 0.057471264 | AB6: =H6+I6+P6+Q6 -> 10 | AC6: =SUM(B6:I6) -> 87 | AD6: =SUM(J6:Q6) -> 10 | AE6: =SUM(B6:Q6) -> 97
A7: 0.3125 | B7: =Ferney!B7+'StGenis total'!B7+Crassy!B7+'Mategnin Total'!B7 -> 34 | C7: =Ferney!C7+'StGenis total'!C7+Crassy!C7+'Mategnin Total'!C7 -> 14 | D7: =Ferney!D7+'StGenis total'!D7+Crassy!D7+'Mategnin Total'!D7 -> 10 | E7: =Ferney!E7+'StGenis total'!E7+Crassy!E7+'Mategnin Total'!E7 -> 7 | F7: =Ferney!F7+'StGenis total'!F7+Crassy!F7+'Mategnin Total'!F7 -> 1 | G7: =Ferney!G7+'StGenis total'!G7+Crassy!G7+'Mategnin Total'!G7 -> 1 | H7: =Ferney!H7+'StGenis total'!H7+Crassy!H7+'Mategnin Total'!H7 -> 3 | I7: =Ferney!I7+'StGenis total'!I7+Crassy!I7+'Mategnin Total'!I7 -> 0 | ... Q7: =Ferney!Q7+'StGenis total'!Q7+Crassy!Q7+'Mategnin Total'!Q7 -> 0 | S7: =B7+D7+F7+H7+J7+L7+N7+P7 -> 55 | T7: =C7+E7+G7+I7+K7+M7+O7+Q7 -> 23 | U7: =T7/(T7+S7) -> 0.29487179 | V7: =B7+C7+J7+K7 -> 52 | W7: =D7+E7+L7+M7 -> 20 | X7: =F7+G7+N7+O7 -> 2 | Y7: =SUM(V7:X7) -> 74 | Z7: =W7/Y7 -> 0.27027027 | AA7: =X7/Y7 -> 0.027027027 | AB7: =H7+I7+P7+Q7 -> 4 | AC7: =SUM(B7:I7) -> 70 | AD7: =SUM(J7:Q7) -> 8 | AE7: =SUM(B7:Q7) -> 78
A8: 0.32291667 | B8: =Ferney!B8+'StGenis total'!B8+Crassy!B8+'Mategnin Total'!B8 -> 28 | C8: =Ferney!C8+'StGenis total'!C8+Crassy!C8+'Mategnin Total'!C8 -> 8 | D8: =Ferney!D8+'StGenis total'!D8+Crassy!D8+'Mategnin Total'!D8 -> 10 | E8: =Ferney!E8+'StGenis total'!E8+Crassy!E8+'Mategnin Total'!E8 -> 14 | F8: =Ferney!F8+'StGenis total'!F8+Crassy!F8+'Mategnin Total'!F8 -> 1 | G8: =Ferney!G8+'StGenis total'!G8+Crassy!G8+'Mategnin Total'!G8 -> 3 | H8: =Ferney!H8+'StGenis total'!H8+Crassy!H8+'Mategnin Total'!H8 -> 3 | I8: =Ferney!I8+'StGenis total'!I8+Crassy!I8+'Mategnin Total'!I8 -> 1 | ... Q8: =Ferney!Q8+'StGenis total'!Q8+Crassy!Q8+'Mategnin Total'!Q8 -> 1 | S8: =B8+D8+F8+H8+J8+L8+N8+P8 -> 45 | T8: =C8+E8+G8+I8+K8+M8+O8+Q8 -> 30 | U8: =T8/(T8+S8) -> 0.4 | V8: =B8+C8+J8+K8 -> 38 | W8: =D8+E8+L8+M8 -> 24 | X8: =F8+G8+N8+O8 -> 6 | Y8: =SUM(V8:X8) -> 68 | Z8: =W8/Y8 -> 0.35294118 | AA8: =X8/Y8 -> 0.088235294 | AB8: =H8+I8+P8+Q8 -> 7 | AC8: =SUM(B8:I8) -> 68 | AD8: =SUM(J8:Q8) -> 7 | AE8: =SUM(B8:Q8) -> 75
A9: 0.33333333 | B9: =Ferney!B9+'StGenis total'!B9+Crassy!B9+'Mategnin Total'!B9 -> 21 | C9: =Ferney!C9+'StGenis total'!C9+Crassy!C9+'Mategnin Total'!C9 -> 14 | D9: =Ferney!D9+'StGenis total'!D9+Crassy!D9+'Mategnin Total'!D9 -> 10 | E9: =Ferney!E9+'StGenis total'!E9+Crassy!E9+'Mategnin Total'!E9 -> 8 | F9: =Ferney!F9+'StGenis total'!F9+Crassy!F9+'Mategnin Total'!F9 -> 2 | G9: =Ferney!G9+'StGenis total'!G9+Crassy!G9+'Mategnin Total'!G9 -> 0 | H9: =Ferney!H9+'StGenis total'!H9+Crassy!H9+'Mategnin Total'!H9 -> 8 | I9: =Ferney!I9+'StGenis total'!I9+Crassy!I9+'Mategnin Total'!I9 -> 0 | ... Q9: =Ferney!Q9+'StGenis total'!Q9+Crassy!Q9+'Mategnin Total'!Q9 -> 1 | S9: =B9+D9+F9+H9+J9+L9+N9+P9 -> 47 | T9: =C9+E9+G9+I9+K9+M9+O9+Q9 -> 24 | U9: =T9/(T9+S9) -> 0.33802817 | V9: =B9+C9+J9+K9 -> 40 | W9: =D9+E9+L9+M9 -> 20 | X9: =F9+G9+N9+O9 -> 2 | Y9: =SUM(V9:X9) -> 62 | Z9: =W9/Y9 -> 0.32258065 | AA9: =X9/Y9 -> 0.032258065 | AB9: =H9+I9+P9+Q9 -> 9 | AC9: =SUM(B9:I9) -> 63 | AD9: =SUM(J9:Q9) -> 8 | AE9: =SUM(B9:Q9) -> 71
A10: 0.34375 | B10: =Ferney!B10+'StGenis total'!B10+Crassy!B10+'Mategnin Total'!B10 -> 24 | C10: =Ferney!C10+'StGenis total'!C10+Crassy!C10+'Mategnin Total'!C10 -> 13 | D10: =Ferney!D10+'StGenis total'!D10+Crassy!D10+'Mategnin Total'!D10 -> 8 | E10: =Ferney!E10+'StGenis total'!E10+Crassy!E10+'Mategnin Total'!E10 -> 16 | F10: =Ferney!F10+'StGenis total'!F10+Crassy!F10+'Mategnin Total'!F10 -> 3 | G10: =Ferney!G10+'StGenis total'!G10+Crassy!G10+'Mategnin Total'!G10 -> 3 | H10: =Ferney!H10+'StGenis total'!H10+Crassy!H10+'Mategnin Total'!H10 -> 5 | I10: =Ferney!I10+'StGenis total'!I10+Crassy!I10+'Mategnin Total'!I10 -> 2 | ... Q10: =Ferney!Q10+'StGenis total'!Q10+Crassy!Q10+'Mategnin Total'!Q10 -> 4 | S10: =B10+D10+F10+H10+J10+L10+N10+P10 -> 48 | T10: =C10+E10+G10+I10+K10+M10+O10+Q10 -> 39 | U10: =T10/(T10+S10) -> 0.44827586 | V10: =B10+C10+J10+K10 -> 40 | W10: =D10+E10+L10+M10 -> 27 | X10: =F10+G10+N10+O10 -> 6 | Y10: =SUM(V10:X10) -> 73 | Z10: =W10/Y10 -> 0.36986301 | AA10: =X10/Y10 -> 0.082191781 | AB10: =H10+I10+P10+Q10 -> 14 | AC10: =SUM(B10:I10) -> 74 | AD10: =SUM(J10:Q10) -> 13 | AE10: =SUM(B10:Q10) -> 87
A11: 0.35416667 | B11: =Ferney!B11+'StGenis total'!B11+Crassy!B11+'Mategnin Total'!B11 -> 35 | C11: =Ferney!C11+'StGenis total'!C11+Crassy!C11+'Mategnin Total'!C11 -> 8 | D11: =Ferney!D11+'StGenis total'!D11+Crassy!D11+'Mategnin Total'!D11 -> 9 | E11: =Ferney!E11+'StGenis total'!E11+Crassy!E11+'Mategnin Total'!E11 -> 6 | F11: =Ferney!F11+'StGenis total'!F11+Crassy!F11+'Mategnin Total'!F11 -> 5 | G11: =Ferney!G11+'StGenis total'!G11+Crassy!G11+'Mategnin Total'!G11 -> 6 | H11: =Ferney!H11+'StGenis total'!H11+Crassy!H11+'Mategnin Total'!H11 -> 10 | I11: =Ferney!I11+'StGenis total'!I11+Crassy!I11+'Mategnin Total'!I11 -> 0 | ... Q11: =Ferney!Q11+'StGenis total'!Q11+Crassy!Q11+'Mategnin Total'!Q11 -> 0 | S11: =B11+D11+F11+H11+J11+L11+N11+P11 -> 66 | T11: =C11+E11+G11+I11+K11+M11+O11+Q11 -> 24 | U11: =T11/(T11+S11) -> 0.26666667 | V11: =B11+C11+J11+K11 -> 50 | W11: =D11+E11+L11+M11 -> 19 | X11: =F11+G11+N11+O11 -> 11 | Y11: =SUM(V11:X11) -> 80 | Z11: =W11/Y11 -> 0.2375 | AA11: =X11/Y11 -> 0.1375 | AB11: =H11+I11+P11+Q11 -> 10 | AC11: =SUM(B11:I11) -> 79 | AD11: =SUM(J11:Q11) -> 11 | AE11: =SUM(B11:Q11) -> 90
A12: 0.36458333 | B12: =Ferney!B12+'StGenis total'!B12+Crassy!B12+'Mategnin Total'!B12 -> 18 | C12: =Ferney!C12+'StGenis total'!C12+Crassy!C12+'Mategnin Total'!C12 -> 9 | D12: =Ferney!D12+'StGenis total'!D12+Crassy!D12+'Mategnin Total'!D12 -> 9 | E12: =Ferney!E12+'StGenis total'!E12+Crassy!E12+'Mategnin Total'!E12 -> 2 | F12: =Ferney!F12+'StGenis total'!F12+Crassy!F12+'Mategnin Total'!F12 -> 2 | G12: =Ferney!G12+'StGenis total'!G12+Crassy!G12+'Mategnin Total'!G12 -> 5 | H12: =Ferney!H12+'StGenis total'!H12+Crassy!H12+'Mategnin Total'!H12 -> 7 | I12: =Ferney!I12+'StGenis total'!I12+Crassy!I12+'Mategnin Total'!I12 -> 3 | ... Q12: =Ferney!Q12+'StGenis total'!Q12+Crassy!Q12+'Mategnin Total'!Q12 -> 5 | S12: =B12+D12+F12+H12+J12+L12+N12+P12 -> 43 | T12: =C12+E12+G12+I12+K12+M12+O12+Q12 -> 28 | U12: =T12/(T12+S12) -> 0.3943662 | V12: =B12+C12+J12+K12 -> 35 | W12: =D12+E12+L12+M12 -> 12 | X12: =F12+G12+N12+O12 -> 7 | Y12: =SUM(V12:X12) -> 54 | Z12: =W12/Y12 -> 0.22222222 | AA12: =X12/Y12 -> 0.12962963 | AB12: =H12+I12+P12+Q12 -> 17 | AC12: =SUM(B12:I12) -> 55 | AD12: =SUM(J12:Q12) -> 16 | AE12: =SUM(B12:Q12) -> 71
A13: Total | B13: =SUM(B5:B12) -> 220 | C13: =SUM(C5:C12) -> 84 | D13: =SUM(D5:D12) -> 78 | E13: =SUM(E5:E12) -> 80 | F13: =SUM(F5:F12) -> 19 | G13: =SUM(G5:G12) -> 20 | H13: =SUM(H5:H12) -> 48 | I13: =SUM(I5:I12) -> 10 | ... Q13: =SUM(Q5:Q12) -> 11 | S13: =B13+D13+F13+H13+J13+L13+N13+P13 -> 414 | T13: =C13+E13+G13+I13+K13+M13+O13+Q13 -> 224 | U13: =T13/(T13+S13) -> 0.35109718 | V13: =B13+C13+J13+K13 -> 344 | W13: =D13+E13+L13+M13 -> 175 | X13: =F13+G13+N13+O13 -> 42 | Y13: =SUM(V13:X13) -> 561 | Z13: =W13/Y13 -> 0.31194296 | AA13: =X13/Y13 -> 0.07486631 | AB13: =H13+I13+P13+Q13 -> 77 | AC13: =SUM(B13:I13) -> 559 | AD13: =SUM(J13:Q13) -> 79 | AE13: =SUM(B13:Q13) -> 638 | AG13: =Ferney!AG13+'StGenis total'!AG13+'Mategnin Total'!AG13 -> 1049 | AH13: =Ferney!AH13+'StGenis total'!AH13+'Mategnin Total'!AH13 -> 160 | AI13: =Ferney!AI13+'StGenis total'!AI13+'Mategnin Total'!AI13 -> 846 | AJ13: =Ferney!AJ13+'StGenis total'!AJ13+'Mategnin Total'!AJ13 -> 363 | AK13: =Ferney!AK13+'StGenis total'!AK13+'Mategnin Total'!AK13 -> 1105 | AL13: =Ferney!AL13+'StGenis total'!AL13+'Mategnin Total'!AL13 -> 104 | AM13: =AJ13/(AJ13+AI13) -> 0.30024814 | AN13: =Ferney!AN13+'StGenis total'!AN13+'Mategnin Total'!AN13 -> 1209 | AP13: =(Y13-AG13)/AG13 -> -0.46520496 | AQ13: =(AB13-AH13)/AH13 -> -0.51875 | AR13: =(S13-AI13)/AI13 -> -0.5106383 | AS13: =(T13-AJ13)/AJ13 -> -0.38292011 | AT13: =(AC13-AK13)/AK13 -> -0.49411765 | AU13: =(AD13-AL13)/AL13 -> -0.24038462 | AV13: =(U13-AM13)/AM13 -> 0.16935672 | AW13: =(AE13-AN13)/AN13 -> -0.47229115
A14: Total HP | B14: =SUM(B7:B10) -> 107 | C14: =SUM(C7:C10) -> 49 | D14: =SUM(D7:D10) -> 38 | E14: =SUM(E7:E10) -> 45 | F14: =SUM(F7:F10) -> 7 | G14: =SUM(G7:G10) -> 7 | H14: =SUM(H7:H10) -> 19 | I14: =SUM(I7:I10) -> 3 | ... Q14: =SUM(Q7:Q10) -> 6 | S14: =B14+D14+F14+H14+J14+L14+N14+P14 -> 195 | T14: =C14+E14+G14+I14+K14+M14+O14+Q14 -> 116 | U14: =T14/(T14+S14) -> 0.37299035 | V14: =B14+C14+J14+K14 -> 170 | W14: =D14+E14+L14+M14 -> 91 | X14: =F14+G14+N14+O14 -> 16 | Y14: =SUM(V14:X14) -> 277 | Z14: =W14/Y14 -> 0.32851986 | AA14: =X14/Y14 -> 0.057761733 | AB14: =H14+I14+P14+Q14 -> 34 | AC14: =SUM(B14:I14) -> 275 | AD14: =SUM(J14:Q14) -> 36 | AE14: =SUM(B14:Q14) -> 311
A16: Tot 7 | B16: =SUM(B5:B8) -> 122 | C16: =SUM(C5:C8) -> 40 | D16: =SUM(D5:D8) -> 42 | E16: =SUM(E5:E8) -> 48 | F16: =SUM(F5:F8) -> 7 | G16: =SUM(G5:G8) -> 6 | H16: =SUM(H5:H8) -> 18 | I16: =SUM(I5:I8) -> 5 | ... Q16: =SUM(Q5:Q8) -> 1
A17: Tot 8 | B17: =SUM(B9:B12) -> 98 | C17: =SUM(C9:C12) -> 44 | D17: =SUM(D9:D12) -> 36 | E17: =SUM(E9:E12) -> 32 | F17: =SUM(F9:F12) -> 12 | G17: =SUM(G9:G12) -> 14 | H17: =SUM(H9:H12) -> 30 | I17: =SUM(I9:I12) -> 5 | ... Q17: =SUM(Q9:Q12) -> 10

Sheet Ferney
B1: Lieu:
B2: France -> Suisse | J2: Suisse -> France | S2: Totaux | AG2: 2019 | AP2: Chanagement 2019 -> 2020
B3: Vélo traditionel | D3: VAE | F3: Mode Nouveau Electrique | H3: Piéton/ne | J3: Vélo traditionel | L3: VAE | N3: Mode Nouveau Electrique (trotinette, scateboard , …) | P3: Piéton/ne | S3: Hommes | T3: Femmes | U3: %Femmes | V3: VT | W3: VAE | X3: Nouveau | Y3: 2r | Z3: %VAE | AA3: %Nouveau | AB3: Piétons | AC3: >CH | AD3: >FR | AE3: TOT | AG3: Cyclistes | AH3: Pietons | AI3: Hommes | AJ3: Femmes | AK3: -> CH | AL3: -> FR | AM3: % femmes | AN3: TOTAL | AP3: Cyclistes | AQ3: Pietons | AR3: Hommes | AS3: Femmes | AT3: -> CH | AU3: -> FR | AV3: % femmes | AW3: TOTAL
A4: Heure | B4: H | C4: F | D4: H | E4: F | F4: H | G4: F | H4: H | I4: F | J4: H | K4: F | L4: H | M4: F | N4: H | O4: F | P4: H | Q4: F
A5: 0.29166667 | B5: 3 | C5: 3 | D5: 1 | E5: 4 | K5: 1 | S5: =B5+D5+F5+H5+J5+L5+N5+P5 -> 4 | T5: =C5+E5+G5+I5+K5+M5+O5+Q5 -> 8 | U5: =T5/(T5+S5) -> 0.66666667 | V5: =B5+C5+J5+K5 -> 7 | W5: =D5+E5+L5+M5 -> 5 | X5: =F5+G5+N5+O5 -> 0 | Y5: =SUM(V5:X5) -> 12 | Z5: =W5/Y5 -> 0.41666667 | AA5: =X5/Y5 -> 0 | AB5: =H5+I5+P5+Q5 -> 0 | AC5: =SUM(B5:I5) -> 11 | AD5: =SUM(J5:Q5) -> 1 | AE5: =SUM(B5:Q5) -> 12
A6: 0.30208333 | B6: 6 | D6: 2 | E6: 4 | H6: 1 | S6: =B6+D6+F6+H6+J6+L6+N6+P6 -> 9 | T6: =C6+E6+G6+I6+K6+M6+O6+Q6 -> 4 | U6: =T6/(T6+S6) -> 0.30769231 | V6: =B6+C6+J6+K6 -> 6 | W6: =D6+E6+L6+M6 -> 6 | X6: =F6+G6+N6+O6 -> 0 | Y6: =SUM(V6:X6) -> 12 | Z6: =W6/Y6 -> 0.5 | AA6: =X6/Y6 -> 0 | AB6: =H6+I6+P6+Q6 -> 1 | AC6: =SUM(B6:I6) -> 13 | AD6: =SUM(J6:Q6) -> 0 | AE6: =SUM(B6:Q6) -> 13
A7: 0.3125 | B7: 8 | C7: 4 | D7: 5 | E7: 1 | J7: 1 | S7: =B7+D7+F7+H7+J7+L7+N7+P7 -> 14 | T7: =C7+E7+G7+I7+K7+M7+O7+Q7 -> 5 | U7: =T7/(T7+S7) -> 0.26315789 | V7: =B7+C7+J7+K7 -> 13 | W7: =D7+E7+L7+M7 -> 6 | X7: =F7+G7+N7+O7 -> 0 | Y7: =SUM(V7:X7) -> 19 | Z7: =W7/Y7 -> 0.31578947 | AA7: =X7/Y7 -> 0 | AB7: =H7+I7+P7+Q7 -> 0 | AC7: =SUM(B7:I7) -> 18 | AD7: =SUM(J7:Q7) -> 1 | AE7: =SUM(B7:Q7) -> 19
A8: 0.32291667 | B8: 10 | C8: 1 | D8: 1 | E8: 5 | S8: =B8+D8+F8+H8+J8+L8+N8+P8 -> 11 | T8: =C8+E8+G8+I8+K8+M8+O8+Q8 -> 6 | U8: =T8/(T8+S8) -> 0.35294118 | V8: =B8+C8+J8+K8 -> 11 | W8: =D8+E8+L8+M8 -> 6 | X8: =F8+G8+N8+O8 -> 0 | Y8: =SUM(V8:X8) -> 17 | Z8: =W8/Y8 -> 0.35294118 | AA8: =X8/Y8 -> 0 | AB8: =H8+I8+P8+Q8 -> 0 | AC8: =SUM(B8:I8) -> 17 | AD8: =SUM(J8:Q8) -> 0 | AE8: =SUM(B8:Q8) -> 17
A9: 0.33333333 | B9: 5 | C9: 7 | D9: 4 | E9: 5 | F9: 2 | J9: 1 | L9: 1 | S9: =B9+D9+F9+H9+J9+L9+N9+P9 -> 13 | T9: =C9+E9+G9+I9+K9+M9+O9+Q9 -> 12 | U9: =T9/(T9+S9) -> 0.48 | V9: =B9+C9+J9+K9 -> 13 | W9: =D9+E9+L9+M9 -> 10 | X9: =F9+G9+N9+O9 -> 2 | Y9: =SUM(V9:X9) -> 25 | Z9: =W9/Y9 -> 0.4 | AA9: =X9/Y9 -> 0.08 | AB9: =H9+I9+P9+Q9 -> 0 | AC9: =SUM(B9:I9) -> 23 | AD9: =SUM(J9:Q9) -> 2 | AE9: =SUM(B9:Q9) -> 25
A10: 0.34375 | B10: 3 | C10: 3 | D10: 3 | E10: 10 | F10: 2 | G10: 1 | H10: 1 | J10: 3 | L10: 1 | S10: =B10+D10+F10+H10+J10+L10+N10+P10 -> 13 | T10: =C10+E10+G10+I10+K10+M10+O10+Q10 -> 14 | U10: =T10/(T10+S10) -> 0.51851852 | V10: =B10+C10+J10+K10 -> 9 | W10: =D10+E10+L10+M10 -> 14 | X10: =F10+G10+N10+O10 -> 3 | Y10: =SUM(V10:X10) -> 26 | Z10: =W10/Y10 -> 0.53846154 | AA10: =X10/Y10 -> 0.11538462 | AB10: =H10+I10+P10+Q10 -> 1 | AC10: =SUM(B10:I10) -> 23 | AD10: =SUM(J10:Q10) -> 4 | AE10: =SUM(B10:Q10) -> 27
A11: 0.35416667 | B11: 13 | C11: 3 | D11: 5 | E11: 4 | G11: 1 | H11: 1 | L11: 2 | M11: 1 | S11: =B11+D11+F11+H11+J11+L11+N11+P11 -> 21 | T11: =C11+E11+G11+I11+K11+M11+O11+Q11 -> 9 | U11: =T11/(T11+S11) -> 0.3 | V11: =B11+C11+J11+K11 -> 16 | W11: =D11+E11+L11+M11 -> 12 | X11: =F11+G11+N11+O11 -> 1 | Y11: =SUM(V11:X11) -> 29 | Z11: =W11/Y11 -> 0.4137931 | AA11: =X11/Y11 -> 0.034482759 | AB11: =H11+I11+P11+Q11 -> 1 | AC11: =SUM(B11:I11) -> 27 | AD11: =SUM(J11:Q11) -> 3 | AE11: =SUM(B11:Q11) -> 30
A12: 0.36458333 | B12: 6 | C12: 2 | D12: 4 | G12: 1 | H12: 1 | J12: 2 | K12: 1 | S12: =B12+D12+F12+H12+J12+L12+N12+P12 -> 13 | T12: =C12+E12+G12+I12+K12+M12+O12+Q12 -> 4 | U12: =T12/(T12+S12) -> 0.23529412 | V12: =B12+C12+J12+K12 -> 11 | W12: =D12+E12+L12+M12 -> 4 | X12: =F12+G12+N12+O12 -> 1 | Y12: =SUM(V12:X12) -> 16 | Z12: =W12/Y12 -> 0.25 | AA12: =X12/Y12 -> 0.0625 | AB12: =H12+I12+P12+Q12 -> 1 | AC12: =SUM(B12:I12) -> 14 | AD12: =SUM(J12:Q12) -> 3 | AE12: =SUM(B12:Q12) -> 17
A13: Total | B13: =SUM(B5:B12) -> 54 | C13: =SUM(C5:C12) -> 23 | D13: =SUM(D5:D12) -> 25 | E13: =SUM(E5:E12) -> 33 | F13: =SUM(F5:F12) -> 4 | G13: =SUM(G5:G12) -> 3 | H13: =SUM(H5:H12) -> 4 | I13: =SUM(I5:I12) -> 0 | ... Q13: =SUM(Q5:Q12) -> 0 | S13: =B13+D13+F13+H13+J13+L13+N13+P13 -> 98 | T13: =C13+E13+G13+I13+K13+M13+O13+Q13 -> 62 | U13: =T13/(T13+S13) -> 0.3875 | V13: =B13+C13+J13+K13 -> 86 | W13: =D13+E13+L13+M13 -> 63 | X13: =F13+G13+N13+O13 -> 7 | Y13: =SUM(V13:X13) -> 156 | Z13: =W13/Y13 -> 0.40384615 | AA13: =X13/Y13 -> 0.044871795 | AB13: =H13+I13+P13+Q13 -> 4 | AC13: =SUM(B13:I13) -> 146 | AD13: =SUM(J13:Q13) -> 14 | AE13: =SUM(B13:Q13) -> 160 | AG13: 312 | AH13: 38 | AI13: 204 | AJ13: 146 | AK13: 342 | AL13: 8 | AM13: =AJ13/(AJ13+AI13) -> 0.41714286 | AN13: 350 | AP13: =(Y13-AG13)/AG13 -> -0.5 | AQ13: =(AB13-AH13)/AH13 -> -0.89473684 | AR13: =(S13-AI13)/AI13 -> -0.51960784 | AS13: =(T13-AJ13)/AJ13 -> -0.57534247 | AT13: =(AC13-AK13)/AK13 -> -0.57309942 | AU13: =(AD13-AL13)/AL13 -> 0.75 | AV13: =(U13-AM13)/AM13 -> -0.071061644 | AW13: =(AE13-AN13)/AN13 -> -0.54285714
A14: Total HP | B14: =SUM(B7:B10) -> 26 | C14: =SUM(C7:C10) -> 15 | D14: =SUM(D7:D10) -> 13 | E14: =SUM(E7:E10) -> 21 | F14: =SUM(F7:F10) -> 4 | G14: =SUM(G7:G10) -> 1 | H14: =SUM(H7:H10) -> 1 | I14: =SUM(I7:I10) -> 0 | ... Q14: =SUM(Q7:Q10) -> 0 | S14: =B14+D14+F14+H14+J14+L14+N14+P14 -> 51 | T14: =C14+E14+G14+I14+K14+M14+O14+Q14 -> 37 | U14: =T14/(T14+S14) -> 0.42045455 | V14: =B14+C14+J14+K14 -> 46 | W14: =D14+E14+L14+M14 -> 36 | X14: =F14+G14+N14+O14 -> 5 | Y14: =SUM(V14:X14) -> 87 | Z14: =W14/Y14 -> 0.4137931 | AA14: =X14/Y14 -> 0.057471264 | AB14: =H14+I14+P14+Q14 -> 1 | AC14: =SUM(B14:I14) -> 81 | AD14: =SUM(J14:Q14) -> 7 | AE14: =SUM(B14:Q14) -> 88
A16: Tot 7 | B16: =SUM(B5:B8) -> 27 | C16: =SUM(C5:C8) -> 8 | D16: =SUM(D5:D8) -> 9 | E16: =SUM(E5:E8) -> 14 | F16: =SUM(F5:F8) -> 0 | G16: =SUM(G5:G8) -> 0 | H16: =SUM(H5:H8) -> 1 | I16: =SUM(I5:I8) -> 0 | ... Q16: =SUM(Q5:Q8) -> 0
A17: Tot 8 | B17: =SUM(B9:B12) -> 27 | C17: =SUM(C9:C12) -> 15 | D17: =SUM(D9:D12) -> 16 | E17: =SUM(E9:E12) -> 19 | F17: =SUM(F9:F12) -> 4 | G17: =SUM(G9:G12) -> 3 | H17: =SUM(H9:H12) -> 3 | I17: =SUM(I9:I12) -> 0 | ... Q17: =SUM(Q9:Q12) -> 0

Sheet StGenis total
B1: Lieu: | D1: StGenis Total
B2: France -> Suisse | J2: Suisse -> France | S2: Totaux | AG2: 2019 | AP2: Chanagement 2019 -> 2020
B3: Vélo traditionel | D3: VAE | F3: Mode Nouveau Electrique | H3: Piéton/ne | J3: Vélo traditionel | L3: VAE | N3: Mode Nouveau Electrique (trotinette, scateboard , …) | P3: Piéton/ne | S3: Hommes | T3: Femmes | U3: %Femmes | V3: VT | W3: VAE | X3: Nouveau | Y3: 2r | Z3: %VAE | AA3: %Nouveau | AB3: Piétons | AC3: >CH | AD3: >FR | AE3: TOT | AG3: Cyclistes | AH3: Pietons | AI3: Hommes | AJ3: Femmes | AK3: -> CH | AL3: -> FR | AM3: % femmes | AN3: TOTAL | AP3: Cyclistes | AQ3: Pietons | AR3: Hommes | AS3: Femmes | AT3: -> CH | AU3: -> FR | AV3: % femmes | AW3: TOTAL
A4: Heure | B4: H | C4: F | D4: H | E4: F | F4: H | G4: F | H4: H | I4: F | J4: H | K4: F | L4: H | M4: F | N4: H | O4: F | P4: H | Q4: F
A5: 0.29166667 | B5: ='StGenis->Meyrin'!B5+'StGenis->Bourdigny'!B5+'StGenis->CERN'!B5 -> 13 | C5: ='StGenis->Meyrin'!C5+'StGenis->Bourdigny'!C5+'StGenis->CERN'!C5 -> 3 | D5: ='StGenis->Meyrin'!D5+'StGenis->Bourdigny'!D5+'StGenis->CERN'!D5 -> 4 | E5: ='StGenis->Meyrin'!E5+'StGenis->Bourdigny'!E5+'StGenis->CERN'!E5 -> 8 | F5: ='StGenis->Meyrin'!F5+'StGenis->Bourdigny'!F5+'StGenis->CERN'!F5 -> 2 | G5: ='StGenis->Meyrin'!G5+'StGenis->Bourdigny'!G5+'StGenis->CERN'!G5 -> 0 | H5: ='StGenis->Meyrin'!H5+'StGenis->Bourdigny'!H5+'StGenis->CERN'!H5 -> 1 | I5: ='StGenis->Meyrin'!I5+'StGenis->Bourdigny'!I5+'StGenis->CERN'!I5 -> 0 | ... Q5: ='StGenis->Meyrin'!Q5+'StGenis->Bourdigny'!Q5+'StGenis->CERN'!Q5 -> 0 | S5: =B5+D5+F5+H5+J5+L5+N5+P5 -> 21 | T5: =C5+E5+G5+I5+K5+M5+O5+Q5 -> 11 | U5: =T5/(T5+S5) -> 0.34375 | V5: =B5+C5+J5+K5 -> 17 | W5: =D5+E5+L5+M5 -> 12 | X5: =F5+G5+N5+O5 -> 2 | Y5: =SUM(V5:X5) -> 31 | Z5: =W5/Y5 -> 0.38709677 | AA5: =X5/Y5 -> 0.064516129 | AB5: =H5+I5+P5+Q5 -> 1 | AC5: =SUM(B5:I5) -> 31 | AD5: =SUM(J5:Q5) -> 1 | AE5: =SUM(B5:Q5) -> 32
A6: 0.30208333 | B6: ='StGenis->Meyrin'!B6+'StGenis->Bourdigny'!B6+'StGenis->CERN'!B6 -> 15 | C6: ='StGenis->Meyrin'!C6+'StGenis->Bourdigny'!C6+'StGenis->CERN'!C6 -> 3 | D6: ='StGenis->Meyrin'!D6+'StGenis->Bourdigny'!D6+'StGenis->CERN'!D6 -> 11 | E6: ='StGenis->Meyrin'!E6+'StGenis->Bourdigny'!E6+'StGenis->CERN'!E6 -> 5 | F6: ='StGenis->Meyrin'!F6+'StGenis->Bourdigny'!F6+'StGenis->CERN'!F6 -> 1 | G6: ='StGenis->Meyrin'!G6+'StGenis->Bourdigny'!G6+'StGenis->CERN'!G6 -> 1 | H6: ='StGenis->Meyrin'!H6+'StGenis->Bourdigny'!H6+'StGenis->CERN'!H6 -> 4 | I6: ='StGenis->Meyrin'!I6+'StGenis->Bourdigny'!I6+'StGenis->CERN'!I6 -> 0 | ... Q6: ='StGenis->Meyrin'!Q6+'StGenis->Bourdigny'!Q6+'StGenis->CERN'!Q6 -> 0 | S6: =B6+D6+F6+H6+J6+L6+N6+P6 -> 34 | T6: =C6+E6+G6+I6+K6+M6+O6+Q6 -> 9 | U6: =T6/(T6+S6) -> 0.20930233 | V6: =B6+C6+J6+K6 -> 19 | W6: =D6+E6+L6+M6 -> 18 | X6: =F6+G6+N6+O6 -> 2 | Y6: =SUM(V6:X6) -> 39 | Z6: =W6/Y6 -> 0.46153846 | AA6: =X6/Y6 -> 0.051282051 | AB6: =H6+I6+P6+Q6 -> 4 | AC6: =SUM(B6:I6) -> 40 | AD6: =SUM(J6:Q6) -> 3 | AE6: =SUM(B6:Q6) -> 43
A7: 0.3125 | B7: ='StGenis->Meyrin'!B7+'StGenis->Bourdigny'!B7+'StGenis->CERN'!B7 -> 13 | C7: ='StGenis->Meyrin'!C7+'StGenis->Bourdigny'!C7+'StGenis->CERN'!C7 -> 4 | D7: ='StGenis->Meyrin'!D7+'StGenis->Bourdigny'!D7+'StGenis->CERN'!D7 -> 4 | E7: ='StGenis->Meyrin'!E7+'StGenis->Bourdigny'!E7+'StGenis->CERN'!E7 -> 4 | F7: ='StGenis->Meyrin'!F7+'StGenis->Bourdigny'!F7+'StGenis->CERN'!F7 -> 1 | G7: ='StGenis->Meyrin'!G7+'StGenis->Bourdigny'!G7+'StGenis->CERN'!G7 -> 1 | H7: ='StGenis->Meyrin'!H7+'StGenis->Bourdigny'!H7+'StGenis->CERN'!H7 -> 2 | I7: ='StGenis->Meyrin'!I7+'StGenis->Bourdigny'!I7+'StGenis->CERN'!I7 -> 0 | ... Q7: ='StGenis->Meyrin'!Q7+'StGenis->Bourdigny'!Q7+'StGenis->CERN'!Q7 -> 0 | S7: =B7+D7+F7+H7+J7+L7+N7+P7 -> 20 | T7: =C7+E7+G7+I7+K7+M7+O7+Q7 -> 9 | U7: =T7/(T7+S7) -> 0.31034483 | V7: =B7+C7+J7+K7 -> 17 | W7: =D7+E7+L7+M7 -> 8 | X7: =F7+G7+N7+O7 -> 2 | Y7: =SUM(V7:X7) -> 27 | Z7: =W7/Y7 -> 0.2962963 | AA7: =X7/Y7 -> 0.074074074 | AB7: =H7+I7+P7+Q7 -> 2 | AC7: =SUM(B7:I7) -> 29 | AD7: =SUM(J7:Q7) -> 0 | AE7: =SUM(B7:Q7) -> 29
A8: 0.32291667 | B8: ='StGenis->Meyrin'!B8+'StGenis->Bourdigny'!B8+'StGenis->CERN'!B8 -> 7 | C8: ='StGenis->Meyrin'!C8+'StGenis->Bourdigny'!C8+'StGenis->CERN'!C8 -> 4 | D8: ='StGenis->Meyrin'!D8+'StGenis->Bourdigny'!D8+'StGenis->CERN'!D8 -> 4 | E8: ='StGenis->Meyrin'!E8+'StGenis->Bourdigny'!E8+'StGenis->CERN'!E8 -> 7 | F8: ='StGenis->Meyrin'!F8+'StGenis->Bourdigny'!F8+'StGenis->CERN'!F8 -> 1 | G8: ='StGenis->Meyrin'!G8+'StGenis->Bourdigny'!G8+'StGenis->CERN'!G8 -> 2 | H8: ='StGenis->Meyrin'!H8+'StGenis->Bourdigny'!H8+'StGenis->CERN'!H8 -> 0 | I8: ='StGenis->Meyrin'!I8+'StGenis->Bourdigny'!I8+'StGenis->CERN'!I8 -> 0 | ... Q8: ='StGenis->Meyrin'!Q8+'StGenis->Bourdigny'!Q8+'StGenis->CERN'!Q8 -> 0 | S8: =B8+D8+F8+H8+J8+L8+N8+P8 -> 12 | T8: =C8+E8+G8+I8+K8+M8+O8+Q8 -> 13 | U8: =T8/(T8+S8) -> 0.52 | V8: =B8+C8+J8+K8 -> 11 | W8: =D8+E8+L8+M8 -> 11 | X8: =F8+G8+N8+O8 -> 3 | Y8: =SUM(V8:X8) -> 25 | Z8: =W8/Y8 -> 0.44 | AA8: =X8/Y8 -> 0.12 | AB8: =H8+I8+P8+Q8 -> 0 | AC8: =SUM(B8:I8) -> 25 | AD8: =SUM(J8:Q8) -> 0 | AE8: =SUM(B8:Q8) -> 25
A9: 0.33333333 | B9: ='StGenis->Meyrin'!B9+'StGenis->Bourdigny'!B9+'StGenis->CERN'!B9 -> 10 | C9: ='StGenis->Meyrin'!C9+'StGenis->Bourdigny'!C9+'StGenis->CERN'!C9 -> 7 | D9: ='StGenis->Meyrin'!D9+'StGenis->Bourdigny'!D9+'StGenis->CERN'!D9 -> 2 | E9: ='StGenis->Meyrin'!E9+'StGenis->Bourdigny'!E9+'StGenis->CERN'!E9 -> 1 | F9: ='StGenis->Meyrin'!F9+'StGenis->Bourdigny'!F9+'StGenis->CERN'!F9 -> 0 | G9: ='StGenis->Meyrin'!G9+'StGenis->Bourdigny'!G9+'StGenis->CERN'!G9 -> 0 | H9: ='StGenis->Meyrin'!H9+'StGenis->Bourdigny'!H9+'StGenis->CERN'!H9 -> 8 | I9: ='StGenis->Meyrin'!I9+'StGenis->Bourdigny'!I9+'StGenis->CERN'!I9 -> 0 | ... Q9: ='StGenis->Meyrin'!Q9+'StGenis->Bourdigny'!Q9+'StGenis->CERN'!Q9 -> 0 | S9: =B9+D9+F9+H9+J9+L9+N9+P9 -> 21 | T9: =C9+E9+G9+I9+K9+M9+O9+Q9 -> 9 | U9: =T9/(T9+S9) -> 0.3 | V9: =B9+C9+J9+K9 -> 19 | W9: =D9+E9+L9+M9 -> 3 | X9: =F9+G9+N9+O9 -> 0 | Y9: =SUM(V9:X9) -> 22 | Z9: =W9/Y9 -> 0.13636364 | AA9: =X9/Y9 -> 0 | AB9: =H9+I9+P9+Q9 -> 8 | AC9: =SUM(B9:I9) -> 28 | AD9: =SUM(J9:Q9) -> 2 | AE9: =SUM(B9:Q9) -> 30
A10: 0.34375 | B10: ='StGenis->Meyrin'!B10+'StGenis->Bourdigny'!B10+'StGenis->CERN'!B10 -> 13 | C10: ='StGenis->Meyrin'!C10+'StGenis->Bourdigny'!C10+'StGenis->CERN'!C10 -> 3 | D10: ='StGenis->Meyrin'!D10+'StGenis->Bourdigny'!D10+'StGenis->CERN'!D10 -> 3 | E10: ='StGenis->Meyrin'!E10+'StGenis->Bourdigny'!E10+'StGenis->CERN'!E10 -> 4 | F10: ='StGenis->Meyrin'!F10+'StGenis->Bourdigny'!F10+'StGenis->CERN'!F10 -> 1 | G10: ='StGenis->Meyrin'!G10+'StGenis->Bourdigny'!G10+'StGenis->CERN'!G10 -> 2 | H10: ='StGenis->Meyrin'!H10+'StGenis->Bourdigny'!H10+'StGenis->CERN'!H10 -> 4 | I10: ='StGenis->Meyrin'!I10+'StGenis->Bourdigny'!I10+'StGenis->CERN'!I10 -> 0 | ... Q10: ='StGenis->Meyrin'!Q10+'StGenis->Bourdigny'!Q10+'StGenis->CERN'!Q10 -> 0 | S10: =B10+D10+F10+H10+J10+L10+N10+P10 -> 22 | T10: =C10+E10+G10+I10+K10+M10+O10+Q10 -> 10 | U10: =T10/(T10+S10) -> 0.3125 | V10: =B10+C10+J10+K10 -> 16 | W10: =D10+E10+L10+M10 -> 9 | X10: =F10+G10+N10+O10 -> 3 | Y10: =SUM(V10:X10) -> 28 | Z10: =W10/Y10 -> 0.32142857 | AA10: =X10/Y10 -> 0.10714286 | AB10: =H10+I10+P10+Q10 -> 4 | AC10: =SUM(B10:I10) -> 30 | AD10: =SUM(J10:Q10) -> 2 | AE10: =SUM(B10:Q10) -> 32
A11: 0.35416667 | B11: ='StGenis->Meyrin'!B11+'StGenis->Bourdigny'!B11+'StGenis->CERN'!B11 -> 13 | C11: ='StGenis->Meyrin'!C11+'StGenis->Bourdigny'!C11+'StGenis->CERN'!C11 -> 3 | D11: ='StGenis->Meyrin'!D11+'StGenis->Bourdigny'!D11+'StGenis->CERN'!D11 -> 1 | E11: ='StGenis->Meyrin'!E11+'StGenis->Bourdigny'!E11+'StGenis->CERN'!E11 -> 0 | F11: ='StGenis->Meyrin'!F11+'StGenis->Bourdigny'!F11+'StGenis->CERN'!F11 -> 5 | G11: ='StGenis->Meyrin'!G11+'StGenis->Bourdigny'!G11+'StGenis->CERN'!G11 -> 5 | H11: ='StGenis->Meyrin'!H11+'StGenis->Bourdigny'!H11+'StGenis->CERN'!H11 -> 6 | I11: ='StGenis->Meyrin'!I11+'StGenis->Bourdigny'!I11+'StGenis->CERN'!I11 -> 0 | ... Q11: ='StGenis->Meyrin'!Q11+'StGenis->Bourdigny'!Q11+'StGenis->CERN'!Q11 -> 0 | S11: =B11+D11+F11+H11+J11+L11+N11+P11 -> 25 | T11: =C11+E11+G11+I11+K11+M11+O11+Q11 -> 9 | U11: =T11/(T11+S11) -> 0.26470588 | V11: =B11+C11+J11+K11 -> 17 | W11: =D11+E11+L11+M11 -> 1 | X11: =F11+G11+N11+O11 -> 10 | Y11: =SUM(V11:X11) -> 28 | Z11: =W11/Y11 -> 0.035714286 | AA11: =X11/Y11 -> 0.35714286 | AB11: =H11+I11+P11+Q11 -> 6 | AC11: =SUM(B11:I11) -> 33 | AD11: =SUM(J11:Q11) -> 1 | AE11: =SUM(B11:Q11) -> 34
A12: 0.36458333 | B12: ='StGenis->Meyrin'!B12+'StGenis->Bourdigny'!B12+'StGenis->CERN'!B12 -> 9 | C12: ='StGenis->Meyrin'!C12+'StGenis->Bourdigny'!C12+'StGenis->CERN'!C12 -> 3 | D12: ='StGenis->Meyrin'!D12+'StGenis->Bourdigny'!D12+'StGenis->CERN'!D12 -> 0 | E12: ='StGenis->Meyrin'!E12+'StGenis->Bourdigny'!E12+'StGenis->CERN'!E12 -> 0 | F12: ='StGenis->Meyrin'!F12+'StGenis->Bourdigny'!F12+'StGenis->CERN'!F12 -> 1 | G12: ='StGenis->Meyrin'!G12+'StGenis->Bourdigny'!G12+'StGenis->CERN'!G12 -> 4 | H12: ='StGenis->Meyrin'!H12+'StGenis->Bourdigny'!H12+'StGenis->CERN'!H12 -> 6 | I12: ='StGenis->Meyrin'!I12+'StGenis->Bourdigny'!I12+'StGenis->CERN'!I12 -> 2 | ... Q12: ='StGenis->Meyrin'!Q12+'StGenis->Bourdigny'!Q12+'StGenis->CERN'!Q12 -> 0 | S12: =B12+D12+F12+H12+J12+L12+N12+P12 -> 16 | T12: =C12+E12+G12+I12+K12+M12+O12+Q12 -> 9 | U12: =T12/(T12+S12) -> 0.36 | V12: =B12+C12+J12+K12 -> 12 | W12: =D12+E12+L12+M12 -> 0 | X12: =F12+G12+N12+O12 -> 5 | Y12: =SUM(V12:X12) -> 17 | Z12: =W12/Y12 -> 0 | AA12: =X12/Y12 -> 0.29411765 | AB12: =H12+I12+P12+Q12 -> 8 | AC12: =SUM(B12:I12) -> 25 | AD12: =SUM(J12:Q12) -> 0 | AE12: =SUM(B12:Q12) -> 25
A13: Total | B13: =SUM(B5:B12) -> 93 | C13: =SUM(C5:C12) -> 30 | D13: =SUM(D5:D12) -> 29 | E13: =SUM(E5:E12) -> 29 | F13: =SUM(F5:F12) -> 12 | G13: =SUM(G5:G12) -> 15 | H13: =SUM(H5:H12) -> 31 | I13: =SUM(I5:I12) -> 2 | ... Q13: =SUM(Q5:Q12) -> 0 | S13: =B13+D13+F13+H13+J13+L13+N13+P13 -> 171 | T13: =C13+E13+G13+I13+K13+M13+O13+Q13 -> 79 | U13: =T13/(T13+S13) -> 0.316 | V13: =B13+C13+J13+K13 -> 128 | W13: =D13+E13+L13+M13 -> 62 | X13: =F13+G13+N13+O13 -> 27 | Y13: =SUM(V13:X13) -> 217 | Z13: =W13/Y13 -> 0.28571429 | AA13: =X13/Y13 -> 0.12442396 | AB13: =H13+I13+P13+Q13 -> 33 | AC13: =SUM(B13:I13) -> 241 | AD13: =SUM(J13:Q13) -> 9 | AE13: =SUM(B13:Q13) -> 250 | AG13: ='StGenis->Meyrin'!AG13+'StGenis->Bourdigny'!AG13+'StGenis->CERN'!AG13 -> 400 | AH13: ='StGenis->Meyrin'!AH13+'StGenis->Bourdigny'!AH13+'StGenis->CERN'!AH13 -> 72 | AI13: ='StGenis->Meyrin'!AI13+'StGenis->Bourdigny'!AI13+'StGenis->CERN'!AI13 -> 366 | AJ13: ='StGenis->Meyrin'!AJ13+'StGenis->Bourdigny'!AJ13+'StGenis->CERN'!AJ13 -> 106 | AK13: ='StGenis->Meyrin'!AK13+'StGenis->Bourdigny'!AK13+'StGenis->CERN'!AK13 -> 455 | AL13: ='StGenis->Meyrin'!AL13+'StGenis->Bourdigny'!AL13+'StGenis->CERN'!AL13 -> 17 | AM13: =AJ13/(AJ13+AI13) -> 0.22457627 | AN13: ='StGenis->Meyrin'!AN13+'StGenis->Bourdigny'!AN13+'StGenis->CERN'!AN13 -> 472 | AP13: =(Y13-AG13)/AG13 -> -0.4575 | AQ13: =(AB13-AH13)/AH13 -> -0.54166667 | AR13: =(S13-AI13)/AI13 -> -0.53278689 | AS13: =(T13-AJ13)/AJ13 -> -0.25471698 | AT13: =(AC13-AK13)/AK13 -> -0.47032967 | AU13: =(AD13-AL13)/AL13 -> -0.47058824 | AV13: =(U13-AM13)/AM13 -> 0.40709434 | AW13: =(AE13-AN13)/AN13 -> -0.47033898
A14: Total HP | B14: =SUM(B7:B10) -> 43 | C14: =SUM(C7:C10) -> 18 | D14: =SUM(D7:D10) -> 13 | E14: =SUM(E7:E10) -> 16 | F14: =SUM(F7:F10) -> 3 | G14: =SUM(G7:G10) -> 5 | H14: =SUM(H7:H10) -> 14 | I14: =SUM(I7:I10) -> 0 | ... Q14: =SUM(Q7:Q10) -> 0 | S14: =B14+D14+F14+H14+J14+L14+N14+P14 -> 75 | T14: =C14+E14+G14+I14+K14+M14+O14+Q14 -> 41 | U14: =T14/(T14+S14) -> 0.35344828 | V14: =B14+C14+J14+K14 -> 63 | W14: =D14+E14+L14+M14 -> 31 | X14: =F14+G14+N14+O14 -> 8 | Y14: =SUM(V14:X14) -> 102 | Z14: =W14/Y14 -> 0.30392157 | AA14: =X14/Y14 -> 0.078431373 | AB14: =H14+I14+P14+Q14 -> 14 | AC14: =SUM(B14:I14) -> 112 | AD14: =SUM(J14:Q14) -> 4 | AE14: =SUM(B14:Q14) -> 116
A16: Tot 7 | B16: =SUM(B5:B8) -> 48 | C16: =SUM(C5:C8) -> 14 | D16: =SUM(D5:D8) -> 23 | E16: =SUM(E5:E8) -> 24 | F16: =SUM(F5:F8) -> 5 | G16: =SUM(G5:G8) -> 4 | H16: =SUM(H5:H8) -> 7 | I16: =SUM(I5:I8) -> 0 | ... Q16: =SUM(Q5:Q8) -> 0
A17: Tot 8 | B17: =SUM(B9:B12) -> 45 | C17: =SUM(C9:C12) -> 16 | D17: =SUM(D9:D12) -> 6 | E17: =SUM(E9:E12) -> 5 | F17: =SUM(F9:F12) -> 7 | G17: =SUM(G9:G12) -> 11 | H17: =SUM(H9:H12) -> 24 | I17: =SUM(I9:I12) -> 2 | ... Q17: =SUM(Q9:Q12) -> 0

Sheet StGenis->Meyrin
B1: Lieu: | C1: STGenis -> Meyrin
B2: France -> Suisse | J2: Suisse -> France | S2: Totaux | AG2: 2019 | AP2: Chanagement 2019 -> 2020
B3: Vélo traditionel | D3: VAE | F3: Mode Nouveau Electrique | H3: Piéton/ne | J3: Vélo traditionel | L3: VAE | N3: Mode Nouveau Electrique (trotinette, scateboard , …) | P3: Piéton/ne | S3: Hommes | T3: Femmes | U3: %Femmes | V3: VT | W3: VAE | X3: Nouveau | Y3: 2r | Z3: %VAE | AA3: %Nouveau | AB3: Piétons | AC3: >CH | AD3: >FR | AE3: TOT | AG3: Cyclistes | AH3: Pietons | AI3: Hommes | AJ3: Femmes | AK3: -> CH | AL3: -> FR | AM3: % femmes | AN3: TOTAL | AP3: Cyclistes | AQ3: Pietons | AR3: Hommes | AS3: Femmes | AT3: -> CH | AU3: -> FR | AV3: % femmes | AW3: TOTAL
A4: Heure | B4: H | C4: F | D4: H | E4: F | F4: H | G4: F | H4: H | I4: F | J4: H | K4: F | L4: H | M4: F | N4: H | O4: F | P4: H | Q4: F
A5: 0.29166667 | B5: 10 | C5: 3 | D5: 3 | E5: 8 | F5: 2 | J5: 1 | S5: =B5+D5+F5+H5+J5+L5+N5+P5 -> 16 | T5: =C5+E5+G5+I5+K5+M5+O5+Q5 -> 11 | U5: =T5/(T5+S5) -> 0.40740741 | V5: =B5+C5+J5+K5 -> 14 | W5: =D5+E5+L5+M5 -> 11 | X5: =F5+G5+N5+O5 -> 2 | Y5: =SUM(V5:X5) -> 27 | Z5: =W5/Y5 -> 0.40740741 | AA5: =X5/Y5 -> 0.074074074 | AB5: =H5+I5+P5+Q5 -> 0 | AC5: =SUM(B5:I5) -> 26 | AD5: =SUM(J5:Q5) -> 1 | AE5: =SUM(B5:Q5) -> 27
A6: 0.30208333 | B6: 6 | C6: 2 | D6: 7 | E6: 5 | F6: 1 | G6: 1 | H6: 1 | J6: 1 | L6: 2 | S6: =B6+D6+#REF!+F6+J6+L6+N6+P6 -> #REF! | T6: =C6+E6+#REF!+G6+K6+M6+O6+Q6 -> #REF! | U6: =T6/(T6+S6) -> #REF! | V6: =B6+C6+J6+K6 -> 9 | W6: =D6+E6+L6+M6 -> 14 | X6: =#REF!+#REF!+N6+O6 -> #REF! | Y6: =SUM(V6:X6) -> #REF! | Z6: =W6/Y6 -> #REF! | AA6: =X6/Y6 -> #REF! | AB6: =F6+G6+P6+Q6 -> 2 | AC6: =SUM(B6:G6) -> 22 | AD6: =SUM(J6:Q6) -> 3 | AE6: =SUM(B6:Q6) -> 26
A7: 0.3125 | B7: 9 | C7: 3 | D7: 4 | E7: 4 | F7: 1 | G7: 1 | H7: 1 | S7: =B7+D7+F7+H7+J7+L7+N7+P7 -> 15 | T7: =C7+E7+G7+I7+K7+M7+O7+Q7 -> 8 | U7: =T7/(T7+S7) -> 0.34782609 | V7: =B7+C7+J7+K7 -> 12 | W7: =D7+E7+L7+M7 -> 8 | X7: =F7+G7+N7+O7 -> 2 | Y7: =SUM(V7:X7) -> 22 | Z7: =W7/Y7 -> 0.36363636 | AA7: =X7/Y7 -> 0.090909091 | AB7: =H7+I7+P7+Q7 -> 1 | AC7: =SUM(B7:I7) -> 23 | AD7: =SUM(J7:Q7) -> 0 | AE7: =SUM(B7:Q7) -> 23
A8: 0.32291667 | B8: 6 | C8: 1 | D8: 4 | E8: 7 | F8: 1 | G8: 2 | S8: =B8+D8+F8+H8+J8+L8+N8+P8 -> 11 | T8: =C8+E8+G8+I8+K8+M8+O8+Q8 -> 10 | U8: =T8/(T8+S8) -> 0.47619048 | V8: =B8+C8+J8+K8 -> 7 | W8: =D8+E8+L8+M8 -> 11 | X8: =F8+G8+N8+O8 -> 3 | Y8: =SUM(V8:X8) -> 21 | Z8: =W8/Y8 -> 0.52380952 | AA8: =X8/Y8 -> 0.14285714 | AB8: =H8+I8+P8+Q8 -> 0 | AC8: =SUM(B8:I8) -> 21 | AD8: =SUM(J8:Q8) -> 0 | AE8: =SUM(B8:Q8) -> 21
A9: 0.33333333 | B9: 8 | C9: 5 | D9: 1 | E9: 1 | H9: 5 | J9: 1 | K9: 1 | S9: =B9+D9+F9+H9+J9+L9+N9+P9 -> 15 | T9: =C9+E9+G9+I9+K9+M9+O9+Q9 -> 7 | U9: =T9/(T9+S9) -> 0.31818182 | V9: =B9+C9+J9+K9 -> 15 | W9: =D9+E9+L9+M9 -> 2 | X9: =F9+G9+N9+O9 -> 0 | Y9: =SUM(V9:X9) -> 17 | Z9: =W9/Y9 -> 0.11764706 | AA9: =X9/Y9 -> 0 | AB9: =H9+I9+P9+Q9 -> 5 | AC9: =SUM(B9:I9) -> 20 | AD9: =SUM(J9:Q9) -> 2 | AE9: =SUM(B9:Q9) -> 22
A10: 0.34375 | B10: 9 | C10: 2 | D10: 2 | E10: 3 | F10: 1 | G10: 2 | H10: 1 | L10: 1 | M10: 1 | S10: =B10+D10+F10+H10+J10+L10+N10+P10 -> 14 | T10: =C10+E10+G10+I10+K10+M10+O10+Q10 -> 8 | U10: =T10/(T10+S10) -> 0.36363636 | V10: =B10+C10+J10+K10 -> 11 | W10: =D10+E10+L10+M10 -> 7 | X10: =F10+G10+N10+O10 -> 3 | Y10: =SUM(V10:X10) -> 21 | Z10: =W10/Y10 -> 0.33333333 | AA10: =X10/Y10 -> 0.14285714 | AB10: =H10+I10+P10+Q10 -> 1 | AC10: =SUM(B10:I10) -> 20 | AD10: =SUM(J10:Q10) -> 2 | AE10: =SUM(B10:Q10) -> 22
A11: 0.35416667 | B11: 9 | C11: 2 | D11: 1 | F11: 5 | G11: 5 | K11: 1 | S11: =B11+D11+F11+H11+J11+L11+N11+P11 -> 15 | T11: =C11+E11+G11+I11+K11+M11+O11+Q11 -> 8 | U11: =T11/(T11+S11) -> 0.34782609 | V11: =B11+C11+J11+K11 -> 12 | W11: =D11+E11+L11+M11 -> 1 | X11: =F11+G11+N11+O11 -> 10 | Y11: =SUM(V11:X11) -> 23 | Z11: =W11/Y11 -> 0.043478261 | AA11: =X11/Y11 -> 0.43478261 | AB11: =H11+I11+P11+Q11 -> 0 | AC11: =SUM(B11:I11) -> 22 | AD11: =SUM(J11:Q11) -> 1 | AE11: =SUM(B11:Q11) -> 23
A12: 0.36458333 | B12: 4 | F12: 1 | G12: 4 | I12: 1 | S12: =B12+D12+F12+H12+J12+L12+N12+P12 -> 5 | T12: =C12+E12+G12+I12+K12+M12+O12+Q12 -> 5 | U12: =T12/(T12+S12) -> 0.5 | V12: =B12+C12+J12+K12 -> 4 | W12: =D12+E12+L12+M12 -> 0 | X12: =F12+G12+N12+O12 -> 5 | Y12: =SUM(V12:X12) -> 9 | Z12: =W12/Y12 -> 0 | AA12: =X12/Y12 -> 0.55555556 | AB12: =H12+I12+P12+Q12 -> 1 | AC12: =SUM(B12:I12) -> 10 | AD12: =SUM(J12:Q12) -> 0 | AE12: =SUM(B12:Q12) -> 10
A13: Total | B13: =SUM(B5:B12) -> 61 | C13: =SUM(C5:C12) -> 18 | D13: =SUM(D5:D12) -> 22 | E13: =SUM(E5:E12) -> 28 | F13: =SUM(F5:F12) -> 12 | G13: =SUM(G5:G12) -> 15 | H13: =SUM(H5:H12) -> 8 | I13: =SUM(I5:I12) -> 1 | ... Q13: =SUM(Q5:Q12) -> 0 | S13: =B13+D13+F13+H13+J13+L13+N13+P13 -> 109 | T13: =C13+E13+G13+I13+K13+M13+O13+Q13 -> 65 | U13: =T13/(T13+S13) -> 0.37356322 | V13: =B13+C13+J13+K13 -> 84 | W13: =D13+E13+L13+M13 -> 54 | X13: =F13+G13+N13+O13 -> 27 | Y13: =SUM(V13:X13) -> 165 | Z13: =W13/Y13 -> 0.32727273 | AA13: =X13/Y13 -> 0.16363636 | AB13: =H13+I13+P13+Q13 -> 9 | AC13: =SUM(B13:I13) -> 165 | AD13: =SUM(J13:Q13) -> 9 | AE13: =SUM(B13:Q13) -> 174 | AG13: 313 | AH13: 40 | AI13: 265 | AJ13: 88 | AK13: 341 | AL13: 12 | AM13: =AJ13/(AJ13+AI13) -> 0.24929178 | AN13: 353 | AP13: =(Y13-AG13)/AG13 -> -0.47284345 | AQ13: =(AB13-AH13)/AH13 -> -0.775 | AR13: =(S13-AI13)/AI13 -> -0.58867925 | AS13: =(T13-AJ13)/AJ13 -> -0.26136364 | AT13: =(AC13-AK13)/AK13 -> -0.51612903 | AU13: =(AD13-AL13)/AL13 -> -0.25 | AV13: =(U13-AM13)/AM13 -> 0.49849791 | AW13: =(AE13-AN13)/AN13 -> -0.50708215
A14: Total HP | B14: =SUM(B7:B10) -> 32 | C14: =SUM(C7:C10) -> 11 | D14: =SUM(D7:D10) -> 11 | E14: =SUM(E7:E10) -> 15 | F14: =SUM(F7:F10) -> 3 | G14: =SUM(G7:G10) -> 5 | H14: =SUM(H7:H10) -> 7 | I14: =SUM(I7:I10) -> 0 | ... Q14: =SUM(Q7:Q10) -> 0 | S14: =B14+D14+F14+H14+J14+L14+N14+P14 -> 55 | T14: =C14+E14+G14+I14+K14+M14+O14+Q14 -> 33 | U14: =T14/(T14+S14) -> 0.375 | V14: =B14+C14+J14+K14 -> 45 | W14: =D14+E14+L14+M14 -> 28 | X14: =F14+G14+N14+O14 -> 8 | Y14: =SUM(V14:X14) -> 81 | Z14: =W14/Y14 -> 0.34567901 | AA14: =X14/Y14 -> 0.098765432 | AB14: =H14+I14+P14+Q14 -> 7 | AC14: =SUM(B14:I14) -> 84 | AD14: =SUM(J14:Q14) -> 4 | AE14: =SUM(B14:Q14) -> 88
A16: 7 | B16: =SUM(B5:B8) -> 31 | C16: =SUM(C5:C8) -> 9 | D16: =SUM(D5:D8) -> 18 | E16: =SUM(E5:E8) -> 24 | F16: =SUM(F5:F8) -> 5 | G16: =SUM(G5:G8) -> 4 | H16: =SUM(H5:H8) -> 2 | I16: =SUM(I5:I8) -> 0 | ... Q16: =SUM(Q5:Q8) -> 0
A17: 8 | B17: =SUM(B9:B12) -> 30 | C17: =SUM(C9:C12) -> 9 | D17: =SUM(D9:D12) -> 4 | E17: =SUM(E9:E12) -> 4 | F17: =SUM(F9:F12) -> 7 | G17: =SUM(G9:G12) -> 11 | H17: =SUM(H9:H12) -> 6 | I17: =SUM(I9:I12) -> 1 | ... Q17: =SUM(Q9:Q12) -> 0

Sheet StGenis->Bourdigny
B1: Lieu: | C1: StGenis -> Bourdigny
B2: France -> Suisse | J2: Suisse -> France | S2: Totaux | AG2: 2019 | AP2: Chanagement 2019 -> 2020
B3: Vélo traditionel | D3: VAE | F3: Mode Nouveau Electrique | H3: Piéton/ne | J3: Vélo traditionel | L3: VAE | N3: Mode Nouveau Electrique (trotinette, scateboard , …) | P3: Piéton/ne | S3: Hommes | T3: Femmes | U3: %Femmes | V3: VT | W3: VAE | X3: Nouveau | Y3: TotVelo | Z3: %VAE | AA3: %Nouveau | AB3: Piétons | AC3: >CH | AD3: >FR | AE3: TOT | AG3: Cyclistes | AH3: Pietons | AI3: Hommes | AJ3: Femmes | AK3: -> CH | AL3: -> FR | AM3: % femmes | AN3: TOTAL | AP3: Cyclistes | AQ3: Pietons | AR3: Hommes | AS3: Femmes | AT3: -> CH | AU3: -> FR | AV3: % femmes | AW3: TOTAL
A4: Heure | B4: H | C4: F | D4: H | E4: F | F4: H | G4: F | H4: H | I4: F | J4: H | K4: F | L4: H | M4: F | N4: H | O4: F | P4: H | Q4: F
A5: 0.29166667 | D5: 1 | S5: =B5+D5+F5+H5+J5+L5+N5+P5 -> 1 | T5: =C5+E5+G5+I5+K5+M5+O5+Q5 -> 0 | U5: =T5/(T5+S5) -> 0 | V5: =B5+C5+J5+K5 -> 0 | W5: =D5+E5+L5+M5 -> 1 | X5: =F5+G5+N5+O5 -> 0 | Y5: =SUM(V5:X5) -> 1 | Z5: =W5/Y5 -> 1 | AA5: =X5/Y5 -> 0 | AB5: =H5+I5+P5+Q5 -> 0 | AC5: =SUM(B5:I5) -> 1 | AD5: =SUM(J5:Q5) -> 0 | AE5: =SUM(B5:Q5) -> 1
A6: 0.30208333 | B6: 1 | C6: 1 | D6: 4 | S6: =B6+D6+F6+H6+J6+L6+N6+P6 -> 5 | T6: =C6+E6+G6+I6+K6+M6+O6+Q6 -> 1 | U6: =T6/(T6+S6) -> 0.16666667 | V6: =B6+C6+J6+K6 -> 2 | W6: =D6+E6+L6+M6 -> 4 | X6: =F6+G6+N6+O6 -> 0 | Y6: =SUM(V6:X6) -> 6 | Z6: =W6/Y6 -> 0.66666667 | AA6: =X6/Y6 -> 0 | AB6: =H6+I6+P6+Q6 -> 0 | AC6: =SUM(B6:I6) -> 6 | AD6: =SUM(J6:Q6) -> 0 | AE6: =SUM(B6:Q6) -> 6
A7: 0.3125 | B7: 1 | S7: =B7+D7+F7+H7+J7+L7+N7+P7 -> 1 | T7: =C7+E7+G7+I7+K7+M7+O7+Q7 -> 0 | U7: =T7/(T7+S7) -> 0 | V7: =B7+C7+J7+K7 -> 1 | W7: =D7+E7+L7+M7 -> 0 | X7: =F7+G7+N7+O7 -> 0 | Y7: =SUM(V7:X7) -> 1 | Z7: =W7/Y7 -> 0 | AA7: =X7/Y7 -> 0 | AB7: =H7+I7+P7+Q7 -> 0 | AC7: =SUM(B7:I7) -> 1 | AD7: =SUM(J7:Q7) -> 0 | AE7: =SUM(B7:Q7) -> 1
A8: 0.32291667 | B8: 1 | C8: 2 | S8: =B8+D8+F8+H8+J8+L8+N8+P8 -> 1 | T8: =C8+E8+G8+I8+K8+M8+O8+Q8 -> 2 | U8: =T8/(T8+S8) -> 0.66666667 | V8: =B8+C8+J8+K8 -> 3 | W8: =D8+E8+L8+M8 -> 0 | X8: =F8+G8+N8+O8 -> 0 | Y8: =SUM(V8:X8) -> 3 | Z8: =W8/Y8 -> 0 | AA8: =X8/Y8 -> 0 | AB8: =H8+I8+P8+Q8 -> 0 | AC8: =SUM(B8:I8) -> 3 | AD8: =SUM(J8:Q8) -> 0 | AE8: =SUM(B8:Q8) -> 3
A9: 0.33333333 | S9: =B9+D9+F9+H9+J9+L9+N9+P9 -> 0 | T9: =C9+E9+G9+I9+K9+M9+O9+Q9 -> 0 | U9: =T9/(T9+S9) -> #DIV/0! | V9: =B9+C9+J9+K9 -> 0 | W9: =D9+E9+L9+M9 -> 0 | X9: =F9+G9+N9+O9 -> 0 | Y9: =SUM(V9:X9) -> 0 | Z9: =W9/Y9 -> #DIV/0! | AA9: =X9/Y9 -> #DIV/0! | AB9: =H9+I9+P9+Q9 -> 0 | AC9: =SUM(B9:I9) -> 0 | AD9: =SUM(J9:Q9) -> 0 | AE9: =SUM(B9:Q9) -> 0
A10: 0.34375 | D10: 1 | E10: 1 | S10: =B10+D10+F10+H10+J10+L10+N10+P10 -> 1 | T10: =C10+E10+G10+I10+K10+M10+O10+Q10 -> 1 | U10: =T10/(T10+S10) -> 0.5 | V10: =B10+C10+J10+K10 -> 0 | W10: =D10+E10+L10+M10 -> 2 | X10: =F10+G10+N10+O10 -> 0 | Y10: =SUM(V10:X10) -> 2 | Z10: =W10/Y10 -> 1 | AA10: =X10/Y10 -> 0 | AB10: =H10+I10+P10+Q10 -> 0 | AC10: =SUM(B10:I10) -> 2 | AD10: =SUM(J10:Q10) -> 0 | AE10: =SUM(B10:Q10) -> 2
A11: 0.35416667 | H11: 1 | S11: =B11+D11+F11+#REF!+H11+L11+N11+P11 -> #REF! | T11: =C11+E11+G11+I11+K11+M11+O11+Q11 -> 0 | U11: =T11/(T11+S11) -> #REF! | V11: =B11+C11+H11+K11 -> 1 | W11: =D11+E11+L11+M11 -> 0 | X11: =F11+G11+N11+O11 -> 0 | Y11: =SUM(V11:X11) -> 1 | Z11: =W11/Y11 -> 0 | AA11: =X11/Y11 -> 0 | AB11: =#REF!+I11+P11+Q11 -> #REF! | AC11: =SUM(B11:I11) -> 1 | AD11: =SUM(H11:Q11) -> 1 | AE11: =SUM(B11:Q11) -> 1
A12: 0.36458333 | H12: 1 | S12: =B12+D12+F12+#REF!+H12+L12+N12+P12 -> #REF! | T12: =C12+E12+G12+I12+K12+M12+O12+Q12 -> 0 | U12: =T12/(T12+S12) -> #REF! | V12: =B12+C12+H12+K12 -> 1 | W12: =D12+E12+L12+M12 -> 0 | X12: =F12+G12+N12+O12 -> 0 | Y12: =SUM(V12:X12) -> 1 | Z12: =W12/Y12 -> 0 | AA12: =X12/Y12 -> 0 | AB12: =#REF!+I12+P12+Q12 -> #REF! | AC12: =SUM(B12:I12) -> 1 | AD12: =SUM(H12:Q12) -> 1 | AE12: =SUM(B12:Q12) -> 1
A13: Total | B13: =SUM(B5:B12) -> 3 | C13: =SUM(C5:C12) -> 3 | D13: =SUM(D5:D12) -> 6 | E13: =SUM(E5:E12) -> 1 | F13: =SUM(F5:F12) -> 0 | G13: =SUM(G5:G12) -> 0 | H13: =SUM(H5:H12) -> 2 | I13: =SUM(I5:I12) -> 0 | ... Q13: =SUM(Q5:Q12) -> 0 | S13: =B13+D13+F13+H13+J13+L13+N13+P13 -> 11 | T13: =C13+E13+G13+I13+K13+M13+O13+Q13 -> 4 | U13: =T13/(T13+S13) -> 0.26666667 | V13: =B13+C13+J13+K13 -> 6 | W13: =D13+E13+L13+M13 -> 7 | X13: =F13+G13+N13+O13 -> 0 | Y13: =SUM(V13:X13) -> 13 | Z13: =W13/Y13 -> 0.53846154 | AA13: =X13/Y13 -> 0 | AB13: =H13+I13+P13+Q13 -> 2 | AC13: =SUM(B13:I13) -> 15 | AD13: =SUM(J13:Q13) -> 0 | AE13: =SUM(B13:Q13) -> 15 | AP13: =(Y13-AG13)/AG13 -> #DIV/0! | AQ13: =(AB13-AH13)/AH13 -> #DIV/0! | AR13: =(S13-AI13)/AI13 -> #DIV/0! | AS13: =(T13-AJ13)/AJ13 -> #DIV/0! | AT13: =(AC13-AK13)/AK13 -> #DIV/0! | AU13: =(AD13-AL13)/AL13 -> #DIV/0! | AV13: =(U13-AM13)/AM13 -> #DIV/0! | AW13: =(AE13-AN13)/AN13 -> #DIV/0!
A14: Total HP | B14: =SUM(B7:B10) -> 2 | C14: =SUM(C7:C10) -> 2 | D14: =SUM(D7:D10) -> 1 | E14: =SUM(E7:E10) -> 1 | F14: =SUM(F7:F10) -> 0 | G14: =SUM(G7:G10) -> 0 | H14: =SUM(H7:H10) -> 0 | I14: =SUM(I7:I10) -> 0 | ... Q14: =SUM(Q7:Q10) -> 0 | S14: =B14+D14+F14+H14+J14+L14+N14+P14 -> 3 | T14: =C14+E14+G14+I14+K14+M14+O14+Q14 -> 3 | U14: =T14/(T14+S14) -> 0.5 | V14: =B14+C14+J14+K14 -> 4 | W14: =D14+E14+L14+M14 -> 2 | X14: =F14+G14+N14+O14 -> 0 | Y14: =SUM(V14:X14) -> 6 | Z14: =W14/Y14 -> 0.33333333 | AA14: =X14/Y14 -> 0 | AB14: =H14+I14+P14+Q14 -> 0 | AC14: =SUM(B14:I14) -> 6 | AD14: =SUM(J14:Q14) -> 0 | AE14: =SUM(B14:Q14) -> 6
A16: 7 | B16: =SUM(B5:B8) -> 3 | C16: =SUM(C5:C8) -> 3 | D16: =SUM(D5:D8) -> 5 | E16: =SUM(E5:E8) -> 0 | F16: =SUM(F5:F8) -> 0 | G16: =SUM(G5:G8) -> 0 | H16: =SUM(H5:H8) -> 0 | I16: =SUM(I5:I8) -> 0 | ... Q16: =SUM(Q5:Q8) -> 0
A17: 8 | B17: =SUM(B9:B12) -> 0 | C17: =SUM(C9:C12) -> 0 | D17: =SUM(D9:D12) -> 1 | E17: =SUM(E9:E12) -> 1 | F17: =SUM(F9:F12) -> 0 | G17: =SUM(G9:G12) -> 0 | H17: =SUM(H9:H12) -> 2 | I17: =SUM(I9:I12) -> 0 | ... Q17: =SUM(Q9:Q12) -> 0

Sheet StGenis->CERN
B1: Lieu: | C1: STGenis - CERN
B2: France -> Suisse | J2: Suisse -> France | S2: Totaux | AG2: 2019 | AP2: Chanagement 2019 -> 2020
B3: Vélo traditionel | D3: VAE | F3: Mode Nouveau Electrique | H3: Piéton/ne | J3: Vélo traditionel | L3: VAE | N3: Mode Nouveau Electrique (trotinette, scateboard , …) | P3: Piéton/ne | S3: Hommes | T3: Femmes | U3: %Femmes | V3: VT | W3: VAE | X3: Nouveau | Y3: TotVelo | Z3: %VAE | AA3: %Nouveau | AB3: Piétons | AC3: >CH | AD3: >FR | AE3: TOT | AG3: Cyclistes | AH3: Pietons | AI3: Hommes | AJ3: Femmes | AK3: -> CH | AL3: -> FR | AM3: % femmes | AN3: TOTAL | AP3: Cyclistes | AQ3: Pietons | AR3: Hommes | AS3: Femmes | AT3: -> CH | AU3: -> FR | AV3: % femmes | AW3: TOTAL
A4: Heure | B4: H | C4: F | D4: H | E4: F | F4: H | G4: F | H4: H | I4: F | J4: H | K4: F | L4: H | M4: F | N4: H | O4: F | P4: H | Q4: F
A5: 0.29166667 | B5: 3 | H5: 1 | S5: =B5+D5+F5+H5+J5+L5+N5+P5 -> 4 | T5: =C5+E5+G5+I5+K5+M5+O5+Q5 -> 0 | U5: =T5/(T5+S5) -> 0 | V5: =B5+C5+J5+K5 -> 3 | W5: =D5+E5+L5+M5 -> 0 | X5: =F5+G5+N5+O5 -> 0 | Y5: =SUM(V5:X5) -> 3 | Z5: =W5/Y5 -> 0 | AA5: =X5/Y5 -> 0 | AB5: =H5+I5+P5+Q5 -> 1 | AC5: =SUM(B5:I5) -> 4 | AD5: =SUM(J5:Q5) -> 0 | AE5: =SUM(B5:Q5) -> 4
A6: 0.30208333 | B6: 8 | H6: 3 | S6: =B6+D6+F6+H6+J6+L6+N6+P6 -> 11 | T6: =C6+E6+G6+I6+K6+M6+O6+Q6 -> 0 | U6: =T6/(T6+S6) -> 0 | V6: =B6+C6+J6+K6 -> 8 | W6: =D6+E6+L6+M6 -> 0 | X6: =F6+G6+N6+O6 -> 0 | Y6: =SUM(V6:X6) -> 8 | Z6: =W6/Y6 -> 0 | AA6: =X6/Y6 -> 0 | AB6: =H6+I6+P6+Q6 -> 3 | AC6: =SUM(B6:I6) -> 11 | AD6: =SUM(J6:Q6) -> 0 | AE6: =SUM(B6:Q6) -> 11
A7: 0.3125 | B7: 3 | C7: 1 | H7: 1 | S7: =B7+D7+F7+H7+J7+L7+N7+P7 -> 4 | T7: =C7+E7+G7+I7+K7+M7+O7+Q7 -> 1 | U7: =T7/(T7+S7) -> 0.2 | V7: =B7+C7+J7+K7 -> 4 | W7: =D7+E7+L7+M7 -> 0 | X7: =F7+G7+N7+O7 -> 0 | Y7: =SUM(V7:X7) -> 4 | Z7: =W7/Y7 -> 0 | AA7: =X7/Y7 -> 0 | AB7: =H7+I7+P7+Q7 -> 1 | AC7: =SUM(B7:I7) -> 5 | AD7: =SUM(J7:Q7) -> 0 | AE7: =SUM(B7:Q7) -> 5
A8: 0.32291667 | C8: 1 | S8: =B8+D8+F8+H8+J8+L8+N8+P8 -> 0 | T8: =C8+E8+G8+I8+K8+M8+O8+Q8 -> 1 | U8: =T8/(T8+S8) -> 1 | V8: =B8+C8+J8+K8 -> 1 | W8: =D8+E8+L8+M8 -> 0 | X8: =F8+G8+N8+O8 -> 0 | Y8: =SUM(V8:X8) -> 1 | Z8: =W8/Y8 -> 0 | AA8: =X8/Y8 -> 0 | AB8: =H8+I8+P8+Q8 -> 0 | AC8: =SUM(B8:I8) -> 1 | AD8: =SUM(J8:Q8) -> 0 | AE8: =SUM(B8:Q8) -> 1
A9: 0.33333333 | B9: 2 | C9: 2 | D9: 1 | H9: 3 | S9: =B9+D9+F9+H9+J9+L9+N9+P9 -> 6 | T9: =C9+E9+G9+I9+K9+M9+O9+Q9 -> 2 | U9: =T9/(T9+S9) -> 0.25 | V9: =B9+C9+J9+K9 -> 4 | W9: =D9+E9+L9+M9 -> 1 | X9: =F9+G9+N9+O9 -> 0 | Y9: =SUM(V9:X9) -> 5 | Z9: =W9/Y9 -> 0.2 | AA9: =X9/Y9 -> 0 | AB9: =H9+I9+P9+Q9 -> 3 | AC9: =SUM(B9:I9) -> 8 | AD9: =SUM(J9:Q9) -> 0 | AE9: =SUM(B9:Q9) -> 8
A10: 0.34375 | B10: 4 | C10: 1 | H10: 3 | S10: =B10+D10+F10+H10+J10+L10+N10+P10 -> 7 | T10: =C10+E10+G10+I10+K10+M10+O10+Q10 -> 1 | U10: =T10/(T10+S10) -> 0.125 | V10: =B10+C10+J10+K10 -> 5 | W10: =D10+E10+L10+M10 -> 0 | X10: =F10+G10+N10+O10 -> 0 | Y10: =SUM(V10:X10) -> 5 | Z10: =W10/Y10 -> 0 | AA10: =X10/Y10 -> 0 | AB10: =H10+I10+P10+Q10 -> 3 | AC10: =SUM(B10:I10) -> 8 | AD10: =SUM(J10:Q10) -> 0 | AE10: =SUM(B10:Q10) -> 8
A11: 0.35416667 | B11: 4 | C11: 1 | H11: 5 | S11: =B11+D11+F11+H11+J11+L11+N11+P11 -> 9 | T11: =C11+E11+G11+I11+K11+M11+O11+Q11 -> 1 | U11: =T11/(T11+S11) -> 0.1 | V11: =B11+C11+J11+K11 -> 5 | W11: =D11+E11+L11+M11 -> 0 | X11: =F11+G11+N11+O11 -> 0 | Y11: =SUM(V11:X11) -> 5 | Z11: =W11/Y11 -> 0 | AA11: =X11/Y11 -> 0 | AB11: =H11+I11+P11+Q11 -> 5 | AC11: =SUM(B11:I11) -> 10 | AD11: =SUM(J11:Q11) -> 0 | AE11: =SUM(B11:Q11) -> 10
A12: 0.36458333 | B12: 5 | C12: 3 | H12: 5 | I12: 1 | S12: =B12+D12+F12+H12+J12+L12+N12+P12 -> 10 | T12: =C12+E12+G12+I12+K12+M12+O12+Q12 -> 4 | U12: =T12/(T12+S12) -> 0.28571429 | V12: =B12+C12+J12+K12 -> 8 | W12: =D12+E12+L12+M12 -> 0 | X12: =F12+G12+N12+O12 -> 0 | Y12: =SUM(V12:X12) -> 8 | Z12: =W12/Y12 -> 0 | AA12: =X12/Y12 -> 0 | AB12: =H12+I12+P12+Q12 -> 6 | AC12: =SUM(B12:I12) -> 14 | AD12: =SUM(J12:Q12) -> 0 | AE12: =SUM(B12:Q12) -> 14
A13: Total | B13: =SUM(B5:B12) -> 29 | C13: =SUM(C5:C12) -> 9 | D13: =SUM(D5:D12) -> 1 | E13: =SUM(E5:E12) -> 0 | F13: =SUM(F5:F12) -> 0 | G13: =SUM(G5:G12) -> 0 | H13: =SUM(H5:H12) -> 21 | I13: =SUM(I5:I12) -> 1 | ... Q13: =SUM(Q5:Q12) -> 0 | S13: =B13+D13+F13+H13+J13+L13+N13+P13 -> 51 | T13: =C13+E13+G13+I13+K13+M13+O13+Q13 -> 10 | U13: =T13/(T13+S13) -> 0.16393443 | V13: =B13+C13+J13+K13 -> 38 | W13: =D13+E13+L13+M13 -> 1 | X13: =F13+G13+N13+O13 -> 0 | Y13: =SUM(V13:X13) -> 39 | Z13: =W13/Y13 -> 0.025641026 | AA13: =X13/Y13 -> 0 | AB13: =H13+I13+P13+Q13 -> 22 | AC13: =SUM(B13:I13) -> 61 | AD13: =SUM(J13:Q13) -> 0 | AE13: =SUM(B13:Q13) -> 61 | AG13: 87 | AH13: 32 | AI13: 101 | AJ13: 18 | AK13: 114 | AL13: 5 | AM13: =AJ13/(AJ13+AI13) -> 0.1512605 | AN13: 119 | AP13: =(Y13-AG13)/AG13 -> -0.55172414 | AQ13: =(AB13-AH13)/AH13 -> -0.3125 | AR13: =(S13-AI13)/AI13 -> -0.4950495 | AS13: =(T13-AJ13)/AJ13 -> -0.44444444 | AT13: =(AC13-AK13)/AK13 -> -0.46491228 | AU13: =(AD13-AL13)/AL13 -> -1 | AV13: =(U13-AM13)/AM13 -> 0.083788707 | AW13: =(AE13-AN13)/AN13 -> -0.48739496
A14: Total HP | B14: =SUM(B7:B10) -> 9 | C14: =SUM(C7:C10) -> 5 | D14: =SUM(D7:D10) -> 1 | E14: =SUM(E7:E10) -> 0 | F14: =SUM(F7:F10) -> 0 | G14: =SUM(G7:G10) -> 0 | H14: =SUM(H7:H10) -> 7 | I14: =SUM(I7:I10) -> 0 | ... Q14: =SUM(Q7:Q10) -> 0 | S14: =B14+D14+F14+H14+J14+L14+N14+P14 -> 17 | T14: =C14+E14+G14+I14+K14+M14+O14+Q14 -> 5 | U14: =T14/(T14+S14) -> 0.22727273 | V14: =B14+C14+J14+K14 -> 14 | W14: =D14+E14+L14+M14 -> 1 | X14: =F14+G14+N14+O14 -> 0 | Y14: =SUM(V14:X14) -> 15 | Z14: =W14/Y14 -> 0.066666667 | AA14: =X14/Y14 -> 0 | AB14: =H14+I14+P14+Q14 -> 7 | AC14: =SUM(B14:I14) -> 22 | AD14: =SUM(J14:Q14) -> 0 | AE14: =SUM(B14:Q14) -> 22
A16: 7 | B16: =SUM(B5:B8) -> 14 | C16: =SUM(C5:C8) -> 2 | D16: =SUM(D5:D8) -> 0 | E16: =SUM(E5:E8) -> 0 | F16: =SUM(F5:F8) -> 0 | G16: =SUM(G5:G8) -> 0 | H16: =SUM(H5:H8) -> 5 | I16: =SUM(I5:I8) -> 0 | ... Q16: =SUM(Q5:Q8) -> 0
A17: 8 | B17: =SUM(B9:B12) -> 15 | C17: =SUM(C9:C12) -> 7 | D17: =SUM(D9:D12) -> 1 | E17: =SUM(E9:E12) -> 0 | F17: =SUM(F9:F12) -> 0 | G17: =SUM(G9:G12) -> 0 | H17: =SUM(H9:H12) -> 16 | I17: =SUM(I9:I12) -> 1 | ... Q17: =SUM(Q9:Q12) -> 0

Sheet Crassy
B1: Lieu: | C1: Crassy->Crassier
B2: France -> Suisse | J2: Suisse -> France | S2: Totaux
B3: Vélo traditionel | D3: VAE | F3: Mode Nouveau Electrique | H3: Piéton/ne | J3: Vélo traditionel | L3: VAE | N3: Mode Nouveau Electrique (trotinette, scateboard , …) | P3: Piéton/ne | S3: Hommes | T3: Femmes | U3: %Femmes | V3: VT | W3: VAE | X3: Nouveau | Y3: 2r | Z3: %VAE | AA3: %Nouveau | AB3: Piétons | AC3: >CH | AD3: >FR | AE3: TOT
A4: Heure | B4: H | C4: F | D4: H | E4: F | F4: H | G4: F | H4: H | I4: F | J4: H | K4: F | L4: H | M4: F | N4: H | O4: F | P4: H | Q4: F
A5: 0.29166667 | B5: 2 | J5: 1 | S5: =B5+D5+F5+H5+J5+L5+N5+P5 -> 3 | T5: =C5+E5+G5+I5+K5+M5+O5+Q5 -> 0 | U5: =T5/(T5+S5) -> 0 | V5: =B5+C5+J5+K5 -> 3 | W5: =D5+E5+L5+M5 -> 0 | X5: =F5+G5+N5+O5 -> 0 | Y5: =SUM(V5:X5) -> 3 | Z5: =W5/Y5 -> 0 | AA5: =X5/Y5 -> 0 | AB5: =H5+I5+P5+Q5 -> 0 | AC5: =SUM(B5:I5) -> 2 | AD5: =SUM(J5:Q5) -> 1 | AE5: =SUM(B5:Q5) -> 3
A6: 0.30208333 | B6: 2 | F6: 1 | J6: 1 | S6: =B6+D6+F6+H6+J6+L6+N6+P6 -> 4 | T6: =C6+E6+G6+I6+K6+M6+O6+Q6 -> 0 | U6: =T6/(T6+S6) -> 0 | V6: =B6+C6+J6+K6 -> 3 | W6: =D6+E6+L6+M6 -> 0 | X6: =F6+G6+N6+O6 -> 1 | Y6: =SUM(V6:X6) -> 4 | Z6: =W6/Y6 -> 0 | AA6: =X6/Y6 -> 0.25 | AB6: =H6+I6+P6+Q6 -> 0 | AC6: =SUM(B6:I6) -> 3 | AD6: =SUM(J6:Q6) -> 1 | AE6: =SUM(B6:Q6) -> 4
A7: 0.3125 | B7: 1 | S7: =B7+D7+F7+H7+J7+L7+N7+P7 -> 1 | T7: =C7+E7+G7+I7+K7+M7+O7+Q7 -> 0 | U7: =T7/(T7+S7) -> 0 | V7: =B7+C7+J7+K7 -> 1 | W7: =D7+E7+L7+M7 -> 0 | X7: =F7+G7+N7+O7 -> 0 | Y7: =SUM(V7:X7) -> 1 | Z7: =W7/Y7 -> 0 | AA7: =X7/Y7 -> 0 | AB7: =H7+I7+P7+Q7 -> 0 | AC7: =SUM(B7:I7) -> 1 | AD7: =SUM(J7:Q7) -> 0 | AE7: =SUM(B7:Q7) -> 1
A8: 0.32291667 | D8: 1 | E8: 1 | I8: 1 | S8: =B8+D8+F8+H8+J8+L8+N8+P8 -> 1 | T8: =C8+E8+G8+I8+K8+M8+O8+Q8 -> 2 | U8: =T8/(T8+S8) -> 0.66666667 | V8: =B8+C8+J8+K8 -> 0 | W8: =D8+E8+L8+M8 -> 2 | X8: =F8+G8+N8+O8 -> 0 | Y8: =SUM(V8:X8) -> 2 | Z8: =W8/Y8 -> 1 | AA8: =X8/Y8 -> 0 | AB8: =H8+I8+P8+Q8 -> 1 | AC8: =SUM(B8:I8) -> 3 | AD8: =SUM(J8:Q8) -> 0 | AE8: =SUM(B8:Q8) -> 3
A9: 0.33333333 | D9: 1 | J9: 2 | S9: =B9+D9+F9+H9+J9+L9+N9+P9 -> 3 | T9: =C9+E9+G9+I9+K9+M9+O9+Q9 -> 0 | U9: =T9/(T9+S9) -> 0 | V9: =B9+C9+J9+K9 -> 2 | W9: =D9+E9+L9+M9 -> 1 | X9: =F9+G9+N9+O9 -> 0 | Y9: =SUM(V9:X9) -> 3 | Z9: =W9/Y9 -> 0.33333333 | AA9: =X9/Y9 -> 0 | AB9: =H9+I9+P9+Q9 -> 0 | AC9: =SUM(B9:I9) -> 1 | AD9: =SUM(J9:Q9) -> 2 | AE9: =SUM(B9:Q9) -> 3
A10: 0.34375 | B10: 2 | I10: 1 | Q10: 3 | S10: =B10+D10+F10+H10+J10+L10+N10+P10 -> 2 | T10: =C10+E10+G10+I10+K10+M10+O10+Q10 -> 4 | U10: =T10/(T10+S10) -> 0.66666667 | V10: =B10+C10+J10+K10 -> 2 | W10: =D10+E10+L10+M10 -> 0 | X10: =F10+G10+N10+O10 -> 0 | Y10: =SUM(V10:X10) -> 2 | Z10: =W10/Y10 -> 0 | AA10: =X10/Y10 -> 0 | AB10: =H10+I10+P10+Q10 -> 4 | AC10: =SUM(B10:I10) -> 3 | AD10: =SUM(J10:Q10) -> 3 | AE10: =SUM(B10:Q10) -> 6
A11: 0.35416667 | B11: 2 | J11: 1 | S11: =B11+D11+F11+H11+J11+L11+N11+P11 -> 3 | T11: =C11+E11+G11+I11+K11+M11+O11+Q11 -> 0 | U11: =T11/(T11+S11) -> 0 | V11: =B11+C11+J11+K11 -> 3 | W11: =D11+E11+L11+M11 -> 0 | X11: =F11+G11+N11+O11 -> 0 | Y11: =SUM(V11:X11) -> 3 | Z11: =W11/Y11 -> 0 | AA11: =X11/Y11 -> 0 | AB11: =H11+I11+P11+Q11 -> 0 | AC11: =SUM(B11:I11) -> 2 | AD11: =SUM(J11:Q11) -> 1 | AE11: =SUM(B11:Q11) -> 3
A12: 0.36458333 | D12: 2 | E12: 1 | I12: 1 | Q12: 1 | S12: =B12+D12+F12+H12+J12+L12+N12+P12 -> 2 | T12: =C12+E12+G12+I12+K12+M12+O12+Q12 -> 3 | U12: =T12/(T12+S12) -> 0.6 | V12: =B12+C12+J12+K12 -> 0 | W12: =D12+E12+L12+M12 -> 3 | X12: =F12+G12+N12+O12 -> 0 | Y12: =SUM(V12:X12) -> 3 | Z12: =W12/Y12 -> 1 | AA12: =X12/Y12 -> 0 | AB12: =H12+I12+P12+Q12 -> 2 | AC12: =SUM(B12:I12) -> 4 | AD12: =SUM(J12:Q12) -> 1 | AE12: =SUM(B12:Q12) -> 5
A13: Total | B13: =SUM(B5:B12) -> 9 | C13: =SUM(C5:C12) -> 0 | D13: =SUM(D5:D12) -> 4 | E13: =SUM(E5:E12) -> 2 | F13: =SUM(F5:F12) -> 1 | G13: =SUM(G5:G12) -> 0 | H13: =SUM(H5:H12) -> 0 | I13: =SUM(I5:I12) -> 3 | ... Q13: =SUM(Q5:Q12) -> 4 | S13: =B13+D13+F13+H13+J13+L13+N13+P13 -> 19 | T13: =C13+E13+G13+I13+K13+M13+O13+Q13 -> 9 | U13: =T13/(T13+S13) -> 0.32142857 | V13: =B13+C13+J13+K13 -> 14 | W13: =D13+E13+L13+M13 -> 6 | X13: =F13+G13+N13+O13 -> 1 | Y13: =SUM(V13:X13) -> 21 | Z13: =W13/Y13 -> 0.28571429 | AA13: =X13/Y13 -> 0.047619048 | AB13: =H13+I13+P13+Q13 -> 7 | AC13: =SUM(B13:I13) -> 19 | AD13: =SUM(J13:Q13) -> 9 | AE13: =SUM(B13:Q13) -> 28
A14: Total HP | B14: =SUM(B7:B10) -> 3 | C14: =SUM(C7:C10) -> 0 | D14: =SUM(D7:D10) -> 2 | E14: =SUM(E7:E10) -> 1 | F14: =SUM(F7:F10) -> 0 | G14: =SUM(G7:G10) -> 0 | H14: =SUM(H7:H10) -> 0 | I14: =SUM(I7:I10) -> 2 | ... Q14: =SUM(Q7:Q10) -> 3 | S14: =B14+D14+F14+H14+J14+L14+N14+P14 -> 7 | T14: =C14+E14+G14+I14+K14+M14+O14+Q14 -> 6 | U14: =T14/(T14+S14) -> 0.46153846 | V14: =B14+C14+J14+K14 -> 5 | W14: =D14+E14+L14+M14 -> 3 | X14: =F14+G14+N14+O14 -> 0 | Y14: =SUM(V14:X14) -> 8 | Z14: =W14/Y14 -> 0.375 | AA14: =X14/Y14 -> 0 | AB14: =H14+I14+P14+Q14 -> 5 | AC14: =SUM(B14:I14) -> 8 | AD14: =SUM(J14:Q14) -> 5 | AE14: =SUM(B14:Q14) -> 13
A16: Tot 7 | B16: =SUM(B5:B8) -> 5 | C16: =SUM(C5:C8) -> 0 | D16: =SUM(D5:D8) -> 1 | E16: =SUM(E5:E8) -> 1 | F16: =SUM(F5:F8) -> 1 | G16: =SUM(G5:G8) -> 0 | H16: =SUM(H5:H8) -> 0 | I16: =SUM(I5:I8) -> 1 | ... Q16: =SUM(Q5:Q8) -> 0
A17: Tot 8 | B17: =SUM(B9:B12) -> 4 | C17: =SUM(C9:C12) -> 0 | D17: =SUM(D9:D12) -> 3 | E17: =SUM(E9:E12) -> 1 | F17: =SUM(F9:F12) -> 0 | G17: =SUM(G9:G12) -> 0 | H17: =SUM(H9:H12) -> 0 | I17: =SUM(I9:I12) -> 2 | ... Q17: =SUM(Q9:Q12) -> 4

Sheet Mategnin Total
B1: Lieu: | D1: Mategnin Total
B2: France -> Suisse | J2: Suisse -> France | S2: Totaux | AG2: 2019 | AP2: Chanagement 2019 -> 2020
B3: Vélo traditionel | D3: VAE | F3: Mode Nouveau Electrique | H3: Piéton/ne | J3: Vélo traditionel | L3: VAE | N3: Mode Nouveau Electrique (trotinette, scateboard , …) | P3: Piéton/ne | S3: Hommes | T3: Femmes | U3: %Femmes | V3: VT | W3: VAE | X3: Nouveau | Y3: 2r | Z3: %VAE | AA3: %Nouveau | AB3: Piétons | AC3: >CH | AD3: >FR | AE3: TOT | AG3: Cyclistes | AH3: Pietons | AI3: Hommes | AJ3: Femmes | AK3: -> CH | AL3: -> FR | AM3: % femmes | AN3: TOTAL | AP3: Cyclistes | AQ3: Pietons | AR3: Hommes | AS3: Femmes | AT3: -> CH | AU3: -> FR | AV3: % femmes | AW3: TOTAL
A4: Heure | B4: H | C4: F | D4: H | E4: F | F4: H | G4: F | H4: H | I4: F | J4: H | K4: F | L4: H | M4: F | N4: H | O4: F | P4: H | Q4: F
A5: 0.29166667 | B5: =MategninAnneaux!B5+MategninDouane!B5 -> 6 | C5: =MategninAnneaux!C5+MategninDouane!C5 -> 1 | D5: =MategninAnneaux!D5+MategninDouane!D5 -> 3 | E5: =MategninAnneaux!E5+MategninDouane!E5 -> 3 | F5: =MategninAnneaux!F5+MategninDouane!F5 -> 0 | G5: =MategninAnneaux!G5+MategninDouane!G5 -> 1 | H5: =MategninAnneaux!H5+MategninDouane!H5 -> 4 | I5: =MategninAnneaux!I5+MategninDouane!I5 -> 1 | ... Q5: =MategninAnneaux!Q5+MategninDouane!Q5 -> 0 | S5: =B5+D5+F5+H5+J5+L5+N5+P5 -> 15 | T5: =C5+E5+G5+I5+K5+M5+O5+Q5 -> 7 | U5: =T5/(T5+S5) -> 0.31818182 | V5: =B5+C5+J5+K5 -> 8 | W5: =D5+E5+L5+M5 -> 8 | X5: =F5+G5+N5+O5 -> 1 | Y5: =SUM(V5:X5) -> 17 | Z5: =W5/Y5 -> 0.47058824 | AA5: =X5/Y5 -> 0.058823529 | AB5: =H5+I5+P5+Q5 -> 5 | AC5: =SUM(B5:I5) -> 19 | AD5: =SUM(J5:Q5) -> 3 | AE5: =SUM(B5:Q5) -> 22
A6: 0.30208333 | B6: =MategninAnneaux!B6+MategninDouane!B6 -> 13 | C6: =MategninAnneaux!C6+MategninDouane!C6 -> 8 | D6: =MategninAnneaux!D6+MategninDouane!D6 -> 1 | E6: =MategninAnneaux!E6+MategninDouane!E6 -> 3 | F6: =MategninAnneaux!F6+MategninDouane!F6 -> 1 | G6: =MategninAnneaux!G6+MategninDouane!G6 -> 0 | H6: =MategninAnneaux!H6+MategninDouane!H6 -> 2 | I6: =MategninAnneaux!I6+MategninDouane!I6 -> 3 | ... Q6: =MategninAnneaux!Q6+MategninDouane!Q6 -> 0 | S6: =B6+D6+F6+H6+J6+L6+N6+P6 -> 20 | T6: =C6+E6+G6+I6+K6+M6+O6+Q6 -> 17 | U6: =T6/(T6+S6) -> 0.45945946 | V6: =B6+C6+J6+K6 -> 26 | W6: =D6+E6+L6+M6 -> 4 | X6: =F6+G6+N6+O6 -> 2 | Y6: =SUM(V6:X6) -> 32 | Z6: =W6/Y6 -> 0.125 | AA6: =X6/Y6 -> 0.0625 | AB6: =H6+I6+P6+Q6 -> 5 | AC6: =SUM(B6:I6) -> 31 | AD6: =SUM(J6:Q6) -> 6 | AE6: =SUM(B6:Q6) -> 37
A7: 0.3125 | B7: =MategninAnneaux!B7+MategninDouane!B7 -> 12 | C7: =MategninAnneaux!C7+MategninDouane!C7 -> 6 | D7: =MategninAnneaux!D7+MategninDouane!D7 -> 1 | E7: =MategninAnneaux!E7+MategninDouane!E7 -> 2 | F7: =MategninAnneaux!F7+MategninDouane!F7 -> 0 | G7: =MategninAnneaux!G7+MategninDouane!G7 -> 0 | H7: =MategninAnneaux!H7+MategninDouane!H7 -> 1 | I7: =MategninAnneaux!I7+MategninDouane!I7 -> 0 | ... Q7: =MategninAnneaux!Q7+MategninDouane!Q7 -> 0 | S7: =B7+D7+F7+H7+J7+L7+N7+P7 -> 20 | T7: =C7+E7+G7+I7+K7+M7+O7+Q7 -> 9 | U7: =T7/(T7+S7) -> 0.31034483 | V7: =B7+C7+J7+K7 -> 21 | W7: =D7+E7+L7+M7 -> 6 | X7: =F7+G7+N7+O7 -> 0 | Y7: =SUM(V7:X7) -> 27 | Z7: =W7/Y7 -> 0.22222222 | AA7: =X7/Y7 -> 0 | AB7: =H7+I7+P7+Q7 -> 2 | AC7: =SUM(B7:I7) -> 22 | AD7: =SUM(J7:Q7) -> 7 | AE7: =SUM(B7:Q7) -> 29
A8: 0.32291667 | B8: =MategninAnneaux!B8+MategninDouane!B8 -> 11 | C8: =MategninAnneaux!C8+MategninDouane!C8 -> 3 | D8: =MategninAnneaux!D8+MategninDouane!D8 -> 4 | E8: =MategninAnneaux!E8+MategninDouane!E8 -> 1 | F8: =MategninAnneaux!F8+MategninDouane!F8 -> 0 | G8: =MategninAnneaux!G8+MategninDouane!G8 -> 1 | H8: =MategninAnneaux!H8+MategninDouane!H8 -> 3 | I8: =MategninAnneaux!I8+MategninDouane!I8 -> 0 | ... Q8: =MategninAnneaux!Q8+MategninDouane!Q8 -> 1 | S8: =B8+D8+F8+H8+J8+L8+N8+P8 -> 21 | T8: =C8+E8+G8+I8+K8+M8+O8+Q8 -> 9 | U8: =T8/(T8+S8) -> 0.3 | V8: =B8+C8+J8+K8 -> 16 | W8: =D8+E8+L8+M8 -> 5 | X8: =F8+G8+N8+O8 -> 3 | Y8: =SUM(V8:X8) -> 24 | Z8: =W8/Y8 -> 0.20833333 | AA8: =X8/Y8 -> 0.125 | AB8: =H8+I8+P8+Q8 -> 6 | AC8: =SUM(B8:I8) -> 23 | AD8: =SUM(J8:Q8) -> 7 | AE8: =SUM(B8:Q8) -> 30
