Workbook

Sheet LA RO BIOCOOP
A1: Lieu : | B1: La Roche Face Biocoop | O1: Date : | P1: 16 juin 2020
A2: Nom des personnes participant au comptage : | L2: Philippe Poirier
A3: Météo :
A4: Remarques :
A5: Principe d'utilisation pour chaque intervalle de temps,
A6: Marquer une croix vélo ou VAE dans la colonne H ou F. Sauf si 'enfant' marquer E ou 'modes nouveaux de déplacement' (trotinette, skate, ets) marquer Z
A7: Il y a donc un seul marquage par personne comptée
C8: De La Gare (Fg St Bernard) vers | O8: Du Pont du Foron vers | AA8: Du Rd Point La Poste vers
C9: Rd Pt Poste | G9: Rue Perrine | K9: Pont du Foron | O9: Rue Perrine | S9: Rd Pt Poste | W9: La Gare | AA9: Rue Perrine | AE9: Pont du Foron | AI9: La Gare
C10: H | E10: F | G10: H | I10: F | K10: H | M10: F | O10: H | Q10: F | S10: H | U10: F | W10: H | Y10: F | AA10: H | AC10: F | AE10: H | AG10: F | AI10: H | AK10: F
A11: Heure | B11: Minute | C11: VAE | D11: vélo | E11: VAE | F11: vélo | G11: VAE | H11: vélo | I11: VAE | J11: vélo | K11: VAE | L11: vélo | M11: VAE | N11: vélo | O11: VAE | P11: vélo | Q11: VAE | R11: vélo | S11: VAE | T11: vélo | U11: VAE | V11: vélo | W11: VAE | X11: vélo | Y11: VAE | Z11: vélo | AA11: VAE | AB11: vélo | AC11: VAE | AD11: vélo | AE11: VAE | AF11: vélo | AG11: VAE | AH11: vélo | AI11: VAE | AJ11: vélo | AK11: VAE | AL11: vélo
A12: 6 | B12: 30 – 45 | S12: 1
B13: 45 - 59 | U13: 1 | W13: 1
A14: 7 | B14: 00 – 15 | N14: 1 | X14: 1
B15: 15 – 30 | T15: 1 | X15: 1
B16: 30 – 45 | Y16: 1 | AI16: 1
B17: 45 – 59 | X17: 1
A18: 8 | B18: 00 – 15 | R18: 1 | V18: 1 | W18: 1 | X18: 3 | Y18: 1
B19: 15 – 30 | F19: 1 | K19: 1 | L19: 2 | M19: 1 | N19: 1 | T19: 2 | X19: 1 | Z19: 1 | AF19: 1 | AJ19: 2
B20: 30 – 45
A21: 9 | B21: 45 – 59 | O21: 1
A23: Lieu : | B23: =B1 -> La Roche Face Biocoop | O23: Date : | P23: =P1 -> 16 juin 2020
A24: Nom des personnes participant au comptage : | L24: =L2 -> Philippe Poirier
A25: Météo : | C25: =C3 -> 0
A26: Remarques : | C26: =C4 -> 0
A27: Principe d'utilisation : pour chaque intervalle de temps, marquer une croix par personne comptée dans la colonne la décrivant; si enfant marquer E
A28: Il y a donc une seule croix par personne comptée
AO29: 7 trotinnettes
C31: =C8 -> De La Gare (Fg St Bernard) vers | O31: =O8 -> Du Pont du Foron vers | AA31: =AA8 -> Du Rd Point La Poste vers | AO31: TOTAL | AP31: Nombre de VAE dans le total | AQ31: Nombre de femmes dans le total | AR31: Nombre de VAE chez les femmes | AS31: Cycles direc La Gare
C32: =C9 -> Rd Pt Poste | G32: =G9 -> Rue Perrine | K32: =K9 -> Pont du Foron | O32: =O9 -> Rue Perrine | S32: =S9 -> Rd Pt Poste | W32: =W9 -> La Gare | AA32: =AA9 -> Rue Perrine | AE32: =AE9 -> Pont du Foron | AI32: =AI9 -> La Gare
C33: H | E33: F | G33: H | I33: F | K33: H | M33: F | O33: H | Q33: F | S33: H | U33: F | W33: H | Y33: F | AA33: H | AC33: F | AE33: H | AG33: F | AI33: H | AK33: F
A34: Période | C34: VAE | D34: vélo | E34: VAE | F34: vélo | G34: VAE | H34: vélo | I34: VAE | J34: vélo | K34: VAE | L34: vélo | M34: VAE | N34: vélo | O34: VAE | P34: vélo | Q34: VAE | R34: vélo | S34: VAE | T34: vélo | U34: VAE | V34: vélo | W34: VAE | X34: vélo | Y34: VAE | Z34: vélo | AA34: VAE | AB34: vélo | AC34: VAE | AD34: vélo | AE34: VAE | AF34: vélo | AG34: VAE | AH34: vélo | AI34: VAE | AJ34: vélo | AK34: VAE | AL34: vélo | AM34: Période
A35: 6:30 à 7:00 | C35: =SUM(C12:C13) -> 0 | D35: =SUM(D12:D13) -> 0 | E35: =SUM(E12:E13) -> 0 | F35: =SUM(F12:F13) -> 0 | G35: =SUM(G12:G13) -> 0 | H35: =SUM(H12:H13) -> 0 | I35: =SUM(I12:I13) -> 0 | J35: =SUM(J12:J13) -> 0 | ... AL35: =SUM(AL12:AL13) -> 0 | AM35: =A35 -> 6:30 à 7:00 | AO35: =SUM(C35:AL35) -> 3 | AP35: =C35+E35+G35+I35+K35+M35+O35+Q35+S35+U35+W35+Y35+AA35+AC35+AE35+AG35+AI35+AK35 -> 3 | AQ35: =E35+F35+I35+J35+M35+N35+Q35+R35+U35+V35+Y35+Z35+AC35+AD35+AG35+AH35+AK35+AL35 -> 1 | AR35: =E35+I35+M35+Q35+U35+Y35+AC35+AG35+AK35 -> 1 | AS35: =SUM(C35:N35)+SUM(W35:Z35)+SUM(AI35:AL35) -> 1
A36: 7:00 à 8:00 | C36: =SUM(C14:C17) -> 0 | D36: =SUM(D14:D17) -> 0 | E36: =SUM(E14:E17) -> 0 | F36: =SUM(F14:F17) -> 0 | G36: =SUM(G14:G17) -> 0 | H36: =SUM(H14:H17) -> 0 | I36: =SUM(I14:I17) -> 0 | J36: =SUM(J14:J17) -> 0 | ... AL36: =SUM(AL14:AL17) -> 0 | AM36: =A36 -> 7:00 à 8:00 | AO36: =SUM(C36:AL36) -> 7 | AP36: =C36+E36+G36+I36+K36+M36+O36+Q36+S36+U36+W36+Y36+AA36+AC36+AE36+AG36+AI36+AK36 -> 2 | AQ36: =E36+F36+I36+J36+M36+N36+Q36+R36+U36+V36+Y36+Z36+AC36+AD36+AG36+AH36+AK36+AL36 -> 2 | AR36: =E36+I36+M36+Q36+U36+Y36+AC36+AG36+AK36 -> 1 | AS36: =SUM(C36:N36)+SUM(W36:Z36)+SUM(AI36:AL36) -> 6
A37: 7:30 à 8:30 | C37: =SUM(C16:C19) -> 0 | D37: =SUM(D16:D19) -> 0 | E37: =SUM(E16:E19) -> 0 | F37: =SUM(F16:F19) -> 1 | G37: =SUM(G16:G19) -> 0 | H37: =SUM(H16:H19) -> 0 | I37: =SUM(I16:I19) -> 0 | J37: =SUM(J16:J19) -> 0 | ... AL37: =SUM(AL16:AL19) -> 0 | AM37: =A37 -> 7:30 à 8:30 | AO37: =SUM(C37:AL37) -> 23 | AP37: =C37+E37+G37+I37+K37+M37+O37+Q37+S37+U37+W37+Y37+AA37+AC37+AE37+AG37+AI37+AK37 -> 6 | AQ37: =E37+F37+I37+J37+M37+N37+Q37+R37+U37+V37+Y37+Z37+AC37+AD37+AG37+AH37+AK37+AL37 -> 8 | AR37: =E37+I37+M37+Q37+U37+Y37+AC37+AG37+AK37 -> 3 | AS37: =SUM(C37:N37)+SUM(W37:Z37)+SUM(AI37:AL37) -> 18
A38: 8:00 à 9:00 | C38: =SUM(C18:C21) -> 0 | D38: =SUM(D18:D21) -> 0 | E38: =SUM(E18:E21) -> 0 | F38: =SUM(F18:F21) -> 1 | G38: =SUM(G18:G21) -> 0 | H38: =SUM(H18:H21) -> 0 | I38: =SUM(I18:I21) -> 0 | J38: =SUM(J18:J21) -> 0 | ... AL38: =SUM(AL18:AL21) -> 0 | AM38: =A38 -> 8:00 à 9:00 | AO38: =SUM(C38:AL38) -> 21 | AP38: =C38+E38+G38+I38+K38+M38+O38+Q38+S38+U38+W38+Y38+AA38+AC38+AE38+AG38+AI38+AK38 -> 5 | AQ38: =E38+F38+I38+J38+M38+N38+Q38+R38+U38+V38+Y38+Z38+AC38+AD38+AG38+AH38+AK38+AL38 -> 7 | AR38: =E38+I38+M38+Q38+U38+Y38+AC38+AG38+AK38 -> 2 | AS38: =SUM(C38:N38)+SUM(W38:Z38)+SUM(AI38:AL38) -> 15
A39: TOTAL | C39: =SUM(C12:C21) -> 0 | D39: =SUM(D12:D21) -> 0 | E39: =SUM(E12:E21) -> 0 | F39: =SUM(F12:F21) -> 1 | G39: =SUM(G12:G21) -> 0 | H39: =SUM(H12:H21) -> 0 | I39: =SUM(I12:I21) -> 0 | J39: =SUM(J12:J21) -> 0 | ... AL39: =SUM(AL12:AL21) -> 0 | AM39: TOTAL | AO39: =SUM(C39:AL39) -> 31 | AP39: =C39+E39+G39+I39+K39+M39+O39+Q39+S39+U39+W39+Y39+AA39+AC39+AE39+AG39+AI39+AK39 -> 10 | AQ39: =E39+F39+I39+J39+M39+N39+Q39+R39+U39+V39+Y39+Z39+AC39+AD39+AG39+AH39+AK39+AL39 -> 10 | AR39: =E39+I39+M39+Q39+U39+Y39+AC39+AG39+AK39 -> 4 | AS39: =SUM(C39:N39)+SUM(W39:Z39)+SUM(AI39:AL39) -> 22
AM40: =IF($AO$37=MAX($AO$35:$AO$38),AM37,IF($AO$36=MAX($AO$35:$AO$38),AM36,IF($AN$35=MAX($AO$35:$AO$38),AM35,IF($AO$38=MAX($AO$35:$AO$38),AM38,AM38)))) -> 7:30 à 8:30 | AO40: =IF($AO$37=MAX($AO$35:$AO$38),AO37,IF($AO$36=MAX($AO$35:$AO$38),AO36,IF($AN$35=MAX($AO$35:$AO$38),AO35,IF($AO$38=MAX($AO$35:$AO$38),AO38,AO38)))) -> 23 | AP40: =IF($AO$37=MAX($AO$35:$AO$38),AP37,IF($AO$36=MAX($AO$35:$AO$38),AP36,IF($AN$35=MAX($AO$35:$AO$38),AP35,IF($AO$38=MAX($AO$35:$AO$38),AP38,AP38)))) -> 6 | AQ40: =IF($AO$37=MAX($AO$35:$AO$38),AQ37,IF($AO$36=MAX($AO$35:$AO$38),AQ36,IF($AO$35=MAX($AO$35:$AO$38),AQ35,IF($AO$38=MAX($AO$35:$AO$38),AQ38,AQ38)))) -> 8 | AR40: =IF($AO$37=MAX($AO$35:$AO$38),AR37,IF($AO$36=MAX($AO$35:$AO$38),AR36,IF($AO$35=MAX($AO$35:$AO$38),AR35,IF($AO$38=MAX($AO$35:$AO$38),AR38,AR38)))) -> 3 | AS40: =IF($AO$37=MAX($AO$35:$AO$38),AS37,IF($AO$36=MAX($AO$35:$AO$38),AS36,IF($AO$35=MAX($AO$35:$AO$38),AS35,IF($AO$38=MAX($AO$35:$AO$38),AS38,AS38)))) -> 18
AO41: TOTAL | AP41: Part des VAE dans le total | AQ41: Part des femmes dans le total | AR41: Part des VAE chez les femmes | AS41: =AS31 -> Cycles direc La Gare
AM44: Période
...

Sheet LA RO POSTE
B1: La Roche Rond-Point La Poste | S1: Date : | T1: 16 juin 2020 | BC1: Date : | BD1: 16 juin 2020
A2: Nom des personnes participant au comptage : | P2: Lise
A3: Météo :
A4: Remarques :
A5: Principe d'utilisation pour chaque intervalle de temps,
A6: Marquer une croix vélo ou VAE dans la colonne H ou F. Sauf si 'enfant' marquer E ou 'modes nouveaux de déplacement' (trotinette, skate, ets) marquer Z
A7: Il y a donc un seul marquage par personne comptée
C8: De Bonneville vers | S8: DeGrenette (contre-sens) | AE8: DePompiers(contre-sens) | AQ8: De Tourisme vers | BC8: De MJC vers
C9: Grenette | G9: Office Tourisme | K9: Pompiers | O9: Parking | S9: Office Tourisme | W9: Pompiers | AA9: Bonneville | AE9: Bonneville | AI9: Office Tourisme | AM9: Place Grenette | AQ9: Pompiers | AU9: Bonneville | AY9: Grenette | BC9: Office tourisme | BG9: Grenette | BK9: Bonneville | BO9: Pompiers
C10: H | E10: F | G10: H | I10: F | K10: H | M10: F | O10: H | Q10: F | S10: H | U10: F | W10: H | Y10: F | AA10: H | AC10: F | AE10: H | AG10: F | AI10: H | AK10: F | AM10: H | AO10: F | AQ10: H | AS10: F | AU10: H | AW10: F | AY10: H | BA10: F | BC10: H | BE10: F | BG10: H | BI10: F | BK10: H | BM10: F | BO10: H | BQ10: F
A11: Heure | B11: Minute | C11: VAE | D11: vélo | E11: VAE | F11: vélo | G11: VAE | H11: vélo | I11: VAE | J11: vélo | K11: VAE | L11: vélo | M11: VAE | N11: vélo | O11: VAE | P11: vélo | Q11: VAE | R11: vélo | S11: VAE | T11: vélo | U11: VAE | V11: vélo | W11: VAE | X11: vélo | Y11: VAE | Z11: vélo | AA11: VAE | AB11: vélo | AC11: VAE | AD11: vélo | AE11: VAE | AF11: vélo | AG11: VAE | AH11: vélo | AI11: VAE | AJ11: vélo | AK11: VAE | AL11: vélo | AM11: VAE | AN11: vélo | AO11: VAE | AP11: vélo | AQ11: VAE | AR11: vélo | AS11: VAE | AT11: vélo | AU11: VAE | AV11: vélo | AW11: VAE | AX11: vélo | AY11: VAE | AZ11: vélo | BA11: VAE | BB11: vélo | BC11: VAE | BD11: vélo | BE11: VAE | BF11: vélo | BG11: VAE | BH11: vélo | BI11: VAE | BJ11: vélo | BK11: VAE | BL11: vélo | BM11: VAE | BN11: vélo | BO11: VAE | BP11: vélo | BQ11: VAE | BR11: vélo
A12: 6 | B12: 30 – 45
B13: 45 - 59 | I13: 1 | X13: 1 | AY13: 1 | BA13: 1
A14: 7 | B14: 00 – 15 | BN14: 1
B15: 15 – 30 | AB15: 1 | BQ15: 2
B16: 30 – 45 | G16: 1 | K16: 1 | P16: 1 | BL16: 2 | BM16: 1
B17: 45 – 59 | L17: 1
A18: 8 | B18: 00 – 15 | K18: 2 | L18: 1 | AT18: 1 | BP18: 1
B19: 15 – 30 | AQ19: 1
B20: 30 – 45 | AV20: 1 | AX20: 1 | BK20: 1
B21: 45 – 59 | N21: 1
A22: 9 | B22: 00 – 15
B23: 15 – 30
A25: Lieu : | B25: =B1 -> La Roche Rond-Point La Poste | S25: Date : | T25: =T1 -> 16 juin 2020 | BC25: Date : | BD25: =BD1 -> 16 juin 2020
A26: Nom des personnes participant au comptage : | P26: =P2 -> Lise | AZ26: =AZ2 -> 0
A27: Météo : | C27: =C3 -> 0 | AQ27: =AQ3 -> 0
A28: Remarques : | C28: =C4 -> 0 | AQ28: =AQ4 -> 0 | BT28: 5 enfants et sur trottoir 3 trotinettes et 1 vélo à contre-sens
A29: Principe d'utilisation : pour chaque intervalle de temps, marquer une croix par personne comptée dans la colonne la décrivant; si enfant marquer E | BT29: 1 velo+cariole avec enfant pour aller à l'école
A30: Il y a donc une seule croix par personne comptée | BT30: 3 cyclosportifs
C32: =C8 -> De Bonneville vers | S32: =S8 -> DeGrenette (contre-sens) | AE32: =AE8 -> DePompiers(contre-sens) | AQ32: =AQ8 -> De Tourisme vers | BC32: =BC8 -> De MJC vers | BU32: TOTAL | BV32: Nombre de VAE dans le total | BW32: Nombre de femmes dans le total | BX32: Nombre de VAE chez les femmes | BY32: Cycle sur rte Bonneville | BZ32: Remarque
C33: =C9 -> Grenette | G33: =G9 -> Office Tourisme | K33: =K9 -> Pompiers | O33: =O9 -> Parking | S33: =S9 -> Office Tourisme | W33: =W9 -> Pompiers | AA33: =AA9 -> Bonneville | AE33: =AE9 -> Bonneville | AI33: =AI9 -> Office Tourisme | AM33: =AM9 -> Place Grenette | AQ33: =AQ9 -> Pompiers | AU33: =AU9 -> Bonneville | AY33: =AY9 -> Grenette | BC33: =BC9 -> Office tourisme | BG33: =BG9 -> Grenette | BK33: =BK9 -> Bonneville | BO33: =BO9 -> Pompiers
C34: H | E34: F | G34: H | I34: F | K34: H | M34: F | O34: H | Q34: F | S34: H | U34: F | W34: H | Y34: F | AA34: H | AC34: F | AE34: H | AG34: F | AI34: H | AK34: F | AM34: H | AO34: F | AQ34: H | AS34: F | AU34: H | AW34: F | AY34: H | BA34: F | BC34: H | BE34: F | BG34: H | BI34: F | BK34: H | BM34: F | BO34: H | BQ34: F
A35: Période | C35: VAE | D35: vélo | E35: VAE | F35: vélo | G35: VAE | H35: vélo | I35: VAE | J35: vélo | K35: VAE | L35: vélo | M35: VAE | N35: vélo | O35: VAE | P35: vélo | Q35: VAE | R35: vélo | S35: VAE | T35: vélo | U35: VAE | V35: vélo | W35: VAE | X35: vélo | Y35: VAE | Z35: vélo | AA35: VAE | AB35: vélo | AC35: VAE | AD35: vélo | AE35: VAE | AF35: vélo | AG35: VAE | AH35: vélo | AI35: VAE | AJ35: vélo | AK35: VAE | AL35: vélo | AM35: VAE | AN35: vélo | AO35: VAE | AP35: vélo | AQ35: VAE | AR35: vélo | AS35: VAE | AT35: vélo | AU35: VAE | AV35: vélo | AW35: VAE | AX35: vélo | AY35: VAE | AZ35: vélo | BA35: VAE | BB35: vélo | BC35: VAE | BD35: vélo | BE35: VAE | BF35: vélo | BG35: VAE | BH35: vélo | BI35: VAE | BJ35: vélo | BK35: VAE | BL35: vélo | BM35: VAE | BN35: vélo | BO35: VAE | BP35: vélo | BQ35: VAE | BR35: vélo | BS35: Période
A36: 6:30 à 7:00 | C36: =SUM(C12:C13) -> 0 | D36: =SUM(D12:D13) -> 0 | E36: =SUM(E12:E13) -> 0 | F36: =SUM(F12:F13) -> 0 | G36: =SUM(G12:G13) -> 0 | H36: =SUM(H12:H13) -> 0 | I36: =SUM(I12:I13) -> 1 | J36: =SUM(J12:J13) -> 0 | ... BR36: =SUM(BR12:BR13) -> 0 | BS36: =A36 -> 6:30 à 7:00 | BU36: =SUM(C36:BR36) -> 4 | BV36: =C36+E36+G36+I36+K36+M36+O36+Q36+S36+U36+W36+Y36+AA36+AC36+AE36+AG36+AI36+AK36+AM36+AO36+AQ36+AS36+AU36+AW36+AY36+BA36+BC36+BE36+BG36+BI36+BK36+BM36+BO36+BQ36 -> 3 | BW36: =E36+F36+I36+J36+M36+N36+Q36+R36+U36+V36+Y36+Z36+AC36+AD36+AG36+AH36+AK36+AL36+AO36+AP36+AS36+AT36+AW36+AX36+BA36+BB36+BE36+BF36+BI36+BJ36+BM36+BN36+BQ36+BR36 -> 2 | BX36: =E36+I36+M36+Q36+U36+Y36+AC36+AG36+AK36+AO36+AS36+AW36+BA36+BE36+BI36+BM36+BQ36 -> 2 | BY36: =SUM(C36:R36)+SUM(AA36:AH36)+SUM(AU36:AX36)+SUM(BK36:BN36) -> 1
A37: 7:00 à 8:00 | C37: =SUM(C14:C17) -> 0 | D37: =SUM(D14:D17) -> 0 | E37: =SUM(E14:E17) -> 0 | F37: =SUM(F14:F17) -> 0 | G37: =SUM(G14:G17) -> 1 | H37: =SUM(H14:H17) -> 0 | I37: =SUM(I14:I17) -> 0 | J37: =SUM(J14:J17) -> 0 | ... BR37: =SUM(BR14:BR17) -> 0 | BS37: =A37 -> 7:00 à 8:00 | BU37: =SUM(C37:BR37) -> 11 | BV37: =C37+E37+G37+I37+K37+M37+O37+Q37+S37+U37+W37+Y37+AA37+AC37+AE37+AG37+AI37+AK37+AM37+AO37+AQ37+AS37+AU37+AW37+AY37+BA37+BC37+BE37+BG37+BI37+BK37+BM37+BO37+BQ37 -> 5 | BW37: =E37+F37+I37+J37+M37+N37+Q37+R37+U37+V37+Y37+Z37+AC37+AD37+AG37+AH37+AK37+AL37+AO37+AP37+AS37+AT37+AW37+AX37+BA37+BB37+BE37+BF37+BI37+BJ37+BM37+BN37+BQ37+BR37 -> 4 | BX37: =E37+I37+M37+Q37+U37+Y37+AC37+AG37+AK37+AO37+AS37+AW37+BA37+BE37+BI37+BM37+BQ37 -> 3 | BY37: =SUM(C37:R37)+SUM(AA37:AH37)+SUM(AU37:AX37)+SUM(BK37:BN37) -> 9
A38: 7:30 à 8:30 | C38: =SUM(C16:C19) -> 0 | D38: =SUM(D16:D19) -> 0 | E38: =SUM(E16:E19) -> 0 | F38: =SUM(F16:F19) -> 0 | G38: =SUM(G16:G19) -> 1 | H38: =SUM(H16:H19) -> 0 | I38: =SUM(I16:I19) -> 0 | J38: =SUM(J16:J19) -> 0 | ... BR38: =SUM(BR16:BR19) -> 0 | BS38: =A38 -> 7:30 à 8:30 | BU38: =SUM(C38:BR38) -> 13 | BV38: =C38+E38+G38+I38+K38+M38+O38+Q38+S38+U38+W38+Y38+AA38+AC38+AE38+AG38+AI38+AK38+AM38+AO38+AQ38+AS38+AU38+AW38+AY38+BA38+BC38+BE38+BG38+BI38+BK38+BM38+BO38+BQ38 -> 6 | BW38: =E38+F38+I38+J38+M38+N38+Q38+R38+U38+V38+Y38+Z38+AC38+AD38+AG38+AH38+AK38+AL38+AO38+AP38+AS38+AT38+AW38+AX38+BA38+BB38+BE38+BF38+BI38+BJ38+BM38+BN38+BQ38+BR38 -> 2 | BX38: =E38+I38+M38+Q38+U38+Y38+AC38+AG38+AK38+AO38+AS38+AW38+BA38+BE38+BI38+BM38+BQ38 -> 1 | BY38: =SUM(C38:R38)+SUM(AA38:AH38)+SUM(AU38:AX38)+SUM(BK38:BN38) -> 10
A39: 8:00 à 9:00 | C39: =SUM(C18:C21) -> 0 | D39: =SUM(D18:D21) -> 0 | E39: =SUM(E18:E21) -> 0 | F39: =SUM(F18:F21) -> 0 | G39: =SUM(G18:G21) -> 0 | H39: =SUM(H18:H21) -> 0 | I39: =SUM(I18:I21) -> 0 | J39: =SUM(J18:J21) -> 0 | ... BR39: =SUM(BR18:BR21) -> 0 | BS39: =A39 -> 8:00 à 9:00 | BU39: =SUM(C39:BR39) -> 10 | BV39: =C39+E39+G39+I39+K39+M39+O39+Q39+S39+U39+W39+Y39+AA39+AC39+AE39+AG39+AI39+AK39+AM39+AO39+AQ39+AS39+AU39+AW39+AY39+BA39+BC39+BE39+BG39+BI39+BK39+BM39+BO39+BQ39 -> 4 | BW39: =E39+F39+I39+J39+M39+N39+Q39+R39+U39+V39+Y39+Z39+AC39+AD39+AG39+AH39+AK39+AL39+AO39+AP39+AS39+AT39+AW39+AX39+BA39+BB39+BE39+BF39+BI39+BJ39+BM39+BN39+BQ39+BR39 -> 3 | BX39: =E39+I39+M39+Q39+U39+Y39+AC39+AG39+AK39+AO39+AS39+AW39+BA39+BE39+BI39+BM39+BQ39 -> 0 | BY39: =SUM(C39:R39)+SUM(AA39:AH39)+SUM(AU39:AX39)+SUM(BK39:BN39) -> 7
A40: TOTAL | C40: =SUM(C12:C23) -> 0 | D40: =SUM(D12:D23) -> 0 | E40: =SUM(E12:E23) -> 0 | F40: =SUM(F12:F23) -> 0 | G40: =SUM(G12:G23) -> 1 | H40: =SUM(H12:H23) -> 0 | I40: =SUM(I12:I23) -> 1 | J40: =SUM(J12:J23) -> 0 | ... BR40: =SUM(BR12:BR23) -> 0 | BS40: TOTAL | BU40: =SUM(C40:BR40) -> 25 | BV40: =C40+E40+G40+I40+K40+M40+O40+Q40+S40+U40+W40+Y40+AA40+AC40+AE40+AG40+AI40+AK40+AM40+AO40+AQ40+AS40+AU40+AW40+AY40+BA40+BC40+BE40+BG40+BI40+BK40+BM40+BO40+BQ40 -> 12 | BW40: =E40+F40+I40+J40+M40+N40+Q40+R40+U40+V40+Y40+Z40+AC40+AD40+AG40+AH40+AK40+AL40+AO40+AP40+AS40+AT40+AW40+AX40+BA40+BB40+BE40+BF40+BI40+BJ40+BM40+BN40+BQ40+BR40 -> 9 | BX40: =E40+I40+M40+Q40+U40+Y40+AC40+AG40+AK40+AO40+AS40+AW40+BA40+BE40+BI40+BM40+BQ40 -> 5 | BY40: =SUM(C40:R40)+SUM(AA40:AH40)+SUM(AU40:AX40)+SUM(BK40:BN40) -> 17
BS41: =IF($BU$36=MAX($BU$36:$BU$39),BS36,IF($BU$37=MAX($BU$36:$BU$39),BS37,IF($BU$38=MAX($BU$36:$BU$39),BS38,IF($BU$39=MAX($BU$36:$BU$39),BS39,BS38)))) -> 7:30 à 8:30 | BU41: =IF($BU$36=MAX($BU$36:$BU$39),BU36,IF($BU$37=MAX($BU$36:$BU$39),BU37,IF($BU$38=MAX($BU$36:$BU$39),BU38,IF($BU$39=MAX($BU$36:$BU$39),BU39,BU38)))) -> 13 | BV41: =IF($BU$36=MAX($BU$36:$BU$39),BV36,IF($BU$37=MAX($BU$36:$BU$39),BV37,IF($BU$38=MAX($BU$36:$BU$39),BV38,IF($BU$39=MAX($BU$36:$BU$39),BV39,BV38)))) -> 6 | BW41: =IF($BU$36=MAX($BU$36:$BU$39),BW36,IF($BU$37=MAX($BU$36:$BU$39),BW37,IF($BU$38=MAX($BU$36:$BU$39),BW38,IF($BU$39=MAX($BU$36:$BU$39),BW39,BW38)))) -> 2 | BX41: =IF($BU$36=MAX($BU$36:$BU$39),BX36,IF($BU$37=MAX($BU$36:$BU$39),BX37,IF($BU$38=MAX($BU$36:$BU$39),BX38,IF($BU$39=MAX($BU$36:$BU$39),BX39,BX38)))) -> 1 | BY41: =IF($BU$36=MAX($BU$36:$BU$39),BY36,IF($BU$37=MAX($BU$36:$BU$39),BY37,IF($BU$38=MAX($BU$36:$BU$39),BY38,IF($BU$39=MAX($BU$36:$BU$39),BY39,BY38)))) -> 10
BU42: TOTAL | BV42: Part des VAE dans le total | BW42: Part des femmes dans le total | BX42: Part des VAE chez les femmes | BZ42: Remarque
...

Sheet LA RO ENILV
A1: Lieu : | B1: La Roche Rond-Point ENILV | O1: Date : | P1: 16 juin 2020
A2: Nom des personnes participant au comptage : | L2: Sylviane
A3: Météo :
A4: Remarques :
A5: Principe d'utilisation pour chaque intervalle de temps,
A6: Marquer une croix vélo ou VAE dans la colonne H ou F
A7: Sauf si 'enfant' marquer E ou 'modes nouveaux de déplacement' (trotinette, skate, ets) marquer Z
A8: Il y a donc un seul marquage par personne comptée
C9: Du centre (La Roche) vers | O9: D'Eteaux av Gambetta vers | AA9: De boutique Enilv vers | AM9: De Reignier vers
C10: Av Gambetta Eteaux | G10: Boutique Enilv | K10: Reignier | O10: Bout Enilv | S10: Reignier | W10: La Roche | AA10: Reignier | AE10: La Roche | AI10: Av Gambetta Eteaux | AM10: La Roche | AQ10: Av Gambetta Eteaux | AU10: Bout Enilv
C11: H | E11: F | G11: H | I11: F | K11: H | M11: F | O11: H | Q11: F | S11: H | U11: F | W11: H | Y11: F | AA11: H | AC11: F | AE11: H | AG11: F | AI11: H | AK11: F | AM11: H | AO11: F | AQ11: H | AS11: F | AU11: H | AW11: F
A12: H | B12: Minute | C12: VAE | D12: vélo | E12: VAE | F12: vélo | G12: VAE | H12: vélo | I12: VAE | J12: vélo | K12: VAE | L12: vélo | M12: VAE | N12: vélo | O12: VAE | P12: vélo | Q12: VAE | R12: vélo | S12: VAE | T12: vélo | U12: VAE | V12: vélo | W12: VAE | X12: vélo | Y12: VAE | Z12: vélo | AA12: VAE | AB12: vélo | AC12: VAE | AD12: vélo | AE12: VAE | AF12: vélo | AG12: VAE | AH12: vélo | AI12: VAE | AJ12: vélo | AK12: VAE | AL12: vélo | AM12: VAE | AN12: vélo | AO12: VAE | AP12: vélo | AQ12: VAE | AR12: vélo | AS12: VAE | AT12: vélo | AU12: VAE | AV12: vélo | AW12: VAE | AX12: vélo
A13: 6 | B13: 30 – 45
B14: 45 - 59 | L14: 1
A15: 7 | B15: 00 – 15 | AE15: 1 | AF15: 1
B16: 15 – 30 | L16: 1 | N16: 1
B17: 30 – 45 | AM17: 1
B18: 45 – 59 | K18: 1 | V18: 1
A19: 8 | B19: 00 – 15 | K19: 1 | Z19: 1
B20: 15 – 30 | L20: 1 | AB20: 1 | AM20: 1 | AN20: 1
B21: 30 – 45 | S21: 2 | AM21: 1
A22: 9 | B22: 45 – 59 | S22: 1
A25: Lieu : | B25: =B1 -> La Roche Rond-Point ENILV | O25: Date : | P25: =P1 -> 16 juin 2020
A26: Nom des personnes participant au comptage : | L26: =L2 -> Sylviane
A27: Météo : | C27: beau mais frais, annoncé pluies dans l'après-midi
A28: Remarques : | C28: 34 piétons plus 32 étudiants piéton en direction lycée et seulement 2 écoliers- les 2 enfants comptés étaient sur le trottoir avec 1 parent- 1 femme sur trottoir
A29: Principe d'utilisation : pour chaque intervalle de temps, marquer une croix par personne comptée dans la colonne la décrivant; si enfant marquer E
A30: Il y a donc une seule croix par personne comptée
C32: =C9 -> Du centre (La Roche) vers | O32: =O9 -> D'Eteaux av Gambetta vers | AA32: =AA9 -> De boutique Enilv vers | AM32: =AM9 -> De Reignier vers | BA32: TOTAL | BB32: Nombre de VAE dans le total | BC32: Nombre de femmes dans le total | BD32: Nombre de VAE chez les femmes | BE32: Cycles sur route de Reignier | BF32: Remarque
C33: =C10 -> Av Gambetta Eteaux | G33: =G10 -> Boutique Enilv | K33: =K10 -> Reignier | O33: =O10 -> Bout Enilv | S33: =S10 -> Reignier | W33: =W10 -> La Roche | AA33: =AA10 -> Reignier | AE33: =AE10 -> La Roche | AI33: =AI10 -> Av Gambetta Eteaux | AM33: =AM10 -> La Roche | AQ33: =AQ10 -> Av Gambetta Eteaux | AU33: =AU10 -> Bout Enilv
C34: H | E34: F | G34: H | I34: F | K34: H | M34: F | O34: H | Q34: F | S34: H | U34: F | W34: H | Y34: F | AA34: H | AC34: F | AE34: H | AG34: F | AI34: H | AK34: F | AM34: H | AO34: F | AQ34: H | AS34: F | AU34: H | AW34: F
A35: Période | C35: VAE | D35: vélo | E35: VAE | F35: vélo | G35: VAE | H35: vélo | I35: VAE | J35: vélo | K35: VAE | L35: vélo | M35: VAE | N35: vélo | O35: VAE | P35: vélo | Q35: VAE | R35: vélo | S35: VAE | T35: vélo | U35: VAE | V35: vélo | W35: VAE | X35: vélo | Y35: VAE | Z35: vélo | AA35: VAE | AB35: vélo | AC35: VAE | AD35: vélo | AE35: VAE | AF35: vélo | AG35: VAE | AH35: vélo | AI35: VAE | AJ35: vélo | AK35: VAE | AL35: vélo | AM35: VAE | AN35: vélo | AO35: VAE | AP35: vélo | AQ35: VAE | AR35: vélo | AS35: VAE | AT35: vélo | AU35: VAE | AV35: vélo | AW35: VAE | AX35: vélo | AY35: Période
A36: 6:30 à 7:00 | C36: =SUM(C13:C14) -> 0 | D36: =SUM(D13:D14) -> 0 | E36: =SUM(E13:E14) -> 0 | F36: =SUM(F13:F14) -> 0 | G36: =SUM(G13:G14) -> 0 | H36: =SUM(H13:H14) -> 0 | I36: =SUM(I13:I14) -> 0 | J36: =SUM(J13:J14) -> 0 | ... AX36: =SUM(AX13:AX14) -> 0 | AY36: =A36 -> 6:30 à 7:00 | BA36: =SUM(C36:AX36) -> 1 | BB36: =C36+E36+G36+I36+K36+M36+O36+Q36+S36+U36+W36+Y36+AA36+AC36+AE36+AG36+AI36+AK36+AM36+AO36+AQ36+AS36+AU36+AW36 -> 0 | BC36: =E36+F36+I36+J36+M36+N36+Q36+R36+U36+V36+Y36+Z36+AC36+AD36+AG36+AH36+AK36+AL36+AO36+AP36+AS36+AT36+AW36+AX36 -> 0 | BD36: =E36+I36+M36+Q36+U36+Y36+AC36+AG36+AK36+AO36+AS36+AW36 -> 0 | BE36: =SUM(K36:N36)+SUM(S36:V36)+SUM(AA36:AD36)+SUM(AM36:AX36) -> 1 | BF36: 34 piétons plus 32 étudiants piétons en direction lycée
A37: 7:00 à 8:00 | C37: =SUM(C15:C18) -> 0 | D37: =SUM(D15:D18) -> 0 | E37: =SUM(E15:E18) -> 0 | F37: =SUM(F15:F18) -> 0 | G37: =SUM(G15:G18) -> 0 | H37: =SUM(H15:H18) -> 0 | I37: =SUM(I15:I18) -> 0 | J37: =SUM(J15:J18) -> 0 | ... AX37: =SUM(AX15:AX18) -> 0 | AY37: =A37 -> 7:00 à 8:00 | BA37: =SUM(C37:AX37) -> 7 | BB37: =C37+E37+G37+I37+K37+M37+O37+Q37+S37+U37+W37+Y37+AA37+AC37+AE37+AG37+AI37+AK37+AM37+AO37+AQ37+AS37+AU37+AW37 -> 3 | BC37: =E37+F37+I37+J37+M37+N37+Q37+R37+U37+V37+Y37+Z37+AC37+AD37+AG37+AH37+AK37+AL37+AO37+AP37+AS37+AT37+AW37+AX37 -> 2 | BD37: =E37+I37+M37+Q37+U37+Y37+AC37+AG37+AK37+AO37+AS37+AW37 -> 0 | BE37: =SUM(K37:N37)+SUM(S37:V37)+SUM(AA37:AD37)+SUM(AM37:AX37) -> 5 | BF37: et seulement 2 écoliers- 2 enfants comptés qui étaient sur le trottoir avec 1 parent
A38: 7:30 à 8:30 | C38: =SUM(C17:C20) -> 0 | D38: =SUM(D17:D20) -> 0 | E38: =SUM(E17:E20) -> 0 | F38: =SUM(F17:F20) -> 0 | G38: =SUM(G17:G20) -> 0 | H38: =SUM(H17:H20) -> 0 | I38: =SUM(I17:I20) -> 0 | J38: =SUM(J17:J20) -> 0 | ... AX38: =SUM(AX17:AX20) -> 0 | AY38: =A38 -> 7:30 à 8:30 | BA38: =SUM(C38:AX38) -> 9 | BB38: =C38+E38+G38+I38+K38+M38+O38+Q38+S38+U38+W38+Y38+AA38+AC38+AE38+AG38+AI38+AK38+AM38+AO38+AQ38+AS38+AU38+AW38 -> 4 | BC38: =E38+F38+I38+J38+M38+N38+Q38+R38+U38+V38+Y38+Z38+AC38+AD38+AG38+AH38+AK38+AL38+AO38+AP38+AS38+AT38+AW38+AX38 -> 2 | BD38: =E38+I38+M38+Q38+U38+Y38+AC38+AG38+AK38+AO38+AS38+AW38 -> 0 | BE38: =SUM(K38:N38)+SUM(S38:V38)+SUM(AA38:AD38)+SUM(AM38:AX38) -> 8 | BF38: 2 des 3 femmes circulaient sur le trottoir !
A39: 8:00 à 9:00 | C39: =SUM(C19:C22) -> 0 | D39: =SUM(D19:D22) -> 0 | E39: =SUM(E19:E22) -> 0 | F39: =SUM(F19:F22) -> 0 | G39: =SUM(G19:G22) -> 0 | H39: =SUM(H19:H22) -> 0 | I39: =SUM(I19:I22) -> 0 | J39: =SUM(J19:J22) -> 0 | ... AX39: =SUM(AX19:AX22) -> 0 | AY39: =A39 -> 8:00 à 9:00 | BA39: =SUM(C39:AX39) -> 10 | BB39: =C39+E39+G39+I39+K39+M39+O39+Q39+S39+U39+W39+Y39+AA39+AC39+AE39+AG39+AI39+AK39+AM39+AO39+AQ39+AS39+AU39+AW39 -> 6 | BC39: =E39+F39+I39+J39+M39+N39+Q39+R39+U39+V39+Y39+Z39+AC39+AD39+AG39+AH39+AK39+AL39+AO39+AP39+AS39+AT39+AW39+AX39 -> 1 | BD39: =E39+I39+M39+Q39+U39+Y39+AC39+AG39+AK39+AO39+AS39+AW39 -> 0 | BE39: =SUM(K39:N39)+SUM(S39:V39)+SUM(AA39:AD39)+SUM(AM39:AX39) -> 9 | BF39: 3 cyclosportifs
A40: TOTAL | C40: =SUM(C13:C22) -> 0 | D40: =SUM(D13:D22) -> 0 | E40: =SUM(E13:E22) -> 0 | F40: =SUM(F13:F22) -> 0 | G40: =SUM(G13:G22) -> 0 | H40: =SUM(H13:H22) -> 0 | I40: =SUM(I13:I22) -> 0 | J40: =SUM(J13:J22) -> 0 | ... AX40: =SUM(AX13:AX22) -> 0 | AY40: TOTAL | BA40: =SUM(C40:AX40) -> 18 | BB40: =C40+E40+G40+I40+K40+M40+O40+Q40+S40+U40+W40+Y40+AA40+AC40+AE40+AG40+AI40+AK40+AM40+AO40+AQ40+AS40+AU40+AW40 -> 9 | BC40: =E40+F40+I40+J40+M40+N40+Q40+R40+U40+V40+Y40+Z40+AC40+AD40+AG40+AH40+AK40+AL40+AO40+AP40+AS40+AT40+AW40+AX40 -> 3 | BD40: =E40+I40+M40+Q40+U40+Y40+AC40+AG40+AK40+AO40+AS40+AW40 -> 0 | BE40: =SUM(K40:N40)+SUM(S40:V40)+SUM(AA40:AD40)+SUM(AM40:AX40) -> 15
AY41: =IF($BA$36=MAX($BA$36:$BA$39),AY36,IF($BA$37=MAX($BA$36:$BA$39),AY37,IF($BA$38=MAX($BA$36:$BA$39),AY38,IF($BA$39=MAX($BA$36:$BA$39),AY39,AY38)))) -> 8:00 à 9:00 | BA41: =IF($BA$36=MAX($BA$36:$BA$39),BA36,IF($BA$37=MAX($BA$36:$BA$39),BA37,IF($BA$38=MAX($BA$36:$BA$39),BA38,IF($BA$39=MAX($BA$36:$BA$39),BA39,BA38)))) -> 10 | BB41: =IF($BA$36=MAX($BA$36:$BA$39),BB36,IF($BA$37=MAX($BA$36:$BA$39),BB37,IF($BA$38=MAX($BA$36:$BA$39),BB38,IF($BA$39=MAX($BA$36:$BA$39),BB39,BB38)))) -> 6 | BC41: =IF($BA$36=MAX($BA$36:$BA$39),BC36,IF($BA$37=MAX($BA$36:$BA$39),BC37,IF($BA$38=MAX($BA$36:$BA$39),BC38,IF($BA$39=MAX($BA$36:$BA$39),BC39,BC38)))) -> 1 | BD41: =IF($BA$36=MAX($BA$36:$BA$39),BD36,IF($BA$37=MAX($BA$36:$BA$39),BD37,IF($BA$38=MAX($BA$36:$BA$39),BD38,IF($BA$39=MAX($BA$36:$BA$39),BD39,BD38)))) -> 0 | BE41: =IF($BA$36=MAX($BA$36:$BA$39),BE36,IF($BA$37=MAX($BA$36:$BA$39),BE37,IF($BA$38=MAX($BA$36:$BA$39),BE38,IF($BA$39=MAX($BA$36:$BA$39),BE39,BE38)))) -> 9
BA42: TOTAL | BB42: Part des VAE dans le total | BC42: Part des femmes dans le total | BD42: Part des VAE chez les femmes | BE42: =BE32 -> Cycles sur route de Reignier | BF42: Remarque
AY45: Période
...

Sheet AR PAPETERI
B1: Arenthon La Papeterie RD19/TNA | S1: Date : | T1: 16 juin 2020
A2: Nom des personnes participant au comptage : | L2: Béa
A3: Météo : | D3: Beau mais temps incertain annoncé
A4: Remarques :
A5: Principe d'utilisation pour chaque intervalle de temps,
A6: Marquer une croix vélo ou VAE dans la colonne H ou F.
A7: Sauf si 'enfant' marquer E ou 'modes nouveaux de déplacement' (trotinette, skate, ets) marquer Z
A8: Il y a donc un seul marquage par personne comptée
C9: De Arenthon vers | O9: De Bonneville vers | AA9: De Rte de La Papeterie vers
C10: Bonneville | G10: TNA | K10: Rte Papeterie | O10: TNA | S10: Arenthon | W10: Rte Papeterie | AA10: Arenthon | AE10: TNA | AI10: Bonneville
C11: H | E11: F | G11: H | I11: F | K11: H | M11: F | O11: H | Q11: F | S11: H | U11: F | W11: H | Y11: F | AA11: H | AC11: F | AE11: H | AG11: F | AI11: H | AK11: F
A12: Heure | B12: Minute | C12: VAE | D12: vélo | E12: VAE | F12: vélo | G12: VAE | H12: vélo | I12: VAE | J12: vélo | K12: VAE | L12: vélo | M12: VAE | N12: vélo | O12: VAE | P12: vélo | Q12: VAE | R12: vélo | S12: VAE | T12: vélo | U12: VAE | V12: vélo | W12: VAE | X12: vélo | Y12: VAE | Z12: vélo | AA12: VAE | AB12: vélo | AC12: VAE | AD12: vélo | AE12: VAE | AF12: vélo | AG12: VAE | AH12: vélo | AI12: VAE | AJ12: vélo | AK12: VAE | AL12: vélo
A13: 6 | B13: 30 – 45
B14: 45 - 59 | D14: 1
A15: 7 | B15: 00 – 15
B16: 15 – 30 | T16: 1
B17: 30 – 45
B18: 45 – 59 | D18: 1 | F18: 1 | T18: 1
A19: 8 | B19: 00 – 15
B20: 15 – 30 | D20: 1 | L20: 1 | T20: 1 | AF20: 1
B21: 30 – 45 | T21: 1 | AJ21: 1
A22: 9 | B22: 45 – 59 | D22: 1 | AI22: 1 | AJ22: 1
A24: Lieu : | B24: =B1 -> Arenthon La Papeterie RD19/TNA | S24: Date : | T24: =T1 -> 16 juin 2020
A25: Nom des personnes participant au comptage : | L25: =L2 -> Béa
A26: Météo :
A27: Remarques :
A28: Principe d'utilisation pour chaque intervalle de temps, | AO28: 11 cyclosportifs
A29: Marquer une croix vélo ou VAE dans la colonne H ou F. Sauf si 'enfant' marquer E ou 'modes nouveaux de déplacement' (trotinette, skate, ets) marquer Z
A30: Il y a donc un seul marquage par personne comptée
C31: =C9 -> De Arenthon vers | O31: =O9 -> De Bonneville vers | AA31: =AA9 -> De Rte de La Papeterie vers | AO31: TOTAL | AP31: Nombre de VAE dans le total | AQ31: Nombre de femmes dans le total | AR31: Nombre de VAE chez les femmes | AS31: Cycles sur RD 19
C32: =C10 -> Bonneville | G32: =G10 -> TNA | K32: =K10 -> Rte Papeterie | O32: =O10 -> TNA | S32: =S10 -> Arenthon | W32: =W10 -> Rte Papeterie | AA32: =AA10 -> Arenthon | AE32: =AE10 -> TNA | AI32: =AI10 -> Bonneville
C33: H | E33: F | G33: H | I33: F | K33: H | M33: F | O33: H | Q33: F | S33: H | U33: F | W33: H | Y33: F | AA33: H | AC33: F | AE33: H | AG33: F | AI33: H | AK33: F
A34: Période | C34: VAE | D34: vélo | E34: VAE | F34: vélo | G34: VAE | H34: vélo | I34: VAE | J34: vélo | K34: VAE | L34: vélo | M34: VAE | N34: vélo | O34: VAE | P34: vélo | Q34: VAE | R34: vélo | S34: VAE | T34: vélo | U34: VAE | V34: vélo | W34: VAE | X34: vélo | Y34: VAE | Z34: vélo | AA34: VAE | AB34: vélo | AC34: VAE | AD34: vélo | AE34: VAE | AF34: vélo | AG34: VAE | AH34: vélo | AI34: VAE | AJ34: vélo | AK34: VAE | AL34: vélo | AM34: Période
A35: 6:30 à 7:00 | C35: =SUM(C13:C14) -> 0 | D35: =SUM(D13:D14) -> 1 | E35: =SUM(E13:E14) -> 0 | F35: =SUM(F13:F14) -> 0 | G35: =SUM(G13:G14) -> 0 | H35: =SUM(H13:H14) -> 0 | I35: =SUM(I13:I14) -> 0 | J35: =SUM(J13:J14) -> 0 | ... AL35: =SUM(AL13:AL14) -> 0 | AM35: =A35 -> 6:30 à 7:00 | AO35: =SUM(C35:AL35) -> 1 | AP35: =C35+E35+G35+I35+K35+M35+O35+Q35+S35+U35+W35+Y35+AA35+AC35+AE35+AG35+AI35+AK35 -> 0 | AQ35: =E35+F35+I35+J35+M35+N35+Q35+R35+U35+V35+Y35+Z35+AC35+AD35+AG35+AH35+AK35+AL35 -> 0 | AR35: =E35+I35+M35+Q35+U35+Y35+AC35+AG35+AK35 -> 0 | AS35: =SUM(C35:AD35)+SUM(AI35:AL35) -> 1
A36: 7:00 à 8:00 | C36: =SUM(C15:C18) -> 0 | D36: =SUM(D15:D18) -> 1 | E36: =SUM(E15:E18) -> 0 | F36: =SUM(F15:F18) -> 1 | G36: =SUM(G15:G18) -> 0 | H36: =SUM(H15:H18) -> 0 | I36: =SUM(I15:I18) -> 0 | J36: =SUM(J15:J18) -> 0 | ... AL36: =SUM(AL15:AL18) -> 0 | AM36: =A36 -> 7:00 à 8:00 | AO36: =SUM(C36:AL36) -> 4 | AP36: =C36+E36+G36+I36+K36+M36+O36+Q36+S36+U36+W36+Y36+AA36+AC36+AE36+AG36+AI36+AK36 -> 0 | AQ36: =E36+F36+I36+J36+M36+N36+Q36+R36+U36+V36+Y36+Z36+AC36+AD36+AG36+AH36+AK36+AL36 -> 1 | AR36: =E36+I36+M36+Q36+U36+Y36+AC36+AG36+AK36 -> 0 | AS36: =SUM(C36:AD36)+SUM(AI36:AL36) -> 4
A37: 7:30 à 8:30 | C37: =SUM(C17:C20) -> 0 | D37: =SUM(D17:D20) -> 2 | E37: =SUM(E17:E20) -> 0 | F37: =SUM(F17:F20) -> 1 | G37: =SUM(G17:G20) -> 0 | H37: =SUM(H17:H20) -> 0 | I37: =SUM(I17:I20) -> 0 | J37: =SUM(J17:J20) -> 0 | ... AL37: =SUM(AL17:AL20) -> 0 | AM37: =A37 -> 7:30 à 8:30 | AO37: =SUM(C37:AL37) -> 7 | AP37: =C37+E37+G37+I37+K37+M37+O37+Q37+S37+U37+W37+Y37+AA37+AC37+AE37+AG37+AI37+AK37 -> 0 | AQ37: =E37+F37+I37+J37+M37+N37+Q37+R37+U37+V37+Y37+Z37+AC37+AD37+AG37+AH37+AK37+AL37 -> 1 | AR37: =E37+I37+M37+Q37+U37+Y37+AC37+AG37+AK37 -> 0 | AS37: =SUM(C37:AD37)+SUM(AI37:AL37) -> 6
A38: 8:00 à 9:00 | C38: =SUM(C19:C22) -> 0 | D38: =SUM(D19:D22) -> 2 | E38: =SUM(E19:E22) -> 0 | F38: =SUM(F19:F22) -> 0 | G38: =SUM(G19:G22) -> 0 | H38: =SUM(H19:H22) -> 0 | I38: =SUM(I19:I22) -> 0 | J38: =SUM(J19:J22) -> 0 | ... AL38: =SUM(AL19:AL22) -> 0 | AM38: =A38 -> 8:00 à 9:00 | AO38: =SUM(C38:AL38) -> 9 | AP38: =C38+E38+G38+I38+K38+M38+O38+Q38+S38+U38+W38+Y38+AA38+AC38+AE38+AG38+AI38+AK38 -> 1 | AQ38: =E38+F38+I38+J38+M38+N38+Q38+R38+U38+V38+Y38+Z38+AC38+AD38+AG38+AH38+AK38+AL38 -> 0 | AR38: =E38+I38+M38+Q38+U38+Y38+AC38+AG38+AK38 -> 0 | AS38: =SUM(C38:AD38)+SUM(AI38:AL38) -> 8
A39: TOTAL | C39: =SUM(C13:C22) -> 0 | D39: =SUM(D13:D22) -> 4 | E39: =SUM(E13:E22) -> 0 | F39: =SUM(F13:F22) -> 1 | G39: =SUM(G13:G22) -> 0 | H39: =SUM(H13:H22) -> 0 | I39: =SUM(I13:I22) -> 0 | J39: =SUM(J13:J22) -> 0 | ... AL39: =SUM(AL13:AL22) -> 0 | AM39: TOTAL | AO39: =SUM(C39:AL39) -> 14 | AP39: =C39+E39+G39+I39+K39+M39+O39+Q39+S39+U39+W39+Y39+AA39+AC39+AE39+AG39+AI39+AK39 -> 1 | AQ39: =E39+F39+I39+J39+M39+N39+Q39+R39+U39+V39+Y39+Z39+AC39+AD39+AG39+AH39+AK39+AL39 -> 1 | AR39: =E39+I39+M39+Q39+U39+Y39+AC39+AG39+AK39 -> 0 | AS39: =AS35+AS36+AS38 -> 13
AM40: =IF($AO$37=MAX($AO$35:$AO$38),AM37,IF($AO$36=MAX($AO$35:$AO$38),AM36,IF($AN$35=MAX($AO$35:$AO$38),AM35,IF($AO$38=MAX($AO$35:$AO$38),AM38,AM38)))) -> 8:00 à 9:00 | AO40: =IF($AO$37=MAX($AO$35:$AO$38),AO37,IF($AO$36=MAX($AO$35:$AO$38),AO36,IF($AN$35=MAX($AO$35:$AO$38),AO35,IF($AO$38=MAX($AO$35:$AO$38),AO38,AO38)))) -> 9 | AP40: =IF($AO$37=MAX($AO$35:$AO$38),AP37,IF($AO$36=MAX($AO$35:$AO$38),AP36,IF($AN$35=MAX($AO$35:$AO$38),AP35,IF($AO$38=MAX($AO$35:$AO$38),AP38,AP38)))) -> 1 | AQ40: =IF($AO$37=MAX($AO$35:$AO$38),AQ37,IF($AO$36=MAX($AO$35:$AO$38),AQ36,IF($AN$35=MAX($AO$35:$AO$38),AQ35,IF($AO$38=MAX($AO$35:$AO$38),AQ38,AQ38)))) -> 0 | AR40: =IF($AO$37=MAX($AO$35:$AO$38),AR37,IF($AO$36=MAX($AO$35:$AO$38),AR36,IF($AN$35=MAX($AO$35:$AO$38),AR35,IF($AO$38=MAX($AO$35:$AO$38),AR38,AR38)))) -> 0 | AS40: =IF($AO$37=MAX($AO$35:$AO$38),AS37,IF($AO$36=MAX($AO$35:$AO$38),AS36,IF($AN$35=MAX($AO$35:$AO$38),AS35,IF($AO$38=MAX($AO$35:$AO$38),AS38,AS38)))) -> 8
AO41: TOTAL | AP41: Part des VAE dans le total | AQ41: Part des femmes dans le total | AR41: Part des VAE chez les femmes | AS41: =AS31 -> Cycles sur RD 19
...

Sheet SCIEN BELCOMBE
A1: Lieu : | B1: Scientrier Carrefour Pont de Bellecombe | M1: Date : | N1: mardi 16 juin 2020
A2: Nom des personnes participant au comptage : | G2: Philippe LEMOINE
A3: Météo : | C3: Beau temps, mais frais
A4: Remarques : | C4: Petite brume matinale (liée à l'Arve) et carrefour très bruyant (beaucoup de camions !)
A5: Méthodologie : | C5: Pour chaque intervalle de temps, marquer une seule croix par personne comptée
C6: Si c'est enfant, remplacer la croix par E, une trottinette T, un piéton P, etc.
C8: Depuis 'La Roche' | K8: Depuis 'Reignier' | S8: Depuis 'Findrol'
C9: vers 'Reignier' | G9: vers 'Findrol' | K9: vers 'Findrol' | O9: vers 'La Roche' | S9: vers 'Reignier' | W9: vers 'La Roche'
C10: H | E10: F | G10: H | I10: F | K10: H | M10: F | O10: H | Q10: F | S10: H | U10: F | W10: H | Y10: F
A11: Heure | B11: Minute | C11: VAE | D11: vélo | E11: VAE | F11: vélo | G11: VAE | H11: vélo | I11: VAE | J11: vélo | K11: VAE | L11: vélo | M11: VAE | N11: vélo | O11: VAE | P11: vélo | Q11: VAE | R11: vélo | S11: VAE | T11: vélo | U11: VAE | V11: vélo | W11: VAE | X11: vélo | Y11: VAE | Z11: vélo
A12: 6 | B12: 30 – 44'59
B13: 45 – 59'59
A14: 7 | B14: 00 – 14'59 | T14: 1
B15: 15 – 29'59
B16: 30 – 44'59 | H16: 1 | L16: 1
B17: 45 – 59'59 | H17: 1 | L17: 1
A18: 8 | B18: 00 – 14'59 | L18: 1
B19: 15 – 29'59
B20: 30 – 44'59
A21: 9 | B21: 45 – 59'59
A23: Lieu : | B23: =B1 -> Scientrier Carrefour Pont de Bellecombe | M23: Date : | N23: =N1 -> mardi 16 juin 2020
A24: Nom des personnes participant au comptage : | G24: =G2 -> Philippe LEMOINE
A25: Météo : | C25: =C3 -> Beau temps, mais frais
A26: Remarques : | C26: =C4 -> Petite brume matinale (liée à l'Arve) et carrefour très bruyant (beaucoup de camions !)
AA27: C'est l'enfer ce carrefour
AA29: Lieu :
C30: =C8 -> Depuis 'La Roche' | K30: =K8 -> Depuis 'Reignier' | S30: =S8 -> Depuis 'Findrol' | AC30: TOTAL | AD30: Nombre de VAE dans le total | AE30: Nombre de femmes dans le total | AF30: Nombre de VAE chez les femmes
C31: =C9 -> vers 'Reignier' | G31: =G9 -> vers 'Findrol' | K31: =K9 -> vers 'Findrol' | O31: =O9 -> vers 'La Roche' | S31: =S9 -> vers 'Reignier' | W31: =W9 -> vers 'La Roche'
C32: H | E32: F | G32: H | I32: F | K32: H | M32: F | O32: H | Q32: F | S32: H | U32: F | W32: H | Y32: F
A33: Période | C33: VAE | D33: vélo | E33: VAE | F33: vélo | G33: VAE | H33: vélo | I33: VAE | J33: vélo | K33: VAE | L33: vélo | M33: VAE | N33: vélo | O33: VAE | P33: vélo | Q33: VAE | R33: vélo | S33: VAE | T33: vélo | U33: VAE | V33: vélo | W33: VAE | X33: vélo | Y33: VAE | Z33: vélo | AA33: Période
A34: 6:30 à 7:00 | C34: =SUM(C12:C13) -> 0 | D34: =SUM(D12:D13) -> 0 | E34: =SUM(E12:E13) -> 0 | F34: =SUM(F12:F13) -> 0 | G34: =SUM(G12:G13) -> 0 | H34: =SUM(H12:H13) -> 0 | I34: =SUM(I12:I13) -> 0 | J34: =SUM(J12:J13) -> 0 | ... Z34: =SUM(Z12:Z13) -> 0 | AA34: =A34 -> 6:30 à 7:00 | AC34: =SUM(C34:Z34) -> 0 | AD34: =C34+E34+G34+I34+K34+M34+O34+Q34+S34+U34+W34+Y34 -> 0 | AE34: =E34+F34+I34+J34+M34+N34+Q34+R34+U34+V34+Y34+Z34 -> 0 | AF34: =E34+I34+M34+Q34+U34+Y34 -> 0
A35: 7:00 à 8:00 | C35: =SUM(C14:C17) -> 0 | D35: =SUM(D14:D17) -> 0 | E35: =SUM(E14:E17) -> 0 | F35: =SUM(F14:F17) -> 0 | G35: =SUM(G14:G17) -> 0 | H35: =SUM(H14:H17) -> 2 | I35: =SUM(I14:I17) -> 0 | J35: =SUM(J14:J17) -> 0 | ... Z35: =SUM(Z14:Z17) -> 0 | AA35: =A35 -> 7:00 à 8:00 | AC35: =SUM(C35:Z35) -> 5 | AD35: =C35+E35+G35+I35+K35+M35+O35+Q35+S35+U35+W35+Y35 -> 0 | AE35: =E35+F35+I35+J35+M35+N35+Q35+R35+U35+V35+Y35+Z35 -> 0 | AF35: =E35+I35+M35+Q35+U35+Y35 -> 0
A36: 7:30 à 8:30 | C36: =SUM(C16:C19) -> 0 | D36: =SUM(D16:D19) -> 0 | E36: =SUM(E16:E19) -> 0 | F36: =SUM(F16:F19) -> 0 | G36: =SUM(G16:G19) -> 0 | H36: =SUM(H16:H19) -> 2 | I36: =SUM(I16:I19) -> 0 | J36: =SUM(J16:J19) -> 0 | ... Z36: =SUM(Z16:Z19) -> 0 | AA36: =A36 -> 7:30 à 8:30 | AC36: =SUM(C36:Z36) -> 5 | AD36: =C36+E36+G36+I36+K36+M36+O36+Q36+S36+U36+W36+Y36 -> 0 | AE36: =E36+F36+I36+J36+M36+N36+Q36+R36+U36+V36+Y36+Z36 -> 0 | AF36: =E36+I36+M36+Q36+U36+Y36 -> 0
A37: 8:00 à 9:00 | C37: =SUM(C18:C21) -> 0 | D37: =SUM(D18:D21) -> 0 | E37: =SUM(E18:E21) -> 0 | F37: =SUM(F18:F21) -> 0 | G37: =SUM(G18:G21) -> 0 | H37: =SUM(H18:H21) -> 0 | I37: =SUM(I18:I21) -> 0 | J37: =SUM(J18:J21) -> 0 | ... Z37: =SUM(Z18:Z21) -> 0 | AA37: =A37 -> 8:00 à 9:00 | AC37: =SUM(C37:Z37) -> 1 | AD37: =C37+E37+G37+I37+K37+M37+O37+Q37+S37+U37+W37+Y37 -> 0 | AE37: =E37+F37+I37+J37+M37+N37+Q37+R37+U37+V37+Y37+Z37 -> 0 | AF37: =E37+I37+M37+Q37+U37+Y37 -> 0
A38: TOTAL | C38: =SUM(C12:C21) -> 0 | D38: =SUM(D12:D21) -> 0 | E38: =SUM(E12:E21) -> 0 | F38: =SUM(F12:F21) -> 0 | G38: =SUM(G12:G21) -> 0 | H38: =SUM(H12:H21) -> 2 | I38: =SUM(I12:I21) -> 0 | J38: =SUM(J12:J21) -> 0 | ... Z38: =SUM(Z12:Z21) -> 0 | AA38: TOTAL | AC38: =SUM(C38:Z38) -> 6 | AD38: =AD34+AD35+AD37 -> 0 | AE38: =AE34+AE35+AE37 -> 0 | AF38: =AF34+AF35+AF37 -> 0
AA39: =IF($AC$37=MAX($AC$34:$AC$37),AA37,IF($AC$36=MAX($AC$34:$AC$37),AA36,IF($AC$35=MAX($AC$34:$AC$37),AA35,IF($AC$34=MAX($AC$34:$AC$37),AA34,AA37)))) -> 7:30 à 8:30 | AC39: =IF($AC$37=MAX($AC$34:$AC$37),AC37,IF($AC$36=MAX($AC$34:$AC$37),AC36,IF($AC$35=MAX($AC$34:$AC$37),AC35,IF($AC$34=MAX($AC$34:$AC$37),AC34,AC37)))) -> 5 | AD39: =IF($AC$37=MAX($AC$34:$AC$37),AD37,IF($AC$36=MAX($AC$34:$AC$37),AD36,IF($AC$35=MAX($AC$34:$AC$37),AD35,IF($AC$34=MAX($AC$34:$AC$37),AD34,AD37)))) -> 0 | AE39: =IF($AC$37=MAX($AC$34:$AC$37),AE37,IF($AC$36=MAX($AC$34:$AC$37),AE36,IF($AC$35=MAX($AC$34:$AC$37),AE35,IF($AC$34=MAX($AC$34:$AC$37),AE34,AE37)))) -> 0 | AF39: =IF($AC$37=MAX($AC$34:$AC$37),AF37,IF($AC$36=MAX($AC$34:$AC$37),AF36,IF($AC$35=MAX($AC$34:$AC$37),AF35,IF($AC$34=MAX($AC$34:$AC$37),AF34,AF37)))) -> 0
AC40: TOTAL | AD40: Part des VAE dans le total | AE40: Part des femmes dans le total | AF40: Part des VAE chez les femmes
AA43: Période
AA44: =AA34 -> 6:30 à 7:00 | AD44: =IF(AD34=0,0,AD34/AC34) -> 0 | AE44: =IF(AE34=0,0,AE34/AC34) -> 0 | AF44: =IF(AF34=0,0,AF34/AD34) -> 0
AA45: =AA35 -> 7:00 à 8:00 | AD45: =IF(AD35=0,0,AD35/AC35) -> 0 | AE45: =IF(AE35=0,0,AE35/AC35) -> 0 | AF45: =IF(AF35=0,0,AF35/AD35) -> 0
...

Sheet ST PI BORNE DESSY
A1: Lieu : | B1: St Pierre Franchissement du Borne Dessy | K1: Date : | L1: 16 juin 2020
A2: Nom des personnes participant au comptage : | I2: Stéphane Moutard-Martin / La Fabrique à Biclou
A3: Météo : | C3: frais 13°C
A4: Remarques : | C4: Faire colonnes VELO puis VAE
A6: Principe d'utilisation pour chaque intervalle de temps,
A7: Marquer une croix vélo ou VAE dans la colonne H ou F.
A8: Sauf si 'enfant' marquer E ou 'modes nouveaux de déplacement' (trotinette, skate, ets) marquer Z
A9: Il y a donc un seul marquage par personne comptée
C10: De Rte Gorges du Borne vers | K10: De Avenue des Digues vers | S10: De Dessy vers
C11: Av des Digues | G11: Dessy | K11: Dessy | O11: Rte Gorges du Borne | S11: Rte Gorges du Borne | W11: Av des Digues
C12: H | E12: F | G12: H | I12: F | K12: H | M12: F | O12: H | Q12: F | S12: H | U12: F | W12: H | Y12: F
A13: Heure | B13: Minute | C13: VAE | D13: vélo | E13: VAE | F13: vélo | G13: VAE | H13: vélo | I13: VAE | J13: vélo | K13: VAE | L13: vélo | M13: VAE | N13: vélo | O13: VAE | P13: vélo | Q13: VAE | R13: vélo | S13: VAE | T13: vélo | U13: VAE | V13: vélo | W13: VAE | X13: vélo | Y13: VAE | Z13: vélo
A14: 6 | B14: 30 – 45
B15: 45 - 59
A16: 7 | B16: 00 – 15 | T16: 1
B17: 15 – 30
B18: 30 – 45 | H18: 2 | Z18: 1
B19: 45 – 59 | D19: 1 | F19: 1 | H19: 2
A20: 8 | B20: 00 – 15 | D20: 1 | I20: 1
B21: 15 – 30 | D21: 1 | H21: 2
B22: 30 – 45 | D22: 1 | H22: 1 | P22: 1 | T22: 1
A23: 9 | B23: 45 – 59 | H23: 3 | J23: 1 | T23: 1 | X23: 1 | Z23: 1
A24: Lieu : | B24: =B1 -> St Pierre Franchissement du Borne Dessy | K24: Date : | L24: =L1 -> 16 juin 2020
A25: Nom des personnes participant au comptage : | I25: =I2 -> Stéphane Moutard-Martin / La Fabrique à Biclou
A26: Météo : | C26: =C3 -> frais 13°C
A27: Remarques : | C27: =C4 -> Faire colonnes VELO puis VAE
A28: Principe d'utilisation : pour chaque intervalle de temps, marquer une croix par personne comptée dans la colonne la décrivant; si enfant marquer E
A29: Il y a donc une seule croix par personne comptée | AA29: Lieu :
C30: =C10 -> De Rte Gorges du Borne vers | K30: =K10 -> De Avenue des Digues vers | S30: =S10 -> De Dessy vers | AC30: TOTAL | AD30: Nombre de VAE dans le total | AE30: Nombre de femmes dans le total | AF30: Nombre de VAE chez les femmes | AG30: Cycles sur rte de Dessy | AH30: Cycles sur rte des Digues
C31: =C11 -> Av des Digues | G31: =G11 -> Dessy | K31: =K11 -> Dessy | O31: =O11 -> Rte Gorges du Borne | S31: =S11 -> Rte Gorges du Borne | W31: =W11 -> Av des Digues
C32: H | E32: F | G32: H | I32: F | K32: H | M32: F | O32: H | Q32: F | S32: H | U32: F | W32: H | Y32: F
A33: Période | C33: VAE | D33: vélo | E33: VAE | F33: vélo | G33: VAE | H33: vélo | I33: VAE | J33: vélo | K33: VAE | L33: vélo | M33: VAE | N33: vélo | O33: VAE | P33: vélo | Q33: VAE | R33: vélo | S33: VAE | T33: vélo | U33: VAE | V33: vélo | W33: VAE | X33: vélo | Y33: VAE | Z33: vélo | AA33: Période
A34: 6:30 à 7:00 | C34: =SUM(C14:C15) -> 0 | D34: =SUM(D14:D15) -> 0 | E34: =SUM(E14:E15) -> 0 | F34: =SUM(F14:F15) -> 0 | G34: =SUM(G14:G15) -> 0 | H34: =SUM(H14:H15) -> 0 | I34: =SUM(I14:I15) -> 0 | J34: =SUM(J14:J15) -> 0 | ... Z34: =SUM(Z14:Z15) -> 0 | AA34: =A34 -> 6:30 à 7:00 | AC34: =SUM(C34:Z34) -> 0 | AD34: =C34+E34+G34+I34+K34+M34+O34+Q34+S34+U34+W34+Y34 -> 0 | AE34: =E34+F34+I34+J34+M34+N34+Q34+R34+U34+V34+Y34+Z34 -> 0 | AF34: =E34+I34+M34+Q34+U34+Y34 -> 0 | AG34: =SUM(G34:N34)+SUM(S34:Z34) -> 0 | AH34: =SUM(C34:F34)+SUM(W34:Z34)+SUM(K34:R34) -> 0
A35: 7:00 à 8:00 | C35: =SUM(C16:C19) -> 0 | D35: =SUM(D16:D19) -> 1 | E35: =SUM(E16:E19) -> 0 | F35: =SUM(F16:F19) -> 1 | G35: =SUM(G16:G19) -> 0 | H35: =SUM(H16:H19) -> 4 | I35: =SUM(I16:I19) -> 0 | J35: =SUM(J16:J19) -> 0 | ... Z35: =SUM(Z16:Z19) -> 1 | AA35: =A35 -> 7:00 à 8:00 | AC35: =SUM(C35:Z35) -> 8 | AD35: =C35+E35+G35+I35+K35+M35+O35+Q35+S35+U35+W35+Y35 -> 0 | AE35: =E35+F35+I35+J35+M35+N35+Q35+R35+U35+V35+Y35+Z35 -> 2 | AF35: =E35+I35+M35+Q35+U35+Y35 -> 0 | AG35: =SUM(G35:N35)+SUM(S35:Z35) -> 6 | AH35: =SUM(C35:F35)+SUM(W35:Z35)+SUM(K35:R35) -> 3
A36: 7:30 à 8:30 | C36: =SUM(C18:C21) -> 0 | D36: =SUM(D18:D21) -> 3 | E36: =SUM(E18:E21) -> 0 | F36: =SUM(F18:F21) -> 1 | G36: =SUM(G18:G21) -> 0 | H36: =SUM(H18:H21) -> 6 | I36: =SUM(I18:I21) -> 1 | J36: =SUM(J18:J21) -> 0 | ... Z36: =SUM(Z18:Z21) -> 1 | AA36: =A36 -> 7:30 à 8:30 | AC36: =SUM(C36:Z36) -> 12 | AD36: =C36+E36+G36+I36+K36+M36+O36+Q36+S36+U36+W36+Y36 -> 1 | AE36: =E36+F36+I36+J36+M36+N36+Q36+R36+U36+V36+Y36+Z36 -> 3 | AF36: =E36+I36+M36+Q36+U36+Y36 -> 1 | AG36: =SUM(G36:N36)+SUM(S36:Z36) -> 8 | AH36: =SUM(C36:F36)+SUM(W36:Z36)+SUM(K36:R36) -> 5
A37: 8:00 à 9:00 | C37: =SUM(C20:C23) -> 0 | D37: =SUM(D20:D23) -> 3 | E37: =SUM(E20:E23) -> 0 | F37: =SUM(F20:F23) -> 0 | G37: =SUM(G20:G23) -> 0 | H37: =SUM(H20:H23) -> 6 | I37: =SUM(I20:I23) -> 1 | J37: =SUM(J20:J23) -> 1 | ... Z37: =SUM(Z20:Z23) -> 1 | AA37: =A37 -> 8:00 à 9:00 | AC37: =SUM(C37:Z37) -> 16 | AD37: =C37+E37+G37+I37+K37+M37+O37+Q37+S37+U37+W37+Y37 -> 1 | AE37: =E37+F37+I37+J37+M37+N37+Q37+R37+U37+V37+Y37+Z37 -> 3 | AF37: =E37+I37+M37+Q37+U37+Y37 -> 1 | AG37: =SUM(G37:N37)+SUM(S37:Z37) -> 12 | AH37: =SUM(C37:F37)+SUM(W37:Z37)+SUM(K37:R37) -> 6
A38: TOTAL | C38: =SUM(C14:C23) -> 0 | D38: =SUM(D14:D23) -> 4 | E38: =SUM(E14:E23) -> 0 | F38: =SUM(F14:F23) -> 1 | G38: =SUM(G14:G23) -> 0 | H38: =SUM(H14:H23) -> 10 | I38: =SUM(I14:I23) -> 1 | J38: =SUM(J14:J23) -> 1 | ... Z38: =SUM(Z14:Z23) -> 2 | AA38: TOTAL | AC38: =SUM(C38:Z38) -> 24 | AD38: =AD34+AD35+AD37 -> 1 | AE38: =AE34+AE35+AE37 -> 5 | AF38: =AF34+AF35+AF37 -> 1 | AG38: =AG34+AG35+AG37 -> 18 | AH38: =AH34+AH35+AH37 -> 9
AA39: =IF($AC$37=MAX($AC$34:$AC$37),AA37,IF($AC$36=MAX($AC$34:$AC$37),AA36,IF($AC$35=MAX($AC$34:$AC$37),AA35,IF($AC$34=MAX($AC$34:$AC$37),AA34,AA37)))) -> 8:00 à 9:00 | AC39: =IF($AC$37=MAX($AC$34:$AC$37),AC37,IF($AC$36=MAX($AC$34:$AC$37),AC36,IF($AC$35=MAX($AC$34:$AC$37),AC35,IF($AC$34=MAX($AC$34:$AC$37),AC34,AC37)))) -> 16 | AD39: =IF($AC$37=MAX($AC$34:$AC$37),AD37,IF($AC$36=MAX($AC$34:$AC$37),AD36,IF($AC$35=MAX($AC$34:$AC$37),AD35,IF($AC$34=MAX($AC$34:$AC$37),AD34,AD37)))) -> 1 | AE39: =IF($AC$37=MAX($AC$34:$AC$37),AE37,IF($AC$36=MAX($AC$34:$AC$37),AE36,IF($AC$35=MAX($AC$34:$AC$37),AE35,IF($AC$34=MAX($AC$34:$AC$37),AE34,AE37)))) -> 3 | AF39: =IF($AC$37=MAX($AC$34:$AC$37),AF37,IF($AC$36=MAX($AC$34:$AC$37),AF36,IF($AC$35=MAX($AC$34:$AC$37),AF35,IF($AC$34=MAX($AC$34:$AC$37),AF34,AF37)))) -> 1 | AG39: =IF($AC$37=MAX($AC$34:$AC$37),AG37,IF($AC$36=MAX($AC$34:$AC$37),AG36,IF($AC$35=MAX($AC$34:$AC$37),AG35,IF($AC$34=MAX($AC$34:$AC$37),AG34,AG37)))) -> 12 | AH39: =IF($AC$37=MAX($AC$34:$AC$37),AH37,IF($AC$36=MAX($AC$34:$AC$37),AH36,IF($AC$35=MAX($AC$34:$AC$37),AH35,IF($AC$34=MAX($AC$34:$AC$37),AH34,AH37)))) -> 6
AC40: TOTAL | AD40: Part des VAE dans le total | AE40: Part des femmes dans le total | AF40: Part des VAE chez les femmes | AG40: =AG30 -> Cycles sur rte de Dessy | AH40: =AH30 -> Cycles sur rte des Digues
AA43: Période
...

Sheet BO BORNE TUCINGE
A1: Lieu : | B1: Bonneville Franchissement du Borne Tucinge
A2: Nom des personnes participant au comptage : | G2: Annick
A3: Météo :
A4: Remarques :
A5: Principe d'utilisation pour chaque intervalle de temps,
A6: Marquer une croix vélo ou VAE dans la colonne H ou F. Sauf si 'enfant' marquer E ou 'modes nouveaux de déplacement' (trotinette, skate, ets) marquer Z
A7: Il y a donc un seul marquage par personne comptée
C8: Pont du Borne
C9: Depuis Bonneville | G9: Depuis St Pierre
C10: H | E10: F | G10: H | I10: F
A11: Heure | B11: Minute | C11: VAE | D11: vélo | E11: VAE | F11: vélo | G11: VAE | H11: vélo | I11: VAE | J11: vélo
A12: 6 | B12: 30 – 45 | H12: 1
B13: 45 - 59 | H13: 1
A14: 7 | B14: 00 – 15 | D14: 1 | H14: 1
B15: 15 – 30
B16: 30 – 45 | D16: 1
B17: 45 – 59 | J17: 3
A18: 8 | B18: 00 – 15 | D18: 1 | H18: 1
B19: 15 – 30 | D19: 1 | F19: 1 | J19: 3
B20: 30 – 45 | D20: 1 | F20: 1 | J20: 1
A21: 9 | B21: 45 – 59 | D21: 4 | F21: 3 | H21: 4
A23: Lieu : | B23: =B1 -> Bonneville Franchissement du Borne Tucinge
A24: Nom des personnes participant au comptage :
A25: Météo : | C25: =C3 -> 0
A26: Remarques : | C26: =C4 -> 0
A27: Principe d'utilisation : pour chaque intervalle de temps, marquer une croix par personne comptée dans la colonne la décrivant; si enfant marquer E
A28: Il y a donc une seule croix par personne comptée
C30: =C8 -> Pont du Borne | M30: TOTAL | N30: Nombre de VAE dans le total | O30: Nombre de femmes dans le total | P30: Nombre de VAE chez les femmes | Q30: Cycles en direction de Bonneville | R30: Remarque
C31: =C9 -> Depuis Bonneville | G31: =G9 -> Depuis St Pierre
C32: H | E32: F | G32: H | I32: F
A33: Période | C33: VAE | D33: vélo | E33: VAE | F33: vélo | G33: VAE | H33: vélo | I33: VAE | J33: vélo | K33: Période
A34: 6:30 à 7:00 | C34: =SUM(C12:C13) -> 0 | D34: =SUM(D12:D13) -> 0 | E34: =SUM(E12:E13) -> 0 | F34: =SUM(F12:F13) -> 0 | G34: =SUM(G12:G13) -> 0 | H34: =SUM(H12:H13) -> 2 | I34: =SUM(I12:I13) -> 0 | J34: =SUM(J12:J13) -> 0 | K34: =A34 -> 6:30 à 7:00 | M34: =SUM(C34:J34) -> 2 | N34: =C34+E34+G34+I34 -> 0 | O34: =E34+F34+I34+J34 -> 0 | P34: =E34+I34 -> 0 | Q34: =SUM(G34:J34) -> 2
A35: 7:00 à 8:00 | C35: =SUM(C14:C17) -> 0 | D35: =SUM(D14:D17) -> 2 | E35: =SUM(E14:E17) -> 0 | F35: =SUM(F14:F17) -> 0 | G35: =SUM(G14:G17) -> 0 | H35: =SUM(H14:H17) -> 1 | I35: =SUM(I14:I17) -> 0 | J35: =SUM(J14:J17) -> 3 | K35: =A35 -> 7:00 à 8:00 | M35: =SUM(C35:J35) -> 6 | N35: =C35+E35+G35+I35 -> 0 | O35: =E35+F35+I35+J35 -> 3 | P35: =E35+I35 -> 0 | Q35: =SUM(G35:J35) -> 4 | R35: 2 enfants + 3 trotinnettes
A36: 7:30 à 8:30 | C36: =SUM(C16:C19) -> 0 | D36: =SUM(D16:D19) -> 3 | E36: =SUM(E16:E19) -> 0 | F36: =SUM(F16:F19) -> 1 | G36: =SUM(G16:G19) -> 0 | H36: =SUM(H16:H19) -> 1 | I36: =SUM(I16:I19) -> 0 | J36: =SUM(J16:J19) -> 6 | K36: =A36 -> 7:30 à 8:30 | M36: =SUM(C36:J36) -> 11 | N36: =C36+E36+G36+I36 -> 0 | O36: =E36+F36+I36+J36 -> 7 | P36: =E36+I36 -> 0 | Q36: =SUM(G36:J36) -> 7
A37: 8:00 à 9:00 | C37: =SUM(C18:C21) -> 0 | D37: =SUM(D18:D21) -> 7 | E37: =SUM(E18:E21) -> 0 | F37: =SUM(F18:F21) -> 5 | G37: =SUM(G18:G21) -> 0 | H37: =SUM(H18:H21) -> 5 | I37: =SUM(I18:I21) -> 0 | J37: =SUM(J18:J21) -> 4 | K37: =A37 -> 8:00 à 9:00 | M37: =SUM(C37:J37) -> 21 | N37: =C37+E37+G37+I37 -> 0 | O37: =E37+F37+I37+J37 -> 9 | P37: =E37+I37 -> 0 | Q37: =SUM(G37:J37) -> 9 | R37: Mardi jour de marché peut expliquer le pic de fréquance de 8 à 9
A38: TOTAL | C38: =SUM(C12:C21) -> 0 | D38: =SUM(D12:D21) -> 9 | E38: =SUM(E12:E21) -> 0 | F38: =SUM(F12:F21) -> 5 | G38: =SUM(G12:G21) -> 0 | H38: =SUM(H12:H21) -> 8 | I38: =SUM(I12:I21) -> 0 | J38: =SUM(J12:J21) -> 7 | K38: TOTAL | M38: =SUM(C38:J38) -> 29 | N38: =N37+N35+N34 -> 0 | O38: =O37+O35+O34 -> 12 | P38: =P37+P35+P34 -> 0 | Q38: =Q37+Q35+Q34 -> 15 | R38: Beaucoup plus de piétons que de vélos
K39: =IF($M$37=MAX($M$34:$M$37),K37,IF($M$36=MAX($M$34:$M$37),K36,IF($M$35=MAX($M$34:$M$37),K35,IF($M$34=MAX($M$34:$M$37),K34,K37)))) -> 8:00 à 9:00 | M39: =IF($M$37=MAX($M$34:$M$37),M37,IF($M$36=MAX($M$34:$M$37),M36,IF($M$35=MAX($M$34:$M$37),M35,IF($M$34=MAX($M$34:$M$37),M34,M37)))) -> 21 | N39: =IF($M$37=MAX($M$34:$M$37),N37,IF($M$36=MAX($M$34:$M$37),N36,IF($M$35=MAX($M$34:$M$37),N35,IF($M$34=MAX($M$34:$M$37),N34,N37)))) -> 0 | O39: =IF($M$37=MAX($M$34:$M$37),O37,IF($M$36=MAX($M$34:$M$37),O36,IF($M$35=MAX($M$34:$M$37),O35,IF($M$34=MAX($M$34:$M$37),O34,O37)))) -> 9 | P39: =IF($M$37=MAX($M$34:$M$37),P37,IF($M$36=MAX($M$34:$M$37),P36,IF($M$35=MAX($M$34:$M$37),P35,IF($M$34=MAX($M$34:$M$37),P34,P37)))) -> 0 | Q39: =IF($M$37=MAX($M$34:$M$37),Q37,IF($M$36=MAX($M$34:$M$37),Q36,IF($M$35=MAX($M$34:$M$37),Q35,IF($M$34=MAX($M$34:$M$37),Q34,Q37)))) -> 9
M40: TOTAL | N40: Part des VAE dans le total | O40: Part des femmes dans le total | P40: Part des VAE chez les femmes | Q40: =Q30 -> Cycles en direction de Bonneville | R40: Remarque
K43: Période
K44: =K34 -> 6:30 à 7:00 | N44: =IF(N34=0,0,N34/M34) -> 0 | O44: =IF(O34=0,0,O34/M34) -> 0 | P44: =IF(P34=0,0,P34/N34) -> 0 | Q44: =IF(Q34=0,0,Q34/M34) -> 1
...

Sheet ST PI BORNE RD1203
B1: St Pierre Pont sur le Borne Principal - RD 1203 | X1: Date : | Y1: 16 juin 2020
A2: Nom des personnes participant au comptage : | L2: René Suard côté La Roche | T2: Christine Suard côté Bonneville
A3: Météo :
A4: Remarques :
A5: Principe d'utilisation pour chaque intervalle de temps,
A6: Marquer une croix vélo ou VAE dans la colonne H ou F. Sauf si 'enfant' marquer E ou 'modes nouveaux de déplacement' (trotinette, skate, ets) marquer Z
A7: Il y a donc un seul marquage par personne comptée
C8: De S Stade vers | W8: De B Bonneville vers | AQ8: De P Prison vers
C9: B Bonneville | G9: P Prison | K9: T Tucinges | O9: R La Roche | S9: D Digues | W9: P Prison | AA9: T Tucinges | AE9: R La Roche | AI9: D Digues | AM9: S Stade | AQ9: T Tucinges | AU9: R La Roche | AY9: D Digues | BC9: S Stade | BG9: B Bonneville
C10: H | E10: F | G10: H | I10: F | K10: H | M10: F | O10: H | Q10: F | S10: H | U10: F | W10: H | Y10: F | AA10: H | AC10: F | AE10: H | AG10: F | AI10: H | AK10: F | AM10: H | AO10: F | AQ10: H | AS10: F | AU10: H | AW10: F | AY10: H | BA10: F | BC10: H | BE10: F | BG10: H | BI10: F
A11: Heure | B11: Minute | C11: VAE | D11: vélo | E11: VAE | F11: vélo | G11: VAE | H11: vélo | I11: VAE | J11: vélo | K11: VAE | L11: vélo | M11: VAE | N11: vélo | O11: VAE | P11: vélo | Q11: VAE | R11: vélo | S11: VAE | T11: vélo | U11: VAE | V11: vélo | W11: VAE | X11: vélo | Y11: VAE | Z11: vélo | AA11: VAE | AB11: vélo | AC11: VAE | AD11: vélo | AE11: VAE | AF11: vélo | AG11: VAE | AH11: vélo | AI11: VAE | AJ11: vélo | AK11: VAE | AL11: vélo | AM11: VAE | AN11: vélo | AO11: VAE | AP11: vélo | AQ11: VAE | AR11: vélo | AS11: VAE | AT11: vélo | AU11: VAE | AV11: vélo | AW11: VAE | AX11: vélo | AY11: VAE | AZ11: vélo | BA11: VAE | BB11: vélo | BC11: VAE | BD11: vélo | BE11: VAE | BF11: vélo | BG11: VAE | BH11: vélo | BI11: VAE | BJ11: vélo
A12: 6 | B12: 30 – 45
B13: 45 - 59 | H13: 1
A14: 7 | B14: 00 – 15
B15: 15 – 30 | AA15: 1 | AB15: 1 | AF15: 1
B16: 30 – 45 | X16: 1
B17: 45 – 59
A18: 8 | B18: 00 – 15 | BB18: 1
B19: 15 – 30 | AJ19: 1
B20: 30 – 45
A21: 9 | B21: 45 – 59 | K21: 3 | AF21: 1
C22: De T Toisinges vers | W22: De R La Roche vers | AQ22: De D Digues vers
C23: R La Roche | G23: D Digues | K23: S Stade | O23: B Bonneville | S23: P Prison | W23: D Digues | AA23: S Stade | AE23: B Bonneville | AI23: P Prison | AM23: T Tucinges | AQ23: S Stade | AU23: B Bonneville | AY23: P Prison | BC23: T Tucinges | BG23: R La Roche
C24: H | E24: F | G24: H | I24: F | K24: H | M24: F | O24: H | Q24: F | S24: H | U24: F | W24: H | Y24: F | AA24: H | AC24: F | AE24: H | AG24: F | AI24: H | AK24: F | AM24: H | AO24: F | AQ24: H | AS24: F | AU24: H | AW24: F | AY24: H | BA24: F | BC24: H | BE24: F | BG24: H | BI24: F
A25: Heure | B25: Minute | C25: VAE | D25: vélo | E25: VAE | F25: vélo | G25: VAE | H25: vélo | I25: VAE | J25: vélo | K25: VAE | L25: vélo | M25: VAE | N25: vélo | O25: VAE | P25: vélo | Q25: VAE | R25: vélo | S25: VAE | T25: vélo | U25: VAE | V25: vélo | W25: VAE | X25: vélo | Y25: VAE | Z25: vélo | AA25: VAE | AB25: vélo | AC25: VAE | AD25: vélo | AE25: VAE | AF25: vélo | AG25: VAE | AH25: vélo | AI25: VAE | AJ25: vélo | AK25: VAE | AL25: vélo | AM25: VAE | AN25: vélo | AO25: VAE | AP25: vélo | AQ25: VAE | AR25: vélo | AS25: VAE | AT25: vélo | AU25: VAE | AV25: vélo | AW25: VAE | AX25: vélo | AY25: VAE | AZ25: vélo | BA25: VAE | BB25: vélo | BC25: VAE | BD25: vélo | BE25: VAE | BF25: vélo | BG25: VAE | BH25: vélo | BI25: VAE | BJ25: vélo
A26: 6 | B26: 30 – 45 | P26: 1
B27: 45 - 59
A28: 7 | B28: 00 – 15
B29: 15 – 30 | AH29: 1
B30: 30 – 45 | AT30: 1
B31: 45 – 59 | AG31: 1 | AW31: 1
A32: 8 | B32: 00 – 15 | AH32: 1 | AX32: 1
B33: 15 – 30 | H33: 1 | BF33: 1 | BH33: 1
B34: 30 – 45 | AV34: 1 | AW34: 1 | AX34: 1 | BB34: 1
A35: 9 | B35: 45 – 59 | H35: 1 | BB35: 2
A36: 9 | B36: 00 – 15
B37: 15 – 30
A39: Lieu : | B39: =B1 -> St Pierre Pont sur le Borne Principal - RD 1203 | W39: Date : | X39: =AG1 -> 0 | BK39: Lieu : | BL39: =B39 -> St Pierre Pont sur le Borne Principal - RD 1203 | BQ39: Date : | BS39: =Y1
A40: Nom des personnes participant au comptage : | L40: =L2 -> René Suard côté La Roche | T40: =T2 -> Christine Suard côté Bonneville | BK40: Nom des personnes participant au comptage : | BP40: =L2 -> René Suard côté La Roche | BT40: =T2 -> Christine Suard côté Bonneville
A41: Météo : | C41: =C3 -> 0 | BK41: Météo : | BM41: =C41 -> 0
...

Sheet AM CORIANDE
A1: Lieu : | B1: Amancy Giratoire de la Coriandre- RD903 et 1203 | M1: Date : | N1: mardi 16 juin 2020
A2: Nom des personnes participant au comptage : | G2: Yannick ROGUET
A3: Météo : | C3: Beau temps, mais frais | G3: P piéton | I3: NE PLUS FAIRE CE CARREFOUR LES ANNEES PROCHAINES
A4: Remarques : | C4: Pour la destintation des cyclistes, se référer au SCAN de la grille utilisée sur le terrain
A5: Méthodologie : | C5: Pour chaque intervalle de temps, marquer une seule croix par personne comptée
C6: Si c'est enfant, remplacer la croix par E, une trottinette T, un piéton P, etc.
C7: Indiquer aussi la lettre correspondant à la sortie : A-ANNECY / B-BIGAILLE / C-COLLEGE / I-INTERMARCHE / V-VETO / Z-ZA
C9: D'Intermarché | G9: de ZA | K9: de Bigaille | O9: d'Annecy | S9: de Véto | W9: de Collège
C10: H | E10: F | G10: H | I10: F | K10: H | M10: F | O10: H | Q10: F | S10: H | U10: F | W10: H | Y10: F
A11: Heure | B11: Minute | C11: VAE | D11: vélo | E11: VAE | F11: vélo | G11: VAE | H11: vélo | I11: VAE | J11: vélo | K11: VAE | L11: vélo | M11: VAE | N11: vélo | O11: VAE | P11: vélo | Q11: VAE | R11: vélo | S11: VAE | T11: vélo | U11: VAE | V11: vélo | W11: VAE | X11: vélo | Y11: VAE | Z11: vélo
A12: 6 | B12: 30 – 44'59
B13: 45 – 59'59 | W13: ZP
A14: 7 | B14: 00 – 14'59 | W14: CP
B15: 15 – 29'59 | G15: 1
B16: 30 – 44'59 | D16: 1
B17: 45 – 59'59
A18: 8 | B18: 00 – 14'59 | G18: CP
B19: 15 – 29'59
B20: 30 – 44'59 | I20: 2CP
A21: 9 | B21: 45 – 59'59 | P21: 1 | W21: 1
A22: 9 | B22: 00 – 14'59
B23: 15 – 29'59
A25: Lieu : | B25: =B1 -> Amancy Giratoire de la Coriandre- RD903 et 1203 | M25: Date : | N25: =N1 -> mardi 16 juin 2020 | AA25: Lieu : | AB25: =B25 -> Amancy Giratoire de la Coriandre- RD903 et 1203 | AG25: Date : | AH25: =N25 -> mardi 16 juin 2020
A26: Nom des personnes participant au comptage : | G26: =G2 -> Yannick ROGUET | AA26: Nom des personnes participant au comptage : | AE26: =G26 -> Yannick ROGUET
A27: Météo : | C27: =C3 -> Beau temps, mais frais | AA27: Météo : | AC27: =C27 -> Beau temps, mais frais
A28: Remarques : | C28: =C4 -> Pour la destintation des cyclistes, se référer au SCAN de la grille utilisée sur le terrain | AA28: Remarques : | AC28: =C28 -> Pour la destintation des cyclistes, se référer au SCAN de la grille utilisée sur le terrain
AC32: TOTAL | AD32: Part des VAE dans le total | AE32: Part des femmes dans le total | AF32: Part des VAE chez les femmes
C33: =C9 -> D'Intermarché | G33: =G9 -> de ZA | K33: =K9 -> de Bigaille | O33: =O9 -> d'Annecy | S33: =S9 -> de Véto | W33: =W9 -> de Collège
C34: H | E34: F | G34: H | I34: F | K34: H | M34: F | O34: H | Q34: F | S34: H | U34: F | W34: H | Y34: F
A35: Période | C35: VAE | D35: vélo | E35: VAE | F35: vélo | G35: VAE | H35: vélo | I35: VAE | J35: vélo | K35: VAE | L35: vélo | M35: VAE | N35: vélo | O35: VAE | P35: vélo | Q35: VAE | R35: vélo | S35: VAE | T35: vélo | U35: VAE | V35: vélo | W35: VAE | X35: vélo | Y35: VAE | Z35: vélo | AA35: Période
