Workbook

Sheet LA_RO_BIOCOOP
A1: Lieu : | B1: La Roche Face Biocoop | O1: Date :
A2: Nom des personnes participant au comptage :
A3: Météo : | P3: Remarques :
A5: PRINCIPE D’UTILISATION : pour chaque intervalle de temps, comptabiliser VAE/vélo dans la colonne H/F
A6: Rajouter aussi en bas de la feuille si déplacement vélo sur trottoir et/ou si enfant
A7: Comptabiliser en bas de la grille si 2 roues hors vélo qui ne sont pas cochés dans la grille (trottinette, skate, ets)
C9: De La Gare (Fg St Bernard) vers | O9: Du Pont du Foron vers | AA9: Du Rd Point La Poste vers
C10: Rd Pt Poste | G10: Rue Perrine | K10: Pont du Foron | O10: Rue Perrine | S10: Rd Pt Poste | W10: La Gare | AA10: Rue Perrine | AE10: Pont du Foron | AI10: La Gare
C11: H | E11: F | G11: H | I11: F | K11: H | M11: F | O11: H | Q11: F | S11: H | U11: F | W11: H | Y11: F | AA11: H | AC11: F | AE11: H | AG11: F | AI11: H | AK11: F
A12: Heure | B12: Minute | C12: VAE | D12: vélo | E12: VAE | F12: vélo | G12: VAE | H12: vélo | I12: VAE | J12: vélo | K12: VAE | L12: vélo | M12: VAE | N12: vélo | O12: VAE | P12: vélo | Q12: VAE | R12: vélo | S12: VAE | T12: vélo | U12: VAE | V12: vélo | W12: VAE | X12: vélo | Y12: VAE | Z12: vélo | AA12: VAE | AB12: vélo | AC12: VAE | AD12: vélo | AE12: VAE | AF12: vélo | AG12: VAE | AH12: vélo | AI12: VAE | AJ12: vélo | AK12: VAE | AL12: vélo
A13: 6 | B13: 30 – 45 | X13: 1 | Y13: 1 | AK13: 1 | AL13: 1
B14: 45 - 59 | S14: 1 | T14: 1 | U14: 1
A15: 7 | B15: 00 – 15 | J15: 1 | AI15: 1
B16: 15 – 30 | H16: 1 | T16: 1 | X16: 1 | Y16: 1 | AF16: 1 | AJ16: 1
B17: 30 – 45 | D17: 1 | F17: 1 | T17: 3 | W17: 1 | X17: 1
B18: 45 – 59 | D18: 1 | E18: 1 | I18: 1 | S18: 1 | X18: 4 | Y18: 1 | Z18: 1 | AF18: 1 | AI18: 2 | AJ18: 1
A19: 8 | B19: 00 – 15 | K19: 1 | L19: 3 | S19: 1 | U19: 1 | V19: 1 | Y19: 1
B20: 15 – 30 | K20: 1 | M20: 1 | S20: 1 | W20: 2 | X20: 1 | Y20: 1 | AI20: 1
B21: 30 – 45 | D21: 1 | I21: 1 | T21: 1 | U21: 1
A22: 9 | B22: 45 – 59 | I22: 1 | L22: 1 | M22: 1
A24: Vélo sur trottoir | F24: 12 | I24: 5 de gareà rue Perrine, en fait 4 en contre-sens | U24: Vélo Spécial (Cargo/Carriole…)
A25: Enfant | F25: 6 | U25: 2 roues hors vélo (trottinette, skate...) | AF25: 20 - 6 comptés avec vélos - 14 sur trottoir non comptés
C35: =C9 -> De La Gare (Fg St Bernard) vers | O35: =O9 -> Du Pont du Foron vers | AA35: =AA9 -> Du Rd Point La Poste vers | AO35: TOTAL | AP35: Nombre de VAE dans le total | AQ35: Nombre de femmes dans le total | AR35: Nombre de VAE chez les femmes | AS35: Cycles direc La Gare
C36: =C10 -> Rd Pt Poste | G36: =G10 -> Rue Perrine | K36: =K10 -> Pont du Foron | O36: =O10 -> Rue Perrine | S36: =S10 -> Rd Pt Poste | W36: =W10 -> La Gare | AA36: =AA10 -> Rue Perrine | AE36: =AE10 -> Pont du Foron | AI36: =AI10 -> La Gare
C37: H | E37: F | G37: H | I37: F | K37: H | M37: F | O37: H | Q37: F | S37: H | U37: F | W37: H | Y37: F | AA37: H | AC37: F | AE37: H | AG37: F | AI37: H | AK37: F
A38: Période | C38: VAE | D38: vélo | E38: VAE | F38: vélo | G38: VAE | H38: vélo | I38: VAE | J38: vélo | K38: VAE | L38: vélo | M38: VAE | N38: vélo | O38: VAE | P38: vélo | Q38: VAE | R38: vélo | S38: VAE | T38: vélo | U38: VAE | V38: vélo | W38: VAE | X38: vélo | Y38: VAE | Z38: vélo | AA38: VAE | AB38: vélo | AC38: VAE | AD38: vélo | AE38: VAE | AF38: vélo | AG38: VAE | AH38: vélo | AI38: VAE | AJ38: vélo | AK38: VAE | AL38: vélo | AM38: Période
A39: 6:30 à 7:00 | C39: =SUM(C13:C14) -> 0 | D39: =SUM(D13:D14) -> 0 | E39: =SUM(E13:E14) -> 0 | F39: =SUM(F13:F14) -> 0 | G39: =SUM(G13:G14) -> 0 | H39: =SUM(H13:H14) -> 0 | I39: =SUM(I13:I14) -> 0 | J39: =SUM(J13:J14) -> 0 | ... AL39: =SUM(AL13:AL14) -> 1 | AM39: =A39 -> 6:30 à 7:00 | AO39: =SUM(C39:AL39) -> 7 | AP39: =C39+E39+G39+I39+K39+M39+O39+Q39+S39+U39+W39+Y39+AA39+AC39+AE39+AG39+AI39+AK39 -> 4 | AQ39: =E39+F39+I39+J39+M39+N39+Q39+R39+U39+V39+Y39+Z39+AC39+AD39+AG39+AH39+AK39+AL39 -> 4 | AR39: =E39+I39+M39+Q39+U39+Y39+AC39+AG39+AK39 -> 3 | AS39: =SUM(C39:N39)+SUM(W39:Z39)+SUM(AI39:AL39) -> 4
A40: 7:00 à 7:30 | C40: =SUM(C15:C16) -> 0 | D40: =SUM(D15:D16) -> 0 | E40: =SUM(E15:E16) -> 0 | F40: =SUM(F15:F16) -> 0 | G40: =SUM(G15:G16) -> 0 | H40: =SUM(H15:H16) -> 1 | I40: =SUM(I15:I16) -> 0 | J40: =SUM(J15:J16) -> 1 | ... AL40: =SUM(AL15:AL16) -> 0 | AM40: =A40 -> 7:00 à 7:30 | AO40: =SUM(C40:AL40) -> 8 | AP40: =C40+E40+G40+I40+K40+M40+O40+Q40+S40+U40+W40+Y40+AA40+AC40+AE40+AG40+AI40+AK40 -> 2 | AQ40: =E40+F40+I40+J40+M40+N40+Q40+R40+U40+V40+Y40+Z40+AC40+AD40+AG40+AH40+AK40+AL40 -> 2 | AR40: =E40+I40+M40+Q40+U40+Y40+AC40+AG40+AK40 -> 1 | AS40: =SUM(C40:N40)+SUM(W40:Z40)+SUM(AI40:AL40) -> 6
A41: 7:30 à 8:00 | C41: =SUM(C17:C18) -> 0 | D41: =SUM(D17:D18) -> 2 | E41: =SUM(E17:E18) -> 1 | F41: =SUM(F17:F18) -> 1 | G41: =SUM(G17:G18) -> 0 | H41: =SUM(H17:H18) -> 0 | I41: =SUM(I17:I18) -> 1 | J41: =SUM(J17:J18) -> 0 | ... AL41: =SUM(AL17:AL18) -> 0 | AM41: =A41 -> 7:30 à 8:00 | AO41: =SUM(C41:AL41) -> 21 | AP41: =C41+E41+G41+I41+K41+M41+O41+Q41+S41+U41+W41+Y41+AA41+AC41+AE41+AG41+AI41+AK41 -> 7 | AQ41: =E41+F41+I41+J41+M41+N41+Q41+R41+U41+V41+Y41+Z41+AC41+AD41+AG41+AH41+AK41+AL41 -> 5 | AR41: =E41+I41+M41+Q41+U41+Y41+AC41+AG41+AK41 -> 3 | AS41: =SUM(C41:N41)+SUM(W41:Z41)+SUM(AI41:AL41) -> 16
A42: 8:00 à 8:30 | C42: =SUM(C19:C20) -> 0 | D42: =SUM(D19:D20) -> 0 | E42: =SUM(E19:E20) -> 0 | F42: =SUM(F19:F20) -> 0 | G42: =SUM(G19:G20) -> 0 | H42: =SUM(H19:H20) -> 0 | I42: =SUM(I19:I20) -> 0 | J42: =SUM(J19:J20) -> 0 | ... AL42: =SUM(AL19:AL20) -> 0 | AM42: =A42 -> 8:00 à 8:30 | AO42: =SUM(C42:AL42) -> 16 | AP42: =C42+E42+G42+I42+K42+M42+O42+Q42+S42+U42+W42+Y42+AA42+AC42+AE42+AG42+AI42+AK42 -> 11 | AQ42: =E42+F42+I42+J42+M42+N42+Q42+R42+U42+V42+Y42+Z42+AC42+AD42+AG42+AH42+AK42+AL42 -> 5 | AR42: =E42+I42+M42+Q42+U42+Y42+AC42+AG42+AK42 -> 4 | AS42: =SUM(C42:N42)+SUM(W42:Z42)+SUM(AI42:AL42) -> 12
A43: 8:30 à 9:00 | C43: =SUM(C21:C22) -> 0 | D43: =SUM(D21:D22) -> 1 | E43: =SUM(E21:E22) -> 0 | F43: =SUM(F21:F22) -> 0 | G43: =SUM(G21:G22) -> 0 | H43: =SUM(H21:H22) -> 0 | I43: =SUM(I21:I22) -> 2 | J43: =SUM(J21:J22) -> 0 | ... AL43: =SUM(AL21:AL22) -> 0 | AM43: =A43 -> 8:30 à 9:00 | AO43: =SUM(C43:AL43) -> 7 | AP43: =C43+E43+G43+I43+K43+M43+O43+Q43+S43+U43+W43+Y43+AA43+AC43+AE43+AG43+AI43+AK43 -> 4 | AQ43: =E43+F43+I43+J43+M43+N43+Q43+R43+U43+V43+Y43+Z43+AC43+AD43+AG43+AH43+AK43+AL43 -> 4 | AR43: =E43+I43+M43+Q43+U43+Y43+AC43+AG43+AK43 -> 4 | AS43: =SUM(C43:N43)+SUM(W43:Z43)+SUM(AI43:AL43) -> 5
A44: TOTAL | C44: =SUM(C13:C22) -> 0 | D44: =SUM(D13:D22) -> 3 | E44: =SUM(E13:E22) -> 1 | F44: =SUM(F13:F22) -> 1 | G44: =SUM(G13:G22) -> 0 | H44: =SUM(H13:H22) -> 1 | I44: =SUM(I13:I22) -> 3 | J44: =SUM(J13:J22) -> 1 | ... AL44: =SUM(AL13:AL22) -> 1 | AM44: TOTAL | AO44: =SUM(C44:AL44) -> 59 | AP44: =C44+E44+G44+I44+K44+M44+O44+Q44+S44+U44+W44+Y44+AA44+AC44+AE44+AG44+AI44+AK44 -> 28 | AQ44: =E44+F44+I44+J44+M44+N44+Q44+R44+U44+V44+Y44+Z44+AC44+AD44+AG44+AH44+AK44+AL44 -> 20 | AR44: =E44+I44+M44+Q44+U44+Y44+AC44+AG44+AK44 -> 15 | AS44: =SUM(C44:N44)+SUM(W44:Z44)+SUM(AI44:AL44) -> 43
AM45: =IF($AO$42=MAX($AO$39:$AO$43),AM42,IF($AO$41=MAX($AO$39:$AO$43),AM41,IF($AO$40=MAX($AO$39:$AO$43),AM40,IF($AN$39=MAX($AO$39:$AO$43),AM39,IF($AO$43=MAX($AO$39:$AO$43),AM43))))) -> 7:30 à 8:00 | AO45: =IF($AO$42=MAX($AO$39:$AO$43),AO42,IF($AO$41=MAX($AO$39:$AO$43),AO41,IF($AO$40=MAX($AO$39:$AO$43),AO40,IF($AN$39=MAX($AO$39:$AO$43),AO39,IF($AO$43=MAX($AO$39:$AO$43),AO43))))) -> 21 | AP45: =IF($AO$42=MAX($AO$39:$AO$43),AP42,IF($AO$41=MAX($AO$39:$AO$43),AP41,IF($AO$40=MAX($AO$39:$AO$43),AP40,IF($AN$39=MAX($AO$39:$AO$43),AP39,IF($AO$43=MAX($AO$39:$AO$43),AP43))))) -> 7 | AQ45: =IF($AO$42=MAX($AO$39:$AO$43),AQ42,IF($AO$41=MAX($AO$39:$AO$43),AQ41,IF($AO$40=MAX($AO$39:$AO$43),AQ40,IF($AN$39=MAX($AO$39:$AO$43),AQ39,IF($AO$43=MAX($AO$39:$AO$43),AQ43))))) -> 5 | AR45: =IF($AO$42=MAX($AO$39:$AO$43),AR42,IF($AO$41=MAX($AO$39:$AO$43),AR41,IF($AO$40=MAX($AO$39:$AO$43),AR40,IF($AN$39=MAX($AO$39:$AO$43),AR39,IF($AO$43=MAX($AO$39:$AO$43),AR43))))) -> 3 | AS45: =IF($AO$42=MAX($AO$39:$AO$43),AS42,IF($AO$41=MAX($AO$39:$AO$43),AS41,IF($AO$40=MAX($AO$39:$AO$43),AS40,IF($AN$39=MAX($AO$39:$AO$43),AS39,IF($AO$43=MAX($AO$39:$AO$43),AS43))))) -> 16
AO46: TOTAL | AP46: Part des VAE dans le total | AQ46: Part des femmes dans le total | AR46: Part des VAE chez les femmes | AS46: =AS35 -> Cycles direc La Gare
AM49: Période
AM50: =AM39 -> 6:30 à 7:00 | AP50: =IF(AP39=0,0,AP39/AO39) -> 0.57142857 | AQ50: =IF(AQ39=0,0,AQ39/AO39) -> 0.57142857 | AR50: =IF(AR39=0,0,AR39/AP39) -> 0.75 | AS50: =IF(AS39=0,0,AS39/AO39) -> 0.57142857
AM51: =AM40 -> 7:00 à 7:30 | AP51: =IF(AP40=0,0,AP40/AO40) -> 0.25 | AQ51: =IF(AQ41=0,0,AQ41/AO41) -> 0.23809524 | AR51: =IF(AR41=0,0,AR41/AP41) -> 0.42857143 | AS51: =IF(AS41=0,0,AS41/AO41) -> 0.76190476
AM52: =AM41 -> 7:30 à 8:00 | AP52: =IF(AP41=0,0,AP41/AO41) -> 0.33333333 | AQ52: =IF(AQ41=0,0,AQ41/AO41) -> 0.23809524 | AR52: =IF(AR41=0,0,AR41/AP41) -> 0.42857143 | AS52: =IF(AS41=0,0,AS41/AO41) -> 0.76190476
AM53: =AM42 -> 8:00 à 8:30 | AP53: =IF(AP42=0,0,AP42/AO42) -> 0.6875 | AQ53: =IF(AQ42=0,0,AQ42/AO42) -> 0.3125 | AR53: =IF(AR42=0,0,AR42/AP42) -> 0.36363636 | AS53: =IF(AS42=0,0,AS42/AO42) -> 0.75
AM54: =AM43 -> 8:30 à 9:00 | AP54: =IF(AP43=0,0,AP43/AO43) -> 0.57142857 | AQ54: =IF(AQ43=0,0,AQ43/AO43) -> 0.57142857 | AR54: =IF(AR43=0,0,AR43/AP43) -> 1 | AS54: =IF(AS43=0,0,AS43/AO43) -> 0.71428571
...

Sheet LA_RO_POSTE
B1: Rond Point La Poste | M1: Date : | O1: Date : | X1: 2022 J Jaures masqué
A2: Nom des personnes participant au comptage :
A3: Météo : | N3: Remarques : | P3: Remarques :
A5: PRINCIPE D’UTILISATION : pour chaque intervalle de temps, comptabiliser VAE/vélo dans la colonne H/F
A6: Rajouter aussi en bas de la feuille si déplacement vélo sur trottoir et/ou si enfant
A7: Comptabiliser en bas de la grille si 2 roues hors vélo qui ne sont pas cochés dans la grille (trottinette, skate, ets) | BC7: J jaurèsregroupé ici
C9: De Bonneville vers | S9: DeGrenette (contre-sens) | AE9: De La Base(contre-sens) | AQ9: De Office Tourisme vers | BG9: De MJC vers
C10: Grenette | G10: Office Tourisme | K10: La Base | O10: Parking | S10: Office Tourisme | W10: La Base | AA10: Bonneville | AE10: Bonneville | AI10: Office Tourisme | AM10: Place Grenette | AQ10: La Base | AU10: Bonneville | AY10: Grenette | BC10: De J Jaurès | BG10: Office tourisme | BK10: Grenette | BO10: Bonneville | BS10: Pompiers
C11: H | E11: F | G11: H | I11: F | K11: H | M11: F | O11: H | Q11: F | S11: H | U11: F | W11: H | Y11: F | AA11: H | AC11: F | AE11: H | AG11: F | AI11: H | AK11: F | AM11: H | AO11: F | AQ11: H | AS11: F | AU11: H | AW11: F | AY11: H | BA11: F | BC11: H | BE11: F | BG11: H | BI11: F | BK11: H | BM11: F | BO11: H | BQ11: F | BS11: H | BU11: F
A12: Heure | B12: Minute | C12: VAE | D12: vélo | E12: VAE | F12: vélo | G12: VAE | H12: vélo | I12: VAE | J12: vélo | K12: VAE | L12: vélo | M12: VAE | N12: vélo | O12: VAE | P12: vélo | Q12: VAE | R12: vélo | S12: VAE | T12: vélo | U12: VAE | V12: vélo | W12: VAE | X12: vélo | Y12: VAE | Z12: vélo | AA12: VAE | AB12: vélo | AC12: VAE | AD12: vélo | AE12: VAE | AF12: vélo | AG12: VAE | AH12: vélo | AI12: VAE | AJ12: vélo | AK12: VAE | AL12: vélo | AM12: VAE | AN12: vélo | AO12: VAE | AP12: vélo | AQ12: VAE | AR12: vélo | AS12: VAE | AT12: vélo | AU12: VAE | AV12: vélo | AW12: VAE | AX12: vélo | AY12: VAE | AZ12: vélo | BA12: VAE | BB12: vélo | BC12: VAE | BD12: vélo | BE12: VAE | BF12: vélo | BG12: VAE | BH12: vélo | BI12: VAE | BJ12: vélo | BK12: VAE | BL12: vélo | BM12: VAE | BN12: vélo | BO12: VAE | BP12: vélo | BQ12: VAE | BR12: vélo | BS12: VAE | BT12: vélo | BU12: VAE | BV12: vélo
A13: 6 | B13: 30 – 45 | J13: 1 | AV13: 1
B14: 45 - 59 | AR14: 1 | AS14: 1 | AY14: 1 | AZ14: 1
A15: 7 | B15: 00 – 15 | K15: 1
B16: 15 – 30 | H16: 1
B17: 30 – 45 | H17: 2 | AR17: 1 | BC17: 1
B18: 45 – 59 | D18: 1 | G18: 2 | L18: 3 | AF18: 1 | AQ18: 1 | AR18: 1 | AV18: 1 | AW18: 1 | AX18: 1
A19: 8 | B19: 00 – 15 | C19: 1 | L19: 1
B20: 15 – 30 | AQ20: 1 | AS20: 1
B21: 30 – 45 | AV21: 1 | BA21: 1 | BE21: 1
B22: 45 – 59 | BC22: 1
A23: 9 | B23: 00 – 15
B24: 15 – 30
A26: Vélo sur trottoir | G26: 2 | AD26: Vélo Spécial (Cargo/Carriole…)
A27: Enfant | G27: 4 écoliers | AD27: 2 roues hors vélo (trottinette, skate...) | AT27: 15
BC31: J jaurèsregroupé ici
C33: =C9 -> De Bonneville vers | S33: =S9 -> DeGrenette (contre-sens) | AE33: =AE9 -> De La Base(contre-sens) | AQ33: =AQ9 -> De Office Tourisme vers | BG33: =BG9 -> De MJC vers | BY33: TOTAL | BZ33: Nombre de VAE dans le total | CA33: Nombre de femmes dans le total | CB33: Nombre de VAE chez les femmes | CC33: Cycle sur rte Bonneville | CD33: Remarque
C34: =C10 -> Grenette | G34: =G10 -> Office Tourisme | K34: =K10 -> La Base | O34: =O10 -> Parking | S34: =S10 -> Office Tourisme | W34: =W10 -> La Base | AA34: =AA10 -> Bonneville | AE34: =AE10 -> Bonneville | AI34: =AI10 -> Office Tourisme | AM34: =AM10 -> Place Grenette | AQ34: =AQ10 -> La Base | AU34: =AU10 -> Bonneville | AY34: =AY10 -> Grenette | BC34: De J Jaurès | BG34: =BG10 -> Office tourisme | BK34: =BK10 -> Grenette | BO34: =BO10 -> Bonneville | BS34: =BS10 -> Pompiers
C35: H | E35: F | G35: H | I35: F | K35: H | M35: F | O35: H | Q35: F | S35: H | U35: F | W35: H | Y35: F | AA35: H | AC35: F | AE35: H | AG35: F | AI35: H | AK35: F | AM35: H | AO35: F | AQ35: H | AS35: F | AU35: H | AW35: F | AY35: H | BA35: F | BC35: H | BE35: F | BG35: H | BI35: F | BK35: H | BM35: F | BO35: H | BQ35: F | BS35: H | BU35: F
A36: Période | C36: VAE | D36: vélo | E36: VAE | F36: vélo | G36: VAE | H36: vélo | I36: VAE | J36: vélo | K36: VAE | L36: vélo | M36: VAE | N36: vélo | O36: VAE | P36: vélo | Q36: VAE | R36: vélo | S36: VAE | T36: vélo | U36: VAE | V36: vélo | W36: VAE | X36: vélo | Y36: VAE | Z36: vélo | AA36: VAE | AB36: vélo | AC36: VAE | AD36: vélo | AE36: VAE | AF36: vélo | AG36: VAE | AH36: vélo | AI36: VAE | AJ36: vélo | AK36: VAE | AL36: vélo | AM36: VAE | AN36: vélo | AO36: VAE | AP36: vélo | AQ36: VAE | AR36: vélo | AS36: VAE | AT36: vélo | AU36: VAE | AV36: vélo | AW36: VAE | AX36: vélo | AY36: VAE | AZ36: vélo | BA36: VAE | BB36: vélo | BC36: VAE | BD36: vélo | BE36: VAE | BF36: vélo | BG36: VAE | BH36: vélo | BI36: VAE | BJ36: vélo | BK36: VAE | BL36: vélo | BM36: VAE | BN36: vélo | BO36: VAE | BP36: vélo | BQ36: VAE | BR36: vélo | BS36: VAE | BT36: vélo | BU36: VAE | BV36: vélo | BW36: Période
A37: 6:30 à 7:00 | C37: =SUM(C13:C14) -> 0 | D37: =SUM(D13:D14) -> 0 | E37: =SUM(E13:E14) -> 0 | F37: =SUM(F13:F14) -> 0 | G37: =SUM(G13:G14) -> 0 | H37: =SUM(H13:H14) -> 0 | I37: =SUM(I13:I14) -> 0 | J37: =SUM(J13:J14) -> 1 | ... BV37: =SUM(BV13:BV14) -> 0 | BW37: =A37 -> 6:30 à 7:00 | BY37: =SUM(C37:BV37) -> 6 | BZ37: =C37+E37+G37+I37+K37+M37+O37+Q37+S37+U37+W37+Y37+AA37+AC37+AE37+AG37+AI37+AK37+AM37+AO37+AQ37+AS37+AU37+AW37+AY37+BA37+BG37+BI37+BK37+BM37+BO37+BQ37+BS37+BU37 -> 2 | CA37: =E37+F37+I37+J37+M37+N37+Q37+R37+U37+V37+Y37+Z37+AC37+AD37+AG37+AH37+AK37+AL37+AO37+AP37+AS37+AT37+AW37+AX37+BA37+BB37+BI37+BJ37+BM37+BN37+BQ37+BR37+BU37+BV37 -> 2 | CB37: =E37+I37+M37+Q37+U37+Y37+AC37+AG37+AK37+AO37+AS37+AW37+BA37+BI37+BM37+BQ37+BU37 -> 1 | CC37: =SUM(C37:R37)+SUM(AA37:AH37)+SUM(AU37:AX37)+SUM(BO37:BR37) -> 2
A38: 7:00 à 7:30 | C38: =SUM(C15:C16) -> 0 | D38: =SUM(D15:D16) -> 0 | E38: =SUM(E15:E16) -> 0 | F38: =SUM(F15:F16) -> 0 | G38: =SUM(G15:G16) -> 0 | H38: =SUM(H15:H16) -> 1 | I38: =SUM(I15:I16) -> 0 | J38: =SUM(J15:J16) -> 0 | ... BV38: =SUM(BV15:BV16) -> 0 | BW38: =A38 -> 7:00 à 7:30 | BY38: =SUM(C38:BV38) -> 2 | BZ38: =C38+E38+G38+I38+K38+M38+O38+Q38+S38+U38+W38+Y38+AA38+AC38+AE38+AG38+AI38+AK38+AM38+AO38+AQ38+AS38+AU38+AW38+AY38+BA38+BG38+BI38+BK38+BM38+BO38+BQ38+BS38+BU38 -> 1 | CA38: =E38+F38+I38+J38+M38+N38+Q38+R38+U38+V38+Y38+Z38+AC38+AD38+AG38+AH38+AK38+AL38+AO38+AP38+AS38+AT38+AW38+AX38+BA38+BB38+BI38+BJ38+BM38+BN38+BQ38+BR38+BU38+BV38 -> 0 | CB38: =E38+I38+M38+Q38+U38+Y38+AC38+AG38+AK38+AO38+AS38+AW38+BA38+BI38+BM38+BQ38+BU38 -> 0 | CC38: =SUM(C38:R38)+SUM(AA38:AH38)+SUM(AU38:AX38)+SUM(BO38:BR38) -> 2
A39: 7:30 à 8:00 | C39: =SUM(C17:C18) -> 0 | D39: =SUM(D17:D18) -> 1 | E39: =SUM(E17:E18) -> 0 | F39: =SUM(F17:F18) -> 0 | G39: =SUM(G17:G18) -> 2 | H39: =SUM(H17:H18) -> 2 | I39: =SUM(I17:I18) -> 0 | J39: =SUM(J17:J18) -> 0 | ... BV39: =SUM(BV17:BV18) -> 0 | BW39: =A39 -> 7:30 à 8:00 | BY39: =SUM(C39:BV39) -> 16 | BZ39: =C39+E39+G39+I39+K39+M39+O39+Q39+S39+U39+W39+Y39+AA39+AC39+AE39+AG39+AI39+AK39+AM39+AO39+AQ39+AS39+AU39+AW39+AY39+BA39+BG39+BI39+BK39+BM39+BO39+BQ39+BS39+BU39 -> 4 | CA39: =E39+F39+I39+J39+M39+N39+Q39+R39+U39+V39+Y39+Z39+AC39+AD39+AG39+AH39+AK39+AL39+AO39+AP39+AS39+AT39+AW39+AX39+BA39+BB39+BI39+BJ39+BM39+BN39+BQ39+BR39+BU39+BV39 -> 2 | CB39: =E39+I39+M39+Q39+U39+Y39+AC39+AG39+AK39+AO39+AS39+AW39+BA39+BI39+BM39+BQ39+BU39 -> 1 | CC39: =SUM(C39:R39)+SUM(AA39:AH39)+SUM(AU39:AX39)+SUM(BO39:BR39) -> 12
A40: 8:00 à 8:30 | C40: =SUM(C19:C20) -> 1 | D40: =SUM(D19:D20) -> 0 | E40: =SUM(E19:E20) -> 0 | F40: =SUM(F19:F20) -> 0 | G40: =SUM(G19:G20) -> 0 | H40: =SUM(H19:H20) -> 0 | I40: =SUM(I19:I20) -> 0 | J40: =SUM(J19:J20) -> 0 | ... BV40: =SUM(BV19:BV20) -> 0 | BW40: =A40 -> 8:00 à 8:30 | BY40: =SUM(C40:BV40) -> 4 | BZ40: =C40+E40+G40+I40+K40+M40+O40+Q40+S40+U40+W40+Y40+AA40+AC40+AE40+AG40+AI40+AK40+AM40+AO40+AQ40+AS40+AU40+AW40+AY40+BA40+BG40+BI40+BK40+BM40+BO40+BQ40+BS40+BU40 -> 3 | CA40: =E40+F40+I40+J40+M40+N40+Q40+R40+U40+V40+Y40+Z40+AC40+AD40+AG40+AH40+AK40+AL40+AO40+AP40+AS40+AT40+AW40+AX40+BA40+BB40+BI40+BJ40+BM40+BN40+BQ40+BR40+BU40+BV40 -> 1 | CB40: =E40+I40+M40+Q40+U40+Y40+AC40+AG40+AK40+AO40+AS40+AW40+BA40+BI40+BM40+BQ40+BU40 -> 1 | CC40: =SUM(C40:R40)+SUM(AA40:AH40)+SUM(AU40:AX40)+SUM(BO40:BR40) -> 2
A41: 8:30 à 9:00 | C41: =SUM(C21:C22) -> 0 | D41: =SUM(D21:D22) -> 0 | E41: =SUM(E21:E22) -> 0 | F41: =SUM(F21:F22) -> 0 | G41: =SUM(G21:G22) -> 0 | H41: =SUM(H21:H22) -> 0 | I41: =SUM(I21:I22) -> 0 | J41: =SUM(J21:J22) -> 0 | ... BV41: =SUM(BV21:BV22) -> 0 | BW41: =A41 -> 8:30 à 9:00 | BY41: =SUM(C41:BV41) -> 4 | BZ41: =C41+E41+G41+I41+K41+M41+O41+Q41+S41+U41+W41+Y41+AA41+AC41+AE41+AG41+AI41+AK41+AM41+AO41+AQ41+AS41+AU41+AW41+AY41+BA41+BG41+BI41+BK41+BM41+BO41+BQ41+BS41+BU41 -> 1 | CA41: =E41+F41+I41+J41+M41+N41+Q41+R41+U41+V41+Y41+Z41+AC41+AD41+AG41+AH41+AK41+AL41+AO41+AP41+AS41+AT41+AW41+AX41+BA41+BB41+BI41+BJ41+BM41+BN41+BQ41+BR41+BU41+BV41 -> 1 | CB41: =E41+I41+M41+Q41+U41+Y41+AC41+AG41+AK41+AO41+AS41+AW41+BA41+BI41+BM41+BQ41+BU41 -> 1 | CC41: =SUM(C41:R41)+SUM(AA41:AH41)+SUM(AU41:AX41)+SUM(BO41:BR41) -> 1
A42: TOTAL | C42: =SUM(C13:C24) -> 1 | D42: =SUM(D13:D24) -> 1 | E42: =SUM(E13:E24) -> 0 | F42: =SUM(F13:F24) -> 0 | G42: =SUM(G13:G24) -> 2 | H42: =SUM(H13:H24) -> 3 | I42: =SUM(I13:I24) -> 0 | J42: =SUM(J13:J24) -> 1 | ... BV42: =SUM(BV13:BV24) -> 0 | BW42: TOTAL | BY42: =SUM(C42:BV42) -> 32 | BZ42: =C42+E42+G42+I42+K42+M42+O42+Q42+S42+U42+W42+Y42+AA42+AC42+AE42+AG42+AI42+AK42+AM42+AO42+AQ42+AS42+AU42+AW42+AY42+BA42+BG42+BI42+BK42+BM42+BO42+BQ42+BS42+BU42 -> 11 | CA42: =E42+F42+I42+J42+M42+N42+Q42+R42+U42+V42+Y42+Z42+AC42+AD42+AG42+AH42+AK42+AL42+AO42+AP42+AS42+AT42+AW42+AX42+BA42+BB42+BI42+BJ42+BM42+BN42+BQ42+BR42+BU42+BV42 -> 6 | CB42: =E42+I42+M42+Q42+U42+Y42+AC42+AG42+AK42+AO42+AS42+AW42+BA42+BI42+BM42+BQ42+BU42 -> 4 | CC42: =SUM(C42:R42)+SUM(AA42:AH42)+SUM(AU42:AX42)+SUM(BO42:BR42) -> 19
BW43: =IF($BY$37=MAX($BY$37:$BY$41),BW37,IF($BY$38=MAX($BY$37:$BY$41),BW38,IF($BY$39=MAX($BY$37:$BY$41),BW39,IF($BY$40=MAX($BY$37:$BY$41),BW40,IF($BY$41=MAX($BY$37:$BY$41),BW41))))) -> 7:30 à 8:00 | BY43: =IF($BY$37=MAX($BY$37:$BY$41),BY37,IF($BY$38=MAX($BY$37:$BY$41),BY38,IF($BY$39=MAX($BY$37:$BY$41),BY39,IF($BY$40=MAX($BY$37:$BY$41),BY40,IF($BY$41=MAX($BY$37:$BY$41),BY41))))) -> 16 | BZ43: =IF($BY$37=MAX($BY$37:$BY$41),BZ37,IF($BY$38=MAX($BY$37:$BY$41),BZ38,IF($BY$39=MAX($BY$37:$BY$41),BZ39,IF($BY$40=MAX($BY$37:$BY$41),BZ40,IF($BY$41=MAX($BY$37:$BY$41),BZ41))))) -> 4 | CA43: =IF($BY$37=MAX($BY$37:$BY$41),CA37,IF($BY$38=MAX($BY$37:$BY$41),CA38,IF($BY$39=MAX($BY$37:$BY$41),CA39,IF($BY$40=MAX($BY$37:$BY$41),CA40,IF($BY$41=MAX($BY$37:$BY$41),CA41))))) -> 2 | CB43: =IF($BY$37=MAX($BY$37:$BY$41),CB37,IF($BY$38=MAX($BY$37:$BY$41),CB38,IF($BY$39=MAX($BY$37:$BY$41),CB39,IF($BY$40=MAX($BY$37:$BY$41),CB40,IF($BY$41=MAX($BY$37:$BY$41),CB41))))) -> 1 | CC43: =IF($BY$37=MAX($BY$37:$BY$41),CC37,IF($BY$38=MAX($BY$37:$BY$41),CC38,IF($BY$39=MAX($BY$37:$BY$41),CC39,IF($BY$40=MAX($BY$37:$BY$41),CC40,IF($BY$41=MAX($BY$37:$BY$41),CC41))))) -> 12
BY44: TOTAL | BZ44: Part des VAE dans le total | CA44: Part des femmes dans le total | CB44: Part des VAE chez les femmes | CD44: Remarque
BW47: Période
G48: =SUM(G42:J42,AQ42:BB42) -> 21 | BW48: =BW37 -> 6:30 à 7:00 | BZ48: =IF(BZ37=0,0,BZ37/BY37) -> 0.33333333 | CA48: =IF(CA37=0,0,CA37/BY37) -> 0.33333333 | CB48: =IF(CB37=0,0,CB37/BZ37) -> 0.5 | CC48: =IF(CC37=0,0,CC37/BY37) -> 0.33333333
BW49: =BW38 -> 7:00 à 7:30 | BZ49: =IF(BZ39=0,0,BZ39/BY39) -> 0.25 | CA49: =IF(CA39=0,0,CA39/BY39) -> 0.125 | CB49: =IF(CB39=0,0,CB39/BZ39) -> 0.25 | CC49: =IF(CC39=0,0,CC39/BY39) -> 0.75
...

Sheet LA_RO_ENILV
B1: La Roche Rond-Point ENILV - St Renan | O1: Date :
A2: Nom des personnes participant au comptage :
A3: Météo :
A4: Remarques :
A6: PRINCIPE D’UTILISATION : pour chaque intervalle de temps, comptabiliser VAE/vélo dans la colonne H/F
A7: Rajouter aussi en bas de la feuille si déplacement vélo sur trottoir et/ou si enfant
A8: Comptabiliser en bas de la grille si 2 roues hors vélo qui ne sont pas cochés dans la grille (trottinette, skate, ets)
C10: Du centre (La Roche) vers | O10: D'Eteaux av Gambetta vers | AA10: De Av Libération Enilv vers | AM10: De Reignier vers
C11: Av Gambetta Eteaux | G11: Av Libération Enilv | K11: Reignier | O11: Av Libération Enilv | S11: Reignier | W11: La Roche | AA11: Reignier | AE11: La Roche | AI11: Av Gambetta Eteaux | AM11: La Roche | AQ11: Av Gambetta Eteaux | AU11: Av Libération Enilv
C12: H | E12: F | G12: H | I12: F | K12: H | M12: F | O12: H | Q12: F | S12: H | U12: F | W12: H | Y12: F | AA12: H | AC12: F | AE12: H | AG12: F | AI12: H | AK12: F | AM12: H | AO12: F | AQ12: H | AS12: F | AU12: H | AW12: F
A13: H | B13: Minute | C13: VAE | D13: vélo | E13: VAE | F13: vélo | G13: VAE | H13: vélo | I13: VAE | J13: vélo | K13: VAE | L13: vélo | M13: VAE | N13: vélo | O13: VAE | P13: vélo | Q13: VAE | R13: vélo | S13: VAE | T13: vélo | U13: VAE | V13: vélo | W13: VAE | X13: vélo | Y13: VAE | Z13: vélo | AA13: VAE | AB13: vélo | AC13: VAE | AD13: vélo | AE13: VAE | AF13: vélo | AG13: VAE | AH13: vélo | AI13: VAE | AJ13: vélo | AK13: VAE | AL13: vélo | AM13: VAE | AN13: vélo | AO13: VAE | AP13: vélo | AQ13: VAE | AR13: vélo | AS13: VAE | AT13: vélo | AU13: VAE | AV13: vélo | AW13: VAE | AX13: vélo
A14: 6 | B14: 30 – 45
B15: 45 - 59 | T15: 2
A16: 7 | B16: 00 – 15 | K16: 1 | L16: 2
B17: 15 – 30
B18: 30 – 45
B19: 45 – 59 | D19: 3 | L19: 3
A20: 8 | B20: 00 – 15 | K20: 1 | L20: 1 | Y20: 1
B21: 15 – 30 | L21: 2 | N21: 1 | AI21: 1 | AL21: 1
B22: 30 – 45 | N22: 1
A23: 9 | B23: 45 – 59 | F23: 1
A25: Vélo sur trottoir | G25: 4 | V25: Vélo Spécial (Cargo/Carriole…)
A26: Enfant | G26: 1 | V26: 2 roues hors vélo (trottinette, skate...) | AJ26: 4
C34: =C10 -> Du centre (La Roche) vers | O34: =O10 -> D'Eteaux av Gambetta vers | AA34: =AA10 -> De Av Libération Enilv vers | AM34: =AM10 -> De Reignier vers | BA34: TOTAL | BB34: Nombre de VAE dans le total | BC34: Nombre de femmes dans le total | BD34: Nombre de VAE chez les femmes | BE34: Cycles sur route de Reignier | BF34: Remarque
C35: =C11 -> Av Gambetta Eteaux | G35: =G11 -> Av Libération Enilv | K35: =K11 -> Reignier | O35: =O11 -> Av Libération Enilv | S35: =S11 -> Reignier | W35: =W11 -> La Roche | AA35: =AA11 -> Reignier | AE35: =AE11 -> La Roche | AI35: =AI11 -> Av Gambetta Eteaux | AM35: =AM11 -> La Roche | AQ35: =AQ11 -> Av Gambetta Eteaux | AU35: =AU11 -> Av Libération Enilv
C36: H | E36: F | G36: H | I36: F | K36: H | M36: F | O36: H | Q36: F | S36: H | U36: F | W36: H | Y36: F | AA36: H | AC36: F | AE36: H | AG36: F | AI36: H | AK36: F | AM36: H | AO36: F | AQ36: H | AS36: F | AU36: H | AW36: F
A37: Période | C37: VAE | D37: vélo | E37: VAE | F37: vélo | G37: VAE | H37: vélo | I37: VAE | J37: vélo | K37: VAE | L37: vélo | M37: VAE | N37: vélo | O37: VAE | P37: vélo | Q37: VAE | R37: vélo | S37: VAE | T37: vélo | U37: VAE | V37: vélo | W37: VAE | X37: vélo | Y37: VAE | Z37: vélo | AA37: VAE | AB37: vélo | AC37: VAE | AD37: vélo | AE37: VAE | AF37: vélo | AG37: VAE | AH37: vélo | AI37: VAE | AJ37: vélo | AK37: VAE | AL37: vélo | AM37: VAE | AN37: vélo | AO37: VAE | AP37: vélo | AQ37: VAE | AR37: vélo | AS37: VAE | AT37: vélo | AU37: VAE | AV37: vélo | AW37: VAE | AX37: vélo | AY37: Période
A38: 6:30 à 7:00 | C38: =SUM(C14:C15) -> 0 | D38: =SUM(D14:D15) -> 0 | E38: =SUM(E14:E15) -> 0 | F38: =SUM(F14:F15) -> 0 | G38: =SUM(G14:G15) -> 0 | H38: =SUM(H14:H15) -> 0 | I38: =SUM(I14:I15) -> 0 | J38: =SUM(J14:J15) -> 0 | ... AX38: =SUM(AX14:AX15) -> 0 | AY38: =A38 -> 6:30 à 7:00 | BA38: =SUM(C38:AX38) -> 2 | BB38: =C38+E38+G38+I38+K38+M38+O38+Q38+S38+U38+W38+Y38+AA38+AC38+AE38+AG38+AI38+AK38+AM38+AO38+AQ38+AS38+AU38+AW38 -> 0 | BC38: =E38+F38+I38+J38+M38+N38+Q38+R38+U38+V38+Y38+Z38+AC38+AD38+AG38+AH38+AK38+AL38+AO38+AP38+AS38+AT38+AW38+AX38 -> 0 | BD38: =E38+I38+M38+Q38+U38+Y38+AC38+AG38+AK38+AO38+AS38+AW38 -> 0 | BE38: =SUM(K38:N38)+SUM(S38:V38)+SUM(AA38:AD38)+SUM(AM38:AX38) -> 2 | BF38: 34 piétons plus 32 étudiants piétons en direction lycée
A39: 7:00 à 7:30 | C39: =SUM(C16:C17) -> 0 | D39: =SUM(D16:D17) -> 0 | E39: =SUM(E16:E17) -> 0 | F39: =SUM(F16:F17) -> 0 | G39: =SUM(G16:G17) -> 0 | H39: =SUM(H16:H17) -> 0 | I39: =SUM(I16:I17) -> 0 | J39: =SUM(J16:J17) -> 0 | ... AX39: =SUM(AX16:AX17) -> 0 | AY39: =A39 -> 7:00 à 7:30 | BA39: =SUM(C39:AX39) -> 3 | BB39: =C39+E39+G39+I39+K39+M39+O39+Q39+S39+U39+W39+Y39+AA39+AC39+AE39+AG39+AI39+AK39+AM39+AO39+AQ39+AS39+AU39+AW39 -> 1 | BC39: =E39+F39+I39+J39+M39+N39+Q39+R39+U39+V39+Y39+Z39+AC39+AD39+AG39+AH39+AK39+AL39+AO39+AP39+AS39+AT39+AW39+AX39 -> 0 | BD39: =E39+I39+M39+Q39+U39+Y39+AC39+AG39+AK39+AO39+AS39+AW39 -> 0 | BE39: =SUM(K39:N39)+SUM(S39:V39)+SUM(AA39:AD39)+SUM(AM39:AX39) -> 3 | BF39: et seulement 2 écoliers- 2 enfants comptés qui étaient sur le trottoir avec 1 parent
A40: 7:30 à 8:00 | C40: =SUM(C18:C19) -> 0 | D40: =SUM(D18:D19) -> 3 | E40: =SUM(E18:E19) -> 0 | F40: =SUM(F18:F19) -> 0 | G40: =SUM(G18:G19) -> 0 | H40: =SUM(H18:H19) -> 0 | I40: =SUM(I18:I19) -> 0 | J40: =SUM(J18:J19) -> 0 | ... AX40: =SUM(AX18:AX19) -> 0 | AY40: =A40 -> 7:30 à 8:00 | BA40: =SUM(C40:AX40) -> 6 | BB40: =C40+E40+G40+I40+K40+M40+O40+Q40+S40+U40+W40+Y40+AA40+AC40+AE40+AG40+AI40+AK40+AM40+AO40+AQ40+AS40+AU40+AW40 -> 0 | BC40: =E40+F40+I40+J40+M40+N40+Q40+R40+U40+V40+Y40+Z40+AC40+AD40+AG40+AH40+AK40+AL40+AO40+AP40+AS40+AT40+AW40+AX40 -> 0 | BD40: =E40+I40+M40+Q40+U40+Y40+AC40+AG40+AK40+AO40+AS40+AW40 -> 0 | BE40: =SUM(K40:N40)+SUM(S40:V40)+SUM(AA40:AD40)+SUM(AM40:AX40) -> 3 | BF40: et seulement 2 écoliers- 2 enfants comptés qui étaient sur le trottoir avec 1 parent
A41: 8:00 à 8:30 | C41: =SUM(C20:C21) -> 0 | D41: =SUM(D20:D21) -> 0 | E41: =SUM(E20:E21) -> 0 | F41: =SUM(F20:F21) -> 0 | G41: =SUM(G20:G21) -> 0 | H41: =SUM(H20:H21) -> 0 | I41: =SUM(I20:I21) -> 0 | J41: =SUM(J20:J21) -> 0 | ... AX41: =SUM(AX20:AX21) -> 0 | AY41: =A41 -> 8:00 à 8:30 | BA41: =SUM(C41:AX41) -> 8 | BB41: =C41+E41+G41+I41+K41+M41+O41+Q41+S41+U41+W41+Y41+AA41+AC41+AE41+AG41+AI41+AK41+AM41+AO41+AQ41+AS41+AU41+AW41 -> 3 | BC41: =E41+F41+I41+J41+M41+N41+Q41+R41+U41+V41+Y41+Z41+AC41+AD41+AG41+AH41+AK41+AL41+AO41+AP41+AS41+AT41+AW41+AX41 -> 3 | BD41: =E41+I41+M41+Q41+U41+Y41+AC41+AG41+AK41+AO41+AS41+AW41 -> 1 | BE41: =SUM(K41:N41)+SUM(S41:V41)+SUM(AA41:AD41)+SUM(AM41:AX41) -> 5 | BF41: 2 des 3 femmes circulaient sur le trottoir !
A42: 8:30 à 9:00 | C42: =SUM(C21:C23) -> 0 | D42: =SUM(D21:D23) -> 0 | E42: =SUM(E21:E23) -> 0 | F42: =SUM(F21:F23) -> 1 | G42: =SUM(G21:G23) -> 0 | H42: =SUM(H21:H23) -> 0 | I42: =SUM(I21:I23) -> 0 | J42: =SUM(J21:J23) -> 0 | ... AX42: =SUM(AX21:AX23) -> 0 | AY42: =A42 -> 8:30 à 9:00 | BA42: =SUM(C42:AX42) -> 7 | BB42: =C42+E42+G42+I42+K42+M42+O42+Q42+S42+U42+W42+Y42+AA42+AC42+AE42+AG42+AI42+AK42+AM42+AO42+AQ42+AS42+AU42+AW42 -> 1 | BC42: =E42+F42+I42+J42+M42+N42+Q42+R42+U42+V42+Y42+Z42+AC42+AD42+AG42+AH42+AK42+AL42+AO42+AP42+AS42+AT42+AW42+AX42 -> 4 | BD42: =E42+I42+M42+Q42+U42+Y42+AC42+AG42+AK42+AO42+AS42+AW42 -> 0 | BE42: =SUM(K42:N42)+SUM(S42:V42)+SUM(AA42:AD42)+SUM(AM42:AX42) -> 4 | BF42: 3 cyclosportifs
A43: TOTAL | C43: =SUM(C14:C23) -> 0 | D43: =SUM(D14:D23) -> 3 | E43: =SUM(E14:E23) -> 0 | F43: =SUM(F14:F23) -> 1 | G43: =SUM(G14:G23) -> 0 | H43: =SUM(H14:H23) -> 0 | I43: =SUM(I14:I23) -> 0 | J43: =SUM(J14:J23) -> 0 | ... AX43: =SUM(AX14:AX23) -> 0 | AY43: TOTAL | BA43: =SUM(C43:AX43) -> 21 | BB43: =C43+E43+G43+I43+K43+M43+O43+Q43+S43+U43+W43+Y43+AA43+AC43+AE43+AG43+AI43+AK43+AM43+AO43+AQ43+AS43+AU43+AW43 -> 4 | BC43: =E43+F43+I43+J43+M43+N43+Q43+R43+U43+V43+Y43+Z43+AC43+AD43+AG43+AH43+AK43+AL43+AO43+AP43+AS43+AT43+AW43+AX43 -> 5 | BD43: =E43+I43+M43+Q43+U43+Y43+AC43+AG43+AK43+AO43+AS43+AW43 -> 1 | BE43: =SUM(K43:N43)+SUM(S43:V43)+SUM(AA43:AD43)+SUM(AM43:AX43) -> 14
AY44: =IF($BA$38=MAX($BA$38:$BA$42),AY38,IF($BA$39=MAX($BA$38:$BA$42),AY39,IF($BA$40=MAX($BA$38:$BA$42),AY40,IF($BA$41=MAX($BA$38:$BA$42),AY41,IF($BA$42=MAX($BA$38:$BA$42),AY42,AY41))))) -> 8:00 à 8:30 | BA44: =IF($BA$38=MAX($BA$38:$BA$42),BA38,IF($BA$39=MAX($BA$38:$BA$42),BA39,IF($BA$40=MAX($BA$38:$BA$42),BA40,IF($BA$41=MAX($BA$38:$BA$42),BA41,IF($BA$42=MAX($BA$38:$BA$42),BA42,BA41))))) -> 8 | BB44: =IF($BA$38=MAX($BA$38:$BA$42),BB38,IF($BA$39=MAX($BA$38:$BA$42),BB39,IF($BA$40=MAX($BA$38:$BA$42),BB40,IF($BA$41=MAX($BA$38:$BA$42),BB41,IF($BA$42=MAX($BA$38:$BA$42),BB42,BB41))))) -> 3 | BC44: =IF($BA$38=MAX($BA$38:$BA$42),BC38,IF($BA$39=MAX($BA$38:$BA$42),BC39,IF($BA$40=MAX($BA$38:$BA$42),BC40,IF($BA$41=MAX($BA$38:$BA$42),BC41,IF($BA$42=MAX($BA$38:$BA$42),BC42,BC41))))) -> 3 | BD44: =IF($BA$38=MAX($BA$38:$BA$42),BD38,IF($BA$39=MAX($BA$38:$BA$42),BD39,IF($BA$40=MAX($BA$38:$BA$42),BD40,IF($BA$41=MAX($BA$38:$BA$42),BD41,IF($BA$42=MAX($BA$38:$BA$42),BD42,BD41))))) -> 1 | BE44: =IF($BA$38=MAX($BA$38:$BA$42),BE38,IF($BA$39=MAX($BA$38:$BA$42),BE39,IF($BA$40=MAX($BA$38:$BA$42),BE40,IF($BA$41=MAX($BA$38:$BA$42),BE41,IF($BA$42=MAX($BA$38:$BA$42),BE42,BE41))))) -> 5
BA45: TOTAL | BB45: Part des VAE dans le total | BC45: Part des femmes dans le total | BD45: Part des VAE chez les femmes | BE45: =BE34 -> Cycles sur route de Reignier | BF45: Remarque
AY48: Période
AY49: =AY38 -> 6:30 à 7:00 | BB49: =IF(BB38=0,0,BB38/BA38) -> 0 | BC49: =IF(BC38=0,0,BC38/BA38) -> 0 | BD49: =IF(BD38=0,0,BD38/BB38) -> 0 | BE49: =IF(BE38=0,0,BE38/BA38) -> 1
AY50: =AY39 -> 7:00 à 7:30 | BB50: =IF(BB40=0,0,BB40/BA40) -> 0 | BC50: =IF(BC40=0,0,BC40/BA40) -> 0 | BD50: =IF(BD40=0,0,BD40/BB40) -> 0 | BE50: =IF(BE40=0,0,BE40/BA40) -> 0.5
AY51: =AY40 -> 7:30 à 8:00 | BB51: =IF(BB40=0,0,BB40/BA40) -> 0 | BC51: =IF(BC40=0,0,BC40/BA40) -> 0 | BD51: =IF(BD40=0,0,BD40/BB40) -> 0 | BE51: =IF(BE40=0,0,BE40/BA40) -> 0.5
AY52: =AY41 -> 8:00 à 8:30 | BB52: =IF(BB41=0,0,BB41/BA41) -> 0.375 | BC52: =IF(BC41=0,0,BC41/BA41) -> 0.375 | BD52: =IF(BD41=0,0,BD41/BB41) -> 0.33333333 | BE52: =IF(BE41=0,0,BE41/BA41) -> 0.625
...

Sheet LA_RO_SNCF
B1: La Roche Gare/Passage à niveau | O1: Date :
A2: Nom des personnes participant au comptage :
A3: Météo :
A4: Remarques :
A6: PRINCIPE D’UTILISATION : pour chaque intervalle de temps, comptabiliser VAE/vélo dans la colonne H/F
A7: Rajouter aussi en bas de la feuille si déplacement vélo sur trottoir et/ou si enfant
A8: Comptabiliser en bas de la grille si 2 roues hors vélo qui ne sont pas cochés dans la grille (trottinette, skate, ets)
C10: D’Eteaux vers | O10: De av Lucien Rannard vers | AA10: De av J Jaurès vers | AM10: De Gare et av Gare vers
C11: Av L Rannard | G11: Av J Jaurès | K11: Gare/av Gare | O11: Av J Jaurès | S11: Gare/av Gare | W11: Eteaux | AA11: Gare/av Gare | AE11: Eteaux | AI11: Av L Rannard | AM11: Eteaux | AQ11: Av L Rannard | AU11: Av J Jaurès
C12: H | E12: F | G12: H | I12: F | K12: H | M12: F | O12: H | Q12: F | S12: H | U12: F | W12: H | Y12: F | AA12: H | AC12: F | AE12: H | AG12: F | AI12: H | AK12: F | AM12: H | AO12: F | AQ12: H | AS12: F | AU12: H | AW12: F
A13: H | B13: Minute | C13: VAE | D13: vélo | E13: VAE | F13: vélo | G13: VAE | H13: vélo | I13: VAE | J13: vélo | K13: VAE | L13: vélo | M13: VAE | N13: vélo | O13: VAE | P13: vélo | Q13: VAE | R13: vélo | S13: VAE | T13: vélo | U13: VAE | V13: vélo | W13: VAE | X13: vélo | Y13: VAE | Z13: vélo | AA13: VAE | AB13: vélo | AC13: VAE | AD13: vélo | AE13: VAE | AF13: vélo | AG13: VAE | AH13: vélo | AI13: VAE | AJ13: vélo | AK13: VAE | AL13: vélo | AM13: VAE | AN13: vélo | AO13: VAE | AP13: vélo | AQ13: VAE | AR13: vélo | AS13: VAE | AT13: vélo | AU13: VAE | AV13: vélo | AW13: VAE | AX13: vélo
A14: 6 | B14: 30 – 45 | L14: 1 | T14: 1 | AA14: 1 | AC14: 1 | AU14: 1
B15: 45 - 59 | L15: 2 | AN15: 3 | AU15: 1
A16: 7 | B16: 00 – 15 | S16: 1 | AR16: 1 | AW16: 1
B17: 15 – 30 | M17: 1 | N17: 1 | S17: 1 | AF17: 1 | AR17: 1 | AW17: 1
B18: 30 – 45 | H18: 1 | J18: 1 | K18: 1 | T18: 2 | AD18: 1 | AV18: 1
B19: 45 – 59 | D19: 1 | H19: 1 | I19: 1 | V19: 1 | Y19: 1 | AF19: 4 | AH19: 1 | AI19: 1 | AN19: 1 | AR19: 1 | AV19: 1
A20: 8 | B20: 00 – 15 | AA20: 1 | AD20: 1 | AG20: 1 | AV20: 1
B21: 15 – 20 | D21: 1 | AB21: 1 | AC21: 1 | AR21: 1 | AT21: 1 | AV21: 1 | AX21: 1
B22: 30 – 45 | AX22: 1
A23: 9 | B23: 45 – 59 | AU23: 1 | AW23: 1
A25: Vélo sur trottoir | G25: 8 | V25: Vélo Spécial (Cargo/Carriole…) | AK25: 2
A26: Enfant | G26: 6 | V26: 2 roues hors vélo (trottinette, skate...) | AK26: 18
C34: =C10 -> D’Eteaux vers | O34: =O10 -> De av Lucien Rannard vers | AA34: =AA10 -> De av J Jaurès vers | AM34: =AM10 -> De Gare et av Gare vers | BA34: TOTAL | BB34: Nombre de VAE dans le total | BC34: Nombre de femmes dans le total | BD34: Nombre de VAE chez les femmes | BE34: Cycles sur route de Reignier | BF34: Remarque
C35: =C11 -> Av L Rannard | G35: =G11 -> Av J Jaurès | K35: =K11 -> Gare/av Gare | O35: =O11 -> Av J Jaurès | S35: =S11 -> Gare/av Gare | W35: =W11 -> Eteaux | AA35: =AA11 -> Gare/av Gare | AE35: =AE11 -> Eteaux | AI35: =AI11 -> Av L Rannard | AM35: =AM11 -> Eteaux | AQ35: =AQ11 -> Av L Rannard | AU35: =AU11 -> Av J Jaurès
C36: H | E36: F | G36: H | I36: F | K36: H | M36: F | O36: H | Q36: F | S36: H | U36: F | W36: H | Y36: F | AA36: H | AC36: F | AE36: H | AG36: F | AI36: H | AK36: F | AM36: H | AO36: F | AQ36: H | AS36: F | AU36: H | AW36: F
A37: Période | C37: VAE | D37: vélo | E37: VAE | F37: vélo | G37: VAE | H37: vélo | I37: VAE | J37: vélo | K37: VAE | L37: vélo | M37: VAE | N37: vélo | O37: VAE | P37: vélo | Q37: VAE | R37: vélo | S37: VAE | T37: vélo | U37: VAE | V37: vélo | W37: VAE | X37: vélo | Y37: VAE | Z37: vélo | AA37: VAE | AB37: vélo | AC37: VAE | AD37: vélo | AE37: VAE | AF37: vélo | AG37: VAE | AH37: vélo | AI37: VAE | AJ37: vélo | AK37: VAE | AL37: vélo | AM37: VAE | AN37: vélo | AO37: VAE | AP37: vélo | AQ37: VAE | AR37: vélo | AS37: VAE | AT37: vélo | AU37: VAE | AV37: vélo | AW37: VAE | AX37: vélo | AY37: Période
A38: 6:30 à 7:00 | C38: =SUM(C14:C15) -> 0 | D38: =SUM(D14:D15) -> 0 | E38: =SUM(E14:E15) -> 0 | F38: =SUM(F14:F15) -> 0 | G38: =SUM(G14:G15) -> 0 | H38: =SUM(H14:H15) -> 0 | I38: =SUM(I14:I15) -> 0 | J38: =SUM(J14:J15) -> 0 | ... AX38: =SUM(AX14:AX15) -> 0 | AY38: =A38 -> 6:30 à 7:00 | BA38: =SUM(C38:AX38) -> 11 | BB38: =C38+E38+G38+I38+K38+M38+O38+Q38+S38+U38+W38+Y38+AA38+AC38+AE38+AG38+AI38+AK38+AM38+AO38+AQ38+AS38+AU38+AW38 -> 4 | BC38: =E38+F38+I38+J38+M38+N38+Q38+R38+U38+V38+Y38+Z38+AC38+AD38+AG38+AH38+AK38+AL38+AO38+AP38+AS38+AT38+AW38+AX38 -> 1 | BD38: =E38+I38+M38+Q38+U38+Y38+AC38+AG38+AK38+AO38+AS38+AW38 -> 1 | BE38: =SUM(K38:N38)+SUM(S38:V38)+SUM(AA38:AD38)+SUM(AM38:AX38) -> 11
A39: 7:00 à 7:30 | C39: =SUM(C16:C17) -> 0 | D39: =SUM(D16:D17) -> 0 | E39: =SUM(E16:E17) -> 0 | F39: =SUM(F16:F17) -> 0 | G39: =SUM(G16:G17) -> 0 | H39: =SUM(H16:H17) -> 0 | I39: =SUM(I16:I17) -> 0 | J39: =SUM(J16:J17) -> 0 | ... AX39: =SUM(AX16:AX17) -> 0 | AY39: =A39 -> 7:00 à 7:30 | BA39: =SUM(C39:AX39) -> 9 | BB39: =C39+E39+G39+I39+K39+M39+O39+Q39+S39+U39+W39+Y39+AA39+AC39+AE39+AG39+AI39+AK39+AM39+AO39+AQ39+AS39+AU39+AW39 -> 5 | BC39: =E39+F39+I39+J39+M39+N39+Q39+R39+U39+V39+Y39+Z39+AC39+AD39+AG39+AH39+AK39+AL39+AO39+AP39+AS39+AT39+AW39+AX39 -> 4 | BD39: =E39+I39+M39+Q39+U39+Y39+AC39+AG39+AK39+AO39+AS39+AW39 -> 3 | BE39: =SUM(K39:N39)+SUM(S39:V39)+SUM(AA39:AD39)+SUM(AM39:AX39) -> 8
A40: 7:30 à 8:00 | C40: =SUM(C18:C19) -> 0 | D40: =SUM(D18:D19) -> 1 | E40: =SUM(E18:E19) -> 0 | F40: =SUM(F18:F19) -> 0 | G40: =SUM(G18:G19) -> 0 | H40: =SUM(H18:H19) -> 2 | I40: =SUM(I18:I19) -> 1 | J40: =SUM(J18:J19) -> 1 | ... AX40: =SUM(AX18:AX19) -> 0 | AY40: =A40 -> 7:30 à 8:00 | BA40: =SUM(C40:AX40) -> 21 | BB40: =C40+E40+G40+I40+K40+M40+O40+Q40+S40+U40+W40+Y40+AA40+AC40+AE40+AG40+AI40+AK40+AM40+AO40+AQ40+AS40+AU40+AW40 -> 4 | BC40: =E40+F40+I40+J40+M40+N40+Q40+R40+U40+V40+Y40+Z40+AC40+AD40+AG40+AH40+AK40+AL40+AO40+AP40+AS40+AT40+AW40+AX40 -> 6 | BD40: =E40+I40+M40+Q40+U40+Y40+AC40+AG40+AK40+AO40+AS40+AW40 -> 2 | BE40: =SUM(K40:N40)+SUM(S40:V40)+SUM(AA40:AD40)+SUM(AM40:AX40) -> 9
A41: 8:00 à 8:30 | C41: =SUM(C20:C21) -> 0 | D41: =SUM(D20:D21) -> 1 | E41: =SUM(E20:E21) -> 0 | F41: =SUM(F20:F21) -> 0 | G41: =SUM(G20:G21) -> 0 | H41: =SUM(H20:H21) -> 0 | I41: =SUM(I20:I21) -> 0 | J41: =SUM(J20:J21) -> 0 | ... AX41: =SUM(AX20:AX21) -> 1 | AY41: =A41 -> 8:00 à 8:30 | BA41: =SUM(C41:AX41) -> 11 | BB41: =C41+E41+G41+I41+K41+M41+O41+Q41+S41+U41+W41+Y41+AA41+AC41+AE41+AG41+AI41+AK41+AM41+AO41+AQ41+AS41+AU41+AW41 -> 3 | BC41: =E41+F41+I41+J41+M41+N41+Q41+R41+U41+V41+Y41+Z41+AC41+AD41+AG41+AH41+AK41+AL41+AO41+AP41+AS41+AT41+AW41+AX41 -> 5 | BD41: =E41+I41+M41+Q41+U41+Y41+AC41+AG41+AK41+AO41+AS41+AW41 -> 2 | BE41: =SUM(K41:N41)+SUM(S41:V41)+SUM(AA41:AD41)+SUM(AM41:AX41) -> 9
A42: 8:30 à 9:00 | C42: =SUM(C22:C23) -> 0 | D42: =SUM(D22:D23) -> 0 | E42: =SUM(E22:E23) -> 0 | F42: =SUM(F22:F23) -> 0 | G42: =SUM(G22:G23) -> 0 | H42: =SUM(H22:H23) -> 0 | I42: =SUM(I22:I23) -> 0 | J42: =SUM(J22:J23) -> 0 | ... AX42: =SUM(AX22:AX23) -> 1 | AY42: =A42 -> 8:30 à 9:00 | BA42: =SUM(C42:AX42) -> 3 | BB42: =C42+E42+G42+I42+K42+M42+O42+Q42+S42+U42+W42+Y42+AA42+AC42+AE42+AG42+AI42+AK42+AM42+AO42+AQ42+AS42+AU42+AW42 -> 2 | BC42: =E42+F42+I42+J42+M42+N42+Q42+R42+U42+V42+Y42+Z42+AC42+AD42+AG42+AH42+AK42+AL42+AO42+AP42+AS42+AT42+AW42+AX42 -> 2 | BD42: =E42+I42+M42+Q42+U42+Y42+AC42+AG42+AK42+AO42+AS42+AW42 -> 1 | BE42: =SUM(K42:N42)+SUM(S42:V42)+SUM(AA42:AD42)+SUM(AM42:AX42) -> 3
A43: TOTAL | C43: =SUM(C14:C23) -> 0 | D43: =SUM(D14:D23) -> 2 | E43: =SUM(E14:E23) -> 0 | F43: =SUM(F14:F23) -> 0 | G43: =SUM(G14:G23) -> 0 | H43: =SUM(H14:H23) -> 2 | I43: =SUM(I14:I23) -> 1 | J43: =SUM(J14:J23) -> 1 | ... AX43: =SUM(AX14:AX23) -> 2 | AY43: TOTAL | BA43: =SUM(BA38:BA42) -> 55 | BB43: =C43+E43+G43+I43+K43+M43+O43+Q43+S43+U43+W43+Y43+AA43+AC43+AE43+AG43+AI43+AK43+AM43+AO43+AQ43+AS43+AU43+AW43 -> 18 | BC43: =E43+F43+I43+J43+M43+N43+Q43+R43+U43+V43+Y43+Z43+AC43+AD43+AG43+AH43+AK43+AL43+AO43+AP43+AS43+AT43+AW43+AX43 -> 18 | BD43: =E43+I43+M43+Q43+U43+Y43+AC43+AG43+AK43+AO43+AS43+AW43 -> 9 | BE43: =SUM(K43:N43)+SUM(S43:V43)+SUM(AA43:AD43)+SUM(AM43:AX43) -> 40
AY44: =IF($BA$38=MAX($BA$38:$BA$42),AY38,IF($BA$39=MAX($BA$38:$BA$42),AY39,IF($BA$40=MAX($BA$38:$BA$42),AY40,IF($BA$41=MAX($BA$38:$BA$42),AY41,IF($BA$42=MAX($BA$38:$BA$42),AY42,AY41))))) -> 7:30 à 8:00 | BA44: =IF($BA$38=MAX($BA$38:$BA$42),BA38,IF($BA$39=MAX($BA$38:$BA$42),BA39,IF($BA$40=MAX($BA$38:$BA$42),BA40,IF($BA$41=MAX($BA$38:$BA$42),BA41,IF($BA$42=MAX($BA$38:$BA$42),BA42,BA41))))) -> 21 | BB44: =IF($BA$38=MAX($BA$38:$BA$42),BB38,IF($BA$39=MAX($BA$38:$BA$42),BB39,IF($BA$40=MAX($BA$38:$BA$42),BB40,IF($BA$41=MAX($BA$38:$BA$42),BB41,IF($BA$42=MAX($BA$38:$BA$42),BB42,BB41))))) -> 4 | BC44: =IF($BA$38=MAX($BA$38:$BA$42),BC38,IF($BA$39=MAX($BA$38:$BA$42),BC39,IF($BA$40=MAX($BA$38:$BA$42),BC40,IF($BA$41=MAX($BA$38:$BA$42),BC41,IF($BA$42=MAX($BA$38:$BA$42),BC42,BC41))))) -> 6 | BD44: =IF($BA$38=MAX($BA$38:$BA$42),BD38,IF($BA$39=MAX($BA$38:$BA$42),BD39,IF($BA$40=MAX($BA$38:$BA$42),BD40,IF($BA$41=MAX($BA$38:$BA$42),BD41,IF($BA$42=MAX($BA$38:$BA$42),BD42,BD41))))) -> 2 | BE44: =IF($BA$38=MAX($BA$38:$BA$42),BE38,IF($BA$39=MAX($BA$38:$BA$42),BE39,IF($BA$40=MAX($BA$38:$BA$42),BE40,IF($BA$41=MAX($BA$38:$BA$42),BE41,IF($BA$42=MAX($BA$38:$BA$42),BE42,BE41))))) -> 9
BA45: TOTAL | BB45: Part des VAE dans le total | BC45: Part des femmes dans le total | BD45: Part des VAE chez les femmes | BE45: =BE34 -> Cycles sur route de Reignier | BF45: Remarque
AY48: Période
AY49: =AY38 -> 6:30 à 7:00 | BB49: =IF(BB38=0,0,BB38/BA38) -> 0.36363636 | BC49: =IF(BC38=0,0,BC38/BA38) -> 0.090909091 | BD49: =IF(BD38=0,0,BD38/BB38) -> 0.25 | BE49: =IF(BE38=0,0,BE38/BA38) -> 1
AY50: =AY39 -> 7:00 à 7:30 | BB50: =IF(BB40=0,0,BB40/BA40) -> 0.19047619 | BC50: =IF(BC40=0,0,BC40/BA40) -> 0.28571429 | BD50: =IF(BD40=0,0,BD40/BB40) -> 0.5 | BE50: =IF(BE40=0,0,BE40/BA40) -> 0.42857143
AY51: =AY40 -> 7:30 à 8:00 | BB51: =IF(BB40=0,0,BB40/BA40) -> 0.19047619 | BC51: =IF(BC40=0,0,BC40/BA40) -> 0.28571429 | BD51: =IF(BD40=0,0,BD40/BB40) -> 0.5 | BE51: =IF(BE40=0,0,BE40/BA40) -> 0.42857143
AY52: =AY41 -> 8:00 à 8:30 | BB52: =IF(BB41=0,0,BB41/BA41) -> 0.27272727 | BC52: =IF(BC41=0,0,BC41/BA41) -> 0.45454545 | BD52: =IF(BD41=0,0,BD41/BB41) -> 0.66666667 | BE52: =IF(BE41=0,0,BE41/BA41) -> 0.81818182
...

Sheet AMANCY SOUS TERRAIN
B1: Amancy Vozerier Sous terrain | G1: Date :
A2: Nom des personnes participant au comptage :
A3: Météo : | G3: Remarques :
A5: PRINCIPE D’UTILISATION : pour chaque intervalle de temps, comptabiliser VAE/vélo dans la colonne H/F
A6: Rajouter aussi en bas de la feuille si enfant
A7: Comptabiliser en bas de la grille si 2 roues hors vélo qui ne sont pas cochés dans la grille (trottinette, skate, ets)
C9: RN 1203 | K9: Passage souterrain
C10: Direct Bonneville | G10: Direct La Roche | K10: Direct Amancy | O10: Direct Vozerier
C11: H | E11: F | G11: H | I11: F | K11: H | M11: F | O11: H | Q11: F
A12: H | B12: Minute | C12: VAE | D12: vélo | E12: VAE | F12: vélo | G12: VAE | H12: vélo | I12: VAE | J12: vélo | K12: VAE | L12: vélo | M12: VAE | N12: vélo | O12: VAE | P12: vélo | Q12: VAE | R12: vélo
A13: 6 | B13: 30 – 45 | D13: 1 | L13: 1
B14: 45 - 59
A15: 7 | B15: 00 – 15
B16: 15 – 30 | L16: 1 | O16: 1 | P16: 1
B17: 30 – 45 | K17: 1
B18: 45 – 59 | K18: 1 | P18: 1
A19: 8 | B19: 00 – 15
B20: 15 – 30 | L20: 5 | P20: 2
B21: 30 – 45
A22: 9 | B22: 45 – 59
A24: Enfant | K24: Enfant
A25: 2 roues hors vélo (trottinette, skate...) | F25: 3 | K25: 2 roues hors vélo (trottinette, skate...)
C27: =C9 -> RN 1203 | K27: =K9 -> Passage souterrain | U27: TOTAL | V27: Nombre de VAE dans le total | W27: Nombre de femmes dans le total | X27: Nombre de VAE chez les femmes | Z27: Remarque
C28: =C10 -> Direct Bonneville | G28: =G10 -> Direct La Roche | K28: =K10 -> Direct Amancy | O28: =O10 -> Direct Vozerier
C29: H | E29: F | G29: H | I29: F | K29: H | M29: F | O29: H | Q29: F
A30: Période | C30: VAE | D30: vélo | E30: VAE | F30: vélo | G30: VAE | H30: vélo | I30: VAE | J30: vélo | K30: VAE | L30: vélo | M30: VAE | N30: vélo | O30: VAE | P30: vélo | Q30: VAE | R30: vélo | S30: Période
A31: 6:30 à 7:00 | C31: =SUM(C13:C14) -> 0 | D31: =SUM(D13:D14) -> 1 | E31: =SUM(E13:E14) -> 0 | F31: =SUM(F13:F14) -> 0 | G31: =SUM(G13:G14) -> 0 | H31: =SUM(H13:H14) -> 0 | I31: =SUM(I13:I14) -> 0 | J31: =SUM(J13:J14) -> 0 | ... R31: =SUM(R13:R14) -> 0 | S31: =A31 -> 6:30 à 7:00 | U31: =SUM(C31:R31) -> 2 | V31: =C31+E31+G31+I31+K31+M31+O31+Q31 -> 0 | W31: =E31+F31+I31+J31+M31+N31+Q31+R31 -> 0 | X31: =E31+I31 -> 0 | Y31: =SUM(G31:J31) -> 0
A32: 7:00 à 7:30 | C32: =SUM(C15:C16) -> 0 | D32: =SUM(D15:D16) -> 0 | E32: =SUM(E15:E16) -> 0 | F32: =SUM(F15:F16) -> 0 | G32: =SUM(G15:G16) -> 0 | H32: =SUM(H15:H16) -> 0 | I32: =SUM(I15:I16) -> 0 | J32: =SUM(J15:J16) -> 0 | ... R32: =SUM(R15:R16) -> 0 | S32: =A32 -> 7:00 à 7:30 | U32: =SUM(C32:R32) -> 3 | V32: =C32+E32+G32+I32+K32+M32+O32+Q32 -> 1 | W32: =E32+F32+I32+J32+M32+N32+Q32+R32 -> 0 | X32: =E32+I32 -> 0 | Y32: =SUM(G32:J32) -> 0
A33: 7:30 à 8:00 | C33: =SUM(C17:C18) -> 0 | D33: =SUM(D17:D18) -> 0 | E33: =SUM(E17:E18) -> 0 | F33: =SUM(F17:F18) -> 0 | G33: =SUM(G17:G18) -> 0 | H33: =SUM(H17:H18) -> 0 | I33: =SUM(I17:I18) -> 0 | J33: =SUM(J17:J18) -> 0 | ... R33: =SUM(R17:R18) -> 0 | S33: =A33 -> 7:30 à 8:00 | U33: =SUM(C33:R33) -> 3 | V33: =C33+E33+G33+I33+K33+M33+O33+Q33 -> 2 | W33: =E33+F33+I33+J33+M33+N33+Q33+R33 -> 0 | X33: =E33+I33 -> 0 | Y33: =SUM(G33:J33) -> 0
A34: 8:00 à 8:30 | C34: =SUM(C19:C20) -> 0 | D34: =SUM(D19:D20) -> 0 | E34: =SUM(E19:E20) -> 0 | F34: =SUM(F19:F20) -> 0 | G34: =SUM(G19:G20) -> 0 | H34: =SUM(H19:H20) -> 0 | I34: =SUM(I19:I20) -> 0 | J34: =SUM(J19:J20) -> 0 | ... R34: =SUM(R19:R20) -> 0 | S34: =A34 -> 8:00 à 8:30 | U34: =SUM(C34:R34) -> 7 | V34: =C34+E34+G34+I34+K34+M34+O34+Q34 -> 0 | W34: =E34+F34+I34+J34+M34+N34+Q34+R34 -> 0 | X34: =E34+I34 -> 0 | Y34: =SUM(G34:J34) -> 0
A35: 8:30 à 9:00 | C35: =SUM(C21:C22) -> 0 | D35: =SUM(D21:D22) -> 0 | E35: =SUM(E21:E22) -> 0 | F35: =SUM(F21:F22) -> 0 | G35: =SUM(G21:G22) -> 0 | H35: =SUM(H21:H22) -> 0 | I35: =SUM(I21:I22) -> 0 | J35: =SUM(J21:J22) -> 0 | ... R35: =SUM(R21:R22) -> 0 | S35: =A35 -> 8:30 à 9:00 | U35: =SUM(C35:R35) -> 0 | V35: =C35+E35+G35+I35+K35+M35+O35+Q35 -> 0 | W35: =E35+F35+I35+J35+M35+N35+Q35+R35 -> 0 | X35: =E35+I35 -> 0 | Y35: =SUM(G35:J35) -> 0
A36: TOTAL | C36: =SUM(C13:C22) -> 0 | D36: =SUM(D13:D22) -> 1 | E36: =SUM(E13:E22) -> 0 | F36: =SUM(F13:F22) -> 0 | G36: =SUM(G13:G22) -> 0 | H36: =SUM(H13:H22) -> 0 | I36: =SUM(I13:I22) -> 0 | J36: =SUM(J13:J22) -> 0 | ... R36: =SUM(R13:R22) -> 0 | S36: TOTAL | U36: =SUM(C36:R36) -> 15 | V36: =V35+V34+V33+V32+V31 -> 3 | W36: =W35+W34+W33+W32+W31 -> 0 | X36: =X35+X34+X33+X32+X31 -> 0 | Y36: =Y35+Y33+Y31 -> 0
S37: =IF($U$35=MAX($U$31:$U$35),S35,IF($U$34=MAX($U$31:$U$35),S34,IF($U$33=MAX($U$31:$U$35),S33,IF($U$32=MAX($U$31:$U$35),S32,IF($U$31=MAX($U$31:$U$35),S31,S35))))) -> 8:00 à 8:30 | U37: =IF($U$35=MAX($U$31:$U$35),U35,IF($U$34=MAX($U$31:$U$35),U34,IF($U$33=MAX($U$31:$U$35),U33,IF($U$32=MAX($U$31:$U$35),U32,IF($U$31=MAX($U$31:$U$35),U31,U35))))) -> 7 | V37: =IF($U$35=MAX($U$31:$U$35),V35,IF($U$34=MAX($U$31:$U$35),V34,IF($U$33=MAX($U$31:$U$35),V33,IF($U$32=MAX($U$31:$U$35),V32,IF($U$31=MAX($U$31:$U$35),V31,V35))))) -> 0 | W37: =IF($U$35=MAX($U$31:$U$35),W35,IF($U$34=MAX($U$31:$U$35),W34,IF($U$33=MAX($U$31:$U$35),W33,IF($U$32=MAX($U$31:$U$35),W32,IF($U$31=MAX($U$31:$U$35),W31,W35))))) -> 0 | X37: =IF($U$35=MAX($U$31:$U$35),X35,IF($U$34=MAX($U$31:$U$35),X34,IF($U$33=MAX($U$31:$U$35),X33,IF($U$32=MAX($U$31:$U$35),X32,IF($U$31=MAX($U$31:$U$35),X31,X35))))) -> 0 | Y37: =IF($U$35=MAX($U$31:$U$35),Y35,IF($U$34=MAX($U$31:$U$35),Y34,IF($U$33=MAX($U$31:$U$35),Y33,IF($U$32=MAX($U$31:$U$35),Y32,IF($U$31=MAX($U$31:$U$35),Y31,Y35))))) -> 0
U38: TOTAL | V38: Part des VAE dans le total | W38: Part des femmes dans le total | X38: Part des VAE chez les femmes | Y38: =Y27 -> 0 | Z38: Remarque
S41: Période
S42: =S31 -> 6:30 à 7:00 | V42: =IF(V31=0,0,V31/U31) -> 0 | W42: =IF(W31=0,0,W31/U31) -> 0 | X42: =IF(X31=0,0,X31/V31) -> 0 | Y42: =IF(Y31=0,0,Y31/U31) -> 0
S43: =S32 -> 7:00 à 7:30 | V43: =IF(V33=0,0,V33/U33) -> 0.66666667 | W43: =IF(W33=0,0,W33/U33) -> 0 | X43: =IF(X33=0,0,X33/V33) -> 0 | Y43: =IF(Y33=0,0,Y33/U33) -> 0
S44: =S33 -> 7:30 à 8:00 | V44: =IF(V33=0,0,V33/U33) -> 0.66666667 | W44: =IF(W33=0,0,W33/U33) -> 0 | X44: =IF(X33=0,0,X33/V33) -> 0 | Y44: =IF(Y33=0,0,Y33/U33) -> 0
S45: =S34 -> 8:00 à 8:30 | V45: =IF(V34=0,0,V34/U34) -> 0 | W45: =IF(W34=0,0,W34/U34) -> 0 | X45: =IF(X34=0,0,X34/V34) -> 0 | Y45: =IF(Y34=0,0,Y34/U34) -> 0
S46: =S35 -> 8:30 à 9:00 | V46: =IF(V35=0,0,V35/U35) -> 0 | W46: =IF(W35=0,0,W35/U35) -> 0 | X46: =IF(X35=0,0,X35/V35) -> 0 | Y46: =IF(Y35=0,0,Y35/U35) -> 0
...

Sheet ARENT_PAPETERIE
B1: Arenthon La Papeterie | O1: Date :
A2: Nom des personnes participant au comptage : | K2: Bea
A3: Météo : | N3: Remarques :
A5: PRINCIPE D’UTILISATION : pour chaque intervalle de temps, comptabiliser VAE/vélo dans la colonne H/F
A6: Rajouter aussi en bas de la feuille si déplacement vélo sur trottoir et/ou si enfant
A7: Comptabiliser en bas de la grille si 2 roues hors vélo qui ne sont pas cochés dans la grille (trottinette, skate, ets)
C9: De Arenthon vers | O9: De Bonneville vers | AA9: De Rte Papeterie vers | AM9: De TNA vers
C10: Bonneville | G10: TNA | K10: Rte Papeterie | O10: TNA | S10: Arenthon | W10: Rte Papeterie | AA10: Arenthon | AE10: TNA | AI10: Bonneville | AM10: Bonneville | AQ10: Arenthon | AU10: Rte Papeterie
C11: H | E11: F | G11: H | I11: F | K11: H | M11: F | O11: H | Q11: F | S11: H | U11: F | W11: H | Y11: F | AA11: H | AC11: F | AE11: H | AG11: F | AI11: H | AK11: F | AM11: H | AO11: F | AQ11: H | AS11: F | AU11: H | AW11: F
A12: H | B12: Minute | C12: VAE | D12: vélo | E12: VAE | F12: vélo | G12: VAE | H12: vélo | I12: VAE | J12: vélo | K12: VAE | L12: vélo | M12: VAE | N12: vélo | O12: VAE | P12: vélo | Q12: VAE | R12: vélo | S12: VAE | T12: vélo | U12: VAE | V12: vélo | W12: VAE | X12: vélo | Y12: VAE | Z12: vélo | AA12: VAE | AB12: vélo | AC12: VAE | AD12: vélo | AE12: VAE | AF12: vélo | AG12: VAE | AH12: vélo | AI12: VAE | AJ12: vélo | AK12: VAE | AL12: vélo | AM12: VAE | AN12: vélo | AO12: VAE | AP12: vélo | AQ12: VAE | AR12: vélo | AS12: VAE | AT12: vélo | AU12: VAE | AV12: vélo | AW12: VAE | AX12: vélo
A13: 6 | B13: 30 – 45 | U13: 1
B14: 45 - 59 | D14: 1
A15: 7 | B15: 00 – 15
B16: 15 – 30
B17: 30 – 45 | AB17: 1
B18: 45 – 59 | T18: 1
A19: 8 | B19: 00 – 15
B20: 15 – 30 | C20: 1 | X20: 1
B21: 30 – 45
A22: 9 | B22: 45 – 59
A24: Vélo sur trottoir | V24: Vélo Spécial (Cargo/Carriole…)
A25: Enfant | V25: 2 roues hors vélo (trottinette, skate...)
C34: =C9 -> De Arenthon vers | O34: =O9 -> De Bonneville vers | AA34: =AA9 -> De Rte Papeterie vers | AM34: =AM9 -> De TNA vers | BA34: TOTAL | BB34: Nombre de VAE dans le total | BC34: Nombre de femmes dans le total | BD34: Nombre de VAE chez les femmes | BE34: Cycles sur route de Reignier | BF34: Remarque
C35: =C10 -> Bonneville | G35: =G10 -> TNA | K35: =K10 -> Rte Papeterie | O35: =O10 -> TNA | S35: =S10 -> Arenthon | W35: =W10 -> Rte Papeterie | AA35: =AA10 -> Arenthon | AE35: =AE10 -> TNA | AI35: =AI10 -> Bonneville | AM35: =AM10 -> Bonneville | AQ35: =AQ10 -> Arenthon | AU35: =AU10 -> Rte Papeterie
C36: H | E36: F | G36: H | I36: F | K36: H | M36: F | O36: H | Q36: F | S36: H | U36: F | W36: H | Y36: F | AA36: H | AC36: F | AE36: H | AG36: F | AI36: H | AK36: F | AM36: H | AO36: F | AQ36: H | AS36: F | AU36: H | AW36: F
A37: Période | C37: VAE | D37: vélo | E37: VAE | F37: vélo | G37: VAE | H37: vélo | I37: VAE | J37: vélo | K37: VAE | L37: vélo | M37: VAE | N37: vélo | O37: VAE | P37: vélo | Q37: VAE | R37: vélo | S37: VAE | T37: vélo | U37: VAE | V37: vélo | W37: VAE | X37: vélo | Y37: VAE | Z37: vélo | AA37: VAE | AB37: vélo | AC37: VAE | AD37: vélo | AE37: VAE | AF37: vélo | AG37: VAE | AH37: vélo | AI37: VAE | AJ37: vélo | AK37: VAE | AL37: vélo | AM37: VAE | AN37: vélo | AO37: VAE | AP37: vélo | AQ37: VAE | AR37: vélo | AS37: VAE | AT37: vélo | AU37: VAE | AV37: vélo | AW37: VAE | AX37: vélo | AY37: Période
A38: 6:30 à 7:00 | C38: =SUM(C13:C14) -> 0 | D38: =SUM(D13:D14) -> 1 | E38: =SUM(E13:E14) -> 0 | F38: =SUM(F13:F14) -> 0 | G38: =SUM(G13:G14) -> 0 | H38: =SUM(H13:H14) -> 0 | I38: =SUM(I13:I14) -> 0 | J38: =SUM(J13:J14) -> 0 | ... AX38: =SUM(AX13:AX14) -> 0 | AY38: =A38 -> 6:30 à 7:00 | BA38: =SUM(C38:AX38) -> 2 | BB38: =C38+E38+G38+I38+K38+M38+O38+Q38+S38+U38+W38+Y38+AA38+AC38+AE38+AG38+AI38+AK38+AM38+AO38+AQ38+AS38+AU38+AW38 -> 1 | BC38: =E38+F38+I38+J38+M38+N38+Q38+R38+U38+V38+Y38+Z38+AC38+AD38+AG38+AH38+AK38+AL38+AO38+AP38+AS38+AT38+AW38+AX38 -> 1 | BD38: =E38+I38+M38+Q38+U38+Y38+AC38+AG38+AK38+AO38+AS38+AW38 -> 1 | BE38: =SUM(K38:N38)+SUM(S38:V38)+SUM(AA38:AD38)+SUM(AM38:AX38) -> 1 | BF38: 34 piétons plus 32 étudiants piétons en direction lycée
A39: 7:00 à 7:30 | C39: =SUM(C15:C16) -> 0 | D39: =SUM(D15:D16) -> 0 | E39: =SUM(E15:E16) -> 0 | F39: =SUM(F15:F16) -> 0 | G39: =SUM(G15:G16) -> 0 | H39: =SUM(H15:H16) -> 0 | I39: =SUM(I15:I16) -> 0 | J39: =SUM(J15:J16) -> 0 | ... AX39: =SUM(AX15:AX16) -> 0 | AY39: =A39 -> 7:00 à 7:30 | BA39: =SUM(C39:AX39) -> 0 | BB39: =C39+E39+G39+I39+K39+M39+O39+Q39+S39+U39+W39+Y39+AA39+AC39+AE39+AG39+AI39+AK39+AM39+AO39+AQ39+AS39+AU39+AW39 -> 0 | BC39: =E39+F39+I39+J39+M39+N39+Q39+R39+U39+V39+Y39+Z39+AC39+AD39+AG39+AH39+AK39+AL39+AO39+AP39+AS39+AT39+AW39+AX39 -> 0 | BD39: =E39+I39+M39+Q39+U39+Y39+AC39+AG39+AK39+AO39+AS39+AW39 -> 0 | BE39: =SUM(K39:N39)+SUM(S39:V39)+SUM(AA39:AD39)+SUM(AM39:AX39) -> 0 | BF39: et seulement 2 écoliers- 2 enfants comptés qui étaient sur le trottoir avec 1 parent
A40: 7:30 à 8:00 | C40: =SUM(C17:C18) -> 0 | D40: =SUM(D17:D18) -> 0 | E40: =SUM(E17:E18) -> 0 | F40: =SUM(F17:F18) -> 0 | G40: =SUM(G17:G18) -> 0 | H40: =SUM(H17:H18) -> 0 | I40: =SUM(I17:I18) -> 0 | J40: =SUM(J17:J18) -> 0 | ... AX40: =SUM(AX17:AX18) -> 0 | AY40: =A40 -> 7:30 à 8:00 | BA40: =SUM(C40:AX40) -> 2 | BB40: =C40+E40+G40+I40+K40+M40+O40+Q40+S40+U40+W40+Y40+AA40+AC40+AE40+AG40+AI40+AK40+AM40+AO40+AQ40+AS40+AU40+AW40 -> 0 | BC40: =E40+F40+I40+J40+M40+N40+Q40+R40+U40+V40+Y40+Z40+AC40+AD40+AG40+AH40+AK40+AL40+AO40+AP40+AS40+AT40+AW40+AX40 -> 0 | BD40: =E40+I40+M40+Q40+U40+Y40+AC40+AG40+AK40+AO40+AS40+AW40 -> 0 | BE40: =SUM(K40:N40)+SUM(S40:V40)+SUM(AA40:AD40)+SUM(AM40:AX40) -> 2 | BF40: et seulement 2 écoliers- 2 enfants comptés qui étaient sur le trottoir avec 1 parent
A41: 8:00 à 8:30 | C41: =SUM(C19:C20) -> 1 | D41: =SUM(D19:D20) -> 0 | E41: =SUM(E19:E20) -> 0 | F41: =SUM(F19:F20) -> 0 | G41: =SUM(G19:G20) -> 0 | H41: =SUM(H19:H20) -> 0 | I41: =SUM(I19:I20) -> 0 | J41: =SUM(J19:J20) -> 0 | ... AX41: =SUM(AX19:AX20) -> 0 | AY41: =A41 -> 8:00 à 8:30 | BA41: =SUM(C41:AX41) -> 2 | BB41: =C41+E41+G41+I41+K41+M41+O41+Q41+S41+U41+W41+Y41+AA41+AC41+AE41+AG41+AI41+AK41+AM41+AO41+AQ41+AS41+AU41+AW41 -> 1 | BC41: =E41+F41+I41+J41+M41+N41+Q41+R41+U41+V41+Y41+Z41+AC41+AD41+AG41+AH41+AK41+AL41+AO41+AP41+AS41+AT41+AW41+AX41 -> 0 | BD41: =E41+I41+M41+Q41+U41+Y41+AC41+AG41+AK41+AO41+AS41+AW41 -> 0 | BE41: =SUM(K41:N41)+SUM(S41:V41)+SUM(AA41:AD41)+SUM(AM41:AX41) -> 0 | BF41: 2 des 3 femmes circulaient sur le trottoir !
A42: 8:30 à 9:00 | C42: =SUM(C20:C22) -> 1 | D42: =SUM(D20:D22) -> 0 | E42: =SUM(E20:E22) -> 0 | F42: =SUM(F20:F22) -> 0 | G42: =SUM(G20:G22) -> 0 | H42: =SUM(H20:H22) -> 0 | I42: =SUM(I20:I22) -> 0 | J42: =SUM(J20:J22) -> 0 | ... AX42: =SUM(AX20:AX22) -> 0 | AY42: =A42 -> 8:30 à 9:00 | BA42: =SUM(C42:AX42) -> 2 | BB42: =C42+E42+G42+I42+K42+M42+O42+Q42+S42+U42+W42+Y42+AA42+AC42+AE42+AG42+AI42+AK42+AM42+AO42+AQ42+AS42+AU42+AW42 -> 1 | BC42: =E42+F42+I42+J42+M42+N42+Q42+R42+U42+V42+Y42+Z42+AC42+AD42+AG42+AH42+AK42+AL42+AO42+AP42+AS42+AT42+AW42+AX42 -> 0 | BD42: =E42+I42+M42+Q42+U42+Y42+AC42+AG42+AK42+AO42+AS42+AW42 -> 0 | BE42: =SUM(K42:N42)+SUM(S42:V42)+SUM(AA42:AD42)+SUM(AM42:AX42) -> 0 | BF42: 3 cyclosportifs
A43: TOTAL | C43: =SUM(C13:C22) -> 1 | D43: =SUM(D13:D22) -> 1 | E43: =SUM(E13:E22) -> 0 | F43: =SUM(F13:F22) -> 0 | G43: =SUM(G13:G22) -> 0 | H43: =SUM(H13:H22) -> 0 | I43: =SUM(I13:I22) -> 0 | J43: =SUM(J13:J22) -> 0 | ... AX43: =SUM(AX13:AX22) -> 0 | AY43: TOTAL | BA43: =SUM(C43:AX43) -> 6 | BB43: =C43+E43+G43+I43+K43+M43+O43+Q43+S43+U43+W43+Y43+AA43+AC43+AE43+AG43+AI43+AK43+AM43+AO43+AQ43+AS43+AU43+AW43 -> 2 | BC43: =E43+F43+I43+J43+M43+N43+Q43+R43+U43+V43+Y43+Z43+AC43+AD43+AG43+AH43+AK43+AL43+AO43+AP43+AS43+AT43+AW43+AX43 -> 1 | BD43: =E43+I43+M43+Q43+U43+Y43+AC43+AG43+AK43+AO43+AS43+AW43 -> 1 | BE43: =SUM(K43:N43)+SUM(S43:V43)+SUM(AA43:AD43)+SUM(AM43:AX43) -> 3
AY44: =IF($BA$38=MAX($BA$38:$BA$42),AY38,IF($BA$39=MAX($BA$38:$BA$42),AY39,IF($BA$40=MAX($BA$38:$BA$42),AY40,IF($BA$41=MAX($BA$38:$BA$42),AY41,IF($BA$42=MAX($BA$38:$BA$42),AY42,AY41))))) -> 6:30 à 7:00 | BA44: =IF($BA$38=MAX($BA$38:$BA$42),BA38,IF($BA$39=MAX($BA$38:$BA$42),BA39,IF($BA$40=MAX($BA$38:$BA$42),BA40,IF($BA$41=MAX($BA$38:$BA$42),BA41,IF($BA$42=MAX($BA$38:$BA$42),BA42,BA41))))) -> 2 | BB44: =IF($BA$38=MAX($BA$38:$BA$42),BB38,IF($BA$39=MAX($BA$38:$BA$42),BB39,IF($BA$40=MAX($BA$38:$BA$42),BB40,IF($BA$41=MAX($BA$38:$BA$42),BB41,IF($BA$42=MAX($BA$38:$BA$42),BB42,BB41))))) -> 1 | BC44: =IF($BA$38=MAX($BA$38:$BA$42),BC38,IF($BA$39=MAX($BA$38:$BA$42),BC39,IF($BA$40=MAX($BA$38:$BA$42),BC40,IF($BA$41=MAX($BA$38:$BA$42),BC41,IF($BA$42=MAX($BA$38:$BA$42),BC42,BC41))))) -> 1 | BD44: =IF($BA$38=MAX($BA$38:$BA$42),BD38,IF($BA$39=MAX($BA$38:$BA$42),BD39,IF($BA$40=MAX($BA$38:$BA$42),BD40,IF($BA$41=MAX($BA$38:$BA$42),BD41,IF($BA$42=MAX($BA$38:$BA$42),BD42,BD41))))) -> 1 | BE44: =IF($BA$38=MAX($BA$38:$BA$42),BE38,IF($BA$39=MAX($BA$38:$BA$42),BE39,IF($BA$40=MAX($BA$38:$BA$42),BE40,IF($BA$41=MAX($BA$38:$BA$42),BE41,IF($BA$42=MAX($BA$38:$BA$42),BE42,BE41))))) -> 1
BA45: TOTAL | BB45: Part des VAE dans le total | BC45: Part des femmes dans le total | BD45: Part des VAE chez les femmes | BE45: =BE34 -> Cycles sur route de Reignier | BF45: Remarque
AY48: Période
AY49: =AY38 -> 6:30 à 7:00 | BB49: =IF(BB38=0,0,BB38/BA38) -> 0.5 | BC49: =IF(BC38=0,0,BC38/BA38) -> 0.5 | BD49: =IF(BD38=0,0,BD38/BB38) -> 1 | BE49: =IF(BE38=0,0,BE38/BA38) -> 0.5
AY50: =AY39 -> 7:00 à 7:30 | BB50: =IF(BB40=0,0,BB40/BA40) -> 0 | BC50: =IF(BC40=0,0,BC40/BA40) -> 0 | BD50: =IF(BD40=0,0,BD40/BB40) -> 0 | BE50: =IF(BE40=0,0,BE40/BA40) -> 1
AY51: =AY40 -> 7:30 à 8:00 | BB51: =IF(BB40=0,0,BB40/BA40) -> 0 | BC51: =IF(BC40=0,0,BC40/BA40) -> 0 | BD51: =IF(BD40=0,0,BD40/BB40) -> 0 | BE51: =IF(BE40=0,0,BE40/BA40) -> 1
AY52: =AY41 -> 8:00 à 8:30 | BB52: =IF(BB41=0,0,BB41/BA41) -> 0.5 | BC52: =IF(BC41=0,0,BC41/BA41) -> 0 | BD52: =IF(BD41=0,0,BD41/BB41) -> 0 | BE52: =IF(BE41=0,0,BE41/BA41) -> 0
AY53: =AY42 -> 8:30 à 9:00 | BB53: =IF(BB42=0,0,BB42/BA42) -> 0.5 | BC53: =IF(BC42=0,0,BC42/BA42) -> 0 | BD53: =IF(BD42=0,0,BD42/BB42) -> 0 | BE53: =IF(BE42=0,0,BE42/BA42) -> 0
...

Sheet ST_PI_BORNE_DESSY
B1: St Pierre en face Franchissement du Borne au 245 Rte des Gorges du Borne | O1: Date :
A2: Nom des personnes participant au comptage :
A3: Météo : | P3: Remarques :
A5: PRINCIPE D’UTILISATION : pour chaque intervalle de temps, comptabiliser VAE/vélo dans la colonne H/F
A6: Comptabiliser en bas de la grille si 2 roues hors vélo qui ne sont pas cochés dans la grille (trottinette, skate, ets)
C8: De Rte Gorges du Borne vers | K8: De Avenue des Digues vers | S8: De Avenue de Monaz vers
C9: Av des Digues | G9: Av de Monaz | K9: Av de Monaz | O9: Rte Gorges du Borne | S9: Rte Gorges du Borne | W9: Av des Digues
C10: H | E10: F | G10: H | I10: F | K10: H | M10: F | O10: H | Q10: F | S10: H | U10: F | W10: H | Y10: F
A11: H | B11: mn | C11: VAE | D11: vélo | E11: VAE | F11: vélo | G11: VAE | H11: vélo | I11: VAE | J11: vélo | K11: VAE | L11: vélo | M11: VAE | N11: vélo | O11: VAE | P11: vélo | Q11: VAE | R11: vélo | S11: VAE | T11: vélo | U11: VAE | V11: vélo | W11: VAE | X11: vélo | Y11: VAE | Z11: vélo
A12: 6 | B12: 30 – 45
B13: 45 - 59 | X13: 1
A14: 7 | B14: 00 – 15 | H14: 1 | T14: 1
B15: 15 – 30 | G15: 1 | H15: 1 | T15: 1 | X15: 1
B16: 30 – 45 | C16: 1 | E16: 1 | J16: 1 | T16: 1
B17: 45 – 59 | E17: 1
A18: 8 | B18: 00 – 15 | T18: 1
B19: 15 – 30 | D19: 1 | H19: 1
B20: 30 – 45 | C20: 1 | H20: 2
A21: 9 | B21: 45 – 59 | T21: 1 | V21: 1
A23: Vélo Spécial (Cargo/Carriole…)
A24: 2 roues hors vélo (trottinette, skate...) | I24: 2
C28: =C8 -> De Rte Gorges du Borne vers | K28: =K8 -> De Avenue des Digues vers | S28: =S8 -> De Avenue de Monaz vers | AC28: TOTAL | AD28: Nombre de VAE dans le total | AE28: Nombre de femmes dans le total | AF28: Nombre de VAE chez les femmes | AG28: Cycles sur rte de Dessy | AH28: Cycles sur rte des Digues
