Workbook
Name Print_Area: ARENT_PAPETERIE!$A$1:$Z$32
Name Print_Area: BO_BORNE_TUCINGE!$A$1:$J$21
Name Print_Area: 'LA RO ANDREV 23'!$A$1:$J$22
Name Print_Area: 'LA RO ANDREV 24'!$A$1:$J$32
Name Print_Area: LA_RO_BIOCOOP!$A$1:$AL$22
Name Print_Area: LA_RO_POSTE!$A$1:$BV$34
Name Print_Area: LA_RO_SNCF!$A$1:$Z$33
Name Print_Area: 'ST PI M BRICOLAGE'!$A$1:$R$27
Name Print_Area: ST_PI_BORNE_DESSY!$A$1:$Z$22
Name Print_Area: ST_PI_BORNE_RD1203!$A$1:$V$39,ST_PI_BORNE_RD1203!$A$42:$V$84

Sheet LA_RO_BIOCOOP
A1: Lieu : | B1: La Roche Face Biocoop | P1: Date : | R1: 45085
A2: Nom des personnes participant au comptage : | J2: Philippe Poirier
A3: Météo : | C3: bonne | P3: Remarques :
A5: PRINCIPE D’UTILISATION : pour chaque intervalle de temps, comptabiliser VAE/vélo dans la colonne H/F
A6: Rajouter aussi en bas de la feuille si déplacement vélo sur trottoir et/ou si enfant
A7: Comptabiliser en bas de la grille si 2 roues hors vélo qui ne sont pas cochés dans la grille (trottinette, skate, ets)
C9: De La Gare (Fg St Bernard) vers | O9: Du Pont du Foron vers | AA9: Du Rd Point La Poste vers
C10: Rd Pt Poste | G10: Rue Perrine | K10: Pont du Foron | O10: Rue Perrine | S10: Rd Pt Poste | W10: La Gare | AA10: Rue Perrine | AE10: Pont du Foron | AI10: La Gare
C11: H | E11: F | G11: H | I11: F | K11: H | M11: F | O11: H | Q11: F | S11: H | U11: F | W11: H | Y11: F | AA11: H | AC11: F | AE11: H | AG11: F | AI11: H | AK11: F
A12: Période | C12: VAE | D12: vélo | E12: VAE | F12: vélo | G12: VAE | H12: vélo | I12: VAE | J12: vélo | K12: VAE | L12: vélo | M12: VAE | N12: vélo | O12: VAE | P12: vélo | Q12: VAE | R12: vélo | S12: VAE | T12: vélo | U12: VAE | V12: vélo | W12: VAE | X12: vélo | Y12: VAE | Z12: vélo | AA12: VAE | AB12: vélo | AC12: VAE | AD12: vélo | AE12: VAE | AF12: vélo | AG12: VAE | AH12: vélo | AI12: VAE | AJ12: vélo | AK12: VAE | AL12: vélo
A13: 0.27083333 | B13: 0.29166667 | T13: 3 | V13: 1 | X13: 2 | AM13: =SUM(C13:AL13) -> 6
A14: 0.29166667 | B14: 0.3125 | D14: 1 | W14: 1 | X14: 5 | Z14: 2 | AG14: 1 | AL14: 1 | AM14: =SUM(C14:AL14) -> 11
A15: 0.3125 | B15: 0.33333333 | L15: 2 | T15: 4 | U15: 4 | V15: 1 | X15: 2 | Z15: 1 | AB15: 1 | AE15: 1 | AF15: 1 | AL15: 1 | AM15: =SUM(C15:AL15) -> 18
A16: 0.33333333 | B16: 0.35416667 | H16: 1 | N16: 1 | O16: 1 | Q16: 1 | R16: 2 | T16: 2 | U16: 1 | X16: 5 | Z16: 2 | AA16: 1 | AM16: =SUM(C16:AL16) -> 17
A17: 0.35416667 | B17: 0.375 | K17: 1 | L17: 1 | P17: 1 | T17: 2 | U17: 1 | V17: 1 | W17: 1 | X17: 2 | Y17: 2 | AF17: 2 | AJ17: 2 | AM17: =SUM(C17:AL17) -> 16
AM18: =SUM(C18:AL18) -> 0
A19: 5 | B19: dont Enfant
A20: 2 | B20: vélo sur trottoir
B21: dont Cyclo sportifs
A22: 23 | B22: hors grille, plus 2 roues hors vélo (trottinette, skate...)
C26: =C9 -> De La Gare (Fg St Bernard) vers | O26: =O9 -> Du Pont du Foron vers | AA26: =AA9 -> Du Rd Point La Poste vers | AO26: TOTAL | AP26: Nombre de VAE dans le total | AQ26: Nombre de femmes dans le total | AR26: Nombre de VAE chez les femmes | AX26: Nombre de VAE chez les femmes | AY26: Cycles direc La Gare
C27: =C10 -> Rd Pt Poste | G27: =G10 -> Rue Perrine | K27: =K10 -> Pont du Foron | O27: =O10 -> Rue Perrine | S27: =S10 -> Rd Pt Poste | W27: =W10 -> La Gare | AA27: =AA10 -> Rue Perrine | AE27: =AE10 -> Pont du Foron | AI27: =AI10 -> La Gare
C28: H | E28: F | G28: H | I28: F | K28: H | M28: F | O28: H | Q28: F | S28: H | U28: F | W28: H | Y28: F | AA28: H | AC28: F | AE28: H | AG28: F | AI28: H | AK28: F
A29: Période | C29: VAE | D29: vélo | E29: VAE | F29: vélo | G29: VAE | H29: vélo | I29: VAE | J29: vélo | K29: VAE | L29: vélo | M29: VAE | N29: vélo | O29: VAE | P29: vélo | Q29: VAE | R29: vélo | S29: VAE | T29: vélo | U29: VAE | V29: vélo | W29: VAE | X29: vélo | Y29: VAE | Z29: vélo | AA29: VAE | AB29: vélo | AC29: VAE | AD29: vélo | AE29: VAE | AF29: vélo | AG29: VAE | AH29: vélo | AI29: VAE | AJ29: vélo | AK29: VAE | AL29: vélo | AM29: Période | AS29: plus trotinette skate | AT29: dont enfant | AU29: vélo sur trottoir | AV29: dont cyclo
A30: 6:30 à 7:00 | C30: =+C13 -> 0 | D30: =+D13 -> 0 | E30: =+E13 -> 0 | F30: =+F13 -> 0 | G30: =+G13 -> 0 | H30: =+H13 -> 0 | I30: =+I13 -> 0 | J30: =+J13 -> 0 | ... AL30: =+AL13 -> 0 | AM30: 6:30 à 7:00 | AO30: =SUM(C30:AL30) -> 6 | AP30: =C30+E30+G30+I30+K30+M30+O30+Q30+S30+U30+W30+Y30+AA30+AC30+AE30+AG30+AI30+AK30 -> 0 | AQ30: =E30+F30+I30+J30+M30+N30+Q30+R30+U30+V30+Y30+Z30+AC30+AD30+AG30+AH30+AK30+AL30 -> 1 | AR30: =E30+I30+M30+Q30+U30+Y30+AC30+AG30+AK30 -> 0 | AX30: =E30+I30+M30+Q30+U30+Y30+AC30+AG30+AK30 -> 0 | AY30: =SUM(C30:N30)+SUM(W30:Z30)+SUM(AI30:AL30) -> 2
A31: 7:00 à 7:30 | C31: =+C14 -> 0 | D31: =+D14 -> 1 | E31: =+E14 -> 0 | F31: =+F14 -> 0 | G31: =+G14 -> 0 | H31: =+H14 -> 0 | I31: =+I14 -> 0 | J31: =+J14 -> 0 | ... AL31: =+AL14 -> 1 | AM31: 7:00 à 7:30 | AO31: =SUM(C31:AL31) -> 11 | AP31: =C31+E31+G31+I31+K31+M31+O31+Q31+S31+U31+W31+Y31+AA31+AC31+AE31+AG31+AI31+AK31 -> 2 | AQ31: =E31+F31+I31+J31+M31+N31+Q31+R31+U31+V31+Y31+Z31+AC31+AD31+AG31+AH31+AK31+AL31 -> 4 | AR31: =E31+I31+M31+Q31+U31+Y31+AC31+AG31+AK31 -> 1 | AX31: =E31+I31+M31+Q31+U31+Y31+AC31+AG31+AK31 -> 1 | AY31: =SUM(C31:N31)+SUM(W31:Z31)+SUM(AI31:AL31) -> 10
A32: 7:30 à 8:00 | C32: =+C15 -> 0 | D32: =+D15 -> 0 | E32: =+E15 -> 0 | F32: =+F15 -> 0 | G32: =+G15 -> 0 | H32: =+H15 -> 0 | I32: =+I15 -> 0 | J32: =+J15 -> 0 | ... AL32: =+AL15 -> 1 | AM32: 7:30 à 8:00 | AO32: =SUM(C32:AL32) -> 18 | AP32: =C32+E32+G32+I32+K32+M32+O32+Q32+S32+U32+W32+Y32+AA32+AC32+AE32+AG32+AI32+AK32 -> 5 | AQ32: =E32+F32+I32+J32+M32+N32+Q32+R32+U32+V32+Y32+Z32+AC32+AD32+AG32+AH32+AK32+AL32 -> 7 | AR32: =E32+I32+M32+Q32+U32+Y32+AC32+AG32+AK32 -> 4 | AX32: =E32+I32+M32+Q32+U32+Y32+AC32+AG32+AK32 -> 4 | AY32: =SUM(C32:N32)+SUM(W32:Z32)+SUM(AI32:AL32) -> 6
A33: 8:00 à 8:30 | C33: =+C16 -> 0 | D33: =+D16 -> 0 | E33: =+E16 -> 0 | F33: =+F16 -> 0 | G33: =+G16 -> 0 | H33: =+H16 -> 1 | I33: =+I16 -> 0 | J33: =+J16 -> 0 | ... AL33: =+AL16 -> 0 | AM33: 8:00 à 8:30 | AO33: =SUM(C33:AL33) -> 17 | AP33: =C33+E33+G33+I33+K33+M33+O33+Q33+S33+U33+W33+Y33+AA33+AC33+AE33+AG33+AI33+AK33 -> 4 | AQ33: =E33+F33+I33+J33+M33+N33+Q33+R33+U33+V33+Y33+Z33+AC33+AD33+AG33+AH33+AK33+AL33 -> 7 | AR33: =E33+I33+M33+Q33+U33+Y33+AC33+AG33+AK33 -> 2 | AX33: =E33+I33+M33+Q33+U33+Y33+AC33+AG33+AK33 -> 2 | AY33: =SUM(C33:N33)+SUM(W33:Z33)+SUM(AI33:AL33) -> 9
A34: 8:30 à 9:00 | C34: =+C17 -> 0 | D34: =+D17 -> 0 | E34: =+E17 -> 0 | F34: =+F17 -> 0 | G34: =+G17 -> 0 | H34: =+H17 -> 0 | I34: =+I17 -> 0 | J34: =+J17 -> 0 | ... AL34: =+AL17 -> 0 | AM34: 8:30 à 9:00 | AO34: =SUM(C34:AL34) -> 16 | AP34: =C34+E34+G34+I34+K34+M34+O34+Q34+S34+U34+W34+Y34+AA34+AC34+AE34+AG34+AI34+AK34 -> 5 | AQ34: =E34+F34+I34+J34+M34+N34+Q34+R34+U34+V34+Y34+Z34+AC34+AD34+AG34+AH34+AK34+AL34 -> 4 | AR34: =E34+I34+M34+Q34+U34+Y34+AC34+AG34+AK34 -> 3 | AX34: =E34+I34+M34+Q34+U34+Y34+AC34+AG34+AK34 -> 3 | AY34: =SUM(C34:N34)+SUM(W34:Z34)+SUM(AI34:AL34) -> 9
A35: TOTAL | C35: =+C18 -> 0 | D35: =+D18 -> 0 | E35: =+E18 -> 0 | F35: =+F18 -> 0 | G35: =+G18 -> 0 | H35: =+H18 -> 0 | I35: =+I18 -> 0 | J35: =+J18 -> 0 | ... AL35: =+AL18 -> 0 | AM35: TOTAL | AO35: =SUM(AO30:AO34) -> 68 | AP35: =SUM(AP30:AP34) -> 16 | AQ35: =SUM(AQ30:AQ34) -> 23 | AR35: =SUM(AR30:AR34) -> 10 | AS35: =A22 -> 23 | AT35: =A19 -> 5 | AU35: =A20 -> 2 | AV35: =A21 -> 0 | AX35: =E35+I35+M35+Q35+U35+Y35+AC35+AG35+AK35 -> 0 | AY35: =SUM(C35:N35)+SUM(W35:Z35)+SUM(AI35:AL35) -> 0
AL36: H POINTE | AM36: 7:30 à 8:00 | AO36: 18
AL37: H POINTE | AM37: 8:00 à 8:30 | AO37: 17
AM38: Total H pointe | AO38: =SUM(AO36:AO37) -> 35
AM39: =IF(AO30=MAX($AO$30:$AO$35),AM30,IF(AO31=MAX($AO$30:$AO$35),AM31,IF(AO32=MAX($AO$30:$AO$35),AM32,IF(AO33=MAX($AO$30:$AO$35),AM33,IF(AO34=MAX($AO$30:$AO$35),AM34,AM33))))) -> 8:00 à 8:30 | AO39: =IF(AQ30=MAX($AO$30:$AO$35),AO30,IF(AQ31=MAX($AO$30:$AO$35),AO31,IF(AQ32=MAX($AO$30:$AO$35),AO32,IF(AQ33=MAX($AO$30:$AO$35),AO33,IF(AQ34=MAX($AO$30:$AO$35),AO34,AO33))))) -> 17 | AP39: =IF(AT30=MAX($AO$30:$AO$35),AP30,IF(AT31=MAX($AO$30:$AO$35),AP31,IF(AT32=MAX($AO$30:$AO$35),AP32,IF(AT33=MAX($AO$30:$AO$35),AP33,IF(AT34=MAX($AO$30:$AO$35),AP34,AP33))))) -> 4 | AQ39: =IF(AU30=MAX($AO$30:$AO$35),AQ30,IF(AU31=MAX($AO$30:$AO$35),AQ31,IF(AU32=MAX($AO$30:$AO$35),AQ32,IF(AU33=MAX($AO$30:$AO$35),AQ33,IF(AU34=MAX($AO$30:$AO$35),AQ34,AQ33))))) -> 7 | AR39: =IF(AV30=MAX($AO$30:$AO$35),AR30,IF(AV31=MAX($AO$30:$AO$35),AR31,IF(AV32=MAX($AO$30:$AO$35),AR32,IF(AV33=MAX($AO$30:$AO$35),AR33,IF(AV34=MAX($AO$30:$AO$35),AR34,AR33))))) -> 2
AO40: TOTAL | AP40: Part des VAE dans le total | AQ40: Part des femmes dans le total | AR40: Part des VAE chez les femmes
AM43: Période
AM44: =AM30 -> 6:30 à 7:00 | AP44: =IF(AP31=0,0,AP31/AO31) -> 0.18181818 | AQ44: =IF(AQ31=0,0,AQ31/AO31) -> 0.36363636 | AR44: =IF(AT31=0,0,AT31/AP31) -> 0
AM45: =AM31 -> 7:00 à 7:30 | AP45: =IF(AP31=0,0,AP31/AO31) -> 0.18181818 | AQ45: =IF(AQ31=0,0,AQ31/AO31) -> 0.36363636 | AR45: =IF(AT31=0,0,AT31/AP31) -> 0
AM46: =AM32 -> 7:30 à 8:00 | AP46: =IF(AP32=0,0,AP32/AO32) -> 0.27777778 | AQ46: =IF(AQ32=0,0,AQ32/AO32) -> 0.38888889 | AR46: =IF(AT32=0,0,AT32/AP32) -> 0
AM47: =AM33 -> 8:00 à 8:30 | AP47: =IF(AP33=0,0,AP33/AO33) -> 0.23529412 | AQ47: =IF(AQ33=0,0,AQ33/AO33) -> 0.41176471 | AR47: =IF(AT33=0,0,AT33/AP33) -> 0
...

Sheet LA_RO_POSTE
B1: Rond Point La Poste | O1: Date :
A2: Nom des personnes participant au comptage :
A3: Météo : | P3: Remarques :
A5: PRINCIPE D’UTILISATION : pour chaque intervalle de temps, comptabiliser VAE/vélo dans la colonne H/F
A6: Rajouter aussi en bas de la feuille si déplacement vélo sur trottoir et/ou si enfant
A7: Comptabiliser en bas de la grille si 2 roues hors vélo qui ne sont pas cochés dans la grille (trottinette, skate, ets)
C9: De Bonneville vers | S9: De Grenette (contre-sens) | AE9: De La Base(contre-sens)
C10: Grenette | G10: Orange | K10: La Base | O10: J Jaurès (contre sens) | S10: Orange | W10: La Base | AA10: Bonneville | AE10: Bonneville | AJ10: Orange | AM10: Place Grenette
C11: H | E11: F | G11: H | I11: F | K11: H | M11: F | O11: H | Q11: F | S11: H | U11: F | W11: H | Y11: F | AA11: H | AC11: F | AE11: H | AG11: F | AH11: F | AJ11: H | AM11: H | AO11: F
A12: Période | C12: VAE | D12: vélo | E12: VAE | F12: vélo | G12: VAE | H12: vélo | I12: VAE | J12: vélo | K12: VAE | L12: vélo | M12: VAE | N12: vélo | O12: VAE | P12: vélo | Q12: VAE | R12: vélo | S12: VAE | T12: vélo | U12: VAE | V12: vélo | W12: VAE | X12: vélo | Y12: VAE | Z12: vélo | AA12: VAE | AB12: vélo | AC12: VAE | AD12: vélo | AE12: VAE | AF12: vélo | AG12: VAE | AH12: VAE | AI12: vélo | AJ12: VAE | AK12: vélo | AL12: vélo | AM12: VAE | AN12: vélo | AO12: VAE | AP12: vélo
A13: 0.27083333 | B13: 0.29166667 | I13: 1 | K13: 1
A14: 0.29166667 | B14: 0.3125 | J14: 1 | P14: 1
A15: 0.3125 | B15: 0.33333333 | H15: 2 | L15: 2 | O15: 1
A16: 0.33333333 | B16: 0.35416667 | I16: 1 | K16: 1 | L16: 1 | M16: 1 | W16: 1
A17: 0.35416667 | B17: 0.375 | G17: 2 | H17: 1 | I17: 1 | K17: 1 | P17: 1 | AJ17: 1
A18: 9 | B18: 00 – 15
B19: 15 – 30
C21: De Orange vers | O21: De Jean Jaurès MJC vers
C22: La Base | G22: Bonneville | K22: Grenette | O22: Orange | S22: Grenette | W22: Bonneville | AA22: La Base
C23: H | E23: F | G23: H | I23: F | K23: H | M23: F | O23: H | Q23: F | S23: H | U23: F | W23: H | Y23: F | AA23: H | AC23: F
A24: Période | C24: VAE | D24: vélo | E24: VAE | F24: vélo | G24: VAE | H24: vélo | I24: VAE | J24: vélo | K24: VAE | L24: vélo | M24: VAE | N24: vélo | O24: VAE | P24: vélo | Q24: VAE | R24: vélo | S24: VAE | T24: vélo | U24: VAE | V24: vélo | W24: VAE | X24: vélo | Y24: VAE | Z24: vélo | AA24: VAE | AB24: vélo | AC24: VAE | AD24: vélo
A25: 0.27083333 | B25: 0.29166667 | H25: 1 | J25: 1 | S25: 1 | W25: 1
A26: 0.29166667 | B26: 0.3125 | H26: 1 | J26: 1 | X26: 1 | AC26: 1
A27: 0.3125 | B27: 0.33333333 | D27: 2 | E27: 1 | F27: 1 | O27: 1 | X27: 2
A28: 0.33333333 | B28: 0.35416667 | C28: 1 | E28: 1 | G28: 1 | O28: 1
A29: 0.35416667 | B29: 0.375 | C29: 2 | G29: 2 | Q29: 1 | X29: 2 | AP29: x
A30: 9 | B30: 00 – 15
B31: 15 – 30
A33: 6 | B33: dont Enfant
A34: 5 | B34: vélo sur trottoir
B35: dont Cyclo sportifs
A36: 22 | B36: hors grille, plus 2 roues hors vélo (trottinette, skate...) | N36: 33 motos
AC37: TOTAL | AD37: Nombre de VAE dans le total | AE37: Nombre de femmes dans le total | AF37: Nombre de VAE chez les femmes
C39: H | E39: F
A40: Période | C40: VAE | D40: vélo | E40: VAE | F40: vélo | AA40: Période | AH40: plus trotinette skate | AI40: dont enfant | AJ40: vélo sur trottoir | AK40: dont cyclo
A41: 6:30 à 7:00 | C41: =C13+G13+K13+O13+S13+W13+AA13+AE13+AJ13+AM13+C25+G25+K25+O25+S25+W25+AA25 -> 3 | D41: =D13+H13+L13+P13+T13+X13+AB13+AF13+AK13+AN13+D25+H25+L25+P25+T25+X25+AB25 -> 1 | E41: =E13+I13+M13+Q13+U13+Y13+AC13+AG13+AH13+AO13+E25+I25+M25+Q25+U25+Y25+AC25 -> 1 | F41: =F13+J13+N13+R13+V13+Z13+AD13+AI13+AL13+AP13+F25+J25+N25+R25+V25+Z25+AD25 -> 1 | AA41: 6:30 à 7:00 | AC41: =SUM(C41:F41) -> 6 | AD41: =C41+E41 -> 4 | AE41: =E41+F41 -> 2 | AF41: =E41 -> 1
A42: 7:00 à 7:30 | C42: =C14+G14+K14+O14+S14+W14+AA14+AE14+AJ14+AM14+C26+G26+K26+O26+S26+W26+AA26 -> 0 | D42: =D14+H14+L14+P14+T14+X14+AB14+AF14+AK14+AN14+D26+H26+L26+P26+T26+X26+AB26 -> 3 | E42: =E14+I14+M14+Q14+U14+Y14+AC14+AG14+AH14+AO14+E26+I26+M26+Q26+U26+Y26+AC26 -> 1 | F42: =F14+J14+N14+R14+V14+Z14+AD14+AI14+AL14+AP14+F26+J26+N26+R26+V26+Z26+AD26 -> 2 | AA42: 7:00 à 7:30 | AC42: =SUM(C42:F42) -> 6 | AD42: =C42+E42 -> 1 | AE42: =E42+F42 -> 3 | AF42: =E42 -> 1
A43: 7:30 à 8:00 | C43: =C15+G15+K15+O15+S15+W15+AA15+AE15+AJ15+AM15+C27+G27+K27+O27+S27+W27+AA27 -> 2 | D43: =D15+H15+L15+P15+T15+X15+AB15+AF15+AK15+AN15+D27+H27+L27+P27+T27+X27+AB27 -> 8 | E43: =E15+I15+M15+Q15+U15+Y15+AC15+AG15+AH15+AO15+E27+I27+M27+Q27+U27+Y27+AC27 -> 1 | F43: =F15+J15+N15+R15+V15+Z15+AD15+AI15+AL15+AP15+F27+J27+N27+R27+V27+Z27+AD27 -> 1 | AA43: 7:30 à 8:00 | AC43: =SUM(C43:F43) -> 12 | AD43: =C43+E43 -> 3 | AE43: =E43+F43 -> 2 | AF43: =E43 -> 1
A44: 8:00 à 8:30 | C44: =C16+G16+K16+O16+S16+W16+AA16+AE16+AJ16+AM16+C28+G28+K28+O28+S28+W28+AA28 -> 5 | D44: =D16+H16+L16+P16+T16+X16+AB16+AF16+AK16+AN16+D28+H28+L28+P28+T28+X28+AB28 -> 1 | E44: =E16+I16+M16+Q16+U16+Y16+AC16+AG16+AH16+AO16+E28+I28+M28+Q28+U28+Y28+AC28 -> 3 | F44: =F16+J16+N16+R16+V16+Z16+AD16+AI16+AL16+AP16+F28+J28+N28+R28+V28+Z28+AD28 -> 0 | AA44: 8:00 à 8:30 | AC44: =SUM(C44:F44) -> 9 | AD44: =C44+E44 -> 8 | AE44: =E44+F44 -> 3 | AF44: =E44 -> 3
A45: 8:30 à 9:00 | C45: =C17+G17+K17+O17+S17+W17+AA17+AE17+AJ17+AM17+C29+G29+K29+O29+S29+W29+AA29 -> 8 | D45: =D17+H17+L17+P17+T17+X17+AB17+AF17+AK17+AN17+D29+H29+L29+P29+T29+X29+AB29 -> 4 | E45: =E17+I17+M17+Q17+U17+Y17+AC17+AG17+AH17+AO17+E29+I29+M29+Q29+U29+Y29+AC29 -> 2 | F45: =F17+J17+N17+R17+V17+Z17+AD17+AI17+AL17+AP17+F29+J29+N29+R29+V29+Z29+AD29 -> 0 | AA45: 8:30 à 9:00 | AC45: =SUM(C45:F45) -> 14 | AD45: =C45+E45 -> 10 | AE45: =E45+F45 -> 2 | AF45: =E45 -> 2
...

Sheet LA_RO_SNCF
B1: La Roche Gare/Passage à niveau | O1: Date :
A2: Nom des personnes participant au comptage :
A3: Météo :
A4: Remarques :
A6: PRINCIPE D’UTILISATION : pour chaque intervalle de temps, comptabiliser VAE/vélo dans la colonne H/F
A7: Rajouter aussi en bas de la feuille si déplacement vélo sur trottoir et/ou si enfant
A8: Comptabiliser en bas de la grille si 2 roues hors vélo qui ne sont pas cochés dans la grille (trottinette, skate, ets)
C10: D’Eteaux vers | O10: De av Lucien Rannard vers
C11: Av L Rannard | G11: Av J Jaurès | K11: Gare/av Gare | O11: Av J Jaurès | S11: Gare/av Gare | W11: Eteaux
C12: H | E12: F | G12: H | I12: F | K12: H | M12: F | O12: H | Q12: F | S12: H | U12: F | W12: H | Y12: F
A13: Période | C13: VAE | D13: vélo | E13: VAE | F13: vélo | G13: VAE | H13: vélo | I13: VAE | J13: vélo | K13: VAE | L13: vélo | M13: VAE | N13: vélo | O13: VAE | P13: vélo | Q13: VAE | R13: vélo | S13: VAE | T13: vélo | U13: VAE | V13: vélo | W13: VAE | X13: vélo | Y13: VAE | Z13: vélo
A14: 0.27083333 | B14: 0.29166667 | D14: 1 | G14: 1 | L14: 2
A15: 0.29166667 | B15: 0.3125 | L15: 2 | M15: 2 | T15: 2
A16: 0.3125 | B16: 0.33333333 | C16: 2 | D16: 2 | G16: 1 | H16: 1 | S16: 1
A17: 0.33333333 | B17: 0.34722222 | D17: 1 | E17: 1 | H17: 1 | M17: 1 | N17: 1 | P17: 1 | T17: 1
C20: De av J Jaurès vers | O20: De Gare et av Gare vers
C21: Gare/av Gare | G21: Eteaux | K21: Av L Rannard | O21: Eteaux | S21: Av L Rannard | W21: Av J Jaurès
C22: H | E22: F | G22: H | I22: F | K22: H | M22: F | O22: H | Q22: F | S22: H | U22: F | W22: H | Y22: F
A23: Période | C23: VAE | D23: vélo | E23: VAE | F23: vélo | G23: VAE | H23: vélo | I23: VAE | J23: vélo | K23: VAE | L23: vélo | M23: VAE | N23: vélo | O23: VAE | P23: vélo | Q23: VAE | R23: vélo | S23: VAE | T23: vélo | U23: VAE | V23: vélo | W23: VAE | X23: vélo | Y23: VAE | Z23: vélo
A24: 0.27083333 | B24: 0.29166667 | D24: 1 | L24: 2 | P24: 1 | T24: 1 | X24: 1
A25: 0.29166667 | B25: 0.3125 | C25: 3 | D25: 3 | E25: 1 | F25: 1 | K25: 2 | P25: 1 | T25: 1
A26: 0.3125 | B26: 0.33333333 | E26: 1 | H26: 2 | J26: 1 | L26: 2 | P26: 1
A27: 0.33333333 | B27: 0.34722222 | C27: 1 | D27: 2 | H27: 1
A30: 4 | B30: dont Enfant
A31: 3 | B31: vélo sur trottoir
B32: dont Cyclo sportifs
A33: 17 | B33: hors grille, plus 2 roues hors vélo (trottinette, skate...) | M33: 17
AC35: TOTAL | AD35: Nombre de VAE dans le total | AE35: Nombre de femmes dans le total | AF35: Nombre de VAE chez les femmes | AG35: Cycles sur route de Reignier
C37: H | E37: F
A38: Période | C38: VAE | D38: vélo | E38: VAE | F38: vélo | AA38: Période | AH38: plus trotinette skate | AI38: dont enfant | AJ38: vélo sur trottoir | AK38: dont cyclo
A39: 6:30 à 7:00 | C39: =C14+G14+K14+O14+S14+W14+C24+G24+K24+O24+S24+W24 -> 1 | D39: =D14+H14+L14+P14+T14+X14+D24+H24+L24+P24+T24+X24 -> 9 | E39: =E14+I14+M14+Q14+U14+Y14+E24+I24+M24+Q24+U24+Y24 -> 0 | F39: =F14+J14+N14+R14+V14+Z14+F24+J24+N24+R24+V24+Z24 -> 0 | AA39: =A39 -> 6:30 à 7:00 | AC39: =SUM(C39:Z39) -> 10 | AD39: =C39+E39 -> 1 | AE39: =E39+F39 -> 0 | AF39: =E39 -> 0
A40: 7:00 à 7:30 | C40: =C15+G15+K15+O15+S15+W15+C25+G25+K25+O25+S25+W25 -> 5 | D40: =D15+H15+L15+P15+T15+X15+D25+H25+L25+P25+T25+X25 -> 9 | E40: =E15+I15+M15+Q15+U15+Y15+E25+I25+M25+Q25+U25+Y25 -> 3 | F40: =F15+J15+N15+R15+V15+Z15+F25+J25+N25+R25+V25+Z25 -> 1 | AA40: =A40 -> 7:00 à 7:30 | AC40: =SUM(C40:Z40) -> 18 | AD40: =C40+E40 -> 8 | AE40: =E40+F40 -> 4 | AF40: =E40 -> 3
A41: 7:30 à 8:00 | C41: =C16+G16+K16+O16+S16+W16+C26+G26+K26+O26+S26+W26 -> 4 | D41: =D16+H16+L16+P16+T16+X16+D26+H26+L26+P26+T26+X26 -> 8 | E41: =E16+I16+M16+Q16+U16+Y16+E26+I26+M26+Q26+U26+Y26 -> 1 | F41: =F16+J16+N16+R16+V16+Z16+F26+J26+N26+R26+V26+Z26 -> 1 | AA41: =A41 -> 7:30 à 8:00 | AC41: =SUM(C41:Z41) -> 14 | AD41: =C41+E41 -> 5 | AE41: =E41+F41 -> 2 | AF41: =E41 -> 1
A42: 8:00 à 8:20 | C42: =C17+G17+K17+O17+S17+W17+C27+G27+K27+O27+S27+W27 -> 1 | D42: =D17+H17+L17+P17+T17+X17+D27+H27+L27+P27+T27+X27 -> 7 | E42: =E17+I17+M17+Q17+U17+Y17+E27+I27+M27+Q27+U27+Y27 -> 2 | F42: =F17+J17+N17+R17+V17+Z17+F27+J27+N27+R27+V27+Z27 -> 1 | AA42: =A42 -> 8:00 à 8:20 | AC42: =SUM(C42:Z42) -> 11 | AD42: =C42+E42 -> 3 | AE42: =E42+F42 -> 3 | AF42: =E42 -> 2
C43: =C18+G18+K18+O18+S18+W18+C28+G28+K28+O28+S28+W28 -> 0 | D43: =D18+H18+L18+P18+T18+X18+D28+H28+L28+P28+T28+X28 -> 0 | E43: =E18+I18+M18+Q18+U18+Y18+E28+I28+M28+Q28+U28+Y28 -> 0 | F43: =F18+J18+N18+R18+V18+Z18+F28+J28+N28+R28+V28+Z28 -> 0 | AA43: =A43 -> 0 | AC43: =SUM(C43:Z43) -> 0 | AD43: =C43+E43 -> 0 | AE43: =E43+F43 -> 0 | AF43: =E43 -> 0
A44: TOTAL | C44: =SUM(C14:C18) -> 2 | D44: =SUM(D14:D18) -> 4 | E44: =SUM(E14:E18) -> 1 | F44: =SUM(F14:F18) -> 0 | AA44: TOTAL | AC44: =SUM(AC39:AC43) -> 53 | AD44: =SUM(AD39:AD43) -> 17 | AE44: =SUM(AE39:AE43) -> 9 | AF44: =SUM(AF39:AF43) -> 6 | AG44: =SUM(AG39:AG43) -> 0 | AH44: =A33 -> 17 | AI44: =A30 -> 4 | AJ44: =A31 -> 3 | AK44: =A32 -> 0
Z45: H POINTE | AA45: 7:00 à 7:30 | AC45: 18
Z46: H POINTE | AA46: 7:30 à 8:00 | AC46: 14
AA47: Total H pointe | AC47: =SUM(AC45:AC46) -> 32
Z48: H POINTE | AA48: =IF($AC$39=MAX($AC$39:$AC$43),AA39,IF($AC$40=MAX($AC$39:$AC$43),AA40,IF($AC$41=MAX($AC$39:$AC$43),AA41,IF($AC$42=MAX($AC$39:$AC$43),AA42,IF($AC$43=MAX($AC$39:$AC$43),AA43,AA42))))) -> 7:00 à 7:30 | AC48: =IF($AC$39=MAX($AC$39:$AC$43),AC39,IF($AC$40=MAX($AC$39:$AC$43),AC40,IF($AC$41=MAX($AC$39:$AC$43),AC41,IF($AC$42=MAX($AC$39:$AC$43),AC42,IF($AC$43=MAX($AC$39:$AC$43),AC43,AC42))))) -> 18 | AD48: =IF($AC$39=MAX($AC$39:$AC$43),AD39,IF($AC$40=MAX($AC$39:$AC$43),AD40,IF($AC$41=MAX($AC$39:$AC$43),AD41,IF($AC$42=MAX($AC$39:$AC$43),AD42,IF($AC$43=MAX($AC$39:$AC$43),AD43,AD42))))) -> 8 | AE48: =IF($AC$39=MAX($AC$39:$AC$43),AE39,IF($AC$40=MAX($AC$39:$AC$43),AE40,IF($AC$41=MAX($AC$39:$AC$43),AE41,IF($AC$42=MAX($AC$39:$AC$43),AE42,IF($AC$43=MAX($AC$39:$AC$43),AE43,AE42))))) -> 4 | AF48: =IF($AC$39=MAX($AC$39:$AC$43),AF39,IF($AC$40=MAX($AC$39:$AC$43),AF40,IF($AC$41=MAX($AC$39:$AC$43),AF41,IF($AC$42=MAX($AC$39:$AC$43),AF42,IF($AC$43=MAX($AC$39:$AC$43),AF43,AF42))))) -> 3 | AG48: =IF($AC$39=MAX($AC$39:$AC$43),AG39,IF($AC$40=MAX($AC$39:$AC$43),AG40,IF($AC$41=MAX($AC$39:$AC$43),AG41,IF($AC$42=MAX($AC$39:$AC$43),AG42,IF($AC$43=MAX($AC$39:$AC$43),AG43,AG42))))) -> 0
...

Sheet LA RO ANDREV 23
B1: La Roche Andrevetan | G1: Date :
A2: Nom des personnes participant au comptage :
A3: Météo : | G3: Remarques :
A5: PRINCIPE D’UTILISATION : pour chaque intervalle de temps, comptabiliser VAE/vélo dans la colonne H/F
A6: Rajouter aussi en bas de la feuille si déplacement vélo sur trottoir et/ou si enfant
A7: Comptabiliser en bas de la grille si 2 roues hors vélo qui ne sont pas cochés dans la grille (trottinette, skate, ets)
C9: Rue de La Patience
C10: Vers La Roche | G10: Vers St Pierre
C11: H | E11: F | G11: H | I11: F
A12: Période | C12: VAE | D12: vélo | E12: VAE | F12: vélo | G12: VAE | H12: vélo | I12: VAE | J12: vélo
A13: 0.27083333 | B13: 0.29166667 | C13: 1 | G13: 1
A14: 0.29166667 | B14: 0.3125 | C14: 1
A15: 0.3125 | B15: 0.33333333 | C15: 2 | D15: 3 | G15: 3 | H15: 1
A16: 0.33333333 | B16: 0.35416667 | C16: 4 | D16: 1
A17: 0.35416667 | B17: 0.375 | D17: 2 | E17: 2 | H17: 5
B19: dont Enfant
B20: vélo sur trottoir
B21: dont Cyclo sportifs
A22: 6 | B22: hors grille, plus 2 roues hors vélo (trottinette, skate...)
C24: =C9 -> Rue de La Patience | M24: TOTAL | N24: Nombre de VAE dans le total | O24: Nombre de femmes dans le total | P24: Nombre de VAE chez les femmes | R24: plus trotinette skate | S24: dont enfant | T24: vélo sur trottoir | U24: dont cyclo
C25: =C10 -> Vers La Roche | G25: =G10 -> Vers St Pierre
C26: H | E26: F | G26: H | I26: F
A27: Période | C27: VAE | D27: vélo | E27: VAE | F27: vélo | G27: VAE | H27: vélo | I27: VAE | J27: vélo | K27: Période
A28: 6:30 à 7:00 | C28: =+C13 -> 1 | D28: =+D13 -> 0 | E28: =+E13 -> 0 | F28: =+F13 -> 0 | G28: =+G13 -> 1 | H28: =+H13 -> 0 | I28: =+I13 -> 0 | J28: =+J13 -> 0 | K28: =A28 -> 6:30 à 7:00 | M28: =SUM(C28:J28) -> 2 | N28: =C28+E28+G28+I28 -> 2 | O28: =E28+F28+I28+J28 -> 0 | P28: =E28+I28 -> 0
A29: 7:00 à 7:30 | C29: =+C14 -> 1 | D29: =+D14 -> 0 | E29: =+E14 -> 0 | F29: =+F14 -> 0 | G29: =+G14 -> 0 | H29: =+H14 -> 0 | I29: =+I14 -> 0 | J29: =+J14 -> 0 | K29: =A29 -> 7:00 à 7:30 | M29: =SUM(C29:J29) -> 1 | N29: =C29+E29+G29+I29 -> 1 | O29: =E29+F29+I29+J29 -> 0 | P29: =E29+I29 -> 0
A30: 7:30 à 8:00 | C30: =+C15 -> 2 | D30: =+D15 -> 3 | E30: =+E15 -> 0 | F30: =+F15 -> 0 | G30: =+G15 -> 3 | H30: =+H15 -> 1 | I30: =+I15 -> 0 | J30: =+J15 -> 0 | K30: =A30 -> 7:30 à 8:00 | M30: =SUM(C30:J30) -> 9 | N30: =C30+E30+G30+I30 -> 5 | O30: =E30+F30+I30+J30 -> 0 | P30: =E30+I30 -> 0
A31: 8:00 à 8:30 | C31: =+C16 -> 4 | D31: =+D16 -> 1 | E31: =+E16 -> 0 | F31: =+F16 -> 0 | G31: =+G16 -> 0 | H31: =+H16 -> 0 | I31: =+I16 -> 0 | J31: =+J16 -> 0 | K31: =A31 -> 8:00 à 8:30 | M31: =SUM(C31:J31) -> 5 | N31: =C31+E31+G31+I31 -> 4 | O31: =E31+F31+I31+J31 -> 0 | P31: =E31+I31 -> 0
A32: 8:30 à 9:00 | C32: =+C17 -> 0 | D32: =+D17 -> 2 | E32: =+E17 -> 2 | F32: =+F17 -> 0 | G32: =+G17 -> 0 | H32: =+H17 -> 5 | I32: =+I17 -> 0 | J32: =+J17 -> 0 | K32: =A32 -> 8:30 à 9:00 | M32: =SUM(C32:J32) -> 9 | N32: =C32+E32+G32+I32 -> 2 | O32: =E32+F32+I32+J32 -> 2 | P32: =E32+I32 -> 2
A33: TOTAL | C33: =SUM(C13:C17) -> 8 | D33: =SUM(D13:D17) -> 6 | E33: =SUM(E13:E17) -> 2 | F33: =SUM(F13:F17) -> 0 | G33: =SUM(G13:G17) -> 4 | H33: =SUM(H13:H17) -> 6 | I33: =SUM(I13:I17) -> 0 | J33: =SUM(J13:J17) -> 0 | K33: TOTAL | M33: =SUM(C33:J33) -> 26 | N33: =N32+N31+N30+N29+N28 -> 14 | O33: =O32+O31+O30+O29+O28 -> 2 | P33: =P32+P31+P30+P29+P28 -> 2 | R33: =A22 -> 6 | S33: =A19 -> 0 | T33: =A20 -> 0 | U33: =A21 -> 0
J34: H POINTE | K34: 8:00 à 8:30 | M34: 5
J35: H POINTE | K35: 8:30 à 9:00 | M35: 9
K36: Total H pointe | M36: =SUM(M34:M35) -> 14
J37: H POINTE | K37: =IF($M$32=MAX($M$28:$M$32),K32,IF($M$31=MAX($M$28:$M$32),K31,IF($M$30=MAX($M$28:$M$32),K30,IF($M$29=MAX($M$28:$M$32),K29,IF($M$28=MAX($M$28:$M$32),K28,K32))))) -> 8:30 à 9:00 | M37: =IF($M$32=MAX($M$28:$M$32),M32,IF($M$31=MAX($M$28:$M$32),M31,IF($M$30=MAX($M$28:$M$32),M30,IF($M$29=MAX($M$28:$M$32),M29,IF($M$28=MAX($M$28:$M$32),M28,M32))))) -> 9 | N37: =IF($M$32=MAX($M$28:$M$32),N32,IF($M$31=MAX($M$28:$M$32),N31,IF($M$30=MAX($M$28:$M$32),N30,IF($M$29=MAX($M$28:$M$32),N29,IF($M$28=MAX($M$28:$M$32),N28,N32))))) -> 2 | O37: =IF($M$32=MAX($M$28:$M$32),O32,IF($M$31=MAX($M$28:$M$32),O31,IF($M$30=MAX($M$28:$M$32),O30,IF($M$29=MAX($M$28:$M$32),O29,IF($M$28=MAX($M$28:$M$32),O28,O32))))) -> 2 | P37: =IF($M$32=MAX($M$28:$M$32),P32,IF($M$31=MAX($M$28:$M$32),P31,IF($M$30=MAX($M$28:$M$32),P30,IF($M$29=MAX($M$28:$M$32),P29,IF($M$28=MAX($M$28:$M$32),P28,P32))))) -> 2
M38: TOTAL | N38: Part des VAE dans le total | O38: Part des femmes dans le total | P38: Part des VAE chez les femmes
K41: Période
K42: =K28 -> 6:30 à 7:00 | N42: =IF(N28=0,0,N28/M28) -> 1 | O42: =IF(O28=0,0,O28/M28) -> 0 | P42: =IF(P28=0,0,P28/N28) -> 0
K43: =K29 -> 7:00 à 7:30 | N43: =IF(N30=0,0,N30/M30) -> 0.55555556 | O43: =IF(O30=0,0,O30/M30) -> 0 | P43: =IF(P30=0,0,P30/N30) -> 0
K44: =K30 -> 7:30 à 8:00 | N44: =IF(N30=0,0,N30/M30) -> 0.55555556 | O44: =IF(O30=0,0,O30/M30) -> 0 | P44: =IF(P30=0,0,P30/N30) -> 0
K45: =K31 -> 8:00 à 8:30 | N45: =IF(N31=0,0,N31/M31) -> 0.8 | O45: =IF(O31=0,0,O31/M31) -> 0 | P45: =IF(P31=0,0,P31/N31) -> 0
K46: =K32 -> 8:30 à 9:00 | N46: =IF(N32=0,0,N32/M32) -> 0.22222222 | O46: =IF(O32=0,0,O32/M32) -> 0.22222222 | P46: =IF(P32=0,0,P32/N32) -> 1
...

Sheet LA RO ANDREV 24
B1: La Roche Andrevetan | E1: Rue Patience/St Sixt | K1: Date :
A2: Nom des personnes participant au comptage :
A3: Météo : | K3: Remarques :
A5: PRINCIPE D’UTILISATION : pour chaque intervalle de temps, comptabiliser VAE/vélo dans la colonne H/F
A6: Rajouter aussi en bas de la feuille si déplacement vélo sur trottoir et/ou si enfant
A7: Comptabiliser en bas de la grille si 2 roues hors vélo qui ne sont pas cochés dans la grille (trottinette, skate, ets)
C9: De La Roche vers | K9: De St Pierre rue Patience vers
C10: St Pierre/ Rue Patience | G10: St Sixt | K10: La Roche | O10: St Sixt
C11: H | E11: F | G11: H | I11: F | K11: H | M11: F | O11: H | Q11: F
A12: Période | C12: VAE | D12: vélo | E12: VAE | F12: vélo | G12: VAE | H12: vélo | I12: VAE | J12: vélo | K12: VAE | L12: vélo | M12: VAE | N12: vélo | O12: VAE | P12: vélo | Q12: VAE | R12: vélo
A13: 0.27083333 | B13: 0.29166667 | C13: 1
A14: 0.29166667 | B14: 0.3125
A15: 0.3125 | B15: 0.33333333 | C15: 3 | D15: 1 | K15: 1 | L15: 3
A16: 0.33333333 | B16: 0.35416667 | H16: 1
A17: 0.35416667 | B17: 0.375 | D17: 5 | L17: 1 | M17: 2
C19: De St Sixt vers
C20: Rue Patience | G20: La Roche
C21: H | E21: F | G21: H | I21: F
A22: Période | C22: VAE | D22: vélo | E22: VAE | F22: vélo | G22: VAE | H22: vélo | I22: VAE | J22: vélo
A23: 0.27083333 | B23: 0.29166667 | G23: 1
A24: 0.29166667 | B24: 0.3125 | G24: 1
A25: 0.3125 | B25: 0.33333333 | C25: 1 | G25: 1 | M25: Jacqueline a utilisé l'autre fiche de comptage
A26: 0.33333333 | B26: 0.35416667 | M26: Axe St Sixt / La Roche = 8
A27: 0.35416667 | B27: 0.375 | C27: 1 | G27: 1 | I27: 2 | M27: Axe St Sixt / St Pierre = 2
B29: dont Enfant
B30: vélo sur trottoir
B31: dont Cyclo sportifs
A32: 6 | B32: hors grille, plus 2 roues hors vélo (trottinette, skate...) | F32: 6
M34: TOTAL | N34: Nombre de VAE dans le total | O34: Nombre de femmes dans le total | P34: Nombre de VAE chez les femmes | R34: dont enfant | S34: vélo sur trottoir | T34: dont cyclo | U34: plus trotinette skate
C36: H | E36: F
A37: Période | C37: VAE | D37: vélo | E37: VAE | F37: vélo | K37: Période
A38: 6:30 à 7:00 | C38: =C13+G13+K13+O13+C23+G23 -> 2 | D38: =D13+H13+L13+P13+D23+H23 -> 0 | E38: =E13+I13+M13+Q13+E23+I23 -> 0 | F38: =F13+J13+N13+R13+F23+J23 -> 0 | K38: =A38 -> 6:30 à 7:00 | M38: =SUM(C38:J38) -> 2 | N38: =C38+E38 -> 2 | O38: =E38+F38 -> 0 | P38: =F38 -> 0 | Q38: =SUM(G38:J38) -> 0
A39: 7:00 à 7:30 | C39: =C14+G14+K14+O14+C24+G24 -> 1 | D39: =D14+H14+L14+P14+D24+H24 -> 0 | E39: =E14+I14+M14+Q14+E24+I24 -> 0 | F39: =F14+J14+N14+R14+F24+J24 -> 0 | K39: =A39 -> 7:00 à 7:30 | M39: =SUM(C39:J39) -> 1 | N39: =C39+E39 -> 1 | O39: =E39+F39 -> 0 | P39: =F39 -> 0 | Q39: =SUM(G39:J39) -> 0
A40: 7:30 à 8:00 | C40: =C15+G15+K15+O15+C25+G25 -> 6 | D40: =D15+H15+L15+P15+D25+H25 -> 4 | E40: =E15+I15+M15+Q15+E25+I25 -> 0 | F40: =F15+J15+N15+R15+F25+J25 -> 0 | K40: =A40 -> 7:30 à 8:00 | M40: =SUM(C40:J40) -> 10 | N40: =C40+E40 -> 6 | O40: =E40+F40 -> 0 | P40: =F40 -> 0 | Q40: =SUM(G40:J40) -> 0
A41: 8:00 à 8:30 | C41: =C16+G16+K16+O16+C26+G26 -> 0 | D41: =D16+H16+L16+P16+D26+H26 -> 1 | E41: =E16+I16+M16+Q16+E26+I26 -> 0 | F41: =F16+J16+N16+R16+F26+J26 -> 0 | K41: =A41 -> 8:00 à 8:30 | M41: =SUM(C41:J41) -> 1 | N41: =C41+E41 -> 0 | O41: =E41+F41 -> 0 | P41: =F41 -> 0 | Q41: =SUM(G41:J41) -> 0
A42: 8:30 à 9:00 | C42: =C17+G17+K17+O17+C27+G27 -> 2 | D42: =D17+H17+L17+P17+D27+H27 -> 6 | E42: =E17+I17+M17+Q17+E27+I27 -> 4 | F42: =F17+J17+N17+R17+F27+J27 -> 0 | K42: =A42 -> 8:30 à 9:00 | M42: =SUM(C42:J42) -> 12 | N42: =C42+E42 -> 6 | O42: =E42+F42 -> 4 | P42: =F42 -> 0 | Q42: =SUM(G42:J42) -> 0
A43: TOTAL | C43: =SUM(C38:C42) -> 11 | D43: =SUM(D38:D42) -> 11 | E43: =SUM(E38:E42) -> 4 | F43: =SUM(F38:F42) -> 0 | K43: TOTAL | M43: =SUM(C43:J43) -> 26 | N43: =N42+N41+N40+N39+N38 -> 15 | O43: =O42+O41+O40+O39+O38 -> 4 | P43: =P42+P41+P40+P39+P38 -> 0 | Q43: =Q42+Q40+Q38 -> 0 | R43: =A29 -> 0 | S43: =A30 -> 0 | T43: =A31 -> 0 | U43: =A32 -> 6
J47: H POINTE | K47: =IF($M$42=MAX($M$38:$M$42),K42,IF($M$41=MAX($M$38:$M$42),K41,IF($M$40=MAX($M$38:$M$42),K40,IF($M$39=MAX($M$38:$M$42),K39,IF($M$38=MAX($M$38:$M$42),K38,K42))))) -> 8:30 à 9:00 | M47: =IF($M$42=MAX($M$38:$M$42),M42,IF($M$41=MAX($M$38:$M$42),M41,IF($M$40=MAX($M$38:$M$42),M40,IF($M$39=MAX($M$38:$M$42),M39,IF($M$38=MAX($M$38:$M$42),M38,M42))))) -> 12 | N47: =IF($M$42=MAX($M$38:$M$42),N42,IF($M$41=MAX($M$38:$M$42),N41,IF($M$40=MAX($M$38:$M$42),N40,IF($M$39=MAX($M$38:$M$42),N39,IF($M$38=MAX($M$38:$M$42),N38,N42))))) -> 6 | O47: =IF($M$42=MAX($M$38:$M$42),O42,IF($M$41=MAX($M$38:$M$42),O41,IF($M$40=MAX($M$38:$M$42),O40,IF($M$39=MAX($M$38:$M$42),O39,IF($M$38=MAX($M$38:$M$42),O38,O42))))) -> 4 | P47: =IF($M$42=MAX($M$38:$M$42),P42,IF($M$41=MAX($M$38:$M$42),P41,IF($M$40=MAX($M$38:$M$42),P40,IF($M$39=MAX($M$38:$M$42),P39,IF($M$38=MAX($M$38:$M$42),P38,P42))))) -> 0 | Q47: =IF($M$42=MAX($M$38:$M$42),Q42,IF($M$41=MAX($M$38:$M$42),Q41,IF($M$40=MAX($M$38:$M$42),Q40,IF($M$39=MAX($M$38:$M$42),Q39,IF($M$38=MAX($M$38:$M$42),Q38,Q42))))) -> 0
M48: TOTAL | N48: Part des VAE dans le total | O48: Part des femmes dans le total | P48: Part des VAE chez les femmes | Q48: =Q34 -> 0 | R48: Remarque
K51: Période
...

Sheet ARENT_PAPETERIE
B1: Arenthon La Papeterie | O1: Date :
A2: Nom des personnes participant au comptage :
A3: Météo : | N3: Remarques :
A5: PRINCIPE D’UTILISATION : pour chaque intervalle de temps, comptabiliser VAE/vélo dans la colonne H/F
A6: Rajouter aussi en bas de la feuille si enfant
A7: Comptabiliser en bas de la grille si 2 roues hors vélo qui ne sont pas cochés dans la grille (trottinette, skate, ets)
C9: De Arenthon vers | O9: De Bonneville vers
C10: Bonneville | G10: TNA | K10: Rte Papeterie | O10: TNA | S10: Arenthon | W10: Rte Papeterie
C11: H | E11: F | G11: H | I11: F | K11: H | M11: F | O11: H | Q11: F | S11: H | U11: F | W11: H | Y11: F
A12: Période | C12: VAE | D12: vélo | E12: VAE | F12: vélo | G12: VAE | H12: vélo | I12: VAE | J12: vélo | K12: VAE | L12: vélo | M12: VAE | N12: vélo | O12: VAE | P12: vélo | Q12: VAE | R12: vélo | S12: VAE | T12: vélo | U12: VAE | V12: vélo | W12: VAE | X12: vélo | Y12: VAE | Z12: vélo
A13: 0.27083333 | B13: 0.29166667 | C13: 1 | E13: 1
A14: 0.29166667 | B14: 0.3125 | C14: 1 | P14: 1 | X14: 1
A15: 0.3125 | B15: 0.33333333 | D15: 1 | N15: 1 | P15: 1 | T15: 1
A16: 0.33333333 | B16: 0.35416667 | C16: 1
A17: 0.35416667 | B17: 0.375 | H17: 1 | X17: 2
C19: De Rte Papeterie vers | O19: De TNA vers
C20: Arenthon | G20: TNA | K20: Bonneville | O20: Bonneville | S20: Arenthon | W20: Rte Papeterie
C21: H | E21: F | G21: H | I21: F | K21: H | M21: F | O21: H | Q21: F | S21: H | U21: F | W21: H | Y21: F
A22: Période | C22: VAE | D22: vélo | E22: VAE | F22: vélo | G22: VAE | H22: vélo | I22: VAE | J22: vélo | K22: VAE | L22: vélo | M22: VAE | N22: vélo | O22: VAE | P22: vélo | Q22: VAE | R22: vélo | S22: VAE | T22: vélo | U22: VAE | V22: vélo | W22: VAE | X22: vélo | Y22: VAE | Z22: vélo
A23: 0.27083333 | B23: 0.29166667 | G23: 1 | L23: 1 | X23: 1
A24: 0.29166667 | B24: 0.3125 | H24: 1 | M24: 1 | O24: 1
A25: 0.3125 | B25: 0.33333333 | H25: 1 | L25: 1 | P25: 1 | W25: 1
A26: 0.33333333 | B26: 0.35416667 | H26: 1 | M26: 1
A27: 0.35416667 | B27: 0.375 | P27: 1
A29: 1 | B29: dont Enfant
B30: vélo sur trottoir
A31: 3 | B31: dont Cyclo sportifs
A32: 1 | B32: hors grille, plus 2 roues hors vélo (trottinette, skate...)
C34: H | E34: F
A35: Période | C35: VAE | D35: vélo | E35: VAE | F35: vélo | AA35: Période | AC35: TOTAL | AD35: Nombre de VAE dans le total | AE35: Nombre de femmes dans le total | AF35: Nombre de VAE chez les femmes | AG35: plus trotinette skate | AH35: dont enfant | AI35: vélo sur trottoir | AJ35: dont cyclo
A36: 6:30 à 7:00 | C36: =C13+G13+K13+O13+S13+W13+C23+G23+K23+O23+S23+W23 -> 2 | D36: =D13+H13+L13+P13+T13+X13+D23+H23+L23+P23+T23+X23 -> 2 | E36: =E13+I13+M13+Q13+U13+Y13+E23+I23+M23+Q23+U23+Y23 -> 1 | F36: =F13+J13+N13+R13+V13+Z13+F23+J23+N23+R23+V23+Z23 -> 0 | AA36: =A36 -> 6:30 à 7:00 | AC36: =SUM(C36:Z36) -> 5 | AD36: =C36+E36 -> 3 | AE36: =E36+F36 -> 1 | AF36: =E36 -> 1
A37: 7:00 à 7:30 | C37: =C14+G14+K14+O14+S14+W14+C24+G24+K24+O24+S24+W24 -> 2 | D37: =D14+H14+L14+P14+T14+X14+D24+H24+L24+P24+T24+X24 -> 3 | E37: =E14+I14+M14+Q14+U14+Y14+E24+I24+M24+Q24+U24+Y24 -> 1 | F37: =F14+J14+N14+R14+V14+Z14+F24+J24+N24+R24+V24+Z24 -> 0 | AA37: =A37 -> 7:00 à 7:30 | AC37: =SUM(C37:Z37) -> 6 | AD37: =C37+E37 -> 3 | AE37: =E37+F37 -> 1 | AF37: =E37 -> 1
A38: 7:30 à 8:00 | C38: =C15+G15+K15+O15+S15+W15+C25+G25+K25+O25+S25+W25 -> 1 | D38: =D15+H15+L15+P15+T15+X15+D25+H25+L25+P25+T25+X25 -> 6 | E38: =E15+I15+M15+Q15+U15+Y15+E25+I25+M25+Q25+U25+Y25 -> 0 | F38: =F15+J15+N15+R15+V15+Z15+F25+J25+N25+R25+V25+Z25 -> 1 | AA38: =A38 -> 7:30 à 8:00 | AC38: =SUM(C38:Z38) -> 8 | AD38: =C38+E38 -> 1 | AE38: =E38+F38 -> 1 | AF38: =E38 -> 0
A39: 8:00 à 8:30 | C39: =C16+G16+K16+O16+S16+W16+C26+G26+K26+O26+S26+W26 -> 1 | D39: =D16+H16+L16+P16+T16+X16+D26+H26+L26+P26+T26+X26 -> 1 | E39: =E16+I16+M16+Q16+U16+Y16+E26+I26+M26+Q26+U26+Y26 -> 1 | F39: =F16+J16+N16+R16+V16+Z16+F26+J26+N26+R26+V26+Z26 -> 0 | AA39: =A39 -> 8:00 à 8:30 | AC39: =SUM(C39:Z39) -> 3 | AD39: =C39+E39 -> 2 | AE39: =E39+F39 -> 1 | AF39: =E39 -> 1
A40: 8:30 à 9:00 | C40: =C17+G17+K17+O17+S17+W17+C27+G27+K27+O27+S27+W27 -> 0 | D40: =D17+H17+L17+P17+T17+X17+D27+H27+L27+P27+T27+X27 -> 4 | E40: =E17+I17+M17+Q17+U17+Y17+E27+I27+M27+Q27+U27+Y27 -> 0 | F40: =F17+J17+N17+R17+V17+Z17+F27+J27+N27+R27+V27+Z27 -> 0 | AA40: 8:30 à 9:00 | AC40: =SUM(C40:Z40) -> 4 | AD40: =C40+E40 -> 0 | AE40: =E40+F40 -> 0 | AF40: =E40 -> 0
A41: TOTAL | C41: =SUM(C13:C17) -> 3 | D41: =SUM(D13:D17) -> 1 | E41: =SUM(E13:E17) -> 1 | F41: =SUM(F13:F17) -> 0 | AA41: TOTAL | AC41: =SUM(AC36:AC40) -> 26 | AD41: =SUM(AD36:AD40) -> 9 | AE41: =SUM(AE36:AE40) -> 4 | AF41: =SUM(AF36:AF40) -> 3 | AG41: 1 | AH41: 1 | AI41: =A30 -> 0 | AJ41: 3
AA42: 7:00 à 7:30 | AC42: 6
AA43: 7:30 à 8:00 | AC43: 8
AA44: Total H pointe | AC44: =SUM(AC42:AC43) -> 14
Z45: H POINTE | AA45: =IF($AC$37=MAX($AC$36:$AC$40),AA37,IF($AC$38=MAX($AC$36:$AC$40),AA38,IF($AC$39=MAX($AC$36:$AC$40),AA39,IF($AC$40=MAX($AC$36:$AC$40),AA40,IF($AC$36=MAX($AC$36:$AC$40),AA36,AA39))))) -> 7:30 à 8:00 | AC45: =IF($AC$37=MAX($AC$36:$AC$40),AC37,IF($AC$38=MAX($AC$36:$AC$40),AC38,IF($AC$39=MAX($AC$36:$AC$40),AC39,IF($AC$40=MAX($AC$36:$AC$40),AC40,IF($AC$41=MAX($AC$36:$AC$40),AC41,AC39))))) -> 8 | AD45: =IF($AC$37=MAX($AC$36:$AC$40),AD37,IF($AC$38=MAX($AC$36:$AC$40),AD38,IF($AC$39=MAX($AC$36:$AC$40),AD39,IF($AC$40=MAX($AC$36:$AC$40),AD40,IF($AC$41=MAX($AC$36:$AC$40),AD41,AD39))))) -> 1 | AE45: =IF($AC$37=MAX($AC$36:$AC$40),AE37,IF($AC$38=MAX($AC$36:$AC$40),AE38,IF($AC$39=MAX($AC$36:$AC$40),AE39,IF($AC$40=MAX($AC$36:$AC$40),AE40,IF($AC$41=MAX($AC$36:$AC$40),AE41,AE39))))) -> 1 | AF45: =IF($AC$37=MAX($AC$36:$AC$40),AF37,IF($AC$38=MAX($AC$36:$AC$40),AF38,IF($AC$39=MAX($AC$36:$AC$40),AF39,IF($AC$40=MAX($AC$36:$AC$40),AF40,IF($AC$41=MAX($AC$36:$AC$40),AF41,AF39))))) -> 0
...

Sheet ST_PI_BORNE_DESSY
B1: St Pierre Franchissement du Borne Dessy | O1: Date : | P1: 45085
A2: Nom des personnes participant au comptage : | H2: SS
A3: Météo : | C3: SOLEIL | P3: Remarques :
A5: PRINCIPE D’UTILISATION : pour chaque intervalle de temps, comptabiliser VAE/vélo dans la colonne H/F
A6: Rajouter aussi en bas de la feuille si enfant
A7: Comptabiliser en bas de la grille si 2 roues hors vélo qui ne sont pas cochés dans la grille (trottinette, skate, ets)
C9: De Rte Gorges du Borne vers | K9: De Avenue des Digues vers | S9: De Avenue de Monaz vers
C10: Av des Digues | G10: Av Monaz | K10: Av Monaz | O10: Rte Gorges du Borne | S10: Rte Gorges du Borne | W10: Av des Digues
C11: H | E11: F | G11: H | I11: F | K11: H | M11: F | O11: H | Q11: F | S11: H | U11: F | W11: H | Y11: F
A12: Période | C12: VAE | D12: vélo | E12: VAE | F12: vélo | G12: VAE | H12: vélo | I12: VAE | J12: vélo | K12: VAE | L12: vélo | M12: VAE | N12: vélo | O12: VAE | P12: vélo | Q12: VAE | R12: vélo | S12: VAE | T12: vélo | U12: VAE | V12: vélo | W12: VAE | X12: vélo | Y12: VAE | Z12: vélo
A13: 0.27083333 | B13: 0.29166667 | D13: 2 | G13: 1 | H13: 2 | S13: 1
A14: 0.29166667 | B14: 0.3125 | G14: 3 | H14: 1 | I14: 1 | J14: 1 | L14: 1 | T14: 1
A15: 0.3125 | B15: 0.33333333 | C15: 1 | D15: 2 | E15: 1 | F15: 1 | G15: 1 | H15: 3 | I15: 2 | J15: 2 | P15: 1 | S15: 1 | U15: 1 | Z15: 1
A16: 0.33333333 | B16: 0.35416667 | D16: 1 | F16: 1 | G16: 1 | H16: 3 | T16: 2
A17: 0.35416667 | B17: 0.375 | H17: 1 | L17: 2 | P17: 1 | T17: 4 | V17: 1 | Z17: 1
A19: 2 | B19: dont Enfant
B20: vélo sur trottoir
A21: 17 | B21: dont Cyclo sportifs
A22: 1 | B22: hors grille, plus 2 roues hors vélo (trottinette, skate...)
AC24: en jaune, tableau global Yannick
C25: =C9 -> De Rte Gorges du Borne vers | K25: =K9 -> De Avenue des Digues vers | S25: =S9 -> De Avenue de Monaz vers | AC25: TOTAL | AD25: Nombre de VAE dans le total | AE25: Nombre de femmes dans le total | AF25: Nombre de VAE chez les femmes | AK25: Cycles sur rte de Dessy | AL25: Cycles sur rte des Digues
C26: =C10 -> Av des Digues | G26: =G10 -> Av Monaz | K26: =K10 -> Av Monaz | O26: =O10 -> Rte Gorges du Borne | S26: =S10 -> Rte Gorges du Borne | W26: =W10 -> Av des Digues
C27: H | E27: F | G27: H | I27: F | K27: H | M27: F | O27: H | Q27: F | S27: H | U27: F | W27: H | Y27: F
A28: Période | C28: VAE | D28: vélo | E28: VAE | F28: vélo | G28: VAE | H28: vélo | I28: VAE | J28: vélo | K28: VAE | L28: vélo | M28: VAE | N28: vélo | O28: VAE | P28: vélo | Q28: VAE | R28: vélo | S28: VAE | T28: vélo | U28: VAE | V28: vélo | W28: VAE | X28: vélo | Y28: VAE | Z28: vélo | AA28: Période | AG28: plus trotinette skate | AH28: dont enfant | AI28: vélo sur trottoir | AJ28: dont cyclo
A29: 6:30 à 7:00 | C29: =C13 -> 0 | D29: =D13 -> 2 | E29: =E13 -> 0 | F29: =F13 -> 0 | G29: =G13 -> 1 | H29: =H13 -> 2 | I29: =I13 -> 0 | J29: =J13 -> 0 | ... Z29: =Z13 -> 0 | AA29: =A29 -> 6:30 à 7:00 | AC29: =SUM(C29:Z29) -> 6 | AD29: =C29+E29+G29+I29+K29+M29+O29+Q29+S29+U29+W29+Y29 -> 2 | AE29: =E29+F29+I29+J29+M29+N29+Q29+R29+U29+V29+Y29+Z29 -> 0 | AF29: =E29+I29+M29+Q29+U29+Y29 -> 0 | AK29: =SUM(G29:N29)+SUM(S29:Z29) -> 4 | AL29: =SUM(C29:F29)+SUM(W29:Z29)+SUM(K29:R29) -> 2
A30: 7:00 à 7:30 | C30: =C14 -> 0 | D30: =D14 -> 0 | E30: =E14 -> 0 | F30: =F14 -> 0 | G30: =G14 -> 3 | H30: =H14 -> 1 | I30: =I14 -> 1 | J30: =J14 -> 1 | ... Z30: =Z14 -> 0 | AA30: =A30 -> 7:00 à 7:30 | AC30: =SUM(C30:Z30) -> 8 | AD30: =C30+E30+G30+I30+K30+M30+O30+Q30+S30+U30+W30+Y30 -> 4 | AE30: =E30+F30+I30+J30+M30+N30+Q30+R30+U30+V30+Y30+Z30 -> 2 | AF30: =E30+I30+M30+Q30+U30+Y30 -> 1 | AK30: =SUM(G30:N30)+SUM(S30:Z30) -> 8 | AL30: =SUM(C30:F30)+SUM(W30:Z30)+SUM(K30:R30) -> 1
A31: 7:30 à 8:00 | C31: =C15 -> 1 | D31: =D15 -> 2 | E31: =E15 -> 1 | F31: =F15 -> 1 | G31: =G15 -> 1 | H31: =H15 -> 3 | I31: =I15 -> 2 | J31: =J15 -> 2 | ... Z31: =Z15 -> 1 | AA31: =A31 -> 7:30 à 8:00 | AC31: =SUM(C31:Z31) -> 17 | AD31: =C31+E31+G31+I31+K31+M31+O31+Q31+S31+U31+W31+Y31 -> 7 | AE31: =E31+F31+I31+J31+M31+N31+Q31+R31+U31+V31+Y31+Z31 -> 8 | AF31: =E31+I31+M31+Q31+U31+Y31 -> 4 | AK31: =SUM(G31:N31)+SUM(S31:Z31) -> 11 | AL31: =SUM(C31:F31)+SUM(W31:Z31)+SUM(K31:R31) -> 7
A32: 8:00 à 8:30 | C32: =C16 -> 0 | D32: =D16 -> 1 | E32: =E16 -> 0 | F32: =F16 -> 1 | G32: =G16 -> 1 | H32: =H16 -> 3 | I32: =I16 -> 0 | J32: =J16 -> 0 | ... Z32: =Z16 -> 0 | AA32: =A32 -> 8:00 à 8:30 | AC32: =SUM(C32:Z32) -> 8 | AD32: =C32+E32+G32+I32+K32+M32+O32+Q32+S32+U32+W32+Y32 -> 1 | AE32: =E32+F32+I32+J32+M32+N32+Q32+R32+U32+V32+Y32+Z32 -> 1 | AF32: =E32+I32+M32+Q32+U32+Y32 -> 0 | AK32: =SUM(G32:N32)+SUM(S32:Z32) -> 6 | AL32: =SUM(C32:F32)+SUM(W32:Z32)+SUM(K32:R32) -> 2
A33: 8:30 à 9:00 | C33: =C17 -> 0 | D33: =D17 -> 0 | E33: =E17 -> 0 | F33: =F17 -> 0 | G33: =G17 -> 0 | H33: =H17 -> 1 | I33: =I17 -> 0 | J33: =J17 -> 0 | ... Z33: =Z17 -> 1 | AA33: =A33 -> 8:30 à 9:00 | AC33: =SUM(C33:Z33) -> 10 | AD33: =C33+E33+G33+I33+K33+M33+O33+Q33+S33+U33+W33+Y33 -> 0 | AE33: =E33+F33+I33+J33+M33+N33+Q33+R33+U33+V33+Y33+Z33 -> 2 | AF33: =E33+I33+M33+Q33+U33+Y33 -> 0 | AK33: =SUM(G33:N33)+SUM(S33:Z33) -> 9 | AL33: =SUM(C33:F33)+SUM(W33:Z33)+SUM(K33:R33) -> 4
A34: TOTAL | C34: =SUM(C13:C17) -> 1 | D34: =SUM(D13:D17) -> 5 | E34: =SUM(E13:E17) -> 1 | F34: =SUM(F13:F17) -> 2 | G34: =SUM(G13:G17) -> 6 | H34: =SUM(H13:H17) -> 10 | I34: =SUM(I13:I17) -> 3 | J34: =SUM(J13:J17) -> 3 | ... Z34: =SUM(Z13:Z17) -> 2 | AA34: TOTAL | AC34: =SUM(C34:Z34) -> 49 | AD34: =AD29+AD30+AD31+AD32+AD33 -> 14 | AE34: =AE29+AE31+AE33 -> 10 | AF34: =AF29+AF31+AF33 -> 4 | AG34: =A22 -> 1 | AH34: =A19 -> 2 | AJ34: =A21 -> 17 | AK34: =AK29+AK31+AK33 -> 24 | AL34: =AL29+AL31+AL33 -> 13
AA35: 7:00 à 7:30 | AC35: 8
AA36: 7:30 à 8:00 | AC36: 17
AA37: Total H pointe | AC37: =SUM(AC35:AC36) -> 25
Z38: H POINTE | AA38: 7:00 à 7:30 | AC38: =IF($AC$33=MAX($AC$29:$AC$33),AC33,IF($AC$32=MAX($AC$29:$AC$33),AC32,IF($AC$31=MAX($AC$29:$AC$33),AC31,IF($AC$30=MAX($AC$29:$AC$33),AC30,IF($AC$29=MAX($AC$29:$AC$33),AC29))))) -> 17 | AD38: =IF($AC$33=MAX($AC$29:$AC$33),AD33,IF($AC$32=MAX($AC$29:$AC$33),AD32,IF($AC$31=MAX($AC$29:$AC$33),AD31,IF($AC$30=MAX($AC$29:$AC$33),AD30,IF($AC$29=MAX($AC$29:$AC$33),AD29))))) -> 7 | AE38: =IF($AC$33=MAX($AC$29:$AC$33),AE33,IF($AC$32=MAX($AC$29:$AC$33),AE32,IF($AC$31=MAX($AC$29:$AC$33),AE31,IF($AC$30=MAX($AC$29:$AC$33),AE30,IF($AC$29=MAX($AC$29:$AC$33),AE29))))) -> 8 | AF38: =IF($AC$33=MAX($AC$29:$AC$33),AF33,IF($AC$32=MAX($AC$29:$AC$33),AF32,IF($AC$31=MAX($AC$29:$AC$33),AF31,IF($AC$30=MAX($AC$29:$AC$33),AF30,IF($AC$29=MAX($AC$29:$AC$33),AF29))))) -> 4 | AK38: =IF($AC$33=MAX($AC$29:$AC$33),AK33,IF($AC$32=MAX($AC$29:$AC$33),AK32,IF($AC$31=MAX($AC$29:$AC$33),AK31,IF($AC$30=MAX($AC$29:$AC$33),AK30,IF($AC$29=MAX($AC$29:$AC$33),AK29))))) -> 11 | AL38: =IF($AC$33=MAX($AC$29:$AC$33),AL33,IF($AC$32=MAX($AC$29:$AC$33),AL32,IF($AC$31=MAX($AC$29:$AC$33),AL31,IF($AC$30=MAX($AC$29:$AC$33),AL30,IF($AC$29=MAX($AC$29:$AC$33),AL29))))) -> 7
AC39: TOTAL | AD39: Part des VAE dans le total | AE39: Part des femmes dans le total | AF39: Part des VAE chez les femmes | AK39: =AK25 -> Cycles sur rte de Dessy | AL39: =AL25 -> Cycles sur rte des Digues
AA42: Période
AA43: =AA29 -> 6:30 à 7:00 | AD43: =IF(AD29=0,0,AD29/AC29) -> 0.33333333 | AE43: =IF(AE29=0,0,AE29/AC29) -> 0 | AF43: =IF(AF29=0,0,AF29/AD29) -> 0 | AK43: =IF(AK29=0,0,AK29/AC29) -> 0.66666667 | AL43: =IF(AL29=0,0,AL29/AC29) -> 0.33333333
AA44: =AA30 -> 7:00 à 7:30 | AD44: =IF(AD31=0,0,AD31/AC31) -> 0.41176471 | AE44: =IF(AE31=0,0,AE31/AC31) -> 0.47058824 | AF44: =IF(AF31=0,0,AF31/AD31) -> 0.57142857 | AK44: =IF(AK31=0,0,AK31/AC31) -> 0.64705882 | AL44: =IF(AL31=0,0,AL31/AC31) -> 0.41176471
AA45: =AA31 -> 7:30 à 8:00 | AD45: =IF(AD31=0,0,AD31/AC31) -> 0.41176471 | AE45: =IF(AE31=0,0,AE31/AC31) -> 0.47058824 | AF45: =IF(AF31=0,0,AF31/AD31) -> 0.57142857 | AK45: =IF(AK31=0,0,AK31/AC31) -> 0.64705882 | AL45: =IF(AL31=0,0,AL31/AC31) -> 0.41176471
AA46: =AA32 -> 8:00 à 8:30 | AD46: =IF(AD32=0,0,AD32/AC32) -> 0.125 | AE46: =IF(AE32=0,0,AE32/AC32) -> 0.125 | AF46: =IF(AF32=0,0,AF32/AD32) -> 0 | AK46: =IF(AK32=0,0,AK32/AC32) -> 0.75 | AL46: =IF(AL32=0,0,AL32/AC32) -> 0.25
...

Sheet BO_BORNE_TUCINGE
B1: Bonneville Franchissement du Borne Tucinge | G1: Date :
A2: Nom des personnes participant au comptage :
A3: Météo : | G3: Remarques :
A5: PRINCIPE D’UTILISATION : pour chaque intervalle de temps, comptabiliser VAE/vélo dans la colonne H/F
A6: Rajouter aussi en bas de la feuille si déplacement vélo sur trottoir et/ou si enfant
A7: Comptabiliser en bas de la grille si 2 roues hors vélo qui ne sont pas cochés dans la grille (trottinette, skate, ets)
C8: Pont du Borne
C9: Depuis Bonneville | G9: Depuis St Pierre
C10: H | D10: H | E10: F | F10: F | G10: H | H10: H | I10: F | J10: F
A11: Période | C11: VAE | D11: vélo | E11: VAE | F11: vélo | G11: VAE | H11: vélo | I11: VAE | J11: vélo
A12: 0.27083333 | B12: 0.29166667
A13: 0.29166667 | B13: 0.3125 | D13: 4 | H13: 6
A14: 0.3125 | B14: 0.33333333 | D14: 3 | H14: 2
A15: 0.33333333 | B15: 0.35416667 | F15: 1 | H15: 6 | J15: 4
A16: 0.35416667 | B16: 0.375 | E16: 2 | F16: 6 | H16: 21 | J16: 20 | L16: classe 28 élèves enlevés dans le tableau final, 14 H et 14 F
A18: 5 | B18: dont Enfant | D18: 28 enfants enlevés
B19: vélo sur trottoir
B20: dont Cyclo sportifs
A21: 10 | B21: hors grille, plus 2 roues hors vélo (trottinette, skate...)
M22: en jaune, tableau global Yannick
C23: =C8 -> Pont du Borne | K23: Période | M23: TOTAL | N23: Nombre de VAE dans le total | O23: Nombre de femmes dans le total | P23: Nombre de VAE chez les femmes | Q23: plus trotinette skate | R23: dont enfant | S23: vélo sur trottoir | T23: dont cyclo | U23: Cycles en direction de Bonneville
C24: =C9 -> Depuis Bonneville | G24: =G9 -> Depuis St Pierre
C25: H | E25: F | G25: H | I25: F
A26: Période | C26: VAE | D26: vélo | E26: VAE | F26: vélo | G26: VAE | H26: vélo | I26: VAE | J26: vélo
A27: 6:30 à 7:00 | C27: =+C12 -> 0 | D27: =+D12 -> 0 | E27: =+E12 -> 0 | F27: =+F12 -> 0 | G27: =+G12 -> 0 | H27: =+H12 -> 0 | I27: =+I12 -> 0 | J27: =+J12 -> 0 | K27: =A27 -> 6:30 à 7:00 | M27: =SUM(C27:J27) -> 0 | N27: =C27+E27+G27+I27 -> 0 | O27: =E27+F27+I27+J27 -> 0 | P27: =E27+I27 -> 0 | U27: =SUM(G27:J27) -> 0
A28: 7:00 à 7:30 | C28: =+C13 -> 0 | D28: =+D13 -> 4 | E28: =+E13 -> 0 | F28: =+F13 -> 0 | G28: =+G13 -> 0 | H28: =+H13 -> 6 | I28: =+I13 -> 0 | J28: =+J13 -> 0 | K28: =A28 -> 7:00 à 7:30 | M28: =SUM(C28:J28) -> 10 | N28: =C28+E28+G28+I28 -> 0 | O28: =E28+F28+I28+J28 -> 0 | P28: =E28+I28 -> 0 | U28: =SUM(G28:J28) -> 6
A29: 7:30 à 8:00 | C29: =+C14 -> 0 | D29: =+D14 -> 3 | E29: =+E14 -> 0 | F29: =+F14 -> 0 | G29: =+G14 -> 0 | H29: =+H14 -> 2 | I29: =+I14 -> 0 | J29: =+J14 -> 0 | K29: =A29 -> 7:30 à 8:00 | M29: =SUM(C29:J29) -> 5 | N29: =C29+E29+G29+I29 -> 0 | O29: =E29+F29+I29+J29 -> 0 | P29: =E29+I29 -> 0 | U29: =SUM(G29:J29) -> 2
A30: 8:00 à 8:30 | C30: =+C15 -> 0 | D30: =+D15 -> 0 | E30: =+E15 -> 0 | F30: =+F15 -> 1 | G30: =+G15 -> 0 | H30: =+H15 -> 6 | I30: =+I15 -> 0 | J30: =+J15 -> 4 | K30: =A30 -> 8:00 à 8:30 | M30: =SUM(C30:J30) -> 11 | N30: =C30+E30+G30+I30 -> 0 | O30: =E30+F30+I30+J30 -> 5 | P30: =E30+I30 -> 0 | U30: =SUM(G30:J30) -> 10
A31: 8:30 à 9:00 | C31: =+C16 -> 0 | D31: =+D16 -> 0 | E31: =+E16 -> 2 | F31: =+F16 -> 6 | G31: =+G16 -> 0 | H31: =+H16 -> 21 | I31: =+I16 -> 0 | J31: =+J16 -> 20 | K31: =A31 -> 8:30 à 9:00 | M31: =SUM(C31:J31)-28 -> 21 | N31: =C31+E31+G31+I31 -> 2 | O31: =E31+F31+I31+J31-14 -> 14 | P31: =E31+I31 -> 2 | U31: =SUM(G31:J31) -> 41
A32: TOTAL | C32: =SUM(C12:C16) -> 0 | D32: =SUM(D12:D16) -> 7 | E32: =SUM(E12:E16) -> 2 | F32: =SUM(F12:F16) -> 7 | G32: =SUM(G12:G16) -> 0 | H32: =SUM(H12:H16) -> 35 | I32: =SUM(I12:I16) -> 0 | J32: =SUM(J12:J16) -> 24 | K32: TOTAL | M32: =SUM(M27:M31) -> 47 | N32: =SUM(N27:N31) -> 2 | O32: =SUM(O27:O31) -> 19 | P32: =SUM(P27:P31) -> 2 | Q32: =A21 -> 10 | R32: =A18 -> 5 | T32: =A20 -> 0 | U32: =SUM(U27:U31) -> 59
K33: 8:00 à 8:30 | M33: 11
K34: 8:30 à 9:00 | M34: 21
K35: Total H pointe | M35: =SUM(M33:M34) -> 32
J36: H POINTE | K36: =IF($M$31=MAX($M$27:$M$31),K31,IF($M$30=MAX($M$27:$M$31),K30,IF($M$29=MAX($M$27:$M$31),K29,IF($M$28=MAX($M$27:$M$31),K28,IF($M$27=MAX($M$27:$M$31),K27,K31))))) -> 8:30 à 9:00 | M36: =IF($M$31=MAX($M$27:$M$31),M31,IF($M$30=MAX($M$27:$M$31),M30,IF($M$29=MAX($M$27:$M$31),M29,IF($M$28=MAX($M$27:$M$31),M28,IF($M$27=MAX($M$27:$M$31),M27,M31))))) -> 21 | N36: =IF($M$31=MAX($M$27:$M$31),N31,IF($M$30=MAX($M$27:$M$31),N30,IF($M$29=MAX($M$27:$M$31),N29,IF($M$28=MAX($M$27:$M$31),N28,IF($M$27=MAX($M$27:$M$31),N27,N31))))) -> 2 | O36: =IF($M$31=MAX($M$27:$M$31),O31,IF($M$30=MAX($M$27:$M$31),O30,IF($M$29=MAX($M$27:$M$31),O29,IF($M$28=MAX($M$27:$M$31),O28,IF($M$27=MAX($M$27:$M$31),O27,O31))))) -> 14 | P36: =IF($M$31=MAX($M$27:$M$31),P31,IF($M$30=MAX($M$27:$M$31),P30,IF($M$29=MAX($M$27:$M$31),P29,IF($M$28=MAX($M$27:$M$31),P28,IF($M$27=MAX($M$27:$M$31),P27,P31))))) -> 2 | U36: =IF($M$31=MAX($M$27:$M$31),U31,IF($M$30=MAX($M$27:$M$31),U30,IF($M$29=MAX($M$27:$M$31),U29,IF($M$28=MAX($M$27:$M$31),U28,IF($M$27=MAX($M$27:$M$31),U27,U31))))) -> 41
M37: TOTAL | N37: Part des VAE dans le total | O37: Part des femmes dans le total | P37: Part des VAE chez les femmes | U37: =U23 -> Cycles en direction de Bonneville
K40: Période
K41: =K27 -> 6:30 à 7:00 | N41: =IF(N27=0,0,N27/M27) -> 0 | O41: =IF(O27=0,0,O27/M27) -> 0 | P41: =IF(P27=0,0,P27/N27) -> 0 | U41: =IF(U27=0,0,U27/M27) -> 0
K42: =K28 -> 7:00 à 7:30 | N42: =IF(N29=0,0,N29/M29) -> 0 | O42: =IF(O29=0,0,O29/M29) -> 0 | P42: =IF(P29=0,0,P29/N29) -> 0 | U42: =IF(U29=0,0,U29/M29) -> 0.4
K43: =K29 -> 7:30 à 8:00 | N43: =IF(N29=0,0,N29/M29) -> 0 | O43: =IF(O29=0,0,O29/M29) -> 0 | P43: =IF(P29=0,0,P29/N29) -> 0 | U43: =IF(U29=0,0,U29/M29) -> 0.4
K44: =K30 -> 8:00 à 8:30 | N44: =IF(N30=0,0,N30/M30) -> 0 | O44: =IF(O30=0,0,O30/M30) -> 0.45454545 | P44: =IF(P30=0,0,P30/N30) -> 0 | U44: =IF(U30=0,0,U30/M30) -> 0.90909091
...

Sheet ST_PI_BORNE_RD1203
B1: St Pierre Pont sur le Borne Principal - RD 1203 | O1: Date :
A2: Nom des personnes participant au comptage : | L2: côté La Roche | T2: côté Bonneville
A3: Météo : | N3: Remarques :
A5: PRINCIPE D’UTILISATION : pour chaque intervalle de temps, comptabiliser VAE/vélo dans la colonne H/F
A6: Rajouter aussi en bas de la feuille si déplacement vélo sur trottoir et/ou si enfant
A7: Comptabiliser en bas de la grille si 2 roues hors vélo qui ne sont pas cochés dans la grille (trottinette, skate, ets)
C9: De Stade vers
C10: Bonneville | G10: Prison | K10: Tucinges | O10: La Roche | S10: Digues
C11: H | E11: F | G11: H | I11: F | K11: H | M11: F | O11: H | Q11: F | S11: H | U11: F
A12: Période | C12: VAE | D12: vélo | E12: VAE | F12: vélo | G12: VAE | H12: vélo | I12: VAE | J12: vélo | K12: VAE | L12: vélo | M12: VAE | N12: vélo | O12: VAE | P12: vélo | Q12: VAE | R12: vélo | S12: VAE | T12: vélo | U12: VAE | V12: vélo
A13: 0.27083333 | B13: 0.29166667
A14: 0.29166667 | B14: 0.3125 | C14: 1 | W14: =SUM(C14:V14) -> 1
A15: 0.3125 | B15: 0.33333333 | J15: 1 | K15: 1 | W15: =SUM(C15:V15) -> 2
A16: 0.33333333 | B16: 0.35416667
A17: 0.35416667 | B17: 0.375
W18: =SUM(W13:W17) -> 3
C19: De Bonneville vers
C20: Prison | G20: Tucinges | K20: La Roche | O20: Digues | S20: Stade
C21: H | E21: F | G21: H | I21: F | K21: H | M21: F | O21: H | Q21: F | S21: H | U21: F
A22: Période | C22: VAE | D22: vélo | E22: VAE | F22: vélo | G22: VAE | H22: vélo | I22: VAE | J22: vélo | K22: VAE | L22: vélo | M22: VAE | N22: vélo | O22: VAE | P22: vélo | Q22: VAE | R22: vélo | S22: VAE | T22: vélo | U22: VAE | V22: vélo
A23: 0.27083333 | B23: 0.29166667 | N23: 1 | P23: 1 | R23: 2 | W23: =SUM(C23:V23) -> 4
A24: 0.29166667 | B24: 0.3125 | L24: 1 | P24: 2 | W24: =SUM(C24:V24) -> 3
A25: 0.3125 | B25: 0.33333333 | L25: 2 | N25: 1 | P25: 1 | W25: =SUM(C25:V25) -> 4
A26: 0.33333333 | B26: 0.35416667 | M26: 1 | W26: =SUM(C26:V26) -> 1
A27: 0.35416667 | B27: 0.375 | G27: 1 | I27: 2 | L27: 1 | P27: 1 | Q27: 1 | W27: =SUM(C27:V27) -> 6
W28: =SUM(W23:W27) -> 18
C29: De Prison vers
C30: Tucinges | G30: La Roche | K30: Digues | O30: Stade | S30: Bonneville
C31: H | E31: F | G31: H | I31: F | K31: H | M31: F | O31: H | Q31: F | S31: H | U31: F
A32: Période | C32: VAE | D32: vélo | E32: VAE | F32: vélo | G32: VAE | H32: vélo | I32: VAE | J32: vélo | K32: VAE | L32: vélo | M32: VAE | N32: vélo | O32: VAE | P32: vélo | Q32: VAE | R32: vélo | S32: VAE | T32: vélo | U32: VAE | V32: vélo
A33: 0.27083333 | B33: 0.29166667
A34: 0.29166667 | B34: 0.3125
A35: 0.3125 | B35: 0.33333333
A36: 0.33333333 | B36: 0.35416667
A37: 0.35416667 | B37: 0.375 | L37: 1
B38: dont Enfant
A39: 6 | B39: vélo sur trottoir
B40: dont Cyclo sportifs
A41: 3 | B41: hors grille, plus 2 roues hors vélo (trottinette, skate...)
B42: St Pierre Pont sur le Borne Principal - RD 1203
...

Sheet ST PI M BRICOLAGE
B1: ST PIERRE Mr BRICOLAGE | G1: Date :
A2: Nom des personnes participant au comptage :
A3: Météo : | G3: Remarques :
A6: PRINCIPE D’UTILISATION : pour chaque intervalle de temps, comptabiliser VAE/vélo dans la colonne H/F
A7: Comptabiliser en bas de la grille si 2 roues hors vélo qui ne sont pas cochés dans la grille (trottinette, skate, ets)
C9: PISTE CYCLABLE en continu | K9: JAMAIS sur PISTE CYCLABLE
C10: Vers La Roche | G10: Vers Bonnevile | K10: Direction La Roche | O10: Direction Bonneville
C11: H | E11: F | G11: H | I11: F | K11: H | M11: F | O11: H | Q11: F
A12: Période | C12: VAE | D12: vélo | E12: VAE | F12: vélo | G12: VAE | H12: vélo | I12: VAE | J12: vélo | K12: VAE | L12: vélo | M12: VAE | N12: vélo | O12: VAE | P12: vélo | Q12: VAE | R12: vélo
A13: 0.27083333 | B13: 0.29166667 | H13: 1
A14: 0.29166667 | B14: 0.3125 | D14: 1 | H14: 2 | L14: 1
A15: 0.3125 | B15: 0.33333333 | D15: 1 | F15: 1 | G15: 1 | I15: 1 | J15: 1 | P15: 1
A16: 0.33333333 | B16: 0.35416667 | D16: 2 | E16: 1 | I16: 1 | J16: 1 | Q16: 1
A17: 0.35416667 | B17: 0.375 | D17: 1
C19: PARTIELLEMENT sur PISTE CYCLABLE
C20: Vers La Roche | G20: Vers StT Pierre ou zone Jourdies | K20: Vers Bonnevile
C21: H | E21: F | G21: H | I21: F | K21: H | M21: F
A22: Période | C22: VAE | D22: vélo | E22: VAE | F22: vélo | G22: VAE | H22: vélo | I22: VAE | J22: vélo | K22: VAE | L22: vélo | M22: VAE | N22: vélo
A23: 0.27083333 | B23: 0.29166667 | D23: 1 | H23: 2 | J23: 3
A24: 0.29166667 | B24: 0.3125 | H24: 2
A25: 0.3125 | B25: 0.33333333 | H25: 4 | I25: 1
A26: 0.33333333 | B26: 0.35416667 | H26: 1 | I26: 1
A27: 0.35416667 | B27: 0.375 | G27: 1 | I27: 1 | J27: 2
B28: dont Enfant
A29: 4 | B29: vélo sur trottoir
B30: dont Cyclo sportifs
A31: 2 | B31: hors grille, plus 2 roues hors vélo (trottinette, skate...) | U31: en jaune, tableau global Yannick
U32: TOTAL | V32: Nombre de VAE dans le total | W32: Nombre de femmes dans le total | X32: Nombre de VAE chez les femmes | Y32: plus trotinette skate | Z32: dont enfant | AA32: vélo sur trottoir | AB32: dont cyclo
C34: H | E34: F
A35: Période | C35: VAE | D35: vélo | E35: VAE | F35: vélo | S35: Période
A36: 6:30 à 7:00 | C36: =C13+G13+K13+O13+C23+G23+K23 -> 0 | D36: =D13+H13+L13+P13+D23+H23+L23 -> 4 | E36: =E13+I13+M13+Q13+E23+I23+M23 -> 0 | F36: =F13+J13+N13+R13+F23+J23+N23 -> 3 | S36: =A36 -> 6:30 à 7:00 | U36: =SUM(C36:F36) -> 7 | V36: =C36+E36 -> 0 | W36: =E36+F36 -> 3 | X36: =E36 -> 0
A37: 7:00 à 7:30 | C37: =C14+G14+K14+O14+C24+G24+K24 -> 0 | D37: =D14+H14+L14+P14+D24+H24+L24 -> 6 | E37: =E14+I14+M14+Q14+E24+I24+M24 -> 0 | F37: =F14+J14+N14+R14+F24+J24+N24 -> 0 | S37: =A37 -> 7:00 à 7:30 | U37: =SUM(C37:F37) -> 6 | V37: =C37+E37 -> 0 | W37: =E37+F37 -> 0 | X37: =E37 -> 0
A38: 7:30 à 8:00 | C38: =C15+G15+K15+O15+C25+G25+K25 -> 1 | D38: =D15+H15+L15+P15+D25+H25+L25 -> 6 | E38: =E15+I15+M15+Q15+E25+I25+M25 -> 2 | F38: =F15+J15+N15+R15+F25+J25+N25 -> 2 | S38: =A38 -> 7:30 à 8:00 | U38: =SUM(C38:F38) -> 11 | V38: =C38+E38 -> 3 | W38: =E38+F38 -> 4 | X38: =E38 -> 2
A39: 8:00 à 8:30 | C39: =C16+G16+K16+O16+C26+G26+K26 -> 0 | D39: =D16+H16+L16+P16+D26+H26+L26 -> 3 | E39: =E16+I16+M16+Q16+E26+I26+M26 -> 4 | F39: =F16+J16+N16+R16+F26+J26+N26 -> 1 | S39: =A39 -> 8:00 à 8:30 | U39: =SUM(C39:F39) -> 8 | V39: =C39+E39 -> 4 | W39: =E39+F39 -> 5 | X39: =E39 -> 4
A40: 8:30 à 9:00 | C40: =C17+G17+K17+O17+C27+G27+K27 -> 1 | D40: =D17+H17+L17+P17+D27+H27+L27 -> 1 | E40: =E17+I17+M17+Q17+E27+I27+M27 -> 1 | F40: =F17+J17+N17+R17+F27+J27+N27 -> 2 | S40: =A40 -> 8:30 à 9:00 | U40: =SUM(C40:F40) -> 5 | V40: =C40+E40 -> 2 | W40: =E40+F40 -> 3 | X40: =E40 -> 1
A41: TOTAL | C41: =SUM(C36:C40) -> 2 | D41: =SUM(D36:D40) -> 20 | E41: =SUM(E36:E40) -> 7 | F41: =SUM(F36:F40) -> 8 | S41: TOTAL | U41: =SUM(U36:U40) -> 37 | V41: =SUM(V36:V40) -> 9 | W41: =SUM(W36:W40) -> 15 | X41: =SUM(X36:X40) -> 7 | Y41: =A31 -> 2 | Z41: =A28 -> 0 | AA41: =A29 -> 4 | AB41: =A30 -> 0
S42: 7:30 à 8:00 | U42: 11
S43: 8:00 à 8:30 | U43: 8
S44: Total H pointe | U44: =SUM(U42:U43) -> 19
S45: =IF(U36=MAX(U36:U40),S36,IF(U37=MAX(U36:U40),S37,IF(U37=MAX(U36:U40),S37,IF(U38=MAX(U36:U40),S38,IF(U39=MAX(U36:U40),S39))))) -> 7:30 à 8:00 | U45: 11 | V45: 1 | W45: 4 | X45: 2

Sheet 2023
A1: 2023
A2: Nombre de bénévoles | B2: Postes de comptage | C2: Nombre de vélos | D2: % VAE dans le total | E2: NB VAE dans le total | F2: % femmes dans le total | G2: NB de femmes dans le total
C4: total
A5: 10 | B5: LA ROCHE_Carrefour Biocoop | C5: 68 | D5: =IF(E5="","",E5/C5) -> 0.23529412 | E5: 16 | F5: =IF(G5="","",G5/#REF!) -> #REF! | G5: 23
B6: LA ROCHE_Giratoire La Poste | C6: 47 | D6: =IF(E6="","",E6/C6) -> 0.55319149 | E6: 26 | F6: =IF(G6="","",G6/#REF!) -> #REF! | G6: 12
B7: LA ROCHE_Giratoire ENILV | D7: =IF(E7="","",E7/C7) | F7: =IF(G7="","",G7/#REF!)
B8: LA ROCHE_Gare Passage à niveau (new 2021) | C8: 53 | D8: =IF(E8="","",E8/C8) -> 0.32075472 | E8: 17 | F8: =IF(G8="","",G8/#REF!) -> #REF! | G8: 9
B9: LA ROCHE Andrevetan/St Sixt (new 2023) | C9: 26 | E9: 14 | G9: 2
B10: TOTAL LA ROCHE | C10: =SUM(C5:C9) -> 194 | D10: =E10/C10 -> 0.37628866 | E10: =SUM(E5:E9) -> 73 | F10: =G10/C10 -> 0.2371134 | G10: =SUM(G5:G9) -> 46
B12: ARENTHON_La Papeterie | C12: 26 | D12: =IF(E12="","",E12/C12) -> 0.34615385 | E12: 9 | F12: =IF(G12="","",G12/C12) -> 0.15384615 | G12: 4
B13: ST-PIERRE_Franchissement Borne-Dessy | C13: 49 | D13: =IF(E13="","",E13/C13) -> 0.28571429 | E13: 14 | F13: =IF(G13="","",G13/C13) -> 0.20408163 | G13: 10
B14: BONNEVILLE_Franchissement Borne-Tucinge | C14: 47 | D14: =IF(E14="","",E14/C14) -> 0.042553191 | E14: 2 | F14: =IF(G14="","",G14/C14) -> 0.40425532 | G14: 19
B15: ST-PIERRE_Pont principal sur le Borne RD1203 | C15: 59 | D15: =IF(E15="","",E15/C15) -> 0.3220339 | E15: 19 | F15: =IF(G15="","",G15/C15) -> 0.3559322 | G15: 21
B16: AMANCY Sous-terrain Vozerier (2022) | D16: =IF(E16="","",E16/C16) | F16: =IF(G16="","",G16/C16)
