Workbook

Sheet LA_RO_BIOCOOP
A1: Lieu : | B1: La Roche Face Biocoop | P1: Date : | Q1: 45440
A2: Nom des personnes participant au comptage : | K2: Sylvianne
A3: Météo : | C3: bonne | P3: Remarques :
A5: PRINCIPE D’UTILISATION : pour chaque intervalle de temps, comptabiliser VAE/vélo dans la colonne H/F
A6: Rajouter aussi en bas de la feuille si déplacement vélo sur trottoir et/ou si enfant
A7: Comptabiliser en bas de la grille si 2 roues hors vélo qui ne sont pas cochés dans la grille (trottinette, skate, ets)
C9: De La Gare (Fg St Bernard) vers | O9: Du Pont du Foron vers | AA9: Du Rd Point La Poste vers
C10: Rd Pt Poste | G10: Rue Perrine | K10: Pont du Foron | O10: Rue Perrine | S10: Rd Pt Poste | W10: La Gare | AA10: Rue Perrine | AE10: Pont du Foron | AI10: La Gare
C11: H | E11: F | G11: H | I11: F | K11: H | M11: F | O11: H | Q11: F | S11: H | U11: F | W11: H | Y11: F | AA11: H | AC11: F | AE11: H | AG11: F | AI11: H | AK11: F
A12: Période | C12: VAE | D12: vélo | E12: VAE | F12: vélo | G12: VAE | H12: vélo | I12: VAE | J12: vélo | K12: VAE | L12: vélo | M12: VAE | N12: vélo | O12: VAE | P12: vélo | Q12: VAE | R12: vélo | S12: VAE | T12: vélo | U12: VAE | V12: vélo | W12: VAE | X12: vélo | Y12: VAE | Z12: vélo | AA12: VAE | AB12: vélo | AC12: VAE | AD12: vélo | AE12: VAE | AF12: vélo | AG12: VAE | AH12: vélo | AI12: VAE | AJ12: vélo | AK12: VAE | AL12: vélo
A13: 0.27083333 | B13: 0.29166667 | L13: 1 | T13: 1 | U13: 1 | V13: 1 | W13: 1 | Z13: 1 | AI13: 1 | AM13: =SUM(C13:AL13) -> 7
A14: 0.29166667 | B14: 0.3125 | F14: 1 | M14: 1 | T14: 4 | U14: 1 | W14: 1 | X14: 5 | Y14: 1 | AG14: 1 | AI14: 1 | AJ14: 2 | AM14: =SUM(C14:AL14) -> 18
A15: 0.3125 | B15: 0.33333333 | N15: 1 | R15: 1 | T15: 2 | U15: 1 | W15: 4 | X15: 1 | Y15: 3 | AH15: 1 | AI15: 1 | AJ15: 1 | AM15: =SUM(C15:AL15) -> 16
A16: 0.33333333 | B16: 0.35416667 | M16: 1 | T16: 2 | V16: 1 | W16: 2 | X16: 2 | Y16: 1 | Z16: 1 | AD16: 1 | AE16: 1 | AH16: 1 | AI16: 2 | AL16: 1 | AM16: =SUM(C16:AL16) -> 16
A17: 0.35416667 | B17: 0.375 | L17: 2 | Q17: 1 | R17: 2 | X17: 1 | AI17: 1 | AM17: =SUM(C17:AL17) -> 7
AM18: =SUM(C18:AL18) -> 0
A19: 8 | B19: dont Enfant | E19: 8
A20: 2 | B20: Dont vélo sur trottoir | G20: 2
A21: 5 | B21: dont Cyclo sportifs | G21: 5
A22: 25 | B22: hors grille, plus 2 roues hors vélo (trottinette, skate...) | P22: 25
C26: =C9 -> De La Gare (Fg St Bernard) vers | O26: =O9 -> Du Pont du Foron vers | AA26: =AA9 -> Du Rd Point La Poste vers | AO26: TOTAL | AP26: Nombre de VAE dans le total | AQ26: Nombre de femmes dans le total | AR26: Nombre de VAE chez les femmes | AX26: Nombre de VAE chez les femmes | AY26: Cycles direc La Gare
C27: =C10 -> Rd Pt Poste | G27: =G10 -> Rue Perrine | K27: =K10 -> Pont du Foron | O27: =O10 -> Rue Perrine | S27: =S10 -> Rd Pt Poste | W27: =W10 -> La Gare | AA27: =AA10 -> Rue Perrine | AE27: =AE10 -> Pont du Foron | AI27: =AI10 -> La Gare
C28: H | E28: F | G28: H | I28: F | K28: H | M28: F | O28: H | Q28: F | S28: H | U28: F | W28: H | Y28: F | AA28: H | AC28: F | AE28: H | AG28: F | AI28: H | AK28: F
A29: Période | C29: VAE | D29: vélo | E29: VAE | F29: vélo | G29: VAE | H29: vélo | I29: VAE | J29: vélo | K29: VAE | L29: vélo | M29: VAE | N29: vélo | O29: VAE | P29: vélo | Q29: VAE | R29: vélo | S29: VAE | T29: vélo | U29: VAE | V29: vélo | W29: VAE | X29: vélo | Y29: VAE | Z29: vélo | AA29: VAE | AB29: vélo | AC29: VAE | AD29: vélo | AE29: VAE | AF29: vélo | AG29: VAE | AH29: vélo | AI29: VAE | AJ29: vélo | AK29: VAE | AL29: vélo | AM29: Période | AS29: plus trotinette skate | AT29: dont enfant | AU29: vélo sur trottoir | AV29: dont cyclo
A30: 6:30 à 7:00 | C30: =+C13 -> 0 | D30: =+D13 -> 0 | E30: =+E13 -> 0 | F30: =+F13 -> 0 | G30: =+G13 -> 0 | H30: =+H13 -> 0 | I30: =+I13 -> 0 | J30: =+J13 -> 0 | ... AL30: =+AL13 -> 0 | AM30: 6:30 à 7:00 | AO30: =SUM(C30:AL30) -> 7 | AP30: =C30+E30+G30+I30+K30+M30+O30+Q30+S30+U30+W30+Y30+AA30+AC30+AE30+AG30+AI30+AK30 -> 3 | AQ30: =E30+F30+I30+J30+M30+N30+Q30+R30+U30+V30+Y30+Z30+AC30+AD30+AG30+AH30+AK30+AL30 -> 3 | AR30: =E30+I30+M30+Q30+U30+Y30+AC30+AG30+AK30 -> 1 | AX30: =E30+I30+M30+Q30+U30+Y30+AC30+AG30+AK30 -> 1 | AY30: =SUM(C30:N30)+SUM(W30:Z30)+SUM(AI30:AL30) -> 4
A31: 7:00 à 7:30 | C31: =+C14 -> 0 | D31: =+D14 -> 0 | E31: =+E14 -> 0 | F31: =+F14 -> 1 | G31: =+G14 -> 0 | H31: =+H14 -> 0 | I31: =+I14 -> 0 | J31: =+J14 -> 0 | ... AL31: =+AL14 -> 0 | AM31: 7:00 à 7:30 | AO31: =SUM(C31:AL31) -> 18 | AP31: =C31+E31+G31+I31+K31+M31+O31+Q31+S31+U31+W31+Y31+AA31+AC31+AE31+AG31+AI31+AK31 -> 6 | AQ31: =E31+F31+I31+J31+M31+N31+Q31+R31+U31+V31+Y31+Z31+AC31+AD31+AG31+AH31+AK31+AL31 -> 5 | AR31: =E31+I31+M31+Q31+U31+Y31+AC31+AG31+AK31 -> 4 | AX31: =E31+I31+M31+Q31+U31+Y31+AC31+AG31+AK31 -> 4 | AY31: =SUM(C31:N31)+SUM(W31:Z31)+SUM(AI31:AL31) -> 12
A32: 7:30 à 8:00 | C32: =+C15 -> 0 | D32: =+D15 -> 0 | E32: =+E15 -> 0 | F32: =+F15 -> 0 | G32: =+G15 -> 0 | H32: =+H15 -> 0 | I32: =+I15 -> 0 | J32: =+J15 -> 0 | ... AL32: =+AL15 -> 0 | AM32: 7:30 à 8:00 | AO32: =SUM(C32:AL32) -> 16 | AP32: =C32+E32+G32+I32+K32+M32+O32+Q32+S32+U32+W32+Y32+AA32+AC32+AE32+AG32+AI32+AK32 -> 9 | AQ32: =E32+F32+I32+J32+M32+N32+Q32+R32+U32+V32+Y32+Z32+AC32+AD32+AG32+AH32+AK32+AL32 -> 7 | AR32: =E32+I32+M32+Q32+U32+Y32+AC32+AG32+AK32 -> 4 | AX32: =E32+I32+M32+Q32+U32+Y32+AC32+AG32+AK32 -> 4 | AY32: =SUM(C32:N32)+SUM(W32:Z32)+SUM(AI32:AL32) -> 11
A33: 8:00 à 8:30 | C33: =+C16 -> 0 | D33: =+D16 -> 0 | E33: =+E16 -> 0 | F33: =+F16 -> 0 | G33: =+G16 -> 0 | H33: =+H16 -> 0 | I33: =+I16 -> 0 | J33: =+J16 -> 0 | ... AL33: =+AL16 -> 1 | AM33: 8:00 à 8:30 | AO33: =SUM(C33:AL33) -> 16 | AP33: =C33+E33+G33+I33+K33+M33+O33+Q33+S33+U33+W33+Y33+AA33+AC33+AE33+AG33+AI33+AK33 -> 7 | AQ33: =E33+F33+I33+J33+M33+N33+Q33+R33+U33+V33+Y33+Z33+AC33+AD33+AG33+AH33+AK33+AL33 -> 7 | AR33: =E33+I33+M33+Q33+U33+Y33+AC33+AG33+AK33 -> 2 | AX33: =E33+I33+M33+Q33+U33+Y33+AC33+AG33+AK33 -> 2 | AY33: =SUM(C33:N33)+SUM(W33:Z33)+SUM(AI33:AL33) -> 10
A34: 8:30 à 9:00 | C34: =+C17 -> 0 | D34: =+D17 -> 0 | E34: =+E17 -> 0 | F34: =+F17 -> 0 | G34: =+G17 -> 0 | H34: =+H17 -> 0 | I34: =+I17 -> 0 | J34: =+J17 -> 0 | ... AL34: =+AL17 -> 0 | AM34: 8:30 à 9:00 | AO34: =SUM(C34:AL34) -> 7 | AP34: =C34+E34+G34+I34+K34+M34+O34+Q34+S34+U34+W34+Y34+AA34+AC34+AE34+AG34+AI34+AK34 -> 2 | AQ34: =E34+F34+I34+J34+M34+N34+Q34+R34+U34+V34+Y34+Z34+AC34+AD34+AG34+AH34+AK34+AL34 -> 3 | AR34: =E34+I34+M34+Q34+U34+Y34+AC34+AG34+AK34 -> 1 | AX34: =E34+I34+M34+Q34+U34+Y34+AC34+AG34+AK34 -> 1 | AY34: =SUM(C34:N34)+SUM(W34:Z34)+SUM(AI34:AL34) -> 4
A35: TOTAL | C35: =+C18 -> 0 | D35: =+D18 -> 0 | E35: =+E18 -> 0 | F35: =+F18 -> 0 | G35: =+G18 -> 0 | H35: =+H18 -> 0 | I35: =+I18 -> 0 | J35: =+J18 -> 0 | ... AL35: =+AL18 -> 0 | AM35: TOTAL | AO35: =SUM(AO30:AO34) -> 64 | AP35: =SUM(AP30:AP34) -> 27 | AQ35: =SUM(AQ30:AQ34) -> 25 | AR35: =SUM(AR30:AR34) -> 12 | AS35: =A22 -> 25 | AT35: =A19 -> 8 | AU35: =A20 -> 2 | AV35: =A21 -> 5 | AX35: =E35+I35+M35+Q35+U35+Y35+AC35+AG35+AK35 -> 0 | AY35: =SUM(C35:N35)+SUM(W35:Z35)+SUM(AI35:AL35) -> 0
AL36: H POINTE | AM36: =AM31 -> 7:00 à 7:30 | AO36: =AO31 -> 18
AL37: H POINTE | AM37: =AM32 -> 7:30 à 8:00 | AO37: =AO32 -> 16
AM38: Total H pointe | AO38: =SUM(AO36:AO37) -> 34
AM39: =IF(AO30=MAX($AO$30:$AO$35),AM30,IF(AO31=MAX($AO$30:$AO$35),AM31,IF(AO32=MAX($AO$30:$AO$35),AM32,IF(AO33=MAX($AO$30:$AO$35),AM33,IF(AO34=MAX($AO$30:$AO$35),AM34,AM33))))) -> 8:00 à 8:30 | AO39: =IF(AQ30=MAX($AO$30:$AO$35),AO30,IF(AQ31=MAX($AO$30:$AO$35),AO31,IF(AQ32=MAX($AO$30:$AO$35),AO32,IF(AQ33=MAX($AO$30:$AO$35),AO33,IF(AQ34=MAX($AO$30:$AO$35),AO34,AO33))))) -> 16 | AP39: =IF(AT30=MAX($AO$30:$AO$35),AP30,IF(AT31=MAX($AO$30:$AO$35),AP31,IF(AT32=MAX($AO$30:$AO$35),AP32,IF(AT33=MAX($AO$30:$AO$35),AP33,IF(AT34=MAX($AO$30:$AO$35),AP34,AP33))))) -> 7 | AQ39: =IF(AU30=MAX($AO$30:$AO$35),AQ30,IF(AU31=MAX($AO$30:$AO$35),AQ31,IF(AU32=MAX($AO$30:$AO$35),AQ32,IF(AU33=MAX($AO$30:$AO$35),AQ33,IF(AU34=MAX($AO$30:$AO$35),AQ34,AQ33))))) -> 7 | AR39: =IF(AV30=MAX($AO$30:$AO$35),AR30,IF(AV31=MAX($AO$30:$AO$35),AR31,IF(AV32=MAX($AO$30:$AO$35),AR32,IF(AV33=MAX($AO$30:$AO$35),AR33,IF(AV34=MAX($AO$30:$AO$35),AR34,AR33))))) -> 2
AO40: TOTAL | AP40: Part des VAE dans le total | AQ40: Part des femmes dans le total | AR40: Part des VAE chez les femmes
AM43: Période
AM44: =AM30 -> 6:30 à 7:00 | AP44: =IF(AP31=0,0,AP31/AO31) -> 0.33333333 | AQ44: =IF(AQ31=0,0,AQ31/AO31) -> 0.27777778 | AR44: =IF(AT31=0,0,AT31/AP31) -> 0
AM45: =AM31 -> 7:00 à 7:30 | AP45: =IF(AP31=0,0,AP31/AO31) -> 0.33333333 | AQ45: =IF(AQ31=0,0,AQ31/AO31) -> 0.27777778 | AR45: =IF(AT31=0,0,AT31/AP31) -> 0
AM46: =AM32 -> 7:30 à 8:00 | AP46: =IF(AP32=0,0,AP32/AO32) -> 0.5625 | AQ46: =IF(AQ32=0,0,AQ32/AO32) -> 0.4375 | AR46: =IF(AT32=0,0,AT32/AP32) -> 0
AM47: =AM33 -> 8:00 à 8:30 | AP47: =IF(AP33=0,0,AP33/AO33) -> 0.4375 | AQ47: =IF(AQ33=0,0,AQ33/AO33) -> 0.4375 | AR47: =IF(AT33=0,0,AT33/AP33) -> 0
...

Sheet LA_RO_POSTE
B1: Rond Point La Poste | O1: Date :
A2: Nom des personnes participant au comptage : | H2: Birgit
A3: Météo : | P3: Remarques :
A5: PRINCIPE D’UTILISATION : pour chaque intervalle de temps, comptabiliser VAE/vélo dans la colonne H/F
A6: Rajouter aussi en bas de la feuille si déplacement vélo sur trottoir et/ou si enfant
A7: Comptabiliser en bas de la grille si 2 roues hors vélo qui ne sont pas cochés dans la grille (trottinette, skate, ets)
C9: De Bonneville vers | S9: De Grenette (contre-sens) | AE9: De La Base(contre-sens)
C10: Grenette | G10: Orange | K10: La Base | O10: J Jaurès (contre sens) | S10: Orange | W10: La Base | AA10: Bonneville | AE10: Bonneville | AJ10: Orange | AM10: Place Grenette
C11: H | E11: F | G11: H | I11: F | K11: H | M11: F | O11: H | Q11: F | S11: H | U11: F | W11: H | Y11: F | AA11: H | AC11: F | AE11: H | AG11: F | AH11: F | AJ11: H | AM11: H | AO11: F
A12: Période | C12: VAE | D12: vélo | E12: VAE | F12: vélo | G12: VAE | H12: vélo | I12: VAE | J12: vélo | K12: VAE | L12: vélo | M12: VAE | N12: vélo | O12: VAE | P12: vélo | Q12: VAE | R12: vélo | S12: VAE | T12: vélo | U12: VAE | V12: vélo | W12: VAE | X12: vélo | Y12: VAE | Z12: vélo | AA12: VAE | AB12: vélo | AC12: VAE | AD12: vélo | AE12: VAE | AF12: vélo | AG12: VAE | AH12: VAE | AI12: vélo | AJ12: VAE | AK12: vélo | AL12: vélo | AM12: VAE | AN12: vélo | AO12: VAE | AP12: vélo
A13: 0.27083333 | B13: 0.29166667 | G13: 1 | H13: 1 | O13: 1 | P13: 1 | R13: 1
A14: 0.29166667 | B14: 0.3125 | H14: 1 | M14: 1 | P14: 1
A15: 0.3125 | B15: 0.33333333 | G15: 2 | H15: 1 | K15: 1 | AM15: 1
A16: 0.33333333 | B16: 0.35416667 | G16: 2 | N16: 2
A17: 0.35416667 | B17: 0.375
A18: 9 | B18: 00 – 15
B19: 15 – 30
C21: De Orange vers | O21: De Jean Jaurès MJC vers
C22: La Base | G22: Bonneville | K22: Grenette | O22: Orange | S22: Grenette | W22: Bonneville | AA22: La Base
C23: H | E23: F | G23: H | I23: F | K23: H | M23: F | O23: H | Q23: F | S23: H | U23: F | W23: H | Y23: F | AA23: H | AC23: F
A24: Période | C24: VAE | D24: vélo | E24: VAE | F24: vélo | G24: VAE | H24: vélo | I24: VAE | J24: vélo | K24: VAE | L24: vélo | M24: VAE | N24: vélo | O24: VAE | P24: vélo | Q24: VAE | R24: vélo | S24: VAE | T24: vélo | U24: VAE | V24: vélo | W24: VAE | X24: vélo | Y24: VAE | Z24: vélo | AA24: VAE | AB24: vélo | AC24: VAE | AD24: vélo
A25: 0.27083333 | B25: 0.29166667 | E25: 1 | H25: 1 | J25: 1 | AB25: 1
A26: 0.29166667 | B26: 0.3125 | C26: 1 | H26: 1 | I26: 2
A27: 0.3125 | B27: 0.33333333 | E27: 1 | H27: 4 | I27: 1 | W27: 1 | X27: 1 | AB27: 1
A28: 0.33333333 | B28: 0.35416667 | E28: 1 | F28: 1 | G28: 1 | H28: 2 | O28: 4 | X28: 1 | Y28: 1 | AA28: 1
A29: 0.35416667 | B29: 0.375 | AP29: x
A30: 9 | B30: 00 – 15
B31: 15 – 30
A33: 9 | B33: dont Enfant | D33: 9
A34: 3 | B34: Dont vélo sur trottoir | F34: 3
A35: 4 | B35: dont Cyclo sportifs | F35: 4
A36: 18 | B36: hors grille, plus 2 roues hors vélo (trottinette, skate...) | L36: 18
AC37: TOTAL | AD37: Nombre de VAE dans le total | AE37: Nombre de femmes dans le total | AF37: Nombre de VAE chez les femmes
C39: H | E39: F
A40: Période | C40: VAE | D40: vélo | E40: VAE | F40: vélo | AA40: Période | AH40: plus trotinette skate | AI40: dont enfant | AJ40: vélo sur trottoir | AK40: dont cyclo
A41: 6:30 à 7:00 | C41: =C13+G13+K13+O13+S13+W13+AA13+AE13+AJ13+AM13+C25+G25+K25+O25+S25+W25+AA25 -> 2 | D41: =D13+H13+L13+P13+T13+X13+AB13+AF13+AK13+AN13+D25+H25+L25+P25+T25+X25+AB25 -> 4 | E41: =E13+I13+M13+Q13+U13+Y13+AC13+AG13+AH13+AO13+E25+I25+M25+Q25+U25+Y25+AC25 -> 1 | F41: =F13+J13+N13+R13+V13+Z13+AD13+AI13+AL13+AP13+F25+J25+N25+R25+V25+Z25+AD25 -> 2 | AA41: 6:30 à 7:00 | AC41: =SUM(C41:F41) -> 9 | AD41: =C41+E41 -> 3 | AE41: =E41+F41 -> 3 | AF41: =E41 -> 1
A42: 7:00 à 7:30 | C42: =C14+G14+K14+O14+S14+W14+AA14+AE14+AJ14+AM14+C26+G26+K26+O26+S26+W26+AA26 -> 1 | D42: =D14+H14+L14+P14+T14+X14+AB14+AF14+AK14+AN14+D26+H26+L26+P26+T26+X26+AB26 -> 3 | E42: =E14+I14+M14+Q14+U14+Y14+AC14+AG14+AH14+AO14+E26+I26+M26+Q26+U26+Y26+AC26 -> 3 | F42: =F14+J14+N14+R14+V14+Z14+AD14+AI14+AL14+AP14+F26+J26+N26+R26+V26+Z26+AD26 -> 0 | AA42: 7:00 à 7:30 | AC42: =SUM(C42:F42) -> 7 | AD42: =C42+E42 -> 4 | AE42: =E42+F42 -> 3 | AF42: =E42 -> 3
A43: 7:30 à 8:00 | C43: =C15+G15+K15+O15+S15+W15+AA15+AE15+AJ15+AM15+C27+G27+K27+O27+S27+W27+AA27 -> 5 | D43: =D15+H15+L15+P15+T15+X15+AB15+AF15+AK15+AN15+D27+H27+L27+P27+T27+X27+AB27 -> 7 | E43: =E15+I15+M15+Q15+U15+Y15+AC15+AG15+AH15+AO15+E27+I27+M27+Q27+U27+Y27+AC27 -> 2 | F43: =F15+J15+N15+R15+V15+Z15+AD15+AI15+AL15+AP15+F27+J27+N27+R27+V27+Z27+AD27 -> 0 | AA43: 7:30 à 8:00 | AC43: =SUM(C43:F43) -> 14 | AD43: =C43+E43 -> 7 | AE43: =E43+F43 -> 2 | AF43: =E43 -> 2
A44: 8:00 à 8:30 | C44: =C16+G16+K16+O16+S16+W16+AA16+AE16+AJ16+AM16+C28+G28+K28+O28+S28+W28+AA28 -> 8 | D44: =D16+H16+L16+P16+T16+X16+AB16+AF16+AK16+AN16+D28+H28+L28+P28+T28+X28+AB28 -> 3 | E44: =E16+I16+M16+Q16+U16+Y16+AC16+AG16+AH16+AO16+E28+I28+M28+Q28+U28+Y28+AC28 -> 2 | F44: =F16+J16+N16+R16+V16+Z16+AD16+AI16+AL16+AP16+F28+J28+N28+R28+V28+Z28+AD28 -> 3 | AA44: 8:00 à 8:30 | AC44: =SUM(C44:F44) -> 16 | AD44: =C44+E44 -> 10 | AE44: =E44+F44 -> 5 | AF44: =E44 -> 2
A45: 8:30 à 9:00 | C45: =C17+G17+K17+O17+S17+W17+AA17+AE17+AJ17+AM17+C29+G29+K29+O29+S29+W29+AA29 -> 0 | D45: =D17+H17+L17+P17+T17+X17+AB17+AF17+AK17+AN17+D29+H29+L29+P29+T29+X29+AB29 -> 0 | E45: =E17+I17+M17+Q17+U17+Y17+AC17+AG17+AH17+AO17+E29+I29+M29+Q29+U29+Y29+AC29 -> 0 | F45: =F17+J17+N17+R17+V17+Z17+AD17+AI17+AL17+AP17+F29+J29+N29+R29+V29+Z29+AD29 -> 0 | AA45: 8:30 à 9:00 | AC45: =SUM(C45:F45) -> 0 | AD45: =C45+E45 -> 0 | AE45: =E45+F45 -> 0 | AF45: =E45 -> 0
...

Sheet LA_RO_ENILV
B1: La Roche Rond-Point ENILV - St Renan | O1: Date :
A2: Nom des personnes participant au comptage : | M2: Robert
A3: Météo :
A4: Remarques :
A6: PRINCIPE D’UTILISATION : pour chaque intervalle de temps, comptabiliser VAE/vélo dans la colonne H/F
A7: Rajouter aussi en bas de la feuille si déplacement vélo sur trottoir et/ou si enfant
A8: Comptabiliser en bas de la grille si 2 roues hors vélo qui ne sont pas cochés dans la grille (trottinette, skate, ets)
C10: Du centre (La Roche) vers | O10: D'Eteaux av Gambetta vers | AA10: De Av Libération Enilv vers | AM10: De Reignier vers
C11: Av Gambetta Eteaux | G11: Av Libération Enilv | K11: Reignier | O11: Av Libération Enilv | S11: Reignier | W11: La Roche | AA11: Reignier | AE11: La Roche | AI11: Av Gambetta Eteaux | AM11: La Roche | AQ11: Av Gambetta Eteaux | AU11: Av Libération Enilv
C12: H | E12: F | G12: H | I12: F | K12: H | M12: F | O12: H | Q12: F | S12: H | U12: F | W12: H | Y12: F | AA12: H | AC12: F | AE12: H | AG12: F | AI12: H | AK12: F | AM12: H | AO12: F | AQ12: H | AS12: F | AU12: H | AW12: F
A13: H | B13: Minute | C13: VAE | D13: vélo | E13: VAE | F13: vélo | G13: VAE | H13: vélo | I13: VAE | J13: vélo | K13: VAE | L13: vélo | M13: VAE | N13: vélo | O13: VAE | P13: vélo | Q13: VAE | R13: vélo | S13: VAE | T13: vélo | U13: VAE | V13: vélo | W13: VAE | X13: vélo | Y13: VAE | Z13: vélo | AA13: VAE | AB13: vélo | AC13: VAE | AD13: vélo | AE13: VAE | AF13: vélo | AG13: VAE | AH13: vélo | AI13: VAE | AJ13: vélo | AK13: VAE | AL13: vélo | AM13: VAE | AN13: vélo | AO13: VAE | AP13: vélo | AQ13: VAE | AR13: vélo | AS13: VAE | AT13: vélo | AU13: VAE | AV13: vélo | AW13: VAE | AX13: vélo
A14: 6 | B14: 30 – 45 | L14: 1 | T14: 1
B15: 45 - 59 | L15: 1 | P15: 1
A16: 7 | B16: 00 – 15 | K16: 1
B17: 15 – 30 | L17: 3 | T17: 1 | AF17: 1
B18: 30 – 45 | C18: 1 | E18: 1 | L18: 1 | N18: 1 | AM18: 1
B19: 45 – 59 | T19: 1
A20: 8 | B20: 00 – 15 | F20: 1 | L20: 1 | AM20: 1
B21: 15 – 30
B22: 30 – 45 | K22: 1 | W22: 1 | AF22: 1 | AH22: 1
A23: 9 | B23: 45 – 59 | AD23: 1
B25: dont Enfant | E25: 1
B26: vélo sur trottoir
B27: dont Cyclo sportifs
B28: hors grille, plus 2 roues hors vélo (trottinette, skate...) | R28: 8
C36: =C10 -> Du centre (La Roche) vers | O36: =O10 -> D'Eteaux av Gambetta vers | AA36: =AA10 -> De Av Libération Enilv vers | AM36: =AM10 -> De Reignier vers | BA36: TOTAL | BB36: Nombre de VAE dans le total | BC36: Nombre de femmes dans le total | BD36: Nombre de VAE chez les femmes | BE36: Cycles sur route de Reignier | BF36: Remarque
C37: =C11 -> Av Gambetta Eteaux | G37: =G11 -> Av Libération Enilv | K37: =K11 -> Reignier | O37: =O11 -> Av Libération Enilv | S37: =S11 -> Reignier | W37: =W11 -> La Roche | AA37: =AA11 -> Reignier | AE37: =AE11 -> La Roche | AI37: =AI11 -> Av Gambetta Eteaux | AM37: =AM11 -> La Roche | AQ37: =AQ11 -> Av Gambetta Eteaux | AU37: =AU11 -> Av Libération Enilv
C38: H | E38: F | G38: H | I38: F | K38: H | M38: F | O38: H | Q38: F | S38: H | U38: F | W38: H | Y38: F | AA38: H | AC38: F | AE38: H | AG38: F | AI38: H | AK38: F | AM38: H | AO38: F | AQ38: H | AS38: F | AU38: H | AW38: F
A39: Période | C39: VAE | D39: vélo | E39: VAE | F39: vélo | G39: VAE | H39: vélo | I39: VAE | J39: vélo | K39: VAE | L39: vélo | M39: VAE | N39: vélo | O39: VAE | P39: vélo | Q39: VAE | R39: vélo | S39: VAE | T39: vélo | U39: VAE | V39: vélo | W39: VAE | X39: vélo | Y39: VAE | Z39: vélo | AA39: VAE | AB39: vélo | AC39: VAE | AD39: vélo | AE39: VAE | AF39: vélo | AG39: VAE | AH39: vélo | AI39: VAE | AJ39: vélo | AK39: VAE | AL39: vélo | AM39: VAE | AN39: vélo | AO39: VAE | AP39: vélo | AQ39: VAE | AR39: vélo | AS39: VAE | AT39: vélo | AU39: VAE | AV39: vélo | AW39: VAE | AX39: vélo | AY39: Période
A40: 6:30 à 7:00 | C40: =SUM(C14:C15) -> 0 | D40: =SUM(D14:D15) -> 0 | E40: =SUM(E14:E15) -> 0 | F40: =SUM(F14:F15) -> 0 | G40: =SUM(G14:G15) -> 0 | H40: =SUM(H14:H15) -> 0 | I40: =SUM(I14:I15) -> 0 | J40: =SUM(J14:J15) -> 0 | ... AX40: =SUM(AX14:AX15) -> 0 | AY40: =A40 -> 6:30 à 7:00 | BA40: =SUM(C40:AX40) -> 4 | BB40: =C40+E40+G40+I40+K40+M40+O40+Q40+S40+U40+W40+Y40+AA40+AC40+AE40+AG40+AI40+AK40+AM40+AO40+AQ40+AS40+AU40+AW40 -> 0 | BC40: =E40+F40+I40+J40+M40+N40+Q40+R40+U40+V40+Y40+Z40+AC40+AD40+AG40+AH40+AK40+AL40+AO40+AP40+AS40+AT40+AW40+AX40 -> 0 | BD40: =E40+I40+M40+Q40+U40+Y40+AC40+AG40+AK40+AO40+AS40+AW40 -> 0 | BE40: =SUM(K40:N40)+SUM(S40:V40)+SUM(AA40:AD40)+SUM(AM40:AX40) -> 3 | BF40: 34 piétons plus 32 étudiants piétons en direction lycée
A41: 7:00 à 7:30 | C41: =SUM(C16:C17) -> 0 | D41: =SUM(D16:D17) -> 0 | E41: =SUM(E16:E17) -> 0 | F41: =SUM(F16:F17) -> 0 | G41: =SUM(G16:G17) -> 0 | H41: =SUM(H16:H17) -> 0 | I41: =SUM(I16:I17) -> 0 | J41: =SUM(J16:J17) -> 0 | ... AX41: =SUM(AX16:AX17) -> 0 | AY41: =A41 -> 7:00 à 7:30 | BA41: =SUM(C41:AX41) -> 6 | BB41: =C41+E41+G41+I41+K41+M41+O41+Q41+S41+U41+W41+Y41+AA41+AC41+AE41+AG41+AI41+AK41+AM41+AO41+AQ41+AS41+AU41+AW41 -> 1 | BC41: =E41+F41+I41+J41+M41+N41+Q41+R41+U41+V41+Y41+Z41+AC41+AD41+AG41+AH41+AK41+AL41+AO41+AP41+AS41+AT41+AW41+AX41 -> 0 | BD41: =E41+I41+M41+Q41+U41+Y41+AC41+AG41+AK41+AO41+AS41+AW41 -> 0 | BE41: =SUM(K41:N41)+SUM(S41:V41)+SUM(AA41:AD41)+SUM(AM41:AX41) -> 5 | BF41: et seulement 2 écoliers- 2 enfants comptés qui étaient sur le trottoir avec 1 parent
A42: 7:30 à 8:00 | C42: =SUM(C18:C19) -> 1 | D42: =SUM(D18:D19) -> 0 | E42: =SUM(E18:E19) -> 1 | F42: =SUM(F18:F19) -> 0 | G42: =SUM(G18:G19) -> 0 | H42: =SUM(H18:H19) -> 0 | I42: =SUM(I18:I19) -> 0 | J42: =SUM(J18:J19) -> 0 | ... AX42: =SUM(AX18:AX19) -> 0 | AY42: =A42 -> 7:30 à 8:00 | BA42: =SUM(C42:AX42) -> 6 | BB42: =C42+E42+G42+I42+K42+M42+O42+Q42+S42+U42+W42+Y42+AA42+AC42+AE42+AG42+AI42+AK42+AM42+AO42+AQ42+AS42+AU42+AW42 -> 3 | BC42: =E42+F42+I42+J42+M42+N42+Q42+R42+U42+V42+Y42+Z42+AC42+AD42+AG42+AH42+AK42+AL42+AO42+AP42+AS42+AT42+AW42+AX42 -> 2 | BD42: =E42+I42+M42+Q42+U42+Y42+AC42+AG42+AK42+AO42+AS42+AW42 -> 1 | BE42: =SUM(K42:N42)+SUM(S42:V42)+SUM(AA42:AD42)+SUM(AM42:AX42) -> 4 | BF42: et seulement 2 écoliers- 2 enfants comptés qui étaient sur le trottoir avec 1 parent
A43: 8:00 à 8:30 | C43: =SUM(C20:C21) -> 0 | D43: =SUM(D20:D21) -> 0 | E43: =SUM(E20:E21) -> 0 | F43: =SUM(F20:F21) -> 1 | G43: =SUM(G20:G21) -> 0 | H43: =SUM(H20:H21) -> 0 | I43: =SUM(I20:I21) -> 0 | J43: =SUM(J20:J21) -> 0 | ... AX43: =SUM(AX20:AX21) -> 0 | AY43: =A43 -> 8:00 à 8:30 | BA43: =SUM(C43:AX43) -> 3 | BB43: =C43+E43+G43+I43+K43+M43+O43+Q43+S43+U43+W43+Y43+AA43+AC43+AE43+AG43+AI43+AK43+AM43+AO43+AQ43+AS43+AU43+AW43 -> 1 | BC43: =E43+F43+I43+J43+M43+N43+Q43+R43+U43+V43+Y43+Z43+AC43+AD43+AG43+AH43+AK43+AL43+AO43+AP43+AS43+AT43+AW43+AX43 -> 1 | BD43: =E43+I43+M43+Q43+U43+Y43+AC43+AG43+AK43+AO43+AS43+AW43 -> 0 | BE43: =SUM(K43:N43)+SUM(S43:V43)+SUM(AA43:AD43)+SUM(AM43:AX43) -> 2 | BF43: 2 des 3 femmes circulaient sur le trottoir !
A44: 8:30 à 9:00 | C44: =SUM(C21:C23) -> 0 | D44: =SUM(D21:D23) -> 0 | E44: =SUM(E21:E23) -> 0 | F44: =SUM(F21:F23) -> 0 | G44: =SUM(G21:G23) -> 0 | H44: =SUM(H21:H23) -> 0 | I44: =SUM(I21:I23) -> 0 | J44: =SUM(J21:J23) -> 0 | ... AX44: =SUM(AX21:AX23) -> 0 | AY44: =A44 -> 8:30 à 9:00 | BA44: =SUM(C44:AX44) -> 5 | BB44: =C44+E44+G44+I44+K44+M44+O44+Q44+S44+U44+W44+Y44+AA44+AC44+AE44+AG44+AI44+AK44+AM44+AO44+AQ44+AS44+AU44+AW44 -> 2 | BC44: =E44+F44+I44+J44+M44+N44+Q44+R44+U44+V44+Y44+Z44+AC44+AD44+AG44+AH44+AK44+AL44+AO44+AP44+AS44+AT44+AW44+AX44 -> 2 | BD44: =E44+I44+M44+Q44+U44+Y44+AC44+AG44+AK44+AO44+AS44+AW44 -> 0 | BE44: =SUM(K44:N44)+SUM(S44:V44)+SUM(AA44:AD44)+SUM(AM44:AX44) -> 2 | BF44: 3 cyclosportifs
A45: TOTAL | C45: =SUM(C14:C23) -> 1 | D45: =SUM(D14:D23) -> 0 | E45: =SUM(E14:E23) -> 1 | F45: =SUM(F14:F23) -> 1 | G45: =SUM(G14:G23) -> 0 | H45: =SUM(H14:H23) -> 0 | I45: =SUM(I14:I23) -> 0 | J45: =SUM(J14:J23) -> 0 | ... AX45: =SUM(AX14:AX23) -> 0 | AY45: TOTAL | BA45: =SUM(C45:AX45) -> 24 | BB45: =C45+E45+G45+I45+K45+M45+O45+Q45+S45+U45+W45+Y45+AA45+AC45+AE45+AG45+AI45+AK45+AM45+AO45+AQ45+AS45+AU45+AW45 -> 7 | BC45: =E45+F45+I45+J45+M45+N45+Q45+R45+U45+V45+Y45+Z45+AC45+AD45+AG45+AH45+AK45+AL45+AO45+AP45+AS45+AT45+AW45+AX45 -> 5 | BD45: =E45+I45+M45+Q45+U45+Y45+AC45+AG45+AK45+AO45+AS45+AW45 -> 1 | BE45: =SUM(K45:N45)+SUM(S45:V45)+SUM(AA45:AD45)+SUM(AM45:AX45) -> 16
AY46: =IF($BA$40=MAX($BA$40:$BA$44),AY40,IF($BA$41=MAX($BA$40:$BA$44),AY41,IF($BA$42=MAX($BA$40:$BA$44),AY42,IF($BA$43=MAX($BA$40:$BA$44),AY43,IF($BA$44=MAX($BA$40:$BA$44),AY44,AY43))))) -> 7:00 à 7:30 | BA46: =IF($BA$40=MAX($BA$40:$BA$44),BA40,IF($BA$41=MAX($BA$40:$BA$44),BA41,IF($BA$42=MAX($BA$40:$BA$44),BA42,IF($BA$43=MAX($BA$40:$BA$44),BA43,IF($BA$44=MAX($BA$40:$BA$44),BA44,BA43))))) -> 6 | BB46: =IF($BA$40=MAX($BA$40:$BA$44),BB40,IF($BA$41=MAX($BA$40:$BA$44),BB41,IF($BA$42=MAX($BA$40:$BA$44),BB42,IF($BA$43=MAX($BA$40:$BA$44),BB43,IF($BA$44=MAX($BA$40:$BA$44),BB44,BB43))))) -> 1 | BC46: =IF($BA$40=MAX($BA$40:$BA$44),BC40,IF($BA$41=MAX($BA$40:$BA$44),BC41,IF($BA$42=MAX($BA$40:$BA$44),BC42,IF($BA$43=MAX($BA$40:$BA$44),BC43,IF($BA$44=MAX($BA$40:$BA$44),BC44,BC43))))) -> 0 | BD46: =IF($BA$40=MAX($BA$40:$BA$44),BD40,IF($BA$41=MAX($BA$40:$BA$44),BD41,IF($BA$42=MAX($BA$40:$BA$44),BD42,IF($BA$43=MAX($BA$40:$BA$44),BD43,IF($BA$44=MAX($BA$40:$BA$44),BD44,BD43))))) -> 0 | BE46: =IF($BA$40=MAX($BA$40:$BA$44),BE40,IF($BA$41=MAX($BA$40:$BA$44),BE41,IF($BA$42=MAX($BA$40:$BA$44),BE42,IF($BA$43=MAX($BA$40:$BA$44),BE43,IF($BA$44=MAX($BA$40:$BA$44),BE44,BE43))))) -> 5
BA47: TOTAL | BB47: Part des VAE dans le total | BC47: Part des femmes dans le total | BD47: Part des VAE chez les femmes | BE47: =BE36 -> Cycles sur route de Reignier | BF47: Remarque
AY50: Période
AY51: =AY40 -> 6:30 à 7:00 | BB51: =IF(BB40=0,0,BB40/BA40) -> 0 | BC51: =IF(BC40=0,0,BC40/BA40) -> 0 | BD51: =IF(BD40=0,0,BD40/BB40) -> 0 | BE51: =IF(BE40=0,0,BE40/BA40) -> 0.75
AY52: =AY41 -> 7:00 à 7:30 | BB52: =IF(BB42=0,0,BB42/BA42) -> 0.5 | BC52: =IF(BC42=0,0,BC42/BA42) -> 0.33333333 | BD52: =IF(BD42=0,0,BD42/BB42) -> 0.33333333 | BE52: =IF(BE42=0,0,BE42/BA42) -> 0.66666667
...

Sheet LA_RO_gare
B1: La Roche Gare/Passage à niveau | O1: Date :
A2: Nom des personnes participant au comptage : | L2: Steph Armand
A3: Météo :
A4: Remarques : | D4: Comptage jusqu'à 8h20
A6: PRINCIPE D’UTILISATION : pour chaque intervalle de temps, comptabiliser VAE/vélo dans la colonne H/F
A7: Rajouter aussi en bas de la feuille si déplacement vélo sur trottoir et/ou si enfant
A8: Comptabiliser en bas de la grille si 2 roues hors vélo qui ne sont pas cochés dans la grille (trottinette, skate, ets)
C10: D’Eteaux vers | O10: De av Lucien Rannard vers | AA10: Dr Roux vers
C11: Av L Rannard | G11: Av J Jaurès | K11: Gare/av Gare | O11: Av J Jaurès | S11: Gare/av Gare | W11: Eteaux | AA11: Gare
C12: H | E12: F | G12: H | I12: F | K12: H | M12: F | O12: H | Q12: F | S12: H | U12: F | W12: H | Y12: F | AA12: H | AC12: F
A13: Période | C13: VAE | D13: vélo | E13: VAE | F13: vélo | G13: VAE | H13: vélo | I13: VAE | J13: vélo | K13: VAE | L13: vélo | M13: VAE | N13: vélo | O13: VAE | P13: vélo | Q13: VAE | R13: vélo | S13: VAE | T13: vélo | U13: VAE | V13: vélo | W13: VAE | X13: vélo | Y13: VAE | Z13: vélo | AA13: VAE | AB13: vélo | AC13: VAE | AD13: vélo
A14: 0.27083333 | B14: 0.29166667 | L14: 2 | AA14: 1
A15: 0.29166667 | B15: 0.3125 | L15: 1 | M15: 2 | T15: 1 | AB15: 4 | AD15: 1
A16: 0.3125 | B16: 0.33333333 | K16: 1 | N16: 1 | T16: 1 | AA16: 1 | AB16: 3
A17: 0.33333333 | B17: 0.35416667 | AC17: 1
A18: 8h30 | B18: 0.375
C20: De av J Jaurès vers | O20: De Gare et av Gare vers | AA20: Av Gare vers
C21: Gare/av Gare | G21: Eteaux | K21: Av L Rannard | O21: Eteaux | S21: Av L Rannard | W21: Av J Jaurès | AA21: Gare
C22: H | E22: F | G22: H | I22: F | K22: H | M22: F | O22: H | Q22: F | S22: H | U22: F | W22: H | Y22: F | AA22: H | AC22: F
A23: Période | C23: VAE | D23: vélo | E23: VAE | F23: vélo | G23: VAE | H23: vélo | I23: VAE | J23: vélo | K23: VAE | L23: vélo | M23: VAE | N23: vélo | O23: VAE | P23: vélo | Q23: VAE | R23: vélo | S23: VAE | T23: vélo | U23: VAE | V23: vélo | W23: VAE | X23: vélo | Y23: VAE | Z23: vélo | AA23: VAE | AB23: vélo | AC23: VAE | AD23: vélo
A24: 0.27083333 | B24: 0.29166667 | C24: 1 | D24: 1 | E24: 1 | G24: 1 | P24: 1 | AB24: 1
A25: 0.29166667 | B25: 0.3125 | D25: 1 | G25: 1 | H25: 1 | I25: 1 | L25: 1 | Q25: 1 | S25: 2 | AB25: 2 | AC25: 1
A26: 0.3125 | B26: 0.33333333 | E26: 1 | H26: 1 | I26: 1 | K26: 2 | S26: 2
A27: 0.33333333 | B27: 0.35416667 | E27: 1 | F27: 1 | G27: 1 | L27: 1
A28: 8h30 | B28: 0.375
B30: dont Enfant | F30: 1
B31: Dont vélo sur trottoir | H31: 3
B32: dont Cyclo sportifs | H32: 4
B33: hors grille, plus 2 roues hors vélo (trottinette, skate...) | R33: 25
AG34: en jaune, tableau global
AG35: TOTAL | AH35: Nombre de VAE dans le total | AI35: Nombre de femmes dans le total | AJ35: Nombre de VAE chez les femmes | AK35: Cycles sur route de Reignier
C37: H | E37: F
A38: Période | C38: VAE | D38: vélo | E38: VAE | F38: vélo | AE38: Période | AL38: plus trotinette skate | AM38: dont enfant | AN38: vélo sur trottoir | AO38: dont cyclo
A39: 6:30 à 7:00 | C39: =C14+G14+K14+O14+S14+AA14+C24+G24+K24+O24+S24+AA24+W14+W24 -> 3 | D39: =D14+H14+L14+P14+T14+AB14+D24+H24+L24+P24+T24+AB24+X24+X14 -> 5 | E39: =E14+I14+M14+Q14+U14+AC14+E24+I24+M24+Q24+U24+AC24+Y24+Y14 -> 1 | F39: =F14+J14+N14+R14+V14+AD14+F24+J24+N24+R24+V24+AD24+Z24+Z14 -> 0 | AE39: =A39 -> 6:30 à 7:00 | AG39: =SUM(C39:AD39) -> 9 | AH39: =C39+E39 -> 4 | AI39: =E39+F39 -> 1 | AJ39: =E39 -> 1
A40: 7:00 à 7:30 | C40: =C15+G15+K15+O15+S15+AA15+C25+G25+K25+O25+S25+AA25+W15+W25 -> 3 | D40: =D15+H15+L15+P15+T15+AB15+D25+H25+L25+P25+T25+AB25+X25+X15 -> 11 | E40: =E15+I15+M15+Q15+U15+AC15+E25+I25+M25+Q25+U25+AC25+Y25+Y15 -> 5 | F40: =F15+J15+N15+R15+V15+AD15+F25+J25+N25+R25+V25+AD25+Z25+Z15 -> 1 | AE40: =A40 -> 7:00 à 7:30 | AG40: =SUM(C40:AD40) -> 20 | AH40: =C40+E40 -> 8 | AI40: =E40+F40 -> 6 | AJ40: =E40 -> 5
A41: 7:30 à 8:00 | C41: =C16+G16+K16+O16+S16+AA16+C26+G26+K26+O26+S26+AA26+W16+W26 -> 6 | D41: =D16+H16+L16+P16+T16+AB16+D26+H26+L26+P26+T26+AB26+X26+X16 -> 5 | E41: =E16+I16+M16+Q16+U16+AC16+E26+I26+M26+Q26+U26+AC26+Y26+Y16 -> 2 | F41: =F16+J16+N16+R16+V16+AD16+F26+J26+N26+R26+V26+AD26+Z26+Z16 -> 1 | AE41: =A41 -> 7:30 à 8:00 | AG41: =SUM(C41:AD41) -> 14 | AH41: =C41+E41 -> 8 | AI41: =E41+F41 -> 3 | AJ41: =E41 -> 2
A42: 8:00 à 8:30 | C42: =C17+G17+K17+O17+S17+AA17+C27+G27+K27+O27+S27+AA27+W17+W27 -> 1 | D42: =D17+H17+L17+P17+T17+AB17+D27+H27+L27+P27+T27+AB27+X27+X17 -> 1 | E42: =E17+I17+M17+Q17+U17+AC17+E27+I27+M27+Q27+U27+AC27+Y27+Y17 -> 2 | F42: =F17+J17+N17+R17+V17+AD17+F27+J27+N27+R27+V27+AD27+Z27+Z17 -> 1 | AE42: =A42 -> 8:00 à 8:30 | AG42: =SUM(C42:AD42) -> 5 | AH42: =C42+E42 -> 3 | AI42: =E42+F42 -> 3 | AJ42: =E42 -> 2
A43: 8:30 à 9h | C43: =C18+G18+K18+O18+S18+AA18+C28+G28+K28+O28+S28+AA28+W18+W28 -> 0 | D43: =D18+H18+L18+P18+T18+AB18+D28+H28+L28+P28+T28+AB28+X28+X18 -> 0 | E43: =E18+I18+M18+Q18+U18+AC18+E28+I28+M28+Q28+U28+AC28+Y28+Y18 -> 0 | F43: =F18+J18+N18+R18+V18+AD18+F28+J28+N28+R28+V28+AD28+Z28+Z18 -> 0 | AE43: =A43 -> 8:30 à 9h | AG43: =SUM(C43:AD43) -> 0 | AH43: =C43+E43 -> 0 | AI43: =E43+F43 -> 0 | AJ43: =E43 -> 0
A44: TOTAL | C44: =SUM(C14:C18)+SUM(C24:C28) -> 1 | D44: =SUM(D14:D18)+SUM(D24:D28) -> 2 | E44: =SUM(E14:E18)+SUM(E24:E28) -> 3 | F44: =SUM(F14:F18)+SUM(F24:F28) -> 1 | AE44: TOTAL | AG44: =SUM(AG39:AG43) -> 48 | AH44: =SUM(AH39:AH43) -> 23 | AI44: =SUM(AI39:AI43) -> 13 | AJ44: =SUM(AJ39:AJ43) -> 10 | AK44: =SUM(AK39:AK43) -> 0 | AL44: =A33 -> 0 | AM44: =A30 -> 0 | AN44: =A31 -> 0 | AO44: =A32 -> 0
Z45: H POINTE | AD45: H POINTE | AE45: 7:00 à 7:30 | AG45: =AG40 -> 20
...

Sheet LA RO ANDREV 24
B1: La Roche Andrevetan | E1: Rue Patience/St Sixt | K1: Date :
A2: Nom des personnes participant au comptage : | F2: Stéphane Moutard-Martin
A3: Météo : | K3: Remarques :
A5: PRINCIPE D’UTILISATION : pour chaque intervalle de temps, comptabiliser VAE/vélo dans la colonne H/F
A6: Rajouter aussi en bas de la feuille si déplacement vélo sur trottoir et/ou si enfant
A7: Comptabiliser en bas de la grille si 2 roues hors vélo qui ne sont pas cochés dans la grille (trottinette, skate, ets)
C9: De La Roche vers | K9: De St Pierre rue Patience vers
C10: St Pierre/ Rue Patience | G10: St Sixt | K10: La Roche | O10: St Sixt
C11: H | E11: F | G11: H | I11: F | K11: H | M11: F | O11: H | Q11: F
A12: Période | C12: VAE | D12: vélo | E12: VAE | F12: vélo | G12: VAE | H12: vélo | I12: VAE | J12: vélo | K12: VAE | L12: vélo | M12: VAE | N12: vélo | O12: VAE | P12: vélo | Q12: VAE | R12: vélo
A13: 0.27083333 | B13: 0.29166667 | D13: 2
A14: 0.29166667 | B14: 0.3125 | E14: 2 | I14: 1 | K14: 1 | L14: 3
A15: 0.3125 | B15: 0.33333333 | E15: 1 | L15: 1
A16: 0.33333333 | B16: 0.35416667 | C16: 1 | K16: 1
A17: 0.35416667 | B17: 0.375 | D17: 3
C19: De St Sixt vers
C20: Rue Patience | G20: La Roche
C21: H | E21: F | G21: H | I21: F
A22: Période | C22: VAE | D22: vélo | E22: VAE | F22: vélo | G22: VAE | H22: vélo | I22: VAE | J22: vélo
A23: 0.27083333 | B23: 0.29166667 | E23: 2 | J23: 1
A24: 0.29166667 | B24: 0.3125 | C24: 1 | H24: 1 | I24: 3
A25: 0.3125 | B25: 0.33333333 | D25: 3 | E25: 1
A26: 0.33333333 | B26: 0.35416667 | I26: 1
A27: 0.35416667 | B27: 0.375 | H27: 1 | J27: 1
B29: dont Enfant | D29: 4
B30: vélo sur trottoir
B31: dont Cyclo sportifs | E31: 3
B32: hors grille, plus 2 roues hors vélo (trottinette, skate...) | I32: 2
M33: en jaune, tableau global
M34: TOTAL | N34: Nombre de VAE dans le total | O34: Nombre de femmes dans le total | P34: Nombre de VAE chez les femmes | R34: dont enfant | S34: vélo sur trottoir | T34: dont cyclo | U34: plus trotinette skate
C36: H | E36: F
A37: Période | C37: VAE | D37: vélo | E37: VAE | F37: vélo | K37: Période
A38: 6:30 à 7:00 | C38: =C13+G13+K13+O13+C23+G23 -> 0 | D38: =D13+H13+L13+P13+D23+H23 -> 2 | E38: =E13+I13+M13+Q13+E23+I23 -> 2 | F38: =F13+J13+N13+R13+F23+J23 -> 1 | K38: =A38 -> 6:30 à 7:00 | M38: =SUM(C38:J38) -> 5 | N38: =C38+E38 -> 2 | O38: =E38+F38 -> 3 | P38: =E38 -> 2 | Q38: =SUM(G38:J38) -> 0
A39: 7:00 à 7:30 | C39: =C14+G14+K14+O14+C24+G24 -> 2 | D39: =D14+H14+L14+P14+D24+H24 -> 4 | E39: =E14+I14+M14+Q14+E24+I24 -> 6 | F39: =F14+J14+N14+R14+F24+J24 -> 0 | K39: =A39 -> 7:00 à 7:30 | M39: =SUM(C39:J39) -> 12 | N39: =C39+E39 -> 8 | O39: =E39+F39 -> 6 | P39: =E39 -> 6 | Q39: =SUM(G39:J39) -> 0
A40: 7:30 à 8:00 | C40: =C15+G15+K15+O15+C25+G25 -> 0 | D40: =D15+H15+L15+P15+D25+H25 -> 4 | E40: =E15+I15+M15+Q15+E25+I25 -> 2 | F40: =F15+J15+N15+R15+F25+J25 -> 0 | K40: =A40 -> 7:30 à 8:00 | M40: =SUM(C40:J40) -> 6 | N40: =C40+E40 -> 2 | O40: =E40+F40 -> 2 | P40: =E40 -> 2 | Q40: =SUM(G40:J40) -> 0
A41: 8:00 à 8:30 | C41: =C16+G16+K16+O16+C26+G26 -> 2 | D41: =D16+H16+L16+P16+D26+H26 -> 0 | E41: =E16+I16+M16+Q16+E26+I26 -> 1 | F41: =F16+J16+N16+R16+F26+J26 -> 0 | K41: =A41 -> 8:00 à 8:30 | M41: =SUM(C41:J41) -> 3 | N41: =C41+E41 -> 3 | O41: =E41+F41 -> 1 | P41: =E41 -> 1 | Q41: =SUM(G41:J41) -> 0
A42: 8:30 à 9:00 | C42: =C17+G17+K17+O17+C27+G27 -> 0 | D42: =D17+H17+L17+P17+D27+H27 -> 4 | E42: =E17+I17+M17+Q17+E27+I27 -> 0 | F42: =F17+J17+N17+R17+F27+J27 -> 1 | K42: =A42 -> 8:30 à 9:00 | M42: =SUM(C42:J42) -> 5 | N42: =C42+E42 -> 0 | O42: =E42+F42 -> 1 | P42: =E42 -> 0 | Q42: =SUM(G42:J42) -> 0
A43: TOTAL | C43: =SUM(C38:C42) -> 4 | D43: =SUM(D38:D42) -> 14 | E43: =SUM(E38:E42) -> 11 | F43: =SUM(F38:F42) -> 2 | K43: TOTAL | M43: =SUM(C43:J43) -> 31 | N43: =N42+N41+N40+N39+N38 -> 15 | O43: =O42+O41+O40+O39+O38 -> 13 | P43: =P42+P41+P40+P39+P38 -> 11 | Q43: =Q42+Q40+Q38 -> 0 | R43: =A29 -> 0 | S43: =A30 -> 0 | T43: =A31 -> 0 | U43: =A32 -> 0
J47: H POINTE | K47: 7 à 8 | M47: =M39+M40 -> 18 | N47: =IF($M$42=MAX($M$38:$M$42),N42,IF($M$41=MAX($M$38:$M$42),N41,IF($M$40=MAX($M$38:$M$42),N40,IF($M$39=MAX($M$38:$M$42),N39,IF($M$38=MAX($M$38:$M$42),N38,N42))))) -> 8 | O47: =IF($M$42=MAX($M$38:$M$42),O42,IF($M$41=MAX($M$38:$M$42),O41,IF($M$40=MAX($M$38:$M$42),O40,IF($M$39=MAX($M$38:$M$42),O39,IF($M$38=MAX($M$38:$M$42),O38,O42))))) -> 6 | P47: =IF($M$42=MAX($M$38:$M$42),P42,IF($M$41=MAX($M$38:$M$42),P41,IF($M$40=MAX($M$38:$M$42),P40,IF($M$39=MAX($M$38:$M$42),P39,IF($M$38=MAX($M$38:$M$42),P38,P42))))) -> 6 | Q47: =IF($M$42=MAX($M$38:$M$42),Q42,IF($M$41=MAX($M$38:$M$42),Q41,IF($M$40=MAX($M$38:$M$42),Q40,IF($M$39=MAX($M$38:$M$42),Q39,IF($M$38=MAX($M$38:$M$42),Q38,Q42))))) -> 0
M48: TOTAL | N48: Part des VAE dans le total | O48: Part des femmes dans le total | P48: Part des VAE chez les femmes | Q48: =Q34 -> 0 | R48: Remarque
...

Sheet ARENT_PAPETERIE
B1: Arenthon La Papeterie | O1: Date :
A2: Nom des personnes participant au comptage : | I2: Nicole
A3: Météo : | N3: Remarques :
A5: PRINCIPE D’UTILISATION : pour chaque intervalle de temps, comptabiliser VAE/vélo dans la colonne H/F
A6: Rajouter aussi en bas de la feuille si enfant
A7: Comptabiliser en bas de la grille si 2 roues hors vélo qui ne sont pas cochés dans la grille (trottinette, skate, ets)
C9: De Arenthon vers | O9: De Bonneville vers
C10: Bonneville | G10: TNA | K10: Rte Papeterie | O10: TNA | S10: Arenthon | W10: Rte Papeterie
C11: H | E11: F | G11: H | I11: F | K11: H | M11: F | O11: H | Q11: F | S11: H | U11: F | W11: H | Y11: F
A12: Période | C12: VAE | D12: vélo | E12: VAE | F12: vélo | G12: VAE | H12: vélo | I12: VAE | J12: vélo | K12: VAE | L12: vélo | M12: VAE | N12: vélo | O12: VAE | P12: vélo | Q12: VAE | R12: vélo | S12: VAE | T12: vélo | U12: VAE | V12: vélo | W12: VAE | X12: vélo | Y12: VAE | Z12: vélo
A13: 0.27083333 | B13: 0.29166667 | C13: 1 | E13: 1
A14: 0.29166667 | B14: 0.3125 | D14: 1 | X14: 1
A15: 0.3125 | B15: 0.33333333 | T15: 1
A16: 0.33333333 | B16: 0.35416667
A17: 0.35416667 | B17: 0.375 | D17: 2 | F17: 1 | T17: 1
C19: De Rte Papeterie vers | O19: De TNA vers
C20: Arenthon | G20: TNA | K20: Bonneville | O20: Bonneville | S20: Arenthon | W20: Rte Papeterie
C21: H | E21: F | G21: H | I21: F | K21: H | M21: F | O21: H | Q21: F | S21: H | U21: F | W21: H | Y21: F
A22: Période | C22: VAE | D22: vélo | E22: VAE | F22: vélo | G22: VAE | H22: vélo | I22: VAE | J22: vélo | K22: VAE | L22: vélo | M22: VAE | N22: vélo | O22: VAE | P22: vélo | Q22: VAE | R22: vélo | S22: VAE | T22: vélo | U22: VAE | V22: vélo | W22: VAE | X22: vélo | Y22: VAE | Z22: vélo
A23: 0.27083333 | B23: 0.29166667
A24: 0.29166667 | B24: 0.3125 | R24: 1
A25: 0.3125 | B25: 0.33333333 | L25: 1
A26: 0.33333333 | B26: 0.35416667 | H26: 1
A27: 0.35416667 | B27: 0.375
B29: dont Enfant
B30: vélo sur trottoir
B31: dont Cyclo sportifs | F31: 2
B32: hors grille, plus 2 roues hors vélo (trottinette, skate...)
C34: H | E34: F | AB34: en jaune, tableau global
A35: Période | C35: VAE | D35: vélo | E35: VAE | F35: vélo | AA35: Période | AC35: TOTAL | AD35: Nombre de VAE dans le total | AE35: Nombre de femmes dans le total | AF35: Nombre de VAE chez les femmes | AG35: plus trotinette skate | AH35: dont enfant | AI35: vélo sur trottoir | AJ35: dont cyclo
A36: 6:30 à 7:00 | C36: =C13+G13+K13+O13+S13+W13+C23+G23+K23+O23+S23+W23 -> 1 | D36: =D13+H13+L13+P13+T13+X13+D23+H23+L23+P23+T23+X23 -> 0 | E36: =E13+I13+M13+Q13+U13+Y13+E23+I23+M23+Q23+U23+Y23 -> 1 | F36: =F13+J13+N13+R13+V13+Z13+F23+J23+N23+R23+V23+Z23 -> 0 | AA36: =A36 -> 6:30 à 7:00 | AC36: =SUM(C36:Z36) -> 2 | AD36: =C36+E36 -> 2 | AE36: =E36+F36 -> 1 | AF36: =E36 -> 1
A37: 7:00 à 7:30 | C37: =C14+G14+K14+O14+S14+W14+C24+G24+K24+O24+S24+W24 -> 0 | D37: =D14+H14+L14+P14+T14+X14+D24+H24+L24+P24+T24+X24 -> 2 | E37: =E14+I14+M14+Q14+U14+Y14+E24+I24+M24+Q24+U24+Y24 -> 0 | F37: =F14+J14+N14+R14+V14+Z14+F24+J24+N24+R24+V24+Z24 -> 1 | AA37: =A37 -> 7:00 à 7:30 | AC37: =SUM(C37:Z37) -> 3 | AD37: =C37+E37 -> 0 | AE37: =E37+F37 -> 1 | AF37: =E37 -> 0
A38: 7:30 à 8:00 | C38: =C15+G15+K15+O15+S15+W15+C25+G25+K25+O25+S25+W25 -> 0 | D38: =D15+H15+L15+P15+T15+X15+D25+H25+L25+P25+T25+X25 -> 2 | E38: =E15+I15+M15+Q15+U15+Y15+E25+I25+M25+Q25+U25+Y25 -> 0 | F38: =F15+J15+N15+R15+V15+Z15+F25+J25+N25+R25+V25+Z25 -> 0 | AA38: =A38 -> 7:30 à 8:00 | AC38: =SUM(C38:Z38) -> 2 | AD38: =C38+E38 -> 0 | AE38: =E38+F38 -> 0 | AF38: =E38 -> 0
A39: 8:00 à 8:30 | C39: =C16+G16+K16+O16+S16+W16+C26+G26+K26+O26+S26+W26 -> 0 | D39: =D16+H16+L16+P16+T16+X16+D26+H26+L26+P26+T26+X26 -> 1 | E39: =E16+I16+M16+Q16+U16+Y16+E26+I26+M26+Q26+U26+Y26 -> 0 | F39: =F16+J16+N16+R16+V16+Z16+F26+J26+N26+R26+V26+Z26 -> 0 | AA39: =A39 -> 8:00 à 8:30 | AC39: =SUM(C39:Z39) -> 1 | AD39: =C39+E39 -> 0 | AE39: =E39+F39 -> 0 | AF39: =E39 -> 0
A40: 8:30 à 9:00 | C40: =C17+G17+K17+O17+S17+W17+C27+G27+K27+O27+S27+W27 -> 0 | D40: =D17+H17+L17+P17+T17+X17+D27+H27+L27+P27+T27+X27 -> 3 | E40: =E17+I17+M17+Q17+U17+Y17+E27+I27+M27+Q27+U27+Y27 -> 0 | F40: =F17+J17+N17+R17+V17+Z17+F27+J27+N27+R27+V27+Z27 -> 1 | AA40: 8:30 à 9:00 | AC40: =SUM(C40:Z40) -> 4 | AD40: =C40+E40 -> 0 | AE40: =E40+F40 -> 1 | AF40: =E40 -> 0
A41: TOTAL | C41: =SUM(C13:C17) -> 1 | D41: =SUM(D13:D17) -> 3 | E41: =SUM(E13:E17) -> 1 | F41: =SUM(F13:F17) -> 1 | AA41: TOTAL | AC41: =SUM(AC36:AC40) -> 12 | AD41: =SUM(AD36:AD40) -> 2 | AE41: =SUM(AE36:AE40) -> 3 | AF41: =SUM(AF36:AF40) -> 1 | AG41: 1 | AH41: 1 | AI41: =A30 -> 0 | AJ41: 3
AA42: 7:00 à 7:30 | AC42: =AC37 -> 3
AA43: 7:30 à 8:00 | AC43: =AC38 -> 2
AA44: Total H pointe | AC44: =SUM(AC42:AC43) -> 5
AC46: TOTAL | AD46: Part des VAE dans le total | AE46: Part des femmes dans le total | AF46: Part des VAE chez les femmes
...

Sheet ST_PI_BORNE_DESSY
B1: St Pierre Franchissement du Borne Dessy | O1: Date :
A2: Nom des personnes participant au comptage : | H2: Mickaël
A3: Météo : | P3: Remarques : | R3: Compatage jusqu’à 8h30
A5: PRINCIPE D’UTILISATION : pour chaque intervalle de temps, comptabiliser VAE/vélo dans la colonne H/F
A6: Rajouter aussi en bas de la feuille si enfant
A7: Comptabiliser en bas de la grille si 2 roues hors vélo qui ne sont pas cochés dans la grille (trottinette, skate, ets)
C9: De Rte Gorges du Borne vers | K9: De Avenue des Digues vers | S9: De Avenue de Monaz vers
C10: Av des Digues | G10: Av Monaz | K10: Av Monaz | O10: Rte Gorges du Borne | S10: Rte Gorges du Borne | W10: Av des Digues
C11: H | E11: F | G11: H | I11: F | K11: H | M11: F | O11: H | Q11: F | S11: H | U11: F | W11: H | Y11: F
A12: Période | C12: VAE | D12: vélo | E12: VAE | F12: vélo | G12: VAE | H12: vélo | I12: VAE | J12: vélo | K12: VAE | L12: vélo | M12: VAE | N12: vélo | O12: VAE | P12: vélo | Q12: VAE | R12: vélo | S12: VAE | T12: vélo | U12: VAE | V12: vélo | W12: VAE | X12: vélo | Y12: VAE | Z12: vélo
A13: 0.27083333 | B13: 0.29166667 | G13: 2
A14: 0.29166667 | B14: 0.3125 | G14: 3 | H14: 2 | I14: 1
A15: 0.3125 | B15: 0.33333333 | D15: 1 | F15: 1 | I15: 2
A16: 0.33333333 | B16: 0.35416667 | D16: 1 | J16: 1
A17: 0.35416667 | B17: 0.375
B19: dont Enfant
B20: vélo sur trottoir
B21: dont Cyclo sportifs | F21: 1
B22: hors grille, plus 2 roues hors vélo (trottinette, skate...)
AC24: en jaune, tableau global
C25: =C9 -> De Rte Gorges du Borne vers | K25: =K9 -> De Avenue des Digues vers | S25: =S9 -> De Avenue de Monaz vers | AC25: TOTAL | AD25: Nombre de VAE dans le total | AE25: Nombre de femmes dans le total | AF25: Nombre de VAE chez les femmes | AK25: Cycles sur rte de Dessy | AL25: Cycles sur rte des Digues
C26: =C10 -> Av des Digues | G26: =G10 -> Av Monaz | K26: =K10 -> Av Monaz | O26: =O10 -> Rte Gorges du Borne | S26: =S10 -> Rte Gorges du Borne | W26: =W10 -> Av des Digues
C27: H | E27: F | G27: H | I27: F | K27: H | M27: F | O27: H | Q27: F | S27: H | U27: F | W27: H | Y27: F
A28: Période | C28: VAE | D28: vélo | E28: VAE | F28: vélo | G28: VAE | H28: vélo | I28: VAE | J28: vélo | K28: VAE | L28: vélo | M28: VAE | N28: vélo | O28: VAE | P28: vélo | Q28: VAE | R28: vélo | S28: VAE | T28: vélo | U28: VAE | V28: vélo | W28: VAE | X28: vélo | Y28: VAE | Z28: vélo | AA28: Période | AG28: plus trotinette skate | AH28: dont enfant | AI28: vélo sur trottoir | AJ28: dont cyclo
A29: 6:30 à 7:00 | C29: =C13 -> 0 | D29: =D13 -> 0 | E29: =E13 -> 0 | F29: =F13 -> 0 | G29: =G13 -> 2 | H29: =H13 -> 0 | I29: =I13 -> 0 | J29: =J13 -> 0 | ... Z29: =Z13 -> 0 | AA29: =A29 -> 6:30 à 7:00 | AC29: =SUM(C29:Z29) -> 2 | AD29: =C29+E29+G29+I29+K29+M29+O29+Q29+S29+U29+W29+Y29 -> 2 | AE29: =E29+F29+I29+J29+M29+N29+Q29+R29+U29+V29+Y29+Z29 -> 0 | AF29: =E29+I29+M29+Q29+U29+Y29 -> 0 | AK29: =SUM(G29:N29)+SUM(S29:Z29) -> 2 | AL29: =SUM(C29:F29)+SUM(W29:Z29)+SUM(K29:R29) -> 0
A30: 7:00 à 7:30 | C30: =C14 -> 0 | D30: =D14 -> 0 | E30: =E14 -> 0 | F30: =F14 -> 0 | G30: =G14 -> 3 | H30: =H14 -> 2 | I30: =I14 -> 1 | J30: =J14 -> 0 | ... Z30: =Z14 -> 0 | AA30: =A30 -> 7:00 à 7:30 | AC30: =SUM(C30:Z30) -> 6 | AD30: =C30+E30+G30+I30+K30+M30+O30+Q30+S30+U30+W30+Y30 -> 4 | AE30: =E30+F30+I30+J30+M30+N30+Q30+R30+U30+V30+Y30+Z30 -> 1 | AF30: =E30+I30+M30+Q30+U30+Y30 -> 1 | AK30: =SUM(G30:N30)+SUM(S30:Z30) -> 6 | AL30: =SUM(C30:F30)+SUM(W30:Z30)+SUM(K30:R30) -> 0
A31: 7:30 à 8:00 | C31: =C15 -> 0 | D31: =D15 -> 1 | E31: =E15 -> 0 | F31: =F15 -> 1 | G31: =G15 -> 0 | H31: =H15 -> 0 | I31: =I15 -> 2 | J31: =J15 -> 0 | ... Z31: =Z15 -> 0 | AA31: =A31 -> 7:30 à 8:00 | AC31: =SUM(C31:Z31) -> 4 | AD31: =C31+E31+G31+I31+K31+M31+O31+Q31+S31+U31+W31+Y31 -> 2 | AE31: =E31+F31+I31+J31+M31+N31+Q31+R31+U31+V31+Y31+Z31 -> 3 | AF31: =E31+I31+M31+Q31+U31+Y31 -> 2 | AK31: =SUM(G31:N31)+SUM(S31:Z31) -> 2 | AL31: =SUM(C31:F31)+SUM(W31:Z31)+SUM(K31:R31) -> 2
A32: 8:00 à 8:30 | C32: =C16 -> 0 | D32: =D16 -> 1 | E32: =E16 -> 0 | F32: =F16 -> 0 | G32: =G16 -> 0 | H32: =H16 -> 0 | I32: =I16 -> 0 | J32: =J16 -> 1 | ... Z32: =Z16 -> 0 | AA32: =A32 -> 8:00 à 8:30 | AC32: =SUM(C32:Z32) -> 2 | AD32: =C32+E32+G32+I32+K32+M32+O32+Q32+S32+U32+W32+Y32 -> 0 | AE32: =E32+F32+I32+J32+M32+N32+Q32+R32+U32+V32+Y32+Z32 -> 1 | AF32: =E32+I32+M32+Q32+U32+Y32 -> 0 | AK32: =SUM(G32:N32)+SUM(S32:Z32) -> 1 | AL32: =SUM(C32:F32)+SUM(W32:Z32)+SUM(K32:R32) -> 1
A33: 8:30 à 9:00 | C33: =C17 -> 0 | D33: =D17 -> 0 | E33: =E17 -> 0 | F33: =F17 -> 0 | G33: =G17 -> 0 | H33: =H17 -> 0 | I33: =I17 -> 0 | J33: =J17 -> 0 | ... Z33: =Z17 -> 0 | AA33: =A33 -> 8:30 à 9:00 | AC33: =SUM(C33:Z33) -> 0 | AD33: =C33+E33+G33+I33+K33+M33+O33+Q33+S33+U33+W33+Y33 -> 0 | AE33: =E33+F33+I33+J33+M33+N33+Q33+R33+U33+V33+Y33+Z33 -> 0 | AF33: =E33+I33+M33+Q33+U33+Y33 -> 0 | AK33: =SUM(G33:N33)+SUM(S33:Z33) -> 0 | AL33: =SUM(C33:F33)+SUM(W33:Z33)+SUM(K33:R33) -> 0
A34: TOTAL | C34: =SUM(C13:C17) -> 0 | D34: =SUM(D13:D17) -> 2 | E34: =SUM(E13:E17) -> 0 | F34: =SUM(F13:F17) -> 1 | G34: =SUM(G13:G17) -> 5 | H34: =SUM(H13:H17) -> 2 | I34: =SUM(I13:I17) -> 3 | J34: =SUM(J13:J17) -> 1 | ... Z34: =SUM(Z13:Z17) -> 0 | AA34: TOTAL | AC34: =SUM(C34:Z34) -> 14 | AD34: =AD29+AD30+AD31+AD32+AD33 -> 8 | AE34: =AE29+AE31+AE33 -> 3 | AF34: =AF29+AF31+AF33 -> 2 | AG34: =A22 -> 0 | AH34: =A19 -> 0 | AJ34: =A21 -> 0 | AK34: =AK29+AK31+AK33 -> 4 | AL34: =AL29+AL31+AL33 -> 2
AA35: 7:00 à 7:30 | AC35: =AC30 -> 6
AA36: 7:30 à 8:00 | AC36: =AC31 -> 4
AA37: Total H pointe | AC37: =SUM(AC35:AC36) -> 10
AC39: TOTAL | AD39: Part des VAE dans le total | AE39: Part des femmes dans le total | AF39: Part des VAE chez les femmes | AK39: =AK25 -> Cycles sur rte de Dessy | AL39: =AL25 -> Cycles sur rte des Digues
AA42: Période
AA43: =AA29 -> 6:30 à 7:00 | AD43: =IF(AD29=0,0,AD29/AC29) -> 1 | AE43: =IF(AE29=0,0,AE29/AC29) -> 0 | AF43: =IF(AF29=0,0,AF29/AD29) -> 0 | AK43: =IF(AK29=0,0,AK29/AC29) -> 1 | AL43: =IF(AL29=0,0,AL29/AC29) -> 0
AA44: =AA30 -> 7:00 à 7:30 | AD44: =IF(AD31=0,0,AD31/AC31) -> 0.5 | AE44: =IF(AE31=0,0,AE31/AC31) -> 0.75 | AF44: =IF(AF31=0,0,AF31/AD31) -> 1 | AK44: =IF(AK31=0,0,AK31/AC31) -> 0.5 | AL44: =IF(AL31=0,0,AL31/AC31) -> 0.5
AA45: =AA31 -> 7:30 à 8:00 | AD45: =IF(AD31=0,0,AD31/AC31) -> 0.5 | AE45: =IF(AE31=0,0,AE31/AC31) -> 0.75 | AF45: =IF(AF31=0,0,AF31/AD31) -> 1 | AK45: =IF(AK31=0,0,AK31/AC31) -> 0.5 | AL45: =IF(AL31=0,0,AL31/AC31) -> 0.5
AA46: =AA32 -> 8:00 à 8:30 | AD46: =IF(AD32=0,0,AD32/AC32) -> 0 | AE46: =IF(AE32=0,0,AE32/AC32) -> 0.5 | AF46: =IF(AF32=0,0,AF32/AD32) -> 0 | AK46: =IF(AK32=0,0,AK32/AC32) -> 0.5 | AL46: =IF(AL32=0,0,AL32/AC32) -> 0.5
AA47: =AA33 -> 8:30 à 9:00 | AD47: =IF(AD33=0,0,AD33/AC33) -> 0 | AE47: =IF(AE33=0,0,AE33/AC33) -> 0 | AF47: =IF(AF33=0,0,AF33/AD33) -> 0 | AK47: =IF(AK33=0,0,AK33/AC33) -> 0 | AL47: =IF(AL33=0,0,AL33/AC33) -> 0
...

Sheet BO_BORNE_PRISON
B1: Bonneville Franchissement du Borne Tucinge - Prison | G1: Date :
A2: Nom des personnes participant au comptage : | E2: Martine
A3: Météo : | G3: Remarques :
A5: PRINCIPE D’UTILISATION : pour chaque intervalle de temps, comptabiliser VAE/vélo dans la colonne H/F
A6: Rajouter aussi en bas de la feuille si déplacement vélo sur trottoir et/ou si enfant
A7: Comptabiliser en bas de la grille si 2 roues hors vélo qui ne sont pas cochés dans la grille (trottinette, skate, ets)
C8: Pont du Borne
C9: Depuis Bonneville | G9: Depuis Tucinges
C10: H | D10: H | E10: F | F10: F | G10: H | H10: H | I10: F | J10: F
A11: Période | C11: VAE | D11: vélo | E11: VAE | F11: vélo | G11: VAE | H11: vélo | I11: VAE | J11: vélo
A12: 0.27083333 | B12: 0.29166667 | C12: 1
A13: 0.29166667 | B13: 0.3125 | D13: 2
A14: 0.3125 | B14: 0.33333333 | D14: 3
A15: 0.33333333 | B15: 0.35416667 | D15: 2 | H15: 10 | J15: 6
A16: 0.35416667 | B16: 0.375 | D16: 1 | E16: 2 | F16: 2
A18: 1 | B18: dont Enfant | D18: 1
A19: 1 | B19: vélo sur trottoir
A20: 1 | B20: dont Cyclo sportifs | D20: 1
B21: hors grille, plus 2 roues hors vélo (trottinette, skate...)
M22: en jaune, tableau global
C23: =C8 -> Pont du Borne | K23: Période | M23: TOTAL | N23: Nombre de VAE dans le total | O23: Nombre de femmes dans le total | P23: Nombre de VAE chez les femmes | Q23: plus trotinette skate | R23: dont enfant | S23: vélo sur trottoir | T23: dont cyclo | U23: Cycles en direction de Bonneville
C24: =C9 -> Depuis Bonneville | G24: =G9 -> Depuis Tucinges
C25: H | E25: F | G25: H | I25: F
A26: Période | C26: VAE | D26: vélo | E26: VAE | F26: vélo | G26: VAE | H26: vélo | I26: VAE | J26: vélo
A27: 6:30 à 7:00 | C27: =+C12 -> 1 | D27: =+D12 -> 0 | E27: =+E12 -> 0 | F27: =+F12 -> 0 | G27: =+G12 -> 0 | H27: =+H12 -> 0 | I27: =+I12 -> 0 | J27: =+J12 -> 0 | K27: =A27 -> 6:30 à 7:00 | M27: =SUM(C27:J27) -> 1 | N27: =C27+E27+G27+I27 -> 1 | O27: =E27+F27+I27+J27 -> 0 | P27: =E27+I27 -> 0 | U27: =SUM(G27:J27) -> 0
A28: 7:00 à 7:30 | C28: =+C13 -> 0 | D28: =+D13 -> 2 | E28: =+E13 -> 0 | F28: =+F13 -> 0 | G28: =+G13 -> 0 | H28: =+H13 -> 0 | I28: =+I13 -> 0 | J28: =+J13 -> 0 | K28: =A28 -> 7:00 à 7:30 | M28: =SUM(C28:J28) -> 2 | N28: =C28+E28+G28+I28 -> 0 | O28: =E28+F28+I28+J28 -> 0 | P28: =E28+I28 -> 0 | U28: =SUM(G28:J28) -> 0
A29: 7:30 à 8:00 | C29: =+C14 -> 0 | D29: =+D14 -> 3 | E29: =+E14 -> 0 | F29: =+F14 -> 0 | G29: =+G14 -> 0 | H29: =+H14 -> 0 | I29: =+I14 -> 0 | J29: =+J14 -> 0 | K29: =A29 -> 7:30 à 8:00 | M29: =SUM(C29:J29) -> 3 | N29: =C29+E29+G29+I29 -> 0 | O29: =E29+F29+I29+J29 -> 0 | P29: =E29+I29 -> 0 | U29: =SUM(G29:J29) -> 0
A30: 8:00 à 8:30 | C30: =+C15 -> 0 | D30: =+D15 -> 2 | E30: =+E15 -> 0 | F30: =+F15 -> 0 | G30: =+G15 -> 0 | H30: =+H15 -> 10 | I30: =+I15 -> 0 | J30: =+J15 -> 6 | K30: =A30 -> 8:00 à 8:30 | M30: =SUM(C30:J30) -> 18 | N30: =C30+E30+G30+I30 -> 0 | O30: =E30+F30+I30+J30 -> 6 | P30: =E30+I30 -> 0 | U30: =SUM(G30:J30) -> 16
A31: 8:30 à 9:00 | C31: =+C16 -> 0 | D31: =+D16 -> 1 | E31: =+E16 -> 2 | F31: =+F16 -> 2 | G31: =+G16 -> 0 | H31: =+H16 -> 0 | I31: =+I16 -> 0 | J31: =+J16 -> 0 | K31: =A31 -> 8:30 à 9:00 | M31: =SUM(C31:J31) -> 5 | N31: =C31+E31+G31+I31 -> 2 | O31: =E31+F31+I31+J31 -> 4 | P31: =E31+I31 -> 2 | U31: =SUM(G31:J31) -> 0
A32: TOTAL | C32: =SUM(C12:C16) -> 1 | D32: =SUM(D12:D16) -> 8 | E32: =SUM(E12:E16) -> 2 | F32: =SUM(F12:F16) -> 2 | G32: =SUM(G12:G16) -> 0 | H32: =SUM(H12:H16) -> 10 | I32: =SUM(I12:I16) -> 0 | J32: =SUM(J12:J16) -> 6 | K32: TOTAL | M32: =SUM(M27:M31) -> 29 | N32: =SUM(N27:N31) -> 3 | O32: =SUM(O27:O31) -> 10 | P32: =SUM(P27:P31) -> 2 | Q32: =A21 -> 0 | R32: =A18 -> 1 | T32: =A20 -> 1 | U32: =SUM(U27:U31) -> 16
K33: =K29 -> 7:30 à 8:00 | M33: =M29 -> 3
K34: =K30 -> 8:00 à 8:30 | M34: =M30 -> 18
K35: Total H pointe | M35: =SUM(M33:M34) -> 21
M37: TOTAL | N37: Part des VAE dans le total | O37: Part des femmes dans le total | P37: Part des VAE chez les femmes | U37: =U23 -> Cycles en direction de Bonneville
K40: Période
K41: =K27 -> 6:30 à 7:00 | N41: =IF(N27=0,0,N27/M27) -> 1 | O41: =IF(O27=0,0,O27/M27) -> 0 | P41: =IF(P27=0,0,P27/N27) -> 0 | U41: =IF(U27=0,0,U27/M27) -> 0
K42: =K28 -> 7:00 à 7:30 | N42: =IF(N29=0,0,N29/M29) -> 0 | O42: =IF(O29=0,0,O29/M29) -> 0 | P42: =IF(P29=0,0,P29/N29) -> 0 | U42: =IF(U29=0,0,U29/M29) -> 0
K43: =K29 -> 7:30 à 8:00 | N43: =IF(N29=0,0,N29/M29) -> 0 | O43: =IF(O29=0,0,O29/M29) -> 0 | P43: =IF(P29=0,0,P29/N29) -> 0 | U43: =IF(U29=0,0,U29/M29) -> 0
K44: =K30 -> 8:00 à 8:30 | N44: =IF(N30=0,0,N30/M30) -> 0 | O44: =IF(O30=0,0,O30/M30) -> 0.33333333 | P44: =IF(P30=0,0,P30/N30) -> 0 | U44: =IF(U30=0,0,U30/M30) -> 0.88888889
K45: =K31 -> 8:30 à 9:00 | N45: =IF(N31=0,0,N31/M31) -> 0.4 | O45: =IF(O31=0,0,O31/M31) -> 0.8 | P45: =IF(P31=0,0,P31/N31) -> 1 | U45: =IF(U31=0,0,U31/M31) -> 0
...

Sheet ST_PI_BORNE_RD1203
B1: St Pierre Pont sur le Borne Principal - RD 1203 | O1: Date :
A2: Nom des personnes participant au comptage : | J2: Christine | L2: côté La Roche | R2: René | T2: côté Bonneville
A3: Météo : | N3: Remarques :
A5: PRINCIPE D’UTILISATION : pour chaque intervalle de temps, comptabiliser VAE/vélo dans la colonne H/F
A6: Rajouter aussi en bas de la feuille si déplacement vélo sur trottoir et/ou si enfant
A7: Comptabiliser en bas de la grille si 2 roues hors vélo qui ne sont pas cochés dans la grille (trottinette, skate, ets)
C9: De Stade vers
C10: Bonneville | G10: Prison | K10: Tucinges | O10: La Roche | S10: Digues
C11: H | E11: F | G11: H | I11: F | K11: H | M11: F | O11: H | Q11: F | S11: H | U11: F
A12: Période | C12: VAE | D12: vélo | E12: VAE | F12: vélo | G12: VAE | H12: vélo | I12: VAE | J12: vélo | K12: VAE | L12: vélo | M12: VAE | N12: vélo | O12: VAE | P12: vélo | Q12: VAE | R12: vélo | S12: VAE | T12: vélo | U12: VAE | V12: vélo
A13: 0.27083333 | B13: 0.29166667 | H13: 1
A14: 0.29166667 | B14: 0.3125 | W14: =SUM(C14:V14) -> 0
A15: 0.3125 | B15: 0.33333333 | W15: =SUM(C15:V15) -> 0
A16: 0.33333333 | B16: 0.35416667
A17: 0.35416667 | B17: 0.375 | N17: 1
W18: =SUM(W13:W17) -> 0
C19: De Bonneville vers
C20: Prison | G20: Tucinges | K20: La Roche | O20: Digues | S20: Stade
C21: H | E21: F | G21: H | I21: F | K21: H | M21: F | O21: H | Q21: F | S21: H | U21: F
A22: Période | C22: VAE | D22: vélo | E22: VAE | F22: vélo | G22: VAE | H22: vélo | I22: VAE | J22: vélo | K22: VAE | L22: vélo | M22: VAE | N22: vélo | O22: VAE | P22: vélo | Q22: VAE | R22: vélo | S22: VAE | T22: vélo | U22: VAE | V22: vélo
A23: 0.27083333 | B23: 0.29166667 | P23: 3 | W23: =SUM(C23:V23) -> 3
A24: 0.29166667 | B24: 0.3125 | K24: 1 | L24: 1 | P24: 1 | W24: =SUM(C24:V24) -> 3
A25: 0.3125 | B25: 0.33333333 | L25: 1 | W25: =SUM(C25:V25) -> 1
A26: 0.33333333 | B26: 0.35416667 | L26: 1 | P26: 1 | W26: =SUM(C26:V26) -> 2
A27: 0.35416667 | B27: 0.375 | L27: 1 | W27: =SUM(C27:V27) -> 1
W28: =SUM(W23:W27) -> 10
C29: De Prison vers
C30: Tucinges | G30: La Roche | K30: Digues | O30: Stade | S30: Bonneville
C31: H | E31: F | G31: H | I31: F | K31: H | M31: F | O31: H | Q31: F | S31: H | U31: F
A32: Période | C32: VAE | D32: vélo | E32: VAE | F32: vélo | G32: VAE | H32: vélo | I32: VAE | J32: vélo | K32: VAE | L32: vélo | M32: VAE | N32: vélo | O32: VAE | P32: vélo | Q32: VAE | R32: vélo | S32: VAE | T32: vélo | U32: VAE | V32: vélo
A33: 0.27083333 | B33: 0.29166667
A34: 0.29166667 | B34: 0.3125 | C34: 1 | K34: 2
A35: 0.3125 | B35: 0.33333333 | H35: 1
A36: 0.33333333 | B36: 0.35416667
A37: 0.35416667 | B37: 0.375
B38: dont Enfant
A39: 4 | B39: vélo sur trottoir
A40: 2 | B40: dont Cyclo sportifs
A41: 3 | B41: hors grille, plus 2 roues hors vélo (trottinette, skate...) | L41: 4
B42: St Pierre-Bonneville Pont sur le Borne Principal - RD 1203
...

Sheet ST_PI_M_BRICOLAGE
B1: ST PIERRE Mr BRICOLAGE | G1: Date :
A2: Nom des personnes participant au comptage : | F2: Simon
A3: Météo : | G3: Remarques :
A6: PRINCIPE D’UTILISATION : pour chaque intervalle de temps, comptabiliser VAE/vélo dans la colonne H/F
A7: Comptabiliser en bas de la grille si 2 roues hors vélo qui ne sont pas cochés dans la grille (trottinette, skate, ets)
C9: PISTE CYCLABLE en continu | K9: JAMAIS sur PISTE CYCLABLE
C10: Vers La Roche | G10: Vers Bonnevile | K10: Direction La Roche | O10: Direction Bonneville
C11: H | E11: F | G11: H | I11: F | K11: H | M11: F | O11: H | Q11: F
A12: Période | C12: VAE | D12: vélo | E12: VAE | F12: vélo | G12: VAE | H12: vélo | I12: VAE | J12: vélo | K12: VAE | L12: vélo | M12: VAE | N12: vélo | O12: VAE | P12: vélo | Q12: VAE | R12: vélo
A13: 0.27083333 | B13: 0.29166667
A14: 0.29166667 | B14: 0.3125 | D14: 3 | K14: 1
A15: 0.3125 | B15: 0.33333333 | G15: 1 | H15: 1 | L15: 1
A16: 0.33333333 | B16: 0.35416667
A17: 0.35416667 | B17: 0.375
C19: PARTIELLEMENT sur PISTE CYCLABLE
C20: Depuis ou vers La Roche | G20: Depuis ou vers Bonneville | K20: Depuis ou vers zone Jourdies | O20: Depuis ou vers St Pierre
C21: H | E21: F | G21: H | I21: F | K21: H | M21: F | O21: H | Q21: F
A22: Période | C22: VAE | D22: vélo | E22: VAE | F22: vélo | G22: VAE | H22: vélo | I22: VAE | J22: vélo | K22: VAE | L22: vélo | M22: VAE | N22: vélo | O22: VAE | P22: vélo | Q22: VAE | R22: vélo
A23: 0.27083333 | B23: 0.29166667 | K23: 4 | L23: 3 | O23: 1
A24: 0.29166667 | B24: 0.3125 | K24: 1 | L24: 2 | P24: 1
A25: 0.3125 | B25: 0.33333333 | K25: 2 | L25: 5
A26: 0.33333333 | B26: 0.35416667 | D26: 1 | L26: 3 | N26: 1
A27: 0.35416667 | B27: 0.375 | N27: 2
B28: dont Enfant
B29: vélo sur trottoir
B30: dont Cyclo sportifs
A31: 10 | B31: hors grille, plus 2 roues hors vélo (trottinette, skate...) | U31: en jaune, tableau global
U32: TOTAL | V32: Nombre de VAE dans le total | W32: Nombre de femmes dans le total | X32: Nombre de VAE chez les femmes | Y32: plus trotinette skate | Z32: dont enfant | AA32: vélo sur trottoir | AB32: dont cyclo
C34: H | E34: F
A35: Période | C35: VAE | D35: vélo | E35: VAE | F35: vélo | S35: Période
A36: 6:30 à 7:00 | C36: =C13+G13+K13+O13+C23+G23+K23+O23+Q23 -> 5 | D36: =D13+H13+L13+P13+D23+H23+L23+P23+R23 -> 3 | E36: =E13+I13+M13+Q13+E23+I23+M23+Q23+S23 -> 0 | F36: =F13+J13+N13+R13+F23+J23+N23+R23+T23 -> 0 | S36: =A36 -> 6:30 à 7:00 | U36: =SUM(C36:F36) -> 8 | V36: =C36+E36 -> 5 | W36: =E36+F36 -> 0 | X36: =E36 -> 0
A37: 7:00 à 7:30 | C37: =C14+G14+K14+O14+C24+G24+K24+O24+Q24 -> 2 | D37: =D14+H14+L14+P14+D24+H24+L24+P24+R24 -> 6 | E37: =E14+I14+M14+Q14+E24+I24+M24+Q24+S24 -> 0 | F37: =F14+J14+N14+R14+F24+J24+N24+R24+T24 -> 0 | S37: =A37 -> 7:00 à 7:30 | U37: =SUM(C37:F37) -> 8 | V37: =C37+E37 -> 2 | W37: =E37+F37 -> 0 | X37: =E37 -> 0
A38: 7:30 à 8:00 | C38: =C15+G15+K15+O15+C25+G25+K25+O25+Q25 -> 3 | D38: =D15+H15+L15+P15+D25+H25+L25+P25+R25 -> 7 | E38: =E15+I15+M15+Q15+E25+I25+M25+Q25+S25 -> 0 | F38: =F15+J15+N15+R15+F25+J25+N25+R25+T25 -> 0 | S38: =A38 -> 7:30 à 8:00 | U38: =SUM(C38:F38) -> 10 | V38: =C38+E38 -> 3 | W38: =E38+F38 -> 0 | X38: =E38 -> 0
A39: 8:00 à 8:30 | C39: =C16+G16+K16+O16+C26+G26+K26+O26+Q26 -> 0 | D39: =D16+H16+L16+P16+D26+H26+L26+P26+R26 -> 4 | E39: =E16+I16+M16+Q16+E26+I26+M26+Q26+S26 -> 0 | F39: =F16+J16+N16+R16+F26+J26+N26+R26+T26 -> 1 | S39: =A39 -> 8:00 à 8:30 | U39: =SUM(C39:F39) -> 5 | V39: =C39+E39 -> 0 | W39: =E39+F39 -> 1 | X39: =E39 -> 0
A40: 8:30 à 9:00 | C40: =C17+G17+K17+O17+C27+G27+K27+O27+Q27 -> 0 | D40: =D17+H17+L17+P17+D27+H27+L27+P27+R27 -> 0 | E40: =E17+I17+M17+Q17+E27+I27+M27+Q27+S27 -> 0 | F40: =F17+J17+N17+R17+F27+J27+N27+R27+T27 -> 2 | S40: =A40 -> 8:30 à 9:00 | U40: =SUM(C40:F40) -> 2 | V40: =C40+E40 -> 0 | W40: =E40+F40 -> 2 | X40: =E40 -> 0
A41: TOTAL | C41: =SUM(C36:C40) -> 10 | D41: =SUM(D36:D40) -> 20 | E41: =SUM(E36:E40) -> 0 | F41: =SUM(F36:F40) -> 3 | S41: TOTAL | U41: =SUM(U36:U40) -> 33 | V41: =SUM(V36:V40) -> 10 | W41: =SUM(W36:W40) -> 3 | X41: =SUM(X36:X40) -> 0 | Y41: =A31 -> 10 | Z41: =A28 -> 0 | AA41: =A29 -> 0 | AB41: =A30 -> 0
S42: 7:30 à 8:00 | U42: =U37 -> 8
S43: 8:00 à 8:30 | U43: =U38 -> 10
S44: Total H pointe | U44: =SUM(U42:U43) -> 18
S45: =IF(U36=MAX(U36:U40),S36,IF(U37=MAX(U36:U40),S37,IF(U37=MAX(U36:U40),S37,IF(U38=MAX(U36:U40),S38,IF(U39=MAX(U36:U40),S39))))) -> 7:30 à 8:00 | U45: 11 | V45: 1 | W45: 4 | X45: 2

Sheet AYZE
B1: AYZE Piste cyclable | G1: Date :
A2: Nom des personnes participant au comptage : | E2: Lise
A3: Météo : | G3: Remarques :
A5: PRINCIPE D’UTILISATION : pour chaque intervalle de temps, comptabiliser VAE/vélo dans la colonne H/F
A6: Rajouter aussi en bas de la feuille si déplacement vélo sur trottoir et/ou si enfant
A7: Comptabiliser en bas de la grille si 2 roues hors vélo qui ne sont pas cochés dans la grille (trottinette, skate, ets)
C8: AYZE piste cyclable
C9: Depuis Bonneville | G9: Depuis Marignier
C10: H | D10: H | E10: F | F10: F | G10: H | H10: H | I10: F | J10: F
A11: Période | C11: VAE | D11: vélo | E11: VAE | F11: vélo | G11: VAE | H11: vélo | I11: VAE | J11: vélo
A12: 0.27083333 | B12: 0.29166667 | C12: 1 | D12: 4 | H12: 3 | I12: 1 | J12: 2
A13: 0.29166667 | B13: 0.3125 | D13: 2 | E13: 1 | G13: 3 | H13: 3 | J13: 1
A14: 0.3125 | B14: 0.33333333 | D14: 5 | E14: 1 | F14: 3 | H14: 2
A15: 0.33333333 | B15: 0.35416667 | D15: 3 | H15: 1 | I15: 1
A16: 0.35416667 | B16: 0.375 | D16: 5 | F16: 1 | H16: 2
B18: dont Enfant
B19: vélo sur trottoir
B20: dont Cyclo sportifs
B21: hors grille, plus 2 roues hors vélo (trottinette, skate...) | G21: 4
M22: en jaune, tableau global
