Workbook

Sheet LA_RO_BIOCOOP
A1: Lieu : | B1: La Roche Face Biocoop | P1: Date : | R1: le jeudi 12 juin
A2: Nom des personnes participant au comptage : | L2: Philippe
A3: Météo : | P3: Remarques :
A5: PRINCIPE D’UTILISATION : pour chaque intervalle de temps, comptabiliser VAE/vélo dans la colonne H/F
A6: Rajouter aussi en bas de la feuille si déplacement vélo sur trottoir et/ou si enfant
A7: Comptabiliser en bas de la grille si 2 roues hors vélo qui ne sont pas cochés dans la grille (trottinette, skate, ets)
C9: De La Gare (Fg St Bernard) vers | O9: Du Pont du Foron vers | AA9: Du Rd Point La Poste vers
C10: Rd Pt Poste | G10: Rue Perrine | K10: Pont du Foron | O10: Rue Perrine | S10: Rd Pt Poste | W10: La Gare | AA10: Rue Perrine | AE10: Pont du Foron | AI10: La Gare
C11: H | E11: F | G11: H | I11: F | K11: H | M11: F | O11: H | Q11: F | S11: H | U11: F | W11: H | Y11: F | AA11: H | AC11: F | AE11: H | AG11: F | AI11: H | AK11: F | AN11: la gare
A12: Période | C12: VAE | D12: vélo | E12: VAE | F12: vélo | G12: VAE | H12: vélo | I12: VAE | J12: vélo | K12: VAE | L12: vélo | M12: VAE | N12: vélo | O12: VAE | P12: vélo | Q12: VAE | R12: vélo | S12: VAE | T12: vélo | U12: VAE | V12: vélo | W12: VAE | X12: vélo | Y12: VAE | Z12: vélo | AA12: VAE | AB12: vélo | AC12: VAE | AD12: vélo | AE12: VAE | AF12: vélo | AG12: VAE | AH12: vélo | AI12: VAE | AJ12: vélo | AK12: VAE | AL12: vélo | AN12: 60 | AO12: =AN12/101 -> 0.59405941
A13: 0.27083333 | B13: 0.29166667 | N13: 1 | S13: 3 | T13: 1 | W13: 1 | X13: 4 | AE13: 3 | AF13: 1 | AI13: 1 | AJ13: 1 | AM13: =SUM(C13:AL13) -> 16 | AN13: Sur 101
A14: 0.29166667 | B14: 0.3125 | K14: 1 | L14: 1 | M14: 1 | U14: 1 | W14: 2 | X14: 5 | Y14: 2 | Z14: 1 | AB14: 1 | AF14: 1 | AH14: 1 | AI14: 1 | AL14: 1 | AM14: =SUM(C14:AL14) -> 19
A15: 0.3125 | B15: 0.33333333 | L15: 4 | T15: 2 | U15: 3 | V15: 2 | Y15: 4 | AE15: 1 | AI15: 1 | AJ15: 1 | AK15: 1 | AM15: =SUM(C15:AL15) -> 19
A16: 0.33333333 | B16: 0.35416667 | D16: 1 | L16: 5 | N16: 1 | S16: 2 | U16: 2 | W16: 1 | X16: 4 | Y16: 3 | Z16: 2 | AE16: 1 | AF16: 2 | AJ16: 4 | AL16: 1 | AM16: =SUM(C16:AL16) -> 29
A17: 0.35416667 | B17: 0.375 | K17: 1 | L17: 1 | M17: 1 | S17: 3 | T17: 2 | U17: 2 | V17: 1 | W17: 1 | X17: 1 | AA17: 2 | AB17: 1 | AE17: 1 | AL17: 1 | AM17: =SUM(C17:AL17) -> 18
AM18: =SUM(C18:AL18) -> 0
B19: dont Enfant | F19: 3
B20: Dont vélo sur trottoir | H20: 12
B21: dont Cyclo sportifs | H21: 9
B22: hors grille, plus 2 roues hors vélo (trottinette, skate...) | R22: 16
C26: =C9 -> De La Gare (Fg St Bernard) vers | O26: =O9 -> Du Pont du Foron vers | AA26: =AA9 -> Du Rd Point La Poste vers | AO26: TOTAL | AP26: Nombre de VAE dans le total | AQ26: Nombre de femmes dans le total | AR26: Nombre de VAE chez les femmes | AX26: Nombre de VAE chez les femmes | AY26: Cycles direc La Gare
C27: =C10 -> Rd Pt Poste | G27: =G10 -> Rue Perrine | K27: =K10 -> Pont du Foron | O27: =O10 -> Rue Perrine | S27: =S10 -> Rd Pt Poste | W27: =W10 -> La Gare | AA27: =AA10 -> Rue Perrine | AE27: =AE10 -> Pont du Foron | AI27: =AI10 -> La Gare
C28: H | E28: F | G28: H | I28: F | K28: H | M28: F | O28: H | Q28: F | S28: H | U28: F | W28: H | Y28: F | AA28: H | AC28: F | AE28: H | AG28: F | AI28: H | AK28: F
A29: Période | C29: VAE | D29: vélo | E29: VAE | F29: vélo | G29: VAE | H29: vélo | I29: VAE | J29: vélo | K29: VAE | L29: vélo | M29: VAE | N29: vélo | O29: VAE | P29: vélo | Q29: VAE | R29: vélo | S29: VAE | T29: vélo | U29: VAE | V29: vélo | W29: VAE | X29: vélo | Y29: VAE | Z29: vélo | AA29: VAE | AB29: vélo | AC29: VAE | AD29: vélo | AE29: VAE | AF29: vélo | AG29: VAE | AH29: vélo | AI29: VAE | AJ29: vélo | AK29: VAE | AL29: vélo | AM29: Période | AS29: plus trotinette skate | AT29: dont enfant | AU29: vélo sur trottoir | AV29: dont cyclo
A30: 6:30 à 7:00 | C30: =+C13 -> 0 | D30: =+D13 -> 0 | E30: =+E13 -> 0 | F30: =+F13 -> 0 | G30: =+G13 -> 0 | H30: =+H13 -> 0 | I30: =+I13 -> 0 | J30: =+J13 -> 0 | ... AL30: =+AL13 -> 0 | AM30: 6:30 à 7:00 | AO30: =SUM(C30:AL30) -> 16 | AP30: =C30+E30+G30+I30+K30+M30+O30+Q30+S30+U30+W30+Y30+AA30+AC30+AE30+AG30+AI30+AK30 -> 8 | AQ30: =E30+F30+I30+J30+M30+N30+Q30+R30+U30+V30+Y30+Z30+AC30+AD30+AG30+AH30+AK30+AL30 -> 1 | AR30: =E30+I30+M30+Q30+U30+Y30+AC30+AG30+AK30 -> 0 | AX30: =E30+I30+M30+Q30+U30+Y30+AC30+AG30+AK30 -> 0 | AY30: =SUM(C30:N30)+SUM(W30:Z30)+SUM(AI30:AL30) -> 8
A31: 7:00 à 7:30 | C31: =+C14 -> 0 | D31: =+D14 -> 0 | E31: =+E14 -> 0 | F31: =+F14 -> 0 | G31: =+G14 -> 0 | H31: =+H14 -> 0 | I31: =+I14 -> 0 | J31: =+J14 -> 0 | ... AL31: =+AL14 -> 1 | AM31: 7:00 à 7:30 | AO31: =SUM(C31:AL31) -> 19 | AP31: =C31+E31+G31+I31+K31+M31+O31+Q31+S31+U31+W31+Y31+AA31+AC31+AE31+AG31+AI31+AK31 -> 8 | AQ31: =E31+F31+I31+J31+M31+N31+Q31+R31+U31+V31+Y31+Z31+AC31+AD31+AG31+AH31+AK31+AL31 -> 7 | AR31: =E31+I31+M31+Q31+U31+Y31+AC31+AG31+AK31 -> 4 | AX31: =E31+I31+M31+Q31+U31+Y31+AC31+AG31+AK31 -> 4 | AY31: =SUM(C31:N31)+SUM(W31:Z31)+SUM(AI31:AL31) -> 15
A32: 7:30 à 8:00 | C32: =+C15 -> 0 | D32: =+D15 -> 0 | E32: =+E15 -> 0 | F32: =+F15 -> 0 | G32: =+G15 -> 0 | H32: =+H15 -> 0 | I32: =+I15 -> 0 | J32: =+J15 -> 0 | ... AL32: =+AL15 -> 0 | AM32: 7:30 à 8:00 | AO32: =SUM(C32:AL32) -> 19 | AP32: =C32+E32+G32+I32+K32+M32+O32+Q32+S32+U32+W32+Y32+AA32+AC32+AE32+AG32+AI32+AK32 -> 10 | AQ32: =E32+F32+I32+J32+M32+N32+Q32+R32+U32+V32+Y32+Z32+AC32+AD32+AG32+AH32+AK32+AL32 -> 10 | AR32: =E32+I32+M32+Q32+U32+Y32+AC32+AG32+AK32 -> 8 | AX32: =E32+I32+M32+Q32+U32+Y32+AC32+AG32+AK32 -> 8 | AY32: =SUM(C32:N32)+SUM(W32:Z32)+SUM(AI32:AL32) -> 11
A33: 8:00 à 8:30 | C33: =+C16 -> 0 | D33: =+D16 -> 1 | E33: =+E16 -> 0 | F33: =+F16 -> 0 | G33: =+G16 -> 0 | H33: =+H16 -> 0 | I33: =+I16 -> 0 | J33: =+J16 -> 0 | ... AL33: =+AL16 -> 1 | AM33: 8:00 à 8:30 | AO33: =SUM(C33:AL33) -> 29 | AP33: =C33+E33+G33+I33+K33+M33+O33+Q33+S33+U33+W33+Y33+AA33+AC33+AE33+AG33+AI33+AK33 -> 9 | AQ33: =E33+F33+I33+J33+M33+N33+Q33+R33+U33+V33+Y33+Z33+AC33+AD33+AG33+AH33+AK33+AL33 -> 9 | AR33: =E33+I33+M33+Q33+U33+Y33+AC33+AG33+AK33 -> 5 | AX33: =E33+I33+M33+Q33+U33+Y33+AC33+AG33+AK33 -> 5 | AY33: =SUM(C33:N33)+SUM(W33:Z33)+SUM(AI33:AL33) -> 22
A34: 8:30 à 9:00 | C34: =+C17 -> 0 | D34: =+D17 -> 0 | E34: =+E17 -> 0 | F34: =+F17 -> 0 | G34: =+G17 -> 0 | H34: =+H17 -> 0 | I34: =+I17 -> 0 | J34: =+J17 -> 0 | ... AL34: =+AL17 -> 1 | AM34: 8:30 à 9:00 | AO34: =SUM(C34:AL34) -> 18 | AP34: =C34+E34+G34+I34+K34+M34+O34+Q34+S34+U34+W34+Y34+AA34+AC34+AE34+AG34+AI34+AK34 -> 11 | AQ34: =E34+F34+I34+J34+M34+N34+Q34+R34+U34+V34+Y34+Z34+AC34+AD34+AG34+AH34+AK34+AL34 -> 5 | AR34: =E34+I34+M34+Q34+U34+Y34+AC34+AG34+AK34 -> 3 | AX34: =E34+I34+M34+Q34+U34+Y34+AC34+AG34+AK34 -> 3 | AY34: =SUM(C34:N34)+SUM(W34:Z34)+SUM(AI34:AL34) -> 6
A35: TOTAL | C35: =+C18 -> 0 | D35: =+D18 -> 0 | E35: =+E18 -> 0 | F35: =+F18 -> 0 | G35: =+G18 -> 0 | H35: =+H18 -> 0 | I35: =+I18 -> 0 | J35: =+J18 -> 0 | ... AL35: =+AL18 -> 0 | AM35: TOTAL | AO35: =SUM(AO30:AO34) -> 101 | AP35: =SUM(AP30:AP34) -> 46 | AQ35: =SUM(AQ30:AQ34) -> 32 | AR35: =SUM(AR30:AR34) -> 20 | AS35: =A22 -> 0 | AT35: =A19 -> 0 | AU35: =A20 -> 0 | AV35: =A21 -> 0 | AX35: =E35+I35+M35+Q35+U35+Y35+AC35+AG35+AK35 -> 0 | AY35: =SUM(C35:N35)+SUM(W35:Z35)+SUM(AI35:AL35) -> 0
AL36: H POINTE | AM36: 7:30 à 8:00 | AO36: 18
AL37: H POINTE | AM37: 8:00 à 8:30 | AO37: 17
AM38: Total H pointe | AO38: =SUM(AO36:AO37) -> 35
AM39: =IF(AO30=MAX($AO$30:$AO$35),AM30,IF(AO31=MAX($AO$30:$AO$35),AM31,IF(AO32=MAX($AO$30:$AO$35),AM32,IF(AO33=MAX($AO$30:$AO$35),AM33,IF(AO34=MAX($AO$30:$AO$35),AM34,AM33))))) -> 8:00 à 8:30 | AO39: =IF(AQ30=MAX($AO$30:$AO$35),AO30,IF(AQ31=MAX($AO$30:$AO$35),AO31,IF(AQ32=MAX($AO$30:$AO$35),AO32,IF(AQ33=MAX($AO$30:$AO$35),AO33,IF(AQ34=MAX($AO$30:$AO$35),AO34,AO33))))) -> 29 | AP39: =IF(AT30=MAX($AO$30:$AO$35),AP30,IF(AT31=MAX($AO$30:$AO$35),AP31,IF(AT32=MAX($AO$30:$AO$35),AP32,IF(AT33=MAX($AO$30:$AO$35),AP33,IF(AT34=MAX($AO$30:$AO$35),AP34,AP33))))) -> 9 | AQ39: =IF(AU30=MAX($AO$30:$AO$35),AQ30,IF(AU31=MAX($AO$30:$AO$35),AQ31,IF(AU32=MAX($AO$30:$AO$35),AQ32,IF(AU33=MAX($AO$30:$AO$35),AQ33,IF(AU34=MAX($AO$30:$AO$35),AQ34,AQ33))))) -> 9 | AR39: =IF(AV30=MAX($AO$30:$AO$35),AR30,IF(AV31=MAX($AO$30:$AO$35),AR31,IF(AV32=MAX($AO$30:$AO$35),AR32,IF(AV33=MAX($AO$30:$AO$35),AR33,IF(AV34=MAX($AO$30:$AO$35),AR34,AR33))))) -> 5
AO40: TOTAL | AP40: Part des VAE dans le total | AQ40: Part des femmes dans le total | AR40: Part des VAE chez les femmes
AM43: Période
AM44: =AM30 -> 6:30 à 7:00 | AP44: =IF(AP31=0,0,AP31/AO31) -> 0.42105263 | AQ44: =IF(AQ31=0,0,AQ31/AO31) -> 0.36842105 | AR44: =IF(AT31=0,0,AT31/AP31) -> 0
AM45: =AM31 -> 7:00 à 7:30 | AP45: =IF(AP31=0,0,AP31/AO31) -> 0.42105263 | AQ45: =IF(AQ31=0,0,AQ31/AO31) -> 0.36842105 | AR45: =IF(AT31=0,0,AT31/AP31) -> 0
AM46: =AM32 -> 7:30 à 8:00 | AP46: =IF(AP32=0,0,AP32/AO32) -> 0.52631579 | AQ46: =IF(AQ32=0,0,AQ32/AO32) -> 0.52631579 | AR46: =IF(AT32=0,0,AT32/AP32) -> 0
AM47: =AM33 -> 8:00 à 8:30 | AP47: =IF(AP33=0,0,AP33/AO33) -> 0.31034483 | AQ47: =IF(AQ33=0,0,AQ33/AO33) -> 0.31034483 | AR47: =IF(AT33=0,0,AT33/AP33) -> 0
...

Sheet LA_RO_POSTE
B1: Rond Point La Poste | O1: Date : | Q1: Le mardi 10/06/2025
A2: Nom des personnes participant au comptage : | H2: Birgit
A3: Météo : | P3: Remarques :
A5: PRINCIPE D’UTILISATION : pour chaque intervalle de temps, comptabiliser VAE/vélo dans la colonne H/F
A6: Rajouter aussi en bas de la feuille si déplacement vélo sur trottoir et/ou si enfant
A7: Comptabiliser en bas de la grille si 2 roues hors vélo qui ne sont pas cochés dans la grille (trottinette, skate, ets)
C9: De Bonneville vers | S9: De Grenette (contre-sens) | AE9: De La Base(contre-sens)
C10: Grenette | G10: Orange | K10: La Base | O10: J Jaurès (contre sens) | S10: Orange | W10: La Base | AA10: Bonneville | AE10: Bonneville | AJ10: Orange | AM10: Place Grenette
C11: H | E11: F | G11: H | I11: F | K11: H | M11: F | O11: H | Q11: F | S11: H | U11: F | W11: H | Y11: F | AA11: H | AC11: F | AE11: H | AG11: F | AH11: F | AJ11: H | AM11: H | AO11: F
A12: Période | C12: VAE | D12: vélo | E12: VAE | F12: vélo | G12: VAE | H12: vélo | I12: VAE | J12: vélo | K12: VAE | L12: vélo | M12: VAE | N12: vélo | O12: VAE | P12: vélo | Q12: VAE | R12: vélo | S12: VAE | T12: vélo | U12: VAE | V12: vélo | W12: VAE | X12: vélo | Y12: VAE | Z12: vélo | AA12: VAE | AB12: vélo | AC12: VAE | AD12: vélo | AE12: VAE | AF12: vélo | AG12: VAE | AH12: VAE | AI12: vélo | AJ12: VAE | AK12: vélo | AL12: vélo | AM12: VAE | AN12: vélo | AO12: VAE | AP12: vélo
A13: 0.27083333 | B13: 0.29166667 | I13: 1 | P13: 1
A14: 0.29166667 | B14: 0.3125 | I14: 1
A15: 0.3125 | B15: 0.33333333 | G15: 2 | I15: 1 | L15: 1
A16: 0.33333333 | B16: 0.35416667 | D16: 1 | G16: 1 | H16: 2 | M16: 1 | AF16: 1
A17: 0.35416667 | B17: 0.375 | G17: 2 | H17: 1 | I17: 1 | AK17: 1
A18: 9 | B18: 00 – 15
B19: 15 – 30
C21: De Orange vers | O21: De Jean Jaurès MJC vers
C22: La Base | G22: Bonneville | K22: Grenette | O22: Orange | S22: Grenette | W22: Bonneville | AA22: La Base
C23: H | E23: F | G23: H | I23: F | K23: H | M23: F | O23: H | Q23: F | S23: H | U23: F | W23: H | Y23: F | AA23: H | AC23: F
A24: Période | C24: VAE | D24: vélo | E24: VAE | F24: vélo | G24: VAE | H24: vélo | I24: VAE | J24: vélo | K24: VAE | L24: vélo | M24: VAE | N24: vélo | O24: VAE | P24: vélo | Q24: VAE | R24: vélo | S24: VAE | T24: vélo | U24: VAE | V24: vélo | W24: VAE | X24: vélo | Y24: VAE | Z24: vélo | AA24: VAE | AB24: vélo | AC24: VAE | AD24: vélo
A25: 0.27083333 | B25: 0.29166667 | J25: 1 | O25: 1
A26: 0.29166667 | B26: 0.3125 | G26: 1 | J26: 1 | W26: 1 | X26: 2
A27: 0.3125 | B27: 0.33333333 | G27: 3 | H27: 3 | I27: 1 | L27: 1
A28: 0.33333333 | B28: 0.35416667 | D28: 1 | G28: 1 | H28: 1 | O28: 1 | AC28: 1
A29: 0.35416667 | B29: 0.375 | D29: 2 | F29: 2 | H29: 1 | P29: 1 | S29: 1 | AP29: x
A30: 9 | B30: 00 – 15
B31: 15 – 30
B33: dont Enfant | F33: 3
B34: Dont vélo sur trottoir | F34: 2
B35: dont Cyclo sportifs | F35: 1
B36: hors grille, plus 2 roues hors vélo (trottinette, skate...) | N36: 12
B37: motos | C37: 54 | AC37: TOTAL | AD37: Nombre de VAE dans le total | AE37: Nombre de femmes dans le total | AF37: Nombre de VAE chez les femmes
C39: H | E39: F
A40: Période | C40: VAE | D40: vélo | E40: VAE | F40: vélo | AA40: Période | AH40: plus trotinette skate | AI40: dont enfant | AJ40: vélo sur trottoir | AK40: dont cyclo
A41: 6:30 à 7:00 | C41: =C13+G13+K13+O13+S13+W13+AA13+AE13+AJ13+AM13+C25+G25+K25+O25+S25+W25+AA25 -> 1 | D41: =D13+H13+L13+P13+T13+X13+AB13+AF13+AK13+AN13+D25+H25+L25+P25+T25+X25+AB25 -> 1 | E41: =E13+I13+M13+Q13+U13+Y13+AC13+AG13+AH13+AO13+E25+I25+M25+Q25+U25+Y25+AC25 -> 1 | F41: =F13+J13+N13+R13+V13+Z13+AD13+AI13+AL16+AP13+F25+J25+N25+R25+V25+Z25+AD25 -> 1 | AA41: 6:30 à 7:00 | AC41: =SUM(C41:F41) -> 4 | AD41: =C41+E41 -> 2 | AE41: =E41+F41 -> 2 | AF41: =E41 -> 1
A42: 7:00 à 7:30 | C42: =C14+G14+K14+O14+S14+W14+AA14+AE14+AJ14+AM14+C26+G26+K26+O26+S26+W26+AA26 -> 2 | D42: =D14+H14+L14+P14+T14+X14+AB14+AF14+AK14+AN14+D26+H26+L26+P26+T26+X26+AB26 -> 2 | E42: =E14+I14+M14+Q14+U14+Y14+AC14+AG14+AH14+AO14+E26+I26+M26+Q26+U26+Y26+AC26 -> 1 | F42: =F14+J14+N14+R14+V14+Z14+AD14+AI14+AL17+AP14+F26+J26+N26+R26+V26+Z26+AD26 -> 1 | AA42: 7:00 à 7:30 | AC42: =SUM(C42:F42) -> 6 | AD42: =C42+E42 -> 3 | AE42: =E42+F42 -> 2 | AF42: =E42 -> 1
A43: 7:30 à 8:00 | C43: =C15+G15+K15+O15+S15+W15+AA15+AE15+AJ15+AM15+C27+G27+K27+O27+S27+W27+AA27 -> 5 | D43: =D15+H15+L15+P15+T15+X15+AB15+AF15+AK15+AN15+D27+H27+L27+P27+T27+X27+AB27 -> 5 | E43: =E15+I15+M15+Q15+U15+Y15+AC15+AG15+AH15+AO15+E27+I27+M27+Q27+U27+Y27+AC27 -> 2 | F43: =F15+J15+N15+R15+V15+Z15+AD15+AI15+AL18+AP15+F27+J27+N27+R27+V27+Z27+AD27 -> 0 | AA43: 7:30 à 8:00 | AC43: =SUM(C43:F43) -> 12 | AD43: =C43+E43 -> 7 | AE43: =E43+F43 -> 2 | AF43: =E43 -> 2
A44: 8:00 à 8:30 | C44: =C16+G16+K16+O16+S16+W16+AA16+AE16+AJ16+AM16+C28+G28+K28+O28+S28+W28+AA28 -> 3 | D44: =D16+H16+L16+P16+T16+X16+AB16+AF16+AK16+AN16+D28+H28+L28+P28+T28+X28+AB28 -> 6 | E44: =E16+I16+M16+Q16+U16+Y16+AC16+AG16+AH16+AO16+E28+I28+M28+Q28+U28+Y28+AC28 -> 2 | F44: =F16+J16+N16+R16+V16+Z16+AD16+AI16+AL19+AP16+F28+J28+N28+R28+V28+Z28+AD28 -> 0 | AA44: 8:00 à 8:30 | AC44: =SUM(C44:F44) -> 11 | AD44: =C44+E44 -> 5 | AE44: =E44+F44 -> 2 | AF44: =E44 -> 2
A45: 8:30 à 9:00 | C45: =C17+G17+K17+O17+S17+W17+AA17+AE17+AJ17+AM17+C29+G29+K29+O29+S29+W29+AA29 -> 3 | D45: =D17+H17+L17+P17+T17+X17+AB17+AF17+AK17+AN17+D29+H29+L29+P29+T29+X29+AB29 -> 6 | E45: =E17+I17+M17+Q17+U17+Y17+AC17+AG17+AH17+AO17+E29+I29+M29+Q29+U29+Y29+AC29 -> 1 | F45: =F17+J17+N17+R17+V17+Z17+AD17+AI17+AK17+AP17+F29+J29+N29+R29+V29+Z29+AD29 -> 3 | AA45: 8:30 à 9:00 | AC45: =SUM(C45:F45) -> 13 | AD45: =C45+E45 -> 4 | AE45: =E45+F45 -> 4 | AF45: =E45 -> 1
...

Sheet LA_RO_SNCF
B1: La Roche Gare/Passage à niveau | O1: Date : | S1: 2025 Fait avec appli
A2: Nom des personnes participant au comptage : | M2: Sylviane | S2: Le mardi 10/06/2025
A3: Météo :
A4: Remarques :
A6: PRINCIPE D’UTILISATION : pour chaque intervalle de temps, comptabiliser VAE/vélo dans la colonne H/F
A7: Rajouter aussi en bas de la feuille si déplacement vélo sur trottoir et/ou si enfant
A8: Comptabiliser en bas de la grille si 2 roues hors vélo qui ne sont pas cochés dans la grille (trottinette, skate, ets)
C10: D’Eteaux vers | O10: De av Lucien Rannard vers | AA10: Dr Roux vers
C11: Av L Rannard | G11: Av J Jaurès | K11: Gare/av Gare | O11: Av J Jaurès | S11: Gare/av Gare | W11: Eteaux | AA11: Gare
C12: H | E12: F | G12: H | I12: F | K12: H | M12: F | O12: H | Q12: F | S12: H | U12: F | W12: H | Y12: F | AA12: H | AC12: F
A13: Période | C13: VAE | D13: vélo | E13: VAE | F13: vélo | G13: VAE | H13: vélo | I13: VAE | J13: vélo | K13: VAE | L13: vélo | M13: VAE | N13: vélo | O13: VAE | P13: vélo | Q13: VAE | R13: vélo | S13: VAE | T13: vélo | U13: VAE | V13: vélo | W13: VAE | X13: vélo | Y13: VAE | Z13: vélo | AA13: VAE | AB13: vélo | AC13: VAE | AD13: vélo
A14: 0.27083333 | B14: 0.29166667
A15: 0.29166667 | B15: 0.3125
A16: 0.3125 | B16: 0.33333333
A17: 0.33333333 | B17: 0.35416667
A18: 8h30 | B18: 0.375
C20: De av J Jaurès vers | O20: De Gare et av Gare vers | AA20: Av Gare vers
C21: Gare/av Gare | G21: Eteaux | K21: Av L Rannard | O21: Eteaux | S21: Av L Rannard | W21: Av J Jaurès | AA21: Gare
C22: H | E22: F | G22: H | I22: F | K22: H | M22: F | O22: H | Q22: F | S22: H | U22: F | W22: H | Y22: F | AA22: H | AC22: F
A23: Période | C23: VAE | D23: vélo | E23: VAE | F23: vélo | G23: VAE | H23: vélo | I23: VAE | J23: vélo | K23: VAE | L23: vélo | M23: VAE | N23: vélo | O23: VAE | P23: vélo | Q23: VAE | R23: vélo | S23: VAE | T23: vélo | U23: VAE | V23: vélo | W23: VAE | X23: vélo | Y23: VAE | Z23: vélo | AA23: VAE | AB23: vélo | AC23: VAE | AD23: vélo
A24: 0.27083333 | B24: 0.29166667
A25: 0.29166667 | B25: 0.3125
A26: 0.3125 | B26: 0.33333333
A27: 0.33333333 | B27: 0.35416667
A28: 8h30 | B28: 0.375
B30: dont Enfant
B31: Dont vélo sur trottoir
B32: dont Cyclo sportifs
B33: hors grille, plus 2 roues hors vélo (trottinette, skate...)
AG34: en jaune, tableau global
AG35: TOTAL | AH35: Nombre de VAE dans le total | AI35: Nombre de femmes dans le total | AJ35: Nombre de VAE chez les femmes | AK35: Cycles sur route de Reignier
C37: H | E37: F
A38: Période | C38: VAE | D38: vélo | E38: VAE | F38: vélo | AE38: Période | AL38: plus trotinette skate | AM38: dont enfant | AN38: vélo sur trottoir | AO38: dont cyclo
A39: 6:30 à 7:00 | C39: =C14+G14+K14+O14+S14+AA14+C24+G24+K24+O24+S24+AA24+W14+W24 -> 0 | D39: =D14+H14+L14+P14+T14+AB14+D24+H24+L24+P24+T24+AB24+X24+X14 -> 0 | E39: =E14+I14+M14+Q14+U14+AC14+E24+I24+M24+Q24+U24+AC24+Y24+Y14 -> 0 | F39: =F14+J14+N14+R14+V14+AD14+F24+J24+N24+R24+V24+AD24+Z24+Z14 -> 0 | AE39: =A39 -> 6:30 à 7:00 | AG39: =SUM(C39:AD39) -> 0 | AH39: =C39+E39 -> 0 | AI39: =E39+F39 -> 0 | AJ39: =E39 -> 0
A40: 7:00 à 7:30 | C40: =C15+G15+K15+O15+S15+AA15+C25+G25+K25+O25+S25+AA25+W15+W25 -> 0 | D40: =D15+H15+L15+P15+T15+AB15+D25+H25+L25+P25+T25+AB25+X25+X15 -> 0 | E40: =E15+I15+M15+Q15+U15+AC15+E25+I25+M25+Q25+U25+AC25+Y25+Y15 -> 0 | F40: =F15+J15+N15+R15+V15+AD15+F25+J25+N25+R25+V25+AD25+Z25+Z15 -> 0 | AE40: =A40 -> 7:00 à 7:30 | AG40: =SUM(C40:AD40) -> 0 | AH40: =C40+E40 -> 0 | AI40: =E40+F40 -> 0 | AJ40: =E40 -> 0
A41: 7:30 à 8:00 | C41: =C16+G16+K16+O16+S16+AA16+C26+G26+K26+O26+S26+AA26+W16+W26 -> 0 | D41: =D16+H16+L16+P16+T16+AB16+D26+H26+L26+P26+T26+AB26+X26+X16 -> 0 | E41: =E16+I16+M16+Q16+U16+AC16+E26+I26+M26+Q26+U26+AC26+Y26+Y16 -> 0 | F41: =F16+J16+N16+R16+V16+AD16+F26+J26+N26+R26+V26+AD26+Z26+Z16 -> 0 | AE41: =A41 -> 7:30 à 8:00 | AG41: =SUM(C41:AD41) -> 0 | AH41: =C41+E41 -> 0 | AI41: =E41+F41 -> 0 | AJ41: =E41 -> 0
A42: 8:00 à 8:30 | C42: =C17+G17+K17+O17+S17+AA17+C27+G27+K27+O27+S27+AA27+W17+W27 -> 0 | D42: =D17+H17+L17+P17+T17+AB17+D27+H27+L27+P27+T27+AB27+X27+X17 -> 0 | E42: =E17+I17+M17+Q17+U17+AC17+E27+I27+M27+Q27+U27+AC27+Y27+Y17 -> 0 | F42: =F17+J17+N17+R17+V17+AD17+F27+J27+N27+R27+V27+AD27+Z27+Z17 -> 0 | AE42: =A42 -> 8:00 à 8:30 | AG42: =SUM(C42:AD42) -> 0 | AH42: =C42+E42 -> 0 | AI42: =E42+F42 -> 0 | AJ42: =E42 -> 0
A43: 8:30 à 9h | C43: =C18+G18+K18+O18+S18+AA18+C28+G28+K28+O28+S28+AA28+W18+W28 -> 0 | D43: =D18+H18+L18+P18+T18+AB18+D28+H28+L28+P28+T28+AB28+X28+X18 -> 0 | E43: =E18+I18+M18+Q18+U18+AC18+E28+I28+M28+Q28+U28+AC28+Y28+Y18 -> 0 | F43: =F18+J18+N18+R18+V18+AD18+F28+J28+N28+R28+V28+AD28+Z28+Z18 -> 0 | AE43: =A43 -> 8:30 à 9h | AG43: =SUM(C43:AD43) -> 0 | AH43: =C43+E43 -> 0 | AI43: =E43+F43 -> 0 | AJ43: =E43 -> 0
A44: TOTAL | C44: 14 | D44: 39 | E44: 16 | F44: 7 | G44: =SUM(C44:F44) -> 76 | J44: + 58 % par rapport à 2024 | AE44: TOTAL | AG44: =SUM(AG39:AG43) -> 0 | AH44: =SUM(AH39:AH43) -> 0 | AI44: =SUM(AI39:AI43) -> 0 | AJ44: =SUM(AJ39:AJ43) -> 0 | AK44: =SUM(AK39:AK43) -> 0 | AL44: =A33 -> 0 | AM44: =A30 -> 0 | AN44: =A31 -> 0 | AO44: =A32 -> 0
I45: 10 velo enfants, tous des garçons, 2 ados sur voirie sinon 8 primaires sur trottoir Dont 1 qui a été déséquilibré et qui est allé sur la route | AF45: 7:00 à 7:30 | AG45: 18
...

Sheet LA_RO_ENILV
B1: La Roche Rond-Point ENILV - St Renan | O1: Date : | R1: Le mardi 10/06/2025
A2: Nom des personnes participant au comptage : | M2: Thierry
A3: Météo :
A4: Remarques :
A6: PRINCIPE D’UTILISATION : pour chaque intervalle de temps, comptabiliser VAE/vélo dans la colonne H/F
A7: Rajouter aussi en bas de la feuille si déplacement vélo sur trottoir et/ou si enfant
A8: Comptabiliser en bas de la grille si 2 roues hors vélo qui ne sont pas cochés dans la grille (trottinette, skate, ets)
C10: Du centre (La Roche) vers | O10: D'Eteaux av Gambetta vers | AA10: De Av Libération Enilv vers | AM10: De Reignier vers
C11: Av Gambetta Eteaux | G11: Av Libération Enilv | K11: Reignier | O11: Av Libération Enilv | S11: Reignier | W11: La Roche | AA11: Reignier | AE11: La Roche | AI11: Av Gambetta Eteaux | AM11: La Roche | AQ11: Av Gambetta Eteaux | AU11: Av Libération Enilv
C12: H | E12: F | G12: H | I12: F | K12: H | M12: F | O12: H | Q12: F | S12: H | U12: F | W12: H | Y12: F | AA12: H | AC12: F | AE12: H | AG12: F | AI12: H | AK12: F | AM12: H | AO12: F | AQ12: H | AS12: F | AU12: H | AW12: F
A13: H | B13: Minute | C13: VAE | D13: vélo | E13: VAE | F13: vélo | G13: VAE | H13: vélo | I13: VAE | J13: vélo | K13: VAE | L13: vélo | M13: VAE | N13: vélo | O13: VAE | P13: vélo | Q13: VAE | R13: vélo | S13: VAE | T13: vélo | U13: VAE | V13: vélo | W13: VAE | X13: vélo | Y13: VAE | Z13: vélo | AA13: VAE | AB13: vélo | AC13: VAE | AD13: vélo | AE13: VAE | AF13: vélo | AG13: VAE | AH13: vélo | AI13: VAE | AJ13: vélo | AK13: VAE | AL13: vélo | AM13: VAE | AN13: vélo | AO13: VAE | AP13: vélo | AQ13: VAE | AR13: vélo | AS13: VAE | AT13: vélo | AU13: VAE | AV13: vélo | AW13: VAE | AX13: vélo
A14: 0.27083333 | B14: 0.29166667 | L14: 1 | AB14: 1
A15: 0.29166667 | B15: 0.3125 | L15: 2 | AF15: 1
A16: 0.3125 | B16: 0.33333333 | G16: 1 | I16: 2 | L16: 1 | M16: 1 | N16: 1 | O16: 1 | AB16: 2 | AI16: 1 | AN16: 1
A17: 0.33333333 | B17: 0.35416667 | N17: 1 | AI17: 1 | AJ17: 1 | AM17: 1 | AV17: 2
A18: 0.35416667 | B18: 0.375 | L18: 1 | W18: 1 | AB18: 1
B20: dont Enfant | G20: 7
B21: vélo sur trottoir | G21: 7
B22: dont Cyclo sportifs
B23: hors grille, plus 2 roues hors vélo (trottinette, skate...) | V23: 2
C31: =C10 -> Du centre (La Roche) vers | O31: =O10 -> D'Eteaux av Gambetta vers | AA31: =AA10 -> De Av Libération Enilv vers | AM31: =AM10 -> De Reignier vers | BA31: TOTAL | BB31: Nombre de VAE dans le total | BC31: Nombre de femmes dans le total | BD31: Nombre de VAE chez les femmes | BE31: Cycles sur route de Reignier | BF31: Remarque
C32: =C11 -> Av Gambetta Eteaux | G32: =G11 -> Av Libération Enilv | K32: =K11 -> Reignier | O32: =O11 -> Av Libération Enilv | S32: =S11 -> Reignier | W32: =W11 -> La Roche | AA32: =AA11 -> Reignier | AE32: =AE11 -> La Roche | AI32: =AI11 -> Av Gambetta Eteaux | AM32: =AM11 -> La Roche | AQ32: =AQ11 -> Av Gambetta Eteaux | AU32: =AU11 -> Av Libération Enilv
C33: H | E33: F | G33: H | I33: F | K33: H | M33: F | O33: H | Q33: F | S33: H | U33: F | W33: H | Y33: F | AA33: H | AC33: F | AE33: H | AG33: F | AI33: H | AK33: F | AM33: H | AO33: F | AQ33: H | AS33: F | AU33: H | AW33: F
A34: Période | C34: VAE | D34: vélo | E34: VAE | F34: vélo | G34: VAE | H34: vélo | I34: VAE | J34: vélo | K34: VAE | L34: vélo | M34: VAE | N34: vélo | O34: VAE | P34: vélo | Q34: VAE | R34: vélo | S34: VAE | T34: vélo | U34: VAE | V34: vélo | W34: VAE | X34: vélo | Y34: VAE | Z34: vélo | AA34: VAE | AB34: vélo | AC34: VAE | AD34: vélo | AE34: VAE | AF34: vélo | AG34: VAE | AH34: vélo | AI34: VAE | AJ34: vélo | AK34: VAE | AL34: vélo | AM34: VAE | AN34: vélo | AO34: VAE | AP34: vélo | AQ34: VAE | AR34: vélo | AS34: VAE | AT34: vélo | AU34: VAE | AV34: vélo | AW34: VAE | AX34: vélo | AY34: Période
A35: 6:30 à 7:00 | C35: =C14 -> 0 | D35: =D14 -> 0 | E35: =E14 -> 0 | F35: =F14 -> 0 | G35: =G14 -> 0 | H35: =H14 -> 0 | I35: =I14 -> 0 | J35: =J14 -> 0 | ... AX35: =AX14 -> 0 | AY35: =A35 -> 6:30 à 7:00 | BA35: =SUM(C35:AX35) -> 2 | BB35: =C35+E35+G35+I35+K35+M35+O35+Q35+S35+U35+W35+Y35+AA35+AC35+AE35+AG35+AI35+AK35+AM35+AO35+AQ35+AS35+AU35+AW35 -> 0 | BC35: =E35+F35+I35+J35+M35+N35+Q35+R35+U35+V35+Y35+Z35+AC35+AD35+AG35+AH35+AK35+AL35+AO35+AP35+AS35+AT35+AW35+AX35 -> 0 | BD35: =E35+I35+M35+Q35+U35+Y35+AC35+AG35+AK35+AO35+AS35+AW35 -> 0 | BE35: =SUM(K35:N35)+SUM(S35:V35)+SUM(AA35:AD35)+SUM(AM35:AX35) -> 2 | BF35: 34 piétons plus 32 étudiants piétons en direction lycée
A36: 7:00 à 7:30 | C36: =C15 -> 0 | D36: =D15 -> 0 | E36: =E15 -> 0 | F36: =F15 -> 0 | G36: =G15 -> 0 | H36: =H15 -> 0 | I36: =I15 -> 0 | J36: =J15 -> 0 | ... AX36: =AX15 -> 0 | AY36: =A36 -> 7:00 à 7:30 | BA36: =SUM(C36:AX36) -> 3 | BB36: =C36+E36+G36+I36+K36+M36+O36+Q36+S36+U36+W36+Y36+AA36+AC36+AE36+AG36+AI36+AK36+AM36+AO36+AQ36+AS36+AU36+AW36 -> 0 | BC36: =E36+F36+I36+J36+M36+N36+Q36+R36+U36+V36+Y36+Z36+AC36+AD36+AG36+AH36+AK36+AL36+AO36+AP36+AS36+AT36+AW36+AX36 -> 0 | BD36: =E36+I36+M36+Q36+U36+Y36+AC36+AG36+AK36+AO36+AS36+AW36 -> 0 | BE36: =SUM(K36:N36)+SUM(S36:V36)+SUM(AA36:AD36)+SUM(AM36:AX36) -> 2 | BF36: et seulement 2 écoliers- 2 enfants comptés qui étaient sur le trottoir avec 1 parent
A37: 7:30 à 8:00 | C37: =C16 -> 0 | D37: =D16 -> 0 | E37: =E16 -> 0 | F37: =F16 -> 0 | G37: =G16 -> 1 | H37: =H16 -> 0 | I37: =I16 -> 2 | J37: =J16 -> 0 | ... AX37: =AX16 -> 0 | AY37: =A37 -> 7:30 à 8:00 | BA37: =SUM(C37:AX37) -> 11 | BB37: =C37+E37+G37+I37+K37+M37+O37+Q37+S37+U37+W37+Y37+AA37+AC37+AE37+AG37+AI37+AK37+AM37+AO37+AQ37+AS37+AU37+AW37 -> 6 | BC37: =E37+F37+I37+J37+M37+N37+Q37+R37+U37+V37+Y37+Z37+AC37+AD37+AG37+AH37+AK37+AL37+AO37+AP37+AS37+AT37+AW37+AX37 -> 4 | BD37: =E37+I37+M37+Q37+U37+Y37+AC37+AG37+AK37+AO37+AS37+AW37 -> 3 | BE37: =SUM(K37:N37)+SUM(S37:V37)+SUM(AA37:AD37)+SUM(AM37:AX37) -> 6 | BF37: et seulement 2 écoliers- 2 enfants comptés qui étaient sur le trottoir avec 1 parent
A38: 8:00 à 8:30 | C38: =C17 -> 0 | D38: =D17 -> 0 | E38: =E17 -> 0 | F38: =F17 -> 0 | G38: =G17 -> 0 | H38: =H17 -> 0 | I38: =I17 -> 0 | J38: =J17 -> 0 | ... AX38: =AX17 -> 0 | AY38: =A38 -> 8:00 à 8:30 | BA38: =SUM(C38:AX38) -> 6 | BB38: =C38+E38+G38+I38+K38+M38+O38+Q38+S38+U38+W38+Y38+AA38+AC38+AE38+AG38+AI38+AK38+AM38+AO38+AQ38+AS38+AU38+AW38 -> 2 | BC38: =E38+F38+I38+J38+M38+N38+Q38+R38+U38+V38+Y38+Z38+AC38+AD38+AG38+AH38+AK38+AL38+AO38+AP38+AS38+AT38+AW38+AX38 -> 1 | BD38: =E38+I38+M38+Q38+U38+Y38+AC38+AG38+AK38+AO38+AS38+AW38 -> 0 | BE38: =SUM(K38:N38)+SUM(S38:V38)+SUM(AA38:AD38)+SUM(AM38:AX38) -> 4 | BF38: 2 des 3 femmes circulaient sur le trottoir !
A39: 8:30 à 9:00 | C39: =C18 -> 0 | D39: =D18 -> 0 | E39: =E18 -> 0 | F39: =F18 -> 0 | G39: =G18 -> 0 | H39: =H18 -> 0 | I39: =I18 -> 0 | J39: =J18 -> 0 | ... AX39: =AX18 -> 0 | AY39: =A39 -> 8:30 à 9:00 | BA39: =SUM(C39:AX39) -> 3 | BB39: =C39+E39+G39+I39+K39+M39+O39+Q39+S39+U39+W39+Y39+AA39+AC39+AE39+AG39+AI39+AK39+AM39+AO39+AQ39+AS39+AU39+AW39 -> 1 | BC39: =E39+F39+I39+J39+M39+N39+Q39+R39+U39+V39+Y39+Z39+AC39+AD39+AG39+AH39+AK39+AL39+AO39+AP39+AS39+AT39+AW39+AX39 -> 0 | BD39: =E39+I39+M39+Q39+U39+Y39+AC39+AG39+AK39+AO39+AS39+AW39 -> 0 | BE39: =SUM(K39:N39)+SUM(S39:V39)+SUM(AA39:AD39)+SUM(AM39:AX39) -> 2 | BF39: 3 cyclosportifs
A40: TOTAL | C40: =SUM(C14:C18) -> 0 | D40: =SUM(D14:D18) -> 0 | E40: =SUM(E14:E18) -> 0 | F40: =SUM(F14:F18) -> 0 | G40: =SUM(G14:G18) -> 1 | H40: =SUM(H14:H18) -> 0 | I40: =SUM(I14:I18) -> 2 | J40: =SUM(J14:J18) -> 0 | ... AX40: =SUM(AX14:AX18) -> 0 | AY40: TOTAL | BA40: =SUM(C40:AX40) -> 25 | BB40: =C40+E40+G40+I40+K40+M40+O40+Q40+S40+U40+W40+Y40+AA40+AC40+AE40+AG40+AI40+AK40+AM40+AO40+AQ40+AS40+AU40+AW40 -> 9 | BC40: =E40+F40+I40+J40+M40+N40+Q40+R40+U40+V40+Y40+Z40+AC40+AD40+AG40+AH40+AK40+AL40+AO40+AP40+AS40+AT40+AW40+AX40 -> 5 | BD40: =E40+I40+M40+Q40+U40+Y40+AC40+AG40+AK40+AO40+AS40+AW40 -> 3 | BE40: =SUM(K40:N40)+SUM(S40:V40)+SUM(AA40:AD40)+SUM(AM40:AX40) -> 16
AY41: =IF($BA$35=MAX($BA$35:$BA$39),AY35,IF($BA$36=MAX($BA$35:$BA$39),AY36,IF($BA$37=MAX($BA$35:$BA$39),AY37,IF($BA$38=MAX($BA$35:$BA$39),AY38,IF($BA$39=MAX($BA$35:$BA$39),AY39,AY38))))) -> 7:30 à 8:00 | BA41: =IF($BA$35=MAX($BA$35:$BA$39),BA35,IF($BA$36=MAX($BA$35:$BA$39),BA36,IF($BA$37=MAX($BA$35:$BA$39),BA37,IF($BA$38=MAX($BA$35:$BA$39),BA38,IF($BA$39=MAX($BA$35:$BA$39),BA39,BA38))))) -> 11 | BB41: =IF($BA$35=MAX($BA$35:$BA$39),BB35,IF($BA$36=MAX($BA$35:$BA$39),BB36,IF($BA$37=MAX($BA$35:$BA$39),BB37,IF($BA$38=MAX($BA$35:$BA$39),BB38,IF($BA$39=MAX($BA$35:$BA$39),BB39,BB38))))) -> 6 | BC41: =IF($BA$35=MAX($BA$35:$BA$39),BC35,IF($BA$36=MAX($BA$35:$BA$39),BC36,IF($BA$37=MAX($BA$35:$BA$39),BC37,IF($BA$38=MAX($BA$35:$BA$39),BC38,IF($BA$39=MAX($BA$35:$BA$39),BC39,BC38))))) -> 4 | BD41: =IF($BA$35=MAX($BA$35:$BA$39),BD35,IF($BA$36=MAX($BA$35:$BA$39),BD36,IF($BA$37=MAX($BA$35:$BA$39),BD37,IF($BA$38=MAX($BA$35:$BA$39),BD38,IF($BA$39=MAX($BA$35:$BA$39),BD39,BD38))))) -> 3 | BE41: =IF($BA$35=MAX($BA$35:$BA$39),BE35,IF($BA$36=MAX($BA$35:$BA$39),BE36,IF($BA$37=MAX($BA$35:$BA$39),BE37,IF($BA$38=MAX($BA$35:$BA$39),BE38,IF($BA$39=MAX($BA$35:$BA$39),BE39,BE38))))) -> 6
BA42: TOTAL | BB42: Part des VAE dans le total | BC42: Part des femmes dans le total | BD42: Part des VAE chez les femmes | BE42: =BE31 -> Cycles sur route de Reignier | BF42: Remarque
AY45: Période
AY46: =AY35 -> 6:30 à 7:00 | BB46: =IF(BB35=0,0,BB35/BA35) -> 0 | BC46: =IF(BC35=0,0,BC35/BA35) -> 0 | BD46: =IF(BD35=0,0,BD35/BB35) -> 0 | BE46: =IF(BE35=0,0,BE35/BA35) -> 1
AY47: =AY36 -> 7:00 à 7:30 | BB47: =IF(BB37=0,0,BB37/BA37) -> 0.54545455 | BC47: =IF(BC37=0,0,BC37/BA37) -> 0.36363636 | BD47: =IF(BD37=0,0,BD37/BB37) -> 0.5 | BE47: =IF(BE37=0,0,BE37/BA37) -> 0.54545455
AY48: =AY37 -> 7:30 à 8:00 | BB48: =IF(BB37=0,0,BB37/BA37) -> 0.54545455 | BC48: =IF(BC37=0,0,BC37/BA37) -> 0.36363636 | BD48: =IF(BD37=0,0,BD37/BB37) -> 0.5 | BE48: =IF(BE37=0,0,BE37/BA37) -> 0.54545455
AY49: =AY38 -> 8:00 à 8:30 | BB49: =IF(BB38=0,0,BB38/BA38) -> 0.33333333 | BC49: =IF(BC38=0,0,BC38/BA38) -> 0.16666667 | BD49: =IF(BD38=0,0,BD38/BB38) -> 0 | BE49: =IF(BE38=0,0,BE38/BA38) -> 0.66666667
AY50: =AY39 -> 8:30 à 9:00 | BB50: =IF(BB39=0,0,BB39/BA39) -> 0.33333333 | BC50: =IF(BC39=0,0,BC39/BA39) -> 0 | BD50: =IF(BD39=0,0,BD39/BB39) -> 0 | BE50: =IF(BE39=0,0,BE39/BA39) -> 0.66666667
AY51: TOTAL | BB51: =IF(BB40=0,0,BB40/BA40) -> 0.36 | BC51: =IF(BC40=0,0,BC40/BA40) -> 0.2 | BD51: =IF(BD40=0,0,BD40/BB40) -> 0.33333333 | BE51: =IF(BE40=0,0,BE40/BA40) -> 0.64
AV52: voir heure de pointe | AY52: =AY41 -> 7:30 à 8:00 | BB52: =BB41/$BA$41 -> 0.54545455 | BC52: =BC41/$BA$41 -> 0.36363636 | BD52: =BD41/$BA$41 -> 0.27272727 | BE52: =BE41/$BA$41 -> 0.54545455

Sheet LA RO ANDREV 24
B1: La Roche Andrevetan | E1: Rue Patience/St Sixt | K1: Date : | L1: le jeudi 12 juin
A2: Nom des personnes participant au comptage : | G2: Birgit
A3: Météo : | K3: Remarques :
A5: PRINCIPE D’UTILISATION : pour chaque intervalle de temps, comptabiliser VAE/vélo dans la colonne H/F
A6: Rajouter aussi en bas de la feuille si déplacement vélo sur trottoir et/ou si enfant
A7: Comptabiliser en bas de la grille si 2 roues hors vélo qui ne sont pas cochés dans la grille (trottinette, skate, ets)
C9: De La Roche vers | K9: De St Pierre rue Patience vers
C10: St Pierre/ Rue Patience | G10: St Sixt | K10: La Roche | O10: St Sixt
C11: H | E11: F | G11: H | I11: F | K11: H | M11: F | O11: H | Q11: F
A12: Période | C12: VAE | D12: vélo | E12: VAE | F12: vélo | G12: VAE | H12: vélo | I12: VAE | J12: vélo | K12: VAE | L12: vélo | M12: VAE | N12: vélo | O12: VAE | P12: vélo | Q12: VAE | R12: vélo
A13: 0.27083333 | B13: 0.29166667 | E13: 1 | G13: 1 | L13: 1 | S13: =SUM(C13:R13) -> 3
A14: 0.29166667 | B14: 0.3125 | C14: 2 | D14: 1 | E14: 1 | L14: 2 | Q14: 1 | S14: =SUM(C14:R14) -> 7
A15: 0.3125 | B15: 0.33333333 | G15: 1 | K15: 1 | M15: 1 | S15: =SUM(C15:R15) -> 3
A16: 0.33333333 | B16: 0.35416667 | C16: 1 | D16: 1 | F16: 1 | K16: 1 | L16: 1 | M16: 1 | S16: =SUM(C16:R16) -> 6
A17: 0.35416667 | B17: 0.375 | D17: 2 | E17: 1 | F17: 1 | J17: 1 | K17: 1 | L17: 1 | S17: =SUM(C17:R17) -> 7
C19: De St Sixt vers
C20: Rue Patience | G20: La Roche
C21: H | E21: F | G21: H | I21: F
A22: Période | C22: VAE | D22: vélo | E22: VAE | F22: vélo | G22: VAE | H22: vélo | I22: VAE | J22: vélo
A23: 0.27083333 | B23: 0.29166667 | E23: 1 | G23: 1 | K23: =SUM(C23:J23) -> 2
A24: 0.29166667 | B24: 0.3125 | C24: 1 | D24: 1 | G24: 3 | H24: 1 | K24: =SUM(C24:J24) -> 6
A25: 0.3125 | B25: 0.33333333 | K25: =SUM(C25:J25) -> 0
A26: 0.33333333 | B26: 0.35416667 | E26: 1 | G26: 1 | H26: 1 | I26: 1 | J26: 1 | K26: =SUM(C26:J26) -> 5
A27: 0.35416667 | B27: 0.375 | E27: 1 | F27: 1 | K27: =SUM(C27:J27) -> 2
B29: dont Enfant | E29: 1
B30: vélo sur trottoir
B31: dont Cyclo sportifs | E31: 7
B32: hors grille, plus 2 roues hors vélo (trottinette, skate...) | J32: 2
M33: en jaune, tableau global
M34: TOTAL | N34: Nombre de VAE dans le total | O34: Nombre de femmes dans le total | P34: Nombre de VAE chez les femmes | R34: dont enfant | S34: vélo sur trottoir | T34: dont cyclo | U34: plus trotinette skate
C36: H | E36: F
A37: Période | C37: VAE | D37: vélo | E37: VAE | F37: vélo | K37: Période
A38: 6:30 à 7:00 | C38: =C13+G13+K13+O13+C23+G23 -> 2 | D38: =D13+H13+L13+P13+D23+H23 -> 1 | E38: =E13+I13+M13+Q13+E23+I23 -> 2 | F38: =F13+J13+N13+R13+F23+J23 -> 0 | K38: =A38 -> 6:30 à 7:00 | M38: =SUM(C38:J38) -> 5 | N38: =C38+E38 -> 4 | O38: =E38+F38 -> 2 | P38: =E38 -> 2 | Q38: =SUM(G38:J38) -> 0
A39: 7:00 à 7:30 | C39: =C14+G14+K14+O14+C24+G24 -> 6 | D39: =D14+H14+L14+P14+D24+H24 -> 5 | E39: =E14+I14+M14+Q14+E24+I24 -> 2 | F39: =F14+J14+N14+R14+F24+J24 -> 0 | K39: =A39 -> 7:00 à 7:30 | M39: =SUM(C39:J39) -> 13 | N39: =C39+E39 -> 8 | O39: =E39+F39 -> 2 | P39: =E39 -> 2 | Q39: =SUM(G39:J39) -> 0
A40: 7:30 à 8:00 | C40: =C15+G15+K15+O15+C25+G25 -> 2 | D40: =D15+H15+L15+P15+D25+H25 -> 0 | E40: =E15+I15+M15+Q15+E25+I25 -> 1 | F40: =F15+J15+N15+R15+F25+J25 -> 0 | K40: =A40 -> 7:30 à 8:00 | M40: =SUM(C40:J40) -> 3 | N40: =C40+E40 -> 3 | O40: =E40+F40 -> 1 | P40: =E40 -> 1 | Q40: =SUM(G40:J40) -> 0
A41: 8:00 à 8:30 | C41: =C16+G16+K16+O16+C26+G26 -> 3 | D41: =D16+H16+L16+P16+D26+H26 -> 3 | E41: =E16+I16+M16+Q16+E26+I26 -> 3 | F41: =F16+J16+N16+R16+F26+J26 -> 2 | K41: =A41 -> 8:00 à 8:30 | M41: =SUM(C41:J41) -> 11 | N41: =C41+E41 -> 6 | O41: =E41+F41 -> 5 | P41: =E41 -> 3 | Q41: =SUM(G41:J41) -> 0
A42: 8:30 à 9:00 | C42: =C17+G17+K17+O17+C27+G27 -> 1 | D42: =D17+H17+L17+P17+D27+H27 -> 3 | E42: =E17+I17+M17+Q17+E27+I27 -> 2 | F42: =F17+J17+N17+R17+F27+J27 -> 3 | K42: =A42 -> 8:30 à 9:00 | M42: =SUM(C42:J42) -> 9 | N42: =C42+E42 -> 3 | O42: =E42+F42 -> 5 | P42: =E42 -> 2 | Q42: =SUM(G42:J42) -> 0
A43: TOTAL | C43: =SUM(C38:C42) -> 14 | D43: =SUM(D38:D42) -> 12 | E43: =SUM(E38:E42) -> 10 | F43: =SUM(F38:F42) -> 5 | K43: TOTAL | M43: =SUM(C43:J43) -> 41 | N43: =N42+N41+N40+N39+N38 -> 24 | O43: =O42+O41+O40+O39+O38 -> 15 | P43: =P42+P41+P40+P39+P38 -> 10 | Q43: =Q42+Q40+Q38 -> 0 | R43: =A29 -> 0 | S43: =A30 -> 0 | T43: =A31 -> 0 | U43: =A32 -> 0
J47: H POINTE | K47: =IF($M$42=MAX($M$38:$M$42),K42,IF($M$41=MAX($M$38:$M$42),K41,IF($M$40=MAX($M$38:$M$42),K40,IF($M$39=MAX($M$38:$M$42),K39,IF($M$38=MAX($M$38:$M$42),K38,K42))))) -> 7:00 à 7:30 | M47: =IF($M$42=MAX($M$38:$M$42),M42,IF($M$41=MAX($M$38:$M$42),M41,IF($M$40=MAX($M$38:$M$42),M40,IF($M$39=MAX($M$38:$M$42),M39,IF($M$38=MAX($M$38:$M$42),M38,M42))))) -> 13 | N47: =IF($M$42=MAX($M$38:$M$42),N42,IF($M$41=MAX($M$38:$M$42),N41,IF($M$40=MAX($M$38:$M$42),N40,IF($M$39=MAX($M$38:$M$42),N39,IF($M$38=MAX($M$38:$M$42),N38,N42))))) -> 8 | O47: =IF($M$42=MAX($M$38:$M$42),O42,IF($M$41=MAX($M$38:$M$42),O41,IF($M$40=MAX($M$38:$M$42),O40,IF($M$39=MAX($M$38:$M$42),O39,IF($M$38=MAX($M$38:$M$42),O38,O42))))) -> 2 | P47: =IF($M$42=MAX($M$38:$M$42),P42,IF($M$41=MAX($M$38:$M$42),P41,IF($M$40=MAX($M$38:$M$42),P40,IF($M$39=MAX($M$38:$M$42),P39,IF($M$38=MAX($M$38:$M$42),P38,P42))))) -> 2 | Q47: =IF($M$42=MAX($M$38:$M$42),Q42,IF($M$41=MAX($M$38:$M$42),Q41,IF($M$40=MAX($M$38:$M$42),Q40,IF($M$39=MAX($M$38:$M$42),Q39,IF($M$38=MAX($M$38:$M$42),Q38,Q42))))) -> 0
M48: TOTAL | N48: Part des VAE dans le total | O48: Part des femmes dans le total | P48: Part des VAE chez les femmes | Q48: =Q34 -> 0 | R48: Remarque
...

Sheet ARENT_PAPETERIE
B1: Arenthon La Papeterie | O1: Date : | Q1: Le mardi 10/06/2025
A2: Nom des personnes participant au comptage : | I2: Bea
A3: Météo : | N3: Remarques :
A5: PRINCIPE D’UTILISATION : pour chaque intervalle de temps, comptabiliser VAE/vélo dans la colonne H/F
A6: Rajouter aussi en bas de la feuille si enfant
A7: Comptabiliser en bas de la grille si 2 roues hors vélo qui ne sont pas cochés dans la grille (trottinette, skate, ets)
C9: De Arenthon vers | O9: De Bonneville vers
C10: Bonneville | G10: TNA | K10: Rte Papeterie | O10: TNA | S10: Arenthon | W10: Rte Papeterie
C11: H | E11: F | G11: H | I11: F | K11: H | M11: F | O11: H | Q11: F | S11: H | U11: F | W11: H | Y11: F
A12: Période | C12: VAE | D12: vélo | E12: VAE | F12: vélo | G12: VAE | H12: vélo | I12: VAE | J12: vélo | K12: VAE | L12: vélo | M12: VAE | N12: vélo | O12: VAE | P12: vélo | Q12: VAE | R12: vélo | S12: VAE | T12: vélo | U12: VAE | V12: vélo | W12: VAE | X12: vélo | Y12: VAE | Z12: vélo
A13: 0.27083333 | B13: 0.29166667 | D13: 1 | T13: 1
A14: 0.29166667 | B14: 0.3125
A15: 0.3125 | B15: 0.33333333 | J15: 1 | S15: 1
A16: 0.33333333 | B16: 0.35416667 | C16: 1 | F16: 1 | H16: 1
A17: 0.35416667 | B17: 0.375 | D17: 1 | F17: 1 | M17: 1 | U17: 1 | V17: 1
C19: De Rte Papeterie vers | O19: De TNA vers
C20: Arenthon | G20: TNA | K20: Bonneville | O20: Bonneville | S20: Arenthon | W20: Rte Papeterie
C21: H | E21: F | G21: H | I21: F | K21: H | M21: F | O21: H | Q21: F | S21: H | U21: F | W21: H | Y21: F
A22: Période | C22: VAE | D22: vélo | E22: VAE | F22: vélo | G22: VAE | H22: vélo | I22: VAE | J22: vélo | K22: VAE | L22: vélo | M22: VAE | N22: vélo | O22: VAE | P22: vélo | Q22: VAE | R22: vélo | S22: VAE | T22: vélo | U22: VAE | V22: vélo | W22: VAE | X22: vélo | Y22: VAE | Z22: vélo
A23: 0.27083333 | B23: 0.29166667
A24: 0.29166667 | B24: 0.3125 | J24: 1 | R24: 1 | Z24: 1
A25: 0.3125 | B25: 0.33333333
A26: 0.33333333 | B26: 0.35416667 | H26: 1
A27: 0.35416667 | B27: 0.375 | X27: 1
B29: dont Enfant
B30: dont Cyclo sportifs
B31: hors grille, plus 2 roues hors vélo (trottinette, skate...) | O31: 1 trottinette
C33: H | E33: F | AB33: en jaune, tableau global
A34: Période | C34: VAE | D34: vélo | E34: VAE | F34: vélo | AA34: Période | AC34: TOTAL | AD34: Nombre de VAE dans le total | AE34: Nombre de femmes dans le total | AF34: Nombre de VAE chez les femmes | AG34: plus trotinette skate | AH34: dont enfant | AI34: vélo sur trottoir | AJ34: dont cyclo
A35: 6:30 à 7:00 | C35: =C13+G13+K13+O13+S13+W13+C23+G23+K23+O23+S23+W23 -> 0 | D35: =D13+H13+L13+P13+T13+X13+D23+H23+L23+P23+T23+X23 -> 2 | E35: =E13+I13+M13+Q13+U13+Y13+E23+I23+M23+Q23+U23+Y23 -> 0 | F35: =F13+J13+N13+R13+V13+Z13+F23+J23+N23+R23+V23+Z23 -> 0 | AA35: =A35 -> 6:30 à 7:00 | AC35: =SUM(C35:Z35) -> 2 | AD35: =C35+E35 -> 0 | AE35: =E35+F35 -> 0 | AF35: =E35 -> 0
A36: 7:00 à 7:30 | C36: =C14+G14+K14+O14+S14+W14+C24+G24+K24+O24+S24+W24 -> 0 | D36: =D14+H14+L14+P14+T14+X14+D24+H24+L24+P24+T24+X24 -> 0 | E36: =E14+I14+M14+Q14+U14+Y14+E24+I24+M24+Q24+U24+Y24 -> 0 | F36: =F14+J14+N14+R14+V14+Z14+F24+J24+N24+R24+V24+Z24 -> 3 | AA36: =A36 -> 7:00 à 7:30 | AC36: =SUM(C36:Z36) -> 3 | AD36: =C36+E36 -> 0 | AE36: =E36+F36 -> 3 | AF36: =E36 -> 0
A37: 7:30 à 8:00 | C37: =C15+G15+K15+O15+S15+W15+C25+G25+K25+O25+S25+W25 -> 1 | D37: =D15+H15+L15+P15+T15+X15+D25+H25+L25+P25+T25+X25 -> 0 | E37: =E15+I15+M15+Q15+U15+Y15+E25+I25+M25+Q25+U25+Y25 -> 0 | F37: =F15+J15+N15+R15+V15+Z15+F25+J25+N25+R25+V25+Z25 -> 1 | AA37: =A37 -> 7:30 à 8:00 | AC37: =SUM(C37:Z37) -> 2 | AD37: =C37+E37 -> 1 | AE37: =E37+F37 -> 1 | AF37: =E37 -> 0
A38: 8:00 à 8:30 | C38: =C16+G16+K16+O16+S16+W16+C26+G26+K26+O26+S26+W26 -> 1 | D38: =D16+H16+L16+P16+T16+X16+D26+H26+L26+P26+T26+X26 -> 2 | E38: =E16+I16+M16+Q16+U16+Y16+E26+I26+M26+Q26+U26+Y26 -> 0 | F38: =F16+J16+N16+R16+V16+Z16+F26+J26+N26+R26+V26+Z26 -> 1 | AA38: =A38 -> 8:00 à 8:30 | AC38: =SUM(C38:Z38) -> 4 | AD38: =C38+E38 -> 1 | AE38: =E38+F38 -> 1 | AF38: =E38 -> 0
A39: 8:30 à 9:00 | C39: =C17+G17+K17+O17+S17+W17+C27+G27+K27+O27+S27+W27 -> 0 | D39: =D17+H17+L17+P17+T17+X17+D27+H27+L27+P27+T27+X27 -> 2 | E39: =E17+I17+M17+Q17+U17+Y17+E27+I27+M27+Q27+U27+Y27 -> 2 | F39: =F17+J17+N17+R17+V17+Z17+F27+J27+N27+R27+V27+Z27 -> 2 | AA39: 8:30 à 9:00 | AC39: =SUM(C39:Z39) -> 6 | AD39: =C39+E39 -> 2 | AE39: =E39+F39 -> 4 | AF39: =E39 -> 2
A40: TOTAL | C40: =SUM(C35:C39) -> 2 | D40: =SUM(D35:D39) -> 6 | E40: =SUM(E35:E39) -> 2 | F40: =SUM(F35:F39) -> 7 | G40: =SUM(C40:F40) -> 17 | AA40: TOTAL | AC40: =SUM(AC35:AC39) -> 17 | AD40: =SUM(AD35:AD39) -> 4 | AE40: =SUM(AE35:AE39) -> 9 | AF40: =SUM(AF35:AF39) -> 2 | AG40: 1 | AH40: 1 | AI40: =#REF! -> #REF! | AJ40: 3
AA41: 7:00 à 7:30 | AC41: 6
AA42: 7:30 à 8:00 | AC42: 8
AA43: Total H pointe | AC43: =SUM(AC41:AC42) -> 14
Z44: H POINTE | AA44: =IF($AC$36=MAX($AC$35:$AC$39),AA36,IF($AC$37=MAX($AC$35:$AC$39),AA37,IF($AC$38=MAX($AC$35:$AC$39),AA38,IF($AC$39=MAX($AC$35:$AC$39),AA39,IF($AC$35=MAX($AC$35:$AC$39),AA35,AA38))))) -> 8:30 à 9:00 | AC44: =IF($AC$36=MAX($AC$35:$AC$39),AC36,IF($AC$37=MAX($AC$35:$AC$39),AC37,IF($AC$38=MAX($AC$35:$AC$39),AC38,IF($AC$39=MAX($AC$35:$AC$39),AC39,IF($AC$40=MAX($AC$35:$AC$39),AC40,AC38))))) -> 6 | AD44: =IF($AC$36=MAX($AC$35:$AC$39),AD36,IF($AC$37=MAX($AC$35:$AC$39),AD37,IF($AC$38=MAX($AC$35:$AC$39),AD38,IF($AC$39=MAX($AC$35:$AC$39),AD39,IF($AC$40=MAX($AC$35:$AC$39),AD40,AD38))))) -> 2 | AE44: =IF($AC$36=MAX($AC$35:$AC$39),AE36,IF($AC$37=MAX($AC$35:$AC$39),AE37,IF($AC$38=MAX($AC$35:$AC$39),AE38,IF($AC$39=MAX($AC$35:$AC$39),AE39,IF($AC$40=MAX($AC$35:$AC$39),AE40,AE38))))) -> 4 | AF44: =IF($AC$36=MAX($AC$35:$AC$39),AF36,IF($AC$37=MAX($AC$35:$AC$39),AF37,IF($AC$38=MAX($AC$35:$AC$39),AF38,IF($AC$39=MAX($AC$35:$AC$39),AF39,IF($AC$40=MAX($AC$35:$AC$39),AF40,AF38))))) -> 2
AC45: TOTAL | AD45: Part des VAE dans le total | AE45: Part des femmes dans le total | AF45: Part des VAE chez les femmes
...

Sheet ST_PI_BORNE_DESSY
B1: St Pierre Franchissement du Borne Dessy | O1: Date :
A2: Nom des personnes participant au comptage : | I2: pas fait 2025, faute de benevole
A3: Météo : | P3: Remarques :
A5: PRINCIPE D’UTILISATION : pour chaque intervalle de temps, comptabiliser VAE/vélo dans la colonne H/F
A6: Rajouter aussi en bas de la feuille si enfant
A7: Comptabiliser en bas de la grille si 2 roues hors vélo qui ne sont pas cochés dans la grille (trottinette, skate, ets)
C9: De Rte Gorges du Borne vers | K9: De Avenue des Digues vers | S9: De Avenue de Monaz vers
C10: Av des Digues | G10: Av Monaz | K10: Av Monaz | O10: Rte Gorges du Borne | S10: Rte Gorges du Borne | W10: Av des Digues
C11: H | E11: F | G11: H | I11: F | K11: H | M11: F | O11: H | Q11: F | S11: H | U11: F | W11: H | Y11: F
A12: Période | C12: VAE | D12: vélo | E12: VAE | F12: vélo | G12: VAE | H12: vélo | I12: VAE | J12: vélo | K12: VAE | L12: vélo | M12: VAE | N12: vélo | O12: VAE | P12: vélo | Q12: VAE | R12: vélo | S12: VAE | T12: vélo | U12: VAE | V12: vélo | W12: VAE | X12: vélo | Y12: VAE | Z12: vélo
A13: 0.27083333 | B13: 0.29166667
A14: 0.29166667 | B14: 0.3125
A15: 0.3125 | B15: 0.33333333
A16: 0.33333333 | B16: 0.35416667
A17: 0.35416667 | B17: 0.375
B19: dont Enfant
B20: vélo sur trottoir
B21: dont Cyclo sportifs
B22: hors grille, plus 2 roues hors vélo (trottinette, skate...)
AC24: en jaune, tableau global
C25: =C9 -> De Rte Gorges du Borne vers | K25: =K9 -> De Avenue des Digues vers | S25: =S9 -> De Avenue de Monaz vers | AC25: TOTAL | AD25: Nombre de VAE dans le total | AE25: Nombre de femmes dans le total | AF25: Nombre de VAE chez les femmes | AK25: Cycles sur rte de Dessy | AL25: Cycles sur rte des Digues
C26: =C10 -> Av des Digues | G26: =G10 -> Av Monaz | K26: =K10 -> Av Monaz | O26: =O10 -> Rte Gorges du Borne | S26: =S10 -> Rte Gorges du Borne | W26: =W10 -> Av des Digues
C27: H | E27: F | G27: H | I27: F | K27: H | M27: F | O27: H | Q27: F | S27: H | U27: F | W27: H | Y27: F
A28: Période | C28: VAE | D28: vélo | E28: VAE | F28: vélo | G28: VAE | H28: vélo | I28: VAE | J28: vélo | K28: VAE | L28: vélo | M28: VAE | N28: vélo | O28: VAE | P28: vélo | Q28: VAE | R28: vélo | S28: VAE | T28: vélo | U28: VAE | V28: vélo | W28: VAE | X28: vélo | Y28: VAE | Z28: vélo | AA28: Période | AG28: plus trotinette skate | AH28: dont enfant | AI28: vélo sur trottoir | AJ28: dont cyclo
A29: 6:30 à 7:00 | C29: =C13 -> 0 | D29: =D13 -> 0 | E29: =E13 -> 0 | F29: =F13 -> 0 | G29: =G13 -> 0 | H29: =H13 -> 0 | I29: =I13 -> 0 | J29: =J13 -> 0 | ... Z29: =Z13 -> 0 | AA29: =A29 -> 6:30 à 7:00 | AC29: =SUM(C29:Z29) -> 0 | AD29: =C29+E29+G29+I29+K29+M29+O29+Q29+S29+U29+W29+Y29 -> 0 | AE29: =E29+F29+I29+J29+M29+N29+Q29+R29+U29+V29+Y29+Z29 -> 0 | AF29: =E29+I29+M29+Q29+U29+Y29 -> 0 | AK29: =SUM(G29:N29)+SUM(S29:Z29) -> 0 | AL29: =SUM(C29:F29)+SUM(W29:Z29)+SUM(K29:R29) -> 0
A30: 7:00 à 7:30 | C30: =C14 -> 0 | D30: =D14 -> 0 | E30: =E14 -> 0 | F30: =F14 -> 0 | G30: =G14 -> 0 | H30: =H14 -> 0 | I30: =I14 -> 0 | J30: =J14 -> 0 | ... Z30: =Z14 -> 0 | AA30: =A30 -> 7:00 à 7:30 | AC30: =SUM(C30:Z30) -> 0 | AD30: =C30+E30+G30+I30+K30+M30+O30+Q30+S30+U30+W30+Y30 -> 0 | AE30: =E30+F30+I30+J30+M30+N30+Q30+R30+U30+V30+Y30+Z30 -> 0 | AF30: =E30+I30+M30+Q30+U30+Y30 -> 0 | AK30: =SUM(G30:N30)+SUM(S30:Z30) -> 0 | AL30: =SUM(C30:F30)+SUM(W30:Z30)+SUM(K30:R30) -> 0
A31: 7:30 à 8:00 | C31: =C15 -> 0 | D31: =D15 -> 0 | E31: =E15 -> 0 | F31: =F15 -> 0 | G31: =G15 -> 0 | H31: =H15 -> 0 | I31: =I15 -> 0 | J31: =J15 -> 0 | ... Z31: =Z15 -> 0 | AA31: =A31 -> 7:30 à 8:00 | AC31: =SUM(C31:Z31) -> 0 | AD31: =C31+E31+G31+I31+K31+M31+O31+Q31+S31+U31+W31+Y31 -> 0 | AE31: =E31+F31+I31+J31+M31+N31+Q31+R31+U31+V31+Y31+Z31 -> 0 | AF31: =E31+I31+M31+Q31+U31+Y31 -> 0 | AK31: =SUM(G31:N31)+SUM(S31:Z31) -> 0 | AL31: =SUM(C31:F31)+SUM(W31:Z31)+SUM(K31:R31) -> 0
A32: 8:00 à 8:30 | C32: =C16 -> 0 | D32: =D16 -> 0 | E32: =E16 -> 0 | F32: =F16 -> 0 | G32: =G16 -> 0 | H32: =H16 -> 0 | I32: =I16 -> 0 | J32: =J16 -> 0 | ... Z32: =Z16 -> 0 | AA32: =A32 -> 8:00 à 8:30 | AC32: =SUM(C32:Z32) -> 0 | AD32: =C32+E32+G32+I32+K32+M32+O32+Q32+S32+U32+W32+Y32 -> 0 | AE32: =E32+F32+I32+J32+M32+N32+Q32+R32+U32+V32+Y32+Z32 -> 0 | AF32: =E32+I32+M32+Q32+U32+Y32 -> 0 | AK32: =SUM(G32:N32)+SUM(S32:Z32) -> 0 | AL32: =SUM(C32:F32)+SUM(W32:Z32)+SUM(K32:R32) -> 0
A33: 8:30 à 9:00 | C33: =C17 -> 0 | D33: =D17 -> 0 | E33: =E17 -> 0 | F33: =F17 -> 0 | G33: =G17 -> 0 | H33: =H17 -> 0 | I33: =I17 -> 0 | J33: =J17 -> 0 | ... Z33: =Z17 -> 0 | AA33: =A33 -> 8:30 à 9:00 | AC33: =SUM(C33:Z33) -> 0 | AD33: =C33+E33+G33+I33+K33+M33+O33+Q33+S33+U33+W33+Y33 -> 0 | AE33: =E33+F33+I33+J33+M33+N33+Q33+R33+U33+V33+Y33+Z33 -> 0 | AF33: =E33+I33+M33+Q33+U33+Y33 -> 0 | AK33: =SUM(G33:N33)+SUM(S33:Z33) -> 0 | AL33: =SUM(C33:F33)+SUM(W33:Z33)+SUM(K33:R33) -> 0
A34: TOTAL | C34: =SUM(C13:C17) -> 0 | D34: =SUM(D13:D17) -> 0 | E34: =SUM(E13:E17) -> 0 | F34: =SUM(F13:F17) -> 0 | G34: =SUM(G13:G17) -> 0 | H34: =SUM(H13:H17) -> 0 | I34: =SUM(I13:I17) -> 0 | J34: =SUM(J13:J17) -> 0 | ... Z34: =SUM(Z13:Z17) -> 0 | AA34: TOTAL | AC34: =SUM(C34:Z34) -> 0 | AD34: =AD29+AD30+AD31+AD32+AD33 -> 0 | AE34: =AE29+AE31+AE33 -> 0 | AF34: =AF29+AF31+AF33 -> 0 | AG34: =A22 -> 0 | AH34: =A19 -> 0 | AJ34: =A21 -> 0 | AK34: =AK29+AK31+AK33 -> 0 | AL34: =AL29+AL31+AL33 -> 0
AA35: 7:00 à 7:30 | AC35: 8
AA36: 7:30 à 8:00 | AC36: 17
AA37: Total H pointe | AC37: =SUM(AC35:AC36) -> 25
Z38: H POINTE | AA38: 7:00 à 7:30 | AC38: =IF($AC$33=MAX($AC$29:$AC$33),AC33,IF($AC$32=MAX($AC$29:$AC$33),AC32,IF($AC$31=MAX($AC$29:$AC$33),AC31,IF($AC$30=MAX($AC$29:$AC$33),AC30,IF($AC$29=MAX($AC$29:$AC$33),AC29))))) -> 0 | AD38: =IF($AC$33=MAX($AC$29:$AC$33),AD33,IF($AC$32=MAX($AC$29:$AC$33),AD32,IF($AC$31=MAX($AC$29:$AC$33),AD31,IF($AC$30=MAX($AC$29:$AC$33),AD30,IF($AC$29=MAX($AC$29:$AC$33),AD29))))) -> 0 | AE38: =IF($AC$33=MAX($AC$29:$AC$33),AE33,IF($AC$32=MAX($AC$29:$AC$33),AE32,IF($AC$31=MAX($AC$29:$AC$33),AE31,IF($AC$30=MAX($AC$29:$AC$33),AE30,IF($AC$29=MAX($AC$29:$AC$33),AE29))))) -> 0 | AF38: =IF($AC$33=MAX($AC$29:$AC$33),AF33,IF($AC$32=MAX($AC$29:$AC$33),AF32,IF($AC$31=MAX($AC$29:$AC$33),AF31,IF($AC$30=MAX($AC$29:$AC$33),AF30,IF($AC$29=MAX($AC$29:$AC$33),AF29))))) -> 0 | AK38: =IF($AC$33=MAX($AC$29:$AC$33),AK33,IF($AC$32=MAX($AC$29:$AC$33),AK32,IF($AC$31=MAX($AC$29:$AC$33),AK31,IF($AC$30=MAX($AC$29:$AC$33),AK30,IF($AC$29=MAX($AC$29:$AC$33),AK29))))) -> 0 | AL38: =IF($AC$33=MAX($AC$29:$AC$33),AL33,IF($AC$32=MAX($AC$29:$AC$33),AL32,IF($AC$31=MAX($AC$29:$AC$33),AL31,IF($AC$30=MAX($AC$29:$AC$33),AL30,IF($AC$29=MAX($AC$29:$AC$33),AL29))))) -> 0
AC39: TOTAL | AD39: Part des VAE dans le total | AE39: Part des femmes dans le total | AF39: Part des VAE chez les femmes | AK39: =AK25 -> Cycles sur rte de Dessy | AL39: =AL25 -> Cycles sur rte des Digues
AA42: Période
AA43: =AA29 -> 6:30 à 7:00 | AD43: =IF(AD29=0,0,AD29/AC29) -> 0 | AE43: =IF(AE29=0,0,AE29/AC29) -> 0 | AF43: =IF(AF29=0,0,AF29/AD29) -> 0 | AK43: =IF(AK29=0,0,AK29/AC29) -> 0 | AL43: =IF(AL29=0,0,AL29/AC29) -> 0
AA44: =AA30 -> 7:00 à 7:30 | AD44: =IF(AD31=0,0,AD31/AC31) -> 0 | AE44: =IF(AE31=0,0,AE31/AC31) -> 0 | AF44: =IF(AF31=0,0,AF31/AD31) -> 0 | AK44: =IF(AK31=0,0,AK31/AC31) -> 0 | AL44: =IF(AL31=0,0,AL31/AC31) -> 0
AA45: =AA31 -> 7:30 à 8:00 | AD45: =IF(AD31=0,0,AD31/AC31) -> 0 | AE45: =IF(AE31=0,0,AE31/AC31) -> 0 | AF45: =IF(AF31=0,0,AF31/AD31) -> 0 | AK45: =IF(AK31=0,0,AK31/AC31) -> 0 | AL45: =IF(AL31=0,0,AL31/AC31) -> 0
AA46: =AA32 -> 8:00 à 8:30 | AD46: =IF(AD32=0,0,AD32/AC32) -> 0 | AE46: =IF(AE32=0,0,AE32/AC32) -> 0 | AF46: =IF(AF32=0,0,AF32/AD32) -> 0 | AK46: =IF(AK32=0,0,AK32/AC32) -> 0 | AL46: =IF(AL32=0,0,AL32/AC32) -> 0
...

Sheet BO_BORNE_PRISON
B1: Bonneville Franchissement du Borne Tucinge - Prison | G1: Date : | H1: le jeudi 12 juin 2025
A2: Nom des personnes participant au comptage : | E2: Jocelyne
A3: Météo : | G3: Remarques : | H3: fait aussi avec l’appli où il y a une erreur avec 2 VAE Femme en trop
A5: PRINCIPE D’UTILISATION : pour chaque intervalle de temps, comptabiliser VAE/vélo dans la colonne H/F
A6: Rajouter aussi en bas de la feuille si déplacement vélo sur trottoir et/ou si enfant
A7: Comptabiliser en bas de la grille si 2 roues hors vélo qui ne sont pas cochés dans la grille (trottinette, skate, ets)
C8: Pont du Borne
C9: H | D9: H | E9: F | F9: F
A10: Période | C10: VAE | D10: vélo | E10: VAE | F10: vélo
A11: 0.27083333 | B11: 0.29166667 | C11: 1 | E11: 1 | G11: =SUM(C11:F11) -> 2
A12: 0.29166667 | B12: 0.3125 | D12: 1 | E12: 1 | F12: 1 | G12: =SUM(C12:F12) -> 3
A13: 0.3125 | B13: 0.33333333 | C13: 1 | D13: 2 | G13: =SUM(C13:F13) -> 3
A14: 0.33333333 | B14: 0.35416667 | D14: 6 | E14: 5 | F14: 5 | G14: =SUM(C14:F14) -> 16
A15: 0.35416667 | B15: 0.375 | D15: 3 | E15: 1 | G15: =SUM(C15:F15) -> 4
B17: dont Enfant | D17: 3 | E17: 2 filles 1 garçon, rajoutés sur l’appli | G17: =SUM(G11:G16) -> 28
M18: en jaune, tableau global
C19: =C8 -> Pont du Borne | K19: Période | M19: TOTAL | N19: Nombre de VAE dans le total | O19: Nombre de femmes dans le total | P19: Nombre de VAE chez les femmes | Q19: plus trotinette skate | R19: dont enfant | S19: vélo sur trottoir | T19: dont cyclo | U19: Cycles en direction de Bonneville
C21: H | E21: F
A22: Période | C22: VAE | D22: vélo | E22: VAE | F22: vélo
A23: 6:30 à 7:00 | C23: =+C11 -> 1 | D23: =+D11 -> 0 | E23: =+E11 -> 1 | F23: =+F11 -> 0 | K23: =A23 -> 6:30 à 7:00 | M23: =SUM(C23:J23) -> 2 | N23: =C23+E23+G23+I23 -> 2 | O23: =E23+F23+I23+J23 -> 1 | P23: =E23+I23 -> 1 | U23: =SUM(G23:J23) -> 0
A24: 7:00 à 7:30 | C24: =+C12 -> 0 | D24: =+D12 -> 1 | E24: =+E12 -> 1 | F24: =+F12 -> 1 | K24: =A24 -> 7:00 à 7:30 | M24: =SUM(C24:J24) -> 3 | N24: =C24+E24+G24+I24 -> 1 | O24: =E24+F24+I24+J24 -> 2 | P24: =E24+I24 -> 1 | U24: =SUM(G24:J24) -> 0
A25: 7:30 à 8:00 | C25: =+C13 -> 1 | D25: =+D13 -> 2 | E25: =+E13 -> 0 | F25: =+F13 -> 0 | K25: =A25 -> 7:30 à 8:00 | M25: =SUM(C25:J25) -> 3 | N25: =C25+E25+G25+I25 -> 1 | O25: =E25+F25+I25+J25 -> 0 | P25: =E25+I25 -> 0 | U25: =SUM(G25:J25) -> 0
A26: 8:00 à 8:30 | C26: =+C14 -> 0 | D26: =+D14 -> 6 | E26: =+E14 -> 5 | F26: =+F14 -> 5 | K26: =A26 -> 8:00 à 8:30 | M26: =SUM(C26:J26) -> 16 | N26: =C26+E26+G26+I26 -> 5 | O26: =E26+F26+I26+J26 -> 10 | P26: =E26+I26 -> 5 | U26: =SUM(G26:J26) -> 0
A27: 8:30 à 9:00 | C27: =+C15 -> 0 | D27: =+D15 -> 3 | E27: =+E15 -> 1 | F27: =+F15 -> 0 | K27: =A27 -> 8:30 à 9:00 | M27: =SUM(C27:J27) -> 4 | N27: =C27+E27+G27+I27 -> 1 | O27: =E27+F27+I27+J27 -> 1 | P27: =E27+I27 -> 1 | U27: =SUM(G27:J27) -> 0
A28: TOTAL | C28: =SUM(C11:C15) -> 2 | D28: =SUM(D11:D15) -> 12 | E28: =SUM(E11:E15) -> 8 | F28: =SUM(F11:F15) -> 6 | G28: =SUM(C28:F28) -> 28 | K28: TOTAL | M28: =SUM(M23:M27) -> 28 | N28: =SUM(N23:N27) -> 10 | O28: =SUM(O23:O27) -> 14 | P28: =SUM(P23:P27) -> 8 | Q28: =#REF! -> #REF! | R28: =A17 -> 0 | T28: =#REF! -> #REF! | U28: =SUM(U23:U27) -> 0
K29: 8:00 à 8:30
K30: 8:30 à 9:00
K31: Total H pointe | M31: =SUM(M29:M30) -> 0
J32: H POINTE | K32: =IF($M$27=MAX($M$23:$M$27),K27,IF($M$26=MAX($M$23:$M$27),K26,IF($M$25=MAX($M$23:$M$27),K25,IF($M$24=MAX($M$23:$M$27),K24,IF($M$23=MAX($M$23:$M$27),K23,K27))))) -> 8:00 à 8:30 | M32: =IF($M$27=MAX($M$23:$M$27),M27,IF($M$26=MAX($M$23:$M$27),M26,IF($M$25=MAX($M$23:$M$27),M25,IF($M$24=MAX($M$23:$M$27),M24,IF($M$23=MAX($M$23:$M$27),M23,M27))))) -> 16 | N32: =IF($M$27=MAX($M$23:$M$27),N27,IF($M$26=MAX($M$23:$M$27),N26,IF($M$25=MAX($M$23:$M$27),N25,IF($M$24=MAX($M$23:$M$27),N24,IF($M$23=MAX($M$23:$M$27),N23,N27))))) -> 5 | O32: =IF($M$27=MAX($M$23:$M$27),O27,IF($M$26=MAX($M$23:$M$27),O26,IF($M$25=MAX($M$23:$M$27),O25,IF($M$24=MAX($M$23:$M$27),O24,IF($M$23=MAX($M$23:$M$27),O23,O27))))) -> 10 | P32: =IF($M$27=MAX($M$23:$M$27),P27,IF($M$26=MAX($M$23:$M$27),P26,IF($M$25=MAX($M$23:$M$27),P25,IF($M$24=MAX($M$23:$M$27),P24,IF($M$23=MAX($M$23:$M$27),P23,P27))))) -> 5 | U32: =IF($M$27=MAX($M$23:$M$27),U27,IF($M$26=MAX($M$23:$M$27),U26,IF($M$25=MAX($M$23:$M$27),U25,IF($M$24=MAX($M$23:$M$27),U24,IF($M$23=MAX($M$23:$M$27),U23,U27))))) -> 0
M33: TOTAL | N33: Part des VAE dans le total | O33: Part des femmes dans le total | P33: Part des VAE chez les femmes | U33: =U19 -> Cycles en direction de Bonneville
K36: Période
K37: =K23 -> 6:30 à 7:00 | N37: =IF(N23=0,0,N23/M23) -> 1 | O37: =IF(O23=0,0,O23/M23) -> 0.5 | P37: =IF(P23=0,0,P23/N23) -> 0.5 | U37: =IF(U23=0,0,U23/M23) -> 0
K38: =K24 -> 7:00 à 7:30 | N38: =IF(N25=0,0,N25/M25) -> 0.33333333 | O38: =IF(O25=0,0,O25/M25) -> 0 | P38: =IF(P25=0,0,P25/N25) -> 0 | U38: =IF(U25=0,0,U25/M25) -> 0
K39: =K25 -> 7:30 à 8:00 | N39: =IF(N25=0,0,N25/M25) -> 0.33333333 | O39: =IF(O25=0,0,O25/M25) -> 0 | P39: =IF(P25=0,0,P25/N25) -> 0 | U39: =IF(U25=0,0,U25/M25) -> 0
K40: =K26 -> 8:00 à 8:30 | N40: =IF(N26=0,0,N26/M26) -> 0.3125 | O40: =IF(O26=0,0,O26/M26) -> 0.625 | P40: =IF(P26=0,0,P26/N26) -> 1 | U40: =IF(U26=0,0,U26/M26) -> 0
K41: =K27 -> 8:30 à 9:00 | N41: =IF(N27=0,0,N27/M27) -> 0.25 | O41: =IF(O27=0,0,O27/M27) -> 0.25 | P41: =IF(P27=0,0,P27/N27) -> 1 | U41: =IF(U27=0,0,U27/M27) -> 0
K42: TOTAL | N42: =IF(N28=0,0,N28/M28) -> 0.35714286 | O42: =IF(O28=0,0,O28/M28) -> 0.5 | P42: =IF(P28=0,0,P28/N28) -> 0.8 | U42: =IF(U28=0,0,U28/M28) -> 0
K43: =K32 -> 8:00 à 8:30 | M43: =IF($AS$44=MAX($AS$44:$AS$48),M37,IF($AS$45=MAX($AS$44:$AS$48),M39,IF($AS$46=MAX($AS$44:$AS$48),M40,IF($AS$47=MAX($AS$44:$AS$48),(M40),M41)))) -> 0 | N43: =IF($AS$44=MAX($AS$44:$AS$48),N37,IF($AS$45=MAX($AS$44:$AS$48),N39,IF($AS$46=MAX($AS$44:$AS$48),N40,IF($AS$47=MAX($AS$44:$AS$48),(N40),N41)))) -> 1 | O43: =O41 -> 0.25 | P43: =IF($AS$44=MAX($AS$44:$AS$48),P37,IF($AS$45=MAX($AS$44:$AS$48),P39,IF($AS$46=MAX($AS$44:$AS$48),P40,IF($AS$47=MAX($AS$44:$AS$48),(P40),P41)))) -> 0.5 | U43: =IF($AS$44=MAX($AS$44:$AS$48),U37,IF($AS$45=MAX($AS$44:$AS$48),U39,IF($AS$46=MAX($AS$44:$AS$48),U40,IF($AS$47=MAX($AS$44:$AS$48),(U40),U41)))) -> 0

Sheet ST_PI_BON BORNE_RD1203
B1: St Pierre Pont sur le Borne Principal - RD 1203 | O1: Date : | Q1: Le mardi 10/06/2025
A2: Nom des personnes participant au comptage : | I2: Suard Christine et René | N2: côté Bonneville
A3: Météo : | N3: Remarques :
A5: Principe d'utilisation pour chaque intervalle de temps, comptabiliser vélo ou VAE dans la colonne H ou F
A6: Et cocher bas de la grille si déplacement sur trottoir et/ou si enfant et/ou si 2 roues hors vélo (trott, skate…)
C8: De Stade vers
C9: Bonneville | G9: Prison | K9: Tucinges | O9: La Roche | S9: Digues
C10: H | E10: F | G10: H | I10: F | K10: H | M10: F | O10: H | Q10: F | S10: H | U10: F
A11: Période | C11: VAE | D11: vélo | E11: VAE | F11: vélo | G11: VAE | H11: vélo | I11: VAE | J11: vélo | K11: VAE | L11: vélo | M11: VAE | N11: vélo | O11: VAE | P11: vélo | Q11: VAE | R11: vélo | S11: VAE | T11: vélo | U11: VAE | V11: vélo
A12: 0.27083333 | B12: 0.29166667 | W12: =SUM(C12:V12) -> 0
A13: 0.29166667 | B13: 0.3125 | H13: 1 | O13: 1 | S13: 1 | W13: =SUM(C13:V13) -> 3
A14: 0.3125 | B14: 0.33333333 | E14: 1 | H14: 1 | O14: 1 | T14: 1 | W14: =SUM(C14:V14) -> 4
A15: 0.33333333 | B15: 0.35416667 | V15: 1 | W15: =SUM(C15:V15) -> 1
A16: 0.35416667 | B16: 0.375 | W16: =SUM(C16:V16) -> 0
W17: =SUM(W12:W16) -> 8
C18: De Bonneville vers
C19: Prison | G19: Tucinges | K19: La Roche | O19: Digues | S19: Stade
C20: H | E20: F | G20: H | I20: F | K20: H | M20: F | O20: H | Q20: F | S20: H | U20: F
A21: Période | C21: VAE | D21: vélo | E21: VAE | F21: vélo | G21: VAE | H21: vélo | I21: VAE | J21: vélo | K21: VAE | L21: vélo | M21: VAE | N21: vélo | O21: VAE | P21: vélo | Q21: VAE | R21: vélo | S21: VAE | T21: vélo | U21: VAE | V21: vélo
A22: 0.27083333 | B22: 0.29166667 | H22: 1 | L22: 1 | P22: 1 | W22: =SUM(C22:V22) -> 3
A23: 0.29166667 | B23: 0.3125 | L23: 1 | O23: 1 | W23: =SUM(C23:V23) -> 2
A24: 0.3125 | B24: 0.33333333 | K24: 1 | O24: 1 | W24: =SUM(C24:V24) -> 2
A25: 0.33333333 | B25: 0.35416667 | W25: =SUM(C25:V25) -> 0
A26: 0.35416667 | B26: 0.375 | V26: 1 | W26: =SUM(C26:V26) -> 1
W27: =SUM(W22:W26) -> 8
C28: De Prison vers
C29: Tucinges | G29: La Roche | K29: Digues | O29: Stade | S29: Bonneville
C30: H | E30: F | G30: H | I30: F | K30: H | M30: F | O30: H | Q30: F | S30: H | U30: F
A31: Période | C31: VAE | D31: vélo | E31: VAE | F31: vélo | G31: VAE | H31: vélo | I31: VAE | J31: vélo | K31: VAE | L31: vélo | M31: VAE | N31: vélo | O31: VAE | P31: vélo | Q31: VAE | R31: vélo | S31: VAE | T31: vélo | U31: VAE | V31: vélo
A32: 0.27083333 | B32: 0.29166667 | W32: =SUM(C32:V32) -> 0
A33: 0.29166667 | B33: 0.3125 | K33: 2 | W33: =SUM(C33:V33) -> 2
A34: 0.3125 | B34: 0.33333333 | H34: 1 | W34: =SUM(C34:V34) -> 1
A35: 0.33333333 | B35: 0.35416667 | T35: 1 | W35: =SUM(C35:V35) -> 1
A36: 0.35416667 | B36: 0.375 | W36: =SUM(C36:V36) -> 0
B37: dont Enfant | F37: 1 | W37: =SUM(W32:W36) -> 4
B38: vélo sur trottoir | F38: 8
B39: dont Cyclo sportifs
B40: hors grille, plus 2 roues hors vélo (trottinette, skate...) | N40: 5
B42: St Pierre Pont sur le Borne Principal - RD 1203
A43: Nom des personnes participant au comptage : | L43: côté La Roche
...

Sheet ST_PI_M_BRICOLAGE
B1: ST PIERRE Mr BRICOLAGE | G1: Date : | H1: Le mardi 10/06/2025
A2: Nom des personnes participant au comptage : | G2: simon
A3: Météo : | G3: Remarques :
A6: PRINCIPE D’UTILISATION : pour chaque intervalle de temps, comptabiliser VAE/vélo dans la colonne H/F
A7: Comptabiliser en bas de la grille si 2 roues hors vélo qui ne sont pas cochés dans la grille (trottinette, skate, ets)
C9: PISTE CYCLABLE en continu | K9: JAMAIS sur PISTE CYCLABLE
C10: Vers La Roche | G10: Vers Bonnevile | K10: Direction La Roche | O10: Direction Bonneville
C11: H | E11: F | G11: H | I11: F | K11: H | M11: F | O11: H | Q11: F
A12: Période | C12: VAE | D12: vélo | E12: VAE | F12: vélo | G12: VAE | H12: vélo | I12: VAE | J12: vélo | K12: VAE | L12: vélo | M12: VAE | N12: vélo | O12: VAE | P12: vélo | Q12: VAE | R12: vélo
A13: 0.27083333 | B13: 0.29166667 | C13: 1 | D13: 2 | G13: 2 | H13: 1 | L13: 1 | M13: 1 | S13: =SUM(C13:R13) -> 8
A14: 0.29166667 | B14: 0.3125 | G14: 1 | I14: 1 | L14: 1 | S14: =SUM(C14:R14) -> 3
