Workbook

Sheet Index
C3: Eléments à renseigner par chaque association dans l'onglet "2022"
D5: Colonne | F5: Ce qu'il faut renseigner
D7: Toutes les cellules blanches ne sont pas à renseigner (formule de calcul ou NC)
D9: Eléments obligatoires >> cellules en vert dans l'onglet "2022"
D10: DONNEES GENERALES | E10: D | F10: nombre de bénévoles par poste de comptage
E11: E | F11: nom/localisation du poste de comptage
E12: F | F12: implantation : France / Suisse / Frontière
E13: G | F13: nombre total de cyclistes comptés sur toute la période
E14: H | F14: nombre de cyclistes comptés sur l'heure de pointe (7h30 - 8h30) uniquement
E15: I | F15: calcul automatique (du nombre de VAE dans le total)
E16: J | F16: nombre de VAE dans le total (référence à la colonne G)
E17: K | F17: calcul automatique (du nombre de femmes dans le total)
E18: L | F18: nombre de femmes dans le total (référence à la colonne G)
D20: Eléments obligatoires pour les postes frontières et carrefours proches frontière
D21: >> cellules en bleu dans l'onglet "2022"
D22: FRONTIERE | E22: S | F22: nombre total de cyclistes comptés sur toute la période - Direction Suisse
E23: T | F23: nombre de cyclistes comptés sur l'heure de pointe (7h30 - 8h30) uniquement - Direction Suisse
E24: U | F24: nombre total de cyclistes comptés sur toute la période - Direction France
E25: V | F25: nombre de cyclistes comptés sur l'heure de pointe (7h30 - 8h30) uniquement - Direction France
D27: Eléments facultatifs >> cellules en rose dans l'onglet "2022"
D28: AUTRES DONNEES | E28: M | F28: calcul automatique (du nombre total de VAE chez les femmes)
E29: N | F29: nombre total de VAE chez les femmes (valeur spécifique à relever)
E30: O | F30: nombre total de personnes comptées sur toute la période en "autre mode" (trottinette, gyropode…)
E31: P | F31: nombre total de personnes comptées en HPM (7h30 - 8h30) en "autre mode" (trottinette, gyropode…)
E32: Q | F32: nombre total de piétons comptés sur toute la période
E33: R | F33: nombre total de piétons comptés en HPM (7h30 - 8h30)

Sheet 2020
A2: X | B2: Association(s) | C2: Arrière-pays | D2: Nombre de bénévoles | E2: Postes de comptage | F2: France / Suisse / Frontière | G2: Nombre de vélos | I2: % VAE dans le total | J2: NB VAE dans le total | K2: % femmes dans le total | L2: NB de femmes dans le total | M2: % de VAE chez les femmes | N2: NB de VAE chez les femmes | O2: Autres modes | Q2: Piétons | S2: > Suisse | U2: > France
A3: X
A4: X | G4: total | H4: HP | O4: total | P4: HP | Q4: total | R4: HP | S4: total | T4: HP | U4: total | V4: HP | AB4: 2020
A5: =IF(D5="Sous-total","X",IF(E5="","","X")) -> X | B5: UP Cluses | C5: OUI | D5: 2 | E5: CLUSES_Passerelle de Messy | F5: France | G5: =27+11+2+15+8 -> 63 | H5: 29 | I5: =2/G5 -> 0.031746032 | J5: =I5*G5 -> 2 | K5: =(2+15)/G5 -> 0.26984127 | L5: =K5*G5 -> 17 | M5: =2/17 -> 0.11764706 | N5: =IF(M5="-","-",M5*L5) -> 2 | AB5: =IF(G5>0,$F5,"") -> France
A6: =IF(D6="Sous-total","X",IF(E6="","","X")) -> X | B6: L'Abeille (Contamine) | C6: OUI | E6: BONNE_Loëx (sous voie rapide) | F6: France | I6: =2/G6 -> #DIV/0! | K6: =(2+15)/G6 -> #DIV/0! | M6: =2/17 -> 0.11764706 | AB6: =IF(G6>0,$F6,"")
A7: =IF(D7="Sous-total","X",IF(E7="","","X")) -> X | B7: AMDC (Chablais) | C7: OUI | E7: ALLINGES_Rond point des Fleysets | F7: France | I7: 0.32258065 | K7: 0.32258065 | M7: - | N7: - | O7: - | P7: - | Q7: - | R7: - | AB7: =IF(G7>0,$F7,"")
A8: =IF(D8="Sous-total","X",IF(E8="","","X")) -> X | E8: BONS_Gare | F8: France | I8: 0.48 | K8: 0.36 | M8: - | N8: - | O8: - | P8: - | Q8: - | R8: - | AB8: =IF(G8>0,$F8,"")
A9: =IF(D9="Sous-total","X",IF(E9="","","X")) -> X | E9: DOUVAINE_Mairie | F9: France | I9: 0.48 | K9: 0.36 | M9: - | N9: - | O9: - | P9: - | Q9: - | R9: - | AB9: =IF(G9>0,$F9,"")
A10: =IF(D10="Sous-total","X",IF(E10="","","X")) -> X | E10: EVIAN_Gare | F10: France | I10: 0.48 | K10: 0.36 | M10: - | N10: - | O10: - | P10: - | Q10: - | R10: - | AB10: =IF(G10>0,$F10,"")
A11: =IF(D11="Sous-total","X",IF(E11="","","X")) -> X | E11: PERRIGNIER_Gare | F11: France | I11: 0.48 | K11: 0.36 | M11: - | N11: - | O11: - | P11: - | Q11: - | R11: - | AB11: =IF(G11>0,$F11,"")
A12: =IF(D12="Sous-total","X",IF(E12="","","X")) -> X | E12: THONON_Embarcadère CGN | F12: Frontière | I12: 0.48 | K12: 0.36 | M12: - | N12: - | O12: - | P12: - | Q12: - | R12: - | AB12: =IF(G12>0,$F12,"")
A13: =IF(D13="Sous-total","X",IF(E13="","","X")) -> X | E13: THONON_Entrée côté place de Crête | F13: France | I13: 0.48 | K13: 0.36 | M13: - | N13: - | O13: - | P13: - | Q13: - | R13: - | AB13: =IF(G13>0,$F13,"")
A14: =IF(D14="Sous-total","X",IF(E14="","","X")) -> X | E14: THONON_Parvis de la gare | F14: France | I14: 0.48 | K14: 0.36 | M14: - | N14: - | O14: - | P14: - | Q14: - | R14: - | AB14: =IF(G14>0,$F14,"")
A15: =IF(D15="Sous-total","X",IF(E15="","","X")) -> X | E15: THONON_Avenue d’Evian | F15: France | I15: 0.48 | K15: 0.36 | M15: - | N15: - | O15: - | P15: - | Q15: - | R15: - | AB15: =IF(G15>0,$F15,"")
A16: =IF(D16="Sous-total","X",IF(E16="","","X")) -> X | E16: THONON_Carrefour Libération | F16: France | I16: 0.48 | K16: 0.36 | M16: - | N16: - | O16: - | P16: - | Q16: - | R16: - | AB16: =IF(G16>0,$F16,"")
A17: =IF(D17="Sous-total","X",IF(E17="","","X")) -> X | E17: THONON_Collège Champagne | F17: France | I17: 0.48 | K17: 0.36 | M17: - | N17: - | O17: - | P17: - | Q17: - | R17: - | AB17: =IF(G17>0,$F17,"")
A18: =IF(D18="Sous-total","X",IF(E18="","","X")) -> X | E18: THONON_Ecole Jule Ferry | F18: France | I18: 0.48 | K18: 0.36 | M18: - | N18: - | O18: - | P18: - | Q18: - | R18: - | AB18: =IF(G18>0,$F18,"")
A19: =IF(D19="Sous-total","X",IF(E19="","","X")) -> X | E19: THONON_Rond point J. Ferry G Andrier Pl des Arts Bld du Canal | F19: France | I19: 0.48 | K19: 0.36 | M19: - | N19: - | O19: - | P19: - | Q19: - | R19: - | AB19: =IF(G19>0,$F19,"")
... A22: =IF(D22="Sous-total","X",IF(E22="","","X")) -> X | E22: VEIGY_Douane | F22: Frontière | I22: 0.5 | K22: 0 | M22: - | N22: - | O22: - | P22: - | Q22: - | R22: - | AB22: =IF(G22>0,$F22,"")
A23: =IF(D23="Sous-total","X",IF(E23="","","X")) -> X | D23: Sous-total | G23: =SUM(G7:G22) -> 0 | H23: =SUM(H7:H22) -> 0 | I23: =J23/G23 -> #DIV/0! | J23: =SUM(J7:J22) -> 0 | K23: =L23/G23 -> #DIV/0! | L23: =SUM(L7:L22) -> 0 | M23: =N23/L23 -> #DIV/0! | N23: =SUM(N7:N22) -> 0 | O23: =SUM(O7:O22) -> 0 | P23: =SUM(P7:P22) -> 0 | Q23: =SUM(Q7:Q22) -> 0 | R23: =SUM(R7:R22) -> 0 | AB23: =IF(G23>0,$F23,"")
A24: =IF(D24="Sous-total","X",IF(E24="","","X")) -> X | B24: NatEnv & Fabrique à Biclou | C24: OUI | D24: 8 | E24: LA ROCHE_Carrefour Biocoop | F24: France | G24: 31 | H24: 23 | I24: 0.32258065 | J24: =I24*G24 -> 10 | K24: 0.32258065 | L24: =K24*G24 -> 10 | M24: - | N24: - | O24: - | P24: - | Q24: - | R24: - | AB24: =IF(G24>0,$F24,"") -> France
A25: =IF(D25="Sous-total","X",IF(E25="","","X")) -> X | E25: LA ROCHE_Giratoire La Poste | F25: France | G25: 25 | H25: 13 | I25: 0.48 | J25: =I25*G25 -> 12 | K25: 0.36 | L25: =K25*G25 -> 9 | M25: - | N25: - | O25: - | P25: - | Q25: - | R25: - | AB25: =IF(G25>0,$F25,"") -> France
A26: =IF(D26="Sous-total","X",IF(E26="","","X")) -> X | E26: LA ROCHE_Giratoire ENILV | F26: France | G26: 18 | H26: 10 | I26: 0.5 | J26: =I26*G26 -> 9 | K26: 0.16666667 | L26: =K26*G26 -> 3 | M26: - | N26: - | O26: - | P26: - | Q26: - | R26: - | AB26: =IF(G26>0,$F26,"") -> France
A27: =IF(D27="Sous-total","X",IF(E27="","","X")) -> X | E27: LA ROCHE_Gare Passage à niveau (new 2021) | F27: France | I27: 0.5 | K27: 0.16666667 | M27: - | N27: - | O27: - | P27: - | Q27: - | R27: - | AB27: =IF(G27>0,$F27,"")
A28: =IF(D28="Sous-total","X",IF(E28="","","X")) -> X | E28: ARENTHON_La Papeterie | F28: France | G28: 14 | H28: 9 | I28: 0.071428571 | J28: =I28*G28 -> 1 | K28: 0.071428571 | L28: =K28*G28 -> 1 | M28: - | N28: - | O28: - | P28: - | Q28: - | R28: - | AB28: =IF(G28>0,$F28,"") -> France
A29: =IF(D29="Sous-total","X",IF(E29="","","X")) -> X | E29: ST-PIERRE_Franchissement Borne-Dessy | F29: France | G29: 24 | H29: 16 | I29: 0.041666667 | J29: =I29*G29 -> 1 | K29: 0.20833333 | L29: =K29*G29 -> 5 | M29: - | N29: - | O29: - | P29: - | Q29: - | R29: - | AB29: =IF(G29>0,$F29,"") -> France
A30: =IF(D30="Sous-total","X",IF(E30="","","X")) -> X | E30: BONNEVILLE_Franchissement Borne-Tucinge | F30: France | G30: 29 | H30: 21 | I30: 0 | J30: =I30*G30 -> 0 | K30: 0.4137931 | L30: =K30*G30 -> 12 | M30: - | N30: - | O30: - | P30: - | Q30: - | R30: - | AB30: =IF(G30>0,$F30,"") -> France
A31: =IF(D31="Sous-total","X",IF(E31="","","X")) -> X | E31: ST-PIERRE_Pont principal sur le Borne | F31: France | G31: 27 | H31: 17 | I31: 0.25925926 | J31: =I31*G31 -> 7 | K31: 0.48148148 | L31: =K31*G31 -> 13 | M31: - | N31: - | O31: - | P31: - | Q31: - | R31: - | AB31: =IF(G31>0,$F31,"") -> France
A32: =IF(D32="Sous-total","X",IF(E32="","","X")) -> X | E32: AMANCY Sous-terrain Vozerier (new 2022) | F32: France | I32: 0.25925926 | K32: 0.48148148 | M32: - | N32: - | O32: - | P32: - | Q32: - | R32: - | AB32: =IF(G32>0,$F32,"")
A33: =IF(D33="Sous-total","X",IF(E33="","","X")) -> X | E33: ST-PIERRE M. Bricolage | F33: France | I33: 0.25925926 | K33: 0.48148148 | M33: - | N33: - | O33: - | P33: - | Q33: - | R33: - | AB33: =IF(G33>0,$F33,"")
A34: =IF(D34="Sous-total","X",IF(E34="","","X")) -> X | E34: AMANCY_Giratoire Coriandre | F34: France | G34: 4 | H34: 2 | I34: 0.5 | J34: =I34*G34 -> 2 | K34: 0 | L34: =K34*G34 -> 0 | M34: - | N34: - | O34: - | P34: - | Q34: - | R34: - | AB34: =IF(G34>0,$F34,"") -> France
A35: =IF(D35="Sous-total","X",IF(E35="","","X")) -> X | D35: Sous-total | G35: =SUM(G24:G34) -> 172 | H35: =SUM(H24:H34) -> 111 | I35: =J35/G35 -> 0.24418605 | J35: =SUM(J24:J34) -> 42 | K35: =L35/G35 -> 0.30813953 | L35: =SUM(L24:L34) -> 53 | M35: =N35/L35 -> 0 | N35: =SUM(N24:N34) -> 0 | O35: =SUM(O24:O34) -> 0 | P35: =SUM(P24:P34) -> 0 | Q35: =SUM(Q24:Q34) -> 0 | R35: =SUM(R24:R34) -> 0 | AB35: =IF(G35>0,$F35,"") -> 0
A36: =IF(D36="Sous-total","X",IF(E36="","","X")) -> X | B36: AERE | C36: OUI | D36: 9 | E36: ETREMBIERES_Giratoire ex PN93 | F36: France | G36: 37 | H36: 23 | I36: 0.38 | J36: =I36*G36 -> 14.06 | K36: 0.16 | L36: =K36*G36 -> 5.92 | M36: 1 | N36: =IF(M36="-","-",M36*L36) -> 5.92 | AB36: =IF(G36>0,$F36,"") -> France
A37: =IF(D37="Sous-total","X",IF(E37="","","X")) -> X | E37: ETREMBIERES_Carrefour sous Château | F37: France | G37: 33 | H37: 15 | I37: 0.3 | J37: =I37*G37 -> 9.9 | K37: 0.09 | L37: =K37*G37 -> 2.97 | M37: 1 | N37: =IF(M37="-","-",M37*L37) -> 2.97 | AB37: =IF(G37>0,$F37,"") -> France
A38: =IF(D38="Sous-total","X",IF(E38="","","X")) -> X | E38: SCIENTRIER_Carrefour Tour de Bellecombe | F38: France | G38: 6 | H38: 5 | I38: 0 | J38: =I38*G38 -> 0 | K38: 0 | L38: =K38*G38 -> 0 | M38: 0 | N38: =IF(M38="-","-",M38*L38) -> 0 | AB38: =IF(G38>0,$F38,"") -> France
A39: =IF(D39="Sous-total","X",IF(E39="","","X")) -> X | E39: REIGNIER_Giratoire église | F39: France | G39: 25 | H39: 15 | I39: 0.28 | J39: =I39*G39 -> 7 | K39: 0.16 | L39: =K39*G39 -> 4 | M39: 0.25 | N39: =IF(M39="-","-",M39*L39) -> 1 | AB39: =IF(G39>0,$F39,"") -> France
A40: =IF(D40="Sous-total","X",IF(E40="","","X")) -> X | E40: REIGNIER_Giratoire Foron | F40: France | G40: 15 | H40: 9 | I40: 0.13 | J40: =I40*G40 -> 1.95 | K40: 0.07 | L40: =K40*G40 -> 1.05 | M40: 0 | N40: =IF(M40="-","-",M40*L40) -> 0 | AB40: =IF(G40>0,$F40,"") -> France
A41: =IF(D41="Sous-total","X",IF(E41="","","X")) -> X | E41: REIGNIER_Giratoire La Forge | F41: France | G41: 16 | H41: 14 | I41: 0.38 | J41: =I41*G41 -> 6.08 | K41: 0.13 | L41: =K41*G41 -> 2.08 | M41: 1 | N41: =IF(M41="-","-",M41*L41) -> 2.08 | AB41: =IF(G41>0,$F41,"") -> France
A42: =IF(D42="Sous-total","X",IF(E42="","","X")) -> X | E42: PERS-JUSSY_Giratoire Casino | F42: France | G42: 7 | H42: 5 | I42: 0.14 | J42: =I42*G42 -> 0.98 | K42: 0 | L42: =K42*G42 -> 0 | M42: 0 | N42: =IF(M42="-","-",M42*L42) -> 0 | AB42: =IF(G42>0,$F42,"") -> France
A43: =IF(D43="Sous-total","X",IF(E43="","","X")) | I43: 0.14 | K43: 0 | M43: 0 | AB43: =IF(G43>0,$F43,"")
...

Sheet 2021
A2: X | B2: Association(s) | C2: Arrière-pays | D2: Nombre de bénévoles | E2: Postes de comptage | F2: France / Suisse / Frontière | G2: Nombre de vélos | I2: % VAE dans le total | J2: NB VAE dans le total | K2: % femmes dans le total | L2: NB de femmes dans le total | M2: % de VAE chez les femmes | N2: NB de VAE chez les femmes | O2: Autres modes | Q2: Piétons | S2: > Suisse | U2: > France
A3: X
A4: X | G4: total | H4: HP | O4: total | P4: HP | Q4: total | R4: HP | S4: total | T4: HP | U4: total | V4: HP | AB4: 2020
A5: =IF(D5="Sous-total","X",IF(E5="","","X")) -> X | B5: Université Populaire de Cluses | C5: OUI | D5: 2 | E5: CLUSES_Passerelle de Messy | F5: France | G5: 102 | H5: 94 | I5: =J5/G5 -> 0.019607843 | J5: 2 | K5: =L5/G5 -> 0.17647059 | L5: 18 | M5: =IF(N5="-","-",N5/L5) -> 0.11111111 | N5: 2 | AB5: =IF(G5>0,$F5,"") -> France
A6: =IF(D6="Sous-total","X",IF(E6="","","X")) -> X | B6: L'Abeille (Contamine) | C6: OUI | E6: BONNE_Loëx (sous voie rapide) | F6: France | I6: =J6/G6 -> #DIV/0! | K6: =L6/G6 -> #DIV/0! | M6: =IF(N6="-","-",N6/L6) -> #DIV/0! | AB6: =IF(G6>0,$F6,"")
A7: =IF(D7="Sous-total","X",IF(E7="","","X")) -> X | B7: AMDC (Chablais) | C7: OUI | E7: ALLINGES_Rond point des Fleysets | F7: France | I7: =J7/G7 -> #DIV/0! | K7: =L7/G7 -> #DIV/0! | M7: =IF(N7="-","-",N7/L7) -> - | N7: - | O7: - | P7: - | Q7: - | R7: - | S7: - | T7: - | U7: - | V7: - | AB7: =IF(G7>0,$F7,"")
A8: =IF(D8="Sous-total","X",IF(E8="","","X")) -> X | E8: BONS_Gare | F8: France | I8: =J8/G8 -> #DIV/0! | K8: =L8/G8 -> #DIV/0! | M8: =IF(N8="-","-",N8/L8) -> - | N8: - | O8: - | P8: - | Q8: - | R8: - | S8: - | T8: - | U8: - | V8: - | AB8: =IF(G8>0,$F8,"")
A9: =IF(D9="Sous-total","X",IF(E9="","","X")) -> X | E9: DOUVAINE_Mairie | F9: France | I9: =J9/G9 -> #DIV/0! | K9: =L9/G9 -> #DIV/0! | M9: =IF(N9="-","-",N9/L9) -> - | N9: - | O9: - | P9: - | Q9: - | R9: - | S9: - | T9: - | U9: - | V9: - | AB9: =IF(G9>0,$F9,"")
A10: =IF(D10="Sous-total","X",IF(E10="","","X")) -> X | E10: EVIAN_Gare | F10: France | I10: =J10/G10 -> #DIV/0! | K10: =L10/G10 -> #DIV/0! | M10: =IF(N10="-","-",N10/L10) -> - | N10: - | O10: - | P10: - | Q10: - | R10: - | S10: - | T10: - | U10: - | V10: - | AB10: =IF(G10>0,$F10,"")
A11: =IF(D11="Sous-total","X",IF(E11="","","X")) -> X | E11: PERRIGNIER_Gare | F11: France | I11: =J11/G11 -> #DIV/0! | K11: =L11/G11 -> #DIV/0! | M11: =IF(N11="-","-",N11/L11) -> - | N11: - | O11: - | P11: - | Q11: - | R11: - | S11: - | T11: - | U11: - | V11: - | AB11: =IF(G11>0,$F11,"")
A12: =IF(D12="Sous-total","X",IF(E12="","","X")) -> X | E12: THONON_Embarcadère CGN | F12: Frontière | I12: =J12/G12 -> #DIV/0! | K12: =L12/G12 -> #DIV/0! | M12: =IF(N12="-","-",N12/L12) -> - | N12: - | O12: - | P12: - | Q12: - | R12: - | S12: - | T12: - | U12: - | V12: - | AB12: =IF(G12>0,$F12,"")
A13: =IF(D13="Sous-total","X",IF(E13="","","X")) -> X | E13: THONON_Entrée côté place de Crête | F13: France | I13: =J13/G13 -> #DIV/0! | K13: =L13/G13 -> #DIV/0! | M13: =IF(N13="-","-",N13/L13) -> - | N13: - | O13: - | P13: - | Q13: - | R13: - | S13: - | T13: - | U13: - | V13: - | AB13: =IF(G13>0,$F13,"")
A14: =IF(D14="Sous-total","X",IF(E14="","","X")) -> X | E14: THONON_Parvis de la gare | F14: France | I14: =J14/G14 -> #DIV/0! | K14: =L14/G14 -> #DIV/0! | M14: =IF(N14="-","-",N14/L14) -> - | N14: - | O14: - | P14: - | Q14: - | R14: - | S14: - | T14: - | U14: - | V14: - | AB14: =IF(G14>0,$F14,"")
A15: =IF(D15="Sous-total","X",IF(E15="","","X")) -> X | E15: THONON_Avenue d’Evian | F15: France | I15: =J15/G15 -> #DIV/0! | K15: =L15/G15 -> #DIV/0! | M15: =IF(N15="-","-",N15/L15) -> - | N15: - | O15: - | P15: - | Q15: - | R15: - | S15: - | T15: - | U15: - | V15: - | AB15: =IF(G15>0,$F15,"")
A16: =IF(D16="Sous-total","X",IF(E16="","","X")) -> X | E16: THONON_Carrefour Libération | F16: France | I16: =J16/G16 -> #DIV/0! | K16: =L16/G16 -> #DIV/0! | M16: =IF(N16="-","-",N16/L16) -> - | N16: - | O16: - | P16: - | Q16: - | R16: - | S16: - | T16: - | U16: - | V16: - | AB16: =IF(G16>0,$F16,"")
A17: =IF(D17="Sous-total","X",IF(E17="","","X")) -> X | E17: THONON_Collège Champagne | F17: France | I17: =J17/G17 -> #DIV/0! | K17: =L17/G17 -> #DIV/0! | M17: =IF(N17="-","-",N17/L17) -> - | N17: - | O17: - | P17: - | Q17: - | R17: - | S17: - | T17: - | U17: - | V17: - | AB17: =IF(G17>0,$F17,"")
A18: =IF(D18="Sous-total","X",IF(E18="","","X")) -> X | E18: THONON_Ecole Jule Ferry | F18: France | I18: =J18/G18 -> #DIV/0! | K18: =L18/G18 -> #DIV/0! | M18: =IF(N18="-","-",N18/L18) -> - | N18: - | O18: - | P18: - | Q18: - | R18: - | S18: - | T18: - | U18: - | V18: - | AB18: =IF(G18>0,$F18,"")
A19: =IF(D19="Sous-total","X",IF(E19="","","X")) -> X | E19: THONON_Rond point J. Ferry G Andrier Pl des Arts Bld du Canal | F19: France | I19: =J19/G19 -> #DIV/0! | K19: =L19/G19 -> #DIV/0! | M19: =IF(N19="-","-",N19/L19) -> - | N19: - | O19: - | P19: - | Q19: - | R19: - | S19: - | T19: - | U19: - | V19: - | AB19: =IF(G19>0,$F19,"")
... A22: =IF(D22="Sous-total","X",IF(E22="","","X")) -> X | E22: VEIGY_Douane | F22: Frontière | I22: =J22/G22 -> #DIV/0! | K22: =L22/G22 -> #DIV/0! | M22: =IF(N22="-","-",N22/L22) -> - | N22: - | O22: - | P22: - | Q22: - | R22: - | S22: - | T22: - | U22: - | V22: - | AB22: =IF(G22>0,$F22,"")
A23: =IF(D23="Sous-total","X",IF(E23="","","X")) -> X | D23: Sous-total | G23: =SUM(G7:G22) -> 0 | H23: =SUM(H7:H22) -> 0 | I23: =J23/G23 -> #DIV/0! | J23: =SUM(J7:J22) -> 0 | K23: =L23/G23 -> #DIV/0! | L23: =SUM(L7:L22) -> 0 | M23: =N23/L23 -> #DIV/0! | N23: =SUM(N7:N22) -> 0 | O23: =SUM(O7:O22) -> 0 | P23: =SUM(P7:P22) -> 0 | Q23: =SUM(Q7:Q22) -> 0 | R23: =SUM(R7:R22) -> 0 | AB23: =IF(G23>0,$F23,"")
A24: =IF(D24="Sous-total","X",IF(E24="","","X")) -> X | B24: NatEnv (Nature Environnement en Pays rochois) Fabrique à Biclou Pays rochois en Transition | C24: OUI | D24: 9 | E24: LA ROCHE_Carrefour Biocoop | F24: France | G24: 76 | H24: 50 | I24: =J24/G24 -> 0.22368421 | J24: 17 | K24: =L24/G24 -> 0.36842105 | L24: 28 | M24: =IF(N24="-","-",N24/L24) -> - | N24: - | O24: - | P24: - | Q24: - | R24: - | S24: - | T24: - | U24: - | V24: - | AB24: =IF(G24>0,$F24,"") -> France
A25: =IF(D25="Sous-total","X",IF(E25="","","X")) -> X | E25: LA ROCHE_Giratoire La Poste | F25: France | G25: 45 | H25: 27 | I25: =J25/G25 -> 0.46666667 | J25: 21 | K25: =L25/G25 -> 0.31111111 | L25: 14 | M25: =IF(N25="-","-",N25/L25) -> - | N25: - | O25: - | P25: - | Q25: - | R25: - | S25: - | T25: - | U25: - | V25: - | AB25: =IF(G25>0,$F25,"") -> France
A26: =IF(D26="Sous-total","X",IF(E26="","","X")) -> X | E26: LA ROCHE_Giratoire ENILV | F26: France | G26: 16 | H26: 10 | I26: =J26/G26 -> 0.3125 | J26: 5 | K26: =L26/G26 -> 0.1875 | L26: 3 | M26: =IF(N26="-","-",N26/L26) -> - | N26: - | O26: - | P26: - | Q26: - | R26: - | S26: - | T26: - | U26: - | V26: - | AB26: =IF(G26>0,$F26,"") -> France
A27: =IF(D27="Sous-total","X",IF(E27="","","X")) -> X | E27: LA ROCHE_Gare Passage à niveau (new 2021) | F27: France | G27: 56 | H27: 36 | I27: =J27/G27 -> 0.21428571 | J27: 12 | K27: =L27/G27 -> 0.17857143 | L27: 10 | M27: =IF(N27="-","-",N27/L27) -> - | N27: - | O27: - | P27: - | Q27: - | R27: - | AB27: =IF(G27>0,$F27,"") -> France
A28: =IF(D28="Sous-total","X",IF(E28="","","X")) -> X | E28: ARENTHON_La Papeterie | F28: France | G28: 13 | H28: 8 | I28: =J28/G28 -> 0.53846154 | J28: 7 | K28: =L28/G28 -> 0.46153846 | L28: 6 | M28: =IF(N28="-","-",N28/L28) -> - | N28: - | O28: - | P28: - | Q28: - | R28: - | S28: - | T28: - | U28: - | V28: - | AB28: =IF(G28>0,$F28,"") -> France
A29: =IF(D29="Sous-total","X",IF(E29="","","X")) -> X | E29: ST-PIERRE_Franchissement Borne-Dessy | F29: France | G29: 24 | H29: 20 | I29: =J29/G29 -> 0.29166667 | J29: 7 | K29: =L29/G29 -> 0.29166667 | L29: 7 | M29: =IF(N29="-","-",N29/L29) -> - | N29: - | O29: - | P29: - | Q29: - | R29: - | S29: - | T29: - | U29: - | V29: - | AB29: =IF(G29>0,$F29,"") -> France
A30: =IF(D30="Sous-total","X",IF(E30="","","X")) -> X | E30: BONNEVILLE_Franchissement Borne-Tucinge | F30: France | G30: 33 | H30: 25 | I30: =J30/G30 -> 0 | J30: 0 | K30: =L30/G30 -> 0.21212121 | L30: 7 | M30: =IF(N30="-","-",N30/L30) -> - | N30: - | O30: - | P30: - | Q30: - | R30: - | S30: - | T30: - | U30: - | V30: - | AB30: =IF(G30>0,$F30,"") -> France
A31: =IF(D31="Sous-total","X",IF(E31="","","X")) -> X | E31: ST-PIERRE_Pont principal sur le Borne | F31: France | G31: 32 | H31: 17 | I31: =J31/G31 -> 0.15625 | J31: 5 | K31: =L31/G31 -> 0.375 | L31: 12 | M31: =IF(N31="-","-",N31/L31) -> - | N31: - | O31: - | P31: - | Q31: - | R31: - | S31: - | T31: - | U31: - | V31: - | AB31: =IF(G31>0,$F31,"") -> France
A32: =IF(D32="Sous-total","X",IF(E32="","","X")) -> X | E32: AMANCY Sous-terrain Vozerier (new 2022) | F32: France | I32: =J32/G32 -> #DIV/0! | K32: =L32/G32 -> #DIV/0! | M32: =IF(N32="-","-",N32/L32) -> - | N32: - | O32: - | P32: - | Q32: - | R32: - | AB32: =IF(G32>0,$F32,"")
A33: =IF(D33="Sous-total","X",IF(E33="","","X")) -> X | E33: ST-PIERRE M. Bricolage | F33: France | I33: =J33/G33 -> #DIV/0! | K33: =L33/G33 -> #DIV/0! | M33: =IF(N33="-","-",N33/L33) -> - | N33: - | O33: - | P33: - | Q33: - | R33: - | AB33: =IF(G33>0,$F33,"")
A34: =IF(D34="Sous-total","X",IF(E34="","","X")) -> X | E34: AMANCY_Giratoire Coriandre | F34: France | I34: =J34/G34 -> #DIV/0! | K34: =L34/G34 -> #DIV/0! | M34: =IF(N34="-","-",N34/L34) -> - | N34: - | O34: - | P34: - | Q34: - | R34: - | S34: - | T34: - | U34: - | V34: - | AB34: =IF(G34>0,$F34,"")
A35: =IF(D35="Sous-total","X",IF(E35="","","X")) -> X | D35: Sous-total | G35: =SUM(G24:G34) -> 295 | H35: =SUM(H24:H34) -> 193 | I35: =J35/G35 -> 0.25084746 | J35: =SUM(J24:J34) -> 74 | K35: =L35/G35 -> 0.29491525 | L35: =SUM(L24:L34) -> 87 | M35: =N35/L35 -> 0 | N35: =SUM(N24:N34) -> 0 | O35: =SUM(O24:O34) -> 0 | P35: =SUM(P24:P34) -> 0 | Q35: =SUM(Q24:Q34) -> 0 | R35: =SUM(R24:R34) -> 0 | AB35: =IF(G35>0,$F35,"") -> 0
A36: =IF(D36="Sous-total","X",IF(E36="","","X")) -> X | B36: AERE (Association Environnement Reignier-Esery) | C36: OUI | D36: 9 | E36: ETREMBIERES_Giratoire ex PN93 | F36: France | G36: 46 | H36: 32 | I36: =J36/G36 -> 0.65217391 | J36: 30 | K36: =L36/G36 -> 0.19565217 | L36: 9 | M36: =IF(N36="-","-",N36/L36) -> 1 | N36: 9 | O36: - | P36: - | Q36: - | R36: - | S36: - | T36: - | U36: - | V36: - | AB36: =IF(G36>0,$F36,"") -> France
A37: =IF(D37="Sous-total","X",IF(E37="","","X")) -> X | E37: ETREMBIERES_Carrefour sous Château | F37: France | G37: 28 | H37: 17 | I37: =J37/G37 -> 0.64285714 | J37: 18 | K37: =L37/G37 -> 0.32142857 | L37: 9 | M37: =IF(N37="-","-",N37/L37) -> 0.77777778 | N37: 7 | O37: - | P37: - | Q37: - | R37: - | S37: - | T37: - | U37: - | V37: - | AB37: =IF(G37>0,$F37,"") -> France
A38: =IF(D38="Sous-total","X",IF(E38="","","X")) -> X | E38: SCIENTRIER_Carrefour Tour de Bellecombe | F38: France | G38: 5 | H38: 5 | I38: =J38/G38 -> 0.6 | J38: 3 | K38: =L38/G38 -> 0.2 | L38: 1 | M38: =IF(N38="-","-",N38/L38) -> 1 | N38: 1 | O38: - | P38: - | Q38: - | R38: - | S38: - | T38: - | U38: - | V38: - | AB38: =IF(G38>0,$F38,"") -> France
A39: =IF(D39="Sous-total","X",IF(E39="","","X")) -> X | E39: REIGNIER_Giratoire église | F39: France | G39: 45 | H39: 26 | I39: =J39/G39 -> 0.26666667 | J39: 12 | K39: =L39/G39 -> 0.26666667 | L39: 12 | M39: =IF(N39="-","-",N39/L39) -> 0.25 | N39: 3 | O39: - | P39: - | Q39: - | R39: - | S39: - | T39: - | U39: - | V39: - | AB39: =IF(G39>0,$F39,"") -> France
A40: =IF(D40="Sous-total","X",IF(E40="","","X")) -> X | E40: REIGNIER_Giratoire Foron | F40: France | G40: 14 | H40: 9 | I40: =J40/G40 -> 0.21428571 | J40: 3 | K40: =L40/G40 -> 0.14285714 | L40: 2 | M40: =IF(N40="-","-",N40/L40) -> 0.5 | N40: 1 | O40: - | P40: - | Q40: - | R40: - | S40: - | T40: - | U40: - | V40: - | AB40: =IF(G40>0,$F40,"") -> France
A41: =IF(D41="Sous-total","X",IF(E41="","","X")) -> X | E41: REIGNIER_Giratoire La Forge | F41: France | G41: 31 | H41: 23 | I41: =J41/G41 -> 0.5483871 | J41: 17 | K41: =L41/G41 -> 0.16129032 | L41: 5 | M41: =IF(N41="-","-",N41/L41) -> 1 | N41: 5 | O41: - | P41: - | Q41: - | R41: - | S41: - | T41: - | U41: - | V41: - | AB41: =IF(G41>0,$F41,"") -> France
A42: =IF(D42="Sous-total","X",IF(E42="","","X")) -> X | E42: PERS-JUSSY_Giratoire Casino | F42: France | G42: 12 | H42: 7 | I42: =J42/G42 -> 0.33333333 | J42: 4 | K42: =L42/G42 -> 0.33333333 | L42: 4 | M42: =IF(N42="-","-",N42/L42) -> 0.5 | N42: 2 | O42: - | P42: - | Q42: - | R42: - | S42: - | T42: - | U42: - | V42: - | AB42: =IF(G42>0,$F42,"") -> France
A43: =IF(D43="Sous-total","X",IF(E43="","","X")) | I43: =J43/G43 -> #DIV/0! | K43: =L43/G43 -> #DIV/0! | M43: =IF(N43="-","-",N43/L43) -> #DIV/0! | AB43: =IF(G43>0,$F43,"")
...

Sheet 2022
A2: X | B2: Association(s) | C2: Arrière-pays | D2: Nombre de bénévoles | E2: Postes de comptage | F2: France / Suisse / Frontière | G2: Nombre de vélos | I2: % VAE dans le total | J2: NB VAE dans le total | K2: % femmes dans le total | L2: NB de femmes dans le total | M2: % de VAE chez les femmes | N2: NB de VAE chez les femmes | O2: Autres modes | Q2: Piétons | S2: > Suisse | U2: > France
A3: X
A4: X | G4: total | H4: HP | O4: total | P4: HP | Q4: total | R4: HP | S4: total | T4: HP | U4: total | V4: HP | AB4: 2020
A5: =IF(D5="Sous-total","X",IF(E5="","","X")) -> X | B5: Université Populaire de Cluses | C5: OUI | D5: 2 | E5: CLUSES_Passerelle de Messy | F5: France | I5: =IF(J5="","",J5/G5) | K5: =IF(L5="","",L5/G5) | M5: =IF(N5="","",N5/L5) | AB5: =IF(G5<>"",$F5,"")
A6: =IF(D6="Sous-total","X",IF(E6="","","X")) -> X | B6: L'Abeille (Contamine) | C6: OUI | D6: 2 | E6: BONNE_Loëx (sous voie rapide) | F6: France | G6: 20 | H6: 9 | I6: =IF(J6="","",J6/G6) -> 0.4 | J6: 8 | K6: =IF(L6="","",L6/G6) -> 0.2 | L6: 4 | M6: =IF(N6="","",N6/L6) -> 0.5 | N6: 2 | W6: OK | AB6: =IF(G6<>"",$F6,"") -> France
A7: =IF(D7="Sous-total","X",IF(E7="","","X")) -> X | B7: AMDC (Chablais) | C7: OUI | D7: 18 | E7: ALLINGES_Rond point des Fleysets | F7: France | G7: 23 | H7: =G7 -> 23 | I7: =IF(J7="","",J7/G7) -> 0.47826087 | J7: 11 | K7: =IF(L7="","",L7/G7) -> 0.47826087 | L7: 11 | M7: =IF(N7="","",N7/L7) -> 0.90909091 | N7: 10 | O7: 0 | W7: OK | AB7: =IF(G7<>"",$F7,"") -> France
A8: =IF(D8="Sous-total","X",IF(E8="","","X")) -> X | E8: BONS_Gare | F8: France | G8: 25 | H8: =G8-12 -> 13 | I8: =IF(J8="","",J8/G8) -> 0.4 | J8: 10 | K8: =IF(L8="","",L8/G8) -> 0.44 | L8: 11 | M8: =IF(N8="","",N8/L8) -> 0.63636364 | N8: 7 | O8: 22 | W8: OK | AB8: =IF(G8<>"",$F8,"") -> France
A9: =IF(D9="Sous-total","X",IF(E9="","","X")) -> X | E9: DOUVAINE_Mairie | F9: France | G9: 20 | H9: =G9 -> 20 | I9: =IF(J9="","",J9/G9) -> 0.45 | J9: 9 | K9: =IF(L9="","",L9/G9) -> 0.4 | L9: 8 | M9: =IF(N9="","",N9/L9) -> 0.375 | N9: 3 | O9: 6 | W9: OK | AB9: =IF(G9<>"",$F9,"") -> France
A10: =IF(D10="Sous-total","X",IF(E10="","","X")) -> X | E10: EVIAN_Gare | F10: France | G10: 13 | H10: =G10-1 -> 12 | I10: =IF(J10="","",J10/G10) -> 0.15384615 | J10: 2 | K10: =IF(L10="","",L10/G10) -> 0.30769231 | L10: 4 | M10: =IF(N10="","",N10/L10) -> 0.5 | N10: 2 | O10: 7 | W10: OK | AB10: =IF(G10<>"",$F10,"") -> France
A11: =IF(D11="Sous-total","X",IF(E11="","","X")) -> X | E11: PERRIGNIER_Gare | F11: France | G11: 7 | H11: =G11-1 -> 6 | I11: =IF(J11="","",J11/G11) -> 0.28571429 | J11: 2 | K11: =IF(L11="","",L11/G11) -> 0 | L11: 0 | M11: =IF(N11="","",N11/L11) | O11: 6 | W11: OK | AB11: =IF(G11<>"",$F11,"") -> France
A12: =IF(D12="Sous-total","X",IF(E12="","","X")) -> X | E12: THONON_Embarcadère CGN | F12: Frontière | G12: 74 | H12: =G12-44 -> 30 | I12: =IF(J12="","",J12/G12) -> 0.2972973 | J12: 22 | K12: =IF(L12="","",L12/G12) -> 0.36486486 | L12: 27 | M12: =IF(N12="","",N12/L12) -> 0.48148148 | N12: 13 | O12: 101 | S12: 74 | T12: 30 | U12: 0 | V12: 0 | W12: OK | AB12: =IF(G12<>"",$F12,"") -> Frontière
A13: =IF(D13="Sous-total","X",IF(E13="","","X")) -> X | E13: THONON_Entrée côté place de Crête | F13: France | G13: 34 | H13: =G13 -> 34 | I13: =IF(J13="","",J13/G13) -> 0.17647059 | J13: 6 | K13: =IF(L13="","",L13/G13) -> 0.38235294 | L13: 13 | M13: =IF(N13="","",N13/L13) -> 0.15384615 | N13: 2 | O13: 12 | W13: OK | AB13: =IF(G13<>"",$F13,"") -> France
A14: =IF(D14="Sous-total","X",IF(E14="","","X")) -> X | E14: THONON_Parvis de la gare | F14: France | G14: 47 | H14: =G14 -> 47 | I14: =IF(J14="","",J14/G14) -> 0.063829787 | J14: 3 | K14: =IF(L14="","",L14/G14) -> 0.31914894 | L14: 15 | M14: =IF(N14="","",N14/L14) -> 0.2 | N14: 3 | O14: 37 | W14: OK | AB14: =IF(G14<>"",$F14,"") -> France
A15: =IF(D15="Sous-total","X",IF(E15="","","X")) -> X | E15: THONON_Avenue d’Evian | F15: France | G15: 92 | H15: =G15 -> 92 | I15: =IF(J15="","",J15/G15) -> 0.097826087 | J15: 9 | K15: =IF(L15="","",L15/G15) -> 0.45652174 | L15: 42 | M15: =IF(N15="","",N15/L15) -> 0.14285714 | N15: 6 | O15: 19 | W15: OK | AB15: =IF(G15<>"",$F15,"") -> France
A16: =IF(D16="Sous-total","X",IF(E16="","","X")) -> X | E16: THONON_Carrefour Libération | F16: France | G16: 77 | H16: =G16 -> 77 | I16: =IF(J16="","",J16/G16) -> 0.14285714 | J16: 11 | K16: =IF(L16="","",L16/G16) -> 0.4025974 | L16: 31 | M16: =IF(N16="","",N16/L16) -> 0.16129032 | N16: 5 | O16: 20 | W16: OK | AB16: =IF(G16<>"",$F16,"") -> France
A17: =IF(D17="Sous-total","X",IF(E17="","","X")) -> X | E17: THONON_Collège Champagne | F17: France | G17: 19 | H17: =G17 -> 19 | I17: =IF(J17="","",J17/G17) -> 0.21052632 | J17: 4 | K17: =IF(L17="","",L17/G17) -> 0.31578947 | L17: 6 | M17: =IF(N17="","",N17/L17) -> 0.16666667 | N17: 1 | O17: 3 | W17: OK | AB17: =IF(G17<>"",$F17,"") -> France
A18: =IF(D18="Sous-total","X",IF(E18="","","X")) -> X | E18: THONON_Ecole Jule Ferry | F18: France | G18: 24 | H18: =G18 -> 24 | I18: =IF(J18="","",J18/G18) -> 0.29166667 | J18: 7 | K18: =IF(L18="","",L18/G18) -> 0.54166667 | L18: 13 | M18: =IF(N18="","",N18/L18) -> 0.46153846 | N18: 6 | O18: 11 | W18: OK | AB18: =IF(G18<>"",$F18,"") -> France
A19: =IF(D19="Sous-total","X",IF(E19="","","X")) -> X | E19: THONON_Rond point J. Ferry G Andrier Pl des Arts Bld du Canal | F19: France | G19: 101 | H19: =G19 -> 101 | I19: =IF(J19="","",J19/G19) -> 0.14851485 | J19: 15 | K19: =IF(L19="","",L19/G19) -> 0.3960396 | L19: 40 | M19: =IF(N19="","",N19/L19) -> 0.225 | N19: 9 | O19: 34 | W19: OK | AB19: =IF(G19<>"",$F19,"") -> France
A20: =IF(D20="Sous-total","X",IF(E20="","","X")) -> X | E20: THONON/ANTHY_Pont de Marclaz | F20: France | G20: 25 | H20: =G20 -> 25 | I20: =IF(J20="","",J20/G20) -> 0.28 | J20: 7 | K20: =IF(L20="","",L20/G20) -> 0.24 | L20: 6 | M20: =IF(N20="","",N20/L20) -> 0.66666667 | N20: 4 | O20: 4 | W20: OK | AB20: =IF(G20<>"",$F20,"") -> France
A21: =IF(D21="Sous-total","X",IF(E21="","","X")) -> X | E21: THONON/MARIN_Pont de Dranse | F21: France | G21: 45 | H21: =G21 -> 45 | I21: =IF(J21="","",J21/G21) -> 0.4 | J21: 18 | K21: =IF(L21="","",L21/G21) -> 0.22222222 | L21: 10 | M21: =IF(N21="","",N21/L21) -> 0.6 | N21: 6 | O21: 4 | W21: OK | AB21: =IF(G21<>"",$F21,"") -> France
A22: =IF(D22="Sous-total","X",IF(E22="","","X")) -> X | E22: VEIGY_Douane | F22: Frontière | G22: 68 | H22: =G22-25 -> 43 | I22: =IF(J22="","",J22/G22) -> 0.51470588 | J22: 35 | K22: =IF(L22="","",L22/G22) -> 0.44117647 | L22: 30 | M22: =IF(N22="","",N22/L22) -> 0.53333333 | N22: 16 | O22: 1 | Q22: 16 | S22: 61 | T22: 38 | U22: 7 | V22: 5 | W22: OK | AB22: =IF(G22<>"",$F22,"") -> Frontière
A23: =IF(D23="Sous-total","X",IF(E23="","","X")) -> X | D23: Sous-total | G23: =SUM(G7:G22) -> 694 | H23: =SUM(H7:H22) -> 611 | I23: =IF(J23="","",J23/G23) -> 0.24639769 | J23: =SUM(J7:J22) -> 171 | K23: =IF(L23="","",L23/G23) -> 0.38472622 | L23: =SUM(L7:L22) -> 267 | M23: =IF(N23="","",N23/L23) -> 0.34831461 | N23: =SUM(N7:N22) -> 93 | O23: =SUM(O7:O22) -> 287 | P23: =SUM(P7:P22) -> 0 | Q23: =SUM(Q7:Q22) -> 16 | R23: =SUM(R7:R22) -> 0 | S23: =SUM(S7:S22) -> 135 | T23: =SUM(T7:T22) -> 68 | U23: =SUM(U7:U22) -> 7 | V23: =SUM(V7:V22) -> 5 | W23: OK | AB23: =IF(G23<>"",$F23,"") -> 0
A24: =IF(D24="Sous-total","X",IF(E24="","","X")) -> X | B24: NatEnv (Nature Environnement en Pays rochois) Fabrique à Biclou Pays rochois en Transition | C24: OUI | D24: 11 | E24: LA ROCHE_Carrefour Biocoop | F24: France | G24: 59 | H24: 21 | I24: =IF(J24="","",J24/G24) -> 0.47457627 | J24: 28 | K24: =IF(L24="","",L24/G24) -> 0.33898305 | L24: 20 | M24: =IF(N24="","",N24/L24) | O24: 14 | S24: - | T24: - | U24: - | V24: - | W24: OK | AB24: =IF(G24<>"",$F24,"") -> France
A25: =IF(D25="Sous-total","X",IF(E25="","","X")) -> X | E25: LA ROCHE_Giratoire La Poste | F25: France | G25: 32 | H25: 16 | I25: =IF(J25="","",J25/G25) -> 0.34375 | J25: 11 | K25: =IF(L25="","",L25/G25) -> 0.1875 | L25: 6 | M25: =IF(N25="","",N25/L25) | O25: 15 | S25: - | T25: - | U25: - | V25: - | W25: OK | AB25: =IF(G25<>"",$F25,"") -> France
A26: =IF(D26="Sous-total","X",IF(E26="","","X")) -> X | E26: LA ROCHE_Giratoire ENILV | F26: France | G26: 21 | H26: 8 | I26: =IF(J26="","",J26/G26) -> 0.19047619 | J26: 4 | K26: =IF(L26="","",L26/G26) -> 0.23809524 | L26: 5 | M26: =IF(N26="","",N26/L26) | O26: 4 | S26: - | T26: - | U26: - | V26: - | W26: OK | AB26: =IF(G26<>"",$F26,"") -> France
A27: =IF(D27="Sous-total","X",IF(E27="","","X")) -> X | E27: LA ROCHE_Gare Passage à niveau (new 2021) | F27: France | G27: 55 | H27: 21 | I27: =IF(J27="","",J27/G27) -> 0.32727273 | J27: 18 | K27: =IF(L27="","",L27/G27) -> 0.32727273 | L27: 18 | M27: =IF(N27="","",N27/L27) | O27: 20 | S27: - | T27: - | U27: - | V27: - | W27: OK | AB27: =IF(G27<>"",$F27,"") -> France
A28: =IF(D28="Sous-total","X",IF(E28="","","X")) -> X | E28: ARENTHON_La Papeterie | F28: France | G28: 6 | H28: 2 | I28: =IF(J28="","",J28/G28) -> 0.33333333 | J28: 2 | K28: =IF(L28="","",L28/G28) -> 0.16666667 | L28: 1 | M28: =IF(N28="","",N28/L28) | S28: - | T28: - | U28: - | V28: - | W28: OK | AB28: =IF(G28<>"",$F28,"") -> France
A29: =IF(D29="Sous-total","X",IF(E29="","","X")) -> X | E29: ST-PIERRE_Franchissement Borne-Dessy | F29: France | G29: 20 | H29: 6 | I29: =IF(J29="","",J29/G29) -> 0.25 | J29: 5 | K29: =IF(L29="","",L29/G29) -> 0.2 | L29: 4 | M29: =IF(N29="","",N29/L29) | O29: 2 | S29: - | T29: - | U29: - | V29: - | W29: OK | AB29: =IF(G29<>"",$F29,"") -> France
A30: =IF(D30="Sous-total","X",IF(E30="","","X")) -> X | E30: BONNEVILLE_Franchissement Borne-Tucinge | F30: France | G30: 20 | H30: 9 | I30: =IF(J30="","",J30/G30) -> 0.25 | J30: 5 | K30: =IF(L30="","",L30/G30) -> 0.25 | L30: 5 | M30: =IF(N30="","",N30/L30) | O30: 1 | S30: - | T30: - | U30: - | V30: - | W30: OK | AB30: =IF(G30<>"",$F30,"") -> France
A31: =IF(D31="Sous-total","X",IF(E31="","","X")) -> X | E31: ST-PIERRE_Pont principal sur le Borne | F31: France | G31: 35 | H31: 9 | I31: =IF(J31="","",J31/G31) -> 0.31428571 | J31: 11 | K31: =IF(L31="","",L31/G31) -> 0.22857143 | L31: 8 | M31: =IF(N31="","",N31/L31) | O31: 2 | S31: - | T31: - | U31: - | V31: - | W31: OK | AB31: =IF(G31<>"",$F31,"") -> France
A32: =IF(D32="Sous-total","X",IF(E32="","","X")) -> X | E32: AMANCY Sous-terrain Vozerier (new 2022) | F32: France | G32: 15 | H32: 7 | I32: =IF(J32="","",J32/G32) -> 0.2 | J32: 3 | K32: =IF(L32="","",L32/G32) | M32: =IF(N32="","",N32/L32) | S32: - | T32: - | U32: - | V32: - | W32: OK | AB32: =IF(G32<>"",$F32,"") -> France
A33: =IF(D33="Sous-total","X",IF(E33="","","X")) -> X | E33: ST-PIERRE M. Bricolage | F33: France | G33: 22 | H33: 7 | I33: =IF(J33="","",J33/G33) -> 0.090909091 | J33: 2 | K33: =IF(L33="","",L33/G33) -> 0.22727273 | L33: 5 | M33: =IF(N33="","",N33/L33) | S33: - | T33: - | U33: - | V33: - | W33: OK | AB33: =IF(G33<>"",$F33,"") -> France
A34: =IF(D34="Sous-total","X",IF(E34="","","X")) -> X | E34: AMANCY_Giratoire Coriandre | F34: France | I34: =IF(J34="","",J34/G34) | K34: =IF(L34="","",L34/G34) | M34: =IF(N34="","",N34/L34) | S34: - | T34: - | U34: - | V34: - | W34: OK | AB34: =IF(G34<>"",$F34,"")
A35: =IF(D35="Sous-total","X",IF(E35="","","X")) -> X | D35: Sous-total | G35: =SUM(G24:G34) -> 285 | H35: =SUM(H24:H34) -> 106 | I35: =J35/G35 -> 0.3122807 | J35: =SUM(J24:J34) -> 89 | K35: =IF(L35="","",L35/G35) -> 0.25263158 | L35: =SUM(L24:L34) -> 72 | M35: =IF(N35="","",N35/L35) -> 0 | N35: =SUM(N24:N34) -> 0 | O35: =SUM(O24:O34) -> 58 | P35: =SUM(P24:P34) -> 0 | Q35: =SUM(Q24:Q34) -> 0 | R35: =SUM(R24:R34) -> 0 | S35: =SUM(S24:S34) -> 0 | T35: =SUM(T24:T34) -> 0 | U35: =SUM(U24:U34) -> 0 | V35: =SUM(V24:V34) -> 0 | W35: OK | AB35: =IF(G35<>"",$F35,"") -> 0
A36: =IF(D36="Sous-total","X",IF(E36="","","X")) -> X | B36: AERE (Association Environnement Reignier-Esery) | C36: OUI | D36: 6 | E36: ETREMBIERES_Giratoire ex PN93 | F36: France | G36: 50 | H36: 37 | I36: =IF(J36="","",J36/G36) -> 0.68 | J36: 34 | K36: =IF(L36="","",L36/G36) -> 0.22 | L36: 11 | M36: =IF(N36="","",N36/L36) -> 0.81818182 | N36: 9 | O36: 3 | P36: 3 | Q36: 2 | R36: 2 | S36: - | T36: - | U36: - | V36: - | W36: OK | AB36: =IF(G36<>"",$F36,"") -> France
A37: =IF(D37="Sous-total","X",IF(E37="","","X")) -> X | E37: ETREMBIERES_Carrefour sous Château | F37: France | G37: 26 | H37: 17 | I37: =IF(J37="","",J37/G37) -> 0.42307692 | J37: 11 | K37: =IF(L37="","",L37/G37) -> 0.23076923 | L37: 6 | M37: =IF(N37="","",N37/L37) -> 0.66666667 | N37: 4 | Q37: 1 | R37: 1 | S37: - | T37: - | U37: - | V37: - | W37: OK | AB37: =IF(G37<>"",$F37,"") -> France
A38: =IF(D38="Sous-total","X",IF(E38="","","X")) -> X | E38: SCIENTRIER_Carrefour Tour de Bellecombe | F38: France | I38: =IF(J38="","",J38/G38) | K38: =IF(L38="","",L38/G38) | M38: =IF(N38="","",N38/L38) | S38: - | T38: - | U38: - | V38: - | W38: OK | AB38: =IF(G38<>"",$F38,"")
A39: =IF(D39="Sous-total","X",IF(E39="","","X")) -> X | E39: REIGNIER_Giratoire église | F39: France | G39: 29 | H39: 16 | I39: =IF(J39="","",J39/G39) -> 0.37931034 | J39: 11 | K39: =IF(L39="","",L39/G39) -> 0.31034483 | L39: 9 | M39: =IF(N39="","",N39/L39) -> 0.55555556 | N39: 5 | O39: 4 | P39: 3 | Q39: 49 | R39: 36 | S39: - | T39: - | U39: - | V39: - | W39: OK | AB39: =IF(G39<>"",$F39,"") -> France
A40: =IF(D40="Sous-total","X",IF(E40="","","X")) -> X | E40: REIGNIER_Giratoire Foron | F40: France | G40: 18 | H40: 9 | I40: =IF(J40="","",J40/G40) -> 0.33333333 | J40: 6 | K40: =IF(L40="","",L40/G40) -> 0.16666667 | L40: 3 | M40: =IF(N40="","",N40/L40) -> 1 | N40: 3 | S40: - | T40: - | U40: - | V40: - | W40: OK | AB40: =IF(G40<>"",$F40,"") -> France
A41: =IF(D41="Sous-total","X",IF(E41="","","X")) -> X | E41: REIGNIER_Giratoire La Forge | F41: France | I41: =IF(J41="","",J41/G41) | K41: =IF(L41="","",L41/G41) | M41: =IF(N41="","",N41/L41) | S41: - | T41: - | U41: - | V41: - | W41: OK | AB41: =IF(G41<>"",$F41,"")
...

Sheet SYNTHESE
A2: X | B2: Association(s) | C2: Arrière-pays | D2: NB de bénévoles | G2: Postes de comptage | K2: France / Suisse / Frontière | L2: Nombre de vélos | R2: VAE dans le total | X2: Femmes dans le total | AD2: VAE chez les femmes | AJ2: Autres modes | AL2: Piétons | AN2: > Suisse | AP2: > France
A3: X | L3: Total | O3: HP | R3: [en %] | U3: [en valeur] | X3: [en %] | AA3: [en valeur] | AD3: [en %] | AG3: [en valeur]
A4: X | D4: 2020 | E4: 2021 | F4: 2022 | H4: 2020 | I4: 2021 | J4: 2022 | L4: 2020 | M4: 2021 | N4: 2022 | O4: 2020 | P4: 2021 | Q4: 2022 | R4: 2020 | S4: 2021 | T4: 2022 | U4: 2020 | V4: 2021 | W4: 2022 | X4: 2020 | Y4: 2021 | Z4: 2022 | AA4: 2020 | AB4: 2021 | AC4: 2022 | AD4: 2020 | AE4: 2021 | AF4: 2022 | AG4: 2020 | AH4: 2021 | AI4: 2022 | AJ4: total | AK4: HP | AL4: total | AM4: HP | AN4: total | AO4: HP | AP4: total | AQ4: HP | AY4: 2020 | AZ4: 2021 | BA4: 2022
A5: =IF(D5="Sous-total","X",IF(G5="","","X")) -> X | B5: Université Populaire de Cluses | C5: OUI | D5: ='2020'!D5 -> 2 | E5: ='2021'!D5 -> 2 | F5: ='2022'!D5 -> 2 | G5: CLUSES_Passerelle de Messy | H5: =IF(L5=0,"","X") -> X | I5: =IF(M5=0,"","X") -> X | J5: =IF(N5=0,"","X") | K5: France | L5: ='2020'!G5 -> 63 | M5: ='2021'!G5 -> 102 | N5: ='2022'!G5 -> 0 | O5: ='2020'!H5 -> 29 | P5: ='2021'!H5 -> 94 | Q5: ='2022'!H5 -> 0 | R5: =IF(L5="",0,IF(U5=0,0,U5/L5)) -> 0.031746032 | S5: =IF(M5="",0,IF(V5=0,0,V5/M5)) -> 0.019607843 | T5: =IF(N5="",0,IF(W5=0,0,W5/N5)) -> 0 | U5: ='2020'!J5 -> 2 | V5: ='2021'!J5 -> 2 | W5: ='2022'!J5 -> 0 | X5: =IF(L5=0,"",IF(AA5="","",AA5/L5)) -> 0.26984127 | Y5: =IF(M5=0,"",IF(AB5="","",AB5/M5)) -> 0.17647059 | Z5: =IF(N5=0,"",IF(AC5="","",AC5/N5)) | AA5: ='2020'!L5 -> 17 | AB5: ='2021'!L5 -> 18 | AC5: ='2022'!L5 -> 0 | AD5: =IF(AA5=0,"",IF(AG5="-","",AG5/AA5)) -> 0.11764706 | AE5: =IF(AB5=0,"",IF(AH5="-","",AH5/AB5)) -> 0.11111111 | AF5: =IF(AC5=0,"",IF(AI5="-","",AI5/AC5)) | AG5: ='2020'!N5 -> 2 | AH5: ='2021'!N5 -> 2 | AI5: ='2022'!N5 -> 0 | AJ5: - | AK5: - | AL5: - | AM5: - | AN5: - | AO5: - | AP5: - | AQ5: - | AY5: =IF(H5<>"",$K5,"") -> France | AZ5: =IF(I5<>"",$K5,"") -> France | BA5: =IF(J5<>"",$K5,"")
A6: =IF(D6="Sous-total","X",IF(G6="","","X")) -> X | B6: L'Abeille (Contamine) | C6: OUI | D6: ='2020'!D6 -> 0 | E6: ='2021'!D6 -> 0 | F6: ='2022'!D6 -> 2 | G6: BONNE_Loëx (sous voie rapide) | H6: =IF(L6=0,"","X") | I6: =IF(M6=0,"","X") | J6: =IF(N6=0,"","X") -> X | K6: France | L6: ='2020'!G6 -> 0 | M6: ='2021'!G6 -> 0 | N6: ='2022'!G6 -> 20 | O6: ='2020'!H6 -> 0 | P6: ='2021'!H6 -> 0 | Q6: ='2022'!H6 -> 9 | R6: =IF(L6="",0,IF(U6=0,0,U6/L6)) -> 0 | S6: =IF(M6="",0,IF(V6=0,0,V6/M6)) -> 0 | T6: =IF(N6="",0,IF(W6=0,0,W6/N6)) -> 0.4 | U6: ='2020'!J6 -> 0 | V6: ='2021'!J6 -> 0 | W6: ='2022'!J6 -> 8 | X6: =IF(L6=0,"",IF(AA6="","",AA6/L6)) | Y6: =IF(M6=0,"",IF(AB6="","",AB6/M6)) | Z6: =IF(N6=0,"",IF(AC6="","",AC6/N6)) -> 0.2 | AA6: ='2020'!L6 -> 0 | AB6: ='2021'!L6 -> 0 | AC6: ='2022'!L6 -> 4 | AD6: =IF(AA6=0,"",IF(AG6="-","",AG6/AA6)) | AE6: =IF(AB6=0,"",IF(AH6="-","",AH6/AB6)) | AF6: =IF(AC6=0,"",IF(AI6="-","",AI6/AC6)) -> 0.5 | AG6: ='2020'!N6 -> 0 | AH6: ='2021'!N6 -> 0 | AI6: ='2022'!N6 -> 2 | AJ6: - | AK6: - | AL6: - | AM6: - | AN6: - | AO6: - | AP6: - | AQ6: - | AY6: =IF(H6<>"",$K6,"") | AZ6: =IF(I6<>"",$K6,"") | BA6: =IF(J6<>"",$K6,"") -> France
A7: =IF(D7="Sous-total","X",IF(G7="","","X")) -> X | B7: AMDC (Chablais) | C7: OUI | D7: ='2020'!D7 -> 0 | E7: ='2021'!D7 -> 0 | F7: ='2022'!D7 -> 18 | G7: ALLINGES_Rond point des Fleysets | H7: =IF(L7=0,"","X") | I7: =IF(M7=0,"","X") | J7: =IF(N7=0,"","X") -> X | K7: France | L7: ='2020'!G7 -> 0 | M7: ='2021'!G7 -> 0 | N7: ='2022'!G7 -> 23 | O7: ='2020'!H7 -> 0 | P7: ='2021'!H7 -> 0 | Q7: ='2022'!H7 -> 23 | R7: =IF(L7="",0,IF(U7=0,0,U7/L7)) -> 0 | S7: =IF(M7="",0,IF(V7=0,0,V7/M7)) -> 0 | T7: =IF(N7="",0,IF(W7=0,0,W7/N7)) -> 0.47826087 | U7: ='2020'!J7 -> 0 | V7: ='2021'!J7 -> 0 | W7: ='2022'!J7 -> 11 | X7: =IF(L7=0,"",IF(AA7="","",AA7/L7)) | Y7: =IF(M7=0,"",IF(AB7="","",AB7/M7)) | Z7: =IF(N7=0,"",IF(AC7="","",AC7/N7)) -> 0.47826087 | AA7: ='2020'!L7 -> 0 | AB7: ='2021'!L7 -> 0 | AC7: ='2022'!L7 -> 11 | AD7: =IF(AA7=0,"",IF(AG7="-","",AG7/AA7)) | AE7: =IF(AB7=0,"",IF(AH7="-","",AH7/AB7)) | AF7: =IF(AC7=0,"",IF(AI7="-","",AI7/AC7)) -> 0.90909091 | AG7: ='2020'!N7 -> - | AH7: ='2021'!N7 -> - | AI7: ='2022'!N7 -> 10 | AJ7: - | AK7: - | AL7: - | AM7: - | AN7: - | AO7: - | AP7: - | AQ7: - | AY7: =IF(H7<>"",$K7,"") | AZ7: =IF(I7<>"",$K7,"") | BA7: =IF(J7<>"",$K7,"") -> France
A8: =IF(D8="Sous-total","X",IF(G8="","","X")) -> X | G8: BONS_Gare | H8: =IF(L8=0,"","X") | I8: =IF(M8=0,"","X") | J8: =IF(N8=0,"","X") -> X | K8: France | L8: ='2020'!G8 -> 0 | M8: ='2021'!G8 -> 0 | N8: ='2022'!G8 -> 25 | O8: ='2020'!H8 -> 0 | P8: ='2021'!H8 -> 0 | Q8: ='2022'!H8 -> 13 | R8: =IF(L8="",0,IF(U8=0,0,U8/L8)) -> 0 | S8: =IF(M8="",0,IF(V8=0,0,V8/M8)) -> 0 | T8: =IF(N8="",0,IF(W8=0,0,W8/N8)) -> 0.4 | U8: ='2020'!J8 -> 0 | V8: ='2021'!J8 -> 0 | W8: ='2022'!J8 -> 10 | X8: =IF(L8=0,"",IF(AA8="","",AA8/L8)) | Y8: =IF(M8=0,"",IF(AB8="","",AB8/M8)) | Z8: =IF(N8=0,"",IF(AC8="","",AC8/N8)) -> 0.44 | AA8: ='2020'!L8 -> 0 | AB8: ='2021'!L8 -> 0 | AC8: ='2022'!L8 -> 11 | AD8: =IF(AA8=0,"",IF(AG8="-","",AG8/AA8)) | AE8: =IF(AB8=0,"",IF(AH8="-","",AH8/AB8)) | AF8: =IF(AC8=0,"",IF(AI8="-","",AI8/AC8)) -> 0.63636364 | AG8: ='2020'!N8 -> - | AH8: ='2021'!N8 -> - | AI8: ='2022'!N8 -> 7 | AJ8: - | AK8: - | AL8: - | AM8: - | AN8: - | AO8: - | AP8: - | AQ8: - | AY8: =IF(H8<>"",$K8,"") | AZ8: =IF(I8<>"",$K8,"") | BA8: =IF(J8<>"",$K8,"") -> France
A9: =IF(D9="Sous-total","X",IF(G9="","","X")) -> X | G9: DOUVAINE_Mairie | H9: =IF(L9=0,"","X") | I9: =IF(M9=0,"","X") | J9: =IF(N9=0,"","X") -> X | K9: France | L9: ='2020'!G9 -> 0 | M9: ='2021'!G9 -> 0 | N9: ='2022'!G9 -> 20 | O9: ='2020'!H9 -> 0 | P9: ='2021'!H9 -> 0 | Q9: ='2022'!H9 -> 20 | R9: =IF(L9="",0,IF(U9=0,0,U9/L9)) -> 0 | S9: =IF(M9="",0,IF(V9=0,0,V9/M9)) -> 0 | T9: =IF(N9="",0,IF(W9=0,0,W9/N9)) -> 0.45 | U9: ='2020'!J9 -> 0 | V9: ='2021'!J9 -> 0 | W9: ='2022'!J9 -> 9 | X9: =IF(L9=0,"",IF(AA9="","",AA9/L9)) | Y9: =IF(M9=0,"",IF(AB9="","",AB9/M9)) | Z9: =IF(N9=0,"",IF(AC9="","",AC9/N9)) -> 0.4 | AA9: ='2020'!L9 -> 0 | AB9: ='2021'!L9 -> 0 | AC9: ='2022'!L9 -> 8 | AD9: =IF(AA9=0,"",IF(AG9="-","",AG9/AA9)) | AE9: =IF(AB9=0,"",IF(AH9="-","",AH9/AB9)) | AF9: =IF(AC9=0,"",IF(AI9="-","",AI9/AC9)) -> 0.375 | AG9: ='2020'!N9 -> - | AH9: ='2021'!N9 -> - | AI9: ='2022'!N9 -> 3 | AJ9: - | AK9: - | AL9: - | AM9: - | AN9: - | AO9: - | AP9: - | AQ9: - | AY9: =IF(H9<>"",$K9,"") | AZ9: =IF(I9<>"",$K9,"") | BA9: =IF(J9<>"",$K9,"") -> France
A10: =IF(D10="Sous-total","X",IF(G10="","","X")) -> X | G10: EVIAN_Gare | H10: =IF(L10=0,"","X") | I10: =IF(M10=0,"","X") | J10: =IF(N10=0,"","X") -> X | K10: France | L10: ='2020'!G10 -> 0 | M10: ='2021'!G10 -> 0 | N10: ='2022'!G10 -> 13 | O10: ='2020'!H10 -> 0 | P10: ='2021'!H10 -> 0 | Q10: ='2022'!H10 -> 12 | R10: =IF(L10="",0,IF(U10=0,0,U10/L10)) -> 0 | S10: =IF(M10="",0,IF(V10=0,0,V10/M10)) -> 0 | T10: =IF(N10="",0,IF(W10=0,0,W10/N10)) -> 0.15384615 | U10: ='2020'!J10 -> 0 | V10: ='2021'!J10 -> 0 | W10: ='2022'!J10 -> 2 | X10: =IF(L10=0,"",IF(AA10="","",AA10/L10)) | Y10: =IF(M10=0,"",IF(AB10="","",AB10/M10)) | Z10: =IF(N10=0,"",IF(AC10="","",AC10/N10)) -> 0.30769231 | AA10: ='2020'!L10 -> 0 | AB10: ='2021'!L10 -> 0 | AC10: ='2022'!L10 -> 4 | AD10: =IF(AA10=0,"",IF(AG10="-","",AG10/AA10)) | AE10: =IF(AB10=0,"",IF(AH10="-","",AH10/AB10)) | AF10: =IF(AC10=0,"",IF(AI10="-","",AI10/AC10)) -> 0.5 | AG10: ='2020'!N10 -> - | AH10: ='2021'!N10 -> - | AI10: ='2022'!N10 -> 2 | AJ10: - | AK10: - | AL10: - | AM10: - | AN10: - | AO10: - | AP10: - | AQ10: - | AY10: =IF(H10<>"",$K10,"") | AZ10: =IF(I10<>"",$K10,"") | BA10: =IF(J10<>"",$K10,"") -> France
A11: =IF(D11="Sous-total","X",IF(G11="","","X")) -> X | G11: PERRIGNIER_Gare | H11: =IF(L11=0,"","X") | I11: =IF(M11=0,"","X") | J11: =IF(N11=0,"","X") -> X | K11: France | L11: ='2020'!G11 -> 0 | M11: ='2021'!G11 -> 0 | N11: ='2022'!G11 -> 7 | O11: ='2020'!H11 -> 0 | P11: ='2021'!H11 -> 0 | Q11: ='2022'!H11 -> 6 | R11: =IF(L11="",0,IF(U11=0,0,U11/L11)) -> 0 | S11: =IF(M11="",0,IF(V11=0,0,V11/M11)) -> 0 | T11: =IF(N11="",0,IF(W11=0,0,W11/N11)) -> 0.28571429 | U11: ='2020'!J11 -> 0 | V11: ='2021'!J11 -> 0 | W11: ='2022'!J11 -> 2 | X11: =IF(L11=0,"",IF(AA11="","",AA11/L11)) | Y11: =IF(M11=0,"",IF(AB11="","",AB11/M11)) | Z11: =IF(N11=0,"",IF(AC11="","",AC11/N11)) -> 0 | AA11: ='2020'!L11 -> 0 | AB11: ='2021'!L11 -> 0 | AC11: ='2022'!L11 -> 0 | AD11: =IF(AA11=0,"",IF(AG11="-","",AG11/AA11)) | AE11: =IF(AB11=0,"",IF(AH11="-","",AH11/AB11)) | AF11: =IF(AC11=0,"",IF(AI11="-","",AI11/AC11)) | AG11: ='2020'!N11 -> - | AH11: ='2021'!N11 -> - | AI11: ='2022'!N11 -> 0 | AJ11: - | AK11: - | AL11: - | AM11: - | AN11: - | AO11: - | AP11: - | AQ11: - | AY11: =IF(H11<>"",$K11,"") | AZ11: =IF(I11<>"",$K11,"") | BA11: =IF(J11<>"",$K11,"") -> France
A12: =IF(D12="Sous-total","X",IF(G12="","","X")) -> X | G12: THONON_Embarcadère CGN | H12: =IF(L12=0,"","X") | I12: =IF(M12=0,"","X") | J12: =IF(N12=0,"","X") -> X | K12: Frontière | L12: ='2020'!G12 -> 0 | M12: ='2021'!G12 -> 0 | N12: ='2022'!G12 -> 74 | O12: ='2020'!H12 -> 0 | P12: ='2021'!H12 -> 0 | Q12: ='2022'!H12 -> 30 | R12: =IF(L12="",0,IF(U12=0,0,U12/L12)) -> 0 | S12: =IF(M12="",0,IF(V12=0,0,V12/M12)) -> 0 | T12: =IF(N12="",0,IF(W12=0,0,W12/N12)) -> 0.2972973 | U12: ='2020'!J12 -> 0 | V12: ='2021'!J12 -> 0 | W12: ='2022'!J12 -> 22 | X12: =IF(L12=0,"",IF(AA12="","",AA12/L12)) | Y12: =IF(M12=0,"",IF(AB12="","",AB12/M12)) | Z12: =IF(N12=0,"",IF(AC12="","",AC12/N12)) -> 0.36486486 | AA12: ='2020'!L12 -> 0 | AB12: ='2021'!L12 -> 0 | AC12: ='2022'!L12 -> 27 | AD12: =IF(AA12=0,"",IF(AG12="-","",AG12/AA12)) | AE12: =IF(AB12=0,"",IF(AH12="-","",AH12/AB12)) | AF12: =IF(AC12=0,"",IF(AI12="-","",AI12/AC12)) -> 0.48148148 | AG12: ='2020'!N12 -> - | AH12: ='2021'!N12 -> - | AI12: ='2022'!N12 -> 13 | AJ12: - | AK12: - | AL12: - | AM12: - | AN12: - | AO12: - | AP12: - | AQ12: - | AY12: =IF(H12<>"",$K12,"") | AZ12: =IF(I12<>"",$K12,"") | BA12: =IF(J12<>"",$K12,"") -> Frontière
A13: =IF(D13="Sous-total","X",IF(G13="","","X")) -> X | G13: THONON_Entrée côté place de Crête | H13: =IF(L13=0,"","X") | I13: =IF(M13=0,"","X") | J13: =IF(N13=0,"","X") -> X | K13: France | L13: ='2020'!G13 -> 0 | M13: ='2021'!G13 -> 0 | N13: ='2022'!G13 -> 34 | O13: ='2020'!H13 -> 0 | P13: ='2021'!H13 -> 0 | Q13: ='2022'!H13 -> 34 | R13: =IF(L13="",0,IF(U13=0,0,U13/L13)) -> 0 | S13: =IF(M13="",0,IF(V13=0,0,V13/M13)) -> 0 | T13: =IF(N13="",0,IF(W13=0,0,W13/N13)) -> 0.17647059 | U13: ='2020'!J13 -> 0 | V13: ='2021'!J13 -> 0 | W13: ='2022'!J13 -> 6 | X13: =IF(L13=0,"",IF(AA13="","",AA13/L13)) | Y13: =IF(M13=0,"",IF(AB13="","",AB13/M13)) | Z13: =IF(N13=0,"",IF(AC13="","",AC13/N13)) -> 0.38235294 | AA13: ='2020'!L13 -> 0 | AB13: ='2021'!L13 -> 0 | AC13: ='2022'!L13 -> 13 | AD13: =IF(AA13=0,"",IF(AG13="-","",AG13/AA13)) | AE13: =IF(AB13=0,"",IF(AH13="-","",AH13/AB13)) | AF13: =IF(AC13=0,"",IF(AI13="-","",AI13/AC13)) -> 0.15384615 | AG13: ='2020'!N13 -> - | AH13: ='2021'!N13 -> - | AI13: ='2022'!N13 -> 2 | AJ13: - | AK13: - | AL13: - | AM13: - | AN13: - | AO13: - | AP13: - | AQ13: - | AY13: =IF(H13<>"",$K13,"") | AZ13: =IF(I13<>"",$K13,"") | BA13: =IF(J13<>"",$K13,"") -> France
A14: =IF(D14="Sous-total","X",IF(G14="","","X")) -> X | G14: THONON_Parvis de la gare | H14: =IF(L14=0,"","X") | I14: =IF(M14=0,"","X") | J14: =IF(N14=0,"","X") -> X | K14: France | L14: ='2020'!G14 -> 0 | M14: ='2021'!G14 -> 0 | N14: ='2022'!G14 -> 47 | O14: ='2020'!H14 -> 0 | P14: ='2021'!H14 -> 0 | Q14: ='2022'!H14 -> 47 | R14: =IF(L14="",0,IF(U14=0,0,U14/L14)) -> 0 | S14: =IF(M14="",0,IF(V14=0,0,V14/M14)) -> 0 | T14: =IF(N14="",0,IF(W14=0,0,W14/N14)) -> 0.063829787 | U14: ='2020'!J14 -> 0 | V14: ='2021'!J14 -> 0 | W14: ='2022'!J14 -> 3 | X14: =IF(L14=0,"",IF(AA14="","",AA14/L14)) | Y14: =IF(M14=0,"",IF(AB14="","",AB14/M14)) | Z14: =IF(N14=0,"",IF(AC14="","",AC14/N14)) -> 0.31914894 | AA14: ='2020'!L14 -> 0 | AB14: ='2021'!L14 -> 0 | AC14: ='2022'!L14 -> 15 | AD14: =IF(AA14=0,"",IF(AG14="-","",AG14/AA14)) | AE14: =IF(AB14=0,"",IF(AH14="-","",AH14/AB14)) | AF14: =IF(AC14=0,"",IF(AI14="-","",AI14/AC14)) -> 0.2 | AG14: ='2020'!N14 -> - | AH14: ='2021'!N14 -> - | AI14: ='2022'!N14 -> 3 | AJ14: - | AK14: - | AL14: - | AM14: - | AN14: - | AO14: - | AP14: - | AQ14: - | AY14: =IF(H14<>"",$K14,"") | AZ14: =IF(I14<>"",$K14,"") | BA14: =IF(J14<>"",$K14,"") -> France
A15: =IF(D15="Sous-total","X",IF(G15="","","X")) -> X | G15: THONON_Avenue d’Evian | H15: =IF(L15=0,"","X") | I15: =IF(M15=0,"","X") | J15: =IF(N15=0,"","X") -> X | K15: France | L15: ='2020'!G15 -> 0 | M15: ='2021'!G15 -> 0 | N15: ='2022'!G15 -> 92 | O15: ='2020'!H15 -> 0 | P15: ='2021'!H15 -> 0 | Q15: ='2022'!H15 -> 92 | R15: =IF(L15="",0,IF(U15=0,0,U15/L15)) -> 0 | S15: =IF(M15="",0,IF(V15=0,0,V15/M15)) -> 0 | T15: =IF(N15="",0,IF(W15=0,0,W15/N15)) -> 0.097826087 | U15: ='2020'!J15 -> 0 | V15: ='2021'!J15 -> 0 | W15: ='2022'!J15 -> 9 | X15: =IF(L15=0,"",IF(AA15="","",AA15/L15)) | Y15: =IF(M15=0,"",IF(AB15="","",AB15/M15)) | Z15: =IF(N15=0,"",IF(AC15="","",AC15/N15)) -> 0.45652174 | AA15: ='2020'!L15 -> 0 | AB15: ='2021'!L15 -> 0 | AC15: ='2022'!L15 -> 42 | AD15: =IF(AA15=0,"",IF(AG15="-","",AG15/AA15)) | AE15: =IF(AB15=0,"",IF(AH15="-","",AH15/AB15)) | AF15: =IF(AC15=0,"",IF(AI15="-","",AI15/AC15)) -> 0.14285714 | AG15: ='2020'!N15 -> - | AH15: ='2021'!N15 -> - | AI15: ='2022'!N15 -> 6 | AJ15: - | AK15: - | AL15: - | AM15: - | AN15: - | AO15: - | AP15: - | AQ15: - | AY15: =IF(H15<>"",$K15,"") | AZ15: =IF(I15<>"",$K15,"") | BA15: =IF(J15<>"",$K15,"") -> France
A16: =IF(D16="Sous-total","X",IF(G16="","","X")) -> X | G16: THONON_Carrefour Libération | H16: =IF(L16=0,"","X") | I16: =IF(M16=0,"","X") | J16: =IF(N16=0,"","X") -> X | K16: France | L16: ='2020'!G16 -> 0 | M16: ='2021'!G16 -> 0 | N16: ='2022'!G16 -> 77 | O16: ='2020'!H16 -> 0 | P16: ='2021'!H16 -> 0 | Q16: ='2022'!H16 -> 77 | R16: =IF(L16="",0,IF(U16=0,0,U16/L16)) -> 0 | S16: =IF(M16="",0,IF(V16=0,0,V16/M16)) -> 0 | T16: =IF(N16="",0,IF(W16=0,0,W16/N16)) -> 0.14285714 | U16: ='2020'!J16 -> 0 | V16: ='2021'!J16 -> 0 | W16: ='2022'!J16 -> 11 | X16: =IF(L16=0,"",IF(AA16="","",AA16/L16)) | Y16: =IF(M16=0,"",IF(AB16="","",AB16/M16)) | Z16: =IF(N16=0,"",IF(AC16="","",AC16/N16)) -> 0.4025974 | AA16: ='2020'!L16 -> 0 | AB16: ='2021'!L16 -> 0 | AC16: ='2022'!L16 -> 31 | AD16: =IF(AA16=0,"",IF(AG16="-","",AG16/AA16)) | AE16: =IF(AB16=0,"",IF(AH16="-","",AH16/AB16)) | AF16: =IF(AC16=0,"",IF(AI16="-","",AI16/AC16)) -> 0.16129032 | AG16: ='2020'!N16 -> - | AH16: ='2021'!N16 -> - | AI16: ='2022'!N16 -> 5 | AJ16: - | AK16: - | AL16: - | AM16: - | AN16: - | AO16: - | AP16: - | AQ16: - | AY16: =IF(H16<>"",$K16,"") | AZ16: =IF(I16<>"",$K16,"") | BA16: =IF(J16<>"",$K16,"") -> France
A17: =IF(D17="Sous-total","X",IF(G17="","","X")) -> X | G17: THONON_Collège Champagne | H17: =IF(L17=0,"","X") | I17: =IF(M17=0,"","X") | J17: =IF(N17=0,"","X") -> X | K17: France | L17: ='2020'!G17 -> 0 | M17: ='2021'!G17 -> 0 | N17: ='2022'!G17 -> 19 | O17: ='2020'!H17 -> 0 | P17: ='2021'!H17 -> 0 | Q17: ='2022'!H17 -> 19 | R17: =IF(L17="",0,IF(U17=0,0,U17/L17)) -> 0 | S17: =IF(M17="",0,IF(V17=0,0,V17/M17)) -> 0 | T17: =IF(N17="",0,IF(W17=0,0,W17/N17)) -> 0.21052632 | U17: ='2020'!J17 -> 0 | V17: ='2021'!J17 -> 0 | W17: ='2022'!J17 -> 4 | X17: =IF(L17=0,"",IF(AA17="","",AA17/L17)) | Y17: =IF(M17=0,"",IF(AB17="","",AB17/M17)) | Z17: =IF(N17=0,"",IF(AC17="","",AC17/N17)) -> 0.31578947 | AA17: ='2020'!L17 -> 0 | AB17: ='2021'!L17 -> 0 | AC17: ='2022'!L17 -> 6 | AD17: =IF(AA17=0,"",IF(AG17="-","",AG17/AA17)) | AE17: =IF(AB17=0,"",IF(AH17="-","",AH17/AB17)) | AF17: =IF(AC17=0,"",IF(AI17="-","",AI17/AC17)) -> 0.16666667 | AG17: ='2020'!N17 -> - | AH17: ='2021'!N17 -> - | AI17: ='2022'!N17 -> 1 | AJ17: - | AK17: - | AL17: - | AM17: - | AN17: - | AO17: - | AP17: - | AQ17: - | AY17: =IF(H17<>"",$K17,"") | AZ17: =IF(I17<>"",$K17,"") | BA17: =IF(J17<>"",$K17,"") -> France
A18: =IF(D18="Sous-total","X",IF(G18="","","X")) -> X | G18: THONON_Ecole Jule Ferry | H18: =IF(L18=0,"","X") | I18: =IF(M18=0,"","X") | J18: =IF(N18=0,"","X") -> X | K18: France | L18: ='2020'!G18 -> 0 | M18: ='2021'!G18 -> 0 | N18: ='2022'!G18 -> 24 | O18: ='2020'!H18 -> 0 | P18: ='2021'!H18 -> 0 | Q18: ='2022'!H18 -> 24 | R18: =IF(L18="",0,IF(U18=0,0,U18/L18)) -> 0 | S18: =IF(M18="",0,IF(V18=0,0,V18/M18)) -> 0 | T18: =IF(N18="",0,IF(W18=0,0,W18/N18)) -> 0.29166667 | U18: ='2020'!J18 -> 0 | V18: ='2021'!J18 -> 0 | W18: ='2022'!J18 -> 7 | X18: =IF(L18=0,"",IF(AA18="","",AA18/L18)) | Y18: =IF(M18=0,"",IF(AB18="","",AB18/M18)) | Z18: =IF(N18=0,"",IF(AC18="","",AC18/N18)) -> 0.54166667 | AA18: ='2020'!L18 -> 0 | AB18: ='2021'!L18 -> 0 | AC18: ='2022'!L18 -> 13 | AD18: =IF(AA18=0,"",IF(AG18="-","",AG18/AA18)) | AE18: =IF(AB18=0,"",IF(AH18="-","",AH18/AB18)) | AF18: =IF(AC18=0,"",IF(AI18="-","",AI18/AC18)) -> 0.46153846 | AG18: ='2020'!N18 -> - | AH18: ='2021'!N18 -> - | AI18: ='2022'!N18 -> 6 | AJ18: - | AK18: - | AL18: - | AM18: - | AN18: - | AO18: - | AP18: - | AQ18: - | AY18: =IF(H18<>"",$K18,"") | AZ18: =IF(I18<>"",$K18,"") | BA18: =IF(J18<>"",$K18,"") -> France
A19: =IF(D19="Sous-total","X",IF(G19="","","X")) -> X | G19: THONON_Rond point J. Ferry G Andrier Pl des Arts Bld du Canal | H19: =IF(L19=0,"","X") | I19: =IF(M19=0,"","X") | J19: =IF(N19=0,"","X") -> X | K19: France | L19: ='2020'!G19 -> 0 | M19: ='2021'!G19 -> 0 | N19: ='2022'!G19 -> 101 | O19: ='2020'!H19 -> 0 | P19: ='2021'!H19 -> 0 | Q19: ='2022'!H19 -> 101 | R19: =IF(L19="",0,IF(U19=0,0,U19/L19)) -> 0 | S19: =IF(M19="",0,IF(V19=0,0,V19/M19)) -> 0 | T19: =IF(N19="",0,IF(W19=0,0,W19/N19)) -> 0.14851485 | U19: ='2020'!J19 -> 0 | V19: ='2021'!J19 -> 0 | W19: ='2022'!J19 -> 15 | X19: =IF(L19=0,"",IF(AA19="","",AA19/L19)) | Y19: =IF(M19=0,"",IF(AB19="","",AB19/M19)) | Z19: =IF(N19=0,"",IF(AC19="","",AC19/N19)) -> 0.3960396 | AA19: ='2020'!L19 -> 0 | AB19: ='2021'!L19 -> 0 | AC19: ='2022'!L19 -> 40 | AD19: =IF(AA19=0,"",IF(AG19="-","",AG19/AA19)) | AE19: =IF(AB19=0,"",IF(AH19="-","",AH19/AB19)) | AF19: =IF(AC19=0,"",IF(AI19="-","",AI19/AC19)) -> 0.225 | AG19: ='2020'!N19 -> - | AH19: ='2021'!N19 -> - | AI19: ='2022'!N19 -> 9 | AJ19: - | AK19: - | AL19: - | AM19: - | AN19: - | AO19: - | AP19: - | AQ19: - | AY19: =IF(H19<>"",$K19,"") | AZ19: =IF(I19<>"",$K19,"") | BA19: =IF(J19<>"",$K19,"") -> France
... A22: =IF(D22="Sous-total","X",IF(G22="","","X")) -> X | G22: VEIGY_Douane | H22: =IF(L22=0,"","X") | I22: =IF(M22=0,"","X") | J22: =IF(N22=0,"","X") -> X | K22: Frontière | L22: ='2020'!G22 -> 0 | M22: ='2021'!G22 -> 0 | N22: ='2022'!G22 -> 68 | O22: ='2020'!H22 -> 0 | P22: ='2021'!H22 -> 0 | Q22: ='2022'!H22 -> 43 | R22: =IF(L22="",0,IF(U22=0,0,U22/L22)) -> 0 | S22: =IF(M22="",0,IF(V22=0,0,V22/M22)) -> 0 | T22: =IF(N22="",0,IF(W22=0,0,W22/N22)) -> 0.51470588 | U22: ='2020'!J22 -> 0 | V22: ='2021'!J22 -> 0 | W22: ='2022'!J22 -> 35 | X22: =IF(L22=0,"",IF(AA22="","",AA22/L22)) | Y22: =IF(M22=0,"",IF(AB22="","",AB22/M22)) | Z22: =IF(N22=0,"",IF(AC22="","",AC22/N22)) -> 0.44117647 | AA22: ='2020'!L22 -> 0 | AB22: ='2021'!L22 -> 0 | AC22: ='2022'!L22 -> 30 | AD22: =IF(AA22=0,"",IF(AG22="-","",AG22/AA22)) | AE22: =IF(AB22=0,"",IF(AH22="-","",AH22/AB22)) | AF22: =IF(AC22=0,"",IF(AI22="-","",AI22/AC22)) -> 0.53333333 | AG22: ='2020'!N22 -> - | AH22: ='2021'!N22 -> - | AI22: ='2022'!N22 -> 16 | AJ22: - | AK22: - | AL22: - | AM22: - | AN22: - | AO22: - | AP22: - | AQ22: - | AY22: =IF(H22<>"",$K22,"") | AZ22: =IF(I22<>"",$K22,"") | BA22: =IF(J22<>"",$K22,"") -> Frontière
A23: =IF(D23="Sous-total","X",IF(G23="","","X")) -> X | D23: Sous-total | L23: =SUM(L7:L22) -> 0 | M23: =SUM(M7:M22) -> 0 | N23: =SUM(N7:N22) -> 694 | O23: =SUM(O7:O22) -> 0 | P23: =SUM(P7:P22) -> 0 | Q23: =SUM(Q7:Q22) -> 611 | R23: =IF(L23="",0,IF(U23=0,0,U23/L23)) -> 0 | S23: =IF(M23="",0,IF(V23=0,0,V23/M23)) -> 0 | T23: =IF(N23="",0,IF(W23=0,0,W23/N23)) -> 0.24639769 | U23: =SUM(U7:U22) -> 0 | V23: =SUM(V7:V22) -> 0 | W23: =SUM(W7:W22) -> 171 | X23: =IF(L23=0,"",IF(AA23="","",AA23/L23)) | Y23: =IF(M23=0,"",IF(AB23="","",AB23/M23)) | Z23: =IF(N23=0,"",IF(AC23="","",AC23/N23)) -> 0.38472622 | AA23: =SUM(AA7:AA22) -> 0 | AB23: =SUM(AB7:AB22) -> 0 | AC23: =SUM(AC7:AC22) -> 267 | AD23: =IF(AA23=0,"",IF(AG23="-","",AG23/AA23)) | AE23: =IF(AB23=0,"",IF(AH23="-","",AH23/AB23)) | AF23: =IF(AC23=0,"",IF(AI23="-","",AI23/AC23)) -> 0.34831461 | AG23: =SUM(AG7:AG22) -> 0 | AH23: =SUM(AH7:AH22) -> 0 | AI23: =SUM(AI7:AI22) -> 93 | AY23: =IF(H23<>"",$K23,"") | AZ23: =IF(I23<>"",$K23,"") | BA23: =IF(J23<>"",$K23,"")
