Workbook

Sheet Index
C3: Eléments à renseigner par chaque association dans l'onglet "2022"
D5: Colonne | F5: Ce qu'il faut renseigner
D7: Toutes les cellules blanches ne sont pas à renseigner (formule de calcul ou NC)
D9: Eléments obligatoires >> cellules en vert dans l'onglet "2022"
D10: DONNEES GENERALES | E10: D | F10: nombre de bénévoles par poste de comptage
E11: E | F11: nom/localisation du poste de comptage
E12: F | F12: implantation : France / Suisse / Frontière
E13: G | F13: nombre total de cyclistes comptés sur toute la période
E14: H | F14: nombre de cyclistes comptés sur l'heure de pointe (7h30 - 8h30) uniquement
E15: I | F15: calcul automatique (du nombre de VAE dans le total)
E16: J | F16: nombre de VAE dans le total (référence à la colonne G)
E17: K | F17: calcul automatique (du nombre de femmes dans le total)
E18: L | F18: nombre de femmes dans le total (référence à la colonne G)
D20: Eléments obligatoires pour les postes frontières et carrefours proches frontière
D21: >> cellules en bleu dans l'onglet "2022"
D22: FRONTIERE | E22: S | F22: nombre total de cyclistes comptés sur toute la période - Direction Suisse
E23: T | F23: nombre de cyclistes comptés sur l'heure de pointe (7h30 - 8h30) uniquement - Direction Suisse
E24: U | F24: nombre total de cyclistes comptés sur toute la période - Direction France
E25: V | F25: nombre de cyclistes comptés sur l'heure de pointe (7h30 - 8h30) uniquement - Direction France
D27: Eléments facultatifs >> cellules en rose dans l'onglet "2022"
D28: AUTRES DONNEES | E28: M | F28: calcul automatique (du nombre total de VAE chez les femmes)
E29: N | F29: nombre total de VAE chez les femmes (valeur spécifique à relever)
E30: O | F30: nombre total de personnes comptées sur toute la période en "autre mode" (trottinette, gyropode…)
E31: P | F31: nombre total de personnes comptées en HPM (7h30 - 8h30) en "autre mode" (trottinette, gyropode…)
E32: Q | F32: nombre total de piétons comptés sur toute la période
E33: R | F33: nombre total de piétons comptés en HPM (7h30 - 8h30)

Sheet 2022
B2: Association(s) | C2: Arrière-pays | D2: Nombre de bénévoles | E2: Postes de comptage | F2: France / Suisse / Frontière | G2: Nombre de vélos | I2: % VAE dans le total | J2: NB VAE dans le total | K2: % femmes dans le total | L2: NB de femmes dans le total | M2: % de VAE chez les femmes | N2: NB de VAE chez les femmes | O2: Autres modes | Q2: Piétons | S2: > Suisse | U2: > France
G4: total | H4: HP | O4: total | P4: HP | Q4: total | R4: HP | S4: total | T4: HP | U4: total | V4: HP
B5: Université Populaire de Cluses | C5: OUI | D5: 2 | E5: CLUSES_Passerelle de Messy | F5: France | I5: =J5/G5 -> #DIV/0! | K5: =L5/G5 -> #DIV/0! | M5: =IF(N5="-","-",N5/L5) -> #DIV/0! | S5: - | T5: - | U5: - | V5: -
B6: L'Abeille (Contamine) | C6: OUI | D6: 2 | E6: BONNE_Loëx (sous voie rapide) | F6: France | I6: =J6/G6 -> #DIV/0! | K6: =L6/G6 -> #DIV/0! | M6: =IF(N6="-","-",N6/L6) -> #DIV/0! | S6: - | T6: - | U6: - | V6: -
B7: Association Mobilité Douce pour le Chablais (Chablais) | C7: OUI | D7: 18 | E7: ='Synthèse AMDC'!A3 -> Allinges – Rond point des Fleysets | F7: France | G7: ='Synthèse AMDC'!B3+'Synthèse AMDC'!C3+'Synthèse AMDC'!E3+'Synthèse AMDC'!F3 -> 23 | H7: =G7 -> 23 | I7: =J7/G7 -> 0.47826087 | J7: ='Synthèse AMDC'!B3+'Synthèse AMDC'!E3 -> 11 | K7: =L7/G7 -> 0.47826087 | L7: ='Synthèse AMDC'!E3+'Synthèse AMDC'!F3 -> 11 | M7: =IF(N7="-","-",N7/L7) -> 0.90909091 | N7: ='Synthèse AMDC'!E3 -> 10 | O7: ='Synthèse AMDC'!D3+'Synthèse AMDC'!G3 -> 0
E8: ='Synthèse AMDC'!A4 -> Bons en Chablais – Gare | G8: ='Synthèse AMDC'!B4+'Synthèse AMDC'!C4+'Synthèse AMDC'!E4+'Synthèse AMDC'!F4 -> 25 | H8: =G8-12 -> 13 | I8: =J8/G8 -> 0.4 | J8: ='Synthèse AMDC'!B4+'Synthèse AMDC'!E4 -> 10 | K8: =L8/G8 -> 0.44 | L8: ='Synthèse AMDC'!E4+'Synthèse AMDC'!F4 -> 11 | M8: =IF(N8="-","-",N8/L8) -> 0.63636364 | N8: ='Synthèse AMDC'!E4 -> 7 | O8: ='Synthèse AMDC'!D4+'Synthèse AMDC'!G4 -> 22
E9: ='Synthèse AMDC'!A5 -> Douvaine – Mairie | G9: ='Synthèse AMDC'!B5+'Synthèse AMDC'!C5+'Synthèse AMDC'!E5+'Synthèse AMDC'!F5 -> 20 | H9: =G9 -> 20 | I9: =J9/G9 -> 0.45 | J9: ='Synthèse AMDC'!B5+'Synthèse AMDC'!E5 -> 9 | K9: =L9/G9 -> 0.4 | L9: ='Synthèse AMDC'!E5+'Synthèse AMDC'!F5 -> 8 | M9: =IF(N9="-","-",N9/L9) -> 0.375 | N9: ='Synthèse AMDC'!E5 -> 3 | O9: ='Synthèse AMDC'!D5+'Synthèse AMDC'!G5 -> 6
E10: ='Synthèse AMDC'!A6 -> Evian – Gare | G10: ='Synthèse AMDC'!B6+'Synthèse AMDC'!C6+'Synthèse AMDC'!E6+'Synthèse AMDC'!F6 -> 13 | H10: =G10-1 -> 12 | I10: =J10/G10 -> 0.15384615 | J10: ='Synthèse AMDC'!B6+'Synthèse AMDC'!E6 -> 2 | K10: =L10/G10 -> 0.30769231 | L10: ='Synthèse AMDC'!E6+'Synthèse AMDC'!F6 -> 4 | M10: =IF(N10="-","-",N10/L10) -> 0.5 | N10: ='Synthèse AMDC'!E6 -> 2 | O10: ='Synthèse AMDC'!D6+'Synthèse AMDC'!G6 -> 7
E11: ='Synthèse AMDC'!A7 -> Perrignier – Gare | F11: France | G11: ='Synthèse AMDC'!B7+'Synthèse AMDC'!C7+'Synthèse AMDC'!E7+'Synthèse AMDC'!F7 -> 7 | H11: =G11-1 -> 6 | I11: =J11/G11 -> 0.28571429 | J11: ='Synthèse AMDC'!B7+'Synthèse AMDC'!E7 -> 2 | K11: =L11/G11 -> 0 | L11: ='Synthèse AMDC'!E7+'Synthèse AMDC'!F7 -> 0 | M11: =IF(N11="-","-",N11/L11) -> #DIV/0! | N11: ='Synthèse AMDC'!E7 -> 0 | O11: ='Synthèse AMDC'!D7+'Synthèse AMDC'!G7 -> 6
E12: ='Synthèse AMDC'!A8 -> Thonon - Embarcadère CGN | F12: France | G12: ='Synthèse AMDC'!B8+'Synthèse AMDC'!C8+'Synthèse AMDC'!E8+'Synthèse AMDC'!F8 -> 74 | H12: =G12-44 -> 30 | I12: =J12/G12 -> 0.2972973 | J12: ='Synthèse AMDC'!B8+'Synthèse AMDC'!E8 -> 22 | K12: =L12/G12 -> 0.36486486 | L12: ='Synthèse AMDC'!E8+'Synthèse AMDC'!F8 -> 27 | M12: =IF(N12="-","-",N12/L12) -> 0.48148148 | N12: ='Synthèse AMDC'!E8 -> 13 | O12: ='Synthèse AMDC'!D8+'Synthèse AMDC'!G8 -> 101 | S12: 74 | T12: 30 | U12: 0 | V12: 0
E13: ='Synthèse AMDC'!A9 -> Thonon - Entrée côté place de Crête | F13: France | G13: ='Synthèse AMDC'!B9+'Synthèse AMDC'!C9+'Synthèse AMDC'!E9+'Synthèse AMDC'!F9 -> 34 | H13: =G13 -> 34 | I13: =J13/G13 -> 0.17647059 | J13: ='Synthèse AMDC'!B9+'Synthèse AMDC'!E9 -> 6 | K13: =L13/G13 -> 0.38235294 | L13: ='Synthèse AMDC'!E9+'Synthèse AMDC'!F9 -> 13 | M13: =IF(N13="-","-",N13/L13) -> 0.15384615 | N13: ='Synthèse AMDC'!E9 -> 2 | O13: ='Synthèse AMDC'!D9+'Synthèse AMDC'!G9 -> 12
E14: ='Synthèse AMDC'!A10 -> Thonon - Parvis de la gare | F14: France | G14: ='Synthèse AMDC'!B10+'Synthèse AMDC'!C10+'Synthèse AMDC'!E10+'Synthèse AMDC'!F10 -> 47 | H14: =G14 -> 47 | I14: =J14/G14 -> 0.063829787 | J14: ='Synthèse AMDC'!B10+'Synthèse AMDC'!E10 -> 3 | K14: =L14/G14 -> 0.31914894 | L14: ='Synthèse AMDC'!E10+'Synthèse AMDC'!F10 -> 15 | M14: =IF(N14="-","-",N14/L14) -> 0.2 | N14: ='Synthèse AMDC'!E10 -> 3 | O14: ='Synthèse AMDC'!D10+'Synthèse AMDC'!G10 -> 37
E15: ='Synthèse AMDC'!A11 -> Thonon – Avenue d’Evian | F15: France | G15: ='Synthèse AMDC'!B11+'Synthèse AMDC'!C11+'Synthèse AMDC'!E11+'Synthèse AMDC'!F11 -> 92 | H15: =G15 -> 92 | I15: =J15/G15 -> 0.097826087 | J15: ='Synthèse AMDC'!B11+'Synthèse AMDC'!E11 -> 9 | K15: =L15/G15 -> 0.45652174 | L15: ='Synthèse AMDC'!E11+'Synthèse AMDC'!F11 -> 42 | M15: =IF(N15="-","-",N15/L15) -> 0.14285714 | N15: ='Synthèse AMDC'!E11 -> 6 | O15: ='Synthèse AMDC'!D11+'Synthèse AMDC'!G11 -> 19
E16: ='Synthèse AMDC'!A12 -> Thonon – Carrefour Libération | F16: France | G16: ='Synthèse AMDC'!B12+'Synthèse AMDC'!C12+'Synthèse AMDC'!E12+'Synthèse AMDC'!F12 -> 77 | H16: =G16 -> 77 | I16: =J16/G16 -> 0.14285714 | J16: ='Synthèse AMDC'!B12+'Synthèse AMDC'!E12 -> 11 | K16: =L16/G16 -> 0.4025974 | L16: ='Synthèse AMDC'!E12+'Synthèse AMDC'!F12 -> 31 | M16: =IF(N16="-","-",N16/L16) -> 0.16129032 | N16: ='Synthèse AMDC'!E12 -> 5 | O16: ='Synthèse AMDC'!D12+'Synthèse AMDC'!G12 -> 20
E17: ='Synthèse AMDC'!A13 -> Thonon – Collège Champagne | F17: France | G17: ='Synthèse AMDC'!B13+'Synthèse AMDC'!C13+'Synthèse AMDC'!E13+'Synthèse AMDC'!F13 -> 19 | H17: =G17 -> 19 | I17: =J17/G17 -> 0.21052632 | J17: ='Synthèse AMDC'!B13+'Synthèse AMDC'!E13 -> 4 | K17: =L17/G17 -> 0.31578947 | L17: ='Synthèse AMDC'!E13+'Synthèse AMDC'!F13 -> 6 | M17: =IF(N17="-","-",N17/L17) -> 0.16666667 | N17: ='Synthèse AMDC'!E13 -> 1 | O17: ='Synthèse AMDC'!D13+'Synthèse AMDC'!G13 -> 3
E18: ='Synthèse AMDC'!A14 -> Thonon – Ecole Jule Ferry | G18: ='Synthèse AMDC'!B14+'Synthèse AMDC'!C14+'Synthèse AMDC'!E14+'Synthèse AMDC'!F14 -> 24 | H18: =G18 -> 24 | I18: =J18/G18 -> 0.29166667 | J18: ='Synthèse AMDC'!B14+'Synthèse AMDC'!E14 -> 7 | K18: =L18/G18 -> 0.54166667 | L18: ='Synthèse AMDC'!E14+'Synthèse AMDC'!F14 -> 13 | M18: =IF(N18="-","-",N18/L18) -> 0.46153846 | N18: ='Synthèse AMDC'!E14 -> 6 | O18: ='Synthèse AMDC'!D14+'Synthèse AMDC'!G14 -> 11
E19: ='Synthèse AMDC'!A15 -> Thonon – Rond point J. Ferry G Andrier Pl des Arts Bld du Canal | G19: ='Synthèse AMDC'!B15+'Synthèse AMDC'!C15+'Synthèse AMDC'!E15+'Synthèse AMDC'!F15 -> 101 | H19: =G19 -> 101 | I19: =J19/G19 -> 0.14851485 | J19: ='Synthèse AMDC'!B15+'Synthèse AMDC'!E15 -> 15 | K19: =L19/G19 -> 0.3960396 | L19: ='Synthèse AMDC'!E15+'Synthèse AMDC'!F15 -> 40 | M19: =IF(N19="-","-",N19/L19) -> 0.225 | N19: ='Synthèse AMDC'!E15 -> 9 | O19: ='Synthèse AMDC'!D15+'Synthèse AMDC'!G15 -> 34
E20: ='Synthèse AMDC'!A16 -> Thonon / Anthy – Pont de Marclaz | G20: ='Synthèse AMDC'!B16+'Synthèse AMDC'!C16+'Synthèse AMDC'!E16+'Synthèse AMDC'!F16 -> 25 | H20: =G20 -> 25 | I20: =J20/G20 -> 0.28 | J20: ='Synthèse AMDC'!B16+'Synthèse AMDC'!E16 -> 7 | K20: =L20/G20 -> 0.24 | L20: ='Synthèse AMDC'!E16+'Synthèse AMDC'!F16 -> 6 | M20: =IF(N20="-","-",N20/L20) -> 0.66666667 | N20: ='Synthèse AMDC'!E16 -> 4 | O20: ='Synthèse AMDC'!D16+'Synthèse AMDC'!G16 -> 4
E21: ='Synthèse AMDC'!A17 -> Thonon / Marin - Pont de Dranse | G21: ='Synthèse AMDC'!B17+'Synthèse AMDC'!C17+'Synthèse AMDC'!E17+'Synthèse AMDC'!F17 -> 45 | H21: =G21 -> 45 | I21: =J21/G21 -> 0.4 | J21: ='Synthèse AMDC'!B17+'Synthèse AMDC'!E17 -> 18 | K21: =L21/G21 -> 0.22222222 | L21: ='Synthèse AMDC'!E17+'Synthèse AMDC'!F17 -> 10 | M21: =IF(N21="-","-",N21/L21) -> 0.6 | N21: ='Synthèse AMDC'!E17 -> 6 | O21: ='Synthèse AMDC'!D17+'Synthèse AMDC'!G17 -> 4
E22: ='Synthèse AMDC'!A18 -> Veigy – Douane | F22: France | G22: ='Synthèse AMDC'!B18+'Synthèse AMDC'!C18+'Synthèse AMDC'!E18+'Synthèse AMDC'!F18 -> 68 | H22: =G22-25 -> 43 | I22: =J22/G22 -> 0.51470588 | J22: ='Synthèse AMDC'!B18+'Synthèse AMDC'!E18 -> 35 | K22: =L22/G22 -> 0.44117647 | L22: ='Synthèse AMDC'!E18+'Synthèse AMDC'!F18 -> 30 | M22: =IF(N22="-","-",N22/L22) -> 0.53333333 | N22: ='Synthèse AMDC'!E18 -> 16 | O22: ='Synthèse AMDC'!D18+'Synthèse AMDC'!G18 -> 1 | Q22: ='Synthèse AMDC'!J18 -> 16 | S22: 61 | T22: 38 | U22: 7 | V22: 5
D23: Sous-total | G23: =SUM(G7:G22) -> 694 | H23: =SUM(H7:H22) -> 611 | I23: =J23/G23 -> 0.24639769 | J23: =SUM(J7:J22) -> 171 | K23: =L23/G23 -> 0.38472622 | L23: =SUM(L7:L22) -> 267 | M23: =N23/L23 -> 0.34831461 | N23: =SUM(N7:N22) -> 93 | O23: =SUM(O7:O22) -> 287 | P23: =SUM(P7:P22) -> 0 | Q23: =SUM(Q7:Q22) -> 16 | R23: =SUM(R7:R22) -> 0 | S23: =SUM(S7:S22) -> 135 | T23: =SUM(T7:T22) -> 68 | U23: =SUM(U7:U22) -> 7 | V23: =SUM(V7:V22) -> 5
B24: NatEnv (Nature Environnement en Pays rochois) Fabrique à Biclou Pays rochois en Transition | C24: OUI | D24: 9 | E24: LA ROCHE_Carrefour Biocoop | F24: France | I24: =J24/G24 -> #DIV/0! | K24: =L24/G24 -> #DIV/0! | M24: =IF(N24="-","-",N24/L24) -> #DIV/0! | S24: - | T24: - | U24: - | V24: -
E25: LA ROCHE_Giratoire La Poste | F25: France | I25: =J25/G25 -> #DIV/0! | K25: =L25/G25 -> #DIV/0! | M25: =IF(N25="-","-",N25/L25) -> #DIV/0! | S25: - | T25: - | U25: - | V25: -
E26: LA ROCHE_Giratoire ENILV | F26: France | I26: =J26/G26 -> #DIV/0! | K26: =L26/G26 -> #DIV/0! | M26: =IF(N26="-","-",N26/L26) -> #DIV/0! | S26: - | T26: - | U26: - | V26: -
E27: LA ROCHE_Gare Passage à niveau (new 2021) | F27: France | I27: =J27/G27 -> #DIV/0! | K27: =L27/G27 -> #DIV/0! | M27: =IF(N27="-","-",N27/L27) -> #DIV/0! | S27: - | T27: - | U27: - | V27: -
E28: ARENTHON_La Papeterie | F28: France | I28: =J28/G28 -> #DIV/0! | K28: =L28/G28 -> #DIV/0! | M28: =IF(N28="-","-",N28/L28) -> #DIV/0! | S28: - | T28: - | U28: - | V28: -
E29: ST-PIERRE_Franchissement Borne-Dessy | F29: France | I29: =J29/G29 -> #DIV/0! | K29: =L29/G29 -> #DIV/0! | M29: =IF(N29="-","-",N29/L29) -> #DIV/0! | S29: - | T29: - | U29: - | V29: -
E30: BONNEVILLE_Franchissement Borne-Tucinge | F30: France | I30: =J30/G30 -> #DIV/0! | K30: =L30/G30 -> #DIV/0! | M30: =IF(N30="-","-",N30/L30) -> #DIV/0! | S30: - | T30: - | U30: - | V30: -
E31: ST-PIERRE_Pont principal sur le Borne | F31: France | I31: =J31/G31 -> #DIV/0! | K31: =L31/G31 -> #DIV/0! | M31: =IF(N31="-","-",N31/L31) -> #DIV/0! | S31: - | T31: - | U31: - | V31: -
I32: =J32/G32 -> #DIV/0! | K32: =L32/G32 -> #DIV/0! | M32: =IF(N32="-","-",N32/L32) -> #DIV/0! | S32: - | T32: - | U32: - | V32: -
I33: =J33/G33 -> #DIV/0! | K33: =L33/G33 -> #DIV/0! | M33: =IF(N33="-","-",N33/L33) -> #DIV/0! | S33: - | T33: - | U33: - | V33: -
E34: AMANCY_Giratoire Coriandre | F34: France | I34: =J34/G34 -> #DIV/0! | K34: =L34/G34 -> #DIV/0! | M34: =IF(N34="-","-",N34/L34) -> #DIV/0! | S34: - | T34: - | U34: - | V34: -
D35: Sous-total | G35: =SUM(G24:G34) -> 0 | H35: =SUM(H24:H34) -> 0 | I35: =J35/G35 -> #DIV/0! | J35: =SUM(J24:J34) -> 0 | K35: =L35/G35 -> #DIV/0! | L35: =SUM(L24:L34) -> 0 | M35: =N35/L35 -> #DIV/0! | N35: =SUM(N24:N34) -> 0 | O35: =SUM(O24:O34) -> 0 | P35: =SUM(P24:P34) -> 0 | Q35: =SUM(Q24:Q34) -> 0 | R35: =SUM(R24:R34) -> 0 | S35: =SUM(S24:S34) -> 0 | T35: =SUM(T24:T34) -> 0 | U35: =SUM(U24:U34) -> 0 | V35: =SUM(V24:V34) -> 0
B36: AERE (Association Environnement Reignier-Esery) | C36: OUI | D36: 9 | E36: ETREMBIERES_Giratoire ex PN93 | F36: France | I36: =J36/G36 -> #DIV/0! | K36: =L36/G36 -> #DIV/0! | M36: =IF(N36="-","-",N36/L36) -> #DIV/0! | S36: - | T36: - | U36: - | V36: -
E37: ETREMBIERES_Carrefour sous Château | F37: France | I37: =J37/G37 -> #DIV/0! | K37: =L37/G37 -> #DIV/0! | M37: =IF(N37="-","-",N37/L37) -> #DIV/0! | S37: - | T37: - | U37: - | V37: -
E38: SCIENTRIER_Carrefour Tour de Bellecombe | F38: France | I38: =J38/G38 -> #DIV/0! | K38: =L38/G38 -> #DIV/0! | M38: =IF(N38="-","-",N38/L38) -> #DIV/0! | S38: - | T38: - | U38: - | V38: -
E39: REIGNIER_Giratoire église | F39: France | I39: =J39/G39 -> #DIV/0! | K39: =L39/G39 -> #DIV/0! | M39: =IF(N39="-","-",N39/L39) -> #DIV/0! | S39: - | T39: - | U39: - | V39: -
E40: REIGNIER_Giratoire Foron | F40: France | I40: =J40/G40 -> #DIV/0! | K40: =L40/G40 -> #DIV/0! | M40: =IF(N40="-","-",N40/L40) -> #DIV/0! | S40: - | T40: - | U40: - | V40: -
E41: REIGNIER_Giratoire La Forge | F41: France | I41: =J41/G41 -> #DIV/0! | K41: =L41/G41 -> #DIV/0! | M41: =IF(N41="-","-",N41/L41) -> #DIV/0! | S41: - | T41: - | U41: - | V41: -
E42: PERS-JUSSY_Giratoire Casino | F42: France | I42: =J42/G42 -> #DIV/0! | K42: =L42/G42 -> #DIV/0! | M42: =IF(N42="-","-",N42/L42) -> #DIV/0! | S42: - | T42: - | U42: - | V42: -
...

Sheet Synthèse AMDC
B1: Données
A2: Point de comptage | B2: Somme - Homme / VAE | C2: Somme - Homme / Vélo | D2: Somme - Homme / Trottinette, skate, roller | E2: Somme - Femme / VAE | F2: Somme - Femme / Vélo | G2: Somme - Femme / Trottinette, skate, roller | H2: Somme - Enfant / Trottinette, skate, roller | I2: Somme - Enfant / Vélo | J2: Somme - Piéton
A3: Allinges – Rond point des Fleysets | B3: 1 | C3: 11 | D3: 0 | E3: 10 | F3: 1 | G3: 0 | H3: 0 | I3: 0
A4: Bons en Chablais – Gare | B4: 3 | C4: 11 | D4: 19 | E4: 7 | F4: 4 | G4: 3 | H4: 7 | I4: 4
A5: Douvaine – Mairie | B5: 6 | C5: 6 | D5: 3 | E5: 3 | F5: 5 | G5: 3 | H5: 18 | I5: 10
A6: Evian – Gare | B6: 0 | C6: 9 | D6: 4 | E6: 2 | F6: 2 | G6: 3 | H6: 0 | I6: 0
A7: Perrignier – Gare | B7: 2 | C7: 5 | D7: 2 | E7: 0 | F7: 0 | G7: 4 | H7: 1 | I7: 1
A8: Thonon - Embarcadère CGN | B8: 9 | C8: 38 | D8: 52 | E8: 13 | F8: 14 | G8: 49
A9: Thonon - Entrée côté place de Crête | B9: 4 | C9: 17 | D9: 7 | E9: 2 | F9: 11 | G9: 5 | H9: 4 | I9: 4
A10: Thonon - Parvis de la gare | B10: 0 | C10: 32 | D10: 24 | E10: 3 | F10: 12 | G10: 13 | H10: 15 | I10: 4
A11: Thonon – Avenue d’Evian | B11: 3 | C11: 47 | D11: 4 | E11: 6 | F11: 36 | G11: 15 | H11: 40 | I11: 2
A12: Thonon – Carrefour Libération | B12: 6 | C12: 40 | D12: 14 | E12: 5 | F12: 26 | G12: 6 | H12: 11 | I12: 7
A13: Thonon – Collège Champagne | B13: 3 | C13: 10 | D13: 1 | E13: 1 | F13: 5 | G13: 2 | H13: 27 | I13: 6
A14: Thonon – Ecole Jule Ferry | B14: 1 | C14: 10 | D14: 5 | E14: 6 | F14: 7 | G14: 6 | H14: 16 | I14: 5
A15: Thonon – Rond point J. Ferry G Andrier Pl des Arts Bld du Canal | B15: 6 | C15: 55 | D15: 15 | E15: 9 | F15: 31 | G15: 19 | H15: 11 | I15: 4
A16: Thonon / Anthy – Pont de Marclaz | B16: 3 | C16: 16 | D16: 4 | E16: 4 | F16: 2 | G16: 0 | H16: 0 | I16: 0
A17: Thonon / Marin - Pont de Dranse | B17: 12 | C17: 23 | D17: 1 | E17: 6 | F17: 4 | G17: 3 | H17: 0 | I17: 0
A18: Veigy – Douane | B18: 19 | C18: 19 | D18: 1 | E18: 16 | F18: 14 | G18: 0 | H18: 0 | I18: 0 | J18: 16
A19: Total Résultat | B19: 78 | C19: 349 | D19: 156 | E19: 93 | F19: 174 | G19: 131 | H19: 150 | I19: 47 | J19: 16
A23: Synthèse CICLABLE
B24: Données
A25: Point de comptage | B25: Somme - VAE | C25: Somme - Vélo | D25: Somme - Homme | E25: Somme - Femme
A26: Allinges – Rond point des Fleysets | B26: 11 | C26: 12 | D26: 12 | E26: 11
A27: Bons en Chablais – Gare | B27: 10 | C27: 15 | D27: 14 | E27: 11
A28: Douvaine – Mairie | B28: 9 | C28: 11 | D28: 12 | E28: 8
A29: Evian – Gare | B29: 2 | C29: 11 | D29: 9 | E29: 4
A30: Perrignier – Gare | B30: 2 | C30: 5 | D30: 7 | E30: 0
A31: Thonon - Embarcadère CGN | B31: 22 | C31: 52 | D31: 47 | E31: 27
A32: Thonon - Entrée côté place de Crête | B32: 6 | C32: 28 | D32: 21 | E32: 13
A33: Thonon - Parvis de la gare | B33: 3 | C33: 44 | D33: 32 | E33: 15
A34: Thonon – Avenue d’Evian | B34: 9 | C34: 83 | D34: 50 | E34: 42
A35: Thonon – Carrefour Libération | B35: 11 | C35: 66 | D35: 46 | E35: 31
A36: Thonon – Collège Champagne | B36: 4 | C36: 15 | D36: 13 | E36: 6
A37: Thonon – Ecole Jule Ferry | B37: 7 | C37: 17 | D37: 11 | E37: 13
... A42: Total Résultat | B42: 171 | C42: 523 | D42: 427 | E42: 267
