Workbook

Sheet Index
C3: Eléments à renseigner par chaque association dans l'onglet "2021"
D5: Colonne | F5: Ce qu'il faut renseigner
D7: Toutes les cellules blanches ne sont pas à renseigner (formule de calcul ou NC)
D9: Eléments obligatoires >> cellules en vert dans l'onglet "2021"
D10: DONNEES GENERALES | E10: D | F10: nombre de bénévoles par poste de comptage
E11: E | F11: nom/localisation du poste de comptage
E12: F | F12: implantation : France / Suisse / Frontière
E13: G | F13: nombre total de cyclistes comptés sur toute la période
E14: H | F14: nombre de cyclistes comptés sur l'heure de pointe (7h30 - 8h30) uniquement
E15: I | F15: calcul automatique (du nombre de VAE dans le total)
E16: J | F16: nombre de VAE dans le total (référence à la colonne G)
E17: K | F17: calcul automatique (du nombre de femmes dans le total)
E18: L | F18: nombre de femmes dans le total (référence à la colonne G)
D20: Eléments obligatoires pour les postes frontières et carrefours proches frontière
D21: >> cellules en vert dans l'onglet "2021"
D22: FRONTIERE | E22: S | F22: nombre total de cyclistes comptés sur toute la période - Direction Suisse
E23: T | F23: nombre de cyclistes comptés sur l'heure de pointe (7h30 - 8h30) uniquement - Direction Suisse
E24: U | F24: nombre total de cyclistes comptés sur toute la période - Direction France
E25: V | F25: nombre de cyclistes comptés sur l'heure de pointe (7h30 - 8h30) uniquement - Direction France
D27: Eléments facultatifs >> cellules en rose dans l'onglet "2021"
D28: AUTRES DONNEES | E28: M | F28: calcul automatique (du nombre total de VAE chez les femmes)
E29: N | F29: nombre total de VAE chez les femmes (valeur spécifique à relever)
E30: O | F30: nombre total de personnes comptées sur toute la période en "autre mode" (trottinette, gyropode…)
E31: P | F31: nombre total de personnes comptées en HPM (7h30 - 8h30) en "autre mode" (trottinette, gyropode…)
E32: Q | F32: nombre total de piétons comptés sur toute la période
E33: R | F33: nombre total de piétons comptés en HPM (7h30 - 8h30)

Sheet 2020
B2: Association(s) | C2: Arrière-pays | D2: Nombre de bénévoles | E2: Postes de comptage | F2: France / Suisse / Frontière | G2: Nombre de vélos | I2: % VAE dans le total | J2: NB VAE dans le total | K2: % femmes dans le total | L2: NB de femmes dans le total | M2: % de VAE chez les femmes | N2: NB de VAE chez les femmes | O2: Autres modes | Q2: Piétons | S2: > Suisse | U2: > France
G4: total | H4: HP | O4: total | P4: HP | Q4: total | R4: HP | S4: total | T4: HP | U4: total | V4: HP
B5: UP Cluses | C5: OUI | D5: 2 | E5: CLUSES_Passerelle de Messy | F5: France | G5: =27+11+2+15+8 -> 63 | H5: 29 | I5: =2/G5 -> 0.031746032 | J5: =I5*G5 -> 2 | K5: =(2+15)/G5 -> 0.26984127 | L5: =K5*G5 -> 17 | M5: =2/17 -> 0.11764706 | N5: =IF(M5="-","-",M5*L5) -> 2
B6: NatEnv & Fabrique à Biclou | C6: OUI | D6: 8 | E6: LA ROCHE_Carrefour Biocoop | F6: France | G6: 31 | H6: 23 | I6: 0.32258065 | J6: =I6*G6 -> 10 | K6: 0.32258065 | L6: =K6*G6 -> 10 | M6: - | N6: =IF(M6="-","-",M6*L6) -> -
E7: LA ROCHE_Giratoire La Poste | F7: France | G7: 25 | H7: 13 | I7: 0.48 | J7: =I7*G7 -> 12 | K7: 0.36 | L7: =K7*G7 -> 9 | M7: - | N7: =IF(M7="-","-",M7*L7) -> -
E8: LA ROCHE_Giratoire ENILV | F8: France | G8: 18 | H8: 10 | I8: 0.5 | J8: =I8*G8 -> 9 | K8: 0.16666667 | L8: =K8*G8 -> 3 | M8: - | N8: =IF(M8="-","-",M8*L8) -> -
E10: ARENTHON_La Papeterie | F10: France | G10: 14 | H10: 9 | I10: 0.071428571 | J10: =I10*G10 -> 1 | K10: 0.071428571 | L10: =K10*G10 -> 1 | M10: - | N10: =IF(M10="-","-",M10*L10) -> -
E11: ST-PIERRE_Franchissement Borne-Dessy | F11: France | G11: 24 | H11: 16 | I11: 0.041666667 | J11: =I11*G11 -> 1 | K11: 0.20833333 | L11: =K11*G11 -> 5 | M11: - | N11: =IF(M11="-","-",M11*L11) -> -
E12: BONNEVILLE_Franchissement Borne-Tucinge | F12: France | G12: 29 | H12: 21 | I12: 0 | J12: =I12*G12 -> 0 | K12: 0.4137931 | L12: =K12*G12 -> 12 | M12: - | N12: =IF(M12="-","-",M12*L12) -> -
E13: ST-PIERRE_Pont principal sur le Borne | F13: France | G13: 27 | H13: 17 | I13: 0.25925926 | J13: =I13*G13 -> 7 | K13: 0.48148148 | L13: =K13*G13 -> 13 | M13: - | N13: =IF(M13="-","-",M13*L13) -> -
E14: AMANCY_Giratoire Coriandre | F14: France | G14: 4 | H14: 2 | I14: 0.5 | J14: =I14*G14 -> 2 | K14: 0 | L14: =K14*G14 -> 0 | M14: - | N14: =IF(M14="-","-",M14*L14) -> -
D15: Sous-total | G15: =SUM(G6:G14) -> 172 | H15: =SUM(H6:H14) -> 111 | I15: =J15/G15 -> 0.24418605 | J15: =SUM(J6:J14) -> 42 | K15: =L15/G15 -> 0.30813953 | L15: =SUM(L6:L14) -> 53 | M15: =N15/L15 -> 0 | N15: =SUM(N6:N14) -> 0
B16: AERE | C16: OUI | D16: 9 | E16: ETREMBIERES_Giratoire ex PN93 | F16: France | G16: 37 | H16: 23 | I16: 0.38 | J16: =I16*G16 -> 14.06 | K16: 0.16 | L16: =K16*G16 -> 5.92 | M16: 1 | N16: =IF(M16="-","-",M16*L16) -> 5.92
E17: ETREMBIERES_Carrefour sous Château | F17: France | G17: 33 | H17: 15 | I17: 0.3 | J17: =I17*G17 -> 9.9 | K17: 0.09 | L17: =K17*G17 -> 2.97 | M17: 1 | N17: =IF(M17="-","-",M17*L17) -> 2.97
E18: SCIENTRIER_Carrefour Tour de Bellecombe | F18: France | G18: 6 | H18: 5 | I18: 0 | J18: =I18*G18 -> 0 | K18: 0 | L18: =K18*G18 -> 0 | M18: - | N18: =IF(M18="-","-",M18*L18) -> -
E19: REIGNIER_Giratoire église | F19: France | G19: 25 | H19: 15 | I19: 0.28 | J19: =I19*G19 -> 7 | K19: 0.16 | L19: =K19*G19 -> 4 | M19: 0.25 | N19: =IF(M19="-","-",M19*L19) -> 1
E20: REIGNIER_Giratoire Foron | F20: France | G20: 15 | H20: 9 | I20: 0.13 | J20: =I20*G20 -> 1.95 | K20: 0.07 | L20: =K20*G20 -> 1.05 | M20: - | N20: =IF(M20="-","-",M20*L20) -> -
E21: REIGNIER_Giratoire La Forge | F21: France | G21: 16 | H21: 14 | I21: 0.38 | J21: =I21*G21 -> 6.08 | K21: 0.13 | L21: =K21*G21 -> 2.08 | M21: 1 | N21: =IF(M21="-","-",M21*L21) -> 2.08
E22: PERS-JUSSY_Giratoire Casino | F22: France | G22: 7 | H22: 5 | I22: 0.14 | J22: =I22*G22 -> 0.98 | K22: 0 | L22: =K22*G22 -> 0 | M22: - | N22: =IF(M22="-","-",M22*L22) -> -
E23: ARTHAZ_Giratoire lavage auto | F23: France | G23: 20 | H23: 9 | I23: 0.25 | J23: =I23*G23 -> 5 | K23: 0.15 | L23: =K23*G23 -> 3 | M23: 0.33 | N23: =IF(M23="-","-",M23*L23) -> 0.99
D24: Sous-total | G24: =SUM(G16:G23) -> 159 | H24: =SUM(H16:H23) -> 95 | I24: =J24/G24 -> 0.28283019 | J24: =SUM(J16:J23) -> 44.97 | K24: =L24/G24 -> 0.11962264 | L24: =SUM(L16:L23) -> 19.02 | M24: =N24/L24 -> 0.68138801 | N24: =SUM(N16:N23) -> 12.96
B25: Sous-total périmètre "arrière-pays" | D25: =SUM(D5:D23) -> 19 | E25: =COUNT(G5:G23) -> 18 | F25: =COUNT(J5:J23) -> 18 | G25: =G5+G15+G24 -> 394 | H25: =H5+H15+H24 -> 235 | I25: =J25/G25 -> 0.22581218 | J25: =J5+J15+J24 -> 88.97 | K25: =L25/G25 -> 0.22593909 | L25: =L5+L15+L24 -> 89.02 | M25: =N25/(L5+L16+L17+L19+L21+L23) -> 0.42779525 | N25: =N5+N15+N24 -> 14.96
B26: EVAV | C26: NON | D26: 31 | E26: AMBILLY_Voie verte Pont Noir | F26: France | G26: 603 | H26: 173 | J26: 261 | L26: 242 | M26: - | N26: =IF(M26="-","-",M26*L26) -> -
E27: ANNEMASSE_Voie verte Jura | F27: France | G27: 354 | H27: 103 | J27: 142 | L27: 161 | M27: - | N27: =IF(M27="-","-",M27*L27) -> -
E28: ANNEMASSE_Devant l'agglo | F28: France | G28: 222 | H28: 66 | J28: 137 | L28: 88 | M28: - | N28: =IF(M28="-","-",M28*L28) -> -
E29: GAILLARD_Douane de Fossard | F29: Frontière | G29: 106 | H29: 35 | J29: 39 | L29: 48 | M29: - | N29: =IF(M29="-","-",M29*L29) -> -
E30: ANNEMASSE_Clos Fleury | F30: France | G30: 206 | H30: 70 | J30: 87 | L30: 83 | M30: - | N30: =IF(M30="-","-",M30*L30) -> -
E31: GAILLARD_Douane de Moïllesullaz | F31: Frontière | G31: 173 | H31: 62 | J31: 39 | L31: 75 | M31: - | N31: =IF(M31="-","-",M31*L31) -> -
D32: Sous-total | G32: =SUM(G26:G31) -> 1664 | H32: =SUM(H26:H31) -> 509 | I32: =J32/G32 -> 0.42367788 | J32: =SUM(J26:J31) -> 705 | K32: =L32/G32 -> 0.41887019 | L32: =SUM(L26:L31) -> 697 | M32: =N32/L32 -> 0 | N32: =SUM(N26:N31) -> 0
B33: Salève Vivant | C33: NON | D33: 12 | E33: COLLONGES_Douane de Croix de Rozon | F33: Frontière | G33: 88 | H33: 88 | I33: 0.60227273 | J33: =I33*G33 -> 53 | K33: 0.36363636 | L33: =K33*G33 -> 32 | M33: 0.84375 | N33: =IF(M33="-","-",M33*L33) -> 27 | S33: 78 | T33: 78 | U33: 10 | V33: 10
E34: ARCHAMPS_Douane de Landecy | F34: Frontière | G34: 33 | H34: 33 | I34: 0.63636364 | J34: =I34*G34 -> 21 | K34: 0.24242424 | L34: =K34*G34 -> 8 | M34: 0.875 | N34: =IF(M34="-","-",M34*L34) -> 7 | S34: 33 | T34: 33 | U34: 0 | V34: 0
E35: BOSSEY_Douane de Pierre-Grand | F35: Frontière | G35: 14 | H35: 14 | I35: 0.64285714 | J35: =I35*G35 -> 9 | K35: 0.5 | L35: =K35*G35 -> 7 | M35: 0.57142857 | N35: =IF(M35="-","-",M35*L35) -> 4 | S35: 14 | T35: 14 | U35: 0 | V35: 0
E36: BOSSEY_Douane de Troinex/Bossey | F36: Frontière | G36: 23 | H36: 23 | I36: 0.65217391 | J36: =I36*G36 -> 15 | K36: 0.47826087 | L36: =K36*G36 -> 11 | M36: 0.72727273 | N36: =IF(M36="-","-",M36*L36) -> 8 | S36: 20 | T36: 20 | U36: 3 | V36: 3
E37: VEYRIER_Douane du Pas de l'Echelle | F37: Frontière | G37: 36 | H37: 36 | I37: 0.5 | J37: =I37*G37 -> 18 | K37: 0.47222222 | L37: =K37*G37 -> 17 | M37: 0.76470588 | N37: =IF(M37="-","-",M37*L37) -> 13 | S37: 36 | T37: 36 | U37: 0 | V37: 0
E38: ST-JULIEN_Douane de Charrot | F38: Frontière | G38: 45 | H38: 45 | I38: 0.57777778 | J38: =I38*G38 -> 26 | K38: 0.42222222 | L38: =K38*G38 -> 19 | M38: 0.73684211 | N38: =IF(M38="-","-",M38*L38) -> 14 | S38: 39 | T38: 39 | U38: 6 | V38: 6
D39: Sous-total | G39: =SUM(G33:G38) -> 239 | H39: =SUM(H33:H38) -> 239 | I39: =J39/G39 -> 0.59414226 | J39: =SUM(J33:J38) -> 142 | K39: =L39/G39 -> 0.39330544 | L39: =SUM(L33:L38) -> 94 | M39: =N39/L39 -> 0.77659574 | N39: =SUM(N33:N38) -> 73 | S39: =SUM(S33:S38) -> 220 | T39: =SUM(T33:T38) -> 220 | U39: =SUM(U33:U38) -> 19 | V39: =SUM(V33:V38) -> 19
B40: Groupe St-Julien | C40: NON | D40: 10 | E40: ST-JULIEN_Douane de Perly | F40: Frontière | G40: 59 | H40: =G40 -> 59 | I40: 0.51 | J40: =I40*G40 -> 30.09 | K40: 0.44 | L40: =K40*G40 -> 25.96 | M40: 0.62 | N40: =IF(M40="-","-",M40*L40) -> 16.0952
E41: ST-JULIEN_Passage douanier des Crottes | F41: Frontière | G41: 45 | H41: =G41 -> 45 | I41: 0.58 | J41: =I41*G41 -> 26.1 | K41: 0.44 | L41: =K41*G41 -> 19.8 | M41: 0.65 | N41: =IF(M41="-","-",M41*L41) -> 12.87
E42: ST-JULIEN_Paguette (chemin de l'Aire) | F42: Frontière | G42: 16 | H42: =G42 -> 16 | I42: 0.44 | J42: =I42*G42 -> 7.04 | K42: 0.31 | L42: =K42*G42 -> 4.96 | M42: 0.4 | N42: =IF(M42="-","-",M42*L42) -> 1.984
E43: ST-JULIEN_Douane de Certoux (rte Thérens) | F43: Frontière | G43: 31 | H43: =G43 -> 31 | I43: 0.29 | J43: =I43*G43 -> 8.99 | K43: 0.32 | L43: =K43*G43 -> 9.92 | M43: 0.3 | N43: =IF(M43="-","-",M43*L43) -> 2.976
...

Sheet 2021
B2: Association(s) | C2: Arrière-pays | D2: Nombre de bénévoles | E2: Postes de comptage | F2: France / Suisse / Frontière | G2: Nombre de vélos | I2: % VAE dans le total | J2: NB VAE dans le total | K2: % femmes dans le total | L2: NB de femmes dans le total | M2: % de VAE chez les femmes | N2: NB de VAE chez les femmes | O2: Autres modes | Q2: Piétons | S2: > Suisse | U2: > France
G4: total | H4: HP | O4: total | P4: HP | Q4: total | R4: HP | S4: total | T4: HP | U4: total | V4: HP
B5: Université Populaire de Cluses | C5: OUI | D5: 2 | E5: CLUSES_Passerelle de Messy | F5: France | G5: 102 | H5: 94 | I5: =J5/G5 -> 0.019607843 | J5: 2 | K5: =L5/G5 -> 0.17647059 | L5: 18 | M5: =IF(N5="-","-",N5/L5) -> 0.11111111 | N5: 2 | S5: - | T5: - | U5: - | V5: - | W5: OK
B6: NatEnv (Nature Environnement en Pays rochois) Fabrique à Biclou Pays rochois en Transition | C6: OUI | D6: 9 | E6: LA ROCHE_Carrefour Biocoop | F6: France | G6: 76 | H6: 50 | I6: =J6/G6 -> 0.22368421 | J6: 17 | K6: =L6/G6 -> 0.36842105 | L6: 28 | M6: =IF(N6="-","-",N6/L6) -> - | N6: - | S6: - | T6: - | U6: - | V6: - | W6: OK
E7: LA ROCHE_Giratoire La Poste | F7: France | G7: 45 | H7: 27 | I7: =J7/G7 -> 0.46666667 | J7: 21 | K7: =L7/G7 -> 0.31111111 | L7: 14 | M7: =IF(N7="-","-",N7/L7) -> - | N7: - | S7: - | T7: - | U7: - | V7: - | W7: OK
E8: LA ROCHE_Giratoire ENILV | F8: France | G8: 16 | H8: 10 | I8: =J8/G8 -> 0.3125 | J8: 5 | K8: =L8/G8 -> 0.1875 | L8: 3 | M8: =IF(N8="-","-",N8/L8) -> - | N8: - | S8: - | T8: - | U8: - | V8: - | W8: OK
E9: LA ROCHE_Gare Passage à niveau (new 2021) | F9: France | G9: 56 | H9: 36 | J9: 12 | L9: 10 | W9: OK
E10: ARENTHON_La Papeterie | F10: France | G10: 13 | H10: 8 | I10: =J10/G10 -> 0.53846154 | J10: 7 | K10: =L10/G10 -> 0.46153846 | L10: 6 | M10: =IF(N10="-","-",N10/L10) -> - | N10: - | S10: - | T10: - | U10: - | V10: - | W10: OK
E11: ST-PIERRE_Franchissement Borne-Dessy | F11: France | G11: 24 | H11: 20 | I11: =J11/G11 -> 0.29166667 | J11: 7 | K11: =L11/G11 -> 0.29166667 | L11: 7 | M11: =IF(N11="-","-",N11/L11) -> - | N11: - | S11: - | T11: - | U11: - | V11: - | W11: OK
E12: BONNEVILLE_Franchissement Borne-Tucinge | F12: France | G12: 33 | H12: 25 | I12: =J12/G12 -> 0 | J12: 0 | K12: =L12/G12 -> 0.21212121 | L12: 7 | M12: =IF(N12="-","-",N12/L12) -> - | N12: - | S12: - | T12: - | U12: - | V12: - | W12: OK
E13: ST-PIERRE_Pont principal sur le Borne | F13: France | G13: 32 | H13: 17 | I13: =J13/G13 -> 0.15625 | J13: 5 | K13: =L13/G13 -> 0.375 | L13: 12 | M13: =IF(N13="-","-",N13/L13) -> - | N13: - | S13: - | T13: - | U13: - | V13: - | W13: OK
E14: AMANCY_Giratoire Coriandre | F14: France | I14: =J14/G14 -> #DIV/0! | K14: =L14/G14 -> #DIV/0! | M14: =IF(N14="-","-",N14/L14) -> - | N14: - | S14: - | T14: - | U14: - | V14: - | W14: OK
D15: Sous-total | G15: =SUM(G6:G14) -> 295 | H15: =SUM(H6:H14) -> 193 | I15: =J15/G15 -> 0.25084746 | J15: =SUM(J6:J14) -> 74 | K15: =L15/G15 -> 0.29491525 | L15: =SUM(L6:L14) -> 87 | M15: =N15/L15 -> 0 | N15: =SUM(N6:N14) -> 0 | W15: OK
B16: AERE (Association Environnement Reignier-Esery) | C16: OUI | D16: 9 | E16: ETREMBIERES_Giratoire ex PN93 | F16: France | G16: 46 | H16: 32 | I16: =J16/G16 -> 0.65217391 | J16: 30 | K16: =L16/G16 -> 0.19565217 | L16: 9 | M16: =IF(N16="-","-",N16/L16) -> 1 | N16: 9 | S16: - | T16: - | U16: - | V16: - | W16: OK
E17: ETREMBIERES_Carrefour sous Château | F17: France | G17: 28 | H17: 17 | I17: =J17/G17 -> 0.64285714 | J17: 18 | K17: =L17/G17 -> 0.32142857 | L17: 9 | M17: =IF(N17="-","-",N17/L17) -> 0.77777778 | N17: 7 | S17: - | T17: - | U17: - | V17: - | W17: OK
E18: SCIENTRIER_Carrefour Tour de Bellecombe | F18: France | G18: 5 | H18: 5 | I18: =J18/G18 -> 0.6 | J18: 3 | K18: =L18/G18 -> 0.2 | L18: 1 | M18: =IF(N18="-","-",N18/L18) -> 1 | N18: 1 | S18: - | T18: - | U18: - | V18: - | W18: OK
E19: REIGNIER_Giratoire église | F19: France | G19: 45 | H19: 26 | I19: =J19/G19 -> 0.26666667 | J19: 12 | K19: =L19/G19 -> 0.26666667 | L19: 12 | M19: =IF(N19="-","-",N19/L19) -> 0.25 | N19: 3 | S19: - | T19: - | U19: - | V19: - | W19: OK
E20: REIGNIER_Giratoire Foron | F20: France | G20: 14 | H20: 9 | I20: =J20/G20 -> 0.21428571 | J20: 3 | K20: =L20/G20 -> 0.14285714 | L20: 2 | M20: =IF(N20="-","-",N20/L20) -> 0.5 | N20: 1 | S20: - | T20: - | U20: - | V20: - | W20: OK
E21: REIGNIER_Giratoire La Forge | F21: France | G21: 31 | H21: 23 | I21: =J21/G21 -> 0.5483871 | J21: 17 | K21: =L21/G21 -> 0.16129032 | L21: 5 | M21: =IF(N21="-","-",N21/L21) -> 1 | N21: 5 | S21: - | T21: - | U21: - | V21: - | W21: OK
E22: PERS-JUSSY_Giratoire Casino | F22: France | G22: 12 | H22: 7 | I22: =J22/G22 -> 0.33333333 | J22: 4 | K22: =L22/G22 -> 0.33333333 | L22: 4 | M22: =IF(N22="-","-",N22/L22) -> 0.5 | N22: 2 | S22: - | T22: - | U22: - | V22: - | W22: OK
E23: ARTHAZ_Giratoire lavage auto | F23: France | G23: 17 | H23: 9 | I23: =J23/G23 -> 0.41176471 | J23: 7 | K23: =L23/G23 -> 0.23529412 | L23: 4 | M23: =IF(N23="-","-",N23/L23) -> 0.25 | N23: 1 | S23: - | T23: - | U23: - | V23: - | W23: OK
D24: Sous-total | G24: =SUM(G16:G23) -> 198 | H24: =SUM(H16:H23) -> 128 | I24: =J24/G24 -> 0.47474747 | J24: =SUM(J16:J23) -> 94 | K24: =L24/G24 -> 0.23232323 | L24: =SUM(L16:L23) -> 46 | M24: =N24/L24 -> 0.63043478 | N24: =SUM(N16:N23) -> 29 | W24: OK
B25: Sous-total périmètre "arrière-pays" | D25: =SUM(D5:D23) -> 20 | E25: =COUNT(G5:G23) -> 18 | F25: =COUNT(J5:J23) -> 18 | G25: =G5+G15+G24 -> 595 | H25: =H5+H15+H24 -> 415 | I25: =J25/G25 -> 0.28571429 | J25: =J5+J15+J24 -> 170 | K25: =L25/G25 -> 0.25378151 | L25: =L5+L15+L24 -> 151 | M25: =N25/(L5+SUM(L16:L23)) -> 0.484375 | N25: =N5+N15+N24 -> 31 | W25: OK
B26: EVAV (En Ville A Vélo) | C26: NON | D26: 6 | E26: AMBILLY_Voie verte Pont Noir | F26: France | I26: =J26/G26 -> #DIV/0! | K26: =L26/G26 -> #DIV/0! | M26: =IF(N26="-","-",N26/L26) -> - | N26: - | W26: KO
E27: ANNEMASSE_Voie verte Jura | F27: France | I27: =J27/G27 -> #DIV/0! | K27: =L27/G27 -> #DIV/0! | M27: =IF(N27="-","-",N27/L27) -> - | N27: - | S27: - | T27: - | U27: - | V27: - | W27: KO
E28: ANNEMASSE_Devant l'agglo | F28: France | G28: 228 | H28: 125 | I28: =J28/G28 -> 0.39473684 | J28: 90 | K28: =L28/G28 -> 0.39912281 | L28: 91 | M28: =IF(N28="-","-",N28/L28) -> - | N28: - | S28: - | T28: - | U28: - | V28: - | W28: KO
E29: GAILLARD_Douane de Fossard | F29: Frontière | G29: 141 | H29: 80 | I29: =J29/G29 -> 0.46099291 | J29: 65 | K29: =L29/G29 -> 0.43971631 | L29: 62 | M29: =IF(N29="-","-",N29/L29) -> - | N29: - | W29: KO
E30: ANNEMASSE_Clos Fleury | F30: France | G30: 234 | H30: 127 | I30: =J30/G30 -> 0.42307692 | J30: 99 | K30: =L30/G30 -> 0.47863248 | L30: 112 | M30: =IF(N30="-","-",N30/L30) -> - | N30: - | S30: - | T30: - | U30: - | V30: - | W30: KO
E31: GAILLARD_Douane de Moïllesullaz | F31: Frontière | G31: 157 | H31: 82 | I31: =J31/G31 -> 0.22929936 | J31: 36 | K31: =L31/G31 -> 0.31210191 | L31: 49 | M31: =IF(N31="-","-",N31/L31) -> - | N31: - | W31: KO
D32: Sous-total | G32: =SUM(G26:G31) -> 760 | H32: =SUM(H26:H31) -> 414 | I32: =J32/G32 -> 0.38157895 | J32: =SUM(J26:J31) -> 290 | K32: =L32/G32 -> 0.41315789 | L32: =SUM(L26:L31) -> 314 | M32: =N32/L32 -> 0 | N32: =SUM(N26:N31) -> 0 | S32: =SUM(S26:S31) -> 0 | T32: =SUM(T26:T31) -> 0 | U32: =SUM(U26:U31) -> 0 | V32: =SUM(V26:V31) -> 0
B33: Salève Vivant | C33: NON | D33: 11 | E33: COLLONGES_Douane de Croix de Rozon | F33: Frontière | G33: 117 | H33: 86 | I33: =J33/G33 -> 0.69230769 | J33: 81 | K33: =L33/G33 -> 0.4017094 | L33: 47 | M33: =IF(N33="-","-",N33/L33) -> 0.70212766 | N33: 33 | O33: - | P33: - | Q33: - | R33: - | S33: 112 | T33: 82 | U33: 5 | V33: 4 | W33: OK
E34: ARCHAMPS_Douane de Landecy | F34: Frontière | G34: 53 | H34: 38 | I34: =J34/G34 -> 0.60377358 | J34: 32 | K34: =L34/G34 -> 0.22641509 | L34: 12 | M34: =IF(N34="-","-",N34/L34) -> 0.83333333 | N34: 10 | O34: - | P34: - | Q34: - | R34: - | S34: 51 | T34: 36 | U34: 2 | V34: 2 | W34: OK
E35: BOSSEY_Douane de Pierre-Grand | F35: Frontière | G35: 22 | H35: 20 | I35: =J35/G35 -> 0.72727273 | J35: 16 | K35: =L35/G35 -> 0.54545455 | L35: 12 | M35: =IF(N35="-","-",N35/L35) -> 0.75 | N35: 9 | O35: - | P35: - | Q35: - | R35: - | S35: 22 | T35: 20 | U35: 0 | V35: 0 | W35: OK
E36: BOSSEY_Douane de Troinex/Bossey | F36: Frontière | G36: 49 | H36: 33 | I36: =J36/G36 -> 0.71428571 | J36: 35 | K36: =L36/G36 -> 0.40816327 | L36: 20 | M36: =IF(N36="-","-",N36/L36) -> 0.85 | N36: 17 | O36: - | P36: - | Q36: - | R36: - | S36: 46 | T36: 31 | U36: 3 | V36: 2 | W36: OK
E37: VEYRIER_Douane du Pas de l'Echelle | F37: Frontière | G37: 44 | H37: 44 | I37: =J37/G37 -> 0.63636364 | J37: 28 | K37: =L37/G37 -> 0.36363636 | L37: 16 | M37: =IF(N37="-","-",N37/L37) -> 0.9375 | N37: 15 | O37: - | P37: - | Q37: - | R37: - | S37: 40 | T37: 40 | U37: 4 | V37: 4 | W37: OK | X37: Compté par ProVélo en 2021 (Salève Vivant en 2020)
E38: ST-JULIEN_Douane de Charrot | F38: Frontière | G38: 5 | H38: 4 | I38: =J38/G38 -> 0.4 | J38: 2 | K38: =L38/G38 -> 0.2 | L38: 1 | M38: =IF(N38="-","-",N38/L38) -> 0 | N38: 0 | O38: - | P38: - | Q38: - | R38: - | S38: 5 | T38: 4 | U38: 0 | V38: 0 | W38: OK
D39: Sous-total | G39: =SUM(G33:G38) -> 290 | H39: =SUM(H33:H38) -> 225 | I39: =J39/G39 -> 0.66896552 | J39: =SUM(J33:J38) -> 194 | K39: =L39/G39 -> 0.37241379 | L39: =SUM(L33:L38) -> 108 | M39: =N39/L39 -> 0.77777778 | N39: =SUM(N33:N38) -> 84 | S39: =SUM(S33:S38) -> 276 | T39: =SUM(T33:T38) -> 213 | U39: =SUM(U33:U38) -> 14 | V39: =SUM(V33:V38) -> 12 | W39: OK
B40: Groupe St-Julien | C40: NON | D40: 10 | E40: ST-JULIEN_Douane de Perly | F40: Frontière | G40: 76 | H40: =G40 -> 76 | I40: =J40/G40 -> 0.5 | J40: =17+21 -> 38 | K40: =L40/G40 -> 0.38157895 | L40: 29 | M40: =IF(N40="-","-",N40/L40) -> 0.72413793 | N40: 21 | S40: 75 | T40: 75 | U40: 1 | V40: 1 | W40: OK
E41: ST-JULIEN_Passage douanier des Crottes | F41: Frontière | G41: 80 | H41: =G41 -> 80 | I41: =J41/G41 -> 0.6375 | J41: =25+26 -> 51 | K41: =L41/G41 -> 0.5 | L41: 40 | M41: =IF(N41="-","-",N41/L41) -> 0.65 | N41: 26 | S41: 74 | T41: 74 | U41: 6 | V41: 6 | W41: OK
E42: ST-JULIEN_Paguette (chemin de l'Aire) | F42: Frontière | G42: 31 | H42: =G42 -> 31 | I42: =J42/G42 -> 0.32258065 | J42: =5+5 -> 10 | K42: =L42/G42 -> 0.35483871 | L42: 11 | M42: =IF(N42="-","-",N42/L42) -> 0.45454545 | N42: 5 | S42: 31 | T42: 31 | U42: 0 | V42: 0 | W42: OK
...

Sheet 2021-2020
B2: Association(s) | C2: Arrière-pays | D2: Nombre de bénévoles | E2: Postes de comptage | F2: France / Suisse / Frontière | G2: Evolution des vélos 2020-2021 | K2: Evolution des VAE 2020-2021 | M2: Evolution des femmes 2020-2021 | O2: Evolution des VAE chez les femmes 2020-2021 | Q2: Autres modes | S2: Piétons | U2: > Suisse | W2: > France
G3: TOTAL | I3: HP | U3: en HP | W3: en HP
G4: # | H4: % | I4: # | J4: % | K4: # | L4: % | M4: # | N4: % | O4: # | P4: % | Q4: total | R4: HP | S4: total | T4: HP | U4: # | V4: % | W4: # | X4: %
B5: Université Populaire de Cluses | C5: OUI | D5: 2 | E5: CLUSES_Passerelle de Messy | F5: France | G5: ='2021'!G5-'2020'!G5 -> 39 | H5: =IF('2021'!G5=0,0,IF('2020'!G5=0,0,'2021'!G5/'2020'!G5-1)) -> 0.61904762 | I5: ='2021'!H5-'2020'!H5 -> 65 | J5: =IF('2021'!H5=0,0,IF('2020'!H5=0,0,'2021'!H5/'2020'!H5-1)) -> 2.2413793 | K5: ='2021'!J5-'2020'!J5 -> 0 | L5: =IF('2021'!J5=0,0,IF('2020'!J5=0,0,'2021'!J5/'2020'!J5-1)) -> 0 | M5: ='2021'!L5-'2020'!L5 -> 1 | N5: =IF('2021'!L5=0,0,IF('2020'!L5=0,0,'2021'!L5/'2020'!L5-1)) -> 0.058823529 | O5: =IF('2020'!N5="-",0,'2021'!N5-'2020'!N5) -> 0 | P5: =IF('2021'!N5=0,0,IF('2020'!N5="-",0,'2021'!N5/'2020'!N5-1)) -> 0 | U5: - | V5: - | W5: - | X5: -
B6: NatEnv (Nature Environnement en Pays rochois) Fabrique à Biclou Pays rochois en Transition | C6: OUI | D6: 8 | E6: LA ROCHE_Carrefour Biocoop | F6: France | G6: ='2021'!G6-'2020'!G6 -> 45 | H6: =IF('2021'!G6=0,0,IF('2020'!G6=0,0,'2021'!G6/'2020'!G6-1)) -> 1.4516129 | I6: ='2021'!H6-'2020'!H6 -> 27 | J6: =IF('2021'!H6=0,0,IF('2020'!H6=0,0,'2021'!H6/'2020'!H6-1)) -> 1.173913 | K6: ='2021'!J6-'2020'!J6 -> 7 | L6: =IF('2021'!J6=0,0,IF('2020'!J6=0,0,'2021'!J6/'2020'!J6-1)) -> 0.7 | M6: ='2021'!L6-'2020'!L6 -> 18 | N6: =IF('2021'!L6=0,0,IF('2020'!L6=0,0,'2021'!L6/'2020'!L6-1)) -> 1.8 | O6: =IF('2020'!N6="-",0,'2021'!N6-'2020'!N6) -> 0 | P6: =IF('2021'!N6=0,0,IF('2020'!N6="-",0,'2021'!N6/'2020'!N6-1)) -> 0 | U6: - | V6: - | W6: - | X6: -
E7: LA ROCHE_Giratoire La Poste | F7: France | G7: ='2021'!G7-'2020'!G7 -> 20 | H7: =IF('2021'!G7=0,0,IF('2020'!G7=0,0,'2021'!G7/'2020'!G7-1)) -> 0.8 | I7: ='2021'!H7-'2020'!H7 -> 14 | J7: =IF(I7=0,0,'2021'!H7/'2020'!H7-1) -> 1.0769231 | K7: ='2021'!J7-'2020'!J7 -> 9 | L7: =IF('2021'!J7=0,0,IF('2020'!J7=0,0,'2021'!J7/'2020'!J7-1)) -> 0.75 | M7: ='2021'!L7-'2020'!L7 -> 5 | N7: =IF('2021'!L7=0,0,IF('2020'!L7=0,0,'2021'!L7/'2020'!L7-1)) -> 0.55555556 | O7: =IF('2020'!N7="-",0,'2021'!N7-'2020'!N7) -> 0 | P7: =IF('2021'!N7=0,0,IF('2020'!N7="-",0,'2021'!N7/'2020'!N7-1)) -> 0 | U7: - | V7: - | W7: - | X7: -
E8: LA ROCHE_Giratoire ENILV | F8: France | G8: ='2021'!G8-'2020'!G8 -> -2 | H8: =IF('2021'!G8=0,0,IF('2020'!G8=0,0,'2021'!G8/'2020'!G8-1)) -> -0.11111111 | I8: ='2021'!H8-'2020'!H8 -> 0 | J8: =IF(I8=0,0,'2021'!H8/'2020'!H8-1) -> 0 | K8: ='2021'!J8-'2020'!J8 -> -4 | L8: =IF('2021'!J8=0,0,IF('2020'!J8=0,0,'2021'!J8/'2020'!J8-1)) -> -0.44444444 | M8: ='2021'!L8-'2020'!L8 -> 0 | N8: =IF('2021'!L8=0,0,IF('2020'!L8=0,0,'2021'!L8/'2020'!L8-1)) -> 0 | O8: =IF('2020'!N8="-",0,'2021'!N8-'2020'!N8) -> 0 | P8: =IF('2021'!N8=0,0,IF('2020'!N8="-",0,'2021'!N8/'2020'!N8-1)) -> 0 | U8: - | V8: - | W8: - | X8: -
E9: LA ROCHE_Gare Passage à niveau (new2021)
E10: ARENTHON_La Papeterie | F10: France | G10: ='2021'!G10-'2020'!G10 -> -1 | H10: =IF('2021'!G10=0,0,IF('2020'!G10=0,0,'2021'!G10/'2020'!G10-1)) -> -0.071428571 | I10: ='2021'!H10-'2020'!H10 -> -1 | J10: =IF(I10=0,0,'2021'!H10/'2020'!H10-1) -> -0.11111111 | K10: ='2021'!J10-'2020'!J10 -> 6 | L10: =IF('2021'!J10=0,0,IF('2020'!J10=0,0,'2021'!J10/'2020'!J10-1)) -> 6 | M10: ='2021'!L10-'2020'!L10 -> 5 | N10: =IF('2021'!L10=0,0,IF('2020'!L10=0,0,'2021'!L10/'2020'!L10-1)) -> 5 | O10: =IF('2020'!N10="-",0,'2021'!N10-'2020'!N10) -> 0 | P10: =IF('2021'!N10=0,0,IF('2020'!N10="-",0,'2021'!N10/'2020'!N10-1)) -> 0 | U10: - | V10: - | W10: - | X10: -
E11: ST-PIERRE_Franchissement Borne-Dessy | F11: France | G11: ='2021'!G11-'2020'!G11 -> 0 | H11: =IF('2021'!G11=0,0,IF('2020'!G11=0,0,'2021'!G11/'2020'!G11-1)) -> 0 | I11: ='2021'!H11-'2020'!H11 -> 4 | J11: =IF(I11=0,0,'2021'!H11/'2020'!H11-1) -> 0.25 | K11: ='2021'!J11-'2020'!J11 -> 6 | L11: =IF('2021'!J11=0,0,IF('2020'!J11=0,0,'2021'!J11/'2020'!J11-1)) -> 6 | M11: ='2021'!L11-'2020'!L11 -> 2 | N11: =IF('2021'!L11=0,0,IF('2020'!L11=0,0,'2021'!L11/'2020'!L11-1)) -> 0.4 | O11: =IF('2020'!N11="-",0,'2021'!N11-'2020'!N11) -> 0 | P11: =IF('2021'!N11=0,0,IF('2020'!N11="-",0,'2021'!N11/'2020'!N11-1)) -> 0 | U11: - | V11: - | W11: - | X11: -
E12: BONNEVILLE_Franchissement Borne-Tucinge | F12: France | G12: ='2021'!G12-'2020'!G12 -> 4 | H12: =IF('2021'!G12=0,0,IF('2020'!G12=0,0,'2021'!G12/'2020'!G12-1)) -> 0.13793103 | I12: ='2021'!H12-'2020'!H12 -> 4 | J12: =IF(I12=0,0,'2021'!H12/'2020'!H12-1) -> 0.19047619 | K12: ='2021'!J12-'2020'!J12 -> 0 | L12: =IF('2021'!J12=0,0,IF('2020'!J12=0,0,'2021'!J12/'2020'!J12-1)) -> 0 | M12: ='2021'!L12-'2020'!L12 -> -5 | N12: =IF('2021'!L12=0,0,IF('2020'!L12=0,0,'2021'!L12/'2020'!L12-1)) -> -0.41666667 | O12: =IF('2020'!N12="-",0,'2021'!N12-'2020'!N12) -> 0 | P12: =IF('2021'!N12=0,0,IF('2020'!N12="-",0,'2021'!N12/'2020'!N12-1)) -> 0 | U12: - | V12: - | W12: - | X12: -
E13: ST-PIERRE_Pont principal sur le Borne | F13: France | G13: ='2021'!G13-'2020'!G13 -> 5 | H13: =IF('2021'!G13=0,0,IF('2020'!G13=0,0,'2021'!G13/'2020'!G13-1)) -> 0.18518519 | I13: ='2021'!H13-'2020'!H13 -> 0 | J13: =IF(I13=0,0,'2021'!H13/'2020'!H13-1) -> 0 | K13: ='2021'!J13-'2020'!J13 -> -2 | L13: =IF('2021'!J13=0,0,IF('2020'!J13=0,0,'2021'!J13/'2020'!J13-1)) -> -0.28571429 | M13: ='2021'!L13-'2020'!L13 -> -1 | N13: =IF('2021'!L13=0,0,IF('2020'!L13=0,0,'2021'!L13/'2020'!L13-1)) -> -0.076923077 | O13: =IF('2020'!N13="-",0,'2021'!N13-'2020'!N13) -> 0 | P13: =IF('2021'!N13=0,0,IF('2020'!N13="-",0,'2021'!N13/'2020'!N13-1)) -> 0 | U13: - | V13: - | W13: - | X13: -
E14: AMANCY_Giratoire Coriandre | F14: France
D15: Sous-total | G15: ='2021'!G15-'2020'!G15 -> 123 | H15: =IF('2021'!G15=0,0,IF('2020'!G15=0,0,'2021'!G15/'2020'!G15-1)) -> 0.71511628 | I15: ='2021'!H15-'2020'!H15 -> 82 | J15: =IF(I15=0,0,'2021'!H15/'2020'!H15-1) -> 0.73873874 | K15: ='2021'!J15-'2020'!J15 -> 32 | L15: =IF('2021'!J15=0,0,IF('2020'!J15=0,0,'2021'!J15/'2020'!J15-1)) -> 0.76190476 | M15: ='2021'!L15-'2020'!L15 -> 34 | N15: =IF('2021'!L15=0,0,IF('2020'!L15=0,0,'2021'!L15/'2020'!L15-1)) -> 0.64150943 | O15: =IF('2020'!N15="-",0,'2021'!N15-'2020'!N15) -> 0 | P15: =IF('2021'!N15=0,0,IF('2020'!N15="-",0,'2021'!N15/'2020'!N15-1)) -> 0
B16: AERE (Association Environnement Reignier-Esery) | C16: OUI | D16: 8 | E16: ETREMBIERES_Giratoire ex PN93 | F16: France | G16: ='2021'!G16-'2020'!G16 -> 9 | H16: =IF('2021'!G16=0,0,IF('2020'!G16=0,0,'2021'!G16/'2020'!G16-1)) -> 0.24324324 | I16: ='2021'!H16-'2020'!H16 -> 9 | J16: =IF('2021'!H16=0,0,IF('2020'!H16=0,0,'2021'!H16/'2020'!H16-1)) -> 0.39130435 | K16: ='2021'!J16-'2020'!J16 -> 15.94 | L16: =IF('2021'!J16=0,0,IF('2020'!J16=0,0,'2021'!J16/'2020'!J16-1)) -> 1.1337127 | M16: ='2021'!L16-'2020'!L16 -> 3.08 | N16: =IF('2021'!L16=0,0,IF('2020'!L16=0,0,'2021'!L16/'2020'!L16-1)) -> 0.52027027 | O16: =IF('2020'!N16="-",0,'2021'!N16-'2020'!N16) -> 3.08 | P16: =IF('2021'!N16=0,0,IF('2020'!N16="-",0,'2021'!N16/'2020'!N16-1)) -> 0.52027027 | U16: - | V16: - | W16: - | X16: -
E17: ETREMBIERES_Carrefour sous Château | F17: France | G17: ='2021'!G17-'2020'!G17 -> -5 | H17: =IF('2021'!G17=0,0,IF('2020'!G17=0,0,'2021'!G17/'2020'!G17-1)) -> -0.15151515 | I17: ='2021'!H17-'2020'!H17 -> 2 | J17: =IF(I17=0,0,'2021'!H17/'2020'!H17-1) -> 0.13333333 | K17: ='2021'!J17-'2020'!J17 -> 8.1 | L17: =IF('2021'!J17=0,0,IF('2020'!J17=0,0,'2021'!J17/'2020'!J17-1)) -> 0.81818182 | M17: ='2021'!L17-'2020'!L17 -> 6.03 | N17: =IF('2021'!L17=0,0,IF('2020'!L17=0,0,'2021'!L17/'2020'!L17-1)) -> 2.030303 | O17: =IF('2020'!N17="-",0,'2021'!N17-'2020'!N17) -> 4.03 | P17: =IF('2021'!N17=0,0,IF('2020'!N17="-",0,'2021'!N17/'2020'!N17-1)) -> 1.3569024 | U17: - | V17: - | W17: - | X17: -
E18: SCIENTRIER_Carrefour Tour de Bellecombe | F18: France | G18: ='2021'!G18-'2020'!G18 -> -1 | H18: =IF('2021'!G18=0,0,IF('2020'!G18=0,0,'2021'!G18/'2020'!G18-1)) -> -0.16666667 | I18: ='2021'!H18-'2020'!H18 -> 0 | J18: =IF(I18=0,0,'2021'!H18/'2020'!H18-1) -> 0 | K18: ='2021'!J18-'2020'!J18 -> 3 | L18: =IF('2021'!J18=0,0,IF('2020'!J18=0,0,'2021'!J18/'2020'!J18-1)) -> 0 | M18: ='2021'!L18-'2020'!L18 -> 1 | N18: =IF('2021'!L18=0,0,IF('2020'!L18=0,0,'2021'!L18/'2020'!L18-1)) -> 0 | O18: =IF('2020'!N18="-",0,'2021'!N18-'2020'!N18) -> 0 | P18: =IF('2021'!N18=0,0,IF('2020'!N18="-",0,'2021'!N18/'2020'!N18-1)) -> 0 | U18: - | V18: - | W18: - | X18: -
E19: REIGNIER_Giratoire église | F19: France | G19: ='2021'!G19-'2020'!G19 -> 20 | H19: =IF('2021'!G19=0,0,IF('2020'!G19=0,0,'2021'!G19/'2020'!G19-1)) -> 0.8 | I19: ='2021'!H19-'2020'!H19 -> 11 | J19: =IF(I19=0,0,'2021'!H19/'2020'!H19-1) -> 0.73333333 | K19: ='2021'!J19-'2020'!J19 -> 5 | L19: =IF('2021'!J19=0,0,IF('2020'!J19=0,0,'2021'!J19/'2020'!J19-1)) -> 0.71428571 | M19: ='2021'!L19-'2020'!L19 -> 8 | N19: =IF('2021'!L19=0,0,IF('2020'!L19=0,0,'2021'!L19/'2020'!L19-1)) -> 2 | O19: =IF('2020'!N19="-",0,'2021'!N19-'2020'!N19) -> 2 | P19: =IF('2021'!N19=0,0,IF('2020'!N19="-",0,'2021'!N19/'2020'!N19-1)) -> 2 | U19: - | V19: - | W19: - | X19: -
E20: REIGNIER_Giratoire Foron | F20: France | G20: ='2021'!G20-'2020'!G20 -> -1 | H20: =IF('2021'!G20=0,0,IF('2020'!G20=0,0,'2021'!G20/'2020'!G20-1)) -> -0.066666667 | I20: ='2021'!H20-'2020'!H20 -> 0 | J20: =IF(I20=0,0,'2021'!H20/'2020'!H20-1) -> 0 | K20: ='2021'!J20-'2020'!J20 -> 1.05 | L20: =IF('2021'!J20=0,0,IF('2020'!J20=0,0,'2021'!J20/'2020'!J20-1)) -> 0.53846154 | M20: ='2021'!L20-'2020'!L20 -> 0.95 | N20: =IF('2021'!L20=0,0,IF('2020'!L20=0,0,'2021'!L20/'2020'!L20-1)) -> 0.9047619 | O20: =IF('2020'!N20="-",0,'2021'!N20-'2020'!N20) -> 0 | P20: =IF('2021'!N20=0,0,IF('2020'!N20="-",0,'2021'!N20/'2020'!N20-1)) -> 0 | U20: - | V20: - | W20: - | X20: -
E21: REIGNIER_Giratoire La Forge | F21: France | G21: ='2021'!G21-'2020'!G21 -> 15 | H21: =IF('2021'!G21=0,0,IF('2020'!G21=0,0,'2021'!G21/'2020'!G21-1)) -> 0.9375 | I21: ='2021'!H21-'2020'!H21 -> 9 | J21: =IF(I21=0,0,'2021'!H21/'2020'!H21-1) -> 0.64285714 | K21: ='2021'!J21-'2020'!J21 -> 10.92 | L21: =IF('2021'!J21=0,0,IF('2020'!J21=0,0,'2021'!J21/'2020'!J21-1)) -> 1.7960526 | M21: ='2021'!L21-'2020'!L21 -> 2.92 | N21: =IF('2021'!L21=0,0,IF('2020'!L21=0,0,'2021'!L21/'2020'!L21-1)) -> 1.4038462 | O21: =IF('2020'!N21="-",0,'2021'!N21-'2020'!N21) -> 2.92 | P21: =IF('2021'!N21=0,0,IF('2020'!N21="-",0,'2021'!N21/'2020'!N21-1)) -> 1.4038462 | U21: - | V21: - | W21: - | X21: -
E22: PERS-JUSSY_Giratoire Casino | F22: France | G22: ='2021'!G22-'2020'!G22 -> 5 | H22: =IF('2021'!G22=0,0,IF('2020'!G22=0,0,'2021'!G22/'2020'!G22-1)) -> 0.71428571 | I22: ='2021'!H22-'2020'!H22 -> 2 | J22: =IF(I22=0,0,'2021'!H22/'2020'!H22-1) -> 0.4 | K22: ='2021'!J22-'2020'!J22 -> 3.02 | L22: =IF('2021'!J22=0,0,IF('2020'!J22=0,0,'2021'!J22/'2020'!J22-1)) -> 3.0816327 | M22: ='2021'!L22-'2020'!L22 -> 4 | N22: =IF('2021'!L22=0,0,IF('2020'!L22=0,0,'2021'!L22/'2020'!L22-1)) -> 0 | O22: =IF('2020'!N22="-",0,'2021'!N22-'2020'!N22) -> 0 | P22: =IF('2021'!N22=0,0,IF('2020'!N22="-",0,'2021'!N22/'2020'!N22-1)) -> 0 | U22: - | V22: - | W22: - | X22: -
E23: ARTHAZ_Giratoire lavage auto | F23: France | G23: ='2021'!G23-'2020'!G23 -> -3 | H23: =IF('2021'!G23=0,0,IF('2020'!G23=0,0,'2021'!G23/'2020'!G23-1)) -> -0.15 | I23: ='2021'!H23-'2020'!H23 -> 0 | J23: =IF(I23=0,0,'2021'!H23/'2020'!H23-1) -> 0 | K23: ='2021'!J23-'2020'!J23 -> 2 | L23: =IF('2021'!J23=0,0,IF('2020'!J23=0,0,'2021'!J23/'2020'!J23-1)) -> 0.4 | M23: ='2021'!L23-'2020'!L23 -> 1 | N23: =IF('2021'!L23=0,0,IF('2020'!L23=0,0,'2021'!L23/'2020'!L23-1)) -> 0.33333333 | O23: =IF('2020'!N23="-",0,'2021'!N23-'2020'!N23) -> 0.01 | P23: =IF('2021'!N23=0,0,IF('2020'!N23="-",0,'2021'!N23/'2020'!N23-1)) -> 0.01010101 | U23: - | V23: - | W23: - | X23: -
D24: Sous-total | G24: ='2021'!G24-'2020'!G24 -> 39 | H24: =IF('2021'!G24=0,0,IF('2020'!G24=0,0,'2021'!G24/'2020'!G24-1)) -> 0.24528302 | I24: ='2021'!H24-'2020'!H24 -> 33 | J24: =IF(I24=0,0,'2021'!H24/'2020'!H24-1) -> 0.34736842 | K24: ='2021'!J24-'2020'!J24 -> 49.03 | L24: =IF('2021'!J24=0,0,IF('2020'!J24=0,0,'2021'!J24/'2020'!J24-1)) -> 1.0902824 | M24: ='2021'!L24-'2020'!L24 -> 26.98 | N24: =IF('2021'!L24=0,0,IF('2020'!L24=0,0,'2021'!L24/'2020'!L24-1)) -> 1.4185068 | O24: =IF('2020'!N24="-",0,'2021'!N24-'2020'!N24) -> 16.04 | P24: =IF('2021'!N24=0,0,IF('2020'!N24="-",0,'2021'!N24/'2020'!N24-1)) -> 1.2376543
B25: Sous-total périmètre "arrière-pays" | D25: =SUM(D5:D23) -> 18 | E25: =COUNT(G5:G23) -> 17 | F25: =COUNT(K5:K23) -> 17 | G25: =G5+G15+G24 -> 201 | H25: =IF('2021'!G25=0,0,IF('2020'!G25=0,0,'2021'!G25/'2020'!G25-1)) -> 0.51015228 | I25: =I5+I15+I24 -> 180 | J25: =IF(I25=0,0,'2021'!H25/'2020'!H25-1) -> 0.76595745 | K25: =K5+K15+K24 -> 81.03 | L25: =IF('2021'!J25=0,0,IF('2020'!J25=0,0,'2021'!J25/'2020'!J25-1)) -> 0.91075643 | M25: =M5+M15+M24 -> 61.98 | N25: =IF('2021'!L25=0,0,IF('2020'!L25=0,0,'2021'!L25/'2020'!L25-1)) -> 0.69624803 | O25: =O5+O15+O24 -> 16.04 | P25: =IF('2021'!N25=0,0,IF('2020'!N25="-",0,'2021'!N25/'2020'!N25-1)) -> 1.0721925
B26: EVAV (En Ville A Vélo) | C26: NON | D26: 31 | E26: AMBILLY_Voie verte Pont Noir | F26: France
E27: ANNEMASSE_Voie verte Jura | F27: France
E28: ANNEMASSE_Devant l'agglo | F28: France | G28: ='2021'!G28-'2020'!G28 -> 6 | H28: =IF('2021'!G28=0,0,IF('2020'!G28=0,0,'2021'!G28/'2020'!G28-1)) -> 0.027027027 | I28: ='2021'!H28-'2020'!H28 -> 59 | J28: =IF(I28=0,0,'2021'!H28/'2020'!H28-1) -> 0.89393939 | K28: ='2021'!J28-'2020'!J28 -> -47 | L28: =IF('2021'!J28=0,0,IF('2020'!J28=0,0,'2021'!J28/'2020'!J28-1)) -> -0.34306569 | M28: ='2021'!L28-'2020'!L28 -> 3 | N28: =IF('2021'!L28=0,0,IF('2020'!L28=0,0,'2021'!L28/'2020'!L28-1)) -> 0.034090909 | O28: =IF('2020'!N28="-",0,'2021'!N28-'2020'!N28) -> 0 | P28: =IF('2021'!N28=0,0,IF('2020'!N28="-",0,'2021'!N28/'2020'!N28-1)) -> 0 | U28: - | V28: - | W28: - | X28: -
E29: GAILLARD_Douane de Fossard | F29: Frontière | G29: ='2021'!G29-'2020'!G29 -> 35 | H29: =IF('2021'!G29=0,0,IF('2020'!G29=0,0,'2021'!G29/'2020'!G29-1)) -> 0.33018868 | I29: ='2021'!H29-'2020'!H29 -> 45 | J29: =IF(I29=0,0,'2021'!H29/'2020'!H29-1) -> 1.2857143 | K29: ='2021'!J29-'2020'!J29 -> 26 | L29: =IF('2021'!J29=0,0,IF('2020'!J29=0,0,'2021'!J29/'2020'!J29-1)) -> 0.66666667 | M29: ='2021'!L29-'2020'!L29 -> 14 | N29: =IF('2021'!L29=0,0,IF('2020'!L29=0,0,'2021'!L29/'2020'!L29-1)) -> 0.29166667 | O29: =IF('2020'!N29="-",0,'2021'!N29-'2020'!N29) -> 0 | P29: =IF('2021'!N29=0,0,IF('2020'!N29="-",0,'2021'!N29/'2020'!N29-1)) -> 0
E30: ANNEMASSE_Clos Fleury | F30: France | G30: ='2021'!G30-'2020'!G30 -> 28 | H30: =IF('2021'!G30=0,0,IF('2020'!G30=0,0,'2021'!G30/'2020'!G30-1)) -> 0.13592233 | I30: ='2021'!H30-'2020'!H30 -> 57 | J30: =IF(I30=0,0,'2021'!H30/'2020'!H30-1) -> 0.81428571 | K30: ='2021'!J30-'2020'!J30 -> 12 | L30: =IF('2021'!J30=0,0,IF('2020'!J30=0,0,'2021'!J30/'2020'!J30-1)) -> 0.13793103 | M30: ='2021'!L30-'2020'!L30 -> 29 | N30: =IF('2021'!L30=0,0,IF('2020'!L30=0,0,'2021'!L30/'2020'!L30-1)) -> 0.34939759 | O30: =IF('2020'!N30="-",0,'2021'!N30-'2020'!N30) -> 0 | P30: =IF('2021'!N30=0,0,IF('2020'!N30="-",0,'2021'!N30/'2020'!N30-1)) -> 0 | U30: - | V30: - | W30: - | X30: -
E31: GAILLARD_Douane de Moïllesullaz | F31: Frontière | G31: ='2021'!G31-'2020'!G31 -> -16 | H31: =IF('2021'!G31=0,0,IF('2020'!G31=0,0,'2021'!G31/'2020'!G31-1)) -> -0.092485549 | I31: ='2021'!H31-'2020'!H31 -> 20 | J31: =IF(I31=0,0,'2021'!H31/'2020'!H31-1) -> 0.32258065 | K31: ='2021'!J31-'2020'!J31 -> -3 | L31: =IF('2021'!J31=0,0,IF('2020'!J31=0,0,'2021'!J31/'2020'!J31-1)) -> -0.076923077 | M31: ='2021'!L31-'2020'!L31 -> -26 | N31: =IF('2021'!L31=0,0,IF('2020'!L31=0,0,'2021'!L31/'2020'!L31-1)) -> -0.34666667 | O31: =IF('2020'!N31="-",0,'2021'!N31-'2020'!N31) -> 0 | P31: =IF('2021'!N31=0,0,IF('2020'!N31="-",0,'2021'!N31/'2020'!N31-1)) -> 0
D32: Sous-total | G32: ='2021'!G32-'2020'!G32 -> -904 | H32: =IF('2021'!G32=0,0,IF('2020'!G32=0,0,'2021'!G32/'2020'!G32-1)) -> -0.54326923 | I32: ='2021'!H32-'2020'!H32 -> -95 | J32: =IF(I32=0,0,'2021'!H32/'2020'!H32-1) -> -0.18664047 | K32: ='2021'!J32-'2020'!J32 -> -415 | L32: =IF('2021'!J32=0,0,IF('2020'!J32=0,0,'2021'!J32/'2020'!J32-1)) -> -0.58865248 | M32: ='2021'!L32-'2020'!L32 -> -383 | N32: =IF('2021'!L32=0,0,IF('2020'!L32=0,0,'2021'!L32/'2020'!L32-1)) -> -0.54949785 | O32: =IF('2020'!N32="-",0,'2021'!N32-'2020'!N32) -> 0 | P32: =IF('2021'!N32=0,0,IF('2020'!N32="-",0,'2021'!N32/'2020'!N32-1)) -> 0
B33: Salève Vivant | C33: NON | D33: 12 | E33: COLLONGES_Douane de Croix de Rozon | F33: Frontière | G33: ='2021'!G33-'2020'!G33 -> 29 | H33: =IF('2021'!G33=0,0,IF('2020'!G33=0,0,'2021'!G33/'2020'!G33-1)) -> 0.32954545 | I33: ='2021'!H33-'2020'!H33 -> -2 | J33: =IF(I33=0,0,'2021'!H33/'2020'!H33-1) -> -0.022727273 | K33: ='2021'!J33-'2020'!J33 -> 28 | L33: =IF('2021'!J33=0,0,IF('2020'!J33=0,0,'2021'!J33/'2020'!J33-1)) -> 0.52830189 | M33: ='2021'!L33-'2020'!L33 -> 15 | N33: =IF('2021'!L33=0,0,IF('2020'!L33=0,0,'2021'!L33/'2020'!L33-1)) -> 0.46875 | O33: =IF('2020'!N33="-",0,'2021'!N33-'2020'!N33) -> 6 | P33: =IF('2021'!N33=0,0,IF('2020'!N33="-",0,'2021'!N33/'2020'!N33-1)) -> 0.22222222 | U33: ='2021'!S33-'2020'!S33 -> 34 | V33: =IF('2021'!S33=0,0,IF('2020'!S33=0,0,'2021'!S33/'2020'!S33-1)) -> 0.43589744 | W33: ='2021'!U33-'2020'!U33 -> -5 | X33: =IF('2021'!U33=0,0,IF('2020'!U33=0,0,'2021'!U33/'2020'!U33-1)) -> -0.5
E34: ARCHAMPS_Douane de Landecy | F34: Frontière | G34: ='2021'!G34-'2020'!G34 -> 20 | H34: =IF('2021'!G34=0,0,IF('2020'!G34=0,0,'2021'!G34/'2020'!G34-1)) -> 0.60606061 | I34: ='2021'!H34-'2020'!H34 -> 5 | J34: =IF(I34=0,0,'2021'!H34/'2020'!H34-1) -> 0.15151515 | K34: ='2021'!J34-'2020'!J34 -> 11 | L34: =IF('2021'!J34=0,0,IF('2020'!J34=0,0,'2021'!J34/'2020'!J34-1)) -> 0.52380952 | M34: ='2021'!L34-'2020'!L34 -> 4 | N34: =IF('2021'!L34=0,0,IF('2020'!L34=0,0,'2021'!L34/'2020'!L34-1)) -> 0.5 | O34: =IF('2020'!N34="-",0,'2021'!N34-'2020'!N34) -> 3 | P34: =IF('2021'!N34=0,0,IF('2020'!N34="-",0,'2021'!N34/'2020'!N34-1)) -> 0.42857143 | U34: ='2021'!S34-'2020'!S34 -> 18 | V34: =IF('2021'!S34=0,0,IF('2020'!S34=0,0,'2021'!S34/'2020'!S34-1)) -> 0.54545455 | W34: ='2021'!U34-'2020'!U34 -> 2 | X34: =IF('2021'!U34=0,0,IF('2020'!U34=0,0,'2021'!U34/'2020'!U34-1)) -> 0
E35: BOSSEY_Douane de Pierre-Grand | F35: Frontière | G35: ='2021'!G35-'2020'!G35 -> 8 | H35: =IF('2021'!G35=0,0,IF('2020'!G35=0,0,'2021'!G35/'2020'!G35-1)) -> 0.57142857 | I35: ='2021'!H35-'2020'!H35 -> 6 | J35: =IF(I35=0,0,'2021'!H35/'2020'!H35-1) -> 0.42857143 | K35: ='2021'!J35-'2020'!J35 -> 7 | L35: =IF('2021'!J35=0,0,IF('2020'!J35=0,0,'2021'!J35/'2020'!J35-1)) -> 0.77777778 | M35: ='2021'!L35-'2020'!L35 -> 5 | N35: =IF('2021'!L35=0,0,IF('2020'!L35=0,0,'2021'!L35/'2020'!L35-1)) -> 0.71428571 | O35: =IF('2020'!N35="-",0,'2021'!N35-'2020'!N35) -> 5 | P35: =IF('2021'!N35=0,0,IF('2020'!N35="-",0,'2021'!N35/'2020'!N35-1)) -> 1.25 | U35: ='2021'!S35-'2020'!S35 -> 8 | V35: =IF('2021'!S35=0,0,IF('2020'!S35=0,0,'2021'!S35/'2020'!S35-1)) -> 0.57142857 | W35: ='2021'!U35-'2020'!U35 -> 0 | X35: =IF('2021'!U35=0,0,IF('2020'!U35=0,0,'2021'!U35/'2020'!U35-1)) -> 0
E36: BOSSEY_Douane de Troinex/Bossey | F36: Frontière | G36: ='2021'!G36-'2020'!G36 -> 26 | H36: =IF('2021'!G36=0,0,IF('2020'!G36=0,0,'2021'!G36/'2020'!G36-1)) -> 1.1304348 | I36: ='2021'!H36-'2020'!H36 -> 10 | J36: =IF(I36=0,0,'2021'!H36/'2020'!H36-1) -> 0.43478261 | K36: ='2021'!J36-'2020'!J36 -> 20 | L36: =IF('2021'!J36=0,0,IF('2020'!J36=0,0,'2021'!J36/'2020'!J36-1)) -> 1.3333333 | M36: ='2021'!L36-'2020'!L36 -> 9 | N36: =IF('2021'!L36=0,0,IF('2020'!L36=0,0,'2021'!L36/'2020'!L36-1)) -> 0.81818182 | O36: =IF('2020'!N36="-",0,'2021'!N36-'2020'!N36) -> 9 | P36: =IF('2021'!N36=0,0,IF('2020'!N36="-",0,'2021'!N36/'2020'!N36-1)) -> 1.125 | U36: ='2021'!S36-'2020'!S36 -> 26 | V36: =IF('2021'!S36=0,0,IF('2020'!S36=0,0,'2021'!S36/'2020'!S36-1)) -> 1.3 | W36: ='2021'!U36-'2020'!U36 -> 0 | X36: =IF('2021'!U36=0,0,IF('2020'!U36=0,0,'2021'!U36/'2020'!U36-1)) -> 0
E37: VEYRIER_Douane du Pas de l'Echelle | F37: Frontière | G37: ='2021'!G37-'2020'!G37 -> 8 | H37: =IF('2021'!G37=0,0,IF('2020'!G37=0,0,'2021'!G37/'2020'!G37-1)) -> 0.22222222 | I37: ='2021'!H37-'2020'!H37 -> 8 | J37: =IF(I37=0,0,'2021'!H37/'2020'!H37-1) -> 0.22222222 | K37: ='2021'!J37-'2020'!J37 -> 10 | L37: =IF('2021'!J37=0,0,IF('2020'!J37=0,0,'2021'!J37/'2020'!J37-1)) -> 0.55555556 | M37: ='2021'!L37-'2020'!L37 -> -1 | N37: =IF('2021'!L37=0,0,IF('2020'!L37=0,0,'2021'!L37/'2020'!L37-1)) -> -0.058823529 | O37: =IF('2020'!N37="-",0,'2021'!N37-'2020'!N37) -> 2 | P37: =IF('2021'!N37=0,0,IF('2020'!N37="-",0,'2021'!N37/'2020'!N37-1)) -> 0.15384615 | U37: ='2021'!S37-'2020'!S37 -> 4 | V37: =IF('2021'!S37=0,0,IF('2020'!S37=0,0,'2021'!S37/'2020'!S37-1)) -> 0.11111111 | W37: ='2021'!U37-'2020'!U37 -> 4 | X37: =IF('2021'!U37=0,0,IF('2020'!U37=0,0,'2021'!U37/'2020'!U37-1)) -> 0 | Y37: Compté par ProVélo en 2021 (Salève Vivant en 2020)
E38: ST-JULIEN_Douane de Charrot | F38: Frontière | G38: ='2021'!G38-'2020'!G38 -> -40 | H38: =IF('2021'!G38=0,0,IF('2020'!G38=0,0,'2021'!G38/'2020'!G38-1)) -> -0.88888889 | I38: ='2021'!H38-'2020'!H38 -> -41 | J38: =IF(I38=0,0,'2021'!H38/'2020'!H38-1) -> -0.91111111 | K38: ='2021'!J38-'2020'!J38 -> -24 | L38: =IF('2021'!J38=0,0,IF('2020'!J38=0,0,'2021'!J38/'2020'!J38-1)) -> -0.92307692 | M38: ='2021'!L38-'2020'!L38 -> -18 | N38: =IF('2021'!L38=0,0,IF('2020'!L38=0,0,'2021'!L38/'2020'!L38-1)) -> -0.94736842 | O38: =IF('2020'!N38="-",0,'2021'!N38-'2020'!N38) -> -14 | P38: =IF('2021'!N38=0,0,IF('2020'!N38="-",0,'2021'!N38/'2020'!N38-1)) -> 0 | U38: ='2021'!S38-'2020'!S38 -> -34 | V38: =IF('2021'!S38=0,0,IF('2020'!S38=0,0,'2021'!S38/'2020'!S38-1)) -> -0.87179487 | W38: ='2021'!U38-'2020'!U38 -> -6 | X38: =IF('2021'!U38=0,0,IF('2020'!U38=0,0,'2021'!U38/'2020'!U38-1)) -> 0
D39: Sous-total | G39: ='2021'!G39-'2020'!G39 -> 51 | H39: =IF('2021'!G39=0,0,IF('2020'!G39=0,0,'2021'!G39/'2020'!G39-1)) -> 0.21338912 | I39: ='2021'!H39-'2020'!H39 -> -14 | J39: =IF(I39=0,0,'2021'!H39/'2020'!H39-1) -> -0.058577406 | K39: ='2021'!J39-'2020'!J39 -> 52 | L39: =IF('2021'!J39=0,0,IF('2020'!J39=0,0,'2021'!J39/'2020'!J39-1)) -> 0.36619718 | M39: ='2021'!L39-'2020'!L39 -> 14 | N39: =IF('2021'!L39=0,0,IF('2020'!L39=0,0,'2021'!L39/'2020'!L39-1)) -> 0.14893617 | O39: =IF('2020'!N39="-",0,'2021'!N39-'2020'!N39) -> 11 | P39: =IF('2021'!N39=0,0,IF('2020'!N39="-",0,'2021'!N39/'2020'!N39-1)) -> 0.15068493 | U39: =SUM(U33:U38) -> 56 | V39: =IF('2021'!S39=0,0,IF('2020'!S39=0,0,'2021'!S39/'2020'!S39-1)) -> 0.25454545 | W39: =SUM(W33:W38) -> -5 | X39: =IF('2021'!U39=0,0,IF('2020'!U39=0,0,'2021'!U39/'2020'!U39-1)) -> -0.26315789
B40: Groupe St-Julien | C40: NON | D40: 10 | E40: ST-JULIEN_Douane de Perly | F40: Frontière | G40: ='2021'!G40-'2020'!G40 -> 17 | H40: =IF('2021'!G40=0,0,IF('2020'!G40=0,0,'2021'!G40/'2020'!G40-1)) -> 0.28813559 | I40: ='2021'!H40-'2020'!H40 -> 17 | J40: =IF(I40=0,0,'2021'!H40/'2020'!H40-1) -> 0.28813559 | K40: ='2021'!J40-'2020'!J40 -> 7.91 | L40: =IF('2021'!J40=0,0,IF('2020'!J40=0,0,'2021'!J40/'2020'!J40-1)) -> 0.26287803 | M40: ='2021'!L40-'2020'!L40 -> 3.04 | N40: =IF('2021'!L40=0,0,IF('2020'!L40=0,0,'2021'!L40/'2020'!L40-1)) -> 0.11710324 | O40: =IF('2020'!N40="-",0,'2021'!N40-'2020'!N40) -> 4.9048 | P40: =IF('2021'!N40=0,0,IF('2020'!N40="-",0,'2021'!N40/'2020'!N40-1)) -> 0.30473682 | U40: ='2021'!S40-'2020'!S40 -> 75 | V40: =IF('2021'!S40=0,0,IF('2020'!S40=0,0,'2021'!S40/'2020'!S40-1)) -> 0 | W40: ='2021'!U40-'2020'!U40 -> 1 | X40: =IF('2021'!U40=0,0,IF('2020'!U40=0,0,'2021'!U40/'2020'!U40-1)) -> 0
E41: ST-JULIEN_Passage douanier des Crottes | F41: Frontière | G41: ='2021'!G41-'2020'!G41 -> 35 | H41: =IF('2021'!G41=0,0,IF('2020'!G41=0,0,'2021'!G41/'2020'!G41-1)) -> 0.77777778 | I41: ='2021'!H41-'2020'!H41 -> 35 | J41: =IF(I41=0,0,'2021'!H41/'2020'!H41-1) -> 0.77777778 | K41: ='2021'!J41-'2020'!J41 -> 24.9 | L41: =IF('2021'!J41=0,0,IF('2020'!J41=0,0,'2021'!J41/'2020'!J41-1)) -> 0.95402299 | M41: ='2021'!L41-'2020'!L41 -> 20.2 | N41: =IF('2021'!L41=0,0,IF('2020'!L41=0,0,'2021'!L41/'2020'!L41-1)) -> 1.020202 | O41: =IF('2020'!N41="-",0,'2021'!N41-'2020'!N41) -> 13.13 | P41: =IF('2021'!N41=0,0,IF('2020'!N41="-",0,'2021'!N41/'2020'!N41-1)) -> 1.020202 | U41: ='2021'!S41-'2020'!S41 -> 74 | V41: =IF('2021'!S41=0,0,IF('2020'!S41=0,0,'2021'!S41/'2020'!S41-1)) -> 0 | W41: ='2021'!U41-'2020'!U41 -> 6 | X41: =IF('2021'!U41=0,0,IF('2020'!U41=0,0,'2021'!U41/'2020'!U41-1)) -> 0
...
