Workbook

Sheet Index
C3: Eléments à renseigner par chaque association dans l'onglet "2022"
D5: Colonne | F5: Ce qu'il faut renseigner
D7: Toutes les cellules blanches ne sont pas à renseigner (formule de calcul ou NC)
D9: Eléments obligatoires >> cellules en vert dans l'onglet "2022"
D10: DONNEES GENERALES | E10: D | F10: nombre de bénévoles par poste de comptage
E11: E | F11: nom/localisation du poste de comptage
E12: F | F12: implantation : France / Suisse / Frontière
E13: G | F13: nombre total de cyclistes comptés sur toute la période
E14: H | F14: nombre de cyclistes comptés sur l'heure de pointe (7h30 - 8h30) uniquement
E15: I | F15: calcul automatique (du nombre de VAE dans le total)
E16: J | F16: nombre de VAE dans le total (référence à la colonne G)
E17: K | F17: calcul automatique (du nombre de femmes dans le total)
E18: L | F18: nombre de femmes dans le total (référence à la colonne G)
D20: Eléments obligatoires pour les postes frontières et carrefours proches frontière
D21: >> cellules en bleu dans l'onglet "2022"
D22: FRONTIERE | E22: S | F22: nombre total de cyclistes comptés sur toute la période - Direction Suisse
E23: T | F23: nombre de cyclistes comptés sur l'heure de pointe (7h30 - 8h30) uniquement - Direction Suisse
E24: U | F24: nombre total de cyclistes comptés sur toute la période - Direction France
E25: V | F25: nombre de cyclistes comptés sur l'heure de pointe (7h30 - 8h30) uniquement - Direction France
D27: Eléments facultatifs >> cellules en rose dans l'onglet "2022"
D28: AUTRES DONNEES | E28: M | F28: calcul automatique (du nombre total de VAE chez les femmes)
E29: N | F29: nombre total de VAE chez les femmes (valeur spécifique à relever)
E30: O | F30: nombre total de personnes comptées sur toute la période en "autre mode" (trottinette, gyropode…)
E31: P | F31: nombre total de personnes comptées en HPM (7h30 - 8h30) en "autre mode" (trottinette, gyropode…)
E32: Q | F32: nombre total de piétons comptés sur toute la période
E33: R | F33: nombre total de piétons comptés en HPM (7h30 - 8h30)

Sheet 2020
B2: Association(s) | C2: Arrière-pays | D2: Nombre de bénévoles | E2: Postes de comptage | F2: France / Suisse / Frontière | G2: Nombre de vélos | I2: % VAE dans le total | J2: NB VAE dans le total | K2: % femmes dans le total | L2: NB de femmes dans le total | M2: % de VAE chez les femmes | N2: NB de VAE chez les femmes | O2: Autres modes | Q2: Piétons | S2: > Suisse | U2: > France
G4: total | H4: HP | O4: total | P4: HP | Q4: total | R4: HP | S4: total | T4: HP | U4: total | V4: HP
B5: UP Cluses | C5: OUI | D5: 2 | E5: CLUSES_Passerelle de Messy | F5: France | G5: =27+11+2+15+8 -> 63 | H5: 29 | I5: =2/G5 -> 0.031746032 | J5: =I5*G5 -> 2 | K5: =(2+15)/G5 -> 0.26984127 | L5: =K5*G5 -> 17 | M5: =2/17 -> 0.11764706 | N5: =IF(M5="-","-",M5*L5) -> 2
B6: L'Abeille (Contamine) | C6: OUI | D6: 2 | E6: BONNE_Loëx (sous voie rapide) | F6: France | I6: =2/G6 -> #DIV/0! | K6: =(2+15)/G6 -> #DIV/0! | M6: =2/17 -> 0.11764706
B7: ACMB (Chablais) | C7: OUI | D7: 8 | E7: COMMUNE_Carrefour | F7: France | I7: 0.32258065 | K7: 0.32258065 | M7: - | N7: - | O7: - | P7: - | Q7: - | R7: -
E8: COMMUNE_Carrefour | F8: France | I8: 0.48 | K8: 0.36 | M8: - | N8: - | O8: - | P8: - | Q8: - | R8: -
E9: COMMUNE_Carrefour | F9: France | I9: 0.5 | K9: 0.16666667 | M9: - | N9: - | O9: - | P9: - | Q9: - | R9: -
E10: COMMUNE_Carrefour | I10: 0.5 | K10: 0.16666667 | M10: - | N10: - | O10: - | P10: - | Q10: - | R10: -
E11: COMMUNE_Carrefour | F11: France | I11: 0.071428571 | K11: 0.071428571 | M11: - | N11: - | O11: - | P11: - | Q11: - | R11: -
E12: COMMUNE_Carrefour | F12: France | I12: 0.041666667 | K12: 0.20833333 | M12: - | N12: - | O12: - | P12: - | Q12: - | R12: -
E13: COMMUNE_Carrefour | F13: France | I13: 0 | K13: 0.4137931 | M13: - | N13: - | O13: - | P13: - | Q13: - | R13: -
E14: COMMUNE_Carrefour | F14: France | I14: 0.25925926 | K14: 0.48148148 | M14: - | N14: - | O14: - | P14: - | Q14: - | R14: -
E15: COMMUNE_Carrefour | I15: 0.25925926 | K15: 0.48148148 | M15: - | N15: - | O15: - | P15: - | Q15: - | R15: -
E16: COMMUNE_Carrefour | I16: 0.25925926 | K16: 0.48148148 | M16: - | N16: - | O16: - | P16: - | Q16: - | R16: -
I17: 0.25925926 | K17: 0.48148148 | M17: - | N17: - | O17: - | P17: - | Q17: - | R17: -
I18: 0.25925926 | K18: 0.48148148 | M18: - | N18: - | O18: - | P18: - | Q18: - | R18: -
E19: COMMUNE_Carrefour | F19: France | I19: 0.5 | K19: 0 | M19: - | N19: - | O19: - | P19: - | Q19: - | R19: -
D20: Sous-total | G20: =SUM(G7:G19) -> 0 | H20: =SUM(H7:H19) -> 0 | I20: =J20/G20 -> #DIV/0! | J20: =SUM(J7:J19) -> 0 | K20: =L20/G20 -> #DIV/0! | L20: =SUM(L7:L19) -> 0 | M20: =N20/L20 -> #DIV/0! | N20: =SUM(N7:N19) -> 0
B21: NatEnv & Fabrique à Biclou | C21: OUI | D21: 8 | E21: LA ROCHE_Carrefour Biocoop | F21: France | G21: 31 | H21: 23 | I21: 0.32258065 | J21: =I21*G21 -> 10 | K21: 0.32258065 | L21: =K21*G21 -> 10 | M21: - | N21: - | O21: - | P21: - | Q21: - | R21: -
E22: LA ROCHE_Giratoire La Poste | F22: France | G22: 25 | H22: 13 | I22: 0.48 | J22: =I22*G22 -> 12 | K22: 0.36 | L22: =K22*G22 -> 9 | M22: - | N22: - | O22: - | P22: - | Q22: - | R22: -
E23: LA ROCHE_Giratoire ENILV | F23: France | G23: 18 | H23: 10 | I23: 0.5 | J23: =I23*G23 -> 9 | K23: 0.16666667 | L23: =K23*G23 -> 3 | M23: - | N23: - | O23: - | P23: - | Q23: - | R23: -
I24: 0.5 | K24: 0.16666667 | M24: - | N24: - | O24: - | P24: - | Q24: - | R24: -
E25: ARENTHON_La Papeterie | F25: France | G25: 14 | H25: 9 | I25: 0.071428571 | J25: =I25*G25 -> 1 | K25: 0.071428571 | L25: =K25*G25 -> 1 | M25: - | N25: - | O25: - | P25: - | Q25: - | R25: -
E26: ST-PIERRE_Franchissement Borne-Dessy | F26: France | G26: 24 | H26: 16 | I26: 0.041666667 | J26: =I26*G26 -> 1 | K26: 0.20833333 | L26: =K26*G26 -> 5 | M26: - | N26: - | O26: - | P26: - | Q26: - | R26: -
E27: BONNEVILLE_Franchissement Borne-Tucinge | F27: France | G27: 29 | H27: 21 | I27: 0 | J27: =I27*G27 -> 0 | K27: 0.4137931 | L27: =K27*G27 -> 12 | M27: - | N27: - | O27: - | P27: - | Q27: - | R27: -
E28: ST-PIERRE_Pont principal sur le Borne | F28: France | G28: 27 | H28: 17 | I28: 0.25925926 | J28: =I28*G28 -> 7 | K28: 0.48148148 | L28: =K28*G28 -> 13 | M28: - | N28: - | O28: - | P28: - | Q28: - | R28: -
I29: 0.25925926 | K29: 0.48148148 | M29: - | N29: - | O29: - | P29: - | Q29: - | R29: -
I30: 0.25925926 | K30: 0.48148148 | M30: - | N30: - | O30: - | P30: - | Q30: - | R30: -
E31: AMANCY_Giratoire Coriandre | F31: France | G31: 4 | H31: 2 | I31: 0.5 | J31: =I31*G31 -> 2 | K31: 0 | L31: =K31*G31 -> 0 | M31: - | N31: - | O31: - | P31: - | Q31: - | R31: -
D32: Sous-total | G32: =SUM(G21:G31) -> 172 | H32: =SUM(H21:H31) -> 111 | I32: =J32/G32 -> 0.24418605 | J32: =SUM(J21:J31) -> 42 | K32: =L32/G32 -> 0.30813953 | L32: =SUM(L21:L31) -> 53 | M32: =N32/L32 -> 0 | N32: =SUM(N21:N31) -> 0
B33: AERE | C33: OUI | D33: 9 | E33: ETREMBIERES_Giratoire ex PN93 | F33: France | G33: 37 | H33: 23 | I33: 0.38 | J33: =I33*G33 -> 14.06 | K33: 0.16 | L33: =K33*G33 -> 5.92 | M33: 1 | N33: =IF(M33="-","-",M33*L33) -> 5.92
E34: ETREMBIERES_Carrefour sous Château | F34: France | G34: 33 | H34: 15 | I34: 0.3 | J34: =I34*G34 -> 9.9 | K34: 0.09 | L34: =K34*G34 -> 2.97 | M34: 1 | N34: =IF(M34="-","-",M34*L34) -> 2.97
E35: SCIENTRIER_Carrefour Tour de Bellecombe | F35: France | G35: 6 | H35: 5 | I35: 0 | J35: =I35*G35 -> 0 | K35: 0 | L35: =K35*G35 -> 0 | M35: 0 | N35: =IF(M35="-","-",M35*L35) -> 0
E36: REIGNIER_Giratoire église | F36: France | G36: 25 | H36: 15 | I36: 0.28 | J36: =I36*G36 -> 7 | K36: 0.16 | L36: =K36*G36 -> 4 | M36: 0.25 | N36: =IF(M36="-","-",M36*L36) -> 1
E37: REIGNIER_Giratoire Foron | F37: France | G37: 15 | H37: 9 | I37: 0.13 | J37: =I37*G37 -> 1.95 | K37: 0.07 | L37: =K37*G37 -> 1.05 | M37: 0 | N37: =IF(M37="-","-",M37*L37) -> 0
E38: REIGNIER_Giratoire La Forge | F38: France | G38: 16 | H38: 14 | I38: 0.38 | J38: =I38*G38 -> 6.08 | K38: 0.13 | L38: =K38*G38 -> 2.08 | M38: 1 | N38: =IF(M38="-","-",M38*L38) -> 2.08
E39: PERS-JUSSY_Giratoire Casino | F39: France | G39: 7 | H39: 5 | I39: 0.14 | J39: =I39*G39 -> 0.98 | K39: 0 | L39: =K39*G39 -> 0 | M39: 0 | N39: =IF(M39="-","-",M39*L39) -> 0
I40: 0.14 | K40: 0 | M40: 0
I41: 0.14 | K41: 0 | M41: 0
E42: ARTHAZ_Giratoire lavage auto | F42: France | G42: 20 | H42: 9 | I42: 0.25 | J42: =I42*G42 -> 5 | K42: 0.15 | L42: =K42*G42 -> 3 | M42: 0.33 | N42: =IF(M42="-","-",M42*L42) -> 0.99
...

Sheet 2021
B2: Association(s) | C2: Arrière-pays | D2: Nombre de bénévoles | E2: Postes de comptage | F2: France / Suisse / Frontière | G2: Nombre de vélos | I2: % VAE dans le total | J2: NB VAE dans le total | K2: % femmes dans le total | L2: NB de femmes dans le total | M2: % de VAE chez les femmes | N2: NB de VAE chez les femmes | O2: Autres modes | Q2: Piétons | S2: > Suisse | U2: > France
G4: total | H4: HP | O4: total | P4: HP | Q4: total | R4: HP | S4: total | T4: HP | U4: total | V4: HP
B5: Université Populaire de Cluses | C5: OUI | D5: 2 | E5: CLUSES_Passerelle de Messy | F5: France | G5: 102 | H5: 94 | I5: =J5/G5 -> 0.019607843 | J5: 2 | K5: =L5/G5 -> 0.17647059 | L5: 18 | M5: =IF(N5="-","-",N5/L5) -> 0.11111111 | N5: 2 | O5: - | P5: - | Q5: - | R5: - | S5: - | T5: - | U5: - | V5: - | W5: OK | Y5: =IF(G5="","",1) -> 1
B6: L'Abeille (Contamine) | C6: OUI | D6: 2 | E6: BONNE_Loëx (sous voie rapide) | F6: France | I6: =J6/G6 -> #DIV/0! | K6: =L6/G6 -> #DIV/0! | M6: =IF(N6="-","-",N6/L6) -> #DIV/0! | O6: - | P6: - | Q6: - | R6: - | S6: - | T6: - | U6: - | V6: - | W6: OK | Y6: =IF(G6="","",1)
B7: ACMB (Chablais) | C7: OUI | D7: 9 | E7: COMMUNE_Carrefour | F7: France | I7: =J7/G7 -> #DIV/0! | K7: =L7/G7 -> #DIV/0! | M7: =IF(N7="-","-",N7/L7) -> - | N7: - | O7: - | P7: - | Q7: - | R7: - | S7: - | T7: - | U7: - | V7: - | W7: OK | Y7: =IF(G7="","",1)
E8: COMMUNE_Carrefour | F8: France | I8: =J8/G8 -> #DIV/0! | K8: =L8/G8 -> #DIV/0! | M8: =IF(N8="-","-",N8/L8) -> - | N8: - | O8: - | P8: - | Q8: - | R8: - | S8: - | T8: - | U8: - | V8: - | W8: OK | Y8: =IF(G8="","",1)
E9: COMMUNE_Carrefour | F9: France | I9: =J9/G9 -> #DIV/0! | K9: =L9/G9 -> #DIV/0! | M9: =IF(N9="-","-",N9/L9) -> - | N9: - | O9: - | P9: - | Q9: - | R9: - | S9: - | T9: - | U9: - | V9: - | W9: OK | Y9: =IF(G9="","",1)
E10: COMMUNE_Carrefour | F10: France | I10: =J10/G10 -> #DIV/0! | K10: =L10/G10 -> #DIV/0! | M10: =IF(N10="-","-",N10/L10) -> - | N10: - | O10: - | P10: - | Q10: - | R10: - | W10: OK | Y10: =IF(G10="","",1)
E11: COMMUNE_Carrefour | F11: France | I11: =J11/G11 -> #DIV/0! | K11: =L11/G11 -> #DIV/0! | M11: =IF(N11="-","-",N11/L11) -> - | N11: - | O11: - | P11: - | Q11: - | R11: - | S11: - | T11: - | U11: - | V11: - | W11: OK | Y11: =IF(G11="","",1)
E12: COMMUNE_Carrefour | F12: France | I12: =J12/G12 -> #DIV/0! | K12: =L12/G12 -> #DIV/0! | M12: =IF(N12="-","-",N12/L12) -> - | N12: - | O12: - | P12: - | Q12: - | R12: - | S12: - | T12: - | U12: - | V12: - | W12: OK | Y12: =IF(G12="","",1)
E13: COMMUNE_Carrefour | F13: France | I13: =J13/G13 -> #DIV/0! | K13: =L13/G13 -> #DIV/0! | M13: =IF(N13="-","-",N13/L13) -> - | N13: - | O13: - | P13: - | Q13: - | R13: - | S13: - | T13: - | U13: - | V13: - | W13: OK | Y13: =IF(G13="","",1)
E14: COMMUNE_Carrefour | F14: France | I14: =J14/G14 -> #DIV/0! | K14: =L14/G14 -> #DIV/0! | M14: =IF(N14="-","-",N14/L14) -> - | N14: - | O14: - | P14: - | Q14: - | R14: - | S14: - | T14: - | U14: - | V14: - | W14: OK | Y14: =IF(G14="","",1)
E15: COMMUNE_Carrefour | I15: =J15/G15 -> #DIV/0! | K15: =L15/G15 -> #DIV/0! | M15: =IF(N15="-","-",N15/L15) -> - | N15: - | O15: - | P15: - | Q15: - | R15: -
E16: COMMUNE_Carrefour | I16: =J16/G16 -> #DIV/0! | K16: =L16/G16 -> #DIV/0! | M16: =IF(N16="-","-",N16/L16) -> - | N16: - | O16: - | P16: - | Q16: - | R16: -
I17: =J17/G17 -> #DIV/0! | K17: =L17/G17 -> #DIV/0! | M17: =IF(N17="-","-",N17/L17) -> - | N17: - | O17: - | P17: - | Q17: - | R17: -
I18: =J18/G18 -> #DIV/0! | K18: =L18/G18 -> #DIV/0! | M18: =IF(N18="-","-",N18/L18) -> - | N18: - | O18: - | P18: - | Q18: - | R18: -
E19: COMMUNE_Carrefour | F19: France | I19: =J19/G19 -> #DIV/0! | K19: =L19/G19 -> #DIV/0! | M19: =IF(N19="-","-",N19/L19) -> - | N19: - | O19: - | P19: - | Q19: - | R19: - | S19: - | T19: - | U19: - | V19: - | W19: OK | Y19: =IF(G19="","",1)
D20: Sous-total | G20: =SUM(G7:G19) -> 0 | H20: =SUM(H7:H19) -> 0 | I20: =J20/G20 -> #DIV/0! | J20: =SUM(J7:J19) -> 0 | K20: =L20/G20 -> #DIV/0! | L20: =SUM(L7:L19) -> 0 | M20: =N20/L20 -> #DIV/0! | N20: =SUM(N7:N19) -> 0 | W20: OK
B21: NatEnv (Nature Environnement en Pays rochois) Fabrique à Biclou Pays rochois en Transition | C21: OUI | D21: 9 | E21: LA ROCHE_Carrefour Biocoop | F21: France | G21: 76 | H21: 50 | I21: =J21/G21 -> 0.22368421 | J21: 17 | K21: =L21/G21 -> 0.36842105 | L21: 28 | M21: =IF(N21="-","-",N21/L21) -> - | N21: - | O21: - | P21: - | Q21: - | R21: - | S21: - | T21: - | U21: - | V21: - | W21: OK | Y21: =IF(G21="","",1) -> 1
E22: LA ROCHE_Giratoire La Poste | F22: France | G22: 45 | H22: 27 | I22: =J22/G22 -> 0.46666667 | J22: 21 | K22: =L22/G22 -> 0.31111111 | L22: 14 | M22: =IF(N22="-","-",N22/L22) -> - | N22: - | O22: - | P22: - | Q22: - | R22: - | S22: - | T22: - | U22: - | V22: - | W22: OK | Y22: =IF(G22="","",1) -> 1
E23: LA ROCHE_Giratoire ENILV | F23: France | G23: 16 | H23: 10 | I23: =J23/G23 -> 0.3125 | J23: 5 | K23: =L23/G23 -> 0.1875 | L23: 3 | M23: =IF(N23="-","-",N23/L23) -> - | N23: - | O23: - | P23: - | Q23: - | R23: - | S23: - | T23: - | U23: - | V23: - | W23: OK | Y23: =IF(G23="","",1) -> 1
E24: LA ROCHE_Gare Passage à niveau (new 2021) | F24: France | G24: 56 | H24: 36 | I24: =J24/G24 -> 0.21428571 | J24: 12 | K24: =L24/G24 -> 0.17857143 | L24: 10 | M24: =IF(N24="-","-",N24/L24) -> - | N24: - | O24: - | P24: - | Q24: - | R24: - | W24: OK | Y24: =IF(G24="","",1) -> 1
E25: ARENTHON_La Papeterie | F25: France | G25: 13 | H25: 8 | I25: =J25/G25 -> 0.53846154 | J25: 7 | K25: =L25/G25 -> 0.46153846 | L25: 6 | M25: =IF(N25="-","-",N25/L25) -> - | N25: - | O25: - | P25: - | Q25: - | R25: - | S25: - | T25: - | U25: - | V25: - | W25: OK | Y25: =IF(G25="","",1) -> 1
E26: ST-PIERRE_Franchissement Borne-Dessy | F26: France | G26: 24 | H26: 20 | I26: =J26/G26 -> 0.29166667 | J26: 7 | K26: =L26/G26 -> 0.29166667 | L26: 7 | M26: =IF(N26="-","-",N26/L26) -> - | N26: - | O26: - | P26: - | Q26: - | R26: - | S26: - | T26: - | U26: - | V26: - | W26: OK | Y26: =IF(G26="","",1) -> 1
E27: BONNEVILLE_Franchissement Borne-Tucinge | F27: France | G27: 33 | H27: 25 | I27: =J27/G27 -> 0 | J27: 0 | K27: =L27/G27 -> 0.21212121 | L27: 7 | M27: =IF(N27="-","-",N27/L27) -> - | N27: - | O27: - | P27: - | Q27: - | R27: - | S27: - | T27: - | U27: - | V27: - | W27: OK | Y27: =IF(G27="","",1) -> 1
E28: ST-PIERRE_Pont principal sur le Borne | F28: France | G28: 32 | H28: 17 | I28: =J28/G28 -> 0.15625 | J28: 5 | K28: =L28/G28 -> 0.375 | L28: 12 | M28: =IF(N28="-","-",N28/L28) -> - | N28: - | O28: - | P28: - | Q28: - | R28: - | S28: - | T28: - | U28: - | V28: - | W28: OK | Y28: =IF(G28="","",1) -> 1
I29: =J29/G29 -> #DIV/0! | K29: =L29/G29 -> #DIV/0! | M29: =IF(N29="-","-",N29/L29) -> - | N29: - | O29: - | P29: - | Q29: - | R29: -
I30: =J30/G30 -> #DIV/0! | K30: =L30/G30 -> #DIV/0! | M30: =IF(N30="-","-",N30/L30) -> - | N30: - | O30: - | P30: - | Q30: - | R30: -
E31: AMANCY_Giratoire Coriandre | F31: France | I31: =J31/G31 -> #DIV/0! | K31: =L31/G31 -> #DIV/0! | M31: =IF(N31="-","-",N31/L31) -> - | N31: - | O31: - | P31: - | Q31: - | R31: - | S31: - | T31: - | U31: - | V31: - | W31: OK | Y31: =IF(G31="","",1)
D32: Sous-total | G32: =SUM(G21:G31) -> 295 | H32: =SUM(H21:H31) -> 193 | I32: =J32/G32 -> 0.25084746 | J32: =SUM(J21:J31) -> 74 | K32: =L32/G32 -> 0.29491525 | L32: =SUM(L21:L31) -> 87 | M32: =N32/L32 -> 0 | N32: =SUM(N21:N31) -> 0 | W32: OK
B33: AERE (Association Environnement Reignier-Esery) | C33: OUI | D33: 9 | E33: ETREMBIERES_Giratoire ex PN93 | F33: France | G33: 46 | H33: 32 | I33: =J33/G33 -> 0.65217391 | J33: 30 | K33: =L33/G33 -> 0.19565217 | L33: 9 | M33: =IF(N33="-","-",N33/L33) -> 1 | N33: 9 | O33: - | P33: - | Q33: - | R33: - | S33: - | T33: - | U33: - | V33: - | W33: OK | Y33: =IF(G33="","",1) -> 1
E34: ETREMBIERES_Carrefour sous Château | F34: France | G34: 28 | H34: 17 | I34: =J34/G34 -> 0.64285714 | J34: 18 | K34: =L34/G34 -> 0.32142857 | L34: 9 | M34: =IF(N34="-","-",N34/L34) -> 0.77777778 | N34: 7 | O34: - | P34: - | Q34: - | R34: - | S34: - | T34: - | U34: - | V34: - | W34: OK | Y34: =IF(G34="","",1) -> 1
E35: SCIENTRIER_Carrefour Tour de Bellecombe | F35: France | G35: 5 | H35: 5 | I35: =J35/G35 -> 0.6 | J35: 3 | K35: =L35/G35 -> 0.2 | L35: 1 | M35: =IF(N35="-","-",N35/L35) -> 1 | N35: 1 | O35: - | P35: - | Q35: - | R35: - | S35: - | T35: - | U35: - | V35: - | W35: OK | Y35: =IF(G35="","",1) -> 1
E36: REIGNIER_Giratoire église | F36: France | G36: 45 | H36: 26 | I36: =J36/G36 -> 0.26666667 | J36: 12 | K36: =L36/G36 -> 0.26666667 | L36: 12 | M36: =IF(N36="-","-",N36/L36) -> 0.25 | N36: 3 | O36: - | P36: - | Q36: - | R36: - | S36: - | T36: - | U36: - | V36: - | W36: OK | Y36: =IF(G36="","",1) -> 1
E37: REIGNIER_Giratoire Foron | F37: France | G37: 14 | H37: 9 | I37: =J37/G37 -> 0.21428571 | J37: 3 | K37: =L37/G37 -> 0.14285714 | L37: 2 | M37: =IF(N37="-","-",N37/L37) -> 0.5 | N37: 1 | O37: - | P37: - | Q37: - | R37: - | S37: - | T37: - | U37: - | V37: - | W37: OK | Y37: =IF(G37="","",1) -> 1
E38: REIGNIER_Giratoire La Forge | F38: France | G38: 31 | H38: 23 | I38: =J38/G38 -> 0.5483871 | J38: 17 | K38: =L38/G38 -> 0.16129032 | L38: 5 | M38: =IF(N38="-","-",N38/L38) -> 1 | N38: 5 | O38: - | P38: - | Q38: - | R38: - | S38: - | T38: - | U38: - | V38: - | W38: OK | Y38: =IF(G38="","",1) -> 1
E39: PERS-JUSSY_Giratoire Casino | F39: France | G39: 12 | H39: 7 | I39: =J39/G39 -> 0.33333333 | J39: 4 | K39: =L39/G39 -> 0.33333333 | L39: 4 | M39: =IF(N39="-","-",N39/L39) -> 0.5 | N39: 2 | O39: - | P39: - | Q39: - | R39: - | S39: - | T39: - | U39: - | V39: - | W39: OK | Y39: =IF(G39="","",1) -> 1
I40: =J40/G40 -> #DIV/0! | K40: =L40/G40 -> #DIV/0! | M40: =IF(N40="-","-",N40/L40) -> #DIV/0!
I41: =J41/G41 -> #DIV/0! | K41: =L41/G41 -> #DIV/0! | M41: =IF(N41="-","-",N41/L41) -> #DIV/0!
E42: ARTHAZ_Giratoire lavage auto | F42: France | G42: 17 | H42: 9 | I42: =J42/G42 -> 0.41176471 | J42: 7 | K42: =L42/G42 -> 0.23529412 | L42: 4 | M42: =IF(N42="-","-",N42/L42) -> 0.25 | N42: 1 | O42: - | P42: - | Q42: - | R42: - | S42: - | T42: - | U42: - | V42: - | W42: OK | Y42: =IF(G42="","",1) -> 1
...

Sheet 2022
B2: Association(s) | C2: Arrière-pays | D2: Nombre de bénévoles | E2: Postes de comptage | F2: France / Suisse / Frontière | G2: Nombre de vélos | I2: % VAE dans le total | J2: NB VAE dans le total | K2: % femmes dans le total | L2: NB de femmes dans le total | M2: % de VAE chez les femmes | N2: NB de VAE chez les femmes | O2: Autres modes | Q2: Piétons | S2: > Suisse | U2: > France
G4: total | H4: HP | O4: total | P4: HP | Q4: total | R4: HP | S4: total | T4: HP | U4: total | V4: HP
B5: Université Populaire de Cluses | C5: OUI | D5: 2 | E5: CLUSES_Passerelle de Messy | F5: France | I5: =J5/G5 -> #DIV/0! | K5: =L5/G5 -> #DIV/0! | M5: =IF(N5="-","-",N5/L5) -> #DIV/0! | S5: - | T5: - | U5: - | V5: -
B6: L'Abeille (Contamine) | C6: OUI | D6: 2 | E6: BONNE_Loëx (sous voie rapide) | F6: France | I6: =J6/G6 -> #DIV/0! | K6: =L6/G6 -> #DIV/0! | M6: =IF(N6="-","-",N6/L6) -> #DIV/0! | S6: - | T6: - | U6: - | V6: -
B7: ACMB (Chablais) | C7: OUI | D7: 9 | E7: COMMUNE_Carrefour | F7: France | I7: =J7/G7 -> #DIV/0! | K7: =L7/G7 -> #DIV/0! | M7: =IF(N7="-","-",N7/L7) -> #DIV/0! | S7: - | T7: - | U7: - | V7: -
E8: COMMUNE_Carrefour | F8: France | I8: =J8/G8 -> #DIV/0! | K8: =L8/G8 -> #DIV/0! | M8: =IF(N8="-","-",N8/L8) -> #DIV/0! | S8: - | T8: - | U8: - | V8: -
E9: COMMUNE_Carrefour | F9: France | I9: =J9/G9 -> #DIV/0! | K9: =L9/G9 -> #DIV/0! | M9: =IF(N9="-","-",N9/L9) -> #DIV/0! | S9: - | T9: - | U9: - | V9: -
E10: COMMUNE_Carrefour | F10: France | I10: =J10/G10 -> #DIV/0! | K10: =L10/G10 -> #DIV/0! | M10: =IF(N10="-","-",N10/L10) -> #DIV/0! | S10: - | T10: - | U10: - | V10: -
E11: COMMUNE_Carrefour | F11: France | I11: =J11/G11 -> #DIV/0! | K11: =L11/G11 -> #DIV/0! | M11: =IF(N11="-","-",N11/L11) -> #DIV/0! | S11: - | T11: - | U11: - | V11: -
E12: COMMUNE_Carrefour | F12: France | I12: =J12/G12 -> #DIV/0! | K12: =L12/G12 -> #DIV/0! | M12: =IF(N12="-","-",N12/L12) -> #DIV/0! | S12: - | T12: - | U12: - | V12: -
E13: COMMUNE_Carrefour | F13: France | I13: =J13/G13 -> #DIV/0! | K13: =L13/G13 -> #DIV/0! | M13: =IF(N13="-","-",N13/L13) -> #DIV/0! | S13: - | T13: - | U13: - | V13: -
E14: COMMUNE_Carrefour | F14: France | I14: =J14/G14 -> #DIV/0! | K14: =L14/G14 -> #DIV/0! | M14: =IF(N14="-","-",N14/L14) -> #DIV/0! | S14: - | T14: - | U14: - | V14: -
E15: COMMUNE_Carrefour | I15: =J15/G15 -> #DIV/0! | K15: =L15/G15 -> #DIV/0! | M15: =IF(N15="-","-",N15/L15) -> #DIV/0! | S15: - | T15: - | U15: - | V15: -
E16: COMMUNE_Carrefour | I16: =J16/G16 -> #DIV/0! | K16: =L16/G16 -> #DIV/0! | M16: =IF(N16="-","-",N16/L16) -> #DIV/0! | S16: - | T16: - | U16: - | V16: -
I17: =J17/G17 -> #DIV/0! | K17: =L17/G17 -> #DIV/0! | M17: =IF(N17="-","-",N17/L17) -> #DIV/0! | S17: - | T17: - | U17: - | V17: -
I18: =J18/G18 -> #DIV/0! | K18: =L18/G18 -> #DIV/0! | M18: =IF(N18="-","-",N18/L18) -> #DIV/0! | S18: - | T18: - | U18: - | V18: -
E19: COMMUNE_Carrefour | F19: France | I19: =J19/G19 -> #DIV/0! | K19: =L19/G19 -> #DIV/0! | M19: =IF(N19="-","-",N19/L19) -> #DIV/0! | S19: - | T19: - | U19: - | V19: -
D20: Sous-total | G20: =SUM(G7:G19) -> 0 | H20: =SUM(H7:H19) -> 0 | I20: =J20/G20 -> #DIV/0! | J20: =SUM(J7:J19) -> 0 | K20: =L20/G20 -> #DIV/0! | L20: =SUM(L7:L19) -> 0 | M20: =N20/L20 -> #DIV/0! | N20: =SUM(N7:N19) -> 0 | O20: =SUM(O7:O19) -> 0 | P20: =SUM(P7:P19) -> 0 | Q20: =SUM(Q7:Q19) -> 0 | R20: =SUM(R7:R19) -> 0 | S20: =SUM(S7:S19) -> 0 | T20: =SUM(T7:T19) -> 0 | U20: =SUM(U7:U19) -> 0 | V20: =SUM(V7:V19) -> 0
B21: NatEnv (Nature Environnement en Pays rochois) Fabrique à Biclou Pays rochois en Transition | C21: OUI | D21: 9 | E21: LA ROCHE_Carrefour Biocoop | F21: France | I21: =J21/G21 -> #DIV/0! | K21: =L21/G21 -> #DIV/0! | M21: =IF(N21="-","-",N21/L21) -> #DIV/0! | S21: - | T21: - | U21: - | V21: -
E22: LA ROCHE_Giratoire La Poste | F22: France | I22: =J22/G22 -> #DIV/0! | K22: =L22/G22 -> #DIV/0! | M22: =IF(N22="-","-",N22/L22) -> #DIV/0! | S22: - | T22: - | U22: - | V22: -
E23: LA ROCHE_Giratoire ENILV | F23: France | I23: =J23/G23 -> #DIV/0! | K23: =L23/G23 -> #DIV/0! | M23: =IF(N23="-","-",N23/L23) -> #DIV/0! | S23: - | T23: - | U23: - | V23: -
E24: LA ROCHE_Gare Passage à niveau (new 2021) | F24: France | I24: =J24/G24 -> #DIV/0! | K24: =L24/G24 -> #DIV/0! | M24: =IF(N24="-","-",N24/L24) -> #DIV/0! | S24: - | T24: - | U24: - | V24: -
E25: ARENTHON_La Papeterie | F25: France | I25: =J25/G25 -> #DIV/0! | K25: =L25/G25 -> #DIV/0! | M25: =IF(N25="-","-",N25/L25) -> #DIV/0! | S25: - | T25: - | U25: - | V25: -
E26: ST-PIERRE_Franchissement Borne-Dessy | F26: France | I26: =J26/G26 -> #DIV/0! | K26: =L26/G26 -> #DIV/0! | M26: =IF(N26="-","-",N26/L26) -> #DIV/0! | S26: - | T26: - | U26: - | V26: -
E27: BONNEVILLE_Franchissement Borne-Tucinge | F27: France | I27: =J27/G27 -> #DIV/0! | K27: =L27/G27 -> #DIV/0! | M27: =IF(N27="-","-",N27/L27) -> #DIV/0! | S27: - | T27: - | U27: - | V27: -
E28: ST-PIERRE_Pont principal sur le Borne | F28: France | I28: =J28/G28 -> #DIV/0! | K28: =L28/G28 -> #DIV/0! | M28: =IF(N28="-","-",N28/L28) -> #DIV/0! | S28: - | T28: - | U28: - | V28: -
I29: =J29/G29 -> #DIV/0! | K29: =L29/G29 -> #DIV/0! | M29: =IF(N29="-","-",N29/L29) -> #DIV/0! | S29: - | T29: - | U29: - | V29: -
I30: =J30/G30 -> #DIV/0! | K30: =L30/G30 -> #DIV/0! | M30: =IF(N30="-","-",N30/L30) -> #DIV/0! | S30: - | T30: - | U30: - | V30: -
E31: AMANCY_Giratoire Coriandre | F31: France | I31: =J31/G31 -> #DIV/0! | K31: =L31/G31 -> #DIV/0! | M31: =IF(N31="-","-",N31/L31) -> #DIV/0! | S31: - | T31: - | U31: - | V31: -
D32: Sous-total | G32: =SUM(G21:G31) -> 0 | H32: =SUM(H21:H31) -> 0 | I32: =J32/G32 -> #DIV/0! | J32: =SUM(J21:J31) -> 0 | K32: =L32/G32 -> #DIV/0! | L32: =SUM(L21:L31) -> 0 | M32: =N32/L32 -> #DIV/0! | N32: =SUM(N21:N31) -> 0 | O32: =SUM(O21:O31) -> 0 | P32: =SUM(P21:P31) -> 0 | Q32: =SUM(Q21:Q31) -> 0 | R32: =SUM(R21:R31) -> 0 | S32: =SUM(S21:S31) -> 0 | T32: =SUM(T21:T31) -> 0 | U32: =SUM(U21:U31) -> 0 | V32: =SUM(V21:V31) -> 0
B33: AERE (Association Environnement Reignier-Esery) | C33: OUI | D33: 9 | E33: ETREMBIERES_Giratoire ex PN93 | F33: France | I33: =J33/G33 -> #DIV/0! | K33: =L33/G33 -> #DIV/0! | M33: =IF(N33="-","-",N33/L33) -> #DIV/0! | S33: - | T33: - | U33: - | V33: -
E34: ETREMBIERES_Carrefour sous Château | F34: France | I34: =J34/G34 -> #DIV/0! | K34: =L34/G34 -> #DIV/0! | M34: =IF(N34="-","-",N34/L34) -> #DIV/0! | S34: - | T34: - | U34: - | V34: -
E35: SCIENTRIER_Carrefour Tour de Bellecombe | F35: France | I35: =J35/G35 -> #DIV/0! | K35: =L35/G35 -> #DIV/0! | M35: =IF(N35="-","-",N35/L35) -> #DIV/0! | S35: - | T35: - | U35: - | V35: -
E36: REIGNIER_Giratoire église | F36: France | I36: =J36/G36 -> #DIV/0! | K36: =L36/G36 -> #DIV/0! | M36: =IF(N36="-","-",N36/L36) -> #DIV/0! | S36: - | T36: - | U36: - | V36: -
E37: REIGNIER_Giratoire Foron | F37: France | I37: =J37/G37 -> #DIV/0! | K37: =L37/G37 -> #DIV/0! | M37: =IF(N37="-","-",N37/L37) -> #DIV/0! | S37: - | T37: - | U37: - | V37: -
E38: REIGNIER_Giratoire La Forge | F38: France | I38: =J38/G38 -> #DIV/0! | K38: =L38/G38 -> #DIV/0! | M38: =IF(N38="-","-",N38/L38) -> #DIV/0! | S38: - | T38: - | U38: - | V38: -
E39: PERS-JUSSY_Giratoire Casino | F39: France | I39: =J39/G39 -> #DIV/0! | K39: =L39/G39 -> #DIV/0! | M39: =IF(N39="-","-",N39/L39) -> #DIV/0! | S39: - | T39: - | U39: - | V39: -
I40: =J40/G40 -> #DIV/0! | K40: =L40/G40 -> #DIV/0! | M40: =IF(N40="-","-",N40/L40) -> #DIV/0! | S40: - | T40: - | U40: - | V40: -
I41: =J41/G41 -> #DIV/0! | K41: =L41/G41 -> #DIV/0! | M41: =IF(N41="-","-",N41/L41) -> #DIV/0! | S41: - | T41: - | U41: - | V41: -
E42: ARTHAZ_Giratoire lavage auto | F42: France | I42: =J42/G42 -> #DIV/0! | K42: =L42/G42 -> #DIV/0! | M42: =IF(N42="-","-",N42/L42) -> #DIV/0! | S42: - | T42: - | U42: - | V42: -
...

Sheet SYNTHESE
B2: Association(s) | C2: Arrière-pays | D2: NB de béné-voles | E2: Postes de comptage | F2: France / Suisse / Frontière | G2: Nombre de vélos | M2: VAE dans le total | S2: % femmes dans le total | T2: NB de femmes dans le total | U2: % de VAE chez les femmes | V2: NB de VAE chez les femmes | W2: Autres modes | Y2: Piétons | AA2: > Suisse | AC2: > France
G3: Total | J3: HP | M3: [en %] | P3: [en valeur]
G4: 2020 | H4: 2021 | I4: 2022 | J4: 2020 | K4: 2021 | L4: 2022 | M4: 2020 | N4: 2021 | O4: 2022 | P4: 2020 | Q4: 2021 | R4: 2022 | W4: total | X4: HP | Y4: total | Z4: HP | AA4: total | AB4: HP | AC4: total | AD4: HP
B5: Université Populaire de Cluses | C5: OUI | D5: 2 | E5: CLUSES_Passerelle de Messy | F5: France | G5: ='2020'!G5 -> 63 | H5: ='2021'!G5 -> 102 | I5: ='2022'!G5 -> 0 | J5: ='2020'!H5 -> 29 | K5: ='2021'!H5 -> 94 | L5: ='2022'!H5 -> 0 | M5: =IF(G5=0,0,IF(P5=0,0,P5/G5)) -> 0.031746032 | N5: =IF(H5=0,0,IF(Q5=0,0,Q5/H5)) -> 0.019607843 | O5: =IF(I5=0,0,IF(R5=0,0,R5/I5)) -> 0 | P5: ='2020'!J5 -> 2 | Q5: ='2021'!J5 -> 2 | R5: ='2022'!J5 -> 0 | S5: =T5/G5 -> 0.28571429 | T5: 18 | U5: =IF(V5="-","-",V5/T5) -> 0.11111111 | V5: 2 | W5: - | X5: - | Y5: - | Z5: - | AA5: - | AB5: - | AC5: - | AD5: - | AE5: OK | AG5: =IF(G5="","",1) -> 1
B6: L'Abeille (Contamine) | C6: OUI | D6: 2 | E6: BONNE_Loëx (sous voie rapide) | F6: France | G6: ='2020'!G21 -> 31 | H6: ='2021'!G21 -> 76 | I6: ='2022'!G21 -> 0 | J6: ='2020'!H21 -> 23 | K6: ='2021'!H21 -> 50 | L6: ='2022'!H21 -> 0 | M6: =IF(G6=0,0,IF(P6=0,0,P6/G6)) -> 0.32258065 | N6: =IF(H6=0,0,IF(Q6=0,0,Q6/H6)) -> 0.22368421 | O6: =IF(I6=0,0,IF(R6=0,0,R6/I6)) -> 0 | P6: ='2020'!J21 -> 10 | Q6: ='2021'!J21 -> 17 | R6: ='2022'!J21 -> 0 | S6: =T6/G6 -> 0.58064516 | T6: 18 | U6: =IF(V6="-","-",V6/T6) -> 0.11111111 | V6: 2 | W6: - | X6: - | Y6: - | Z6: - | AA6: - | AB6: - | AC6: - | AD6: - | AE6: OK | AG6: =IF(G6="","",1) -> 1
B7: ACMB (Chablais) | C7: OUI | D7: 9 | E7: COMMUNE_Carrefour | F7: France | G7: ='2020'!G7 -> 0 | H7: ='2021'!G7 -> 0 | I7: ='2022'!G7 -> 0 | J7: ='2020'!H7 -> 0 | K7: ='2021'!H7 -> 0 | L7: ='2022'!H7 -> 0 | M7: =IF(G7=0,0,IF(P7=0,0,P7/G7)) -> 0 | N7: =IF(H7=0,0,IF(Q7=0,0,Q7/H7)) -> 0 | O7: =IF(I7=0,0,IF(R7=0,0,R7/I7)) -> 0 | P7: ='2020'!J7 -> 0 | Q7: ='2021'!J7 -> 0 | R7: ='2022'!J7 -> 0 | S7: =T7/G7 -> #DIV/0! | T7: 28 | U7: =IF(V7="-","-",V7/T7) -> - | V7: - | W7: - | X7: - | Y7: - | Z7: - | AA7: - | AB7: - | AC7: - | AD7: - | AE7: OK | AG7: =IF(G7="","",1) -> 1
E8: COMMUNE_Carrefour | F8: France | G8: ='2020'!G8 -> 0 | H8: ='2021'!G8 -> 0 | I8: ='2022'!G8 -> 0 | J8: ='2020'!H8 -> 0 | K8: ='2021'!H8 -> 0 | L8: ='2022'!H8 -> 0 | M8: =IF(G8=0,0,IF(P8=0,0,P8/G8)) -> 0 | N8: =IF(H8=0,0,IF(Q8=0,0,Q8/H8)) -> 0 | O8: =IF(I8=0,0,IF(R8=0,0,R8/I8)) -> 0 | P8: ='2020'!J8 -> 0 | Q8: ='2021'!J8 -> 0 | R8: ='2022'!J8 -> 0 | S8: =T8/G8 -> #DIV/0! | T8: 14 | U8: =IF(V8="-","-",V8/T8) -> - | V8: - | W8: - | X8: - | Y8: - | Z8: - | AA8: - | AB8: - | AC8: - | AD8: - | AE8: OK | AG8: =IF(G8="","",1) -> 1
E9: COMMUNE_Carrefour | F9: France | G9: ='2020'!G9 -> 0 | H9: ='2021'!G9 -> 0 | I9: ='2022'!G9 -> 0 | J9: ='2020'!H9 -> 0 | K9: ='2021'!H9 -> 0 | L9: ='2022'!H9 -> 0 | M9: =IF(G9=0,0,IF(P9=0,0,P9/G9)) -> 0 | N9: =IF(H9=0,0,IF(Q9=0,0,Q9/H9)) -> 0 | O9: =IF(I9=0,0,IF(R9=0,0,R9/I9)) -> 0 | P9: ='2020'!J9 -> 0 | Q9: ='2021'!J9 -> 0 | R9: ='2022'!J9 -> 0 | S9: =T9/G9 -> #DIV/0! | T9: 3 | U9: =IF(V9="-","-",V9/T9) -> - | V9: - | W9: - | X9: - | Y9: - | Z9: - | AA9: - | AB9: - | AC9: - | AD9: - | AE9: OK | AG9: =IF(G9="","",1) -> 1
E10: COMMUNE_Carrefour | F10: France | G10: ='2020'!G10 -> 0 | H10: ='2021'!G10 -> 0 | I10: ='2022'!G10 -> 0 | J10: ='2020'!H10 -> 0 | K10: ='2021'!H10 -> 0 | L10: ='2022'!H10 -> 0 | M10: =IF(G10=0,0,IF(P10=0,0,P10/G10)) -> 0 | N10: =IF(H10=0,0,IF(Q10=0,0,Q10/H10)) -> 0 | O10: =IF(I10=0,0,IF(R10=0,0,R10/I10)) -> 0 | P10: ='2020'!J10 -> 0 | Q10: ='2021'!J10 -> 0 | R10: ='2022'!J10 -> 0 | T10: 10 | W10: - | X10: - | Y10: - | Z10: - | AE10: OK | AG10: =IF(G10="","",1) -> 1
E11: COMMUNE_Carrefour | F11: France | G11: ='2020'!G11 -> 0 | H11: ='2021'!G11 -> 0 | I11: ='2022'!G11 -> 0 | J11: ='2020'!H11 -> 0 | K11: ='2021'!H11 -> 0 | L11: ='2022'!H11 -> 0 | M11: =IF(G11=0,0,IF(P11=0,0,P11/G11)) -> 0 | N11: =IF(H11=0,0,IF(Q11=0,0,Q11/H11)) -> 0 | O11: =IF(I11=0,0,IF(R11=0,0,R11/I11)) -> 0 | P11: ='2020'!J11 -> 0 | Q11: ='2021'!J11 -> 0 | R11: ='2022'!J11 -> 0 | S11: =T11/G11 -> #DIV/0! | T11: 6 | U11: =IF(V11="-","-",V11/T11) -> - | V11: - | W11: - | X11: - | Y11: - | Z11: - | AA11: - | AB11: - | AC11: - | AD11: - | AE11: OK | AG11: =IF(G11="","",1) -> 1
E12: COMMUNE_Carrefour | F12: France | G12: ='2020'!G12 -> 0 | H12: ='2021'!G12 -> 0 | I12: ='2022'!G12 -> 0 | J12: ='2020'!H12 -> 0 | K12: ='2021'!H12 -> 0 | L12: ='2022'!H12 -> 0 | M12: =IF(G12=0,0,IF(P12=0,0,P12/G12)) -> 0 | N12: =IF(H12=0,0,IF(Q12=0,0,Q12/H12)) -> 0 | O12: =IF(I12=0,0,IF(R12=0,0,R12/I12)) -> 0 | P12: ='2020'!J12 -> 0 | Q12: ='2021'!J12 -> 0 | R12: ='2022'!J12 -> 0 | S12: =T12/G12 -> #DIV/0! | T12: 7 | U12: =IF(V12="-","-",V12/T12) -> - | V12: - | W12: - | X12: - | Y12: - | Z12: - | AA12: - | AB12: - | AC12: - | AD12: - | AE12: OK | AG12: =IF(G12="","",1) -> 1
E13: COMMUNE_Carrefour | F13: France | G13: ='2020'!G13 -> 0 | H13: ='2021'!G13 -> 0 | I13: ='2022'!G13 -> 0 | J13: ='2020'!H13 -> 0 | K13: ='2021'!H13 -> 0 | L13: ='2022'!H13 -> 0 | M13: =IF(G13=0,0,IF(P13=0,0,P13/G13)) -> 0 | N13: =IF(H13=0,0,IF(Q13=0,0,Q13/H13)) -> 0 | O13: =IF(I13=0,0,IF(R13=0,0,R13/I13)) -> 0 | P13: ='2020'!J13 -> 0 | Q13: ='2021'!J13 -> 0 | R13: ='2022'!J13 -> 0 | S13: =T13/G13 -> #DIV/0! | T13: 7 | U13: =IF(V13="-","-",V13/T13) -> - | V13: - | W13: - | X13: - | Y13: - | Z13: - | AA13: - | AB13: - | AC13: - | AD13: - | AE13: OK | AG13: =IF(G13="","",1) -> 1
E14: COMMUNE_Carrefour | F14: France | G14: ='2020'!G14 -> 0 | H14: ='2021'!G14 -> 0 | I14: ='2022'!G14 -> 0 | J14: ='2020'!H14 -> 0 | K14: ='2021'!H14 -> 0 | L14: ='2022'!H14 -> 0 | M14: =IF(G14=0,0,IF(P14=0,0,P14/G14)) -> 0 | N14: =IF(H14=0,0,IF(Q14=0,0,Q14/H14)) -> 0 | O14: =IF(I14=0,0,IF(R14=0,0,R14/I14)) -> 0 | P14: ='2020'!J14 -> 0 | Q14: ='2021'!J14 -> 0 | R14: ='2022'!J14 -> 0 | S14: =T14/G14 -> #DIV/0! | T14: 12 | U14: =IF(V14="-","-",V14/T14) -> - | V14: - | W14: - | X14: - | Y14: - | Z14: - | AA14: - | AB14: - | AC14: - | AD14: - | AE14: OK | AG14: =IF(G14="","",1) -> 1
E15: COMMUNE_Carrefour | G15: ='2020'!G15 -> 0 | H15: ='2021'!G15 -> 0 | I15: ='2022'!G15 -> 0 | J15: ='2020'!H15 -> 0 | K15: ='2021'!H15 -> 0 | L15: ='2022'!H15 -> 0 | M15: =IF(G15=0,0,IF(P15=0,0,P15/G15)) -> 0 | N15: =IF(H15=0,0,IF(Q15=0,0,Q15/H15)) -> 0 | O15: =IF(I15=0,0,IF(R15=0,0,R15/I15)) -> 0 | P15: ='2020'!J15 -> 0 | Q15: ='2021'!J15 -> 0 | R15: ='2022'!J15 -> 0 | S15: =T15/G15 -> #DIV/0! | T15: 13 | U15: =IF(V15="-","-",V15/T15) -> - | V15: - | W15: - | X15: - | Y15: - | Z15: - | AA15: - | AB15: - | AC15: - | AD15: -
E16: COMMUNE_Carrefour | G16: ='2020'!G16 -> 0 | H16: ='2021'!G16 -> 0 | I16: ='2022'!G16 -> 0 | J16: ='2020'!H16 -> 0 | K16: ='2021'!H16 -> 0 | L16: ='2022'!H16 -> 0 | M16: =IF(G16=0,0,IF(P16=0,0,P16/G16)) -> 0 | N16: =IF(H16=0,0,IF(Q16=0,0,Q16/H16)) -> 0 | O16: =IF(I16=0,0,IF(R16=0,0,R16/I16)) -> 0 | P16: ='2020'!J16 -> 0 | Q16: ='2021'!J16 -> 0 | R16: ='2022'!J16 -> 0 | S16: =T16/G16 -> #DIV/0! | T16: 14 | U16: =IF(V16="-","-",V16/T16) -> - | V16: - | W16: - | X16: - | Y16: - | Z16: - | AA16: - | AB16: - | AC16: - | AD16: -
G17: ='2020'!G17 -> 0 | H17: ='2021'!G17 -> 0 | I17: ='2022'!G17 -> 0 | J17: ='2020'!H17 -> 0 | K17: ='2021'!H17 -> 0 | L17: ='2022'!H17 -> 0 | M17: =IF(G17=0,0,IF(P17=0,0,P17/G17)) -> 0 | N17: =IF(H17=0,0,IF(Q17=0,0,Q17/H17)) -> 0 | O17: =IF(I17=0,0,IF(R17=0,0,R17/I17)) -> 0 | P17: ='2020'!J17 -> 0 | Q17: ='2021'!J17 -> 0 | R17: ='2022'!J17 -> 0 | S17: =T17/G17 -> #DIV/0! | T17: 15 | U17: =IF(V17="-","-",V17/T17) -> - | V17: - | W17: - | X17: - | Y17: - | Z17: - | AA17: - | AB17: - | AC17: - | AD17: -
G18: ='2020'!G18 -> 0 | H18: ='2021'!G18 -> 0 | I18: ='2022'!G18 -> 0 | J18: ='2020'!H18 -> 0 | K18: ='2021'!H18 -> 0 | L18: ='2022'!H18 -> 0 | M18: =IF(G18=0,0,IF(P18=0,0,P18/G18)) -> 0 | N18: =IF(H18=0,0,IF(Q18=0,0,Q18/H18)) -> 0 | O18: =IF(I18=0,0,IF(R18=0,0,R18/I18)) -> 0 | P18: ='2020'!J18 -> 0 | Q18: ='2021'!J18 -> 0 | R18: ='2022'!J18 -> 0 | S18: =T18/G18 -> #DIV/0! | T18: 16 | U18: =IF(V18="-","-",V18/T18) -> - | V18: - | W18: - | X18: - | Y18: - | Z18: - | AA18: - | AB18: - | AC18: - | AD18: -
E19: COMMUNE_Carrefour | F19: France | G19: ='2020'!G19 -> 0 | H19: ='2021'!G19 -> 0 | I19: ='2022'!G19 -> 0 | J19: ='2020'!H19 -> 0 | K19: ='2021'!H19 -> 0 | L19: ='2022'!H19 -> 0 | M19: =IF(G19=0,0,IF(P19=0,0,P19/G19)) -> 0 | N19: =IF(H19=0,0,IF(Q19=0,0,Q19/H19)) -> 0 | O19: =IF(I19=0,0,IF(R19=0,0,R19/I19)) -> 0 | P19: ='2020'!J19 -> 0 | Q19: ='2021'!J19 -> 0 | R19: ='2022'!J19 -> 0 | S19: =T19/G19 -> #DIV/0! | U19: =IF(V19="-","-",V19/T19) -> - | V19: - | W19: - | X19: - | Y19: - | Z19: - | AA19: - | AB19: - | AC19: - | AD19: - | AE19: OK | AG19: =IF(G19="","",1) -> 1
D20: Sous-total | G20: =SUM(G7:G19) -> 0 | H20: =SUM(H7:H19) -> 0 | I20: =SUM(I7:I19) -> 0 | J20: =SUM(J7:J19) -> 0 | K20: =SUM(K7:K19) -> 0 | L20: =SUM(L7:L19) -> 0 | M20: =IF(G20=0,0,IF(P20=0,0,P20/G20)) -> 0 | N20: =IF(H20=0,0,IF(Q20=0,0,Q20/H20)) -> 0 | O20: =IF(I20=0,0,IF(R20=0,0,R20/I20)) -> 0 | P20: =SUM(P7:P19) -> 0 | Q20: =SUM(Q7:Q19) -> 0 | R20: =SUM(R7:R19) -> 0 | S20: =T20/G20 -> #DIV/0! | T20: =SUM(T7:T19) -> 145 | U20: =V20/T20 -> 0 | V20: =SUM(V7:V19) -> 0 | AE20: OK
B21: NatEnv (Nature Environnement en Pays rochois) Fabrique à Biclou Pays rochois en Transition | C21: OUI | D21: 9 | E21: LA ROCHE_Carrefour Biocoop | F21: France | G21: ='2020'!G21 -> 31 | H21: ='2021'!G21 -> 76 | I21: ='2022'!G21 -> 0 | J21: ='2020'!H21 -> 23 | K21: ='2021'!H21 -> 50 | L21: ='2022'!H21 -> 0 | M21: =IF(G21=0,0,IF(P21=0,0,P21/G21)) -> 0.32258065 | N21: =IF(H21=0,0,IF(Q21=0,0,Q21/H21)) -> 0.22368421 | O21: =IF(I21=0,0,IF(R21=0,0,R21/I21)) -> 0 | P21: ='2020'!J21 -> 10 | Q21: ='2021'!J21 -> 17 | R21: ='2022'!J21 -> 0 | S21: =T21/G21 -> 0.90322581 | T21: 28 | U21: =IF(V21="-","-",V21/T21) -> - | V21: - | W21: - | X21: - | Y21: - | Z21: - | AA21: - | AB21: - | AC21: - | AD21: - | AE21: OK | AG21: =IF(G21="","",1) -> 1
E22: LA ROCHE_Giratoire La Poste | F22: France | G22: ='2020'!G22 -> 25 | H22: ='2021'!G22 -> 45 | I22: ='2022'!G22 -> 0 | J22: ='2020'!H22 -> 13 | K22: ='2021'!H22 -> 27 | L22: ='2022'!H22 -> 0 | M22: =IF(G22=0,0,IF(P22=0,0,P22/G22)) -> 0.48 | N22: =IF(H22=0,0,IF(Q22=0,0,Q22/H22)) -> 0.46666667 | O22: =IF(I22=0,0,IF(R22=0,0,R22/I22)) -> 0 | P22: ='2020'!J22 -> 12 | Q22: ='2021'!J22 -> 21 | R22: ='2022'!J22 -> 0 | S22: =T22/G22 -> 0.56 | T22: 14 | U22: =IF(V22="-","-",V22/T22) -> - | V22: - | W22: - | X22: - | Y22: - | Z22: - | AA22: - | AB22: - | AC22: - | AD22: - | AE22: OK | AG22: =IF(G22="","",1) -> 1
E23: LA ROCHE_Giratoire ENILV | F23: France | G23: ='2020'!G23 -> 18 | H23: ='2021'!G23 -> 16 | I23: ='2022'!G23 -> 0 | J23: ='2020'!H23 -> 10 | K23: ='2021'!H23 -> 10 | L23: ='2022'!H23 -> 0 | M23: =IF(G23=0,0,IF(P23=0,0,P23/G23)) -> 0.5 | N23: =IF(H23=0,0,IF(Q23=0,0,Q23/H23)) -> 0.3125 | O23: =IF(I23=0,0,IF(R23=0,0,R23/I23)) -> 0 | P23: ='2020'!J23 -> 9 | Q23: ='2021'!J23 -> 5 | R23: ='2022'!J23 -> 0 | S23: =T23/G23 -> 0.16666667 | T23: 3 | U23: =IF(V23="-","-",V23/T23) -> - | V23: - | W23: - | X23: - | Y23: - | Z23: - | AA23: - | AB23: - | AC23: - | AD23: - | AE23: OK | AG23: =IF(G23="","",1) -> 1
E24: LA ROCHE_Gare Passage à niveau (new 2021) | F24: France | G24: ='2020'!G24 -> 0 | H24: ='2021'!G24 -> 56 | I24: ='2022'!G24 -> 0 | J24: ='2020'!H24 -> 0 | K24: ='2021'!H24 -> 36 | L24: ='2022'!H24 -> 0 | M24: =IF(G24=0,0,IF(P24=0,0,P24/G24)) -> 0 | N24: =IF(H24=0,0,IF(Q24=0,0,Q24/H24)) -> 0.21428571 | O24: =IF(I24=0,0,IF(R24=0,0,R24/I24)) -> 0 | P24: ='2020'!J24 -> 0 | Q24: ='2021'!J24 -> 12 | R24: ='2022'!J24 -> 0 | T24: 10 | W24: - | X24: - | Y24: - | Z24: - | AE24: OK | AG24: =IF(G24="","",1) -> 1
E25: ARENTHON_La Papeterie | F25: France | G25: ='2020'!G25 -> 14 | H25: ='2021'!G25 -> 13 | I25: ='2022'!G25 -> 0 | J25: ='2020'!H25 -> 9 | K25: ='2021'!H25 -> 8 | L25: ='2022'!H25 -> 0 | M25: =IF(G25=0,0,IF(P25=0,0,P25/G25)) -> 0.071428571 | N25: =IF(H25=0,0,IF(Q25=0,0,Q25/H25)) -> 0.53846154 | O25: =IF(I25=0,0,IF(R25=0,0,R25/I25)) -> 0 | P25: ='2020'!J25 -> 1 | Q25: ='2021'!J25 -> 7 | R25: ='2022'!J25 -> 0 | S25: =T25/G25 -> 0.42857143 | T25: 6 | U25: =IF(V25="-","-",V25/T25) -> - | V25: - | W25: - | X25: - | Y25: - | Z25: - | AA25: - | AB25: - | AC25: - | AD25: - | AE25: OK | AG25: =IF(G25="","",1) -> 1
E26: ST-PIERRE_Franchissement Borne-Dessy | F26: France | G26: ='2020'!G26 -> 24 | H26: ='2021'!G26 -> 24 | I26: ='2022'!G26 -> 0 | J26: ='2020'!H26 -> 16 | K26: ='2021'!H26 -> 20 | L26: ='2022'!H26 -> 0 | M26: =IF(G26=0,0,IF(P26=0,0,P26/G26)) -> 0.041666667 | N26: =IF(H26=0,0,IF(Q26=0,0,Q26/H26)) -> 0.29166667 | O26: =IF(I26=0,0,IF(R26=0,0,R26/I26)) -> 0 | P26: ='2020'!J26 -> 1 | Q26: ='2021'!J26 -> 7 | R26: ='2022'!J26 -> 0 | S26: =T26/G26 -> 0.29166667 | T26: 7 | U26: =IF(V26="-","-",V26/T26) -> - | V26: - | W26: - | X26: - | Y26: - | Z26: - | AA26: - | AB26: - | AC26: - | AD26: - | AE26: OK | AG26: =IF(G26="","",1) -> 1
E27: BONNEVILLE_Franchissement Borne-Tucinge | F27: France | G27: ='2020'!G27 -> 29 | H27: ='2021'!G27 -> 33 | I27: ='2022'!G27 -> 0 | J27: ='2020'!H27 -> 21 | K27: ='2021'!H27 -> 25 | L27: ='2022'!H27 -> 0 | M27: =IF(G27=0,0,IF(P27=0,0,P27/G27)) -> 0 | N27: =IF(H27=0,0,IF(Q27=0,0,Q27/H27)) -> 0 | O27: =IF(I27=0,0,IF(R27=0,0,R27/I27)) -> 0 | P27: ='2020'!J27 -> 0 | Q27: ='2021'!J27 -> 0 | R27: ='2022'!J27 -> 0 | S27: =T27/G27 -> 0.24137931 | T27: 7 | U27: =IF(V27="-","-",V27/T27) -> - | V27: - | W27: - | X27: - | Y27: - | Z27: - | AA27: - | AB27: - | AC27: - | AD27: - | AE27: OK | AG27: =IF(G27="","",1) -> 1
E28: ST-PIERRE_Pont principal sur le Borne | F28: France | G28: ='2020'!G28 -> 27 | H28: ='2021'!G28 -> 32 | I28: ='2022'!G28 -> 0 | J28: ='2020'!H28 -> 17 | K28: ='2021'!H28 -> 17 | L28: ='2022'!H28 -> 0 | M28: =IF(G28=0,0,IF(P28=0,0,P28/G28)) -> 0.25925926 | N28: =IF(H28=0,0,IF(Q28=0,0,Q28/H28)) -> 0.15625 | O28: =IF(I28=0,0,IF(R28=0,0,R28/I28)) -> 0 | P28: ='2020'!J28 -> 7 | Q28: ='2021'!J28 -> 5 | R28: ='2022'!J28 -> 0 | S28: =T28/G28 -> 0.44444444 | T28: 12 | U28: =IF(V28="-","-",V28/T28) -> - | V28: - | W28: - | X28: - | Y28: - | Z28: - | AA28: - | AB28: - | AC28: - | AD28: - | AE28: OK | AG28: =IF(G28="","",1) -> 1
E31: AMANCY_Giratoire Coriandre | F31: France | G31: ='2020'!G31 -> 4 | H31: ='2021'!G31 -> 0 | I31: ='2022'!G31 -> 0 | J31: ='2020'!H31 -> 2 | K31: ='2021'!H31 -> 0 | L31: ='2022'!H31 -> 0 | M31: =IF(G31=0,0,IF(P31=0,0,P31/G31)) -> 0.5 | N31: =IF(H31=0,0,IF(Q31=0,0,Q31/H31)) -> 0 | O31: =IF(I31=0,0,IF(R31=0,0,R31/I31)) -> 0 | P31: ='2020'!J31 -> 2 | Q31: ='2021'!J31 -> 0 | R31: ='2022'!J31 -> 0 | S31: =T31/G31 -> 0 | U31: =IF(V31="-","-",V31/T31) -> - | V31: - | W31: - | X31: - | Y31: - | Z31: - | AA31: - | AB31: - | AC31: - | AD31: - | AE31: OK | AG31: =IF(G31="","",1) -> 1
D32: Sous-total | G32: =SUM(G21:G31) -> 172 | H32: =SUM(H21:H31) -> 295 | I32: =SUM(I21:I31) -> 0 | J32: =SUM(J21:J31) -> 111 | K32: =SUM(K21:K31) -> 193 | L32: =SUM(L21:L31) -> 0 | M32: =IF(G32=0,0,IF(P32=0,0,P32/G32)) -> 0.24418605 | N32: =IF(H32=0,0,IF(Q32=0,0,Q32/H32)) -> 0.25084746 | O32: =IF(I32=0,0,IF(R32=0,0,R32/I32)) -> 0 | P32: =SUM(P21:P31) -> 42 | Q32: =SUM(Q21:Q31) -> 74 | R32: =SUM(R21:R31) -> 0 | S32: =T32/G32 -> 0.50581395 | T32: =SUM(T21:T31) -> 87 | U32: =V32/T32 -> 0 | V32: =SUM(V21:V31) -> 0 | AE32: OK
B33: AERE (Association Environnement Reignier-Esery) | C33: OUI | D33: 9 | E33: ETREMBIERES_Giratoire ex PN93 | F33: France | G33: ='2020'!G33 -> 37 | H33: ='2021'!G33 -> 46 | I33: ='2022'!G33 -> 0 | J33: ='2020'!H33 -> 23 | K33: ='2021'!H33 -> 32 | L33: ='2022'!H33 -> 0 | M33: =IF(G33=0,0,IF(P33=0,0,P33/G33)) -> 0.38 | N33: =IF(H33=0,0,IF(Q33=0,0,Q33/H33)) -> 0.65217391 | O33: =IF(I33=0,0,IF(R33=0,0,R33/I33)) -> 0 | P33: ='2020'!J33 -> 14.06 | Q33: ='2021'!J33 -> 30 | R33: ='2022'!J33 -> 0 | S33: =T33/G33 -> 0.24324324 | T33: 9 | U33: =IF(V33="-","-",V33/T33) -> 1 | V33: 9 | W33: - | X33: - | Y33: - | Z33: - | AA33: - | AB33: - | AC33: - | AD33: - | AE33: OK | AG33: =IF(G33="","",1) -> 1
E34: ETREMBIERES_Carrefour sous Château | F34: France | G34: ='2020'!G34 -> 33 | H34: ='2021'!G34 -> 28 | I34: ='2022'!G34 -> 0 | J34: ='2020'!H34 -> 15 | K34: ='2021'!H34 -> 17 | L34: ='2022'!H34 -> 0 | M34: =IF(G34=0,0,IF(P34=0,0,P34/G34)) -> 0.3 | N34: =IF(H34=0,0,IF(Q34=0,0,Q34/H34)) -> 0.64285714 | O34: =IF(I34=0,0,IF(R34=0,0,R34/I34)) -> 0 | P34: ='2020'!J34 -> 9.9 | Q34: ='2021'!J34 -> 18 | R34: ='2022'!J34 -> 0 | S34: =T34/G34 -> 0.27272727 | T34: 9 | U34: =IF(V34="-","-",V34/T34) -> 0.77777778 | V34: 7 | W34: - | X34: - | Y34: - | Z34: - | AA34: - | AB34: - | AC34: - | AD34: - | AE34: OK | AG34: =IF(G34="","",1) -> 1
E35: SCIENTRIER_Carrefour Tour de Bellecombe | F35: France | G35: ='2020'!G35 -> 6 | H35: ='2021'!G35 -> 5 | I35: ='2022'!G35 -> 0 | J35: ='2020'!H35 -> 5 | K35: ='2021'!H35 -> 5 | L35: ='2022'!H35 -> 0 | M35: =IF(G35=0,0,IF(P35=0,0,P35/G35)) -> 0 | N35: =IF(H35=0,0,IF(Q35=0,0,Q35/H35)) -> 0.6 | O35: =IF(I35=0,0,IF(R35=0,0,R35/I35)) -> 0 | P35: ='2020'!J35 -> 0 | Q35: ='2021'!J35 -> 3 | R35: ='2022'!J35 -> 0 | S35: =T35/G35 -> 0.16666667 | T35: 1 | U35: =IF(V35="-","-",V35/T35) -> 1 | V35: 1 | W35: - | X35: - | Y35: - | Z35: - | AA35: - | AB35: - | AC35: - | AD35: - | AE35: OK | AG35: =IF(G35="","",1) -> 1
E36: REIGNIER_Giratoire église | F36: France | G36: ='2020'!G36 -> 25 | H36: ='2021'!G36 -> 45 | I36: ='2022'!G36 -> 0 | J36: ='2020'!H36 -> 15 | K36: ='2021'!H36 -> 26 | L36: ='2022'!H36 -> 0 | M36: =IF(G36=0,0,IF(P36=0,0,P36/G36)) -> 0.28 | N36: =IF(H36=0,0,IF(Q36=0,0,Q36/H36)) -> 0.26666667 | O36: =IF(I36=0,0,IF(R36=0,0,R36/I36)) -> 0 | P36: ='2020'!J36 -> 7 | Q36: ='2021'!J36 -> 12 | R36: ='2022'!J36 -> 0 | S36: =T36/G36 -> 0.48 | T36: 12 | U36: =IF(V36="-","-",V36/T36) -> 0.25 | V36: 3 | W36: - | X36: - | Y36: - | Z36: - | AA36: - | AB36: - | AC36: - | AD36: - | AE36: OK | AG36: =IF(G36="","",1) -> 1
E37: REIGNIER_Giratoire Foron | F37: France | G37: ='2020'!G37 -> 15 | H37: ='2021'!G37 -> 14 | I37: ='2022'!G37 -> 0 | J37: ='2020'!H37 -> 9 | K37: ='2021'!H37 -> 9 | L37: ='2022'!H37 -> 0 | M37: =IF(G37=0,0,IF(P37=0,0,P37/G37)) -> 0.13 | N37: =IF(H37=0,0,IF(Q37=0,0,Q37/H37)) -> 0.21428571 | O37: =IF(I37=0,0,IF(R37=0,0,R37/I37)) -> 0 | P37: ='2020'!J37 -> 1.95 | Q37: ='2021'!J37 -> 3 | R37: ='2022'!J37 -> 0 | S37: =T37/G37 -> 0.13333333 | T37: 2 | U37: =IF(V37="-","-",V37/T37) -> 0.5 | V37: 1 | W37: - | X37: - | Y37: - | Z37: - | AA37: - | AB37: - | AC37: - | AD37: - | AE37: OK | AG37: =IF(G37="","",1) -> 1
E38: REIGNIER_Giratoire La Forge | F38: France | G38: ='2020'!G38 -> 16 | H38: ='2021'!G38 -> 31 | I38: ='2022'!G38 -> 0 | J38: ='2020'!H38 -> 14 | K38: ='2021'!H38 -> 23 | L38: ='2022'!H38 -> 0 | M38: =IF(G38=0,0,IF(P38=0,0,P38/G38)) -> 0.38 | N38: =IF(H38=0,0,IF(Q38=0,0,Q38/H38)) -> 0.5483871 | O38: =IF(I38=0,0,IF(R38=0,0,R38/I38)) -> 0 | P38: ='2020'!J38 -> 6.08 | Q38: ='2021'!J38 -> 17 | R38: ='2022'!J38 -> 0 | S38: =T38/G38 -> 0.3125 | T38: 5 | U38: =IF(V38="-","-",V38/T38) -> 1 | V38: 5 | W38: - | X38: - | Y38: - | Z38: - | AA38: - | AB38: - | AC38: - | AD38: - | AE38: OK | AG38: =IF(G38="","",1) -> 1
E39: PERS-JUSSY_Giratoire Casino | F39: France | G39: ='2020'!G39 -> 7 | H39: ='2021'!G39 -> 12 | I39: ='2022'!G39 -> 0 | J39: ='2020'!H39 -> 5 | K39: ='2021'!H39 -> 7 | L39: ='2022'!H39 -> 0 | M39: =IF(G39=0,0,IF(P39=0,0,P39/G39)) -> 0.14 | N39: =IF(H39=0,0,IF(Q39=0,0,Q39/H39)) -> 0.33333333 | O39: =IF(I39=0,0,IF(R39=0,0,R39/I39)) -> 0 | P39: ='2020'!J39 -> 0.98 | Q39: ='2021'!J39 -> 4 | R39: ='2022'!J39 -> 0 | S39: =T39/G39 -> 0.57142857 | T39: 4 | U39: =IF(V39="-","-",V39/T39) -> 0.5 | V39: 2 | W39: - | X39: - | Y39: - | Z39: - | AA39: - | AB39: - | AC39: - | AD39: - | AE39: OK | AG39: =IF(G39="","",1) -> 1
E42: ARTHAZ_Giratoire lavage auto | F42: France | G42: ='2020'!G42 -> 20 | H42: ='2021'!G42 -> 17 | I42: ='2022'!G42 -> 0 | J42: ='2020'!H42 -> 9 | K42: ='2021'!H42 -> 9 | L42: ='2022'!H42 -> 0 | M42: =IF(G42=0,0,IF(P42=0,0,P42/G42)) -> 0.25 | N42: =IF(H42=0,0,IF(Q42=0,0,Q42/H42)) -> 0.41176471 | O42: =IF(I42=0,0,IF(R42=0,0,R42/I42)) -> 0 | P42: ='2020'!J42 -> 5 | Q42: ='2021'!J42 -> 7 | R42: ='2022'!J42 -> 0 | S42: =T42/G42 -> 0.2 | T42: 4 | U42: =IF(V42="-","-",V42/T42) -> 0.25 | V42: 1 | W42: - | X42: - | Y42: - | Z42: - | AA42: - | AB42: - | AC42: - | AD42: - | AE42: OK | AG42: =IF(G42="","",1) -> 1
D43: Sous-total | G43: =SUM(G33:G42) -> 159 | H43: =SUM(H33:H42) -> 198 | I43: =SUM(I33:I42) -> 0 | J43: =SUM(J33:J42) -> 95 | K43: =SUM(K33:K42) -> 128 | L43: =SUM(L33:L42) -> 0 | M43: =IF(G43=0,0,IF(P43=0,0,P43/G43)) -> 0.28283019 | N43: =IF(H43=0,0,IF(Q43=0,0,Q43/H43)) -> 0.47474747 | O43: =IF(I43=0,0,IF(R43=0,0,R43/I43)) -> 0 | P43: =SUM(P33:P42) -> 44.97 | Q43: =SUM(Q33:Q42) -> 94 | R43: =SUM(R33:R42) -> 0 | S43: =T43/G43 -> 0.28930818 | T43: =SUM(T33:T42) -> 46 | U43: =V43/T43 -> 0.63043478 | V43: =SUM(V33:V42) -> 29 | AE43: OK
B44: Sous-total périmètre "arrière-pays" | D44: =SUM(D5:D42) -> 31 | E44: =COUNT(G5:G31,G33:G42) -> 33 | F44: =COUNT(P5:P42) -> 34 | G44: =G5+G32+G43 -> 394 | H44: =H5+H32+H43 -> 595 | I44: =I5+I32+I43 -> 0 | J44: =J5+J32+J43 -> 235 | K44: =K5+K32+K43 -> 415 | L44: =L5+L32+L43 -> 0 | M44: =IF(G44=0,0,IF(P44=0,0,P44/G44)) -> 0.22581218 | N44: =IF(H44=0,0,IF(Q44=0,0,Q44/H44)) -> 0.28571429 | O44: =IF(I44=0,0,IF(R44=0,0,R44/I44)) -> 0 | P44: =P5+P32+P43 -> 88.97 | Q44: =Q5+Q32+Q43 -> 170 | R44: =R5+R32+R43 -> 0 | S44: =T44/G44 -> 0.38324873 | T44: =T5+T32+T43 -> 151 | U44: =V44/(T5+SUM(T33:T42)) -> 0.484375 | V44: =V5+V32+V43 -> 31 | AE44: OK
B45: EVAV (En Ville A Vélo) | C45: NON | D45: 6 | E45: AMBILLY_Voie verte Pont Noir | F45: France | G45: ='2020'!G45 -> 603 | H45: ='2021'!G45 -> 0 | I45: ='2022'!G45 -> 0 | J45: ='2020'!H45 -> 173 | K45: ='2021'!H45 -> 0 | L45: ='2022'!H45 -> 0 | M45: =IF(G45=0,0,IF(P45=0,0,P45/G45)) -> 0.43283582 | N45: =IF(H45=0,0,IF(Q45=0,0,Q45/H45)) -> 0 | O45: =IF(I45=0,0,IF(R45=0,0,R45/I45)) -> 0 | P45: ='2020'!J45 -> 261 | Q45: ='2021'!J45 -> 0 | R45: ='2022'!J45 -> 0 | S45: =T45/G45 -> 0 | U45: =IF(V45="-","-",V45/T45) -> - | V45: - | W45: - | X45: - | Y45: - | Z45: - | AE45: OK | AG45: =IF(G45="","",1) -> 1
...

Sheet 2021-2020
B2: Association(s) | C2: Arrière-pays | D2: Nombre de bénévoles | E2: Postes de comptage | F2: France / Suisse / Frontière | G2: Evolution des vélos 2020-2021 | K2: Evolution des VAE 2020-2021 | M2: Evolution des femmes 2020-2021 | O2: Evolution des VAE chez les femmes 2020-2021 | Q2: Autres modes | S2: Piétons | U2: > Suisse | W2: > France
G3: TOTAL | I3: HP | U3: en HP | W3: en HP
G4: # | H4: % | I4: # | J4: % | K4: # | L4: % | M4: # | N4: % | O4: # | P4: % | Q4: total | R4: HP | S4: total | T4: HP | U4: # | V4: % | W4: # | X4: %
A5: 1 | B5: Université Populaire de Cluses | C5: OUI | D5: ='2021'!D5-'2020'!D5 -> 0 | E5: CLUSES_Passerelle de Messy | F5: France | G5: ='2021'!G5-'2020'!G5 -> 39 | H5: =IF('2021'!G5=0,0,IF('2020'!G5=0,0,'2021'!G5/'2020'!G5-1)) -> 0.61904762 | I5: ='2021'!H5-'2020'!H5 -> 65 | J5: =IF('2021'!H5=0,0,IF('2020'!H5=0,0,'2021'!H5/'2020'!H5-1)) -> 2.2413793 | K5: ='2021'!J5-'2020'!J5 -> 0 | L5: ='2021'!I5-'2020'!I5 -> -0.012138189 | M5: ='2021'!L5-'2020'!L5 -> 1 | N5: ='2021'!K5-'2020'!K5 -> -0.093370682 | O5: =IF('2020'!N5="-",0,'2021'!N5-'2020'!N5) -> 0 | P5: ='2021'!M5-'2020'!M5 -> -0.0065359477 | U5: - | V5: - | W5: - | X5: -
A6: 1 | B6: L'Abeille (Contamine) | C6: OUI | D6: ='2021'!D21-'2020'!D21 -> 1 | E6: BONNE_Loëx (sous voie rapide) | F6: France | G6: ='2021'!G21-'2020'!G21 -> 45 | H6: =IF('2021'!G21=0,0,IF('2020'!G21=0,0,'2021'!G21/'2020'!G21-1)) -> 1.4516129 | I6: ='2021'!H21-'2020'!H21 -> 27 | J6: =IF('2021'!H21=0,0,IF('2020'!H21=0,0,'2021'!H21/'2020'!H21-1)) -> 1.173913 | K6: ='2021'!J21-'2020'!J21 -> 7 | L6: ='2021'!I21-'2020'!I21 -> -0.098896435 | M6: ='2021'!L21-'2020'!L21 -> 18 | N6: ='2021'!K21-'2020'!K21 -> 0.045840407 | O6: =IF('2020'!N21="-",0,'2021'!N21-'2020'!N21) -> 0 | P6: ='2021'!M21-'2020'!M21 -> #VALUE! | U6: - | V6: - | W6: - | X6: -
A7: 2 | B7: ACMB (Chablais) | C7: OUI | D7: 9 | E7: COMMUNE_Carrefour | F7: France | G7: ='2021'!G7-'2020'!G7 -> 0 | H7: =IF('2021'!G7=0,0,IF('2020'!G7=0,0,'2021'!G7/'2020'!G7-1)) -> 0 | I7: ='2021'!H7-'2020'!H7 -> 0 | J7: =IF('2021'!H7=0,0,IF('2020'!H7=0,0,'2021'!H7/'2020'!H7-1)) -> 0 | K7: ='2021'!J7-'2020'!J7 -> 0 | L7: ='2021'!I7-'2020'!I7 -> #DIV/0! | M7: ='2021'!L7-'2020'!L7 -> 0 | N7: ='2021'!K7-'2020'!K7 -> #DIV/0! | U7: - | V7: - | W7: - | X7: -
A8: 3 | E8: COMMUNE_Carrefour | F8: France | G8: ='2021'!G8-'2020'!G8 -> 0 | H8: =IF('2021'!G8=0,0,IF('2020'!G8=0,0,'2021'!G8/'2020'!G8-1)) -> 0 | I8: ='2021'!H8-'2020'!H8 -> 0 | J8: =IF(I8=0,0,'2021'!H8/'2020'!H8-1) -> 0 | K8: ='2021'!J8-'2020'!J8 -> 0 | L8: ='2021'!I8-'2020'!I8 -> #DIV/0! | M8: ='2021'!L8-'2020'!L8 -> 0 | N8: ='2021'!K8-'2020'!K8 -> #DIV/0! | U8: - | V8: - | W8: - | X8: -
A9: 4 | E9: COMMUNE_Carrefour | F9: France | G9: ='2021'!G9-'2020'!G9 -> 0 | H9: =IF('2021'!G9=0,0,IF('2020'!G9=0,0,'2021'!G9/'2020'!G9-1)) -> 0 | I9: ='2021'!H9-'2020'!H9 -> 0 | J9: =IF(I9=0,0,'2021'!H9/'2020'!H9-1) -> 0 | K9: ='2021'!J9-'2020'!J9 -> 0 | L9: ='2021'!I9-'2020'!I9 -> #DIV/0! | M9: ='2021'!L9-'2020'!L9 -> 0 | N9: ='2021'!K9-'2020'!K9 -> #DIV/0! | U9: - | V9: - | W9: - | X9: -
A10: 5 | E10: COMMUNE_Carrefour | G10: ='2021'!G10-'2020'!G10 -> 0 | H10: =IF('2021'!G10=0,0,IF('2020'!G10=0,0,'2021'!G10/'2020'!G10-1)) -> 0 | I10: ='2021'!H10-'2020'!H10 -> 0 | J10: =IF(I10=0,0,'2021'!H10/'2020'!H10-1) -> 0 | K10: ='2021'!J10-'2020'!J10 -> 0 | L10: ='2021'!I10-'2020'!I10 -> #DIV/0! | M10: ='2021'!L10-'2020'!L10 -> 0 | N10: ='2021'!K10-'2020'!K10 -> #DIV/0!
A11: 6 | E11: COMMUNE_Carrefour | F11: France | G11: ='2021'!G11-'2020'!G11 -> 0 | H11: =IF('2021'!G11=0,0,IF('2020'!G11=0,0,'2021'!G11/'2020'!G11-1)) -> 0 | I11: ='2021'!H11-'2020'!H11 -> 0 | J11: =IF(I11=0,0,'2021'!H11/'2020'!H11-1) -> 0 | K11: ='2021'!J11-'2020'!J11 -> 0 | L11: ='2021'!I11-'2020'!I11 -> #DIV/0! | M11: ='2021'!L11-'2020'!L11 -> 0 | N11: ='2021'!K11-'2020'!K11 -> #DIV/0! | U11: - | V11: - | W11: - | X11: -
A12: 7 | E12: COMMUNE_Carrefour | F12: France | G12: ='2021'!G12-'2020'!G12 -> 0 | H12: =IF('2021'!G12=0,0,IF('2020'!G12=0,0,'2021'!G12/'2020'!G12-1)) -> 0 | I12: ='2021'!H12-'2020'!H12 -> 0 | J12: =IF(I12=0,0,'2021'!H12/'2020'!H12-1) -> 0 | K12: ='2021'!J12-'2020'!J12 -> 0 | L12: ='2021'!I12-'2020'!I12 -> #DIV/0! | M12: ='2021'!L12-'2020'!L12 -> 0 | N12: ='2021'!K12-'2020'!K12 -> #DIV/0! | U12: - | V12: - | W12: - | X12: -
A13: 8 | E13: COMMUNE_Carrefour | F13: France | G13: ='2021'!G13-'2020'!G13 -> 0 | H13: =IF('2021'!G13=0,0,IF('2020'!G13=0,0,'2021'!G13/'2020'!G13-1)) -> 0 | I13: ='2021'!H13-'2020'!H13 -> 0 | J13: =IF(I13=0,0,'2021'!H13/'2020'!H13-1) -> 0 | K13: ='2021'!J13-'2020'!J13 -> 0 | L13: ='2021'!I13-'2020'!I13 -> #DIV/0! | M13: ='2021'!L13-'2020'!L13 -> 0 | N13: ='2021'!K13-'2020'!K13 -> #DIV/0! | U13: - | V13: - | W13: - | X13: -
A14: 9 | E14: COMMUNE_Carrefour | F14: France | G14: ='2021'!G14-'2020'!G14 -> 0 | H14: =IF('2021'!G14=0,0,IF('2020'!G14=0,0,'2021'!G14/'2020'!G14-1)) -> 0 | I14: ='2021'!H14-'2020'!H14 -> 0 | J14: =IF(I14=0,0,'2021'!H14/'2020'!H14-1) -> 0 | K14: ='2021'!J14-'2020'!J14 -> 0 | L14: ='2021'!I14-'2020'!I14 -> #DIV/0! | M14: ='2021'!L14-'2020'!L14 -> 0 | N14: ='2021'!K14-'2020'!K14 -> #DIV/0! | U14: - | V14: - | W14: - | X14: -
E15: COMMUNE_Carrefour | G15: ='2021'!G15-'2020'!G15 -> 0 | H15: =IF('2021'!G15=0,0,IF('2020'!G15=0,0,'2021'!G15/'2020'!G15-1)) -> 0 | I15: ='2021'!H15-'2020'!H15 -> 0 | J15: =IF(I15=0,0,'2021'!H15/'2020'!H15-1) -> 0 | K15: ='2021'!J15-'2020'!J15 -> 0 | L15: ='2021'!I15-'2020'!I15 -> #DIV/0! | M15: ='2021'!L15-'2020'!L15 -> 0 | N15: ='2021'!K15-'2020'!K15 -> #DIV/0!
E16: COMMUNE_Carrefour | G16: ='2021'!G16-'2020'!G16 -> 0 | H16: =IF('2021'!G16=0,0,IF('2020'!G16=0,0,'2021'!G16/'2020'!G16-1)) -> 0 | I16: ='2021'!H16-'2020'!H16 -> 0 | J16: =IF(I16=0,0,'2021'!H16/'2020'!H16-1) -> 0 | K16: ='2021'!J16-'2020'!J16 -> 0 | L16: ='2021'!I16-'2020'!I16 -> #DIV/0! | M16: ='2021'!L16-'2020'!L16 -> 0 | N16: ='2021'!K16-'2020'!K16 -> #DIV/0!
A19: 10 | E19: COMMUNE_Carrefour | F19: France | G19: ='2021'!G19-'2020'!G19 -> 0 | H19: =IF('2021'!G19=0,0,IF('2020'!G19=0,0,'2021'!G19/'2020'!G19-1)) -> 0 | I19: ='2021'!H19-'2020'!H19 -> 0 | J19: =IF(I19=0,0,'2021'!H19/'2020'!H19-1) -> 0 | K19: ='2021'!J19-'2020'!J19 -> 0 | L19: ='2021'!I19-'2020'!I19 -> #DIV/0! | M19: ='2021'!L19-'2020'!L19 -> 0 | N19: ='2021'!K19-'2020'!K19 -> #DIV/0!
D20: Sous-total | G20: =SUM(G7:G19) -> 0 | H20: =G20/SUM('2020'!G7:G9,'2020'!G11:G14) -> #DIV/0! | I20: =SUM(I7:I19) -> 0 | J20: =I20/SUM('2020'!H7:H9,'2020'!H11:H14) -> #DIV/0! | K20: =SUM(K7:K19) -> 0 | L20: =K20/SUM('2020'!J7:J9,'2020'!J11:J14) -> #DIV/0! | M20: =SUM(M7:M19) -> 0 | N20: =M20/SUM('2020'!L7:L9,'2020'!L11:L14) -> #DIV/0!
A21: 2 | B21: NatEnv (Nature Environnement en Pays rochois) Fabrique à Biclou Pays rochois en Transition | C21: OUI | D21: ='2021'!D21-'2020'!D21 -> 1 | E21: LA ROCHE_Carrefour Biocoop | F21: France | G21: ='2021'!G21-'2020'!G21 -> 45 | H21: =IF('2021'!G21=0,0,IF('2020'!G21=0,0,'2021'!G21/'2020'!G21-1)) -> 1.4516129 | I21: ='2021'!H21-'2020'!H21 -> 27 | J21: =IF('2021'!H21=0,0,IF('2020'!H21=0,0,'2021'!H21/'2020'!H21-1)) -> 1.173913 | K21: ='2021'!J21-'2020'!J21 -> 7 | L21: ='2021'!I21-'2020'!I21 -> -0.098896435 | M21: ='2021'!L21-'2020'!L21 -> 18 | N21: ='2021'!K21-'2020'!K21 -> 0.045840407 | U21: - | V21: - | W21: - | X21: -
A22: 3 | E22: LA ROCHE_Giratoire La Poste | F22: France | G22: ='2021'!G22-'2020'!G22 -> 20 | H22: =IF('2021'!G22=0,0,IF('2020'!G22=0,0,'2021'!G22/'2020'!G22-1)) -> 0.8 | I22: ='2021'!H22-'2020'!H22 -> 14 | J22: =IF(I22=0,0,'2021'!H22/'2020'!H22-1) -> 1.0769231 | K22: ='2021'!J22-'2020'!J22 -> 9 | L22: ='2021'!I22-'2020'!I22 -> -0.013333333 | M22: ='2021'!L22-'2020'!L22 -> 5 | N22: ='2021'!K22-'2020'!K22 -> -0.048888889 | U22: - | V22: - | W22: - | X22: -
A23: 4 | E23: LA ROCHE_Giratoire ENILV | F23: France | G23: ='2021'!G23-'2020'!G23 -> -2 | H23: =IF('2021'!G23=0,0,IF('2020'!G23=0,0,'2021'!G23/'2020'!G23-1)) -> -0.11111111 | I23: ='2021'!H23-'2020'!H23 -> 0 | J23: =IF(I23=0,0,'2021'!H23/'2020'!H23-1) -> 0 | K23: ='2021'!J23-'2020'!J23 -> -4 | L23: ='2021'!I23-'2020'!I23 -> -0.1875 | M23: ='2021'!L23-'2020'!L23 -> 0 | N23: ='2021'!K23-'2020'!K23 -> 0.020833333 | U23: - | V23: - | W23: - | X23: -
A24: 5 | E24: LA ROCHE_Gare Passage à niveau (new2021) | L24: ='2021'!I24-'2020'!I24 -> -0.28571429 | N24: ='2021'!K24-'2020'!K24 -> 0.011904762
A25: 6 | E25: ARENTHON_La Papeterie | F25: France | G25: ='2021'!G25-'2020'!G25 -> -1 | H25: =IF('2021'!G25=0,0,IF('2020'!G25=0,0,'2021'!G25/'2020'!G25-1)) -> -0.071428571 | I25: ='2021'!H25-'2020'!H25 -> -1 | J25: =IF(I25=0,0,'2021'!H25/'2020'!H25-1) -> -0.11111111 | K25: ='2021'!J25-'2020'!J25 -> 6 | L25: ='2021'!I25-'2020'!I25 -> 0.46703297 | M25: ='2021'!L25-'2020'!L25 -> 5 | N25: ='2021'!K25-'2020'!K25 -> 0.39010989 | U25: - | V25: - | W25: - | X25: -
A26: 7 | E26: ST-PIERRE_Franchissement Borne-Dessy | F26: France | G26: ='2021'!G26-'2020'!G26 -> 0 | H26: =IF('2021'!G26=0,0,IF('2020'!G26=0,0,'2021'!G26/'2020'!G26-1)) -> 0 | I26: ='2021'!H26-'2020'!H26 -> 4 | J26: =IF(I26=0,0,'2021'!H26/'2020'!H26-1) -> 0.25 | K26: ='2021'!J26-'2020'!J26 -> 6 | L26: ='2021'!I26-'2020'!I26 -> 0.25 | M26: ='2021'!L26-'2020'!L26 -> 2 | N26: ='2021'!K26-'2020'!K26 -> 0.083333333 | U26: - | V26: - | W26: - | X26: -
A27: 8 | E27: BONNEVILLE_Franchissement Borne-Tucinge | F27: France | G27: ='2021'!G27-'2020'!G27 -> 4 | H27: =IF('2021'!G27=0,0,IF('2020'!G27=0,0,'2021'!G27/'2020'!G27-1)) -> 0.13793103 | I27: ='2021'!H27-'2020'!H27 -> 4 | J27: =IF(I27=0,0,'2021'!H27/'2020'!H27-1) -> 0.19047619 | K27: ='2021'!J27-'2020'!J27 -> 0 | L27: ='2021'!I27-'2020'!I27 -> 0 | M27: ='2021'!L27-'2020'!L27 -> -5 | N27: ='2021'!K27-'2020'!K27 -> -0.20167189 | U27: - | V27: - | W27: - | X27: -
A28: 9 | E28: ST-PIERRE_Pont principal sur le Borne | F28: France | G28: ='2021'!G28-'2020'!G28 -> 5 | H28: =IF('2021'!G28=0,0,IF('2020'!G28=0,0,'2021'!G28/'2020'!G28-1)) -> 0.18518519 | I28: ='2021'!H28-'2020'!H28 -> 0 | J28: =IF(I28=0,0,'2021'!H28/'2020'!H28-1) -> 0 | K28: ='2021'!J28-'2020'!J28 -> -2 | L28: ='2021'!I28-'2020'!I28 -> -0.10300926 | M28: ='2021'!L28-'2020'!L28 -> -1 | N28: ='2021'!K28-'2020'!K28 -> -0.10648148 | U28: - | V28: - | W28: - | X28: -
A31: 10 | E31: AMANCY_Giratoire Coriandre | F31: France
D32: Sous-total | G32: =SUM(G21:G31) -> 71 | H32: =G32/SUM('2020'!G21:G23,'2020'!G25:G28) -> 0.42261905 | I32: =SUM(I21:I31) -> 48 | J32: =I32/SUM('2020'!H21:H23,'2020'!H25:H28) -> 0.44036697 | K32: =SUM(K21:K31) -> 22 | L32: =K32/SUM('2020'!J21:J23,'2020'!J25:J28) -> 0.55 | M32: =SUM(M21:M31) -> 24 | N32: =M32/SUM('2020'!L21:L23,'2020'!L25:L28) -> 0.45283019
A33: 11 | B33: AERE (Association Environnement Reignier-Esery) | C33: OUI | D33: ='2021'!D33-'2020'!D33 -> 0 | E33: ETREMBIERES_Giratoire ex PN93 | F33: France | G33: ='2021'!G33-'2020'!G33 -> 9 | H33: =IF('2021'!G33=0,0,IF('2020'!G33=0,0,'2021'!G33/'2020'!G33-1)) -> 0.24324324 | I33: ='2021'!H33-'2020'!H33 -> 9 | J33: =IF('2021'!H33=0,0,IF('2020'!H33=0,0,'2021'!H33/'2020'!H33-1)) -> 0.39130435 | K33: ='2021'!J33-'2020'!J33 -> 15.94 | L33: ='2021'!I33-'2020'!I33 -> 0.27217391 | M33: ='2021'!L33-'2020'!L33 -> 3.08 | N33: ='2021'!K33-'2020'!K33 -> 0.035652174 | O33: =IF('2020'!N33="-",0,'2021'!N33-'2020'!N33) -> 3.08 | P33: ='2021'!M33-'2020'!M33 -> 0 | U33: - | V33: - | W33: - | X33: -
