Workbook

Sheet Index
C3: Eléments à renseigner par chaque association dans l'onglet "2023"
D5: Colonne | F5: Ce qu'il faut renseigner
D7: Toutes les cellules blanches ne sont pas à renseigner (formule de calcul ou NC)
D9: Eléments obligatoires >> cellules en vert dans l'onglet "2023"
D10: DONNEES GENERALES | E10: D | F10: nombre de bénévoles par poste de comptage
E11: E | F11: nom/localisation du poste de comptage
E12: F | F12: implantation : France / Suisse / Frontière
E13: G | F13: nombre total de cyclistes comptés sur toute la période
E14: H | F14: nombre de cyclistes comptés sur l'heure de pointe (7h30 - 8h30) uniquement
E15: I | F15: calcul automatique (du nombre de VAE dans le total)
E16: J | F16: nombre de VAE dans le total (référence à la colonne G)
E17: K | F17: calcul automatique (du nombre de femmes dans le total)
E18: L | F18: nombre de femmes dans le total (référence à la colonne G)
D20: Eléments obligatoires pour les postes frontières et carrefours proches frontière
D21: >> cellules en bleu dans l'onglet "2023"
D22: FRONTIERE | E22: S | F22: nombre total de cyclistes comptés sur toute la période - Direction Suisse
E23: T | F23: nombre de cyclistes comptés sur l'heure de pointe (7h30 - 8h30) uniquement - Direction Suisse
E24: U | F24: nombre total de cyclistes comptés sur toute la période - Direction France
E25: V | F25: nombre de cyclistes comptés sur l'heure de pointe (7h30 - 8h30) uniquement - Direction France
D27: Eléments facultatifs >> cellules en rose dans l'onglet "2023"
D28: AUTRES DONNEES | E28: M | F28: calcul automatique (du nombre total de VAE chez les femmes)
E29: N | F29: nombre total de VAE chez les femmes (valeur spécifique à relever)
E30: O | F30: nombre total de personnes comptées sur toute la période en "autre mode" (trottinette, gyropode…)
E31: P | F31: nombre total de personnes comptées en HPM (7h30 - 8h30) en "autre mode" (trottinette, gyropode…)
E32: Q | F32: nombre total de piétons comptés sur toute la période
E33: R | F33: nombre total de piétons comptés en HPM (7h30 - 8h30)

Sheet 2020
E1: 7
A2: S | B2: Association(s) | C2: Arrière-pays | D2: Nombre de bénévoles | E2: Postes de comptage | F2: France / Suisse / Frontière | G2: Nombre de vélos | I2: % VAE dans le total | J2: NB VAE dans le total | K2: % femmes dans le total | L2: NB de femmes dans le total | M2: % de VAE chez les femmes | N2: NB de VAE chez les femmes | O2: Autres modes | Q2: Piétons | S2: > Suisse | U2: > France
A3: S
A4: S | G4: total | H4: HP | O4: total | P4: HP | Q4: total | R4: HP | S4: total | T4: HP | U4: total | V4: HP | AB4: 2020
A5: =IF(D5="Sous-total","S",IF(G5="","","X")) -> X | B5: UP Cluses | C5: OUI | D5: 2 | E5: CLUSES_Passerelle de Messy | F5: France | G5: =27+11+2+15+8 -> 63 | H5: 29 | I5: =2/G5 -> 0.031746032 | J5: =I5*G5 -> 2 | K5: =(2+15)/G5 -> 0.26984127 | L5: =K5*G5 -> 17 | M5: =2/17 -> 0.11764706 | N5: =IF(M5="-","-",M5*L5) -> 2 | AB5: =IF(G5>0,$F5,"") -> France
A6: =IF(D6="Sous-total","S",IF(G6="","","X")) | E6: COMMUNE_Carrefour
A7: =IF(D7="Sous-total","S",IF(G7="","","X")) | E7: COMMUNE_Carrefour
A8: =IF(D8="Sous-total","S",IF(G8="","","X")) -> S | D8: Sous-total | G8: =SUM(G5:G7) -> 63 | H8: =SUM(H5:H7) -> 29 | I8: =J8/G8 -> 0.031746032 | J8: =SUM(J5:J7) -> 2 | K8: =L8/G8 -> 0.26984127 | L8: =SUM(L5:L7) -> 17 | M8: =N8/L8 -> 0.11764706 | N8: =SUM(N5:N7) -> 2 | O8: =SUM(O5:O7) -> 0 | P8: =SUM(P5:P7) -> 0 | Q8: =SUM(Q5:Q7) -> 0 | R8: =SUM(R5:R7) -> 0 | S8: =SUM(S5:S7) -> 0 | T8: =SUM(T5:T7) -> 0 | U8: =SUM(U5:U7) -> 0 | V8: =SUM(V5:V7) -> 0
A9: =IF(D9="Sous-total","S",IF(G9="","","X")) | B9: L'Abeille (Contamine) | C9: OUI | E9: BONNE_Loëx (sous voie rapide) | F9: France | I9: =2/G9 -> #DIV/0! | K9: =(2+15)/G9 -> #DIV/0! | M9: =2/17 -> 0.11764706 | AB9: =IF(G9>0,$F9,"")
A10: =IF(D10="Sous-total","S",IF(G10="","","X"))
A11: =IF(D11="Sous-total","S",IF(G11="","","X"))
A12: =IF(D12="Sous-total","S",IF(G12="","","X")) -> S | D12: Sous-total | G12: =SUM(G9:G11) -> 0 | H12: =SUM(H9:H11) -> 0 | I12: =J12/G12 -> #DIV/0! | J12: =SUM(J9:J11) -> 0 | K12: =L12/G12 -> #DIV/0! | L12: =SUM(L9:L11) -> 0 | M12: =N12/L12 -> #DIV/0! | N12: =SUM(N9:N11) -> 0 | O12: =SUM(O9:O11) -> 0 | P12: =SUM(P9:P11) -> 0 | Q12: =SUM(Q9:Q11) -> 0 | R12: =SUM(R9:R11) -> 0 | S12: =SUM(S9:S11) -> 0 | T12: =SUM(T9:T11) -> 0 | U12: =SUM(U9:U11) -> 0 | V12: =SUM(V9:V11) -> 0
A13: =IF(D13="Sous-total","S",IF(G13="","","X")) | B13: AMDC (Chablais) | C13: OUI | E13: ALLINGES_Rond point des Fleysets | F13: France | I13: 0.32258065 | K13: 0.32258065 | M13: - | N13: - | O13: - | P13: - | Q13: - | R13: - | AB13: =IF(G13>0,$F13,"")
A14: =IF(D14="Sous-total","S",IF(G14="","","X")) | E14: BONS_Gare | F14: France | I14: 0.48 | K14: 0.36 | M14: - | N14: - | O14: - | P14: - | Q14: - | R14: - | AB14: =IF(G14>0,$F14,"")
A15: =IF(D15="Sous-total","S",IF(G15="","","X")) | E15: DOUVAINE_Mairie | F15: France | I15: 0.48 | K15: 0.36 | M15: - | N15: - | O15: - | P15: - | Q15: - | R15: - | AB15: =IF(G15>0,$F15,"")
A16: =IF(D16="Sous-total","S",IF(G16="","","X")) | E16: EVIAN_Gare | F16: France | I16: 0.48 | K16: 0.36 | M16: - | N16: - | O16: - | P16: - | Q16: - | R16: - | AB16: =IF(G16>0,$F16,"")
A17: =IF(D17="Sous-total","S",IF(G17="","","X")) | E17: PERRIGNIER_Gare | F17: France | I17: 0.48 | K17: 0.36 | M17: - | N17: - | O17: - | P17: - | Q17: - | R17: - | AB17: =IF(G17>0,$F17,"")
A18: =IF(D18="Sous-total","S",IF(G18="","","X")) | E18: THONON_Embarcadère CGN | F18: Frontière | I18: 0.48 | K18: 0.36 | M18: - | N18: - | O18: - | P18: - | Q18: - | R18: - | AB18: =IF(G18>0,$F18,"")
A19: =IF(D19="Sous-total","S",IF(G19="","","X")) | E19: THONON_Entrée côté place de Crête | F19: France | I19: 0.48 | K19: 0.36 | M19: - | N19: - | O19: - | P19: - | Q19: - | R19: - | AB19: =IF(G19>0,$F19,"")
A20: =IF(D20="Sous-total","S",IF(G20="","","X")) | E20: THONON_Parvis de la gare | F20: France | I20: 0.48 | K20: 0.36 | M20: - | N20: - | O20: - | P20: - | Q20: - | R20: - | AB20: =IF(G20>0,$F20,"")
A21: =IF(D21="Sous-total","S",IF(G21="","","X")) | E21: THONON_Avenue d’Evian | F21: France | I21: 0.48 | K21: 0.36 | M21: - | N21: - | O21: - | P21: - | Q21: - | R21: - | AB21: =IF(G21>0,$F21,"")
A22: =IF(D22="Sous-total","S",IF(G22="","","X")) | E22: THONON_Carrefour Libération | F22: France | I22: 0.48 | K22: 0.36 | M22: - | N22: - | O22: - | P22: - | Q22: - | R22: - | AB22: =IF(G22>0,$F22,"")
A23: =IF(D23="Sous-total","S",IF(G23="","","X")) | E23: THONON_Collège Champagne | F23: France | I23: 0.48 | K23: 0.36 | M23: - | N23: - | O23: - | P23: - | Q23: - | R23: - | AB23: =IF(G23>0,$F23,"")
A24: =IF(D24="Sous-total","S",IF(G24="","","X")) | E24: THONON_Ecole Jule Ferry | F24: France | I24: 0.48 | K24: 0.36 | M24: - | N24: - | O24: - | P24: - | Q24: - | R24: - | AB24: =IF(G24>0,$F24,"")
A25: =IF(D25="Sous-total","S",IF(G25="","","X")) | E25: THONON_Rond point J. Ferry G Andrier Pl des Arts Bld du Canal | F25: France | I25: 0.48 | K25: 0.36 | M25: - | N25: - | O25: - | P25: - | Q25: - | R25: - | AB25: =IF(G25>0,$F25,"")
... A28: =IF(D28="Sous-total","S",IF(G28="","","X")) | E28: VEIGY_Douane | F28: Frontière | I28: 0.5 | K28: 0 | M28: - | N28: - | O28: - | P28: - | Q28: - | R28: - | AB28: =IF(G28>0,$F28,"")
A29: =IF(D29="Sous-total","S",IF(G29="","","X")) | E29: COMMUNE_Carrefour
A30: =IF(D30="Sous-total","S",IF(G30="","","X")) | E30: COMMUNE_Carrefour
A31: =IF(D31="Sous-total","S",IF(G31="","","X")) | E31: COMMUNE_Carrefour
A32: =IF(D32="Sous-total","S",IF(G32="","","X")) | E32: COMMUNE_Carrefour
A33: =IF(D33="Sous-total","S",IF(G33="","","X")) | E33: COMMUNE_Carrefour
A34: =IF(D34="Sous-total","S",IF(G34="","","X")) -> S | D34: Sous-total | G34: =SUM(G13:G33) -> 0 | H34: =SUM(H13:H33) -> 0 | I34: =J34/G34 -> #DIV/0! | J34: =SUM(J13:J33) -> 0 | K34: =L34/G34 -> #DIV/0! | L34: =SUM(L13:L33) -> 0 | M34: =N34/L34 -> #DIV/0! | N34: =SUM(N13:N33) -> 0 | O34: =SUM(O13:O33) -> 0 | P34: =SUM(P13:P33) -> 0 | Q34: =SUM(Q13:Q33) -> 0 | R34: =SUM(R13:R33) -> 0 | S34: =SUM(S13:S33) -> 0 | T34: =SUM(T13:T33) -> 0 | U34: =SUM(U13:U33) -> 0 | V34: =SUM(V13:V33) -> 0 | AB34: =IF(G34>0,$F34,"")
A35: =IF(D35="Sous-total","S",IF(G35="","","X")) -> X | B35: NatEnv & Fabrique à Biclou | C35: OUI | D35: 8 | E35: LA ROCHE_Carrefour Biocoop | F35: France | G35: 31 | H35: 23 | I35: 0.32258065 | J35: =I35*G35 -> 10 | K35: 0.32258065 | L35: =K35*G35 -> 10 | M35: - | N35: - | O35: - | P35: - | Q35: - | R35: - | AB35: =IF(G35>0,$F35,"") -> France
A36: =IF(D36="Sous-total","S",IF(G36="","","X")) -> X | E36: LA ROCHE_Giratoire La Poste | F36: France | G36: 25 | H36: 13 | I36: 0.48 | J36: =I36*G36 -> 12 | K36: 0.36 | L36: =K36*G36 -> 9 | M36: - | N36: - | O36: - | P36: - | Q36: - | R36: - | AB36: =IF(G36>0,$F36,"") -> France
A37: =IF(D37="Sous-total","S",IF(G37="","","X")) -> X | E37: LA ROCHE_Giratoire ENILV | F37: France | G37: 18 | H37: 10 | I37: 0.5 | J37: =I37*G37 -> 9 | K37: 0.16666667 | L37: =K37*G37 -> 3 | M37: - | N37: - | O37: - | P37: - | Q37: - | R37: - | AB37: =IF(G37>0,$F37,"") -> France
A38: =IF(D38="Sous-total","S",IF(G38="","","X")) | E38: LA ROCHE_Gare Passage à niveau (new 2021) | F38: France | I38: 0.5 | K38: 0.16666667 | M38: - | N38: - | O38: - | P38: - | Q38: - | R38: - | AB38: =IF(G38>0,$F38,"")
A39: =IF(D39="Sous-total","S",IF(G39="","","X")) -> X | E39: ARENTHON_La Papeterie | F39: France | G39: 14 | H39: 9 | I39: 0.071428571 | J39: =I39*G39 -> 1 | K39: 0.071428571 | L39: =K39*G39 -> 1 | M39: - | N39: - | O39: - | P39: - | Q39: - | R39: - | AB39: =IF(G39>0,$F39,"") -> France
A40: =IF(D40="Sous-total","S",IF(G40="","","X")) -> X | E40: ST-PIERRE_Franchissement Borne-Dessy | F40: France | G40: 24 | H40: 16 | I40: 0.041666667 | J40: =I40*G40 -> 1 | K40: 0.20833333 | L40: =K40*G40 -> 5 | M40: - | N40: - | O40: - | P40: - | Q40: - | R40: - | AB40: =IF(G40>0,$F40,"") -> France
A41: =IF(D41="Sous-total","S",IF(G41="","","X")) -> X | E41: BONNEVILLE_Franchissement Borne-Tucinge | F41: France | G41: 29 | H41: 21 | I41: 0 | J41: =I41*G41 -> 0 | K41: 0.4137931 | L41: =K41*G41 -> 12 | M41: - | N41: - | O41: - | P41: - | Q41: - | R41: - | AB41: =IF(G41>0,$F41,"") -> France
A42: =IF(D42="Sous-total","S",IF(G42="","","X")) -> X | E42: ST-PIERRE_Pont principal sur le Borne | F42: France | G42: 27 | H42: 17 | I42: 0.25925926 | J42: =I42*G42 -> 7 | K42: 0.48148148 | L42: =K42*G42 -> 13 | M42: - | N42: - | O42: - | P42: - | Q42: - | R42: - | AB42: =IF(G42>0,$F42,"") -> France
...

Sheet 2021
E1: 7
A2: S | B2: Association(s) | C2: Arrière-pays | D2: Nombre de bénévoles | E2: Postes de comptage | F2: France / Suisse / Frontière | G2: Nombre de vélos | I2: % VAE dans le total | J2: NB VAE dans le total | K2: % femmes dans le total | L2: NB de femmes dans le total | M2: % de VAE chez les femmes | N2: NB de VAE chez les femmes | O2: Autres modes | Q2: Piétons | S2: > Suisse | U2: > France
A3: S
A4: S | G4: total | H4: HP | O4: total | P4: HP | Q4: total | R4: HP | S4: total | T4: HP | U4: total | V4: HP | AB4: 2020
A5: =IF(D5="Sous-total","S",IF(G5="","","X")) -> X | B5: UP Cluses | C5: OUI | D5: 2 | E5: CLUSES_Passerelle de Messy | F5: France | G5: 102 | H5: 94 | I5: =J5/G5 -> 0.019607843 | J5: 2 | K5: =L5/G5 -> 0.17647059 | L5: 18 | M5: =IF(N5="-","-",N5/L5) -> 0.11111111 | N5: 2 | AB5: =IF(G5>0,$F5,"") -> France
A6: =IF(D6="Sous-total","S",IF(G6="","","X")) | E6: COMMUNE_Carrefour
A7: =IF(D7="Sous-total","S",IF(G7="","","X")) | E7: COMMUNE_Carrefour
A8: =IF(D8="Sous-total","S",IF(G8="","","X")) -> S | D8: Sous-total | G8: =SUM(G5:G7) -> 102 | H8: =SUM(H5:H7) -> 94 | I8: =J8/G8 -> 0.019607843 | J8: =SUM(J5:J7) -> 2 | K8: =L8/G8 -> 0.17647059 | L8: =SUM(L5:L7) -> 18 | M8: =N8/L8 -> 0.11111111 | N8: =SUM(N5:N7) -> 2 | O8: =SUM(O5:O7) -> 0 | P8: =SUM(P5:P7) -> 0 | Q8: =SUM(Q5:Q7) -> 0 | R8: =SUM(R5:R7) -> 0 | S8: =SUM(S5:S7) -> 0 | T8: =SUM(T5:T7) -> 0 | U8: =SUM(U5:U7) -> 0 | V8: =SUM(V5:V7) -> 0
A9: =IF(D9="Sous-total","S",IF(G9="","","X")) | B9: L'Abeille (Contamine) | C9: OUI | E9: BONNE_Loëx (sous voie rapide) | F9: France | I9: =J9/G9 -> #DIV/0! | K9: =L9/G9 -> #DIV/0! | M9: =IF(N9="-","-",N9/L9) -> #DIV/0! | AB9: =IF(G9>0,$F9,"")
A10: =IF(D10="Sous-total","S",IF(G10="","","X"))
A11: =IF(D11="Sous-total","S",IF(G11="","","X"))
A12: =IF(D12="Sous-total","S",IF(G12="","","X")) -> S | D12: Sous-total | G12: =SUM(G9:G11) -> 0 | H12: =SUM(H9:H11) -> 0 | I12: =J12/G12 -> #DIV/0! | J12: =SUM(J9:J11) -> 0 | K12: =L12/G12 -> #DIV/0! | L12: =SUM(L9:L11) -> 0 | M12: =N12/L12 -> #DIV/0! | N12: =SUM(N9:N11) -> 0 | O12: =SUM(O9:O11) -> 0 | P12: =SUM(P9:P11) -> 0 | Q12: =SUM(Q9:Q11) -> 0 | R12: =SUM(R9:R11) -> 0 | S12: =SUM(S9:S11) -> 0 | T12: =SUM(T9:T11) -> 0 | U12: =SUM(U9:U11) -> 0 | V12: =SUM(V9:V11) -> 0
A13: =IF(D13="Sous-total","S",IF(G13="","","X")) | B13: AMDC (Chablais) | C13: OUI | E13: ALLINGES_Rond point des Fleysets | F13: France | I13: =J13/G13 -> #DIV/0! | K13: =L13/G13 -> #DIV/0! | M13: =IF(N13="-","-",N13/L13) -> - | N13: - | O13: - | P13: - | Q13: - | R13: - | S13: - | T13: - | U13: - | V13: - | AB13: =IF(G13>0,$F13,"")
A14: =IF(D14="Sous-total","S",IF(G14="","","X")) | E14: BONS_Gare | F14: France | I14: =J14/G14 -> #DIV/0! | K14: =L14/G14 -> #DIV/0! | M14: =IF(N14="-","-",N14/L14) -> - | N14: - | O14: - | P14: - | Q14: - | R14: - | S14: - | T14: - | U14: - | V14: - | AB14: =IF(G14>0,$F14,"")
A15: =IF(D15="Sous-total","S",IF(G15="","","X")) | E15: DOUVAINE_Mairie | F15: France | I15: =J15/G15 -> #DIV/0! | K15: =L15/G15 -> #DIV/0! | M15: =IF(N15="-","-",N15/L15) -> - | N15: - | O15: - | P15: - | Q15: - | R15: - | S15: - | T15: - | U15: - | V15: - | AB15: =IF(G15>0,$F15,"")
A16: =IF(D16="Sous-total","S",IF(G16="","","X")) | E16: EVIAN_Gare | F16: France | I16: =J16/G16 -> #DIV/0! | K16: =L16/G16 -> #DIV/0! | M16: =IF(N16="-","-",N16/L16) -> - | N16: - | O16: - | P16: - | Q16: - | R16: - | S16: - | T16: - | U16: - | V16: - | AB16: =IF(G16>0,$F16,"")
A17: =IF(D17="Sous-total","S",IF(G17="","","X")) | E17: PERRIGNIER_Gare | F17: France | I17: =J17/G17 -> #DIV/0! | K17: =L17/G17 -> #DIV/0! | M17: =IF(N17="-","-",N17/L17) -> - | N17: - | O17: - | P17: - | Q17: - | R17: - | S17: - | T17: - | U17: - | V17: - | AB17: =IF(G17>0,$F17,"")
A18: =IF(D18="Sous-total","S",IF(G18="","","X")) | E18: THONON_Embarcadère CGN | F18: Frontière | I18: =J18/G18 -> #DIV/0! | K18: =L18/G18 -> #DIV/0! | M18: =IF(N18="-","-",N18/L18) -> - | N18: - | O18: - | P18: - | Q18: - | R18: - | S18: - | T18: - | U18: - | V18: - | AB18: =IF(G18>0,$F18,"")
A19: =IF(D19="Sous-total","S",IF(G19="","","X")) | E19: THONON_Entrée côté place de Crête | F19: France | I19: =J19/G19 -> #DIV/0! | K19: =L19/G19 -> #DIV/0! | M19: =IF(N19="-","-",N19/L19) -> - | N19: - | O19: - | P19: - | Q19: - | R19: - | S19: - | T19: - | U19: - | V19: - | AB19: =IF(G19>0,$F19,"")
A20: =IF(D20="Sous-total","S",IF(G20="","","X")) | E20: THONON_Parvis de la gare | F20: France | I20: =J20/G20 -> #DIV/0! | K20: =L20/G20 -> #DIV/0! | M20: =IF(N20="-","-",N20/L20) -> - | N20: - | O20: - | P20: - | Q20: - | R20: - | S20: - | T20: - | U20: - | V20: - | AB20: =IF(G20>0,$F20,"")
A21: =IF(D21="Sous-total","S",IF(G21="","","X")) | E21: THONON_Avenue d’Evian | F21: France | I21: =J21/G21 -> #DIV/0! | K21: =L21/G21 -> #DIV/0! | M21: =IF(N21="-","-",N21/L21) -> - | N21: - | O21: - | P21: - | Q21: - | R21: - | S21: - | T21: - | U21: - | V21: - | AB21: =IF(G21>0,$F21,"")
A22: =IF(D22="Sous-total","S",IF(G22="","","X")) | E22: THONON_Carrefour Libération | F22: France | I22: =J22/G22 -> #DIV/0! | K22: =L22/G22 -> #DIV/0! | M22: =IF(N22="-","-",N22/L22) -> - | N22: - | O22: - | P22: - | Q22: - | R22: - | S22: - | T22: - | U22: - | V22: - | AB22: =IF(G22>0,$F22,"")
A23: =IF(D23="Sous-total","S",IF(G23="","","X")) | E23: THONON_Collège Champagne | F23: France | I23: =J23/G23 -> #DIV/0! | K23: =L23/G23 -> #DIV/0! | M23: =IF(N23="-","-",N23/L23) -> - | N23: - | O23: - | P23: - | Q23: - | R23: - | S23: - | T23: - | U23: - | V23: - | AB23: =IF(G23>0,$F23,"")
A24: =IF(D24="Sous-total","S",IF(G24="","","X")) | E24: THONON_Ecole Jule Ferry | F24: France | I24: =J24/G24 -> #DIV/0! | K24: =L24/G24 -> #DIV/0! | M24: =IF(N24="-","-",N24/L24) -> - | N24: - | O24: - | P24: - | Q24: - | R24: - | S24: - | T24: - | U24: - | V24: - | AB24: =IF(G24>0,$F24,"")
A25: =IF(D25="Sous-total","S",IF(G25="","","X")) | E25: THONON_Rond point J. Ferry G Andrier Pl des Arts Bld du Canal | F25: France | I25: =J25/G25 -> #DIV/0! | K25: =L25/G25 -> #DIV/0! | M25: =IF(N25="-","-",N25/L25) -> - | N25: - | O25: - | P25: - | Q25: - | R25: - | S25: - | T25: - | U25: - | V25: - | AB25: =IF(G25>0,$F25,"")
... A28: =IF(D28="Sous-total","S",IF(G28="","","X")) | E28: VEIGY_Douane | F28: Frontière | I28: =J28/G28 -> #DIV/0! | K28: =L28/G28 -> #DIV/0! | M28: =IF(N28="-","-",N28/L28) -> - | N28: - | O28: - | P28: - | Q28: - | R28: - | S28: - | T28: - | U28: - | V28: - | AB28: =IF(G28>0,$F28,"")
A29: =IF(D29="Sous-total","S",IF(G29="","","X")) | E29: COMMUNE_Carrefour
A30: =IF(D30="Sous-total","S",IF(G30="","","X")) | E30: COMMUNE_Carrefour
A31: =IF(D31="Sous-total","S",IF(G31="","","X")) | E31: COMMUNE_Carrefour
A32: =IF(D32="Sous-total","S",IF(G32="","","X")) | E32: COMMUNE_Carrefour
A33: =IF(D33="Sous-total","S",IF(G33="","","X")) | E33: COMMUNE_Carrefour
A34: =IF(D34="Sous-total","S",IF(G34="","","X")) -> S | D34: Sous-total | G34: =SUM(G13:G33) -> 0 | H34: =SUM(H13:H33) -> 0 | I34: =J34/G34 -> #DIV/0! | J34: =SUM(J13:J33) -> 0 | K34: =L34/G34 -> #DIV/0! | L34: =SUM(L13:L33) -> 0 | M34: =N34/L34 -> #DIV/0! | N34: =SUM(N13:N33) -> 0 | O34: =SUM(O13:O33) -> 0 | P34: =SUM(P13:P33) -> 0 | Q34: =SUM(Q13:Q33) -> 0 | R34: =SUM(R13:R33) -> 0 | S34: =SUM(S13:S33) -> 0 | T34: =SUM(T13:T33) -> 0 | U34: =SUM(U13:U33) -> 0 | V34: =SUM(V13:V33) -> 0 | AB34: =IF(G34>0,$F34,"")
A35: =IF(D35="Sous-total","S",IF(G35="","","X")) -> X | B35: NatEnv (Nature Environnement en Pays rochois) Fabrique à Biclou Pays rochois en Transition | C35: OUI | D35: 9 | E35: LA ROCHE_Carrefour Biocoop | F35: France | G35: 76 | H35: 50 | I35: =J35/G35 -> 0.22368421 | J35: 17 | K35: =L35/G35 -> 0.36842105 | L35: 28 | M35: =IF(N35="-","-",N35/L35) -> - | N35: - | O35: - | P35: - | Q35: - | R35: - | S35: - | T35: - | U35: - | V35: - | AB35: =IF(G35>0,$F35,"") -> France
A36: =IF(D36="Sous-total","S",IF(G36="","","X")) -> X | E36: LA ROCHE_Giratoire La Poste | F36: France | G36: 45 | H36: 27 | I36: =J36/G36 -> 0.46666667 | J36: 21 | K36: =L36/G36 -> 0.31111111 | L36: 14 | M36: =IF(N36="-","-",N36/L36) -> - | N36: - | O36: - | P36: - | Q36: - | R36: - | S36: - | T36: - | U36: - | V36: - | AB36: =IF(G36>0,$F36,"") -> France
A37: =IF(D37="Sous-total","S",IF(G37="","","X")) -> X | E37: LA ROCHE_Giratoire ENILV | F37: France | G37: 16 | H37: 10 | I37: =J37/G37 -> 0.3125 | J37: 5 | K37: =L37/G37 -> 0.1875 | L37: 3 | M37: =IF(N37="-","-",N37/L37) -> - | N37: - | O37: - | P37: - | Q37: - | R37: - | S37: - | T37: - | U37: - | V37: - | AB37: =IF(G37>0,$F37,"") -> France
A38: =IF(D38="Sous-total","S",IF(G38="","","X")) -> X | E38: LA ROCHE_Gare Passage à niveau (new 2021) | F38: France | G38: 56 | H38: 36 | I38: =J38/G38 -> 0.21428571 | J38: 12 | K38: =L38/G38 -> 0.17857143 | L38: 10 | M38: =IF(N38="-","-",N38/L38) -> - | N38: - | O38: - | P38: - | Q38: - | R38: - | AB38: =IF(G38>0,$F38,"") -> France
A39: =IF(D39="Sous-total","S",IF(G39="","","X")) -> X | E39: ARENTHON_La Papeterie | F39: France | G39: 13 | H39: 8 | I39: =J39/G39 -> 0.53846154 | J39: 7 | K39: =L39/G39 -> 0.46153846 | L39: 6 | M39: =IF(N39="-","-",N39/L39) -> - | N39: - | O39: - | P39: - | Q39: - | R39: - | S39: - | T39: - | U39: - | V39: - | AB39: =IF(G39>0,$F39,"") -> France
A40: =IF(D40="Sous-total","S",IF(G40="","","X")) -> X | E40: ST-PIERRE_Franchissement Borne-Dessy | F40: France | G40: 24 | H40: 20 | I40: =J40/G40 -> 0.29166667 | J40: 7 | K40: =L40/G40 -> 0.29166667 | L40: 7 | M40: =IF(N40="-","-",N40/L40) -> - | N40: - | O40: - | P40: - | Q40: - | R40: - | S40: - | T40: - | U40: - | V40: - | AB40: =IF(G40>0,$F40,"") -> France
A41: =IF(D41="Sous-total","S",IF(G41="","","X")) -> X | E41: BONNEVILLE_Franchissement Borne-Tucinge | F41: France | G41: 33 | H41: 25 | I41: =J41/G41 -> 0 | J41: 0 | K41: =L41/G41 -> 0.21212121 | L41: 7 | M41: =IF(N41="-","-",N41/L41) -> - | N41: - | O41: - | P41: - | Q41: - | R41: - | S41: - | T41: - | U41: - | V41: - | AB41: =IF(G41>0,$F41,"") -> France
A42: =IF(D42="Sous-total","S",IF(G42="","","X")) -> X | E42: ST-PIERRE_Pont principal sur le Borne | F42: France | G42: 32 | H42: 17 | I42: =J42/G42 -> 0.15625 | J42: 5 | K42: =L42/G42 -> 0.375 | L42: 12 | M42: =IF(N42="-","-",N42/L42) -> - | N42: - | O42: - | P42: - | Q42: - | R42: - | S42: - | T42: - | U42: - | V42: - | AB42: =IF(G42>0,$F42,"") -> France
...

Sheet 2022
E1: 7
A2: S | B2: Association(s) | C2: Arrière-pays | D2: Nombre de bénévoles | E2: Postes de comptage | F2: France / Suisse / Frontière | G2: Nombre de vélos | I2: % VAE dans le total | J2: NB VAE dans le total | K2: % femmes dans le total | L2: NB de femmes dans le total | M2: % de VAE chez les femmes | N2: NB de VAE chez les femmes | O2: Autres modes | Q2: Piétons | S2: > Suisse | U2: > France
A3: S
A4: S | G4: total | H4: HP | O4: total | P4: HP | Q4: total | R4: HP | S4: total | T4: HP | U4: total | V4: HP | AB4: 2020
A5: =IF(D5="Sous-total","S",IF(G5="","","X")) -> X | B5: UP Cluses | C5: OUI | D5: 2 | E5: CLUSES_Passerelle de Messy | F5: France | G5: 72 | H5: 72 | I5: =IF(J5="","",J5/G5) | K5: =IF(L5="","",L5/G5) | M5: =IF(N5="","",N5/L5) | S5: - | T5: - | U5: - | V5: - | AB5: =IF(G5<>"",$F5,"") -> France
A6: =IF(D6="Sous-total","S",IF(G6="","","X")) | E6: COMMUNE_Carrefour | S6: - | T6: - | U6: - | V6: -
A7: =IF(D7="Sous-total","S",IF(G7="","","X")) | E7: COMMUNE_Carrefour | S7: - | T7: - | U7: - | V7: -
A8: =IF(D8="Sous-total","S",IF(G8="","","X")) -> S | D8: Sous-total | G8: =SUM(G5:G7) -> 72 | H8: =SUM(H5:H7) -> 72 | I8: =IF(J8="","",J8/G8) -> 0 | J8: =SUM(J5:J7) -> 0 | K8: =IF(L8="","",L8/G8) -> 0 | L8: =SUM(L5:L7) -> 0 | M8: =IF(N8="","",N8/L8) -> #DIV/0! | N8: =SUM(N5:N7) -> 0 | O8: =SUM(O5:O7) -> 0 | P8: =SUM(P5:P7) -> 0 | Q8: =SUM(Q5:Q7) -> 0 | R8: =SUM(R5:R7) -> 0 | S8: =SUM(S5:S7) -> 0 | T8: =SUM(T5:T7) -> 0 | U8: =SUM(U5:U7) -> 0 | V8: =SUM(V5:V7) -> 0
A9: =IF(D9="Sous-total","S",IF(G9="","","X")) -> X | B9: L'Abeille (Contamine) | C9: OUI | E9: BONNE_Loëx (sous voie rapide) | F9: France | G9: 20 | H9: 9 | I9: =IF(J9="","",J9/G9) -> 0.4 | J9: 8 | K9: =IF(L9="","",L9/G9) -> 0.2 | L9: 4 | M9: =IF(N9="","",N9/L9) -> 0.5 | N9: 2 | S9: - | T9: - | U9: - | V9: - | W9: OK | AB9: =IF(G9<>"",$F9,"") -> France
A10: =IF(D10="Sous-total","S",IF(G10="","","X")) | S10: - | T10: - | U10: - | V10: -
A11: =IF(D11="Sous-total","S",IF(G11="","","X")) | S11: - | T11: - | U11: - | V11: -
A12: =IF(D12="Sous-total","S",IF(G12="","","X")) -> S | D12: Sous-total | G12: =SUM(G9:G11) -> 20 | H12: =SUM(H9:H11) -> 9 | I12: =IF(J12="","",J12/G12) -> 0.4 | J12: =SUM(J9:J11) -> 8 | K12: =IF(L12="","",L12/G12) -> 0.2 | L12: =SUM(L9:L11) -> 4 | M12: =IF(N12="","",N12/L12) -> 0.5 | N12: =SUM(N9:N11) -> 2 | O12: =SUM(O9:O11) -> 0 | P12: =SUM(P9:P11) -> 0 | Q12: =SUM(Q9:Q11) -> 0 | R12: =SUM(R9:R11) -> 0 | S12: =SUM(S9:S11) -> 0 | T12: =SUM(T9:T11) -> 0 | U12: =SUM(U9:U11) -> 0 | V12: =SUM(V9:V11) -> 0 | W12: OK
A13: =IF(D13="Sous-total","S",IF(G13="","","X")) -> X | B13: AMDC (Chablais) | C13: OUI | D13: 18 | E13: ALLINGES_Rond point des Fleysets | F13: France | G13: 23 | H13: =G13 -> 23 | I13: =IF(J13="","",J13/G13) -> 0.47826087 | J13: 11 | K13: =IF(L13="","",L13/G13) -> 0.47826087 | L13: 11 | M13: =IF(N13="","",N13/L13) -> 0.90909091 | N13: 10 | O13: 0 | W13: OK | AB13: =IF(G13<>"",$F13,"") -> France
A14: =IF(D14="Sous-total","S",IF(G14="","","X")) -> X | E14: BONS_Gare | F14: France | G14: 25 | H14: =G14-12 -> 13 | I14: =IF(J14="","",J14/G14) -> 0.4 | J14: 10 | K14: =IF(L14="","",L14/G14) -> 0.44 | L14: 11 | M14: =IF(N14="","",N14/L14) -> 0.63636364 | N14: 7 | O14: 22 | W14: OK | AB14: =IF(G14<>"",$F14,"") -> France
A15: =IF(D15="Sous-total","S",IF(G15="","","X")) -> X | E15: DOUVAINE_Mairie | F15: France | G15: 20 | H15: =G15 -> 20 | I15: =IF(J15="","",J15/G15) -> 0.45 | J15: 9 | K15: =IF(L15="","",L15/G15) -> 0.4 | L15: 8 | M15: =IF(N15="","",N15/L15) -> 0.375 | N15: 3 | O15: 6 | W15: OK | AB15: =IF(G15<>"",$F15,"") -> France
A16: =IF(D16="Sous-total","S",IF(G16="","","X")) -> X | E16: EVIAN_Gare | F16: France | G16: 13 | H16: =G16-1 -> 12 | I16: =IF(J16="","",J16/G16) -> 0.15384615 | J16: 2 | K16: =IF(L16="","",L16/G16) -> 0.30769231 | L16: 4 | M16: =IF(N16="","",N16/L16) -> 0.5 | N16: 2 | O16: 7 | W16: OK | AB16: =IF(G16<>"",$F16,"") -> France
A17: =IF(D17="Sous-total","S",IF(G17="","","X")) -> X | E17: PERRIGNIER_Gare | F17: France | G17: 7 | H17: =G17-1 -> 6 | I17: =IF(J17="","",J17/G17) -> 0.28571429 | J17: 2 | K17: =IF(L17="","",L17/G17) -> 0 | L17: 0 | M17: =IF(N17="","",N17/L17) | O17: 6 | W17: OK | AB17: =IF(G17<>"",$F17,"") -> France
A18: =IF(D18="Sous-total","S",IF(G18="","","X")) -> X | E18: THONON_Embarcadère CGN | F18: Frontière | G18: 74 | H18: =G18-44 -> 30 | I18: =IF(J18="","",J18/G18) -> 0.2972973 | J18: 22 | K18: =IF(L18="","",L18/G18) -> 0.36486486 | L18: 27 | M18: =IF(N18="","",N18/L18) -> 0.48148148 | N18: 13 | O18: 101 | S18: 74 | T18: 30 | U18: 0 | V18: 0 | W18: OK | AB18: =IF(G18<>"",$F18,"") -> Frontière
A19: =IF(D19="Sous-total","S",IF(G19="","","X")) -> X | E19: THONON_Entrée côté place de Crête | F19: France | G19: 34 | H19: =G19 -> 34 | I19: =IF(J19="","",J19/G19) -> 0.17647059 | J19: 6 | K19: =IF(L19="","",L19/G19) -> 0.38235294 | L19: 13 | M19: =IF(N19="","",N19/L19) -> 0.15384615 | N19: 2 | O19: 12 | W19: OK | AB19: =IF(G19<>"",$F19,"") -> France
A20: =IF(D20="Sous-total","S",IF(G20="","","X")) -> X | E20: THONON_Parvis de la gare | F20: France | G20: 47 | H20: =G20 -> 47 | I20: =IF(J20="","",J20/G20) -> 0.063829787 | J20: 3 | K20: =IF(L20="","",L20/G20) -> 0.31914894 | L20: 15 | M20: =IF(N20="","",N20/L20) -> 0.2 | N20: 3 | O20: 37 | W20: OK | AB20: =IF(G20<>"",$F20,"") -> France
A21: =IF(D21="Sous-total","S",IF(G21="","","X")) -> X | E21: THONON_Avenue d’Evian | F21: France | G21: 92 | H21: =G21 -> 92 | I21: =IF(J21="","",J21/G21) -> 0.097826087 | J21: 9 | K21: =IF(L21="","",L21/G21) -> 0.45652174 | L21: 42 | M21: =IF(N21="","",N21/L21) -> 0.14285714 | N21: 6 | O21: 19 | W21: OK | AB21: =IF(G21<>"",$F21,"") -> France
A22: =IF(D22="Sous-total","S",IF(G22="","","X")) -> X | E22: THONON_Carrefour Libération | F22: France | G22: 77 | H22: =G22 -> 77 | I22: =IF(J22="","",J22/G22) -> 0.14285714 | J22: 11 | K22: =IF(L22="","",L22/G22) -> 0.4025974 | L22: 31 | M22: =IF(N22="","",N22/L22) -> 0.16129032 | N22: 5 | O22: 20 | W22: OK | AB22: =IF(G22<>"",$F22,"") -> France
A23: =IF(D23="Sous-total","S",IF(G23="","","X")) -> X | E23: THONON_Collège Champagne | F23: France | G23: 19 | H23: =G23 -> 19 | I23: =IF(J23="","",J23/G23) -> 0.21052632 | J23: 4 | K23: =IF(L23="","",L23/G23) -> 0.31578947 | L23: 6 | M23: =IF(N23="","",N23/L23) -> 0.16666667 | N23: 1 | O23: 3 | W23: OK | AB23: =IF(G23<>"",$F23,"") -> France
A24: =IF(D24="Sous-total","S",IF(G24="","","X")) -> X | E24: THONON_Ecole Jule Ferry | F24: France | G24: 24 | H24: =G24 -> 24 | I24: =IF(J24="","",J24/G24) -> 0.29166667 | J24: 7 | K24: =IF(L24="","",L24/G24) -> 0.54166667 | L24: 13 | M24: =IF(N24="","",N24/L24) -> 0.46153846 | N24: 6 | O24: 11 | W24: OK | AB24: =IF(G24<>"",$F24,"") -> France
A25: =IF(D25="Sous-total","S",IF(G25="","","X")) -> X | E25: THONON_Rond point J. Ferry G Andrier Pl des Arts Bld du Canal | F25: France | G25: 101 | H25: =G25 -> 101 | I25: =IF(J25="","",J25/G25) -> 0.14851485 | J25: 15 | K25: =IF(L25="","",L25/G25) -> 0.3960396 | L25: 40 | M25: =IF(N25="","",N25/L25) -> 0.225 | N25: 9 | O25: 34 | W25: OK | AB25: =IF(G25<>"",$F25,"") -> France
A26: =IF(D26="Sous-total","S",IF(G26="","","X")) -> X | E26: THONON/ANTHY_Pont de Marclaz | F26: France | G26: 25 | H26: =G26 -> 25 | I26: =IF(J26="","",J26/G26) -> 0.28 | J26: 7 | K26: =IF(L26="","",L26/G26) -> 0.24 | L26: 6 | M26: =IF(N26="","",N26/L26) -> 0.66666667 | N26: 4 | O26: 4 | W26: OK | AB26: =IF(G26<>"",$F26,"") -> France
A27: =IF(D27="Sous-total","S",IF(G27="","","X")) -> X | E27: THONON/MARIN_Pont de Dranse | F27: France | G27: 45 | H27: =G27 -> 45 | I27: =IF(J27="","",J27/G27) -> 0.4 | J27: 18 | K27: =IF(L27="","",L27/G27) -> 0.22222222 | L27: 10 | M27: =IF(N27="","",N27/L27) -> 0.6 | N27: 6 | O27: 4 | W27: OK | AB27: =IF(G27<>"",$F27,"") -> France
A28: =IF(D28="Sous-total","S",IF(G28="","","X")) -> X | E28: VEIGY_Douane | F28: Frontière | G28: 68 | H28: =G28-25 -> 43 | I28: =IF(J28="","",J28/G28) -> 0.51470588 | J28: 35 | K28: =IF(L28="","",L28/G28) -> 0.44117647 | L28: 30 | M28: =IF(N28="","",N28/L28) -> 0.53333333 | N28: 16 | O28: 1 | Q28: 16 | S28: 61 | T28: 38 | U28: 7 | V28: 5 | W28: OK | AB28: =IF(G28<>"",$F28,"") -> Frontière
A29: =IF(D29="Sous-total","S",IF(G29="","","X")) | E29: COMMUNE_Carrefour
A30: =IF(D30="Sous-total","S",IF(G30="","","X")) | E30: COMMUNE_Carrefour
A31: =IF(D31="Sous-total","S",IF(G31="","","X")) | E31: COMMUNE_Carrefour
A32: =IF(D32="Sous-total","S",IF(G32="","","X")) | E32: COMMUNE_Carrefour
A33: =IF(D33="Sous-total","S",IF(G33="","","X")) | E33: COMMUNE_Carrefour
A34: =IF(D34="Sous-total","S",IF(G34="","","X")) -> S | D34: Sous-total | G34: =SUM(G13:G33) -> 694 | H34: =SUM(H13:H33) -> 611 | I34: =IF(J34="","",J34/G34) -> 0.24639769 | J34: =SUM(J13:J33) -> 171 | K34: =IF(L34="","",L34/G34) -> 0.38472622 | L34: =SUM(L13:L33) -> 267 | M34: =IF(N34="","",N34/L34) -> 0.34831461 | N34: =SUM(N13:N33) -> 93 | O34: =SUM(O13:O33) -> 287 | P34: =SUM(P13:P33) -> 0 | Q34: =SUM(Q13:Q33) -> 16 | R34: =SUM(R13:R33) -> 0 | S34: =SUM(S13:S33) -> 135 | T34: =SUM(T13:T33) -> 68 | U34: =SUM(U13:U33) -> 7 | V34: =SUM(V13:V33) -> 5 | W34: OK | AB34: =IF(G34<>"",$F34,"") -> 0
A35: =IF(D35="Sous-total","S",IF(G35="","","X")) -> X | B35: NatEnv (Nature Environnement en Pays rochois) Fabrique à Biclou Pays rochois en Transition | C35: OUI | D35: 11 | E35: LA ROCHE_Carrefour Biocoop | F35: France | G35: 59 | H35: 21 | I35: =IF(J35="","",J35/G35) -> 0.47457627 | J35: 28 | K35: =IF(L35="","",L35/G35) -> 0.33898305 | L35: 20 | M35: =IF(N35="","",N35/L35) | O35: 14 | S35: - | T35: - | U35: - | V35: - | W35: OK | AB35: =IF(G35<>"",$F35,"") -> France
A36: =IF(D36="Sous-total","S",IF(G36="","","X")) -> X | E36: LA ROCHE_Giratoire La Poste | F36: France | G36: 32 | H36: 16 | I36: =IF(J36="","",J36/G36) -> 0.34375 | J36: 11 | K36: =IF(L36="","",L36/G36) -> 0.1875 | L36: 6 | M36: =IF(N36="","",N36/L36) | O36: 15 | S36: - | T36: - | U36: - | V36: - | W36: OK | AB36: =IF(G36<>"",$F36,"") -> France
A37: =IF(D37="Sous-total","S",IF(G37="","","X")) -> X | E37: LA ROCHE_Giratoire ENILV | F37: France | G37: 21 | H37: 8 | I37: =IF(J37="","",J37/G37) -> 0.19047619 | J37: 4 | K37: =IF(L37="","",L37/G37) -> 0.23809524 | L37: 5 | M37: =IF(N37="","",N37/L37) | O37: 4 | S37: - | T37: - | U37: - | V37: - | W37: OK | AB37: =IF(G37<>"",$F37,"") -> France
A38: =IF(D38="Sous-total","S",IF(G38="","","X")) -> X | E38: LA ROCHE_Gare Passage à niveau (new 2021) | F38: France | G38: 55 | H38: 21 | I38: =IF(J38="","",J38/G38) -> 0.32727273 | J38: 18 | K38: =IF(L38="","",L38/G38) -> 0.32727273 | L38: 18 | M38: =IF(N38="","",N38/L38) | O38: 20 | S38: - | T38: - | U38: - | V38: - | W38: OK | AB38: =IF(G38<>"",$F38,"") -> France
A39: =IF(D39="Sous-total","S",IF(G39="","","X")) -> X | E39: ARENTHON_La Papeterie | F39: France | G39: 6 | H39: 2 | I39: =IF(J39="","",J39/G39) -> 0.33333333 | J39: 2 | K39: =IF(L39="","",L39/G39) -> 0.16666667 | L39: 1 | M39: =IF(N39="","",N39/L39) | S39: - | T39: - | U39: - | V39: - | W39: OK | AB39: =IF(G39<>"",$F39,"") -> France
A40: =IF(D40="Sous-total","S",IF(G40="","","X")) -> X | E40: ST-PIERRE_Franchissement Borne-Dessy | F40: France | G40: 20 | H40: 6 | I40: =IF(J40="","",J40/G40) -> 0.25 | J40: 5 | K40: =IF(L40="","",L40/G40) -> 0.2 | L40: 4 | M40: =IF(N40="","",N40/L40) | O40: 2 | S40: - | T40: - | U40: - | V40: - | W40: OK | AB40: =IF(G40<>"",$F40,"") -> France
...

Sheet 2023
E1: 7
A2: S | B2: Association(s) | C2: Arrière-pays | D2: Nombre de bénévoles | E2: Postes de comptage | F2: France / Suisse / Frontière | G2: Nombre de vélos | I2: % VAE dans le total | J2: NB VAE dans le total | K2: % femmes dans le total | L2: NB de femmes dans le total | M2: % de VAE chez les femmes | N2: NB de VAE chez les femmes | O2: Autres modes | Q2: Piétons | S2: > Suisse | U2: > France
A3: S
A4: S | G4: total | H4: HP | O4: total | P4: HP | Q4: total | R4: HP | S4: total | T4: HP | U4: total | V4: HP | AB4: 2020
A5: =IF(D5="Sous-total","S",IF(G5="","","X")) -> X | B5: UP Cluses | C5: OUI | D5: 2 | E5: CLUSES_Passerelle de Messy | F5: France | G5: 176 | I5: =IF(J5="","",J5/G5) -> 0.25568182 | J5: =16+29 -> 45 | K5: =IF(L5="","",L5/G5) -> 0.34090909 | L5: =22+16+22 -> 60 | M5: =IF(N5="","",N5/L5) -> 0.26666667 | N5: 16 | S5: - | T5: - | U5: - | V5: - | AB5: =IF(G5<>"",$F5,"") -> France
A6: =IF(D6="Sous-total","S",IF(G6="","","X")) | E6: COMMUNE_Carrefour | S6: - | T6: - | U6: - | V6: -
A7: =IF(D7="Sous-total","S",IF(G7="","","X")) | E7: COMMUNE_Carrefour | S7: - | T7: - | U7: - | V7: -
A8: =IF(D8="Sous-total","S",IF(G8="","","X")) -> S | D8: Sous-total | G8: =SUM(G5:G7) -> 176 | H8: =SUM(H5:H7) -> 0 | I8: =IF(J8="","",J8/G8) -> 0.25568182 | J8: =SUM(J5:J7) -> 45 | K8: =IF(L8="","",L8/G8) -> 0.34090909 | L8: =SUM(L5:L7) -> 60 | M8: =IF(N8="","",N8/L8) -> 0.26666667 | N8: =SUM(N5:N7) -> 16 | O8: =SUM(O5:O7) -> 0 | P8: =SUM(P5:P7) -> 0 | Q8: =SUM(Q5:Q7) -> 0 | R8: =SUM(R5:R7) -> 0 | S8: =SUM(S5:S7) -> 0 | T8: =SUM(T5:T7) -> 0 | U8: =SUM(U5:U7) -> 0 | V8: =SUM(V5:V7) -> 0
A9: =IF(D9="Sous-total","S",IF(G9="","","X")) | B9: L'Abeille (Contamine) | C9: OUI | E9: BONNE_Loëx (sous voie rapide) | F9: France | I9: =IF(J9="","",J9/G9) | K9: =IF(L9="","",L9/G9) | M9: =IF(N9="","",N9/L9) | S9: - | T9: - | U9: - | V9: - | W9: OK | AB9: =IF(G9<>"",$F9,"")
A10: =IF(D10="Sous-total","S",IF(G10="","","X")) | S10: - | T10: - | U10: - | V10: -
A11: =IF(D11="Sous-total","S",IF(G11="","","X")) | S11: - | T11: - | U11: - | V11: -
A12: =IF(D12="Sous-total","S",IF(G12="","","X")) -> S | D12: Sous-total | G12: =SUM(G9:G11) -> 0 | H12: =SUM(H9:H11) -> 0 | I12: =IF(J12="","",J12/G12) -> #DIV/0! | J12: =SUM(J9:J11) -> 0 | K12: =IF(L12="","",L12/G12) -> #DIV/0! | L12: =SUM(L9:L11) -> 0 | M12: =IF(N12="","",N12/L12) -> #DIV/0! | N12: =SUM(N9:N11) -> 0 | O12: =SUM(O9:O11) -> 0 | P12: =SUM(P9:P11) -> 0 | Q12: =SUM(Q9:Q11) -> 0 | R12: =SUM(R9:R11) -> 0 | S12: =SUM(S9:S11) -> 0 | T12: =SUM(T9:T11) -> 0 | U12: =SUM(U9:U11) -> 0 | V12: =SUM(V9:V11) -> 0 | W12: OK
A13: =IF(D13="Sous-total","S",IF(G13="","","X")) | B13: AMDC (Chablais) | C13: OUI | D13: 18 | E13: ALLINGES_Rond point des Fleysets | F13: France | I13: =IF(J13="","",J13/G13) | K13: =IF(L13="","",L13/G13) | M13: =IF(N13="","",N13/L13) | W13: OK | AB13: =IF(G13<>"",$F13,"")
A14: =IF(D14="Sous-total","S",IF(G14="","","X")) | E14: BONS_Gare | F14: France | I14: =IF(J14="","",J14/G14) | K14: =IF(L14="","",L14/G14) | M14: =IF(N14="","",N14/L14) | W14: OK | AB14: =IF(G14<>"",$F14,"")
A15: =IF(D15="Sous-total","S",IF(G15="","","X")) | E15: DOUVAINE_Mairie | F15: France | I15: =IF(J15="","",J15/G15) | K15: =IF(L15="","",L15/G15) | M15: =IF(N15="","",N15/L15) | W15: OK | AB15: =IF(G15<>"",$F15,"")
A16: =IF(D16="Sous-total","S",IF(G16="","","X")) | E16: EVIAN_Gare | F16: France | I16: =IF(J16="","",J16/G16) | K16: =IF(L16="","",L16/G16) | M16: =IF(N16="","",N16/L16) | W16: OK | AB16: =IF(G16<>"",$F16,"")
A17: =IF(D17="Sous-total","S",IF(G17="","","X")) | E17: PERRIGNIER_Gare | F17: France | I17: =IF(J17="","",J17/G17) | K17: =IF(L17="","",L17/G17) | M17: =IF(N17="","",N17/L17) | W17: OK | AB17: =IF(G17<>"",$F17,"")
A18: =IF(D18="Sous-total","S",IF(G18="","","X")) | E18: THONON_Embarcadère CGN | F18: Frontière | I18: =IF(J18="","",J18/G18) | K18: =IF(L18="","",L18/G18) | M18: =IF(N18="","",N18/L18) | W18: OK | AB18: =IF(G18<>"",$F18,"")
A19: =IF(D19="Sous-total","S",IF(G19="","","X")) | E19: THONON_Entrée côté place de Crête | F19: France | I19: =IF(J19="","",J19/G19) | K19: =IF(L19="","",L19/G19) | M19: =IF(N19="","",N19/L19) | W19: OK | AB19: =IF(G19<>"",$F19,"")
A20: =IF(D20="Sous-total","S",IF(G20="","","X")) | E20: THONON_Parvis de la gare | F20: France | I20: =IF(J20="","",J20/G20) | K20: =IF(L20="","",L20/G20) | M20: =IF(N20="","",N20/L20) | W20: OK | AB20: =IF(G20<>"",$F20,"")
A21: =IF(D21="Sous-total","S",IF(G21="","","X")) | E21: THONON_Avenue d’Evian | F21: France | I21: =IF(J21="","",J21/G21) | K21: =IF(L21="","",L21/G21) | M21: =IF(N21="","",N21/L21) | W21: OK | AB21: =IF(G21<>"",$F21,"")
A22: =IF(D22="Sous-total","S",IF(G22="","","X")) | E22: THONON_Carrefour Libération | F22: France | I22: =IF(J22="","",J22/G22) | K22: =IF(L22="","",L22/G22) | M22: =IF(N22="","",N22/L22) | W22: OK | AB22: =IF(G22<>"",$F22,"")
A23: =IF(D23="Sous-total","S",IF(G23="","","X")) | E23: THONON_Collège Champagne | F23: France | I23: =IF(J23="","",J23/G23) | K23: =IF(L23="","",L23/G23) | M23: =IF(N23="","",N23/L23) | W23: OK | AB23: =IF(G23<>"",$F23,"")
A24: =IF(D24="Sous-total","S",IF(G24="","","X")) | E24: THONON_Ecole Jule Ferry | F24: France | I24: =IF(J24="","",J24/G24) | K24: =IF(L24="","",L24/G24) | M24: =IF(N24="","",N24/L24) | W24: OK | AB24: =IF(G24<>"",$F24,"")
A25: =IF(D25="Sous-total","S",IF(G25="","","X")) | E25: THONON_Rond point J. Ferry G Andrier Pl des Arts Bld du Canal | F25: France | I25: =IF(J25="","",J25/G25) | K25: =IF(L25="","",L25/G25) | M25: =IF(N25="","",N25/L25) | W25: OK | AB25: =IF(G25<>"",$F25,"")
... A28: =IF(D28="Sous-total","S",IF(G28="","","X")) | E28: VEIGY_Douane | F28: Frontière | I28: =IF(J28="","",J28/G28) | K28: =IF(L28="","",L28/G28) | M28: =IF(N28="","",N28/L28) | W28: OK | AB28: =IF(G28<>"",$F28,"")
A29: =IF(D29="Sous-total","S",IF(G29="","","X")) | E29: COMMUNE_Carrefour
A30: =IF(D30="Sous-total","S",IF(G30="","","X")) | E30: COMMUNE_Carrefour
A31: =IF(D31="Sous-total","S",IF(G31="","","X")) | E31: COMMUNE_Carrefour
A32: =IF(D32="Sous-total","S",IF(G32="","","X")) | E32: COMMUNE_Carrefour
A33: =IF(D33="Sous-total","S",IF(G33="","","X")) | E33: COMMUNE_Carrefour
A34: =IF(D34="Sous-total","S",IF(G34="","","X")) -> S | D34: Sous-total | G34: =SUM(G13:G33) -> 0 | H34: =SUM(H13:H33) -> 0 | I34: =IF(J34="","",J34/G34) -> #DIV/0! | J34: =SUM(J13:J33) -> 0 | K34: =IF(L34="","",L34/G34) -> #DIV/0! | L34: =SUM(L13:L33) -> 0 | M34: =IF(N34="","",N34/L34) -> #DIV/0! | N34: =SUM(N13:N33) -> 0 | O34: =SUM(O13:O33) -> 0 | P34: =SUM(P13:P33) -> 0 | Q34: =SUM(Q13:Q33) -> 0 | R34: =SUM(R13:R33) -> 0 | S34: =SUM(S13:S33) -> 0 | T34: =SUM(T13:T33) -> 0 | U34: =SUM(U13:U33) -> 0 | V34: =SUM(V13:V33) -> 0 | W34: OK | AB34: =IF(G34<>"",$F34,"") -> 0
A35: =IF(D35="Sous-total","S",IF(G35="","","X")) | B35: NatEnv (Nature Environnement en Pays rochois) Fabrique à Biclou Pays rochois en Transition | C35: OUI | D35: 11 | E35: LA ROCHE_Carrefour Biocoop | F35: France | I35: =IF(J35="","",J35/G35) | K35: =IF(L35="","",L35/G35) | M35: =IF(N35="","",N35/L35) | S35: - | T35: - | U35: - | V35: - | W35: OK | AB35: =IF(G35<>"",$F35,"")
A36: =IF(D36="Sous-total","S",IF(G36="","","X")) | E36: LA ROCHE_Giratoire La Poste | F36: France | I36: =IF(J36="","",J36/G36) | K36: =IF(L36="","",L36/G36) | M36: =IF(N36="","",N36/L36) | S36: - | T36: - | U36: - | V36: - | W36: OK | AB36: =IF(G36<>"",$F36,"")
A37: =IF(D37="Sous-total","S",IF(G37="","","X")) | E37: LA ROCHE_Giratoire ENILV | F37: France | I37: =IF(J37="","",J37/G37) | K37: =IF(L37="","",L37/G37) | M37: =IF(N37="","",N37/L37) | S37: - | T37: - | U37: - | V37: - | W37: OK | AB37: =IF(G37<>"",$F37,"")
A38: =IF(D38="Sous-total","S",IF(G38="","","X")) | E38: LA ROCHE_Gare Passage à niveau (new 2021) | F38: France | I38: =IF(J38="","",J38/G38) | K38: =IF(L38="","",L38/G38) | M38: =IF(N38="","",N38/L38) | S38: - | T38: - | U38: - | V38: - | W38: OK | AB38: =IF(G38<>"",$F38,"")
A39: =IF(D39="Sous-total","S",IF(G39="","","X")) | E39: ARENTHON_La Papeterie | F39: France | I39: =IF(J39="","",J39/G39) | K39: =IF(L39="","",L39/G39) | M39: =IF(N39="","",N39/L39) | S39: - | T39: - | U39: - | V39: - | W39: OK | AB39: =IF(G39<>"",$F39,"")
A40: =IF(D40="Sous-total","S",IF(G40="","","X")) | E40: ST-PIERRE_Franchissement Borne-Dessy | F40: France | I40: =IF(J40="","",J40/G40) | K40: =IF(L40="","",L40/G40) | M40: =IF(N40="","",N40/L40) | S40: - | T40: - | U40: - | V40: - | W40: OK | AB40: =IF(G40<>"",$F40,"")
A41: =IF(D41="Sous-total","S",IF(G41="","","X")) | E41: BONNEVILLE_Franchissement Borne-Tucinge | F41: France | I41: =IF(J41="","",J41/G41) | K41: =IF(L41="","",L41/G41) | M41: =IF(N41="","",N41/L41) | S41: - | T41: - | U41: - | V41: - | W41: OK | AB41: =IF(G41<>"",$F41,"")
A42: =IF(D42="Sous-total","S",IF(G42="","","X")) | E42: ST-PIERRE_Pont principal sur le Borne | F42: France | I42: =IF(J42="","",J42/G42) | K42: =IF(L42="","",L42/G42) | M42: =IF(N42="","",N42/L42) | S42: - | T42: - | U42: - | V42: - | W42: OK | AB42: =IF(G42<>"",$F42,"")
...

Sheet 2024
E1: 7
A2: S | B2: Association(s) | C2: Arrière-pays | D2: Nombre de bénévoles | E2: Postes de comptage | F2: France / Suisse / Frontière | G2: Nombre de vélos | I2: % VAE dans le total | J2: NB VAE dans le total | K2: % femmes dans le total | L2: NB de femmes dans le total | M2: % de VAE chez les femmes | N2: NB de VAE chez les femmes | O2: Autres modes | Q2: Piétons | S2: > Suisse | U2: > France
A3: S
A4: S | G4: total | H4: HP | O4: total | P4: HP | Q4: total | R4: HP | S4: total | T4: HP | U4: total | V4: HP | AB4: 2020
A5: =IF(D5="Sous-total","S",IF(G5="","","X")) | B5: UP Cluses | C5: OUI | D5: 2 | E5: CLUSES_Passerelle de Messy | F5: France | I5: =IF(J5="","",J5/G5) | K5: =IF(L5="","",L5/G5) | M5: =IF(N5="","",N5/L5) | S5: - | T5: - | U5: - | V5: - | AB5: =IF(G5<>"",$F5,"")
A6: =IF(D6="Sous-total","S",IF(G6="","","X")) | E6: COMMUNE_Carrefour | S6: - | T6: - | U6: - | V6: -
A7: =IF(D7="Sous-total","S",IF(G7="","","X")) | E7: COMMUNE_Carrefour | S7: - | T7: - | U7: - | V7: -
A8: =IF(D8="Sous-total","S",IF(G8="","","X")) -> S | D8: Sous-total | G8: =SUM(G5:G7) -> 0 | H8: =SUM(H5:H7) -> 0 | I8: =IF(J8="","",J8/G8) -> #DIV/0! | J8: =SUM(J5:J7) -> 0 | K8: =IF(L8="","",L8/G8) -> #DIV/0! | L8: =SUM(L5:L7) -> 0 | M8: =IF(N8="","",N8/L8) -> #DIV/0! | N8: =SUM(N5:N7) -> 0 | O8: =SUM(O5:O7) -> 0 | P8: =SUM(P5:P7) -> 0 | Q8: =SUM(Q5:Q7) -> 0 | R8: =SUM(R5:R7) -> 0 | S8: =SUM(S5:S7) -> 0 | T8: =SUM(T5:T7) -> 0 | U8: =SUM(U5:U7) -> 0 | V8: =SUM(V5:V7) -> 0
A9: =IF(D9="Sous-total","S",IF(G9="","","X")) | B9: L'Abeille (Contamine) | C9: OUI | E9: BONNE_Loëx (sous voie rapide) | F9: France | I9: =IF(J9="","",J9/G9) | K9: =IF(L9="","",L9/G9) | M9: =IF(N9="","",N9/L9) | S9: - | T9: - | U9: - | V9: - | W9: OK | AB9: =IF(G9<>"",$F9,"")
A10: =IF(D10="Sous-total","S",IF(G10="","","X")) | S10: - | T10: - | U10: - | V10: -
A11: =IF(D11="Sous-total","S",IF(G11="","","X")) | S11: - | T11: - | U11: - | V11: -
A12: =IF(D12="Sous-total","S",IF(G12="","","X")) -> S | D12: Sous-total | G12: =SUM(G9:G11) -> 0 | H12: =SUM(H9:H11) -> 0 | I12: =IF(J12="","",J12/G12) -> #DIV/0! | J12: =SUM(J9:J11) -> 0 | K12: =IF(L12="","",L12/G12) -> #DIV/0! | L12: =SUM(L9:L11) -> 0 | M12: =IF(N12="","",N12/L12) -> #DIV/0! | N12: =SUM(N9:N11) -> 0 | O12: =SUM(O9:O11) -> 0 | P12: =SUM(P9:P11) -> 0 | Q12: =SUM(Q9:Q11) -> 0 | R12: =SUM(R9:R11) -> 0 | S12: =SUM(S9:S11) -> 0 | T12: =SUM(T9:T11) -> 0 | U12: =SUM(U9:U11) -> 0 | V12: =SUM(V9:V11) -> 0 | W12: OK
A13: =IF(D13="Sous-total","S",IF(G13="","","X")) | B13: AMDC (Chablais) | C13: OUI | D13: 18 | E13: ALLINGES_Rond point des Fleysets | F13: France | I13: =IF(J13="","",J13/G13) | K13: =IF(L13="","",L13/G13) | M13: =IF(N13="","",N13/L13) | W13: OK | AB13: =IF(G13<>"",$F13,"")
A14: =IF(D14="Sous-total","S",IF(G14="","","X")) | E14: BONS_Gare | F14: France | I14: =IF(J14="","",J14/G14) | K14: =IF(L14="","",L14/G14) | M14: =IF(N14="","",N14/L14) | W14: OK | AB14: =IF(G14<>"",$F14,"")
A15: =IF(D15="Sous-total","S",IF(G15="","","X")) | E15: DOUVAINE_Mairie | F15: France | I15: =IF(J15="","",J15/G15) | K15: =IF(L15="","",L15/G15) | M15: =IF(N15="","",N15/L15) | W15: OK | AB15: =IF(G15<>"",$F15,"")
A16: =IF(D16="Sous-total","S",IF(G16="","","X")) | E16: EVIAN_Gare | F16: France | I16: =IF(J16="","",J16/G16) | K16: =IF(L16="","",L16/G16) | M16: =IF(N16="","",N16/L16) | W16: OK | AB16: =IF(G16<>"",$F16,"")
A17: =IF(D17="Sous-total","S",IF(G17="","","X")) | E17: PERRIGNIER_Gare | F17: France | I17: =IF(J17="","",J17/G17) | K17: =IF(L17="","",L17/G17) | M17: =IF(N17="","",N17/L17) | W17: OK | AB17: =IF(G17<>"",$F17,"")
A18: =IF(D18="Sous-total","S",IF(G18="","","X")) | E18: THONON_Embarcadère CGN | F18: Frontière | I18: =IF(J18="","",J18/G18) | K18: =IF(L18="","",L18/G18) | M18: =IF(N18="","",N18/L18) | W18: OK | AB18: =IF(G18<>"",$F18,"")
A19: =IF(D19="Sous-total","S",IF(G19="","","X")) | E19: THONON_Entrée côté place de Crête | F19: France | I19: =IF(J19="","",J19/G19) | K19: =IF(L19="","",L19/G19) | M19: =IF(N19="","",N19/L19) | W19: OK | AB19: =IF(G19<>"",$F19,"")
A20: =IF(D20="Sous-total","S",IF(G20="","","X")) | E20: THONON_Parvis de la gare | F20: France | I20: =IF(J20="","",J20/G20) | K20: =IF(L20="","",L20/G20) | M20: =IF(N20="","",N20/L20) | W20: OK | AB20: =IF(G20<>"",$F20,"")
A21: =IF(D21="Sous-total","S",IF(G21="","","X")) | E21: THONON_Avenue d’Evian | F21: France | I21: =IF(J21="","",J21/G21) | K21: =IF(L21="","",L21/G21) | M21: =IF(N21="","",N21/L21) | W21: OK | AB21: =IF(G21<>"",$F21,"")
A22: =IF(D22="Sous-total","S",IF(G22="","","X")) | E22: THONON_Carrefour Libération | F22: France | I22: =IF(J22="","",J22/G22) | K22: =IF(L22="","",L22/G22) | M22: =IF(N22="","",N22/L22) | W22: OK | AB22: =IF(G22<>"",$F22,"")
A23: =IF(D23="Sous-total","S",IF(G23="","","X")) | E23: THONON_Collège Champagne | F23: France | I23: =IF(J23="","",J23/G23) | K23: =IF(L23="","",L23/G23) | M23: =IF(N23="","",N23/L23) | W23: OK | AB23: =IF(G23<>"",$F23,"")
A24: =IF(D24="Sous-total","S",IF(G24="","","X")) | E24: THONON_Ecole Jule Ferry | F24: France | I24: =IF(J24="","",J24/G24) | K24: =IF(L24="","",L24/G24) | M24: =IF(N24="","",N24/L24) | W24: OK | AB24: =IF(G24<>"",$F24,"")
A25: =IF(D25="Sous-total","S",IF(G25="","","X")) | E25: THONON_Rond point J. Ferry G Andrier Pl des Arts Bld du Canal | F25: France | I25: =IF(J25="","",J25/G25) | K25: =IF(L25="","",L25/G25) | M25: =IF(N25="","",N25/L25) | W25: OK | AB25: =IF(G25<>"",$F25,"")
... A28: =IF(D28="Sous-total","S",IF(G28="","","X")) | E28: VEIGY_Douane | F28: Frontière | I28: =IF(J28="","",J28/G28) | K28: =IF(L28="","",L28/G28) | M28: =IF(N28="","",N28/L28) | W28: OK | AB28: =IF(G28<>"",$F28,"")
A29: =IF(D29="Sous-total","S",IF(G29="","","X")) | E29: COMMUNE_Carrefour
A30: =IF(D30="Sous-total","S",IF(G30="","","X")) | E30: COMMUNE_Carrefour
A31: =IF(D31="Sous-total","S",IF(G31="","","X")) | E31: COMMUNE_Carrefour
A32: =IF(D32="Sous-total","S",IF(G32="","","X")) | E32: COMMUNE_Carrefour
A33: =IF(D33="Sous-total","S",IF(G33="","","X")) | E33: COMMUNE_Carrefour
A34: =IF(D34="Sous-total","S",IF(G34="","","X")) -> S | D34: Sous-total | G34: =SUM(G13:G33) -> 0 | H34: =SUM(H13:H33) -> 0 | I34: =IF(J34="","",J34/G34) -> #DIV/0! | J34: =SUM(J13:J33) -> 0 | K34: =IF(L34="","",L34/G34) -> #DIV/0! | L34: =SUM(L13:L33) -> 0 | M34: =IF(N34="","",N34/L34) -> #DIV/0! | N34: =SUM(N13:N33) -> 0 | O34: =SUM(O13:O33) -> 0 | P34: =SUM(P13:P33) -> 0 | Q34: =SUM(Q13:Q33) -> 0 | R34: =SUM(R13:R33) -> 0 | S34: =SUM(S13:S33) -> 0 | T34: =SUM(T13:T33) -> 0 | U34: =SUM(U13:U33) -> 0 | V34: =SUM(V13:V33) -> 0 | W34: OK | AB34: =IF(G34<>"",$F34,"") -> 0
A35: =IF(D35="Sous-total","S",IF(G35="","","X")) | B35: NatEnv (Nature Environnement en Pays rochois) Fabrique à Biclou Pays rochois en Transition | C35: OUI | D35: 11 | E35: LA ROCHE_Carrefour Biocoop | F35: France | I35: =IF(J35="","",J35/G35) | K35: =IF(L35="","",L35/G35) | M35: =IF(N35="","",N35/L35) | S35: - | T35: - | U35: - | V35: - | W35: OK | AB35: =IF(G35<>"",$F35,"")
A36: =IF(D36="Sous-total","S",IF(G36="","","X")) | E36: LA ROCHE_Giratoire La Poste | F36: France | I36: =IF(J36="","",J36/G36) | K36: =IF(L36="","",L36/G36) | M36: =IF(N36="","",N36/L36) | S36: - | T36: - | U36: - | V36: - | W36: OK | AB36: =IF(G36<>"",$F36,"")
A37: =IF(D37="Sous-total","S",IF(G37="","","X")) | E37: LA ROCHE_Giratoire ENILV | F37: France | I37: =IF(J37="","",J37/G37) | K37: =IF(L37="","",L37/G37) | M37: =IF(N37="","",N37/L37) | S37: - | T37: - | U37: - | V37: - | W37: OK | AB37: =IF(G37<>"",$F37,"")
A38: =IF(D38="Sous-total","S",IF(G38="","","X")) | E38: LA ROCHE_Gare Passage à niveau (new 2021) | F38: France | I38: =IF(J38="","",J38/G38) | K38: =IF(L38="","",L38/G38) | M38: =IF(N38="","",N38/L38) | S38: - | T38: - | U38: - | V38: - | W38: OK | AB38: =IF(G38<>"",$F38,"")
A39: =IF(D39="Sous-total","S",IF(G39="","","X")) | E39: ARENTHON_La Papeterie | F39: France | I39: =IF(J39="","",J39/G39) | K39: =IF(L39="","",L39/G39) | M39: =IF(N39="","",N39/L39) | S39: - | T39: - | U39: - | V39: - | W39: OK | AB39: =IF(G39<>"",$F39,"")
A40: =IF(D40="Sous-total","S",IF(G40="","","X")) | E40: ST-PIERRE_Franchissement Borne-Dessy | F40: France | I40: =IF(J40="","",J40/G40) | K40: =IF(L40="","",L40/G40) | M40: =IF(N40="","",N40/L40) | S40: - | T40: - | U40: - | V40: - | W40: OK | AB40: =IF(G40<>"",$F40,"")
A41: =IF(D41="Sous-total","S",IF(G41="","","X")) | E41: BONNEVILLE_Franchissement Borne-Tucinge | F41: France | I41: =IF(J41="","",J41/G41) | K41: =IF(L41="","",L41/G41) | M41: =IF(N41="","",N41/L41) | S41: - | T41: - | U41: - | V41: - | W41: OK | AB41: =IF(G41<>"",$F41,"")
A42: =IF(D42="Sous-total","S",IF(G42="","","X")) | E42: ST-PIERRE_Pont principal sur le Borne | F42: France | I42: =IF(J42="","",J42/G42) | K42: =IF(L42="","",L42/G42) | M42: =IF(N42="","",N42/L42) | S42: - | T42: - | U42: - | V42: - | W42: OK | AB42: =IF(G42<>"",$F42,"")
...

Sheet 2025
E1: 7
A2: S | B2: Association(s) | C2: Arrière-pays | D2: Nombre de bénévoles | E2: Postes de comptage | F2: France / Suisse / Frontière | G2: Nombre de vélos | I2: % VAE dans le total | J2: NB VAE dans le total | K2: % femmes dans le total | L2: NB de femmes dans le total | M2: % de VAE chez les femmes | N2: NB de VAE chez les femmes | O2: Autres modes | Q2: Piétons | S2: > Suisse | U2: > France
A3: S
A4: S | G4: total | H4: HP | O4: total | P4: HP | Q4: total | R4: HP | S4: total | T4: HP | U4: total | V4: HP | AB4: 2020
A5: =IF(D5="Sous-total","S",IF(G5="","","X")) | B5: UP Cluses | C5: OUI | D5: 2 | E5: CLUSES_Passerelle de Messy | F5: France | I5: =IF(J5="","",J5/G5) | K5: =IF(L5="","",L5/G5) | M5: =IF(N5="","",N5/L5) | S5: - | T5: - | U5: - | V5: - | AB5: =IF(G5<>"",$F5,"")
A6: =IF(D6="Sous-total","S",IF(G6="","","X")) | E6: COMMUNE_Carrefour | S6: - | T6: - | U6: - | V6: -
A7: =IF(D7="Sous-total","S",IF(G7="","","X")) | E7: COMMUNE_Carrefour | S7: - | T7: - | U7: - | V7: -
A8: =IF(D8="Sous-total","S",IF(G8="","","X")) -> S | D8: Sous-total | G8: =SUM(G5:G7) -> 0 | H8: =SUM(H5:H7) -> 0 | I8: =IF(J8="","",J8/G8) -> #DIV/0! | J8: =SUM(J5:J7) -> 0 | K8: =IF(L8="","",L8/G8) -> #DIV/0! | L8: =SUM(L5:L7) -> 0 | M8: =IF(N8="","",N8/L8) -> #DIV/0! | N8: =SUM(N5:N7) -> 0 | O8: =SUM(O5:O7) -> 0 | P8: =SUM(P5:P7) -> 0 | Q8: =SUM(Q5:Q7) -> 0 | R8: =SUM(R5:R7) -> 0 | S8: =SUM(S5:S7) -> 0 | T8: =SUM(T5:T7) -> 0 | U8: =SUM(U5:U7) -> 0 | V8: =SUM(V5:V7) -> 0
A9: =IF(D9="Sous-total","S",IF(G9="","","X")) | B9: L'Abeille (Contamine) | C9: OUI | E9: BONNE_Loëx (sous voie rapide) | F9: France | I9: =IF(J9="","",J9/G9) | K9: =IF(L9="","",L9/G9) | M9: =IF(N9="","",N9/L9) | S9: - | T9: - | U9: - | V9: - | W9: OK | AB9: =IF(G9<>"",$F9,"")
A10: =IF(D10="Sous-total","S",IF(G10="","","X")) | S10: - | T10: - | U10: - | V10: -
A11: =IF(D11="Sous-total","S",IF(G11="","","X")) | S11: - | T11: - | U11: - | V11: -
A12: =IF(D12="Sous-total","S",IF(G12="","","X")) -> S | D12: Sous-total | G12: =SUM(G9:G11) -> 0 | H12: =SUM(H9:H11) -> 0 | I12: =IF(J12="","",J12/G12) -> #DIV/0! | J12: =SUM(J9:J11) -> 0 | K12: =IF(L12="","",L12/G12) -> #DIV/0! | L12: =SUM(L9:L11) -> 0 | M12: =IF(N12="","",N12/L12) -> #DIV/0! | N12: =SUM(N9:N11) -> 0 | O12: =SUM(O9:O11) -> 0 | P12: =SUM(P9:P11) -> 0 | Q12: =SUM(Q9:Q11) -> 0 | R12: =SUM(R9:R11) -> 0 | S12: =SUM(S9:S11) -> 0 | T12: =SUM(T9:T11) -> 0 | U12: =SUM(U9:U11) -> 0 | V12: =SUM(V9:V11) -> 0 | W12: OK
A13: =IF(D13="Sous-total","S",IF(G13="","","X")) | B13: AMDC (Chablais) | C13: OUI | D13: 18 | E13: ALLINGES_Rond point des Fleysets | F13: France | I13: =IF(J13="","",J13/G13) | K13: =IF(L13="","",L13/G13) | M13: =IF(N13="","",N13/L13) | W13: OK | AB13: =IF(G13<>"",$F13,"")
A14: =IF(D14="Sous-total","S",IF(G14="","","X")) | E14: BONS_Gare | F14: France | I14: =IF(J14="","",J14/G14) | K14: =IF(L14="","",L14/G14) | M14: =IF(N14="","",N14/L14) | W14: OK | AB14: =IF(G14<>"",$F14,"")
A15: =IF(D15="Sous-total","S",IF(G15="","","X")) | E15: DOUVAINE_Mairie | F15: France | I15: =IF(J15="","",J15/G15) | K15: =IF(L15="","",L15/G15) | M15: =IF(N15="","",N15/L15) | W15: OK | AB15: =IF(G15<>"",$F15,"")
A16: =IF(D16="Sous-total","S",IF(G16="","","X")) | E16: EVIAN_Gare | F16: France | I16: =IF(J16="","",J16/G16) | K16: =IF(L16="","",L16/G16) | M16: =IF(N16="","",N16/L16) | W16: OK | AB16: =IF(G16<>"",$F16,"")
A17: =IF(D17="Sous-total","S",IF(G17="","","X")) | E17: PERRIGNIER_Gare | F17: France | I17: =IF(J17="","",J17/G17) | K17: =IF(L17="","",L17/G17) | M17: =IF(N17="","",N17/L17) | W17: OK | AB17: =IF(G17<>"",$F17,"")
A18: =IF(D18="Sous-total","S",IF(G18="","","X")) | E18: THONON_Embarcadère CGN | F18: Frontière | I18: =IF(J18="","",J18/G18) | K18: =IF(L18="","",L18/G18) | M18: =IF(N18="","",N18/L18) | W18: OK | AB18: =IF(G18<>"",$F18,"")
A19: =IF(D19="Sous-total","S",IF(G19="","","X")) | E19: THONON_Entrée côté place de Crête | F19: France | I19: =IF(J19="","",J19/G19) | K19: =IF(L19="","",L19/G19) | M19: =IF(N19="","",N19/L19) | W19: OK | AB19: =IF(G19<>"",$F19,"")
A20: =IF(D20="Sous-total","S",IF(G20="","","X")) | E20: THONON_Parvis de la gare | F20: France | I20: =IF(J20="","",J20/G20) | K20: =IF(L20="","",L20/G20) | M20: =IF(N20="","",N20/L20) | W20: OK | AB20: =IF(G20<>"",$F20,"")
A21: =IF(D21="Sous-total","S",IF(G21="","","X")) | E21: THONON_Avenue d’Evian | F21: France | I21: =IF(J21="","",J21/G21) | K21: =IF(L21="","",L21/G21) | M21: =IF(N21="","",N21/L21) | W21: OK | AB21: =IF(G21<>"",$F21,"")
A22: =IF(D22="Sous-total","S",IF(G22="","","X")) | E22: THONON_Carrefour Libération | F22: France | I22: =IF(J22="","",J22/G22) | K22: =IF(L22="","",L22/G22) | M22: =IF(N22="","",N22/L22) | W22: OK | AB22: =IF(G22<>"",$F22,"")
A23: =IF(D23="Sous-total","S",IF(G23="","","X")) | E23: THONON_Collège Champagne | F23: France | I23: =IF(J23="","",J23/G23) | K23: =IF(L23="","",L23/G23) | M23: =IF(N23="","",N23/L23) | W23: OK | AB23: =IF(G23<>"",$F23,"")
A24: =IF(D24="Sous-total","S",IF(G24="","","X")) | E24: THONON_Ecole Jule Ferry | F24: France | I24: =IF(J24="","",J24/G24) | K24: =IF(L24="","",L24/G24) | M24: =IF(N24="","",N24/L24) | W24: OK | AB24: =IF(G24<>"",$F24,"")
A25: =IF(D25="Sous-total","S",IF(G25="","","X")) | E25: THONON_Rond point J. Ferry G Andrier Pl des Arts Bld du Canal | F25: France | I25: =IF(J25="","",J25/G25) | K25: =IF(L25="","",L25/G25) | M25: =IF(N25="","",N25/L25) | W25: OK | AB25: =IF(G25<>"",$F25,"")
... A28: =IF(D28="Sous-total","S",IF(G28="","","X")) | E28: VEIGY_Douane | F28: Frontière | I28: =IF(J28="","",J28/G28) | K28: =IF(L28="","",L28/G28) | M28: =IF(N28="","",N28/L28) | W28: OK | AB28: =IF(G28<>"",$F28,"")
A29: =IF(D29="Sous-total","S",IF(G29="","","X")) | E29: COMMUNE_Carrefour
A30: =IF(D30="Sous-total","S",IF(G30="","","X")) | E30: COMMUNE_Carrefour
A31: =IF(D31="Sous-total","S",IF(G31="","","X")) | E31: COMMUNE_Carrefour
A32: =IF(D32="Sous-total","S",IF(G32="","","X")) | E32: COMMUNE_Carrefour
A33: =IF(D33="Sous-total","S",IF(G33="","","X")) | E33: COMMUNE_Carrefour
A34: =IF(D34="Sous-total","S",IF(G34="","","X")) -> S | D34: Sous-total | G34: =SUM(G13:G33) -> 0 | H34: =SUM(H13:H33) -> 0 | I34: =IF(J34="","",J34/G34) -> #DIV/0! | J34: =SUM(J13:J33) -> 0 | K34: =IF(L34="","",L34/G34) -> #DIV/0! | L34: =SUM(L13:L33) -> 0 | M34: =IF(N34="","",N34/L34) -> #DIV/0! | N34: =SUM(N13:N33) -> 0 | O34: =SUM(O13:O33) -> 0 | P34: =SUM(P13:P33) -> 0 | Q34: =SUM(Q13:Q33) -> 0 | R34: =SUM(R13:R33) -> 0 | S34: =SUM(S13:S33) -> 0 | T34: =SUM(T13:T33) -> 0 | U34: =SUM(U13:U33) -> 0 | V34: =SUM(V13:V33) -> 0 | W34: OK | AB34: =IF(G34<>"",$F34,"") -> 0
A35: =IF(D35="Sous-total","S",IF(G35="","","X")) | B35: NatEnv (Nature Environnement en Pays rochois) Fabrique à Biclou Pays rochois en Transition | C35: OUI | D35: 11 | E35: LA ROCHE_Carrefour Biocoop | F35: France | I35: =IF(J35="","",J35/G35) | K35: =IF(L35="","",L35/G35) | M35: =IF(N35="","",N35/L35) | S35: - | T35: - | U35: - | V35: - | W35: OK | AB35: =IF(G35<>"",$F35,"")
A36: =IF(D36="Sous-total","S",IF(G36="","","X")) | E36: LA ROCHE_Giratoire La Poste | F36: France | I36: =IF(J36="","",J36/G36) | K36: =IF(L36="","",L36/G36) | M36: =IF(N36="","",N36/L36) | S36: - | T36: - | U36: - | V36: - | W36: OK | AB36: =IF(G36<>"",$F36,"")
A37: =IF(D37="Sous-total","S",IF(G37="","","X")) | E37: LA ROCHE_Giratoire ENILV | F37: France | I37: =IF(J37="","",J37/G37) | K37: =IF(L37="","",L37/G37) | M37: =IF(N37="","",N37/L37) | S37: - | T37: - | U37: - | V37: - | W37: OK | AB37: =IF(G37<>"",$F37,"")
A38: =IF(D38="Sous-total","S",IF(G38="","","X")) | E38: LA ROCHE_Gare Passage à niveau (new 2021) | F38: France | I38: =IF(J38="","",J38/G38) | K38: =IF(L38="","",L38/G38) | M38: =IF(N38="","",N38/L38) | S38: - | T38: - | U38: - | V38: - | W38: OK | AB38: =IF(G38<>"",$F38,"")
A39: =IF(D39="Sous-total","S",IF(G39="","","X")) | E39: ARENTHON_La Papeterie | F39: France | I39: =IF(J39="","",J39/G39) | K39: =IF(L39="","",L39/G39) | M39: =IF(N39="","",N39/L39) | S39: - | T39: - | U39: - | V39: - | W39: OK | AB39: =IF(G39<>"",$F39,"")
A40: =IF(D40="Sous-total","S",IF(G40="","","X")) | E40: ST-PIERRE_Franchissement Borne-Dessy | F40: France | I40: =IF(J40="","",J40/G40) | K40: =IF(L40="","",L40/G40) | M40: =IF(N40="","",N40/L40) | S40: - | T40: - | U40: - | V40: - | W40: OK | AB40: =IF(G40<>"",$F40,"")
A41: =IF(D41="Sous-total","S",IF(G41="","","X")) | E41: BONNEVILLE_Franchissement Borne-Tucinge | F41: France | I41: =IF(J41="","",J41/G41) | K41: =IF(L41="","",L41/G41) | M41: =IF(N41="","",N41/L41) | S41: - | T41: - | U41: - | V41: - | W41: OK | AB41: =IF(G41<>"",$F41,"")
A42: =IF(D42="Sous-total","S",IF(G42="","","X")) | E42: ST-PIERRE_Pont principal sur le Borne | F42: France | I42: =IF(J42="","",J42/G42) | K42: =IF(L42="","",L42/G42) | M42: =IF(N42="","",N42/L42) | S42: - | T42: - | U42: - | V42: - | W42: OK | AB42: =IF(G42<>"",$F42,"")
...

Sheet SYNTHESE
B1: 2 | C1: 3 | D1: 4 | E1: 5 | F1: 6 | J1: 7 | K1: 8 | L1: 9 | M1: 10 | Q1: 11 | R1: 12 | S1: 13 | T1: 14 | X1: 15 | Y1: 16 | Z1: 17 | AD1: 18 | AE1: 19 | AF1: 20 | AJ1: 21 | AK1: 22 | AL1: 23 | AP1: 24 | AQ1: 25 | AR1: 26 | AV1: 27 | AW1: 28 | AX1: 29 | BB1: 30 | BC1: 31 | BD1: 32 | BH1: 33 | BI1: 34 | BJ1: 35 | BN1: 36 | BO1: 37 | BP1: 38 | BQ1: 39 | BR1: 40 | BS1: 41 | BT1: 42 | BU1: 43
B2: Association(s) | C2: Arrière-pays | D2: NB de bénévoles | J2: Postes de comptage | Q2: France / Suisse / Frontière | R2: Nombre de vélos | AD2: VAE dans le total | AP2: Femmes dans le total | BB2: VAE chez les femmes | BN2: Autres modes | BP2: Piétons | BR2: > Suisse | BT2: > France
R3: Total | X3: HP | AD3: [en %] | AJ3: [en valeur] | AP3: [en %] | AV3: [en valeur] | BB3: [en %] | BH3: [en valeur]
