Workbook

Sheet XXXI DECEMBRE
B1: MATIN | J1: SOIR
B3: RUE DU XXXI DECEMBRE | J3: RUE DU XXXI DECEMBRE
C4: Vers LAC | G4: Total | H4: Pourcentage | K4: Vers LAC | O4: Total | P4: Pourcentage
C5: 7h30-7h45 | D5: 7h45-8h00 | E5: 8h00-8h15 | F5: 8h15-8h30 | K5: 17h00-17h15 | L5: 17h15-17h30 | M5: 17h30-17h45 | N5: 17h45-18h00
B6: Vélo | C6: 3 | D6: 12 | E6: 6 | F6: 4 | G6: =SUM(C6:F6) -> 25 | H6: =G6/$G$17 -> 0.5952381 | J6: Vélo | K6: 2 | L6: 6 | M6: 13 | N6: 2 | O6: =SUM(K6:N6) -> 23 | P6: =O6/$O$17 -> 0.62162162
B7: VAE | C7: 1 | D7: 5 | E7: 6 | F7: 5 | G7: =SUM(C7:F7) -> 17 | H7: =G7/$G$17 -> 0.4047619 | J7: VAE | K7: 3 | L7: 5 | M7: 3 | N7: 3 | O7: =SUM(K7:N7) -> 14 | P7: =O7/$O$17 -> 0.37837838
B9: Conformistes | C9: 34 | G9: =SUM(C9:F9) -> 34 | H9: =G9/$G$17 -> 0.80952381 | J9: Conformistes | K9: 4 | L9: 7 | M9: 14 | N9: 4 | O9: =SUM(K9:N9) -> 29 | P9: =O9/$O$17 -> 0.78378378
B10: Opportunistes | C10: 7 | G10: =SUM(C10:F10) -> 7 | H10: =G10/$G$17 -> 0.16666667 | J10: Opportunistes | K10: 1 | L10: 2 | M10: 2 | N10: 1 | O10: =SUM(K10:N10) -> 6 | P10: =O10/$O$17 -> 0.16216216
B11: Imprudents | C11: 1 | G11: =SUM(C11:F11) -> 1 | H11: =G11/$G$17 -> 0.023809524 | J11: Imprudents | K11: 0 | L11: 2 | M11: 0 | N11: 0 | O11: =SUM(K11:N11) -> 2 | P11: =O11/$O$17 -> 0.054054054
B13: Hommes | C13: 2 | D13: 8 | E13: 6 | F13: 4 | G13: =SUM(C13:F13) -> 20 | H13: =G13/$G$17 -> 0.47619048 | J13: Hommes | K13: 3 | L13: 7 | M13: 11 | N13: 3 | O13: =SUM(K13:N13) -> 24 | P13: =O13/$O$17 -> 0.64864865
B14: Femmes | C14: 2 | D14: 8 | E14: 6 | F14: 5 | G14: =SUM(C14:F14) -> 21 | H14: =G14/$G$17 -> 0.5 | J14: Femmes | K14: 2 | L14: 4 | M14: 5 | N14: 2 | O14: =SUM(K14:N14) -> 13 | P14: =O14/$O$17 -> 0.35135135
B15: Enfants | C15: 0 | D15: 1 | E15: 0 | F15: 0 | G15: =SUM(C15:F15) -> 1 | H15: =G15/$G$17 -> 0.023809524 | J15: Enfants | K15: 0 | L15: 0 | M15: 0 | N15: 0 | O15: =SUM(K15:N15) -> 0 | P15: =O15/$O$17 -> 0
B17: TOTAL | C17: =SUM(C13:C15) -> 4 | D17: =SUM(D13:D15) -> 17 | E17: =SUM(E13:E15) -> 12 | F17: =SUM(F13:F15) -> 9 | G17: =SUM(C17:F17) -> 42 | J17: TOTAL | K17: =SUM(K13:K15) -> 5 | L17: =SUM(L13:L15) -> 11 | M17: =SUM(M13:M15) -> 16 | N17: =SUM(N13:N15) -> 5 | O17: =SUM(K17:N17) -> 37
B18: Pourcentage | C18: =C17/$G$17 -> 0.095238095 | D18: =D17/$G$17 -> 0.4047619 | E18: =E17/$G$17 -> 0.28571429 | F18: =F17/$G$17 -> 0.21428571 | J18: Pourcentage | K18: =K17/$O$17 -> 0.13513514 | L18: =L17/$O$17 -> 0.2972973 | M18: =M17/$O$17 -> 0.43243243 | N18: =N17/$O$17 -> 0.13513514

Sheet ARQUEBUSE
B1: MATIN | J1: SOIR
B3: RUE DE L'ARQUEBUSE | J3: RUE DE L'ARQUEBUSE
C4: Vers JONCTION | G4: Total | H4: Pourcentage | K4: Vers JONCTION | O4: Total | P4: Pourcentage
C5: 7h30-7h45 | D5: 7h45-8h00 | E5: 8h00-8h15 | F5: 8h15-8h30 | K5: 17h00-17h15 | L5: 17h15-17h30 | M5: 17h30-17h45 | N5: 17h45-18h00
B6: Vélo | C6: 19 | G6: =SUM(C6:F6) -> 19 | H6: =G6/$G$17 -> 0.63333333 | J6: Vélo | K6: 10 | L6: 7 | M6: 6 | N6: 5 | O6: =SUM(K6:N6) -> 28 | P6: =O6/$O$17 -> 0.875
B7: VAE | C7: 11 | G7: =SUM(C7:F7) -> 11 | H7: =G7/$G$17 -> 0.36666667 | J7: VAE | K7: 1 | L7: 1 | M7: 0 | N7: 2 | O7: =SUM(K7:N7) -> 4 | P7: =O7/$O$17 -> 0.125
B9: Conformistes | C9: 3 | G9: =SUM(C9:F9) -> 3 | H9: =G9/$G$17 -> 0.1 | J9: Conformistes | K9: 2 | L9: 1 | M9: 1 | N9: 1 | O9: =SUM(K9:N9) -> 5 | P9: =O9/$O$17 -> 0.15625
B10: Opportunistes | C10: 27 | G10: =SUM(C10:F10) -> 27 | H10: =G10/$G$17 -> 0.9 | J10: Opportunistes | K10: 8 | L10: 7 | M10: 3 | N10: 6 | O10: =SUM(K10:N10) -> 24 | P10: =O10/$O$17 -> 0.75
B11: Imprudents | C11: 0 | G11: =SUM(C11:F11) -> 0 | H11: =G11/$G$17 -> 0 | J11: Imprudents | K11: 1 | L11: 0 | M11: 2 | N11: 0 | O11: =SUM(K11:N11) -> 3 | P11: =O11/$O$17 -> 0.09375
B13: Hommes | C13: 25 | G13: =SUM(C13:F13) -> 25 | H13: =G13/$G$17 -> 0.83333333 | J13: Hommes | K13: 8 | L13: 4 | M13: 2 | N13: 0 | O13: =SUM(K13:N13) -> 14 | P13: =O13/$O$17 -> 0.4375
B14: Femmes | C14: 5 | G14: =SUM(C14:F14) -> 5 | H14: =G14/$G$17 -> 0.16666667 | J14: Femmes | K14: 3 | L14: 4 | M14: 4 | N14: 7 | O14: =SUM(K14:N14) -> 18 | P14: =O14/$O$17 -> 0.5625
B15: Enfants | G15: =SUM(C15:F15) -> 0 | H15: =G15/$G$17 -> 0 | J15: Enfants | K15: 0 | L15: 0 | M15: 0 | N15: 0 | O15: =SUM(K15:N15) -> 0 | P15: =O15/$O$17 -> 0
B17: TOTAL | C17: =SUM(C13:C15) -> 30 | D17: =SUM(D13:D15) -> 0 | E17: =SUM(E13:E15) -> 0 | F17: =SUM(F13:F15) -> 0 | G17: =SUM(C17:F17) -> 30 | J17: TOTAL | K17: =SUM(K13:K15) -> 11 | L17: =SUM(L13:L15) -> 8 | M17: =SUM(M13:M15) -> 6 | N17: =SUM(N13:N15) -> 7 | O17: =SUM(K17:N17) -> 32
B18: Pourcentage | C18: =C17/$G$17 -> 1 | D18: =D17/$G$17 -> 0 | E18: =E17/$G$17 -> 0 | F18: =F17/$G$17 -> 0 | J18: Pourcentage | K18: =K17/$O$17 -> 0.34375 | L18: =L17/$O$17 -> 0.25 | M18: =M17/$O$17 -> 0.1875 | N18: =N17/$O$17 -> 0.21875
B20: RUE DE L'ARQUEBUSE | J20: RUE DE L'ARQUEBUSE
C21: Vers JONCTION | G21: Total | H21: Pourcentage | K21: Vers JONCTION | O21: Total | P21: Pourcentage
C22: 7h30-7h45 | D22: 7h45-8h00 | E22: 8h00-8h15 | F22: 8h15-8h30 | K22: 17h00-17h15 | L22: 17h15-17h30 | M22: 17h30-17h45 | N22: 17h45-18h00
B23: Vélo | C23: 31 | G23: =SUM(C23:F23) -> 31 | H23: =G23/$G$34 -> 0.63265306 | J23: Vélo | K23: 10 | L23: 5 | M23: 8 | N23: 10 | O23: =SUM(K23:N23) -> 33 | P23: =O23/$O$34 -> 0.61111111
B24: VAE | C24: 18 | G24: =SUM(C24:F24) -> 18 | H24: =G24/$G$34 -> 0.36734694 | J24: VAE | K24: 6 | L24: 2 | M24: 4 | N24: 9 | O24: =SUM(K24:N24) -> 21 | P24: =O24/$O$34 -> 0.38888889
B26: Conformistes | C26: 8 | G26: =SUM(C26:F26) -> 8 | H26: =G26/$G$34 -> 0.16326531 | J26: Conformistes | K26: 4 | L26: 2 | M26: 0 | N26: 6 | O26: =SUM(K26:N26) -> 12 | P26: =O26/$O$34 -> 0.22222222
B27: Opportunistes | C27: 38 | G27: =SUM(C27:F27) -> 38 | H27: =G27/$G$34 -> 0.7755102 | J27: Opportunistes | K27: 11 | L27: 6 | M27: 10 | N27: 12 | O27: =SUM(K27:N27) -> 39 | P27: =O27/$O$34 -> 0.72222222
B28: Imprudents | C28: 3 | G28: =SUM(C28:F28) -> 3 | H28: =G28/$G$34 -> 0.06122449 | J28: Imprudents | K28: 1 | L28: 0 | M28: 1 | N28: 1 | O28: =SUM(K28:N28) -> 3 | P28: =O28/$O$34 -> 0.055555556
B30: Hommes | C30: 20 | G30: =SUM(C30:F30) -> 20 | H30: =G30/$G$34 -> 0.40816327 | J30: Hommes | K30: 7 | L30: 2 | M30: 8 | N30: 9 | O30: =SUM(K30:N30) -> 26 | P30: =O30/$O$34 -> 0.48148148
B31: Femmes | C31: 28 | G31: =SUM(C31:F31) -> 28 | H31: =G31/$G$34 -> 0.57142857 | J31: Femmes | K31: 9 | L31: 5 | M31: 4 | N31: 10 | O31: =SUM(K31:N31) -> 28 | P31: =O31/$O$34 -> 0.51851852
B32: Enfants | C32: 1 | G32: =SUM(C32:F32) -> 1 | H32: =G32/$G$34 -> 0.020408163 | J32: Enfants | K32: 0 | L32: 0 | M32: 0 | N32: 0 | O32: =SUM(K32:N32) -> 0 | P32: =O32/$O$34 -> 0
B34: TOTAL | C34: =SUM(C30:C32) -> 49 | D34: =SUM(D30:D32) -> 0 | E34: =SUM(E30:E32) -> 0 | F34: =SUM(F30:F32) -> 0 | G34: =SUM(C34:F34) -> 49 | J34: TOTAL | K34: =SUM(K30:K32) -> 16 | L34: =SUM(L30:L32) -> 7 | M34: =SUM(M30:M32) -> 12 | N34: =SUM(N30:N32) -> 19 | O34: =SUM(K34:N34) -> 54
B35: Pourcentage | C35: =C34/$G$34 -> 1 | D35: =D34/$G$34 -> 0 | E35: =E34/$G$34 -> 0 | F35: =F34/$G$34 -> 0 | J35: Pourcentage | K35: =K34/$O$34 -> 0.2962963 | L35: =L34/$O$34 -> 0.12962963 | M35: =M34/$O$34 -> 0.22222222 | N35: =N34/$O$34 -> 0.35185185

Sheet GEORGES-FAVON
B1: MATIN | J1: SOIR
B3: BLD GEORGES-FAVON | J3: BLD GEORGES-FAVON
C4: Vers GARE | G4: Total | H4: Pourcentage | K4: Vers GARE | O4: Total | P4: Pourcentage
C5: 7h30-7h45 | D5: 7h45-8h00 | E5: 8h00-8h15 | F5: 8h15-8h30 | K5: 17h00-17h15 | L5: 17h15-17h30 | M5: 17h30-17h45 | N5: 17h45-18h00
B6: Vélo | C6: 25 | D6: 40 | E6: 22 | F6: 35 | G6: =SUM(C6:F6) -> 122 | H6: =G6/$G$17 -> 0.80794702 | J6: Vélo | K6: 42 | L6: 36 | M6: 35 | N6: 63 | O6: =SUM(K6:N6) -> 176 | P6: =O6/$O$17 -> 0.81105991
B7: VAE | C7: 4 | D7: 5 | E7: 6 | F7: 14 | G7: =SUM(C7:F7) -> 29 | H7: =G7/$G$17 -> 0.19205298 | J7: VAE | K7: 10 | L7: 13 | M7: 6 | N7: 11 | O7: =SUM(K7:N7) -> 40 | P7: =O7/$O$17 -> 0.1843318
B9: Conformistes | G9: =SUM(C9:F9) -> 0 | H9: =G9/$G$17 -> 0 | J9: Conformistes | K9: 22 | L9: 27 | M9: 18 | N9: 44 | O9: =SUM(K9:N9) -> 111 | P9: =O9/$O$17 -> 0.51152074
B10: Opportunistes | G10: =SUM(C10:F10) -> 0 | H10: =G10/$G$17 -> 0 | J10: Opportunistes | K10: 28 | L10: 20 | M10: 21 | N10: 30 | O10: =SUM(K10:N10) -> 99 | P10: =O10/$O$17 -> 0.4562212
B11: Imprudents | G11: =SUM(C11:F11) -> 0 | H11: =G11/$G$17 -> 0 | J11: Imprudents | K11: 2 | L11: 2 | M11: 2 | N11: 1 | O11: =SUM(K11:N11) -> 7 | P11: =O11/$O$17 -> 0.032258065
B13: Hommes | C13: 16 | D13: 26 | E13: 18 | F13: 26 | G13: =SUM(C13:F13) -> 86 | H13: =G13/$G$17 -> 0.56953642 | J13: Hommes | K13: 31 | L13: 33 | M13: 20 | N13: 45 | O13: =SUM(K13:N13) -> 129 | P13: =O13/$O$17 -> 0.59447005
B14: Femmes | C14: 13 | D14: 19 | E14: 10 | F14: 23 | G14: =SUM(C14:F14) -> 65 | H14: =G14/$G$17 -> 0.43046358 | J14: Femmes | K14: 21 | L14: 16 | M14: 21 | N14: 29 | O14: =SUM(K14:N14) -> 87 | P14: =O14/$O$17 -> 0.40092166
B15: Enfants | C15: 0 | D15: 0 | E15: 0 | F15: 0 | G15: =SUM(C15:F15) -> 0 | H15: =G15/$G$17 -> 0 | J15: Enfants | K15: 0 | L15: 0 | M15: 0 | N15: 1 | O15: =SUM(K15:N15) -> 1 | P15: =O15/$O$17 -> 0.0046082949
B17: TOTAL | C17: =SUM(C13:C15) -> 29 | D17: =SUM(D13:D15) -> 45 | E17: =SUM(E13:E15) -> 28 | F17: =SUM(F13:F15) -> 49 | G17: =SUM(C17:F17) -> 151 | J17: TOTAL | K17: =SUM(K13:K15) -> 52 | L17: =SUM(L13:L15) -> 49 | M17: =SUM(M13:M15) -> 41 | N17: =SUM(N13:N15) -> 75 | O17: =SUM(K17:N17) -> 217
B18: Pourcentage | C18: =C17/$G$17 -> 0.19205298 | D18: =D17/$G$17 -> 0.29801325 | E18: =E17/$G$17 -> 0.18543046 | F18: =F17/$G$17 -> 0.32450331 | J18: Pourcentage | K18: =K17/$O$17 -> 0.23963134 | L18: =L17/$O$17 -> 0.22580645 | M18: =M17/$O$17 -> 0.18894009 | N18: =N17/$O$17 -> 0.34562212
B20: BLD GEORGES-FAVON | J20: BLD GEORGES-FAVON
C21: Vers PLAINPALAIS | G21: Total | H21: Pourcentage | K21: Vers PLAINPALAIS | O21: Total | P21: Pourcentage
C22: 7h30-7h45 | D22: 7h45-8h00 | E22: 8h00-8h15 | F22: 8h15-8h30 | K22: 17h00-17h15 | L22: 17h15-17h30 | M22: 17h30-17h45 | N22: 17h45-18h00
B23: Vélo | C23: 25 | D23: 30 | E23: 33 | F23: 31 | G23: =SUM(C23:F23) -> 119 | H23: =G23/$G$34 -> 0.90151515 | J23: Vélo | K23: 39 | L23: 19 | M23: 33 | N23: 50 | O23: =SUM(K23:N23) -> 141 | P23: =O23/$O$34 -> 0.76216216
B24: VAE | C24: 2 | D24: 2 | E24: 5 | F24: 4 | G24: =SUM(C24:F24) -> 13 | H24: =G24/$G$34 -> 0.098484848 | J24: VAE | K24: 16 | L24: 4 | M24: 15 | N24: 9 | O24: =SUM(K24:N24) -> 44 | P24: =O24/$O$34 -> 0.23783784
B26: Conformistes | G26: =SUM(C26:F26) -> 0 | H26: =G26/$G$34 -> 0 | J26: Conformistes | O26: =SUM(K26:N26) -> 0 | P26: =O26/$O$34 -> 0
B27: Opportunistes | G27: =SUM(C27:F27) -> 0 | H27: =G27/$G$34 -> 0 | J27: Opportunistes | O27: =SUM(K27:N27) -> 0 | P27: =O27/$O$34 -> 0
B28: Imprudents | G28: =SUM(C28:F28) -> 0 | H28: =G28/$G$34 -> 0 | J28: Imprudents | O28: =SUM(K28:N28) -> 0 | P28: =O28/$O$34 -> 0
B30: Hommes | C30: 19 | D30: 19 | E30: 26 | F30: 21 | G30: =SUM(C30:F30) -> 85 | H30: =G30/$G$34 -> 0.64393939 | J30: Hommes | K30: 30 | L30: 13 | M30: 20 | N30: 38 | O30: =SUM(K30:N30) -> 101 | P30: =O30/$O$34 -> 0.54594595
B31: Femmes | C31: 8 | D31: 13 | E31: 12 | F31: 14 | G31: =SUM(C31:F31) -> 47 | H31: =G31/$G$34 -> 0.35606061 | J31: Femmes | K31: 25 | L31: 10 | M31: 28 | N31: 21 | O31: =SUM(K31:N31) -> 84 | P31: =O31/$O$34 -> 0.45405405
B32: Enfants | G32: =SUM(C32:F32) -> 0 | H32: =G32/$G$34 -> 0 | J32: Enfants | K32: 0 | L32: 0 | M32: 0 | N32: 0 | O32: =SUM(K32:N32) -> 0 | P32: =O32/$O$34 -> 0
B34: TOTAL | C34: =SUM(C30:C32) -> 27 | D34: =SUM(D30:D32) -> 32 | E34: =SUM(E30:E32) -> 38 | F34: =SUM(F30:F32) -> 35 | G34: =SUM(C34:F34) -> 132 | J34: TOTAL | K34: =SUM(K30:K32) -> 55 | L34: =SUM(L30:L32) -> 23 | M34: =SUM(M30:M32) -> 48 | N34: =SUM(N30:N32) -> 59 | O34: =SUM(K34:N34) -> 185
B35: Pourcentage | C35: =C34/$G$34 -> 0.20454545 | D35: =D34/$G$34 -> 0.24242424 | E35: =E34/$G$34 -> 0.28787879 | F35: =F34/$G$34 -> 0.26515152 | J35: Pourcentage | K35: =K34/$O$34 -> 0.2972973 | L35: =L34/$O$34 -> 0.12432432 | M35: =M34/$O$34 -> 0.25945946 | N35: =N34/$O$34 -> 0.31891892

Sheet F HODLER
B1: MATIN | J1: SOIR
B3: RUE FERDINAND-HODLER | J3: RUE FERDINAND-HODLER
C4: Vers MALAGNOU | G4: Total | H4: Pourcentage | K4: Vers MALAGNOU | O4: Total | P4: Pourcentage
C5: 7h30-7h45 | D5: 7h45-8h00 | E5: 8h00-8h15 | F5: 8h15-8h30 | K5: 17h00-17h15 | L5: 17h15-17h30 | M5: 17h30-17h45 | N5: 17h45-18h00
B6: Vélo | C6: 2 | D6: 5 | E6: 5 | F6: 3 | G6: =SUM(C6:F6) -> 15 | H6: =G6/$G$17 -> 0.65217391 | J6: Vélo | K6: 5 | L6: 2 | M6: 6 | N6: 7 | O6: =SUM(K6:N6) -> 20 | P6: =O6/$O$17 -> 0.55555556
B7: VAE | C7: 2 | D7: 1 | E7: 3 | F7: 2 | G7: =SUM(C7:F7) -> 8 | H7: =G7/$G$17 -> 0.34782609 | J7: VAE | K7: 4 | L7: 4 | M7: 3 | N7: 5 | O7: =SUM(K7:N7) -> 16 | P7: =O7/$O$17 -> 0.44444444
B9: Conformistes | C9: 3 | D9: 5 | E9: 6 | F9: 5 | G9: =SUM(C9:F9) -> 19 | H9: =G9/$G$17 -> 0.82608696 | J9: Conformistes | K9: 36 | O9: =SUM(K9:N9) -> 36 | P9: =O9/$O$17 -> 1
B10: Opportunistes | C10: 0 | D10: 0 | E10: 2 | F10: 0 | G10: =SUM(C10:F10) -> 2 | H10: =G10/$G$17 -> 0.086956522 | J10: Opportunistes | K10: 0 | O10: =SUM(K10:N10) -> 0 | P10: =O10/$O$17 -> 0
B11: Imprudents | C11: 1 | D11: 1 | E11: 0 | F11: 0 | G11: =SUM(C11:F11) -> 2 | H11: =G11/$G$17 -> 0.086956522 | J11: Imprudents | K11: 0 | O11: =SUM(K11:N11) -> 0 | P11: =O11/$O$17 -> 0
B13: Hommes | C13: 1 | D13: 2 | E13: 4 | F13: 2 | G13: =SUM(C13:F13) -> 9 | H13: =G13/$G$17 -> 0.39130435 | J13: Hommes | K13: 5 | L13: 2 | M13: 4 | N13: 8 | O13: =SUM(K13:N13) -> 19 | P13: =O13/$O$17 -> 0.52777778
B14: Femmes | C14: 2 | D14: 3 | E14: 4 | F14: 3 | G14: =SUM(C14:F14) -> 12 | H14: =G14/$G$17 -> 0.52173913 | J14: Femmes | K14: 4 | L14: 4 | M14: 5 | N14: 4 | O14: =SUM(K14:N14) -> 17 | P14: =O14/$O$17 -> 0.47222222
B15: Enfants | C15: 1 | D15: 1 | E15: 0 | F15: 0 | G15: =SUM(C15:F15) -> 2 | H15: =G15/$G$17 -> 0.086956522 | J15: Enfants | K15: 0 | L15: 0 | M15: 0 | N15: 0 | O15: =SUM(K15:N15) -> 0 | P15: =O15/$O$17 -> 0
B17: TOTAL | C17: =SUM(C13:C15) -> 4 | D17: =SUM(D13:D15) -> 6 | E17: =SUM(E13:E15) -> 8 | F17: =SUM(F13:F15) -> 5 | G17: =SUM(C17:F17) -> 23 | J17: TOTAL | K17: =SUM(K13:K15) -> 9 | L17: =SUM(L13:L15) -> 6 | M17: =SUM(M13:M15) -> 9 | N17: =SUM(N13:N15) -> 12 | O17: =SUM(K17:N17) -> 36
B18: Pourcentage | C18: =C17/$G$17 -> 0.17391304 | D18: =D17/$G$17 -> 0.26086957 | E18: =E17/$G$17 -> 0.34782609 | F18: =F17/$G$17 -> 0.2173913 | J18: Pourcentage | K18: =K17/$O$17 -> 0.25 | L18: =L17/$O$17 -> 0.16666667 | M18: =M17/$O$17 -> 0.25 | N18: =N17/$O$17 -> 0.33333333
B20: RUE FERDINAND-HODLER | J20: RUE FERDINAND-HODLER
C21: Vers TRANCHEE | G21: Total | H21: Pourcentage | K21: Vers TRANCHEE | O21: Total | P21: Pourcentage
C22: 7h30-7h45 | D22: 7h45-8h00 | E22: 8h00-8h15 | F22: 8h15-8h30 | K22: 17h00-17h15 | L22: 17h15-17h30 | M22: 17h30-17h45 | N22: 17h45-18h00
B23: Vélo | C23: 2 | D23: 3 | E23: 1 | F23: 6 | G23: =SUM(C23:F23) -> 12 | H23: =G23/$G$34 -> 0.66666667 | J23: Vélo | K23: 2 | L23: 1 | M23: 2 | N23: 1 | O23: =SUM(K23:N23) -> 6 | P23: =O23/$O$34 -> 0.85714286
B24: VAE | C24: 1 | D24: 0 | E24: 4 | F24: 1 | G24: =SUM(C24:F24) -> 6 | H24: =G24/$G$34 -> 0.33333333 | J24: VAE | K24: 0 | L24: 0 | M24: 0 | N24: 1 | O24: =SUM(K24:N24) -> 1 | P24: =O24/$O$34 -> 0.14285714
B26: Conformistes | C26: 3 | D26: 3 | E26: 5 | F26: 7 | G26: =SUM(C26:F26) -> 18 | H26: =G26/$G$34 -> 1 | J26: Conformistes | K26: 2 | L26: 1 | M26: 2 | N26: 2 | O26: =SUM(K26:N26) -> 7 | P26: =O26/$O$34 -> 1
B27: Opportunistes | C27: 0 | D27: 0 | E27: 0 | F27: 0 | G27: =SUM(C27:F27) -> 0 | H27: =G27/$G$34 -> 0 | J27: Opportunistes | K27: 0 | L27: 0 | M27: 0 | N27: 0 | O27: =SUM(K27:N27) -> 0 | P27: =O27/$O$34 -> 0
B28: Imprudents | C28: 0 | D28: 0 | E28: 0 | F28: 0 | G28: =SUM(C28:F28) -> 0 | H28: =G28/$G$34 -> 0 | J28: Imprudents | K28: 0 | L28: 0 | M28: 0 | N28: 0 | O28: =SUM(K28:N28) -> 0 | P28: =O28/$O$34 -> 0
B30: Hommes | C30: 2 | D30: 3 | E30: 2 | F30: 5 | G30: =SUM(C30:F30) -> 12 | H30: =G30/$G$34 -> 0.66666667 | J30: Hommes | K30: 1 | L30: 1 | M30: 1 | N30: 1 | O30: =SUM(K30:N30) -> 4 | P30: =O30/$O$34 -> 0.57142857
B31: Femmes | C31: 1 | D31: 0 | E31: 3 | F31: 2 | G31: =SUM(C31:F31) -> 6 | H31: =G31/$G$34 -> 0.33333333 | J31: Femmes | K31: 1 | L31: 0 | M31: 1 | N31: 1 | O31: =SUM(K31:N31) -> 3 | P31: =O31/$O$34 -> 0.42857143
B32: Enfants | C32: 0 | D32: 0 | E32: 0 | F32: 0 | G32: =SUM(C32:F32) -> 0 | H32: =G32/$G$34 -> 0 | J32: Enfants | K32: 0 | L32: 0 | M32: 0 | N32: 0 | O32: =SUM(K32:N32) -> 0 | P32: =O32/$O$34 -> 0
B34: TOTAL | C34: =SUM(C30:C32) -> 3 | D34: =SUM(D30:D32) -> 3 | E34: =SUM(E30:E32) -> 5 | F34: =SUM(F30:F32) -> 7 | G34: =SUM(C34:F34) -> 18 | J34: TOTAL | K34: =SUM(K30:K32) -> 2 | L34: =SUM(L30:L32) -> 1 | M34: =SUM(M30:M32) -> 2 | N34: =SUM(N30:N32) -> 2 | O34: =SUM(K34:N34) -> 7
B35: Pourcentage | C35: =C34/$G$34 -> 0.16666667 | D35: =D34/$G$34 -> 0.16666667 | E35: =E34/$G$34 -> 0.27777778 | F35: =F34/$G$34 -> 0.38888889 | J35: Pourcentage | K35: =K34/$O$34 -> 0.28571429 | L35: =L34/$O$34 -> 0.14285714 | M35: =M34/$O$34 -> 0.28571429 | N35: =N34/$O$34 -> 0.28571429
B37: RUE FERDINAND-HODLER | J37: RUE FERDINAND-HODLER
C38: Vers VILLE | G38: Total | H38: Pourcentage | K38: Vers VILLE | O38: Total | P38: Pourcentage
C39: 7h30-7h45 | D39: 7h45-8h00 | E39: 8h00-8h15 | F39: 8h15-8h30 | K39: 17h00-17h15 | L39: 17h15-17h30 | M39: 17h30-17h45 | N39: 17h45-18h00
B40: Vélo | C40: 7 | D40: 10 | E40: 11 | F40: 6 | G40: =SUM(C40:F40) -> 34 | H40: =G40/$G$51 -> 0.50746269 | J40: Vélo | K40: 1 | L40: 3 | M40: 5 | N40: 7 | O40: =SUM(K40:N40) -> 16 | P40: =O40/$O$51 -> 0.76190476
B41: VAE | C41: 6 | D41: 5 | E41: 13 | F41: 9 | G41: =SUM(C41:F41) -> 33 | H41: =G41/$G$51 -> 0.49253731 | J41: VAE | K41: 0 | L41: 2 | M41: 1 | N41: 2 | O41: =SUM(K41:N41) -> 5 | P41: =O41/$O$51 -> 0.23809524
B43: Conformistes | C43: 13 | D43: 10 | E43: 17 | F43: 15 | G43: =SUM(C43:F43) -> 55 | H43: =G43/$G$51 -> 0.82089552 | J43: Conformistes | K43: 1 | L43: 4 | N43: 1 | O43: =SUM(K43:N43) -> 6 | P43: =O43/$O$51 -> 0.28571429
B44: Opportunistes | C44: 0 | D44: 5 | E44: 7 | F44: 0 | G44: =SUM(C44:F44) -> 12 | H44: =G44/$G$51 -> 0.17910448 | J44: Opportunistes | K44: 0 | L44: 2 | O44: =SUM(K44:N44) -> 2 | P44: =O44/$O$51 -> 0.095238095
B45: Imprudents | C45: 0 | D45: 0 | E45: 0 | F45: 0 | G45: =SUM(C45:F45) -> 0 | H45: =G45/$G$51 -> 0 | J45: Imprudents | K45: 0 | L45: 0 | O45: =SUM(K45:N45) -> 0 | P45: =O45/$O$51 -> 0
B47: Hommes | C47: 8 | D47: 6 | E47: 13 | F47: 7 | G47: =SUM(C47:F47) -> 34 | H47: =G47/$G$51 -> 0.50746269 | J47: Hommes | K47: 0 | L47: 3 | M47: 4 | N47: 7 | O47: =SUM(K47:N47) -> 14 | P47: =O47/$O$51 -> 0.66666667
B48: Femmes | C48: 5 | D48: 9 | E48: 11 | F48: 8 | G48: =SUM(C48:F48) -> 33 | H48: =G48/$G$51 -> 0.49253731 | J48: Femmes | K48: 1 | L48: 2 | M48: 2 | N48: 2 | O48: =SUM(K48:N48) -> 7 | P48: =O48/$O$51 -> 0.33333333
B49: Enfants | C49: 0 | D49: 0 | E49: 0 | F49: 0 | G49: =SUM(C49:F49) -> 0 | H49: =G49/$G$51 -> 0 | J49: Enfants | K49: 0 | L49: 0 | M49: 0 | O49: =SUM(K49:N49) -> 0 | P49: =O49/$O$51 -> 0
B51: TOTAL | C51: =SUM(C47:C49) -> 13 | D51: =SUM(D47:D49) -> 15 | E51: =SUM(E47:E49) -> 24 | F51: =SUM(F47:F49) -> 15 | G51: =SUM(C51:F51) -> 67 | J51: TOTAL | K51: =SUM(K47:K49) -> 1 | L51: =SUM(L47:L49) -> 5 | M51: =SUM(M47:M49) -> 6 | N51: =SUM(N47:N49) -> 9 | O51: =SUM(K51:N51) -> 21
B52: Pourcentage | C52: =C51/$G$51 -> 0.19402985 | D52: =D51/$G$51 -> 0.2238806 | E52: =E51/$G$51 -> 0.35820896 | F52: =F51/$G$51 -> 0.2238806 | J52: Pourcentage | K52: =K51/$O$51 -> 0.047619048 | L52: =L51/$O$51 -> 0.23809524 | M52: =M51/$O$51 -> 0.28571429 | N52: =N51/$O$51 -> 0.42857143

Sheet PICTET ROCHEMONT
B1: MATIN | J1: SOIR
B3: AVE PICTET DE ROCHEMONT | J3: AVE PICTET DE ROCHEMONT
C4: Vers VILLE | G4: Total | H4: Pourcentage | K4: Vers VILLE | O4: Total | P4: Pourcentage
C5: 7h30-7h45 | D5: 7h45-8h00 | E5: 8h00-8h15 | F5: 8h15-8h30 | K5: 17h00-17h15 | L5: 17h15-17h30 | M5: 17h30-17h45 | N5: 17h45-18h00
B6: Vélo | C6: 6 | D6: 16 | E6: 16 | F6: 18 | G6: =SUM(C6:F6) -> 56 | H6: =G6/$G$17 -> 0.66666667 | J6: Vélo | K6: 8 | L6: 11 | M6: 16 | N6: 5 | O6: =SUM(K6:N6) -> 40 | P6: =O6/$O$17 -> 0.70175439
B7: VAE | C7: 7 | D7: 6 | E7: 8 | F7: 7 | G7: =SUM(C7:F7) -> 28 | H7: =G7/$G$17 -> 0.33333333 | J7: VAE | K7: 4 | L7: 5 | M7: 2 | N7: 6 | O7: =SUM(K7:N7) -> 17 | P7: =O7/$O$17 -> 0.29824561
B9: Conformistes | C9: 10 | D9: 15 | E9: 14 | F9: 16 | G9: =SUM(C9:F9) -> 55 | H9: =G9/$G$17 -> 0.6547619 | J9: Conformistes | K9: 11 | L9: 10 | M9: 15 | N9: 10 | O9: =SUM(K9:N9) -> 46 | P9: =O9/$O$17 -> 0.80701754
B10: Opportunistes | C10: 4 | D10: 8 | E10: 9 | F10: 8 | G10: =SUM(C10:F10) -> 29 | H10: =G10/$G$17 -> 0.3452381 | J10: Opportunistes | K10: 1 | L10: 5 | M10: 3 | N10: 1 | O10: =SUM(K10:N10) -> 10 | P10: =O10/$O$17 -> 0.1754386
B11: Imprudents | C11: 0 | D11: 0 | E11: 0 | F11: 0 | G11: =SUM(C11:F11) -> 0 | H11: =G11/$G$17 -> 0 | J11: Imprudents | K11: 0 | L11: 1 | M11: 0 | N11: 0 | O11: =SUM(K11:N11) -> 1 | P11: =O11/$O$17 -> 0.01754386
B13: Hommes | C13: 8 | D13: 16 | E13: 16 | F13: 13 | G13: =SUM(C13:F13) -> 53 | H13: =G13/$G$17 -> 0.63095238 | J13: Hommes | K13: 7 | L13: 11 | M13: 9 | N13: 5 | O13: =SUM(K13:N13) -> 32 | P13: =O13/$O$17 -> 0.56140351
B14: Femmes | C14: 5 | D14: 6 | E14: 8 | F14: 12 | G14: =SUM(C14:F14) -> 31 | H14: =G14/$G$17 -> 0.36904762 | J14: Femmes | K14: 5 | L14: 5 | M14: 9 | N14: 6 | O14: =SUM(K14:N14) -> 25 | P14: =O14/$O$17 -> 0.43859649
B15: Enfants | C15: 0 | D15: 0 | E15: 0 | F15: 0 | G15: =SUM(C15:F15) -> 0 | H15: =G15/$G$17 -> 0 | J15: Enfants | K15: 0 | L15: 0 | M15: 0 | N15: 0 | O15: =SUM(K15:N15) -> 0 | P15: =O15/$O$17 -> 0
B17: TOTAL | C17: =SUM(C13:C15) -> 13 | D17: =SUM(D13:D15) -> 22 | E17: =SUM(E13:E15) -> 24 | F17: =SUM(F13:F15) -> 25 | G17: =SUM(C17:F17) -> 84 | J17: TOTAL | K17: =SUM(K13:K15) -> 12 | L17: =SUM(L13:L15) -> 16 | M17: =SUM(M13:M15) -> 18 | N17: =SUM(N13:N15) -> 11 | O17: =SUM(K17:N17) -> 57
B18: Pourcentage | C18: =C17/$G$17 -> 0.1547619 | D18: =D17/$G$17 -> 0.26190476 | E18: =E17/$G$17 -> 0.28571429 | F18: =F17/$G$17 -> 0.29761905 | J18: Pourcentage | K18: =K17/$O$17 -> 0.21052632 | L18: =L17/$O$17 -> 0.28070175 | M18: =M17/$O$17 -> 0.31578947 | N18: =N17/$O$17 -> 0.19298246
B20: AVE PICTET DE ROCHEMONT | J20: AVE PICTET DE ROCHEMONT
C21: Vers ANNEMASSE | G21: Total | H21: Pourcentage | K21: Vers ANNEMASSE | O21: Total | P21: Pourcentage
C22: 7h30-7h45 | D22: 7h45-8h00 | E22: 8h00-8h15 | F22: 8h15-8h30 | K22: 17h00-17h15 | L22: 17h15-17h30 | M22: 17h30-17h45 | N22: 17h45-18h00
B23: Vélo | C23: 6 | D23: 2 | E23: 7 | F23: 4 | G23: =SUM(C23:F23) -> 19 | H23: =G23/$G$34 -> 0.57575758 | J23: Vélo | K23: 7 | L23: 8 | M23: 9 | N23: 4 | O23: =SUM(K23:N23) -> 28 | P23: =O23/$O$34 -> 0.77777778
B24: VAE | C24: 1 | D24: 5 | E24: 3 | F24: 5 | G24: =SUM(C24:F24) -> 14 | H24: =G24/$G$34 -> 0.42424242 | J24: VAE | K24: 0 | L24: 2 | M24: 3 | N24: 3 | O24: =SUM(K24:N24) -> 8 | P24: =O24/$O$34 -> 0.22222222
B26: Conformistes | C26: 24 | G26: =SUM(C26:F26) -> 24 | H26: =G26/$G$34 -> 0.72727273 | J26: Conformistes | K26: 5 | L26: 9 | M26: 8 | N26: 7 | O26: =SUM(K26:N26) -> 29 | P26: =O26/$O$34 -> 0.80555556
B27: Opportunistes | C27: 11 | G27: =SUM(C27:F27) -> 11 | H27: =G27/$G$34 -> 0.33333333 | J27: Opportunistes | K27: 1 | L27: 1 | M27: 4 | N27: 0 | O27: =SUM(K27:N27) -> 6 | P27: =O27/$O$34 -> 0.16666667
B28: Imprudents | C28: 0 | G28: =SUM(C28:F28) -> 0 | H28: =G28/$G$34 -> 0 | J28: Imprudents | K28: 1 | L28: 0 | M28: 0 | N28: 0 | O28: =SUM(K28:N28) -> 1 | P28: =O28/$O$34 -> 0.027777778
B30: Hommes | C30: 4 | D30: 2 | E30: 4 | F30: 2 | G30: =SUM(C30:F30) -> 12 | H30: =G30/$G$34 -> 0.36363636 | J30: Hommes | K30: 5 | L30: 9 | M30: 7 | N30: 3 | O30: =SUM(K30:N30) -> 24 | P30: =O30/$O$34 -> 0.66666667
B31: Femmes | C31: 3 | D31: 5 | E31: 6 | F31: 7 | G31: =SUM(C31:F31) -> 21 | H31: =G31/$G$34 -> 0.63636364 | J31: Femmes | K31: 2 | L31: 1 | M31: 5 | N31: 4 | O31: =SUM(K31:N31) -> 12 | P31: =O31/$O$34 -> 0.33333333
B32: Enfants | C32: 0 | D32: 0 | E32: 0 | F32: 0 | G32: =SUM(C32:F32) -> 0 | H32: =G32/$G$34 -> 0 | J32: Enfants | K32: 0 | L32: 0 | M32: 0 | N32: 0 | O32: =SUM(K32:N32) -> 0 | P32: =O32/$O$34 -> 0
B34: TOTAL | C34: =SUM(C30:C32) -> 7 | D34: =SUM(D30:D32) -> 7 | E34: =SUM(E30:E32) -> 10 | F34: =SUM(F30:F32) -> 9 | G34: =SUM(C34:F34) -> 33 | J34: TOTAL | K34: =SUM(K30:K32) -> 7 | L34: =SUM(L30:L32) -> 10 | M34: =SUM(M30:M32) -> 12 | N34: =SUM(N30:N32) -> 7 | O34: =SUM(K34:N34) -> 36
B35: Pourcentage | C35: =C34/$G$34 -> 0.21212121 | D35: =D34/$G$34 -> 0.21212121 | E35: =E34/$G$34 -> 0.3030303 | F35: =F34/$G$34 -> 0.27272727 | J35: Pourcentage | K35: =K34/$O$34 -> 0.19444444 | L35: =L34/$O$34 -> 0.27777778 | M35: =M34/$O$34 -> 0.33333333 | N35: =N34/$O$34 -> 0.19444444

Sheet VV, BEL AIR
B1: MATIN | J1: SOIR
B3: VV, AVE BEL AIR | J3: VV, AVE BEL AIR
C4: Vers VILLE | G4: Total | H4: Pourcentage | K4: Vers VILLE | O4: Total | P4: Pourcentage
C5: 7h30-7h45 | D5: 7h45-8h00 | E5: 8h00-8h15 | F5: 8h15-8h30 | K5: 17h00-17h15 | L5: 17h15-17h30 | M5: 17h30-17h45 | N5: 17h45-18h00
B6: Vélo | C6: 335 | G6: =SUM(C6:F6) -> 335 | H6: =G6/$G$17 -> 0.59187279 | J6: Vélo | K6: 23 | L6: 30 | M6: 32 | N6: 20 | O6: =SUM(K6:N6) -> 105 | P6: =O6/$O$17 -> 0.71917808
B7: VAE | C7: 231 | G7: =SUM(C7:F7) -> 231 | H7: =G7/$G$17 -> 0.40812721 | J7: VAE | K7: 12 | L7: 9 | M7: 8 | N7: 12 | O7: =SUM(K7:N7) -> 41 | P7: =O7/$O$17 -> 0.28082192
B9: Conformistes | C9: =G17*0.54 -> 305.64 | G9: =SUM(C9:F9) -> 305.64 | H9: =G9/$G$17 -> 0.54 | J9: Conformistes | K9: =$O$17*0.7 -> 102.2 | O9: =SUM(K9:N9) -> 102.2 | P9: =O9/$O$17 -> 0.7
B10: Opportunistes | C10: =G17*0.37 -> 209.42 | G10: =SUM(C10:F10) -> 209.42 | H10: =G10/$G$17 -> 0.37 | J10: Opportunistes | K10: =$O$17*0.25 -> 36.5 | O10: =SUM(K10:N10) -> 36.5 | P10: =O10/$O$17 -> 0.25
B11: Imprudents | C11: =G17*0.09 -> 50.94 | G11: =SUM(C11:F11) -> 50.94 | H11: =G11/$G$17 -> 0.09 | J11: Imprudents | K11: =$O$17*0.05 -> 7.3 | O11: =SUM(K11:N11) -> 7.3 | P11: =O11/$O$17 -> 0.05
B13: Hommes | C13: 287 | G13: =SUM(C13:F13) -> 287 | H13: =G13/$G$17 -> 0.50706714 | J13: Hommes | K13: 21 | L13: 17 | M13: 22 | N13: 17 | O13: =SUM(K13:N13) -> 77 | P13: =O13/$O$17 -> 0.52739726
B14: Femmes | C14: 217 | G14: =SUM(C14:F14) -> 217 | H14: =G14/$G$17 -> 0.38339223 | J14: Femmes | K14: 14 | L14: 21 | M14: 16 | N14: 14 | O14: =SUM(K14:N14) -> 65 | P14: =O14/$O$17 -> 0.44520548
B15: Enfants | C15: 62 | G15: =SUM(C15:F15) -> 62 | H15: =G15/$G$17 -> 0.10954064 | J15: Enfants | K15: 0 | L15: 1 | M15: 2 | N15: 1 | O15: =SUM(K15:N15) -> 4 | P15: =O15/$O$17 -> 0.02739726
B17: TOTAL | C17: =SUM(C13:C15) -> 566 | D17: =SUM(D13:D15) -> 0 | E17: =SUM(E13:E15) -> 0 | F17: =SUM(F13:F15) -> 0 | G17: =SUM(C17:F17) -> 566 | J17: TOTAL | K17: =SUM(K13:K15) -> 35 | L17: =SUM(L13:L15) -> 39 | M17: =SUM(M13:M15) -> 40 | N17: =SUM(N13:N15) -> 32 | O17: =SUM(K17:N17) -> 146
B18: Pourcentage | C18: =C17/$G$17 -> 1 | D18: =D17/$G$17 -> 0 | E18: =E17/$G$17 -> 0 | F18: =F17/$G$17 -> 0 | G18: =G17/G37 -> 0.86943164 | J18: Pourcentage | K18: =K17/$O$17 -> 0.23972603 | L18: =L17/$O$17 -> 0.26712329 | M18: =M17/$O$17 -> 0.2739726 | N18: =N17/$O$17 -> 0.21917808
B20: VV, AVE BEL AIR | J20: VV, AVE BEL AIR
C21: Vers ANNEMASSE | G21: Total | H21: Pourcentage | K21: Vers ANNEMASSE | O21: Total | P21: Pourcentage
C22: 7h30-7h45 | D22: 7h45-8h00 | E22: 8h00-8h15 | F22: 8h15-8h30 | K22: 17h00-17h15 | L22: 17h15-17h30 | M22: 17h30-17h45 | N22: 17h45-18h00
B23: Vélo | C23: 53 | G23: =SUM(C23:F23) -> 53 | H23: =G23/$G$34 -> 0.62352941 | J23: Vélo | K23: 41 | L23: 55 | M23: 40 | N23: 54 | O23: =SUM(K23:N23) -> 190 | P23: =O23/$O$34 -> 0.63973064
B24: VAE | C24: 32 | G24: =SUM(C24:F24) -> 32 | H24: =G24/$G$34 -> 0.37647059 | J24: VAE | K24: 24 | L24: 33 | M24: 26 | N24: 24 | O24: =SUM(K24:N24) -> 107 | P24: =O24/$O$34 -> 0.36026936
B26: Conformistes | C26: =$G$34*H9 -> 45.9 | G26: =SUM(C26:F26) -> 45.9 | H26: =G26/$G$34 -> 0.54 | J26: Conformistes | K26: =O34*0.7 -> 207.9 | O26: =SUM(K26:N26) -> 207.9 | P26: =O26/$O$34 -> 0.7
B27: Opportunistes | C27: =$G$34*H10 -> 31.45 | G27: =SUM(C27:F27) -> 31.45 | H27: =G27/$G$34 -> 0.37 | J27: Opportunistes | K27: =O34*0.25 -> 74.25 | O27: =SUM(K27:N27) -> 74.25 | P27: =O27/$O$34 -> 0.25
B28: Imprudents | C28: =$G$34*H11 -> 7.65 | G28: =SUM(C28:F28) -> 7.65 | H28: =G28/$G$34 -> 0.09 | J28: Imprudents | K28: =O34*0.05 -> 14.85 | O28: =SUM(K28:N28) -> 14.85 | P28: =O28/$O$34 -> 0.05
B30: Hommes | C30: 47 | G30: =SUM(C30:F30) -> 47 | H30: =G30/$G$34 -> 0.55294118 | J30: Hommes | K30: 34 | L30: 52 | M30: 49 | N30: 48 | O30: =SUM(K30:N30) -> 183 | P30: =O30/$O$34 -> 0.61616162
B31: Femmes | C31: 33 | G31: =SUM(C31:F31) -> 33 | H31: =G31/$G$34 -> 0.38823529 | J31: Femmes | K31: 25 | L31: 30 | M31: 14 | N31: 27 | O31: =SUM(K31:N31) -> 96 | P31: =O31/$O$34 -> 0.32323232
B32: Enfants | C32: 5 | G32: =SUM(C32:F32) -> 5 | H32: =G32/$G$34 -> 0.058823529 | J32: Enfants | K32: 6 | L32: 6 | M32: 3 | N32: 3 | O32: =SUM(K32:N32) -> 18 | P32: =O32/$O$34 -> 0.060606061
B34: TOTAL | C34: =SUM(C30:C32) -> 85 | D34: =SUM(D30:D32) -> 0 | E34: =SUM(E30:E32) -> 0 | F34: =SUM(F30:F32) -> 0 | G34: =SUM(C34:F34) -> 85 | J34: TOTAL | K34: =SUM(K30:K32) -> 65 | L34: =SUM(L30:L32) -> 88 | M34: =SUM(M30:M32) -> 66 | N34: =SUM(N30:N32) -> 78 | O34: =SUM(K34:N34) -> 297
B35: Pourcentage | C35: =C34/$G$34 -> 1 | D35: =D34/$G$34 -> 0 | E35: =E34/$G$34 -> 0 | F35: =F34/$G$34 -> 0 | G35: =G34/G37 -> 0.13056836 | J35: Pourcentage | K35: =K34/$O$34 -> 0.21885522 | L35: =L34/$O$34 -> 0.2962963 | M35: =M34/$O$34 -> 0.22222222 | N35: =N34/$O$34 -> 0.26262626
G37: =SUM(G34,G17) -> 651
B39: VV, AVE BEL AIR
C40: Toutes directions | G40: Total | H40: Pourcentage
C41: 7h30-7h45 | D41: 7h45-8h00 | E41: 8h00-8h15 | F41: 8h15-8h30
B42: Vélo | C42: =C6+C23 -> 388 | G42: =SUM(C42:F42) -> 388 | H42: =G42/$G$53 -> 0.59600614
B43: VAE | C43: =C7+C24 -> 263 | G43: =SUM(C43:F43) -> 263 | H43: =G43/$G$53 -> 0.40399386
B45: Conformistes | C45: =C9+C26 -> 351.54 | G45: =SUM(C45:F45) -> 351.54 | H45: =G45/$G$53 -> 0.54
B46: Opportunistes | C46: =C10+C27 -> 240.87 | G46: =SUM(C46:F46) -> 240.87 | H46: =G46/$G$53 -> 0.37
B47: Imprudents | C47: =C11+C28 -> 58.59 | G47: =SUM(C47:F47) -> 58.59 | H47: =G47/$G$53 -> 0.09
B49: Hommes | C49: =C13+C30 -> 334 | G49: =SUM(C49:F49) -> 334 | H49: =G49/$G$53 -> 0.51305684
B50: Femmes | C50: =C14+C31 -> 250 | G50: =SUM(C50:F50) -> 250 | H50: =G50/$G$53 -> 0.38402458
B51: Enfants | C51: =C15+C32 -> 67 | G51: =SUM(C51:F51) -> 67 | H51: =G51/$G$53 -> 0.10291859
B53: TOTAL | C53: =SUM(C49:C51) -> 651 | D53: =SUM(D49:D51) -> 0 | E53: =SUM(E49:E51) -> 0 | F53: =SUM(F49:F51) -> 0 | G53: =SUM(C53:F53) -> 651
...

Sheet VV, FRANK THOMAS
B1: MATIN | J1: SOIR
B3: VV, AVE FRANK THOMAS | J3: VV, AVE FRANK THOMAS
C4: Vers VILLE | G4: Total | H4: Pourcentage | K4: Vers VILLE | O4: Total | P4: Pourcentage
C5: 7h30-7h45 | D5: 7h45-8h00 | E5: 8h00-8h15 | F5: 8h15-8h30 | K5: 17h00-17h15 | L5: 17h15-17h30 | M5: 17h30-17h45 | N5: 17h45-18h00
B6: Vélo | C6: 52 | D6: 72 | E6: 76 | F6: 84 | G6: =SUM(C6:F6) -> 284 | H6: =G6/$G$17 -> 0.56349206 | J6: Vélo | K6: 14 | L6: 33 | M6: 20 | N6: 26 | O6: =SUM(K6:N6) -> 93 | P6: =O6/$O$17 -> 0.78813559
B7: VAE | C7: 40 | D7: 58 | E7: 61 | F7: 61 | G7: =SUM(C7:F7) -> 220 | H7: =G7/$G$17 -> 0.43650794 | J7: VAE | K7: 5 | L7: 5 | M7: 6 | N7: 9 | O7: =SUM(K7:N7) -> 25 | P7: =O7/$O$17 -> 0.21186441
B9: Conformistes | C9: 0 | D9: 0 | E9: 0 | F9: 0 | G9: =SUM(C9:F9) -> 0 | H9: =G9/$G$17 -> 0 | J9: Conformistes | K9: 18 | L9: 37 | M9: 23 | N9: 31 | O9: =SUM(K9:N9) -> 109 | P9: =O9/$O$17 -> 0.92372881
B10: Opportunistes | C10: 31 | D10: 22 | E10: 38 | F10: 26 | G10: =SUM(C10:F10) -> 117 | H10: =G10/$G$17 -> 0.23214286 | J10: Opportunistes | K10: 0 | L10: 1 | M10: 2 | N10: 1 | O10: =SUM(K10:N10) -> 4 | P10: =O10/$O$17 -> 0.033898305
B11: Imprudents | C11: 1 | D11: 1 | E11: 0 | F11: 0 | G11: =SUM(C11:F11) -> 2 | H11: =G11/$G$17 -> 0.003968254 | J11: Imprudents | K11: 1 | L11: 0 | M11: 1 | N11: 3 | O11: =SUM(K11:N11) -> 5 | P11: =O11/$O$17 -> 0.042372881
B13: Hommes | C13: 56 | D13: 66 | E13: 77 | F13: 76 | G13: =SUM(C13:F13) -> 275 | H13: =G13/$G$17 -> 0.54563492 | J13: Hommes | K13: 12 | L13: 23 | M13: 15 | N13: 20 | O13: =SUM(K13:N13) -> 70 | P13: =O13/$O$17 -> 0.59322034
B14: Femmes | C14: 32 | D14: 52 | E14: 52 | F14: 59 | G14: =SUM(C14:F14) -> 195 | H14: =G14/$G$17 -> 0.38690476 | J14: Femmes | K14: 7 | L14: 14 | M14: 9 | N14: 15 | O14: =SUM(K14:N14) -> 45 | P14: =O14/$O$17 -> 0.38135593
B15: Enfants | C15: 4 | D15: 12 | E15: 8 | F15: 10 | G15: =SUM(C15:F15) -> 34 | H15: =G15/$G$17 -> 0.067460317 | J15: Enfants | K15: 0 | L15: 1 | M15: 2 | N15: 0 | O15: =SUM(K15:N15) -> 3 | P15: =O15/$O$17 -> 0.025423729
B17: TOTAL | C17: =SUM(C13:C15) -> 92 | D17: =SUM(D13:D15) -> 130 | E17: =SUM(E13:E15) -> 137 | F17: =SUM(F13:F15) -> 145 | G17: =SUM(C17:F17) -> 504 | J17: TOTAL | K17: =SUM(K13:K15) -> 19 | L17: =SUM(L13:L15) -> 38 | M17: =SUM(M13:M15) -> 26 | N17: =SUM(N13:N15) -> 35 | O17: =SUM(K17:N17) -> 118
B18: Pourcentage | C18: =C17/$G$17 -> 0.18253968 | D18: =D17/$G$17 -> 0.25793651 | E18: =E17/$G$17 -> 0.2718254 | F18: =F17/$G$17 -> 0.28769841 | J18: Pourcentage | K18: =K17/$O$17 -> 0.16101695 | L18: =L17/$O$17 -> 0.3220339 | M18: =M17/$O$17 -> 0.22033898 | N18: =N17/$O$17 -> 0.29661017
B20: VV, AVE FRANK THOMAS | J20: VV, AVE FRANK THOMAS
C21: Vers ANNEMASSE | G21: Total | H21: Pourcentage | K21: Vers ANNEMASSE | O21: Total | P21: Pourcentage
C22: 7h30-7h45 | D22: 7h45-8h00 | E22: 8h00-8h15 | F22: 8h15-8h30 | K22: 17h00-17h15 | L22: 17h15-17h30 | M22: 17h30-17h45 | N22: 17h45-18h00
B23: Vélo | C23: 7 | D23: 29 | E23: 13 | F23: 11 | G23: =SUM(C23:F23) -> 60 | H23: =G23/$G$34 -> 0.54054054 | J23: Vélo | K23: 21 | L23: 28 | M23: 21 | N23: 56 | O23: =SUM(K23:N23) -> 126 | P23: =O23/$O$34 -> 0.62686567
B24: VAE | C24: 8 | D24: 20 | E24: 9 | F24: 14 | G24: =SUM(C24:F24) -> 51 | H24: =G24/$G$34 -> 0.45945946 | J24: VAE | K24: 18 | L24: 17 | M24: 19 | N24: 21 | O24: =SUM(K24:N24) -> 75 | P24: =O24/$O$34 -> 0.37313433
B26: Conformistes | C26: 13 | D26: 32 | E26: 18 | F26: 19 | G26: =SUM(C26:F26) -> 82 | H26: =G26/$G$34 -> 0.73873874 | J26: Conformistes | K26: 30 | L26: 42 | M26: 35 | N26: 69 | O26: =SUM(K26:N26) -> 176 | P26: =O26/$O$34 -> 0.87562189
B27: Opportunistes | C27: 3 | D27: 12 | E27: 3 | F27: 5 | G27: =SUM(C27:F27) -> 23 | H27: =G27/$G$34 -> 0.20720721 | J27: Opportunistes | K27: 9 | L27: 3 | M27: 5 | N27: 6 | O27: =SUM(K27:N27) -> 23 | P27: =O27/$O$34 -> 0.11442786
B28: Imprudents | C28: 0 | D28: 0 | E28: 0 | F28: 0 | G28: =SUM(C28:F28) -> 0 | H28: =G28/$G$34 -> 0 | J28: Imprudents | K28: 0 | L28: 0 | M28: 0 | N28: 2 | O28: =SUM(K28:N28) -> 2 | P28: =O28/$O$34 -> 0.0099502488
B30: Hommes | C30: 7 | D30: 22 | E30: 11 | F30: 16 | G30: =SUM(C30:F30) -> 56 | H30: =G30/$G$34 -> 0.5045045 | J30: Hommes | K30: 22 | L30: 22 | M30: 27 | N30: 50 | O30: =SUM(K30:N30) -> 121 | P30: =O30/$O$34 -> 0.60199005
B31: Femmes | C31: 8 | D31: 20 | E31: 10 | F31: 8 | G31: =SUM(C31:F31) -> 46 | H31: =G31/$G$34 -> 0.41441441 | J31: Femmes | K31: 17 | L31: 21 | M31: 13 | N31: 26 | O31: =SUM(K31:N31) -> 77 | P31: =O31/$O$34 -> 0.38308458
B32: Enfants | C32: 0 | D32: 7 | E32: 1 | F32: 1 | G32: =SUM(C32:F32) -> 9 | H32: =G32/$G$34 -> 0.081081081 | J32: Enfants | K32: 0 | L32: 2 | M32: 0 | N32: 1 | O32: =SUM(K32:N32) -> 3 | P32: =O32/$O$34 -> 0.014925373
B34: TOTAL | C34: =SUM(C30:C32) -> 15 | D34: =SUM(D30:D32) -> 49 | E34: =SUM(E30:E32) -> 22 | F34: =SUM(F30:F32) -> 25 | G34: =SUM(C34:F34) -> 111 | J34: TOTAL | K34: =SUM(K30:K32) -> 39 | L34: =SUM(L30:L32) -> 45 | M34: =SUM(M30:M32) -> 40 | N34: =SUM(N30:N32) -> 77 | O34: =SUM(K34:N34) -> 201
B35: Pourcentage | C35: =C34/$G$34 -> 0.13513514 | D35: =D34/$G$34 -> 0.44144144 | E35: =E34/$G$34 -> 0.1981982 | F35: =F34/$G$34 -> 0.22522523 | J35: Pourcentage | K35: =K34/$O$34 -> 0.19402985 | L35: =L34/$O$34 -> 0.2238806 | M35: =M34/$O$34 -> 0.19900498 | N35: =N34/$O$34 -> 0.38308458

Sheet TRANCHEES
B1: MATIN | J1: SOIR
B3: BLD DES TRANCHEES | J3: BLD DES TRANCHEES
C4: Vers VILLE | G4: Total | H4: Pourcentage | K4: Vers VILLE | O4: Total | P4: Pourcentage
C5: 7h30-7h45 | D5: 7h45-8h00 | E5: 8h00-8h15 | F5: 8h15-8h30 | K5: 17h00-17h15 | L5: 17h15-17h30 | M5: 17h30-17h45 | N5: 17h45-18h00
B6: Vélo | C6: 52 | D6: 43 | E6: 56 | F6: 64 | G6: =SUM(C6:F6) -> 215 | H6: =G6/$G$17 -> 0.72390572 | J6: Vélo | K6: 18 | L6: 24 | M6: 30 | N6: 33 | O6: =SUM(K6:N6) -> 105 | P6: =O6/$O$17 -> 0.65217391
B7: VAE | C7: 22 | D7: 19 | E7: 26 | F7: 15 | G7: =SUM(C7:F7) -> 82 | H7: =G7/$G$17 -> 0.27609428 | J7: VAE | K7: 9 | L7: 17 | M7: 13 | N7: 17 | O7: =SUM(K7:N7) -> 56 | P7: =O7/$O$17 -> 0.34782609
B9: Conformistes | C9: 60 | D9: 49 | E9: 66 | F9: 65 | G9: =SUM(C9:F9) -> 240 | H9: =G9/$G$17 -> 0.80808081 | J9: Conformistes | K9: 15 | L9: 34 | M9: 35 | N9: 41 | O9: =SUM(K9:N9) -> 125 | P9: =O9/$O$17 -> 0.77639752
B10: Opportunistes | C10: 11 | D10: 11 | E10: 13 | F10: 13 | G10: =SUM(C10:F10) -> 48 | H10: =G10/$G$17 -> 0.16161616 | J10: Opportunistes | K10: 7 | L10: 0 | M10: 2 | N10: 1 | O10: =SUM(K10:N10) -> 10 | P10: =O10/$O$17 -> 0.062111801
B11: Imprudents | C11: 3 | D11: 2 | E11: 3 | F11: 1 | G11: =SUM(C11:F11) -> 9 | H11: =G11/$G$17 -> 0.03030303 | J11: Imprudents | K11: 5 | L11: 7 | M11: 6 | N11: 8 | O11: =SUM(K11:N11) -> 26 | P11: =O11/$O$17 -> 0.16149068
B13: Hommes | C13: 40 | D13: 38 | E13: 45 | F13: 45 | G13: =SUM(C13:F13) -> 168 | H13: =G13/$G$17 -> 0.56565657 | J13: Hommes | K13: 17 | L13: 22 | M13: 23 | N13: 24 | O13: =SUM(K13:N13) -> 86 | P13: =O13/$O$17 -> 0.53416149
B14: Femmes | C14: 31 | D14: 18 | E14: 34 | F14: 33 | G14: =SUM(C14:F14) -> 116 | H14: =G14/$G$17 -> 0.39057239 | J14: Femmes | K14: 10 | L14: 19 | M14: 19 | N14: 23 | O14: =SUM(K14:N14) -> 71 | P14: =O14/$O$17 -> 0.44099379
B15: Enfants | C15: 3 | D15: 6 | E15: 3 | F15: 1 | G15: =SUM(C15:F15) -> 13 | H15: =G15/$G$17 -> 0.043771044 | J15: Enfants | K15: 0 | L15: 0 | M15: 1 | N15: 3 | O15: =SUM(K15:N15) -> 4 | P15: =O15/$O$17 -> 0.02484472
B17: TOTAL | C17: =SUM(C13:C15) -> 74 | D17: =SUM(D13:D15) -> 62 | E17: =SUM(E13:E15) -> 82 | F17: =SUM(F13:F15) -> 79 | G17: =SUM(C17:F17) -> 297 | J17: TOTAL | K17: =SUM(K13:K15) -> 27 | L17: =SUM(L13:L15) -> 41 | M17: =SUM(M13:M15) -> 43 | N17: =SUM(N13:N15) -> 50 | O17: =SUM(K17:N17) -> 161
B18: Pourcentage | C18: =C17/$G$17 -> 0.24915825 | D18: =D17/$G$17 -> 0.20875421 | E18: =E17/$G$17 -> 0.27609428 | F18: =F17/$G$17 -> 0.26599327 | J18: Pourcentage | K18: =K17/$O$17 -> 0.16770186 | L18: =L17/$O$17 -> 0.25465839 | M18: =M17/$O$17 -> 0.26708075 | N18: =N17/$O$17 -> 0.31055901
B20: BLD DES TRANCHEES | J20: BLD DES TRANCHEES
C21: Vers ANNEMASSE | G21: Total | H21: Pourcentage | K21: Vers ANNEMASSE | O21: Total | P21: Pourcentage
C22: 7h30-7h45 | D22: 7h45-8h00 | E22: 8h00-8h15 | F22: 8h15-8h30 | K22: 17h00-17h15 | L22: 17h15-17h30 | M22: 17h30-17h45 | N22: 17h45-18h00
B23: Vélo | C23: 3 | D23: 4 | E23: 1 | F23: 3 | G23: =SUM(C23:F23) -> 11 | H23: =G23/$G$34 -> 0.57894737 | J23: Vélo | K23: 6 | L23: 4 | M23: 15 | N23: 15 | O23: =SUM(K23:N23) -> 40 | P23: =O23/$O$34 -> 0.66666667
B24: VAE | C24: 2 | D24: 0 | E24: 3 | F24: 3 | G24: =SUM(C24:F24) -> 8 | H24: =G24/$G$34 -> 0.42105263 | J24: VAE | K24: 4 | L24: 5 | M24: 3 | N24: 8 | O24: =SUM(K24:N24) -> 20 | P24: =O24/$O$34 -> 0.33333333
B26: Conformistes | C26: 6 | D26: 2 | E26: 3 | F26: 6 | G26: =SUM(C26:F26) -> 17 | H26: =G26/$G$34 -> 0.89473684 | J26: Conformistes | K26: 7 | L26: 6 | M26: 10 | N26: 14 | O26: =SUM(K26:N26) -> 37 | P26: =O26/$O$34 -> 0.61666667
B27: Opportunistes | C27: 0 | D27: 0 | E27: 0 | F27: 0 | G27: =SUM(C27:F27) -> 0 | H27: =G27/$G$34 -> 0 | J27: Opportunistes | K27: 0 | L27: 2 | M27: 1 | N27: 2 | O27: =SUM(K27:N27) -> 5 | P27: =O27/$O$34 -> 0.083333333
B28: Imprudents | C28: 0 | D28: 2 | E28: 2 | F28: 0 | G28: =SUM(C28:F28) -> 4 | H28: =G28/$G$34 -> 0.21052632 | J28: Imprudents | K28: 3 | L28: 1 | M28: 7 | N28: 7 | O28: =SUM(K28:N28) -> 18 | P28: =O28/$O$34 -> 0.3
B30: Hommes | C30: 4 | D30: 2 | E30: 2 | F30: 3 | G30: =SUM(C30:F30) -> 11 | H30: =G30/$G$34 -> 0.57894737 | J30: Hommes | K30: 8 | L30: 5 | M30: 10 | N30: 13 | O30: =SUM(K30:N30) -> 36 | P30: =O30/$O$34 -> 0.6
B31: Femmes | C31: 1 | D31: 2 | E31: 2 | F31: 3 | G31: =SUM(C31:F31) -> 8 | H31: =G31/$G$34 -> 0.42105263 | J31: Femmes | K31: 2 | L31: 4 | M31: 8 | N31: 9 | O31: =SUM(K31:N31) -> 23 | P31: =O31/$O$34 -> 0.38333333
B32: Enfants | C32: 0 | D32: 0 | E32: 0 | F32: 0 | G32: =SUM(C32:F32) -> 0 | H32: =G32/$G$34 -> 0 | J32: Enfants | K32: 0 | L32: 0 | M32: 0 | N32: 1 | O32: =SUM(K32:N32) -> 1 | P32: =O32/$O$34 -> 0.016666667
B34: TOTAL | C34: =SUM(C30:C32) -> 5 | D34: =SUM(D30:D32) -> 4 | E34: =SUM(E30:E32) -> 4 | F34: =SUM(F30:F32) -> 6 | G34: =SUM(C34:F34) -> 19 | J34: TOTAL | K34: =SUM(K30:K32) -> 10 | L34: =SUM(L30:L32) -> 9 | M34: =SUM(M30:M32) -> 18 | N34: =SUM(N30:N32) -> 23 | O34: =SUM(K34:N34) -> 60
B35: Pourcentage | C35: =C34/$G$34 -> 0.26315789 | D35: =D34/$G$34 -> 0.21052632 | E35: =E34/$G$34 -> 0.21052632 | F35: =F34/$G$34 -> 0.31578947 | J35: Pourcentage | K35: =K34/$O$34 -> 0.16666667 | L35: =L34/$O$34 -> 0.15 | M35: =M34/$O$34 -> 0.3 | N35: =N34/$O$34 -> 0.38333333

Sheet TOTAL
B1: MATIN | J1: SOIR
C4: Tous sens confondus | G4: Total | H4: Pourcentage | K4: Tous sens confondus | O4: Total | P4: Pourcentage
C5: 7h30-7h45 | D5: 7h45-8h00 | E5: 8h00-8h15 | F5: 8h15-8h30 | K5: 17h00-17h15 | L5: 17h15-17h30 | M5: 17h30-17h45 | N5: 17h45-18h00
B6: Vélo | C6: ='XXXI DECEMBRE'!C6+ARQUEBUSE!C6+ARQUEBUSE!C23+'GEORGES-FAVON'!C6+'GEORGES-FAVON'!C23+'F HODLER'!C6+'F HODLER'!C23+'F HODLER'!C40+'PICTET ROCHEMONT'!C6+'PICTET ROCHEMONT'!C23+'VV, BEL AIR'!C6+'VV, BEL AIR'!C23+'VV, FRANK THOMAS'!C6+'VV, FRANK THOMAS'!C23+TRANCHEES!C6+TRANCHEES!C23 -> 628 | D6: ='XXXI DECEMBRE'!D6+ARQUEBUSE!D6+ARQUEBUSE!D23+'GEORGES-FAVON'!D6+'GEORGES-FAVON'!D23+'F HODLER'!D6+'F HODLER'!D23+'F HODLER'!D40+'PICTET ROCHEMONT'!D6+'PICTET ROCHEMONT'!D23+'VV, BEL AIR'!D6+'VV, BEL AIR'!D23+'VV, FRANK THOMAS'!D6+'VV, FRANK THOMAS'!D23+TRANCHEES!D6+TRANCHEES!D23 -> 266 | E6: ='XXXI DECEMBRE'!E6+ARQUEBUSE!E6+ARQUEBUSE!E23+'GEORGES-FAVON'!E6+'GEORGES-FAVON'!E23+'F HODLER'!E6+'F HODLER'!E23+'F HODLER'!E40+'PICTET ROCHEMONT'!E6+'PICTET ROCHEMONT'!E23+'VV, BEL AIR'!E6+'VV, BEL AIR'!E23+'VV, FRANK THOMAS'!E6+'VV, FRANK THOMAS'!E23+TRANCHEES!E6+TRANCHEES!E23 -> 247 | F6: ='XXXI DECEMBRE'!F6+ARQUEBUSE!F6+ARQUEBUSE!F23+'GEORGES-FAVON'!F6+'GEORGES-FAVON'!F23+'F HODLER'!F6+'F HODLER'!F23+'F HODLER'!F40+'PICTET ROCHEMONT'!F6+'PICTET ROCHEMONT'!F23+'VV, BEL AIR'!F6+'VV, BEL AIR'!F23+'VV, FRANK THOMAS'!F6+'VV, FRANK THOMAS'!F23+TRANCHEES!F6+TRANCHEES!F23 -> 269 | G6: =SUM(C6:F6) -> 1410 | H6: =G6/$G$17 -> 0.63772049 | J6: Vélo | K6: ='XXXI DECEMBRE'!K6+ARQUEBUSE!K6+ARQUEBUSE!K23+'GEORGES-FAVON'!K6+'GEORGES-FAVON'!K23+'F HODLER'!K6+'F HODLER'!K23+'F HODLER'!K40+'PICTET ROCHEMONT'!K6+'PICTET ROCHEMONT'!K23+'VV, BEL AIR'!K6+'VV, BEL AIR'!K23+'VV, FRANK THOMAS'!K6+'VV, FRANK THOMAS'!K23+TRANCHEES!K6+TRANCHEES!K23 -> 249 | L6: ='XXXI DECEMBRE'!L6+ARQUEBUSE!L6+ARQUEBUSE!L23+'GEORGES-FAVON'!L6+'GEORGES-FAVON'!L23+'F HODLER'!L6+'F HODLER'!L23+'F HODLER'!L40+'PICTET ROCHEMONT'!L6+'PICTET ROCHEMONT'!L23+'VV, BEL AIR'!L6+'VV, BEL AIR'!L23+'VV, FRANK THOMAS'!L6+'VV, FRANK THOMAS'!L23+TRANCHEES!L6+TRANCHEES!L23 -> 272 | M6: ='XXXI DECEMBRE'!M6+ARQUEBUSE!M6+ARQUEBUSE!M23+'GEORGES-FAVON'!M6+'GEORGES-FAVON'!M23+'F HODLER'!M6+'F HODLER'!M23+'F HODLER'!M40+'PICTET ROCHEMONT'!M6+'PICTET ROCHEMONT'!M23+'VV, BEL AIR'!M6+'VV, BEL AIR'!M23+'VV, FRANK THOMAS'!M6+'VV, FRANK THOMAS'!M23+TRANCHEES!M6+TRANCHEES!M23 -> 291 | N6: ='XXXI DECEMBRE'!N6+ARQUEBUSE!N6+ARQUEBUSE!N23+'GEORGES-FAVON'!N6+'GEORGES-FAVON'!N23+'F HODLER'!N6+'F HODLER'!N23+'F HODLER'!N40+'PICTET ROCHEMONT'!N6+'PICTET ROCHEMONT'!N23+'VV, BEL AIR'!N6+'VV, BEL AIR'!N23+'VV, FRANK THOMAS'!N6+'VV, FRANK THOMAS'!N23+TRANCHEES!N6+TRANCHEES!N23 -> 358 | O6: =SUM(K6:N6) -> 1170 | P6: =O6/$O$17 -> 0.7027027
B7: VAE | C7: ='XXXI DECEMBRE'!C7+ARQUEBUSE!C7+ARQUEBUSE!C24+'GEORGES-FAVON'!C7+'GEORGES-FAVON'!C24+'F HODLER'!C7+'F HODLER'!C24+'F HODLER'!C41+'PICTET ROCHEMONT'!C7+'PICTET ROCHEMONT'!C24+'VV, BEL AIR'!C7+'VV, BEL AIR'!C24+'VV, FRANK THOMAS'!C7+'VV, FRANK THOMAS'!C24+TRANCHEES!C7+TRANCHEES!C24 -> 388 | D7: ='XXXI DECEMBRE'!D7+ARQUEBUSE!D7+ARQUEBUSE!D24+'GEORGES-FAVON'!D7+'GEORGES-FAVON'!D24+'F HODLER'!D7+'F HODLER'!D24+'F HODLER'!D41+'PICTET ROCHEMONT'!D7+'PICTET ROCHEMONT'!D24+'VV, BEL AIR'!D7+'VV, BEL AIR'!D24+'VV, FRANK THOMAS'!D7+'VV, FRANK THOMAS'!D24+TRANCHEES!D7+TRANCHEES!D24 -> 126 | E7: ='XXXI DECEMBRE'!E7+ARQUEBUSE!E7+ARQUEBUSE!E24+'GEORGES-FAVON'!E7+'GEORGES-FAVON'!E24+'F HODLER'!E7+'F HODLER'!E24+'F HODLER'!E41+'PICTET ROCHEMONT'!E7+'PICTET ROCHEMONT'!E24+'VV, BEL AIR'!E7+'VV, BEL AIR'!E24+'VV, FRANK THOMAS'!E7+'VV, FRANK THOMAS'!E24+TRANCHEES!E7+TRANCHEES!E24 -> 147 | F7: ='XXXI DECEMBRE'!F7+ARQUEBUSE!F7+ARQUEBUSE!F24+'GEORGES-FAVON'!F7+'GEORGES-FAVON'!F24+'F HODLER'!F7+'F HODLER'!F24+'F HODLER'!F41+'PICTET ROCHEMONT'!F7+'PICTET ROCHEMONT'!F24+'VV, BEL AIR'!F7+'VV, BEL AIR'!F24+'VV, FRANK THOMAS'!F7+'VV, FRANK THOMAS'!F24+TRANCHEES!F7+TRANCHEES!F24 -> 140 | G7: =SUM(C7:F7) -> 801 | H7: =G7/$G$17 -> 0.36227951 | J7: VAE | K7: ='XXXI DECEMBRE'!K7+ARQUEBUSE!K7+ARQUEBUSE!K24+'GEORGES-FAVON'!K7+'GEORGES-FAVON'!K24+'F HODLER'!K7+'F HODLER'!K24+'F HODLER'!K41+'PICTET ROCHEMONT'!K7+'PICTET ROCHEMONT'!K24+'VV, BEL AIR'!K7+'VV, BEL AIR'!K24+'VV, FRANK THOMAS'!K7+'VV, FRANK THOMAS'!K24+TRANCHEES!K7+TRANCHEES!K24 -> 116 | L7: ='XXXI DECEMBRE'!L7+ARQUEBUSE!L7+ARQUEBUSE!L24+'GEORGES-FAVON'!L7+'GEORGES-FAVON'!L24+'F HODLER'!L7+'F HODLER'!L24+'F HODLER'!L41+'PICTET ROCHEMONT'!L7+'PICTET ROCHEMONT'!L24+'VV, BEL AIR'!L7+'VV, BEL AIR'!L24+'VV, FRANK THOMAS'!L7+'VV, FRANK THOMAS'!L24+TRANCHEES!L7+TRANCHEES!L24 -> 124 | M7: ='XXXI DECEMBRE'!M7+ARQUEBUSE!M7+ARQUEBUSE!M24+'GEORGES-FAVON'!M7+'GEORGES-FAVON'!M24+'F HODLER'!M7+'F HODLER'!M24+'F HODLER'!M41+'PICTET ROCHEMONT'!M7+'PICTET ROCHEMONT'!M24+'VV, BEL AIR'!M7+'VV, BEL AIR'!M24+'VV, FRANK THOMAS'!M7+'VV, FRANK THOMAS'!M24+TRANCHEES!M7+TRANCHEES!M24 -> 112 | N7: ='XXXI DECEMBRE'!N7+ARQUEBUSE!N7+ARQUEBUSE!N24+'GEORGES-FAVON'!N7+'GEORGES-FAVON'!N24+'F HODLER'!N7+'F HODLER'!N24+'F HODLER'!N41+'PICTET ROCHEMONT'!N7+'PICTET ROCHEMONT'!N24+'VV, BEL AIR'!N7+'VV, BEL AIR'!N24+'VV, FRANK THOMAS'!N7+'VV, FRANK THOMAS'!N24+TRANCHEES!N7+TRANCHEES!N24 -> 142 | O7: =SUM(K7:N7) -> 494 | P7: =O7/$O$17 -> 0.2966967
A9: ! | B9: Conformistes | C9: ='XXXI DECEMBRE'!C9+ARQUEBUSE!C9+ARQUEBUSE!C26+'GEORGES-FAVON'!C9+'GEORGES-FAVON'!C26+'F HODLER'!C9+'F HODLER'!C26+'F HODLER'!C43+'PICTET ROCHEMONT'!C9+'PICTET ROCHEMONT'!C26+'VV, BEL AIR'!C9+'VV, BEL AIR'!C26+'VV, FRANK THOMAS'!C9+'VV, FRANK THOMAS'!C26+TRANCHEES!C9+TRANCHEES!C26 -> 528.54 | D9: ='XXXI DECEMBRE'!D9+ARQUEBUSE!D9+ARQUEBUSE!D26+'GEORGES-FAVON'!D9+'GEORGES-FAVON'!D26+'F HODLER'!D9+'F HODLER'!D26+'F HODLER'!D43+'PICTET ROCHEMONT'!D9+'PICTET ROCHEMONT'!D26+'VV, BEL AIR'!D9+'VV, BEL AIR'!D26+'VV, FRANK THOMAS'!D9+'VV, FRANK THOMAS'!D26+TRANCHEES!D9+TRANCHEES!D26 -> 116 | E9: ='XXXI DECEMBRE'!E9+ARQUEBUSE!E9+ARQUEBUSE!E26+'GEORGES-FAVON'!E9+'GEORGES-FAVON'!E26+'F HODLER'!E9+'F HODLER'!E26+'F HODLER'!E43+'PICTET ROCHEMONT'!E9+'PICTET ROCHEMONT'!E26+'VV, BEL AIR'!E9+'VV, BEL AIR'!E26+'VV, FRANK THOMAS'!E9+'VV, FRANK THOMAS'!E26+TRANCHEES!E9+TRANCHEES!E26 -> 129 | F9: ='XXXI DECEMBRE'!F9+ARQUEBUSE!F9+ARQUEBUSE!F26+'GEORGES-FAVON'!F9+'GEORGES-FAVON'!F26+'F HODLER'!F9+'F HODLER'!F26+'F HODLER'!F43+'PICTET ROCHEMONT'!F9+'PICTET ROCHEMONT'!F26+'VV, BEL AIR'!F9+'VV, BEL AIR'!F26+'VV, FRANK THOMAS'!F9+'VV, FRANK THOMAS'!F26+TRANCHEES!F9+TRANCHEES!F26 -> 133 | G9: =SUM(C9:F9) -> 906.54 | H9: =G9/$G$20 -> 0.58828034 | I9: ! | J9: Conformistes | K9: ='XXXI DECEMBRE'!K9+ARQUEBUSE!K9+ARQUEBUSE!K26+'GEORGES-FAVON'!K9+'GEORGES-FAVON'!K26+'F HODLER'!K9+'F HODLER'!K26+'F HODLER'!K43+'PICTET ROCHEMONT'!K9+'PICTET ROCHEMONT'!K26+'VV, BEL AIR'!K9+'VV, BEL AIR'!K26+'VV, FRANK THOMAS'!K9+'VV, FRANK THOMAS'!K26+TRANCHEES!K9+TRANCHEES!K26 -> 467.1 | L9: ='XXXI DECEMBRE'!L9+ARQUEBUSE!L9+ARQUEBUSE!L26+'GEORGES-FAVON'!L9+'GEORGES-FAVON'!L26+'F HODLER'!L9+'F HODLER'!L26+'F HODLER'!L43+'PICTET ROCHEMONT'!L9+'PICTET ROCHEMONT'!L26+'VV, BEL AIR'!L9+'VV, BEL AIR'!L26+'VV, FRANK THOMAS'!L9+'VV, FRANK THOMAS'!L26+TRANCHEES!L9+TRANCHEES!L26 -> 180 | M9: ='XXXI DECEMBRE'!M9+ARQUEBUSE!M9+ARQUEBUSE!M26+'GEORGES-FAVON'!M9+'GEORGES-FAVON'!M26+'F HODLER'!M9+'F HODLER'!M26+'F HODLER'!M43+'PICTET ROCHEMONT'!M9+'PICTET ROCHEMONT'!M26+'VV, BEL AIR'!M9+'VV, BEL AIR'!M26+'VV, FRANK THOMAS'!M9+'VV, FRANK THOMAS'!M26+TRANCHEES!M9+TRANCHEES!M26 -> 161 | N9: ='XXXI DECEMBRE'!N9+ARQUEBUSE!N9+ARQUEBUSE!N26+'GEORGES-FAVON'!N9+'GEORGES-FAVON'!N26+'F HODLER'!N9+'F HODLER'!N26+'F HODLER'!N43+'PICTET ROCHEMONT'!N9+'PICTET ROCHEMONT'!N26+'VV, BEL AIR'!N9+'VV, BEL AIR'!N26+'VV, FRANK THOMAS'!N9+'VV, FRANK THOMAS'!N26+TRANCHEES!N9+TRANCHEES!N26 -> 230 | O9: =SUM(K9:N9) -> 1038.1 | P9: =O9/$O$20 -> 0.70763463
B10: Opportunistes | C10: ='XXXI DECEMBRE'!C10+ARQUEBUSE!C10+ARQUEBUSE!C27+'GEORGES-FAVON'!C10+'GEORGES-FAVON'!C27+'F HODLER'!C10+'F HODLER'!C27+'F HODLER'!C44+'PICTET ROCHEMONT'!C10+'PICTET ROCHEMONT'!C27+'VV, BEL AIR'!C10+'VV, BEL AIR'!C27+'VV, FRANK THOMAS'!C10+'VV, FRANK THOMAS'!C27+TRANCHEES!C10+TRANCHEES!C27 -> 372.87 | D10: ='XXXI DECEMBRE'!D10+ARQUEBUSE!D10+ARQUEBUSE!D27+'GEORGES-FAVON'!D10+'GEORGES-FAVON'!D27+'F HODLER'!D10+'F HODLER'!D27+'F HODLER'!D44+'PICTET ROCHEMONT'!D10+'PICTET ROCHEMONT'!D27+'VV, BEL AIR'!D10+'VV, BEL AIR'!D27+'VV, FRANK THOMAS'!D10+'VV, FRANK THOMAS'!D27+TRANCHEES!D10+TRANCHEES!D27 -> 58 | E10: ='XXXI DECEMBRE'!E10+ARQUEBUSE!E10+ARQUEBUSE!E27+'GEORGES-FAVON'!E10+'GEORGES-FAVON'!E27+'F HODLER'!E10+'F HODLER'!E27+'F HODLER'!E44+'PICTET ROCHEMONT'!E10+'PICTET ROCHEMONT'!E27+'VV, BEL AIR'!E10+'VV, BEL AIR'!E27+'VV, FRANK THOMAS'!E10+'VV, FRANK THOMAS'!E27+TRANCHEES!E10+TRANCHEES!E27 -> 72 | F10: ='XXXI DECEMBRE'!F10+ARQUEBUSE!F10+ARQUEBUSE!F27+'GEORGES-FAVON'!F10+'GEORGES-FAVON'!F27+'F HODLER'!F10+'F HODLER'!F27+'F HODLER'!F44+'PICTET ROCHEMONT'!F10+'PICTET ROCHEMONT'!F27+'VV, BEL AIR'!F10+'VV, BEL AIR'!F27+'VV, FRANK THOMAS'!F10+'VV, FRANK THOMAS'!F27+TRANCHEES!F10+TRANCHEES!F27 -> 52 | G10: =SUM(C10:F10) -> 554.87 | H10: =G10/$G$20 -> 0.36007138 | J10: Opportunistes | K10: ='XXXI DECEMBRE'!K10+ARQUEBUSE!K10+ARQUEBUSE!K27+'GEORGES-FAVON'!K10+'GEORGES-FAVON'!K27+'F HODLER'!K10+'F HODLER'!K27+'F HODLER'!K44+'PICTET ROCHEMONT'!K10+'PICTET ROCHEMONT'!K27+'VV, BEL AIR'!K10+'VV, BEL AIR'!K27+'VV, FRANK THOMAS'!K10+'VV, FRANK THOMAS'!K27+TRANCHEES!K10+TRANCHEES!K27 -> 176.75 | L10: ='XXXI DECEMBRE'!L10+ARQUEBUSE!L10+ARQUEBUSE!L27+'GEORGES-FAVON'!L10+'GEORGES-FAVON'!L27+'F HODLER'!L10+'F HODLER'!L27+'F HODLER'!L44+'PICTET ROCHEMONT'!L10+'PICTET ROCHEMONT'!L27+'VV, BEL AIR'!L10+'VV, BEL AIR'!L27+'VV, FRANK THOMAS'!L10+'VV, FRANK THOMAS'!L27+TRANCHEES!L10+TRANCHEES!L27 -> 49 | M10: ='XXXI DECEMBRE'!M10+ARQUEBUSE!M10+ARQUEBUSE!M27+'GEORGES-FAVON'!M10+'GEORGES-FAVON'!M27+'F HODLER'!M10+'F HODLER'!M27+'F HODLER'!M44+'PICTET ROCHEMONT'!M10+'PICTET ROCHEMONT'!M27+'VV, BEL AIR'!M10+'VV, BEL AIR'!M27+'VV, FRANK THOMAS'!M10+'VV, FRANK THOMAS'!M27+TRANCHEES!M10+TRANCHEES!M27 -> 53 | N10: ='XXXI DECEMBRE'!N10+ARQUEBUSE!N10+ARQUEBUSE!N27+'GEORGES-FAVON'!N10+'GEORGES-FAVON'!N27+'F HODLER'!N10+'F HODLER'!N27+'F HODLER'!N44+'PICTET ROCHEMONT'!N10+'PICTET ROCHEMONT'!N27+'VV, BEL AIR'!N10+'VV, BEL AIR'!N27+'VV, FRANK THOMAS'!N10+'VV, FRANK THOMAS'!N27+TRANCHEES!N10+TRANCHEES!N27 -> 60 | O10: =SUM(K10:N10) -> 338.75 | P10: =O10/$O$20 -> 0.23091343
B11: Imprudents | C11: ='XXXI DECEMBRE'!C11+ARQUEBUSE!C11+ARQUEBUSE!C28+'GEORGES-FAVON'!C11+'GEORGES-FAVON'!C28+'F HODLER'!C11+'F HODLER'!C28+'F HODLER'!C45+'PICTET ROCHEMONT'!C11+'PICTET ROCHEMONT'!C28+'VV, BEL AIR'!C11+'VV, BEL AIR'!C28+'VV, FRANK THOMAS'!C11+'VV, FRANK THOMAS'!C28+TRANCHEES!C11+TRANCHEES!C28 -> 67.59 | D11: ='XXXI DECEMBRE'!D11+ARQUEBUSE!D11+ARQUEBUSE!D28+'GEORGES-FAVON'!D11+'GEORGES-FAVON'!D28+'F HODLER'!D11+'F HODLER'!D28+'F HODLER'!D45+'PICTET ROCHEMONT'!D11+'PICTET ROCHEMONT'!D28+'VV, BEL AIR'!D11+'VV, BEL AIR'!D28+'VV, FRANK THOMAS'!D11+'VV, FRANK THOMAS'!D28+TRANCHEES!D11+TRANCHEES!D28 -> 6 | E11: ='XXXI DECEMBRE'!E11+ARQUEBUSE!E11+ARQUEBUSE!E28+'GEORGES-FAVON'!E11+'GEORGES-FAVON'!E28+'F HODLER'!E11+'F HODLER'!E28+'F HODLER'!E45+'PICTET ROCHEMONT'!E11+'PICTET ROCHEMONT'!E28+'VV, BEL AIR'!E11+'VV, BEL AIR'!E28+'VV, FRANK THOMAS'!E11+'VV, FRANK THOMAS'!E28+TRANCHEES!E11+TRANCHEES!E28 -> 5 | F11: ='XXXI DECEMBRE'!F11+ARQUEBUSE!F11+ARQUEBUSE!F28+'GEORGES-FAVON'!F11+'GEORGES-FAVON'!F28+'F HODLER'!F11+'F HODLER'!F28+'F HODLER'!F45+'PICTET ROCHEMONT'!F11+'PICTET ROCHEMONT'!F28+'VV, BEL AIR'!F11+'VV, BEL AIR'!F28+'VV, FRANK THOMAS'!F11+'VV, FRANK THOMAS'!F28+TRANCHEES!F11+TRANCHEES!F28 -> 1 | G11: =SUM(C11:F11) -> 79.59 | H11: =G11/$G$20 -> 0.05164828 | J11: Imprudents | K11: ='XXXI DECEMBRE'!K11+ARQUEBUSE!K11+ARQUEBUSE!K28+'GEORGES-FAVON'!K11+'GEORGES-FAVON'!K28+'F HODLER'!K11+'F HODLER'!K28+'F HODLER'!K45+'PICTET ROCHEMONT'!K11+'PICTET ROCHEMONT'!K28+'VV, BEL AIR'!K11+'VV, BEL AIR'!K28+'VV, FRANK THOMAS'!K11+'VV, FRANK THOMAS'!K28+TRANCHEES!K11+TRANCHEES!K28 -> 36.15 | L11: ='XXXI DECEMBRE'!L11+ARQUEBUSE!L11+ARQUEBUSE!L28+'GEORGES-FAVON'!L11+'GEORGES-FAVON'!L28+'F HODLER'!L11+'F HODLER'!L28+'F HODLER'!L45+'PICTET ROCHEMONT'!L11+'PICTET ROCHEMONT'!L28+'VV, BEL AIR'!L11+'VV, BEL AIR'!L28+'VV, FRANK THOMAS'!L11+'VV, FRANK THOMAS'!L28+TRANCHEES!L11+TRANCHEES!L28 -> 13 | M11: ='XXXI DECEMBRE'!M11+ARQUEBUSE!M11+ARQUEBUSE!M28+'GEORGES-FAVON'!M11+'GEORGES-FAVON'!M28+'F HODLER'!M11+'F HODLER'!M28+'F HODLER'!M45+'PICTET ROCHEMONT'!M11+'PICTET ROCHEMONT'!M28+'VV, BEL AIR'!M11+'VV, BEL AIR'!M28+'VV, FRANK THOMAS'!M11+'VV, FRANK THOMAS'!M28+TRANCHEES!M11+TRANCHEES!M28 -> 19 | N11: ='XXXI DECEMBRE'!N11+ARQUEBUSE!N11+ARQUEBUSE!N28+'GEORGES-FAVON'!N11+'GEORGES-FAVON'!N28+'F HODLER'!N11+'F HODLER'!N28+'F HODLER'!N45+'PICTET ROCHEMONT'!N11+'PICTET ROCHEMONT'!N28+'VV, BEL AIR'!N11+'VV, BEL AIR'!N28+'VV, FRANK THOMAS'!N11+'VV, FRANK THOMAS'!N28+TRANCHEES!N11+TRANCHEES!N28 -> 22 | O11: =SUM(K11:N11) -> 90.15 | P11: =O11/$O$20 -> 0.061451943
B13: Hommes | C13: ='XXXI DECEMBRE'!C13+ARQUEBUSE!C13+ARQUEBUSE!C30+'GEORGES-FAVON'!C13+'GEORGES-FAVON'!C30+'F HODLER'!C13+'F HODLER'!C30+'F HODLER'!C47+'PICTET ROCHEMONT'!C13+'PICTET ROCHEMONT'!C30+'VV, BEL AIR'!C30+'VV, BEL AIR'!C13+'VV, FRANK THOMAS'!C13+'VV, FRANK THOMAS'!C30+TRANCHEES!C13+TRANCHEES!C30 -> 546 | D13: ='XXXI DECEMBRE'!D13+ARQUEBUSE!D13+ARQUEBUSE!D30+'GEORGES-FAVON'!D13+'GEORGES-FAVON'!D30+'F HODLER'!D13+'F HODLER'!D30+'F HODLER'!D47+'PICTET ROCHEMONT'!D13+'PICTET ROCHEMONT'!D30+'VV, BEL AIR'!D30+'VV, BEL AIR'!D13+'VV, FRANK THOMAS'!D13+'VV, FRANK THOMAS'!D30+TRANCHEES!D13+TRANCHEES!D30 -> 210 | E13: ='XXXI DECEMBRE'!E13+ARQUEBUSE!E13+ARQUEBUSE!E30+'GEORGES-FAVON'!E13+'GEORGES-FAVON'!E30+'F HODLER'!E13+'F HODLER'!E30+'F HODLER'!E47+'PICTET ROCHEMONT'!E13+'PICTET ROCHEMONT'!E30+'VV, BEL AIR'!E30+'VV, BEL AIR'!E13+'VV, FRANK THOMAS'!E13+'VV, FRANK THOMAS'!E30+TRANCHEES!E13+TRANCHEES!E30 -> 224 | F13: ='XXXI DECEMBRE'!F13+ARQUEBUSE!F13+ARQUEBUSE!F30+'GEORGES-FAVON'!F13+'GEORGES-FAVON'!F30+'F HODLER'!F13+'F HODLER'!F30+'F HODLER'!F47+'PICTET ROCHEMONT'!F13+'PICTET ROCHEMONT'!F30+'VV, BEL AIR'!F30+'VV, BEL AIR'!F13+'VV, FRANK THOMAS'!F13+'VV, FRANK THOMAS'!F30+TRANCHEES!F13+TRANCHEES!F30 -> 220 | G13: =SUM(C13:F13) -> 1200 | H13: =G13/$G$17 -> 0.54274084 | J13: Hommes | K13: ='XXXI DECEMBRE'!K13+ARQUEBUSE!K13+ARQUEBUSE!K30+'GEORGES-FAVON'!K13+'GEORGES-FAVON'!K30+'F HODLER'!K13+'F HODLER'!K30+'F HODLER'!K47+'PICTET ROCHEMONT'!K13+'PICTET ROCHEMONT'!K30+'VV, BEL AIR'!K30+'VV, BEL AIR'!K13+'VV, FRANK THOMAS'!K13+'VV, FRANK THOMAS'!K30+TRANCHEES!K13+TRANCHEES!K30 -> 211 | L13: ='XXXI DECEMBRE'!L13+ARQUEBUSE!L13+ARQUEBUSE!L30+'GEORGES-FAVON'!L13+'GEORGES-FAVON'!L30+'F HODLER'!L13+'F HODLER'!L30+'F HODLER'!L47+'PICTET ROCHEMONT'!L13+'PICTET ROCHEMONT'!L30+'VV, BEL AIR'!L30+'VV, BEL AIR'!L13+'VV, FRANK THOMAS'!L13+'VV, FRANK THOMAS'!L30+TRANCHEES!L13+TRANCHEES!L30 -> 226 | M13: ='XXXI DECEMBRE'!M13+ARQUEBUSE!M13+ARQUEBUSE!M30+'GEORGES-FAVON'!M13+'GEORGES-FAVON'!M30+'F HODLER'!M13+'F HODLER'!M30+'F HODLER'!M47+'PICTET ROCHEMONT'!M13+'PICTET ROCHEMONT'!M30+'VV, BEL AIR'!M30+'VV, BEL AIR'!M13+'VV, FRANK THOMAS'!M13+'VV, FRANK THOMAS'!M30+TRANCHEES!M13+TRANCHEES!M30 -> 232 | N13: ='XXXI DECEMBRE'!N13+ARQUEBUSE!N13+ARQUEBUSE!N30+'GEORGES-FAVON'!N13+'GEORGES-FAVON'!N30+'F HODLER'!N13+'F HODLER'!N30+'F HODLER'!N47+'PICTET ROCHEMONT'!N13+'PICTET ROCHEMONT'!N30+'VV, BEL AIR'!N30+'VV, BEL AIR'!N13+'VV, FRANK THOMAS'!N13+'VV, FRANK THOMAS'!N30+TRANCHEES!N13+TRANCHEES!N30 -> 291 | O13: =SUM(K13:N13) -> 960 | P13: =O13/$O$17 -> 0.57657658
B14: Femmes | C14: ='XXXI DECEMBRE'!C14+ARQUEBUSE!C14+ARQUEBUSE!C31+'GEORGES-FAVON'!C14+'GEORGES-FAVON'!C31+'F HODLER'!C14+'F HODLER'!C31+'F HODLER'!C48+'PICTET ROCHEMONT'!C14+'PICTET ROCHEMONT'!C31+'VV, BEL AIR'!C31+'VV, BEL AIR'!C14+'VV, FRANK THOMAS'!C14+'VV, FRANK THOMAS'!C31+TRANCHEES!C14+TRANCHEES!C31 -> 394 | D14: ='XXXI DECEMBRE'!D14+ARQUEBUSE!D14+ARQUEBUSE!D31+'GEORGES-FAVON'!D14+'GEORGES-FAVON'!D31+'F HODLER'!D14+'F HODLER'!D31+'F HODLER'!D48+'PICTET ROCHEMONT'!D14+'PICTET ROCHEMONT'!D31+'VV, BEL AIR'!D31+'VV, BEL AIR'!D14+'VV, FRANK THOMAS'!D14+'VV, FRANK THOMAS'!D31+TRANCHEES!D14+TRANCHEES!D31 -> 155 | E14: ='XXXI DECEMBRE'!E14+ARQUEBUSE!E14+ARQUEBUSE!E31+'GEORGES-FAVON'!E14+'GEORGES-FAVON'!E31+'F HODLER'!E14+'F HODLER'!E31+'F HODLER'!E48+'PICTET ROCHEMONT'!E14+'PICTET ROCHEMONT'!E31+'VV, BEL AIR'!E31+'VV, BEL AIR'!E14+'VV, FRANK THOMAS'!E14+'VV, FRANK THOMAS'!E31+TRANCHEES!E14+TRANCHEES!E31 -> 158 | F14: ='XXXI DECEMBRE'!F14+ARQUEBUSE!F14+ARQUEBUSE!F31+'GEORGES-FAVON'!F14+'GEORGES-FAVON'!F31+'F HODLER'!F14+'F HODLER'!F31+'F HODLER'!F48+'PICTET ROCHEMONT'!F14+'PICTET ROCHEMONT'!F31+'VV, BEL AIR'!F31+'VV, BEL AIR'!F14+'VV, FRANK THOMAS'!F14+'VV, FRANK THOMAS'!F31+TRANCHEES!F14+TRANCHEES!F31 -> 177 | G14: =SUM(C14:F14) -> 884 | H14: =G14/$G$17 -> 0.39981909 | J14: Femmes | K14: ='XXXI DECEMBRE'!K14+ARQUEBUSE!K14+ARQUEBUSE!K31+'GEORGES-FAVON'!K14+'GEORGES-FAVON'!K31+'F HODLER'!K14+'F HODLER'!K31+'F HODLER'!K48+'PICTET ROCHEMONT'!K14+'PICTET ROCHEMONT'!K31+'VV, BEL AIR'!K31+'VV, BEL AIR'!K14+'VV, FRANK THOMAS'!K14+'VV, FRANK THOMAS'!K31+TRANCHEES!K14+TRANCHEES!K31 -> 148 | L14: ='XXXI DECEMBRE'!L14+ARQUEBUSE!L14+ARQUEBUSE!L31+'GEORGES-FAVON'!L14+'GEORGES-FAVON'!L31+'F HODLER'!L14+'F HODLER'!L31+'F HODLER'!L48+'PICTET ROCHEMONT'!L14+'PICTET ROCHEMONT'!L31+'VV, BEL AIR'!L31+'VV, BEL AIR'!L14+'VV, FRANK THOMAS'!L14+'VV, FRANK THOMAS'!L31+TRANCHEES!L14+TRANCHEES!L31 -> 160 | M14: ='XXXI DECEMBRE'!M14+ARQUEBUSE!M14+ARQUEBUSE!M31+'GEORGES-FAVON'!M14+'GEORGES-FAVON'!M31+'F HODLER'!M14+'F HODLER'!M31+'F HODLER'!M48+'PICTET ROCHEMONT'!M14+'PICTET ROCHEMONT'!M31+'VV, BEL AIR'!M31+'VV, BEL AIR'!M14+'VV, FRANK THOMAS'!M14+'VV, FRANK THOMAS'!M31+TRANCHEES!M14+TRANCHEES!M31 -> 163 | N14: ='XXXI DECEMBRE'!N14+ARQUEBUSE!N14+ARQUEBUSE!N31+'GEORGES-FAVON'!N14+'GEORGES-FAVON'!N31+'F HODLER'!N14+'F HODLER'!N31+'F HODLER'!N48+'PICTET ROCHEMONT'!N14+'PICTET ROCHEMONT'!N31+'VV, BEL AIR'!N31+'VV, BEL AIR'!N14+'VV, FRANK THOMAS'!N14+'VV, FRANK THOMAS'!N31+TRANCHEES!N14+TRANCHEES!N31 -> 200 | O14: =SUM(K14:N14) -> 671 | P14: =O14/$O$17 -> 0.403003
